package net.divinerpg.dimensions.vanilla;

import java.util.Random;

import net.divinerpg.entities.vanilla.EntityLivestockMerchant;
import net.minecraft.init.Blocks;
import net.minecraft.world.World;
import net.minecraft.world.gen.feature.WorldGenerator;

public class WorldGenHut extends WorldGenerator {

	@Override
	public boolean generate(World world, Random rand, int i, int j, int k) {
		if (world.getBlock(i + 5, j, k + 5) == Blocks.grass && world.getBlock(i + 5, j + 1, k + 5) == Blocks.air && world.getBlock(i+3, j, k+3) == Blocks.grass && world.getBlock(i+3, j + 1, k+3) == Blocks.air && world.getBlock(i + 7, j, k + 7) == Blocks.grass && world.getBlock(i + 7, j + 1, k + 7) == Blocks.air) {
			world.setBlock(i + 0, j + 1, k + 0, Blocks.fence);
			world.setBlock(i + 0, j + 1, k + 1, Blocks.fence);
			world.setBlock(i + 0, j + 1, k + 2, Blocks.fence);
			world.setBlock(i + 0, j + 1, k + 3, Blocks.fence);
			world.setBlock(i + 0, j + 1, k + 4, Blocks.fence);
			world.setBlock(i + 0, j + 1, k + 5, Blocks.fence);
			world.setBlock(i + 0, j + 1, k + 6, Blocks.fence);
			world.setBlock(i + 0, j + 1, k + 7, Blocks.fence);
			world.setBlock(i + 0, j + 1, k + 8, Blocks.fence);
			world.setBlock(i + 0, j + 1, k + 9, Blocks.fence);
			world.setBlock(i + 0, j + 1, k + 10, Blocks.fence);
			world.setBlock(i + 1, j + 1, k + 0, Blocks.fence);
			world.setBlock(i + 1, j + 1, k + 10, Blocks.fence);
			world.setBlock(i + 1, j + 4, k + 4, Blocks.hay_block);
			world.setBlock(i + 1, j + 4, k + 5, Blocks.hay_block);
			world.setBlock(i + 1, j + 4, k + 6, Blocks.hay_block);
			world.setBlock(i + 2, j + 0, k + 5, Blocks.brick_block);
			world.setBlock(i + 2, j + 1, k + 0, Blocks.fence);
			world.setBlock(i + 2, j + 1, k + 5, Blocks.hay_block);
			world.setBlock(i + 2, j + 1, k + 10, Blocks.fence);
			world.setBlock(i + 2, j + 2, k + 5, Blocks.hay_block);
			world.setBlock(i + 2, j + 3, k + 5, Blocks.hay_block);
			world.setBlock(i + 2, j + 4, k + 2, Blocks.hay_block);
			world.setBlock(i + 2, j + 4, k + 3, Blocks.hay_block);
			world.setBlock(i + 2, j + 4, k + 4, Blocks.hay_block);
			world.setBlock(i + 2, j + 4, k + 5, Blocks.hay_block);
			world.setBlock(i + 2, j + 4, k + 6, Blocks.hay_block);
			world.setBlock(i + 2, j + 4, k + 7, Blocks.hay_block);
			world.setBlock(i + 2, j + 4, k + 8, Blocks.hay_block);
			world.setBlock(i + 2, j + 5, k + 5, Blocks.hay_block);
			world.setBlock(i + 3, j + 0, k + 3, Blocks.brick_block);
			world.setBlock(i + 3, j + 0, k + 4, Blocks.brick_block);
			world.setBlock(i + 3, j + 0, k + 5, Blocks.brick_block);
			world.setBlock(i + 3, j + 0, k + 6, Blocks.brick_block);
			world.setBlock(i + 3, j + 0, k + 7, Blocks.brick_block);
			world.setBlock(i + 3, j + 1, k + 0, Blocks.fence);
			world.setBlock(i + 3, j + 1, k + 3, Blocks.hay_block);
			world.setBlock(i + 3, j + 1, k + 4, Blocks.hay_block);
			world.setBlock(i + 3, j + 1, k + 6, Blocks.hay_block);
			world.setBlock(i + 3, j + 1, k + 7, Blocks.hay_block);
			world.setBlock(i + 3, j + 1, k + 10, Blocks.fence);
			world.setBlock(i + 3, j + 2, k + 3, Blocks.hay_block);
			world.setBlock(i + 3, j + 2, k + 4, Blocks.hay_block);
			world.setBlock(i + 3, j + 2, k + 6, Blocks.hay_block);
			world.setBlock(i + 3, j + 2, k + 7, Blocks.hay_block);
			world.setBlock(i + 3, j + 3, k + 3, Blocks.hay_block);
			world.setBlock(i + 3, j + 3, k + 4, Blocks.hay_block);
			world.setBlock(i + 3, j + 3, k + 6, Blocks.hay_block);
			world.setBlock(i + 3, j + 3, k + 7, Blocks.hay_block);
			world.setBlock(i + 3, j + 4, k + 2, Blocks.hay_block);
			world.setBlock(i + 3, j + 4, k + 3, Blocks.hay_block);
			world.setBlock(i + 3, j + 4, k + 4, Blocks.hay_block);
			world.setBlock(i + 3, j + 4, k + 5, Blocks.hay_block);
			world.setBlock(i + 3, j + 4, k + 6, Blocks.hay_block);
			world.setBlock(i + 3, j + 4, k + 7, Blocks.hay_block);
			world.setBlock(i + 3, j + 4, k + 8, Blocks.hay_block);
			world.setBlock(i + 3, j + 5, k + 3, Blocks.hay_block);
			world.setBlock(i + 3, j + 5, k + 4, Blocks.hay_block);
			world.setBlock(i + 3, j + 5, k + 5, Blocks.hay_block);
			world.setBlock(i + 3, j + 5, k + 6, Blocks.hay_block);
			world.setBlock(i + 3, j + 5, k + 7, Blocks.hay_block);
			world.setBlock(i + 4, j + 0, k + 3, Blocks.brick_block);
			world.setBlock(i + 4, j + 0, k + 4, Blocks.brick_block);
			world.setBlock(i + 4, j + 0, k + 5, Blocks.brick_block);
			world.setBlock(i + 4, j + 0, k + 6, Blocks.brick_block);
			world.setBlock(i + 4, j + 0, k + 7, Blocks.brick_block);
			world.setBlock(i + 4, j + 1, k + 0, Blocks.fence);
			world.setBlock(i + 4, j + 1, k + 3, Blocks.hay_block);
			world.setBlock(i + 4, j + 1, k + 7, Blocks.hay_block);
			world.setBlock(i + 4, j + 1, k + 10, Blocks.fence);
			world.setBlock(i + 4, j + 2, k + 3, Blocks.hay_block);
			world.setBlock(i + 4, j + 2, k + 7, Blocks.hay_block);
			world.setBlock(i + 4, j + 3, k + 3, Blocks.hay_block);
			world.setBlock(i + 4, j + 3, k + 7, Blocks.hay_block);
			world.setBlock(i + 4, j + 4, k + 1, Blocks.hay_block);
			world.setBlock(i + 4, j + 4, k + 2, Blocks.hay_block);
			world.setBlock(i + 4, j + 4, k + 3, Blocks.hay_block);
			world.setBlock(i + 4, j + 4, k + 4, Blocks.hay_block);
			world.setBlock(i + 4, j + 4, k + 5, Blocks.hay_block);
			world.setBlock(i + 4, j + 4, k + 6, Blocks.hay_block);
			world.setBlock(i + 4, j + 4, k + 7, Blocks.hay_block);
			world.setBlock(i + 4, j + 4, k + 8, Blocks.hay_block);
			world.setBlock(i + 4, j + 4, k + 9, Blocks.hay_block);
			world.setBlock(i + 4, j + 5, k + 3, Blocks.hay_block);
			world.setBlock(i + 4, j + 5, k + 4, Blocks.hay_block);
			world.setBlock(i + 4, j + 5, k + 5, Blocks.hay_block);
			world.setBlock(i + 4, j + 5, k + 6, Blocks.hay_block);
			world.setBlock(i + 4, j + 5, k + 7, Blocks.hay_block);
			world.setBlock(i + 4, j + 6, k + 4, Blocks.hay_block);
			world.setBlock(i + 4, j + 6, k + 5, Blocks.hay_block);
			world.setBlock(i + 4, j + 6, k + 6, Blocks.hay_block);
			world.setBlock(i + 5, j + 0, k + 2, Blocks.brick_block);
			world.setBlock(i + 5, j + 0, k + 3, Blocks.brick_block);
			world.setBlock(i + 5, j + 0, k + 4, Blocks.brick_block);
			world.setBlock(i + 5, j + 0, k + 5, Blocks.brick_block);
			world.setBlock(i + 5, j + 0, k + 6, Blocks.brick_block);
			world.setBlock(i + 5, j + 0, k + 7, Blocks.brick_block);
			world.setBlock(i + 5, j + 0, k + 8, Blocks.brick_block);
			world.setBlock(i + 5, j + 1, k + 0, Blocks.fence);
			world.setBlock(i + 5, j + 1, k + 2, Blocks.hay_block);
			world.setBlock(i + 5, j + 1, k + 8, Blocks.hay_block);
			world.setBlock(i + 5, j + 1, k + 10, Blocks.fence);
			world.setBlock(i + 5, j + 2, k + 2, Blocks.hay_block);
			world.setBlock(i + 5, j + 2, k + 8, Blocks.hay_block);
			world.setBlock(i + 5, j + 3, k + 2, Blocks.hay_block);
			world.setBlock(i + 5, j + 3, k + 8, Blocks.hay_block);
			world.setBlock(i + 5, j + 4, k + 1, Blocks.hay_block);
			world.setBlock(i + 5, j + 4, k + 2, Blocks.hay_block);
			world.setBlock(i + 5, j + 4, k + 3, Blocks.hay_block);
			world.setBlock(i + 5, j + 4, k + 4, Blocks.hay_block);
			world.setBlock(i + 5, j + 4, k + 5, Blocks.glowstone);
			world.setBlock(i + 5, j + 4, k + 6, Blocks.hay_block);
			world.setBlock(i + 5, j + 4, k + 7, Blocks.hay_block);
			world.setBlock(i + 5, j + 4, k + 8, Blocks.hay_block);
			world.setBlock(i + 5, j + 4, k + 9, Blocks.hay_block);
			world.setBlock(i + 5, j + 5, k + 2, Blocks.hay_block);
			world.setBlock(i + 5, j + 5, k + 3, Blocks.hay_block);
			world.setBlock(i + 5, j + 5, k + 4, Blocks.hay_block);
			world.setBlock(i + 5, j + 5, k + 5, Blocks.hay_block);
			world.setBlock(i + 5, j + 5, k + 6, Blocks.hay_block);
			world.setBlock(i + 5, j + 5, k + 7, Blocks.hay_block);
			world.setBlock(i + 5, j + 5, k + 8, Blocks.hay_block);
			world.setBlock(i + 5, j + 6, k + 4, Blocks.hay_block);
			world.setBlock(i + 5, j + 6, k + 5, Blocks.hay_block);
			world.setBlock(i + 5, j + 6, k + 6, Blocks.hay_block);
			world.setBlock(i + 5, j + 7, k + 5, Blocks.hay_block);
			world.setBlock(i + 6, j + 0, k + 3, Blocks.brick_block);
			world.setBlock(i + 6, j + 0, k + 4, Blocks.brick_block);
			world.setBlock(i + 6, j + 0, k + 5, Blocks.brick_block);
			world.setBlock(i + 6, j + 0, k + 6, Blocks.brick_block);
			world.setBlock(i + 6, j + 0, k + 7, Blocks.brick_block);
			world.setBlock(i + 6, j + 1, k + 0, Blocks.fence);
			world.setBlock(i + 6, j + 1, k + 3, Blocks.hay_block);
			world.setBlock(i + 6, j + 1, k + 7, Blocks.hay_block);
			world.setBlock(i + 6, j + 1, k + 10, Blocks.fence);
			world.setBlock(i + 6, j + 2, k + 3, Blocks.hay_block);
			world.setBlock(i + 6, j + 2, k + 7, Blocks.hay_block);
			world.setBlock(i + 6, j + 3, k + 3, Blocks.hay_block);
			world.setBlock(i + 6, j + 3, k + 7, Blocks.hay_block);
			world.setBlock(i + 6, j + 4, k + 1, Blocks.hay_block);
			world.setBlock(i + 6, j + 4, k + 2, Blocks.hay_block);
			world.setBlock(i + 6, j + 4, k + 3, Blocks.hay_block);
			world.setBlock(i + 6, j + 4, k + 4, Blocks.hay_block);
			world.setBlock(i + 6, j + 4, k + 5, Blocks.hay_block);
			world.setBlock(i + 6, j + 4, k + 6, Blocks.hay_block);
			world.setBlock(i + 6, j + 4, k + 7, Blocks.hay_block);
			world.setBlock(i + 6, j + 4, k + 8, Blocks.hay_block);
			world.setBlock(i + 6, j + 4, k + 9, Blocks.hay_block);
			world.setBlock(i + 6, j + 5, k + 3, Blocks.hay_block);
			world.setBlock(i + 6, j + 5, k + 4, Blocks.hay_block);
			world.setBlock(i + 6, j + 5, k + 5, Blocks.hay_block);
			world.setBlock(i + 6, j + 5, k + 6, Blocks.hay_block);
			world.setBlock(i + 6, j + 5, k + 7, Blocks.hay_block);
			world.setBlock(i + 6, j + 6, k + 4, Blocks.hay_block);
			world.setBlock(i + 6, j + 6, k + 5, Blocks.hay_block);
			world.setBlock(i + 6, j + 6, k + 6, Blocks.hay_block);
			world.setBlock(i + 7, j + 0, k + 3, Blocks.brick_block);
			world.setBlock(i + 7, j + 0, k + 4, Blocks.brick_block);
			world.setBlock(i + 7, j + 0, k + 5, Blocks.brick_block);
			world.setBlock(i + 7, j + 0, k + 6, Blocks.brick_block);
			world.setBlock(i + 7, j + 0, k + 7, Blocks.brick_block);
			world.setBlock(i + 7, j + 1, k + 0, Blocks.fence);
			world.setBlock(i + 7, j + 1, k + 3, Blocks.hay_block);
			world.setBlock(i + 7, j + 1, k + 4, Blocks.hay_block);
			world.setBlock(i + 7, j + 1, k + 6, Blocks.hay_block);
			world.setBlock(i + 7, j + 1, k + 7, Blocks.hay_block);
			world.setBlock(i + 7, j + 1, k + 10, Blocks.fence);
			world.setBlock(i + 7, j + 2, k + 3, Blocks.hay_block);
			world.setBlock(i + 7, j + 2, k + 4, Blocks.hay_block);
			world.setBlock(i + 7, j + 2, k + 6, Blocks.hay_block);
			world.setBlock(i + 7, j + 2, k + 7, Blocks.hay_block);
			world.setBlock(i + 7, j + 3, k + 3, Blocks.hay_block);
			world.setBlock(i + 7, j + 3, k + 4, Blocks.hay_block);
			world.setBlock(i + 7, j + 3, k + 5, Blocks.hay_block);
			world.setBlock(i + 7, j + 3, k + 6, Blocks.hay_block);
			world.setBlock(i + 7, j + 3, k + 7, Blocks.hay_block);
			world.setBlock(i + 7, j + 4, k + 2, Blocks.hay_block);
			world.setBlock(i + 7, j + 4, k + 3, Blocks.hay_block);
			world.setBlock(i + 7, j + 4, k + 4, Blocks.hay_block);
			world.setBlock(i + 7, j + 4, k + 5, Blocks.hay_block);
			world.setBlock(i + 7, j + 4, k + 6, Blocks.hay_block);
			world.setBlock(i + 7, j + 4, k + 7, Blocks.hay_block);
			world.setBlock(i + 7, j + 4, k + 8, Blocks.hay_block);
			world.setBlock(i + 7, j + 5, k + 3, Blocks.hay_block);
			world.setBlock(i + 7, j + 5, k + 4, Blocks.hay_block);
			world.setBlock(i + 7, j + 5, k + 5, Blocks.hay_block);
			world.setBlock(i + 7, j + 5, k + 6, Blocks.hay_block);
			world.setBlock(i + 7, j + 5, k + 7, Blocks.hay_block);
			world.setBlock(i + 7, j + 6, k + 5, Blocks.hay_block);
			world.setBlock(i + 8, j + 0, k + 4, Blocks.brick_block);
			world.setBlock(i + 8, j + 0, k + 5, Blocks.brick_block);
			world.setBlock(i + 8, j + 0, k + 6, Blocks.brick_block);
			world.setBlock(i + 8, j + 1, k + 0, Blocks.fence);
			world.setBlock(i + 8, j + 1, k + 4, Blocks.hay_block);
			world.setBlock(i + 8, j + 1, k + 6, Blocks.hay_block);
			world.setBlock(i + 8, j + 1, k + 10, Blocks.fence);
			world.setBlock(i + 8, j + 2, k + 4, Blocks.hay_block);
			world.setBlock(i + 8, j + 2, k + 6, Blocks.hay_block);
			world.setBlock(i + 8, j + 3, k + 4, Blocks.hay_block);
			world.setBlock(i + 8, j + 3, k + 5, Blocks.hay_block);
			world.setBlock(i + 8, j + 3, k + 6, Blocks.hay_block);
			world.setBlock(i + 8, j + 4, k + 2, Blocks.hay_block);
			world.setBlock(i + 8, j + 4, k + 3, Blocks.hay_block);
			world.setBlock(i + 8, j + 4, k + 4, Blocks.hay_block);
			world.setBlock(i + 8, j + 4, k + 5, Blocks.hay_block);
			world.setBlock(i + 8, j + 4, k + 6, Blocks.hay_block);
			world.setBlock(i + 8, j + 4, k + 7, Blocks.hay_block);
			world.setBlock(i + 8, j + 4, k + 8, Blocks.hay_block);
			world.setBlock(i + 8, j + 5, k + 4, Blocks.hay_block);
			world.setBlock(i + 8, j + 5, k + 5, Blocks.hay_block);
			world.setBlock(i + 8, j + 5, k + 6, Blocks.hay_block);
			world.setBlock(i + 9, j + 1, k + 0, Blocks.fence);
			world.setBlock(i + 9, j + 1, k + 4, Blocks.fence);
			world.setBlock(i + 9, j + 1, k + 6, Blocks.fence);
			world.setBlock(i + 9, j + 1, k + 10, Blocks.fence);
			world.setBlock(i + 9, j + 4, k + 3, Blocks.hay_block);
			world.setBlock(i + 9, j + 4, k + 4, Blocks.hay_block);
			world.setBlock(i + 9, j + 4, k + 5, Blocks.hay_block);
			world.setBlock(i + 9, j + 4, k + 6, Blocks.hay_block);
			world.setBlock(i + 9, j + 4, k + 7, Blocks.hay_block);
			world.setBlock(i + 10, j + 1, k + 0, Blocks.fence);
			world.setBlock(i + 10, j + 1, k + 1, Blocks.fence);
			world.setBlock(i + 10, j + 1, k + 2, Blocks.fence);
			world.setBlock(i + 10, j + 1, k + 3, Blocks.fence);
			world.setBlock(i + 10, j + 1, k + 4, Blocks.fence);
			world.setBlock(i + 10, j + 1, k + 6, Blocks.fence);
			world.setBlock(i + 10, j + 1, k + 7, Blocks.fence);
			world.setBlock(i + 10, j + 1, k + 8, Blocks.fence);
			world.setBlock(i + 10, j + 1, k + 9, Blocks.fence);
			world.setBlock(i + 10, j + 1, k + 10, Blocks.fence);
			world.setBlock(i + 7, j + 1, k + 5, Blocks.wooden_door, 2, 2);
			world.setBlock(i + 7, j + 2, k + 5, Blocks.wooden_door, 8, 2);
			
			EntityLivestockMerchant e = new EntityLivestockMerchant(world);
			e.setLocationAndAngles(i+5, j+1, k+5, 0, 0);
			world.spawnEntityInWorld(e);

			return true;
		}
		return false;
	}
}