/*
*** MADE BY MITHION'S .SCHEMATIC TO JAVA CONVERTING TOOL v1.6 ***
*/

package divinerpg.dimensions.vethea.village;
import java.util.Random;

import divinerpg.dimensions.vethea.VetheaWorldGenerator;
import divinerpg.registry.ModBlocks;
import net.minecraft.world.World;
import net.minecraft.world.gen.feature.WorldGenerator;

public class HouseDown2 extends VetheaWorldGenerator
{
	protected int[] GetValidSpawnBlocks() {
		return new int[] {
		};
	}

	public HouseDown2() { }

	public boolean generate(World world, Random rand, int i, int j, int k) {

		setBlock(world, i + 0, j + 0, k + 0, ModBlocks.darkDreamBricks);
		setBlock(world, i + 0, j + 0, k + 1, ModBlocks.darkDreamBricks);
		setBlock(world, i + 0, j + 0, k + 2, ModBlocks.darkDreamBricks);
		setBlock(world, i + 0, j + 0, k + 3, ModBlocks.darkDreamBricks);
		setBlock(world, i + 0, j + 0, k + 4, ModBlocks.darkDreamBricks);
		setBlock(world, i + 0, j + 0, k + 5, ModBlocks.darkDreamBricks);
		setBlock(world, i + 0, j + 0, k + 6, ModBlocks.darkDreamBricks);
		setBlock(world, i + 0, j + 0, k + 7, ModBlocks.darkDreamBricks);
		setBlock(world, i + 0, j + 0, k + 8, ModBlocks.darkDreamBricks);
		setBlock(world, i + 0, j + 0, k + 9, ModBlocks.darkDreamBricks);
		setBlock(world, i + 0, j + 0, k + 10, ModBlocks.darkDreamBricks);
		setBlock(world, i + 0, j + 1, k + 0, ModBlocks.darkDreamBricks);
		setBlock(world, i + 0, j + 1, k + 1, ModBlocks.lightDreamBricks);
		setBlock(world, i + 0, j + 1, k + 2, ModBlocks.lightDreamBricks);
		setBlock(world, i + 0, j + 1, k + 3, ModBlocks.lightDreamBricks);
		setBlock(world, i + 0, j + 1, k + 4, ModBlocks.lightDreamBricks);
		setBlock(world, i + 0, j + 1, k + 5, ModBlocks.lightDreamBricks);
		setBlock(world, i + 0, j + 1, k + 6, ModBlocks.lightDreamBricks);
		setBlock(world, i + 0, j + 1, k + 7, ModBlocks.lightDreamBricks);
		setBlock(world, i + 0, j + 1, k + 8, ModBlocks.lightDreamBricks);
		setBlock(world, i + 0, j + 1, k + 9, ModBlocks.lightDreamBricks);
		setBlock(world, i + 0, j + 1, k + 10, ModBlocks.darkDreamBricks);
		setBlock(world, i + 0, j + 2, k + 0, ModBlocks.darkDreamBricks);
		setBlock(world, i + 0, j + 2, k + 1, ModBlocks.darkDreamBricks);
		setBlock(world, i + 0, j + 2, k + 2, ModBlocks.darkDreamBricks);
		setBlock(world, i + 0, j + 2, k + 3, ModBlocks.darkDreamBricks);
		setBlock(world, i + 0, j + 2, k + 4, ModBlocks.darkDreamBricks);
		setBlock(world, i + 0, j + 2, k + 5, ModBlocks.darkDreamBricks);
		setBlock(world, i + 0, j + 2, k + 6, ModBlocks.darkDreamBricks);
		setBlock(world, i + 0, j + 2, k + 7, ModBlocks.darkDreamBricks);
		setBlock(world, i + 0, j + 2, k + 8, ModBlocks.darkDreamBricks);
		setBlock(world, i + 0, j + 2, k + 9, ModBlocks.darkDreamBricks);
		setBlock(world, i + 0, j + 2, k + 10, ModBlocks.darkDreamBricks);
		setBlock(world, i + 1, j + 0, k + 0, ModBlocks.darkDreamBricks);
		setBlock(world, i + 1, j + 0, k + 1, ModBlocks.smoothGlass);
		setBlock(world, i + 1, j + 0, k + 2, ModBlocks.smoothGlass);
		setBlock(world, i + 1, j + 0, k + 3, ModBlocks.smoothGlass);
		setBlock(world, i + 1, j + 0, k + 4, ModBlocks.smoothGlass);
		setBlock(world, i + 1, j + 0, k + 5, ModBlocks.smoothGlass);
		setBlock(world, i + 1, j + 0, k + 6, ModBlocks.smoothGlass);
		setBlock(world, i + 1, j + 0, k + 7, ModBlocks.smoothGlass);
		setBlock(world, i + 1, j + 0, k + 8, ModBlocks.smoothGlass);
		setBlock(world, i + 1, j + 0, k + 9, ModBlocks.smoothGlass);
		setBlock(world, i + 1, j + 0, k + 10, ModBlocks.darkDreamBricks);
		setBlock(world, i + 1, j + 1, k + 0, ModBlocks.lightDreamBricks);
		setBlock(world, i + 1, j + 1, k + 1, ModBlocks.firelight);
		setBlock(world, i + 1, j + 1, k + 9, ModBlocks.firelight);
		setBlock(world, i + 1, j + 1, k + 10, ModBlocks.lightDreamBricks);
		setBlock(world, i + 1, j + 2, k + 0, ModBlocks.darkDreamBricks);
		setBlock(world, i + 1, j + 2, k + 10, ModBlocks.darkDreamBricks);
		setBlock(world, i + 1, j + 3, k + 1, ModBlocks.darkDreamBricks);
		setBlock(world, i + 1, j + 3, k + 2, ModBlocks.darkDreamBricks);
		setBlock(world, i + 1, j + 3, k + 3, ModBlocks.darkDreamBricks);
		setBlock(world, i + 1, j + 3, k + 4, ModBlocks.darkDreamBricks);
		setBlock(world, i + 1, j + 3, k + 5, ModBlocks.darkDreamBricks);
		setBlock(world, i + 1, j + 3, k + 6, ModBlocks.darkDreamBricks);
		setBlock(world, i + 1, j + 3, k + 7, ModBlocks.darkDreamBricks);
		setBlock(world, i + 1, j + 3, k + 8, ModBlocks.darkDreamBricks);
		setBlock(world, i + 1, j + 3, k + 9, ModBlocks.darkDreamBricks);
		setBlock(world, i + 1, j + 4, k + 1, ModBlocks.darkDreamBricks);
		setBlock(world, i + 1, j + 4, k + 2, ModBlocks.lightDreamBricks);
		setBlock(world, i + 1, j + 4, k + 3, ModBlocks.lightDreamBricks);
		setBlock(world, i + 1, j + 4, k + 4, ModBlocks.lightDreamBricks);
		setBlock(world, i + 1, j + 4, k + 5, ModBlocks.lightDreamBricks);
		setBlock(world, i + 1, j + 4, k + 6, ModBlocks.lightDreamBricks);
		setBlock(world, i + 1, j + 4, k + 7, ModBlocks.lightDreamBricks);
		setBlock(world, i + 1, j + 4, k + 8, ModBlocks.lightDreamBricks);
		setBlock(world, i + 1, j + 4, k + 9, ModBlocks.darkDreamBricks);
		setBlock(world, i + 1, j + 5, k + 1, ModBlocks.darkDreamBricks);
		setBlock(world, i + 1, j + 5, k + 2, ModBlocks.darkDreamBricks);
		setBlock(world, i + 1, j + 5, k + 3, ModBlocks.darkDreamBricks);
		setBlock(world, i + 1, j + 5, k + 4, ModBlocks.darkDreamBricks);
		setBlock(world, i + 1, j + 5, k + 5, ModBlocks.darkDreamBricks);
		setBlock(world, i + 1, j + 5, k + 6, ModBlocks.darkDreamBricks);
		setBlock(world, i + 1, j + 5, k + 7, ModBlocks.darkDreamBricks);
		setBlock(world, i + 1, j + 5, k + 8, ModBlocks.darkDreamBricks);
		setBlock(world, i + 1, j + 5, k + 9, ModBlocks.darkDreamBricks);
		setBlock(world, i + 1, j + 12, k + 3, ModBlocks.darkDreamBricks);
		setBlock(world, i + 1, j + 12, k + 7, ModBlocks.darkDreamBricks);
		setBlock(world, i + 1, j + 13, k + 4, ModBlocks.darkDreamBricks);
		setBlock(world, i + 1, j + 13, k + 5, ModBlocks.darkDreamBricks);
		setBlock(world, i + 1, j + 13, k + 6, ModBlocks.darkDreamBricks);
		setBlock(world, i + 2, j + 0, k + 0, ModBlocks.darkDreamBricks);
		setBlock(world, i + 2, j + 0, k + 1, ModBlocks.smoothGlass);
		setBlock(world, i + 2, j + 0, k + 2, ModBlocks.smoothGlass);
		setBlock(world, i + 2, j + 0, k + 3, ModBlocks.smoothGlass);
		setBlock(world, i + 2, j + 0, k + 4, ModBlocks.smoothGlass);
		setBlock(world, i + 2, j + 0, k + 5, ModBlocks.smoothGlass);
		setBlock(world, i + 2, j + 0, k + 6, ModBlocks.smoothGlass);
		setBlock(world, i + 2, j + 0, k + 7, ModBlocks.smoothGlass);
		setBlock(world, i + 2, j + 0, k + 8, ModBlocks.smoothGlass);
		setBlock(world, i + 2, j + 0, k + 9, ModBlocks.smoothGlass);
		setBlock(world, i + 2, j + 0, k + 10, ModBlocks.darkDreamBricks);
		setBlock(world, i + 2, j + 1, k + 0, ModBlocks.lightDreamBricks);
		setBlock(world, i + 2, j + 1, k + 10, ModBlocks.lightDreamBricks);
		setBlock(world, i + 2, j + 2, k + 0, ModBlocks.darkDreamBricks);
		setBlock(world, i + 2, j + 2, k + 10, ModBlocks.darkDreamBricks);
		setBlock(world, i + 2, j + 3, k + 1, ModBlocks.darkDreamBricks);
		setBlock(world, i + 2, j + 3, k + 9, ModBlocks.darkDreamBricks);
		setBlock(world, i + 2, j + 4, k + 1, ModBlocks.lightDreamBricks);
		setBlock(world, i + 2, j + 4, k + 9, ModBlocks.lightDreamBricks);
		setBlock(world, i + 2, j + 5, k + 1, ModBlocks.darkDreamBricks);
		setBlock(world, i + 2, j + 5, k + 9, ModBlocks.darkDreamBricks);
		setBlock(world, i + 2, j + 6, k + 2, ModBlocks.darkDreamBricks);
		setBlock(world, i + 2, j + 6, k + 3, ModBlocks.darkDreamBricks);
		setBlock(world, i + 2, j + 6, k + 4, ModBlocks.darkDreamBricks);
		setBlock(world, i + 2, j + 6, k + 5, ModBlocks.darkDreamBricks);
		setBlock(world, i + 2, j + 6, k + 6, ModBlocks.darkDreamBricks);
		setBlock(world, i + 2, j + 6, k + 7, ModBlocks.darkDreamBricks);
		setBlock(world, i + 2, j + 6, k + 8, ModBlocks.darkDreamBricks);
		setBlock(world, i + 2, j + 12, k + 3, ModBlocks.darkDreamBricks);
		setBlock(world, i + 2, j + 12, k + 7, ModBlocks.darkDreamBricks);
		setBlock(world, i + 2, j + 13, k + 4, ModBlocks.darkDreamBricks);
		setBlock(world, i + 2, j + 13, k + 5, ModBlocks.darkDreamBricks);
		setBlock(world, i + 2, j + 13, k + 6, ModBlocks.darkDreamBricks);
		setBlock(world, i + 3, j + 0, k + 0, ModBlocks.darkDreamBricks);
		setBlock(world, i + 3, j + 0, k + 1, ModBlocks.smoothGlass);
		setBlock(world, i + 3, j + 0, k + 2, ModBlocks.smoothGlass);
		setBlock(world, i + 3, j + 0, k + 3, ModBlocks.smoothGlass);
		setBlock(world, i + 3, j + 0, k + 4, ModBlocks.smoothGlass);
		setBlock(world, i + 3, j + 0, k + 5, ModBlocks.smoothGlass);
		setBlock(world, i + 3, j + 0, k + 6, ModBlocks.smoothGlass);
		setBlock(world, i + 3, j + 0, k + 7, ModBlocks.smoothGlass);
		setBlock(world, i + 3, j + 0, k + 8, ModBlocks.smoothGlass);
		setBlock(world, i + 3, j + 0, k + 9, ModBlocks.smoothGlass);
		setBlock(world, i + 3, j + 0, k + 10, ModBlocks.darkDreamBricks);
		setBlock(world, i + 3, j + 1, k + 0, ModBlocks.lightDreamBricks);
		setBlock(world, i + 3, j + 1, k + 10, ModBlocks.lightDreamBricks);
		setBlock(world, i + 3, j + 2, k + 0, ModBlocks.darkDreamBricks);
		setBlock(world, i + 3, j + 2, k + 10, ModBlocks.darkDreamBricks);
		setBlock(world, i + 3, j + 3, k + 1, ModBlocks.darkDreamBricks);
		setBlock(world, i + 3, j + 3, k + 9, ModBlocks.darkDreamBricks);
		setBlock(world, i + 3, j + 4, k + 1, ModBlocks.lightDreamBricks);
		setBlock(world, i + 3, j + 4, k + 9, ModBlocks.lightDreamBricks);
		setBlock(world, i + 3, j + 5, k + 1, ModBlocks.darkDreamBricks);
		setBlock(world, i + 3, j + 5, k + 9, ModBlocks.darkDreamBricks);
		setBlock(world, i + 3, j + 6, k + 2, ModBlocks.darkDreamBricks);
		setBlock(world, i + 3, j + 6, k + 8, ModBlocks.darkDreamBricks);
		setBlock(world, i + 3, j + 7, k + 3, ModBlocks.darkDreamBricks);
		setBlock(world, i + 3, j + 7, k + 4, ModBlocks.darkDreamBricks);
		setBlock(world, i + 3, j + 7, k + 5, ModBlocks.darkDreamBricks);
		setBlock(world, i + 3, j + 7, k + 6, ModBlocks.darkDreamBricks);
		setBlock(world, i + 3, j + 7, k + 7, ModBlocks.darkDreamBricks);
		setBlock(world, i + 3, j + 12, k + 3, ModBlocks.darkDreamBricks);
		setBlock(world, i + 3, j + 12, k + 7, ModBlocks.darkDreamBricks);
		setBlock(world, i + 3, j + 13, k + 4, ModBlocks.darkDreamBricks);
		setBlock(world, i + 3, j + 13, k + 5, ModBlocks.darkDreamBricks);
		setBlock(world, i + 3, j + 13, k + 6, ModBlocks.darkDreamBricks);
		setBlock(world, i + 4, j + 0, k + 0, ModBlocks.darkDreamBricks);
		setBlock(world, i + 4, j + 0, k + 1, ModBlocks.smoothGlass);
		setBlock(world, i + 4, j + 0, k + 2, ModBlocks.smoothGlass);
		setBlock(world, i + 4, j + 0, k + 3, ModBlocks.smoothGlass);
		setBlock(world, i + 4, j + 0, k + 4, ModBlocks.smoothGlass);
		setBlock(world, i + 4, j + 0, k + 5, ModBlocks.smoothGlass);
		setBlock(world, i + 4, j + 0, k + 6, ModBlocks.smoothGlass);
		setBlock(world, i + 4, j + 0, k + 7, ModBlocks.smoothGlass);
		setBlock(world, i + 4, j + 0, k + 8, ModBlocks.smoothGlass);
		setBlock(world, i + 4, j + 0, k + 9, ModBlocks.smoothGlass);
		setBlock(world, i + 4, j + 0, k + 10, ModBlocks.darkDreamBricks);
		setBlock(world, i + 4, j + 1, k + 0, ModBlocks.lightDreamBricks);
		setBlock(world, i + 4, j + 1, k + 10, ModBlocks.lightDreamBricks);
		setBlock(world, i + 4, j + 2, k + 0, ModBlocks.darkDreamBricks);
		setBlock(world, i + 4, j + 2, k + 10, ModBlocks.darkDreamBricks);
		setBlock(world, i + 4, j + 3, k + 1, ModBlocks.darkDreamBricks);
		setBlock(world, i + 4, j + 3, k + 9, ModBlocks.darkDreamBricks);
		setBlock(world, i + 4, j + 4, k + 1, ModBlocks.lightDreamBricks);
		setBlock(world, i + 4, j + 4, k + 9, ModBlocks.lightDreamBricks);
		setBlock(world, i + 4, j + 5, k + 1, ModBlocks.darkDreamBricks);
		setBlock(world, i + 4, j + 5, k + 9, ModBlocks.darkDreamBricks);
		setBlock(world, i + 4, j + 6, k + 2, ModBlocks.darkDreamBricks);
		setBlock(world, i + 4, j + 6, k + 8, ModBlocks.darkDreamBricks);
		setBlock(world, i + 4, j + 7, k + 3, ModBlocks.darkDreamBricks);
		setBlock(world, i + 4, j + 7, k + 4, ModBlocks.lunaStone);
		setBlock(world, i + 4, j + 7, k + 5, ModBlocks.lunaStone);
		setBlock(world, i + 4, j + 7, k + 6, ModBlocks.lunaStone);
		setBlock(world, i + 4, j + 7, k + 7, ModBlocks.darkDreamBricks);
		setBlock(world, i + 4, j + 8, k + 4, ModBlocks.darkDreamBricks);
		setBlock(world, i + 4, j + 8, k + 5, ModBlocks.darkDreamBricks);
		setBlock(world, i + 4, j + 8, k + 6, ModBlocks.darkDreamBricks);
		setBlock(world, i + 4, j + 9, k + 4, ModBlocks.darkDreamBricks);
		setBlock(world, i + 4, j + 9, k + 5, ModBlocks.lightDreamBricks);
		setBlock(world, i + 4, j + 9, k + 6, ModBlocks.darkDreamBricks);
		setBlock(world, i + 4, j + 10, k + 4, ModBlocks.darkDreamBricks);
		setBlock(world, i + 4, j + 10, k + 5, ModBlocks.darkDreamBricks);
		setBlock(world, i + 4, j + 10, k + 6, ModBlocks.darkDreamBricks);
		setBlock(world, i + 4, j + 11, k + 4, ModBlocks.darkDreamBricks);
		setBlock(world, i + 4, j + 11, k + 6, ModBlocks.darkDreamBricks);
		setBlock(world, i + 4, j + 12, k + 4, ModBlocks.darkDreamBricks);
		setBlock(world, i + 4, j + 12, k + 6, ModBlocks.darkDreamBricks);
		setBlock(world, i + 4, j + 13, k + 4, ModBlocks.darkDreamBricks);
		setBlock(world, i + 4, j + 13, k + 5, ModBlocks.darkDreamBricks);
		setBlock(world, i + 4, j + 13, k + 6, ModBlocks.darkDreamBricks);
		setBlock(world, i + 5, j + 0, k + 0, ModBlocks.darkDreamBricks);
		setBlock(world, i + 5, j + 0, k + 1, ModBlocks.smoothGlass);
		setBlock(world, i + 5, j + 0, k + 2, ModBlocks.smoothGlass);
		setBlock(world, i + 5, j + 0, k + 3, ModBlocks.smoothGlass);
		setBlock(world, i + 5, j + 0, k + 4, ModBlocks.smoothGlass);
		setBlock(world, i + 5, j + 0, k + 5, ModBlocks.smoothGlass);
		setBlock(world, i + 5, j + 0, k + 6, ModBlocks.smoothGlass);
		setBlock(world, i + 5, j + 0, k + 7, ModBlocks.smoothGlass);
		setBlock(world, i + 5, j + 0, k + 8, ModBlocks.smoothGlass);
		setBlock(world, i + 5, j + 0, k + 9, ModBlocks.smoothGlass);
		setBlock(world, i + 5, j + 0, k + 10, ModBlocks.darkDreamBricks);
		setBlock(world, i + 5, j + 1, k + 0, ModBlocks.lightDreamBricks);
		setBlock(world, i + 5, j + 1, k + 10, ModBlocks.lightDreamBricks);
		setBlock(world, i + 5, j + 2, k + 0, ModBlocks.darkDreamBricks);
		setBlock(world, i + 5, j + 2, k + 10, ModBlocks.darkDreamBricks);
		setBlock(world, i + 5, j + 3, k + 1, ModBlocks.darkDreamBricks);
		setBlock(world, i + 5, j + 3, k + 9, ModBlocks.darkDreamBricks);
		setBlock(world, i + 5, j + 4, k + 1, ModBlocks.lightDreamBricks);
		setBlock(world, i + 5, j + 4, k + 9, ModBlocks.lightDreamBricks);
		setBlock(world, i + 5, j + 5, k + 1, ModBlocks.darkDreamBricks);
		setBlock(world, i + 5, j + 5, k + 9, ModBlocks.darkDreamBricks);
		setBlock(world, i + 5, j + 6, k + 2, ModBlocks.darkDreamBricks);
		setBlock(world, i + 5, j + 6, k + 8, ModBlocks.darkDreamBricks);
		setBlock(world, i + 5, j + 7, k + 3, ModBlocks.darkDreamBricks);
		setBlock(world, i + 5, j + 7, k + 7, ModBlocks.darkDreamBricks);
		setBlock(world, i + 5, j + 8, k + 4, ModBlocks.darkDreamBricks);
		setBlock(world, i + 5, j + 8, k + 6, ModBlocks.darkDreamBricks);
		setBlock(world, i + 5, j + 9, k + 4, ModBlocks.lightDreamBricks);
		setBlock(world, i + 5, j + 9, k + 6, ModBlocks.lightDreamBricks);
		setBlock(world, i + 5, j + 10, k + 4, ModBlocks.lightDreamBricks);
		setBlock(world, i + 5, j + 10, k + 6, ModBlocks.lightDreamBricks);
		setBlock(world, i + 5, j + 11, k + 4, ModBlocks.smoothGlass);
		setBlock(world, i + 5, j + 11, k + 6, ModBlocks.smoothGlass);
		setBlock(world, i + 5, j + 12, k + 4, ModBlocks.lightDreamBricks);
		setBlock(world, i + 5, j + 12, k + 6, ModBlocks.lightDreamBricks);
		setBlock(world, i + 5, j + 13, k + 4, ModBlocks.darkDreamBricks);
		setBlock(world, i + 5, j + 13, k + 5, ModBlocks.lunaStone);
		setBlock(world, i + 5, j + 13, k + 6, ModBlocks.darkDreamBricks);
		setBlock(world, i + 6, j + 0, k + 0, ModBlocks.darkDreamBricks);
		setBlock(world, i + 6, j + 0, k + 1, ModBlocks.smoothGlass);
		setBlock(world, i + 6, j + 0, k + 2, ModBlocks.smoothGlass);
		setBlock(world, i + 6, j + 0, k + 3, ModBlocks.smoothGlass);
		setBlock(world, i + 6, j + 0, k + 4, ModBlocks.smoothGlass);
		setBlock(world, i + 6, j + 0, k + 5, ModBlocks.smoothGlass);
		setBlock(world, i + 6, j + 0, k + 6, ModBlocks.smoothGlass);
		setBlock(world, i + 6, j + 0, k + 7, ModBlocks.smoothGlass);
		setBlock(world, i + 6, j + 0, k + 8, ModBlocks.smoothGlass);
		setBlock(world, i + 6, j + 0, k + 9, ModBlocks.smoothGlass);
		setBlock(world, i + 6, j + 0, k + 10, ModBlocks.darkDreamBricks);
		setBlock(world, i + 6, j + 1, k + 0, ModBlocks.lightDreamBricks);
		setBlock(world, i + 6, j + 1, k + 10, ModBlocks.lightDreamBricks);
		setBlock(world, i + 6, j + 2, k + 0, ModBlocks.darkDreamBricks);
		setBlock(world, i + 6, j + 2, k + 10, ModBlocks.darkDreamBricks);
		setBlock(world, i + 6, j + 3, k + 1, ModBlocks.darkDreamBricks);
		setBlock(world, i + 6, j + 3, k + 9, ModBlocks.darkDreamBricks);
		setBlock(world, i + 6, j + 4, k + 1, ModBlocks.lightDreamBricks);
		setBlock(world, i + 6, j + 4, k + 9, ModBlocks.lightDreamBricks);
		setBlock(world, i + 6, j + 5, k + 1, ModBlocks.darkDreamBricks);
		setBlock(world, i + 6, j + 5, k + 9, ModBlocks.darkDreamBricks);
		setBlock(world, i + 6, j + 6, k + 2, ModBlocks.darkDreamBricks);
		setBlock(world, i + 6, j + 6, k + 8, ModBlocks.darkDreamBricks);
		setBlock(world, i + 6, j + 7, k + 3, ModBlocks.darkDreamBricks);
		setBlock(world, i + 6, j + 7, k + 7, ModBlocks.darkDreamBricks);
		setBlock(world, i + 6, j + 8, k + 4, ModBlocks.darkDreamBricks);
		setBlock(world, i + 6, j + 8, k + 6, ModBlocks.darkDreamBricks);
		setBlock(world, i + 6, j + 9, k + 4, ModBlocks.lightDreamBricks);
		setBlock(world, i + 6, j + 9, k + 6, ModBlocks.lightDreamBricks);
		setBlock(world, i + 6, j + 10, k + 4, ModBlocks.lightDreamBricks);
		setBlock(world, i + 6, j + 10, k + 6, ModBlocks.lightDreamBricks);
		setBlock(world, i + 6, j + 11, k + 4, ModBlocks.smoothGlass);
		setBlock(world, i + 6, j + 11, k + 6, ModBlocks.smoothGlass);
		setBlock(world, i + 6, j + 12, k + 4, ModBlocks.lightDreamBricks);
		setBlock(world, i + 6, j + 12, k + 6, ModBlocks.lightDreamBricks);
		setBlock(world, i + 6, j + 13, k + 4, ModBlocks.darkDreamBricks);
		setBlock(world, i + 6, j + 13, k + 5, ModBlocks.lunaStone);
		setBlock(world, i + 6, j + 13, k + 6, ModBlocks.darkDreamBricks);
		setBlock(world, i + 7, j + 0, k + 0, ModBlocks.darkDreamBricks);
		setBlock(world, i + 7, j + 0, k + 1, ModBlocks.smoothGlass);
		setBlock(world, i + 7, j + 0, k + 2, ModBlocks.smoothGlass);
		setBlock(world, i + 7, j + 0, k + 3, ModBlocks.smoothGlass);
		setBlock(world, i + 7, j + 0, k + 4, ModBlocks.smoothGlass);
		setBlock(world, i + 7, j + 0, k + 5, ModBlocks.smoothGlass);
		setBlock(world, i + 7, j + 0, k + 6, ModBlocks.smoothGlass);
		setBlock(world, i + 7, j + 0, k + 7, ModBlocks.smoothGlass);
		setBlock(world, i + 7, j + 0, k + 8, ModBlocks.smoothGlass);
		setBlock(world, i + 7, j + 0, k + 9, ModBlocks.smoothGlass);
		setBlock(world, i + 7, j + 0, k + 10, ModBlocks.darkDreamBricks);
		setBlock(world, i + 7, j + 1, k + 0, ModBlocks.lightDreamBricks);
		setBlock(world, i + 7, j + 1, k + 10, ModBlocks.lightDreamBricks);
		setBlock(world, i + 7, j + 2, k + 0, ModBlocks.darkDreamBricks);
		setBlock(world, i + 7, j + 2, k + 10, ModBlocks.darkDreamBricks);
		setBlock(world, i + 7, j + 3, k + 1, ModBlocks.darkDreamBricks);
		setBlock(world, i + 7, j + 3, k + 9, ModBlocks.darkDreamBricks);
		setBlock(world, i + 7, j + 4, k + 1, ModBlocks.lightDreamBricks);
		setBlock(world, i + 7, j + 4, k + 9, ModBlocks.lightDreamBricks);
		setBlock(world, i + 7, j + 5, k + 1, ModBlocks.darkDreamBricks);
		setBlock(world, i + 7, j + 5, k + 9, ModBlocks.darkDreamBricks);
		setBlock(world, i + 7, j + 6, k + 2, ModBlocks.darkDreamBricks);
		setBlock(world, i + 7, j + 6, k + 8, ModBlocks.darkDreamBricks);
		setBlock(world, i + 7, j + 7, k + 3, ModBlocks.darkDreamBricks);
		setBlock(world, i + 7, j + 7, k + 7, ModBlocks.darkDreamBricks);
		setBlock(world, i + 7, j + 8, k + 4, ModBlocks.darkDreamBricks);
		setBlock(world, i + 7, j + 8, k + 6, ModBlocks.darkDreamBricks);
		setBlock(world, i + 7, j + 9, k + 4, ModBlocks.lightDreamBricks);
		setBlock(world, i + 7, j + 9, k + 6, ModBlocks.lightDreamBricks);
		setBlock(world, i + 7, j + 10, k + 4, ModBlocks.lightDreamBricks);
		setBlock(world, i + 7, j + 10, k + 6, ModBlocks.lightDreamBricks);
		setBlock(world, i + 7, j + 11, k + 4, ModBlocks.smoothGlass);
		setBlock(world, i + 7, j + 11, k + 6, ModBlocks.smoothGlass);
		setBlock(world, i + 7, j + 12, k + 4, ModBlocks.lightDreamBricks);
		setBlock(world, i + 7, j + 12, k + 6, ModBlocks.lightDreamBricks);
		setBlock(world, i + 7, j + 13, k + 4, ModBlocks.darkDreamBricks);
		setBlock(world, i + 7, j + 13, k + 5, ModBlocks.lunaStone);
		setBlock(world, i + 7, j + 13, k + 6, ModBlocks.darkDreamBricks);
		setBlock(world, i + 8, j + 0, k + 0, ModBlocks.darkDreamBricks);
		setBlock(world, i + 8, j + 0, k + 1, ModBlocks.smoothGlass);
		setBlock(world, i + 8, j + 0, k + 2, ModBlocks.smoothGlass);
		setBlock(world, i + 8, j + 0, k + 3, ModBlocks.smoothGlass);
		setBlock(world, i + 8, j + 0, k + 4, ModBlocks.smoothGlass);
		setBlock(world, i + 8, j + 0, k + 5, ModBlocks.smoothGlass);
		setBlock(world, i + 8, j + 0, k + 6, ModBlocks.smoothGlass);
		setBlock(world, i + 8, j + 0, k + 7, ModBlocks.smoothGlass);
		setBlock(world, i + 8, j + 0, k + 8, ModBlocks.smoothGlass);
		setBlock(world, i + 8, j + 0, k + 9, ModBlocks.smoothGlass);
		setBlock(world, i + 8, j + 0, k + 10, ModBlocks.darkDreamBricks);
		setBlock(world, i + 8, j + 1, k + 0, ModBlocks.lightDreamBricks);
		setBlock(world, i + 8, j + 1, k + 10, ModBlocks.lightDreamBricks);
		setBlock(world, i + 8, j + 2, k + 0, ModBlocks.darkDreamBricks);
		setBlock(world, i + 8, j + 2, k + 10, ModBlocks.darkDreamBricks);
		setBlock(world, i + 8, j + 3, k + 1, ModBlocks.darkDreamBricks);
		setBlock(world, i + 8, j + 3, k + 9, ModBlocks.darkDreamBricks);
		setBlock(world, i + 8, j + 4, k + 1, ModBlocks.lightDreamBricks);
		setBlock(world, i + 8, j + 4, k + 9, ModBlocks.lightDreamBricks);
		setBlock(world, i + 8, j + 5, k + 1, ModBlocks.darkDreamBricks);
		setBlock(world, i + 8, j + 5, k + 9, ModBlocks.darkDreamBricks);
		setBlock(world, i + 8, j + 6, k + 2, ModBlocks.darkDreamBricks);
		setBlock(world, i + 8, j + 6, k + 8, ModBlocks.darkDreamBricks);
		setBlock(world, i + 8, j + 7, k + 3, ModBlocks.darkDreamBricks);
		setBlock(world, i + 8, j + 7, k + 7, ModBlocks.darkDreamBricks);
		setBlock(world, i + 8, j + 8, k + 4, ModBlocks.darkDreamBricks);
		setBlock(world, i + 8, j + 8, k + 6, ModBlocks.darkDreamBricks);
		setBlock(world, i + 8, j + 9, k + 4, ModBlocks.lightDreamBricks);
		setBlock(world, i + 8, j + 9, k + 6, ModBlocks.lightDreamBricks);
		setBlock(world, i + 8, j + 10, k + 4, ModBlocks.lightDreamBricks);
		setBlock(world, i + 8, j + 10, k + 6, ModBlocks.lightDreamBricks);
		setBlock(world, i + 8, j + 11, k + 4, ModBlocks.smoothGlass);
		setBlock(world, i + 8, j + 11, k + 6, ModBlocks.smoothGlass);
		setBlock(world, i + 8, j + 12, k + 4, ModBlocks.lightDreamBricks);
		setBlock(world, i + 8, j + 12, k + 6, ModBlocks.lightDreamBricks);
		setBlock(world, i + 8, j + 13, k + 4, ModBlocks.darkDreamBricks);
		setBlock(world, i + 8, j + 13, k + 5, ModBlocks.lunaStone);
		setBlock(world, i + 8, j + 13, k + 6, ModBlocks.darkDreamBricks);
		setBlock(world, i + 9, j + 0, k + 0, ModBlocks.darkDreamBricks);
		setBlock(world, i + 9, j + 0, k + 1, ModBlocks.smoothGlass);
		setBlock(world, i + 9, j + 0, k + 2, ModBlocks.smoothGlass);
		setBlock(world, i + 9, j + 0, k + 3, ModBlocks.smoothGlass);
		setBlock(world, i + 9, j + 0, k + 4, ModBlocks.smoothGlass);
		setBlock(world, i + 9, j + 0, k + 5, ModBlocks.smoothGlass);
		setBlock(world, i + 9, j + 0, k + 6, ModBlocks.smoothGlass);
		setBlock(world, i + 9, j + 0, k + 7, ModBlocks.smoothGlass);
		setBlock(world, i + 9, j + 0, k + 8, ModBlocks.smoothGlass);
		setBlock(world, i + 9, j + 0, k + 9, ModBlocks.smoothGlass);
		setBlock(world, i + 9, j + 0, k + 10, ModBlocks.darkDreamBricks);
		setBlock(world, i + 9, j + 1, k + 0, ModBlocks.lightDreamBricks);
		setBlock(world, i + 9, j + 1, k + 10, ModBlocks.lightDreamBricks);
		setBlock(world, i + 9, j + 2, k + 0, ModBlocks.darkDreamBricks);
		setBlock(world, i + 9, j + 2, k + 10, ModBlocks.darkDreamBricks);
		setBlock(world, i + 9, j + 3, k + 1, ModBlocks.darkDreamBricks);
		setBlock(world, i + 9, j + 3, k + 9, ModBlocks.darkDreamBricks);
		setBlock(world, i + 9, j + 4, k + 1, ModBlocks.lightDreamBricks);
		setBlock(world, i + 9, j + 4, k + 9, ModBlocks.lightDreamBricks);
		setBlock(world, i + 9, j + 5, k + 1, ModBlocks.darkDreamBricks);
		setBlock(world, i + 9, j + 5, k + 9, ModBlocks.darkDreamBricks);
		setBlock(world, i + 9, j + 6, k + 2, ModBlocks.darkDreamBricks);
		setBlock(world, i + 9, j + 6, k + 8, ModBlocks.darkDreamBricks);
		setBlock(world, i + 9, j + 7, k + 3, ModBlocks.darkDreamBricks);
		setBlock(world, i + 9, j + 7, k + 4, ModBlocks.lunaStone);
		setBlock(world, i + 9, j + 7, k + 5, ModBlocks.lunaStone);
		setBlock(world, i + 9, j + 7, k + 6, ModBlocks.lunaStone);
		setBlock(world, i + 9, j + 7, k + 7, ModBlocks.darkDreamBricks);
		setBlock(world, i + 9, j + 8, k + 4, ModBlocks.darkDreamBricks);
		setBlock(world, i + 9, j + 8, k + 5, ModBlocks.darkDreamBricks);
		setBlock(world, i + 9, j + 8, k + 6, ModBlocks.darkDreamBricks);
		setBlock(world, i + 9, j + 9, k + 4, ModBlocks.darkDreamBricks);
		setBlock(world, i + 9, j + 9, k + 5, ModBlocks.lightDreamBricks);
		setBlock(world, i + 9, j + 9, k + 6, ModBlocks.darkDreamBricks);
		setBlock(world, i + 9, j + 10, k + 4, ModBlocks.darkDreamBricks);
		setBlock(world, i + 9, j + 10, k + 5, ModBlocks.lightDreamBricks);
		setBlock(world, i + 9, j + 10, k + 6, ModBlocks.darkDreamBricks);
		setBlock(world, i + 9, j + 11, k + 4, ModBlocks.darkDreamBricks);
		setBlock(world, i + 9, j + 11, k + 5, ModBlocks.smoothGlass);
		setBlock(world, i + 9, j + 11, k + 6, ModBlocks.darkDreamBricks);
		setBlock(world, i + 9, j + 12, k + 4, ModBlocks.darkDreamBricks);
		setBlock(world, i + 9, j + 12, k + 5, ModBlocks.lightDreamBricks);
		setBlock(world, i + 9, j + 12, k + 6, ModBlocks.darkDreamBricks);
		setBlock(world, i + 9, j + 13, k + 4, ModBlocks.darkDreamBricks);
		setBlock(world, i + 9, j + 13, k + 5, ModBlocks.darkDreamBricks);
		setBlock(world, i + 9, j + 13, k + 6, ModBlocks.darkDreamBricks);
		setBlock(world, i + 10, j + 0, k + 0, ModBlocks.darkDreamBricks);
		setBlock(world, i + 10, j + 0, k + 1, ModBlocks.smoothGlass);
		setBlock(world, i + 10, j + 0, k + 2, ModBlocks.smoothGlass);
		setBlock(world, i + 10, j + 0, k + 3, ModBlocks.smoothGlass);
		setBlock(world, i + 10, j + 0, k + 4, ModBlocks.smoothGlass);
		setBlock(world, i + 10, j + 0, k + 5, ModBlocks.smoothGlass);
		setBlock(world, i + 10, j + 0, k + 6, ModBlocks.smoothGlass);
		setBlock(world, i + 10, j + 0, k + 7, ModBlocks.smoothGlass);
		setBlock(world, i + 10, j + 0, k + 8, ModBlocks.smoothGlass);
		setBlock(world, i + 10, j + 0, k + 9, ModBlocks.smoothGlass);
		setBlock(world, i + 10, j + 0, k + 10, ModBlocks.darkDreamBricks);
		setBlock(world, i + 10, j + 1, k + 0, ModBlocks.lightDreamBricks);
		setBlock(world, i + 10, j + 1, k + 10, ModBlocks.lightDreamBricks);
		setBlock(world, i + 10, j + 2, k + 0, ModBlocks.darkDreamBricks);
		setBlock(world, i + 10, j + 2, k + 10, ModBlocks.darkDreamBricks);
		setBlock(world, i + 10, j + 3, k + 1, ModBlocks.darkDreamBricks);
		setBlock(world, i + 10, j + 3, k + 9, ModBlocks.darkDreamBricks);
		setBlock(world, i + 10, j + 4, k + 1, ModBlocks.lightDreamBricks);
		setBlock(world, i + 10, j + 4, k + 9, ModBlocks.lightDreamBricks);
		setBlock(world, i + 10, j + 5, k + 1, ModBlocks.darkDreamBricks);
		setBlock(world, i + 10, j + 5, k + 9, ModBlocks.darkDreamBricks);
		setBlock(world, i + 10, j + 6, k + 2, ModBlocks.darkDreamBricks);
		setBlock(world, i + 10, j + 6, k + 8, ModBlocks.darkDreamBricks);
		setBlock(world, i + 10, j + 7, k + 3, ModBlocks.darkDreamBricks);
		setBlock(world, i + 10, j + 7, k + 4, ModBlocks.darkDreamBricks);
		setBlock(world, i + 10, j + 7, k + 5, ModBlocks.darkDreamBricks);
		setBlock(world, i + 10, j + 7, k + 6, ModBlocks.darkDreamBricks);
		setBlock(world, i + 10, j + 7, k + 7, ModBlocks.darkDreamBricks);
		setBlock(world, i + 11, j + 0, k + 0, ModBlocks.darkDreamBricks);
		setBlock(world, i + 11, j + 0, k + 1, ModBlocks.smoothGlass);
		setBlock(world, i + 11, j + 0, k + 2, ModBlocks.smoothGlass);
		setBlock(world, i + 11, j + 0, k + 3, ModBlocks.smoothGlass);
		setBlock(world, i + 11, j + 0, k + 4, ModBlocks.smoothGlass);
		setBlock(world, i + 11, j + 0, k + 5, ModBlocks.smoothGlass);
		setBlock(world, i + 11, j + 0, k + 6, ModBlocks.smoothGlass);
		setBlock(world, i + 11, j + 0, k + 7, ModBlocks.smoothGlass);
		setBlock(world, i + 11, j + 0, k + 8, ModBlocks.smoothGlass);
		setBlock(world, i + 11, j + 0, k + 9, ModBlocks.smoothGlass);
		setBlock(world, i + 11, j + 0, k + 10, ModBlocks.darkDreamBricks);
		setBlock(world, i + 11, j + 1, k + 0, ModBlocks.lightDreamBricks);
		setBlock(world, i + 11, j + 1, k + 10, ModBlocks.lightDreamBricks);
		setBlock(world, i + 11, j + 2, k + 0, ModBlocks.darkDreamBricks);
		setBlock(world, i + 11, j + 2, k + 10, ModBlocks.darkDreamBricks);
		setBlock(world, i + 11, j + 3, k + 1, ModBlocks.darkDreamBricks);
		setBlock(world, i + 11, j + 3, k + 9, ModBlocks.darkDreamBricks);
		setBlock(world, i + 11, j + 4, k + 1, ModBlocks.lightDreamBricks);
		setBlock(world, i + 11, j + 4, k + 9, ModBlocks.lightDreamBricks);
		setBlock(world, i + 11, j + 5, k + 1, ModBlocks.darkDreamBricks);
		setBlock(world, i + 11, j + 5, k + 9, ModBlocks.darkDreamBricks);
		setBlock(world, i + 11, j + 6, k + 2, ModBlocks.darkDreamBricks);
		setBlock(world, i + 11, j + 6, k + 3, ModBlocks.darkDreamBricks);
		setBlock(world, i + 11, j + 6, k + 4, ModBlocks.darkDreamBricks);
		setBlock(world, i + 11, j + 6, k + 5, ModBlocks.darkDreamBricks);
		setBlock(world, i + 11, j + 6, k + 6, ModBlocks.darkDreamBricks);
		setBlock(world, i + 11, j + 6, k + 7, ModBlocks.darkDreamBricks);
		setBlock(world, i + 11, j + 6, k + 8, ModBlocks.darkDreamBricks);
		setBlock(world, i + 12, j + 0, k + 0, ModBlocks.darkDreamBricks);
		setBlock(world, i + 12, j + 0, k + 1, ModBlocks.smoothGlass);
		setBlock(world, i + 12, j + 0, k + 2, ModBlocks.smoothGlass);
		setBlock(world, i + 12, j + 0, k + 3, ModBlocks.smoothGlass);
		setBlock(world, i + 12, j + 0, k + 4, ModBlocks.smoothGlass);
		setBlock(world, i + 12, j + 0, k + 5, ModBlocks.smoothGlass);
		setBlock(world, i + 12, j + 0, k + 6, ModBlocks.smoothGlass);
		setBlock(world, i + 12, j + 0, k + 7, ModBlocks.smoothGlass);
		setBlock(world, i + 12, j + 0, k + 8, ModBlocks.smoothGlass);
		setBlock(world, i + 12, j + 0, k + 9, ModBlocks.smoothGlass);
		setBlock(world, i + 12, j + 0, k + 10, ModBlocks.darkDreamBricks);
		setBlock(world, i + 12, j + 1, k + 0, ModBlocks.lightDreamBricks);
		setBlock(world, i + 12, j + 1, k + 1, ModBlocks.firelight);
		setBlock(world, i + 12, j + 1, k + 9, ModBlocks.firelight);
		setBlock(world, i + 12, j + 1, k + 10, ModBlocks.lightDreamBricks);
		setBlock(world, i + 12, j + 2, k + 0, ModBlocks.darkDreamBricks);
		setBlock(world, i + 12, j + 2, k + 10, ModBlocks.darkDreamBricks);
		setBlock(world, i + 12, j + 3, k + 1, ModBlocks.darkDreamBricks);
		setBlock(world, i + 12, j + 3, k + 2, ModBlocks.darkDreamBricks);
		setBlock(world, i + 12, j + 3, k + 3, ModBlocks.darkDreamBricks);
		setBlock(world, i + 12, j + 3, k + 4, ModBlocks.darkDreamBricks);
		setBlock(world, i + 12, j + 3, k + 5, ModBlocks.darkDreamBricks);
		setBlock(world, i + 12, j + 3, k + 6, ModBlocks.darkDreamBricks);
		setBlock(world, i + 12, j + 3, k + 7, ModBlocks.darkDreamBricks);
		setBlock(world, i + 12, j + 3, k + 8, ModBlocks.darkDreamBricks);
		setBlock(world, i + 12, j + 3, k + 9, ModBlocks.darkDreamBricks);
		setBlock(world, i + 12, j + 4, k + 1, ModBlocks.darkDreamBricks);
		setBlock(world, i + 12, j + 4, k + 2, ModBlocks.lightDreamBricks);
		setBlock(world, i + 12, j + 4, k + 3, ModBlocks.lightDreamBricks);
		setBlock(world, i + 12, j + 4, k + 4, ModBlocks.lightDreamBricks);
		setBlock(world, i + 12, j + 4, k + 5, ModBlocks.lightDreamBricks);
		setBlock(world, i + 12, j + 4, k + 6, ModBlocks.lightDreamBricks);
		setBlock(world, i + 12, j + 4, k + 7, ModBlocks.lightDreamBricks);
		setBlock(world, i + 12, j + 4, k + 8, ModBlocks.lightDreamBricks);
		setBlock(world, i + 12, j + 4, k + 9, ModBlocks.darkDreamBricks);
		setBlock(world, i + 12, j + 5, k + 1, ModBlocks.darkDreamBricks);
		setBlock(world, i + 12, j + 5, k + 2, ModBlocks.darkDreamBricks);
		setBlock(world, i + 12, j + 5, k + 3, ModBlocks.darkDreamBricks);
		setBlock(world, i + 12, j + 5, k + 4, ModBlocks.darkDreamBricks);
		setBlock(world, i + 12, j + 5, k + 5, ModBlocks.darkDreamBricks);
		setBlock(world, i + 12, j + 5, k + 6, ModBlocks.darkDreamBricks);
		setBlock(world, i + 12, j + 5, k + 7, ModBlocks.darkDreamBricks);
		setBlock(world, i + 12, j + 5, k + 8, ModBlocks.darkDreamBricks);
		setBlock(world, i + 12, j + 5, k + 9, ModBlocks.darkDreamBricks);
		setBlock(world, i + 13, j + 0, k + 0, ModBlocks.darkDreamBricks);
		setBlock(world, i + 13, j + 0, k + 1, ModBlocks.darkDreamBricks);
		setBlock(world, i + 13, j + 0, k + 2, ModBlocks.darkDreamBricks);
		setBlock(world, i + 13, j + 0, k + 3, ModBlocks.darkDreamBricks);
		setBlock(world, i + 13, j + 0, k + 4, ModBlocks.darkDreamBricks);
		setBlock(world, i + 13, j + 0, k + 5, ModBlocks.darkDreamBricks);
		setBlock(world, i + 13, j + 0, k + 6, ModBlocks.darkDreamBricks);
		setBlock(world, i + 13, j + 0, k + 7, ModBlocks.darkDreamBricks);
		setBlock(world, i + 13, j + 0, k + 8, ModBlocks.darkDreamBricks);
		setBlock(world, i + 13, j + 0, k + 9, ModBlocks.darkDreamBricks);
		setBlock(world, i + 13, j + 0, k + 10, ModBlocks.darkDreamBricks);
		setBlock(world, i + 13, j + 1, k + 0, ModBlocks.darkDreamBricks);
		setBlock(world, i + 13, j + 1, k + 1, ModBlocks.lightDreamBricks);
		setBlock(world, i + 13, j + 1, k + 2, ModBlocks.lightDreamBricks);
		setBlock(world, i + 13, j + 1, k + 3, ModBlocks.lightDreamBricks);
		setBlock(world, i + 13, j + 1, k + 4, ModBlocks.lightDreamBricks);
		setBlock(world, i + 13, j + 1, k + 5, ModBlocks.lightDreamBricks);
		setBlock(world, i + 13, j + 1, k + 6, ModBlocks.lightDreamBricks);
		setBlock(world, i + 13, j + 1, k + 7, ModBlocks.lightDreamBricks);
		setBlock(world, i + 13, j + 1, k + 8, ModBlocks.lightDreamBricks);
		setBlock(world, i + 13, j + 1, k + 9, ModBlocks.lightDreamBricks);
		setBlock(world, i + 13, j + 1, k + 10, ModBlocks.darkDreamBricks);
		setBlock(world, i + 13, j + 2, k + 0, ModBlocks.darkDreamBricks);
		setBlock(world, i + 13, j + 2, k + 1, ModBlocks.darkDreamBricks);
		setBlock(world, i + 13, j + 2, k + 2, ModBlocks.darkDreamBricks);
		setBlock(world, i + 13, j + 2, k + 3, ModBlocks.darkDreamBricks);
		setBlock(world, i + 13, j + 2, k + 4, ModBlocks.darkDreamBricks);
		setBlock(world, i + 13, j + 2, k + 5, ModBlocks.darkDreamBricks);
		setBlock(world, i + 13, j + 2, k + 6, ModBlocks.darkDreamBricks);
		setBlock(world, i + 13, j + 2, k + 7, ModBlocks.darkDreamBricks);
		setBlock(world, i + 13, j + 2, k + 8, ModBlocks.darkDreamBricks);
		setBlock(world, i + 13, j + 2, k + 9, ModBlocks.darkDreamBricks);
		setBlock(world, i + 13, j + 2, k + 10, ModBlocks.darkDreamBricks);

		return true;
	}
}