/*
*** MADE BY MITHION'S .SCHEMATIC TO JAVA CONVERTING TOOL v1.6 ***
*/

package divinerpg.dimensions.vethea.village;
import java.util.Random;

import divinerpg.dimensions.vethea.VetheaWorldGenerator;
import divinerpg.registry.ModBlocks;
import net.minecraft.world.World;
import net.minecraft.world.gen.feature.WorldGenerator;

public class HouseUp5 extends VetheaWorldGenerator
{
	protected int[] GetValidSpawnBlocks() {
		return new int[] {
		};
	}

	public HouseUp5() { }

	public boolean generate(World world, Random rand, int i, int j, int k) {

		setBlock(world, i + 0, j + 0, k + 0, ModBlocks.darkDreamBricks);
		setBlock(world, i + 0, j + 0, k + 1, ModBlocks.darkDreamBricks);
		setBlock(world, i + 0, j + 0, k + 5, ModBlocks.darkDreamBricks);
		setBlock(world, i + 0, j + 0, k + 15, ModBlocks.darkDreamBricks);
		setBlock(world, i + 0, j + 1, k + 1, ModBlocks.darkDreamBricks);
		setBlock(world, i + 0, j + 1, k + 2, ModBlocks.darkDreamBricks);
		setBlock(world, i + 0, j + 2, k + 1, ModBlocks.darkDreamBricks);
		setBlock(world, i + 0, j + 2, k + 2, ModBlocks.darkDreamBricks);
		setBlock(world, i + 0, j + 3, k + 0, ModBlocks.darkDreamBricks);
		setBlock(world, i + 0, j + 3, k + 5, ModBlocks.darkDreamBricks);
		setBlock(world, i + 0, j + 3, k + 15, ModBlocks.darkDreamBricks);
		setBlock(world, i + 1, j + 0, k + 1, ModBlocks.darkDreamBricks);
		setBlock(world, i + 1, j + 0, k + 2, ModBlocks.darkDreamBricks);
		setBlock(world, i + 1, j + 0, k + 5, ModBlocks.darkDreamBricks);
		setBlock(world, i + 1, j + 0, k + 15, ModBlocks.darkDreamBricks);
		setBlock(world, i + 1, j + 1, k + 2, ModBlocks.darkDreamBricks);
		setBlock(world, i + 1, j + 1, k + 3, ModBlocks.darkDreamBricks);
		setBlock(world, i + 1, j + 1, k + 6, ModBlocks.darkDreamBricks);
		setBlock(world, i + 1, j + 1, k + 7, ModBlocks.darkDreamBricks);
		setBlock(world, i + 1, j + 1, k + 8, ModBlocks.darkDreamBricks);
		setBlock(world, i + 1, j + 1, k + 9, ModBlocks.darkDreamBricks);
		setBlock(world, i + 1, j + 1, k + 10, ModBlocks.darkDreamBricks);
		setBlock(world, i + 1, j + 1, k + 11, ModBlocks.darkDreamBricks);
		setBlock(world, i + 1, j + 1, k + 12, ModBlocks.darkDreamBricks);
		setBlock(world, i + 1, j + 1, k + 13, ModBlocks.darkDreamBricks);
		setBlock(world, i + 1, j + 1, k + 14, ModBlocks.darkDreamBricks);
		setBlock(world, i + 1, j + 2, k + 2, ModBlocks.darkDreamBricks);
		setBlock(world, i + 1, j + 2, k + 3, ModBlocks.darkDreamBricks);
		setBlock(world, i + 1, j + 2, k + 6, ModBlocks.darkDreamBricks);
		setBlock(world, i + 1, j + 2, k + 7, ModBlocks.darkDreamBricks);
		setBlock(world, i + 1, j + 2, k + 8, ModBlocks.darkDreamBricks);
		setBlock(world, i + 1, j + 2, k + 9, ModBlocks.darkDreamBricks);
		setBlock(world, i + 1, j + 2, k + 10, ModBlocks.darkDreamBricks);
		setBlock(world, i + 1, j + 2, k + 11, ModBlocks.darkDreamBricks);
		setBlock(world, i + 1, j + 2, k + 12, ModBlocks.darkDreamBricks);
		setBlock(world, i + 1, j + 2, k + 13, ModBlocks.darkDreamBricks);
		setBlock(world, i + 1, j + 2, k + 14, ModBlocks.darkDreamBricks);
		setBlock(world, i + 1, j + 3, k + 0, ModBlocks.darkDreamBricks);
		setBlock(world, i + 1, j + 3, k + 1, ModBlocks.darkDreamBricks);
		setBlock(world, i + 1, j + 3, k + 5, ModBlocks.darkDreamBricks);
		setBlock(world, i + 1, j + 3, k + 15, ModBlocks.darkDreamBricks);
		setBlock(world, i + 2, j + 0, k + 2, ModBlocks.darkDreamBricks);
		setBlock(world, i + 2, j + 0, k + 3, ModBlocks.darkDreamBricks);
		setBlock(world, i + 2, j + 0, k + 5, ModBlocks.darkDreamBricks);
		setBlock(world, i + 2, j + 0, k + 6, ModBlocks.darkDreamBricks);
		setBlock(world, i + 2, j + 0, k + 7, ModBlocks.darkDreamBricks);
		setBlock(world, i + 2, j + 0, k + 8, ModBlocks.darkDreamBricks);
		setBlock(world, i + 2, j + 0, k + 9, ModBlocks.darkDreamBricks);
		setBlock(world, i + 2, j + 0, k + 10, ModBlocks.darkDreamBricks);
		setBlock(world, i + 2, j + 0, k + 11, ModBlocks.darkDreamBricks);
		setBlock(world, i + 2, j + 0, k + 12, ModBlocks.darkDreamBricks);
		setBlock(world, i + 2, j + 0, k + 13, ModBlocks.darkDreamBricks);
		setBlock(world, i + 2, j + 0, k + 14, ModBlocks.darkDreamBricks);
		setBlock(world, i + 2, j + 0, k + 15, ModBlocks.darkDreamBricks);
		setBlock(world, i + 2, j + 1, k + 3, ModBlocks.darkDreamBricks);
		setBlock(world, i + 2, j + 1, k + 4, ModBlocks.darkDreamBricks);
		setBlock(world, i + 2, j + 1, k + 5, ModBlocks.darkDreamBricks);
		setBlock(world, i + 2, j + 1, k + 6, ModBlocks.lunaStone);
		setBlock(world, i + 2, j + 1, k + 7, ModBlocks.lunaStone);
		setBlock(world, i + 2, j + 1, k + 8, ModBlocks.lunaStone);
		setBlock(world, i + 2, j + 1, k + 9, ModBlocks.lunaStone);
		setBlock(world, i + 2, j + 1, k + 10, ModBlocks.lunaStone);
		setBlock(world, i + 2, j + 1, k + 11, ModBlocks.lunaStone);
		setBlock(world, i + 2, j + 1, k + 12, ModBlocks.lunaStone);
		setBlock(world, i + 2, j + 1, k + 13, ModBlocks.lunaStone);
		setBlock(world, i + 2, j + 1, k + 14, ModBlocks.lunaStone);
		setBlock(world, i + 2, j + 1, k + 15, ModBlocks.darkDreamBricks);
		setBlock(world, i + 2, j + 2, k + 3, ModBlocks.darkDreamBricks);
		setBlock(world, i + 2, j + 2, k + 4, ModBlocks.darkDreamBricks);
		setBlock(world, i + 2, j + 2, k + 5, ModBlocks.darkDreamBricks);
		setBlock(world, i + 2, j + 2, k + 6, ModBlocks.lunaStone);
		setBlock(world, i + 2, j + 2, k + 7, ModBlocks.lunaStone);
		setBlock(world, i + 2, j + 2, k + 8, ModBlocks.lunaStone);
		setBlock(world, i + 2, j + 2, k + 9, ModBlocks.lunaStone);
		setBlock(world, i + 2, j + 2, k + 10, ModBlocks.lunaStone);
		setBlock(world, i + 2, j + 2, k + 11, ModBlocks.lunaStone);
		setBlock(world, i + 2, j + 2, k + 12, ModBlocks.lunaStone);
		setBlock(world, i + 2, j + 2, k + 13, ModBlocks.lunaStone);
		setBlock(world, i + 2, j + 2, k + 14, ModBlocks.lunaStone);
		setBlock(world, i + 2, j + 2, k + 15, ModBlocks.darkDreamBricks);
		setBlock(world, i + 2, j + 3, k + 1, ModBlocks.darkDreamBricks);
		setBlock(world, i + 2, j + 3, k + 2, ModBlocks.darkDreamBricks);
		setBlock(world, i + 2, j + 3, k + 5, ModBlocks.darkDreamBricks);
		setBlock(world, i + 2, j + 3, k + 6, ModBlocks.darkDreamBricks);
		setBlock(world, i + 2, j + 3, k + 7, ModBlocks.darkDreamBricks);
		setBlock(world, i + 2, j + 3, k + 8, ModBlocks.darkDreamBricks);
		setBlock(world, i + 2, j + 3, k + 9, ModBlocks.darkDreamBricks);
		setBlock(world, i + 2, j + 3, k + 10, ModBlocks.darkDreamBricks);
		setBlock(world, i + 2, j + 3, k + 11, ModBlocks.darkDreamBricks);
		setBlock(world, i + 2, j + 3, k + 12, ModBlocks.darkDreamBricks);
		setBlock(world, i + 2, j + 3, k + 13, ModBlocks.darkDreamBricks);
		setBlock(world, i + 2, j + 3, k + 14, ModBlocks.darkDreamBricks);
		setBlock(world, i + 2, j + 3, k + 15, ModBlocks.darkDreamBricks);
		setBlock(world, i + 3, j + 0, k + 3, ModBlocks.darkDreamBricks);
		setBlock(world, i + 3, j + 0, k + 4, ModBlocks.darkDreamBricks);
		setBlock(world, i + 3, j + 0, k + 5, ModBlocks.darkDreamBricks);
		setBlock(world, i + 3, j + 0, k + 6,  ModBlocks.smoothGlass);
		setBlock(world, i + 3, j + 0, k + 7,  ModBlocks.smoothGlass);
		setBlock(world, i + 3, j + 0, k + 8,  ModBlocks.smoothGlass);
		setBlock(world, i + 3, j + 0, k + 9,  ModBlocks.smoothGlass);
		setBlock(world, i + 3, j + 0, k + 10,  ModBlocks.smoothGlass);
		setBlock(world, i + 3, j + 0, k + 11,  ModBlocks.smoothGlass);
		setBlock(world, i + 3, j + 0, k + 12,  ModBlocks.smoothGlass);
		setBlock(world, i + 3, j + 0, k + 13,  ModBlocks.smoothGlass);
		setBlock(world, i + 3, j + 0, k + 14,  ModBlocks.smoothGlass);
		setBlock(world, i + 3, j + 0, k + 15, ModBlocks.darkDreamBricks);
		setBlock(world, i + 3, j + 1, k + 15, ModBlocks.darkDreamBricks);
		setBlock(world, i + 3, j + 2, k + 15, ModBlocks.darkDreamBricks);
		setBlock(world, i + 3, j + 3, k + 2, ModBlocks.darkDreamBricks);
		setBlock(world, i + 3, j + 3, k + 3, ModBlocks.darkDreamBricks);
		setBlock(world, i + 3, j + 3, k + 4, ModBlocks.darkDreamBricks);
		setBlock(world, i + 3, j + 3, k + 5, ModBlocks.darkDreamBricks);
		setBlock(world, i + 3, j + 3, k + 6,  ModBlocks.smoothGlass);
		setBlock(world, i + 3, j + 3, k + 7,  ModBlocks.smoothGlass);
		setBlock(world, i + 3, j + 3, k + 8,  ModBlocks.smoothGlass);
		setBlock(world, i + 3, j + 3, k + 9,  ModBlocks.smoothGlass);
		setBlock(world, i + 3, j + 3, k + 10,  ModBlocks.smoothGlass);
		setBlock(world, i + 3, j + 3, k + 11,  ModBlocks.smoothGlass);
		setBlock(world, i + 3, j + 3, k + 12,  ModBlocks.smoothGlass);
		setBlock(world, i + 3, j + 3, k + 13,  ModBlocks.smoothGlass);
		setBlock(world, i + 3, j + 3, k + 14,  ModBlocks.smoothGlass);
		setBlock(world, i + 3, j + 3, k + 15, ModBlocks.darkDreamBricks);
		setBlock(world, i + 4, j + 0, k + 5, ModBlocks.darkDreamBricks);
		setBlock(world, i + 4, j + 0, k + 6,  ModBlocks.smoothGlass);
		setBlock(world, i + 4, j + 0, k + 7,  ModBlocks.smoothGlass);
		setBlock(world, i + 4, j + 0, k + 8,  ModBlocks.smoothGlass);
		setBlock(world, i + 4, j + 0, k + 9,  ModBlocks.smoothGlass);
		setBlock(world, i + 4, j + 0, k + 10,  ModBlocks.smoothGlass);
		setBlock(world, i + 4, j + 0, k + 11,  ModBlocks.smoothGlass);
		setBlock(world, i + 4, j + 0, k + 12,  ModBlocks.smoothGlass);
		setBlock(world, i + 4, j + 0, k + 13,  ModBlocks.smoothGlass);
		setBlock(world, i + 4, j + 0, k + 14,  ModBlocks.smoothGlass);
		setBlock(world, i + 4, j + 0, k + 15, ModBlocks.darkDreamBricks);
		setBlock(world, i + 4, j + 1, k + 15,  ModBlocks.smoothGlass);
		setBlock(world, i + 4, j + 2, k + 15,  ModBlocks.smoothGlass);
		setBlock(world, i + 4, j + 3, k + 5, ModBlocks.darkDreamBricks);
		setBlock(world, i + 4, j + 3, k + 6,  ModBlocks.smoothGlass);
		setBlock(world, i + 4, j + 3, k + 7,  ModBlocks.smoothGlass);
		setBlock(world, i + 4, j + 3, k + 8,  ModBlocks.smoothGlass);
		setBlock(world, i + 4, j + 3, k + 9,  ModBlocks.smoothGlass);
		setBlock(world, i + 4, j + 3, k + 10,  ModBlocks.smoothGlass);
		setBlock(world, i + 4, j + 3, k + 11,  ModBlocks.smoothGlass);
		setBlock(world, i + 4, j + 3, k + 12,  ModBlocks.smoothGlass);
		setBlock(world, i + 4, j + 3, k + 13,  ModBlocks.smoothGlass);
		setBlock(world, i + 4, j + 3, k + 14,  ModBlocks.smoothGlass);
		setBlock(world, i + 4, j + 3, k + 15, ModBlocks.darkDreamBricks);
		setBlock(world, i + 5, j + 0, k + 5, ModBlocks.darkDreamBricks);
		setBlock(world, i + 5, j + 0, k + 6, ModBlocks.darkDreamBricks);
		setBlock(world, i + 5, j + 0, k + 7, ModBlocks.darkDreamBricks);
		setBlock(world, i + 5, j + 0, k + 8, ModBlocks.darkDreamBricks);
		setBlock(world, i + 5, j + 0, k + 9, ModBlocks.darkDreamBricks);
		setBlock(world, i + 5, j + 0, k + 10, ModBlocks.darkDreamBricks);
		setBlock(world, i + 5, j + 0, k + 11, ModBlocks.darkDreamBricks);
		setBlock(world, i + 5, j + 0, k + 12, ModBlocks.darkDreamBricks);
		setBlock(world, i + 5, j + 0, k + 13, ModBlocks.darkDreamBricks);
		setBlock(world, i + 5, j + 0, k + 14, ModBlocks.darkDreamBricks);
		setBlock(world, i + 5, j + 0, k + 15, ModBlocks.darkDreamBricks);
		setBlock(world, i + 5, j + 1, k + 5, ModBlocks.darkDreamBricks);
		setBlock(world, i + 5, j + 1, k + 15, ModBlocks.darkDreamBricks);
		setBlock(world, i + 5, j + 2, k + 5, ModBlocks.darkDreamBricks);
		setBlock(world, i + 5, j + 2, k + 6, ModBlocks.firelight);
		setBlock(world, i + 5, j + 2, k + 14, ModBlocks.firelight);
		setBlock(world, i + 5, j + 2, k + 15, ModBlocks.darkDreamBricks);
		setBlock(world, i + 5, j + 3, k + 5, ModBlocks.darkDreamBricks);
		setBlock(world, i + 5, j + 3, k + 6, ModBlocks.darkDreamBricks);
		setBlock(world, i + 5, j + 3, k + 7, ModBlocks.darkDreamBricks);
		setBlock(world, i + 5, j + 3, k + 8, ModBlocks.darkDreamBricks);
		setBlock(world, i + 5, j + 3, k + 9, ModBlocks.darkDreamBricks);
		setBlock(world, i + 5, j + 3, k + 10, ModBlocks.darkDreamBricks);
		setBlock(world, i + 5, j + 3, k + 11, ModBlocks.darkDreamBricks);
		setBlock(world, i + 5, j + 3, k + 12, ModBlocks.darkDreamBricks);
		setBlock(world, i + 5, j + 3, k + 13, ModBlocks.darkDreamBricks);
		setBlock(world, i + 5, j + 3, k + 14, ModBlocks.darkDreamBricks);
		setBlock(world, i + 5, j + 3, k + 15, ModBlocks.darkDreamBricks);
		setBlock(world, i + 6, j + 1, k + 5, ModBlocks.darkDreamBricks);
		setBlock(world, i + 6, j + 1, k + 6, ModBlocks.darkDreamBricks);
		setBlock(world, i + 6, j + 1, k + 7, ModBlocks.darkDreamBricks);
		setBlock(world, i + 6, j + 1, k + 8, ModBlocks.darkDreamBricks);
		setBlock(world, i + 6, j + 1, k + 9, ModBlocks.darkDreamBricks);
		setBlock(world, i + 6, j + 1, k + 10, ModBlocks.darkDreamBricks);
		setBlock(world, i + 6, j + 1, k + 11, ModBlocks.darkDreamBricks);
		setBlock(world, i + 6, j + 1, k + 12, ModBlocks.darkDreamBricks);
		setBlock(world, i + 6, j + 1, k + 13, ModBlocks.darkDreamBricks);
		setBlock(world, i + 6, j + 1, k + 14, ModBlocks.darkDreamBricks);
		setBlock(world, i + 6, j + 1, k + 15, ModBlocks.darkDreamBricks);
		setBlock(world, i + 6, j + 2, k + 5, ModBlocks.darkDreamBricks);
		setBlock(world, i + 6, j + 2, k + 6, ModBlocks.darkDreamBricks);
		setBlock(world, i + 6, j + 2, k + 7, ModBlocks.darkDreamBricks);
		setBlock(world, i + 6, j + 2, k + 8, ModBlocks.darkDreamBricks);
		setBlock(world, i + 6, j + 2, k + 9, ModBlocks.darkDreamBricks);
		setBlock(world, i + 6, j + 2, k + 10, ModBlocks.darkDreamBricks);
		setBlock(world, i + 6, j + 2, k + 11, ModBlocks.darkDreamBricks);
		setBlock(world, i + 6, j + 2, k + 12, ModBlocks.darkDreamBricks);
		setBlock(world, i + 6, j + 2, k + 13, ModBlocks.darkDreamBricks);
		setBlock(world, i + 6, j + 2, k + 14, ModBlocks.darkDreamBricks);
		setBlock(world, i + 6, j + 2, k + 15, ModBlocks.darkDreamBricks);

		return true;
	}
}