/*
*** MADE BY MITHION'S .SCHEMATIC TO JAVA CONVERTING TOOL v1.6 ***
*/

package divinerpg.dimensions.vethea.village;
import java.util.Random;

import divinerpg.dimensions.vethea.VetheaWorldGenerator;
import divinerpg.registry.ModBlocks;
import net.minecraft.world.World;
import net.minecraft.world.gen.feature.WorldGenerator;

public class HouseUp4 extends VetheaWorldGenerator
{
	protected int[] GetValidSpawnBlocks() {
		return new int[] {
		};
	}

	public HouseUp4() { }

	public boolean generate(World world, Random rand, int i, int j, int k) {

		setBlock(world, i + 0, j + 2, k + 0, ModBlocks.darkDreamBricks);
		setBlock(world, i + 0, j + 2, k + 1, ModBlocks.darkDreamBricks);
		setBlock(world, i + 0, j + 2, k + 2, ModBlocks.darkDreamBricks);
		setBlock(world, i + 0, j + 2, k + 3, ModBlocks.darkDreamBricks);
		setBlock(world, i + 0, j + 2, k + 4, ModBlocks.darkDreamBricks);
		setBlock(world, i + 0, j + 2, k + 5, ModBlocks.darkDreamBricks);
		setBlock(world, i + 0, j + 3, k + 0, ModBlocks.darkDreamBricks);
		setBlock(world, i + 0, j + 3, k + 1, ModBlocks.lightDreamBricks);
		setBlock(world, i + 0, j + 3, k + 2, ModBlocks.lightDreamBricks);
		setBlock(world, i + 0, j + 3, k + 3, ModBlocks.lightDreamBricks);
		setBlock(world, i + 0, j + 3, k + 4, ModBlocks.lightDreamBricks);
		setBlock(world, i + 0, j + 3, k + 5, ModBlocks.darkDreamBricks);
		setBlock(world, i + 0, j + 4, k + 0, ModBlocks.darkDreamBricks);
		setBlock(world, i + 0, j + 4, k + 1, ModBlocks.lightDreamBricks);
		setBlock(world, i + 0, j + 4, k + 2, ModBlocks.smoothGlass);
		setBlock(world, i + 0, j + 4, k + 3, ModBlocks.smoothGlass);
		setBlock(world, i + 0, j + 4, k + 4, ModBlocks.lightDreamBricks);
		setBlock(world, i + 0, j + 4, k + 5, ModBlocks.darkDreamBricks);
		setBlock(world, i + 0, j + 5, k + 0, ModBlocks.darkDreamBricks);
		setBlock(world, i + 0, j + 5, k + 1, ModBlocks.darkDreamBricks);
		setBlock(world, i + 0, j + 5, k + 2, ModBlocks.darkDreamBricks);
		setBlock(world, i + 0, j + 5, k + 3, ModBlocks.darkDreamBricks);
		setBlock(world, i + 0, j + 5, k + 4, ModBlocks.darkDreamBricks);
		setBlock(world, i + 0, j + 5, k + 5, ModBlocks.darkDreamBricks);
		setBlock(world, i + 1, j + 2, k + 0, ModBlocks.darkDreamBricks);
		setBlock(world, i + 1, j + 2, k + 1, ModBlocks.smoothGlass);
		setBlock(world, i + 1, j + 2, k + 2, ModBlocks.smoothGlass);
		setBlock(world, i + 1, j + 2, k + 3, ModBlocks.smoothGlass);
		setBlock(world, i + 1, j + 2, k + 4, ModBlocks.smoothGlass);
		setBlock(world, i + 1, j + 2, k + 5, ModBlocks.darkDreamBricks);
		setBlock(world, i + 1, j + 3, k + 0, ModBlocks.lightDreamBricks);
		setBlock(world, i + 1, j + 3, k + 5, ModBlocks.lightDreamBricks);
		setBlock(world, i + 1, j + 4, k + 0, ModBlocks.lightDreamBricks);
		setBlock(world, i + 1, j + 4, k + 5, ModBlocks.lightDreamBricks);
		setBlock(world, i + 1, j + 5, k + 0, ModBlocks.darkDreamBricks);
		setBlock(world, i + 1, j + 5, k + 1, ModBlocks.firelight);
		setBlock(world, i + 1, j + 5, k + 4, ModBlocks.firelight);
		setBlock(world, i + 1, j + 5, k + 5, ModBlocks.darkDreamBricks);
		setBlock(world, i + 1, j + 6, k + 0, ModBlocks.darkDreamBricks);
		setBlock(world, i + 1, j + 6, k + 1, ModBlocks.darkDreamBricks);
		setBlock(world, i + 1, j + 6, k + 2, ModBlocks.darkDreamBricks);
		setBlock(world, i + 1, j + 6, k + 3, ModBlocks.darkDreamBricks);
		setBlock(world, i + 1, j + 6, k + 4, ModBlocks.darkDreamBricks);
		setBlock(world, i + 1, j + 6, k + 5, ModBlocks.darkDreamBricks);
		setBlock(world, i + 2, j + 2, k + 0, ModBlocks.darkDreamBricks);
		setBlock(world, i + 2, j + 2, k + 1, ModBlocks.smoothGlass);
		setBlock(world, i + 2, j + 2, k + 2, ModBlocks.smoothGlass);
		setBlock(world, i + 2, j + 2, k + 3, ModBlocks.smoothGlass);
		setBlock(world, i + 2, j + 2, k + 4, ModBlocks.smoothGlass);
		setBlock(world, i + 2, j + 2, k + 5, ModBlocks.darkDreamBricks);
		setBlock(world, i + 2, j + 3, k + 0, ModBlocks.lightDreamBricks);
		setBlock(world, i + 2, j + 3, k + 5, ModBlocks.lightDreamBricks);
		setBlock(world, i + 2, j + 4, k + 0, ModBlocks.lightDreamBricks);
		setBlock(world, i + 2, j + 4, k + 5, ModBlocks.lightDreamBricks);
		setBlock(world, i + 2, j + 5, k + 0, ModBlocks.lightDreamBricks);
		setBlock(world, i + 2, j + 5, k + 5, ModBlocks.lightDreamBricks);
		setBlock(world, i + 2, j + 6, k + 0, ModBlocks.darkDreamBricks);
		setBlock(world, i + 2, j + 6, k + 5, ModBlocks.darkDreamBricks);
		setBlock(world, i + 2, j + 7, k + 0, ModBlocks.darkDreamBricks);
		setBlock(world, i + 2, j + 7, k + 1, ModBlocks.darkDreamBricks);
		setBlock(world, i + 2, j + 7, k + 2, ModBlocks.darkDreamBricks);
		setBlock(world, i + 2, j + 7, k + 3, ModBlocks.darkDreamBricks);
		setBlock(world, i + 2, j + 7, k + 4, ModBlocks.darkDreamBricks);
		setBlock(world, i + 2, j + 7, k + 5, ModBlocks.darkDreamBricks);
		setBlock(world, i + 3, j + 2, k + 0, ModBlocks.darkDreamBricks);
		setBlock(world, i + 3, j + 2, k + 1, ModBlocks.smoothGlass);
		setBlock(world, i + 3, j + 2, k + 2, ModBlocks.smoothGlass);
		setBlock(world, i + 3, j + 2, k + 3, ModBlocks.smoothGlass);
		setBlock(world, i + 3, j + 2, k + 4, ModBlocks.smoothGlass);
		setBlock(world, i + 3, j + 2, k + 5, ModBlocks.darkDreamBricks);
		setBlock(world, i + 3, j + 3, k + 0, ModBlocks.lightDreamBricks);
		setBlock(world, i + 3, j + 3, k + 2, ModBlocks.lightDreamBricks);
		setBlock(world, i + 3, j + 3, k + 3, ModBlocks.lightDreamBricks);
		setBlock(world, i + 3, j + 3, k + 5, ModBlocks.lightDreamBricks);
		setBlock(world, i + 3, j + 4, k + 0, ModBlocks.lightDreamBricks);
		setBlock(world, i + 3, j + 4, k + 5, ModBlocks.lightDreamBricks);
		setBlock(world, i + 3, j + 5, k + 0, ModBlocks.lightDreamBricks);
		setBlock(world, i + 3, j + 5, k + 5, ModBlocks.lightDreamBricks);
		setBlock(world, i + 3, j + 6, k + 0, ModBlocks.lightDreamBricks);
		setBlock(world, i + 3, j + 6, k + 5, ModBlocks.lightDreamBricks);
		setBlock(world, i + 3, j + 7, k + 0, ModBlocks.darkDreamBricks);
		setBlock(world, i + 3, j + 7, k + 1, ModBlocks.smoothGlass);
		setBlock(world, i + 3, j + 7, k + 2, ModBlocks.smoothGlass);
		setBlock(world, i + 3, j + 7, k + 3, ModBlocks.smoothGlass);
		setBlock(world, i + 3, j + 7, k + 4, ModBlocks.smoothGlass);
		setBlock(world, i + 3, j + 7, k + 5, ModBlocks.darkDreamBricks);
		setBlock(world, i + 4, j + 2, k + 0, ModBlocks.darkDreamBricks);
		setBlock(world, i + 4, j + 2, k + 1, ModBlocks.darkDreamBricks);
		setBlock(world, i + 4, j + 2, k + 2, ModBlocks.darkDreamBricks);
		setBlock(world, i + 4, j + 2, k + 3, ModBlocks.darkDreamBricks);
		setBlock(world, i + 4, j + 2, k + 4, ModBlocks.darkDreamBricks);
		setBlock(world, i + 4, j + 2, k + 5, ModBlocks.darkDreamBricks);
		setBlock(world, i + 4, j + 3, k + 0, ModBlocks.darkDreamBricks);
		setBlock(world, i + 4, j + 3, k + 1, ModBlocks.darkDreamBricks);
		setBlock(world, i + 4, j + 3, k + 2, ModBlocks.darkDreamBricks);
		setBlock(world, i + 4, j + 3, k + 3, ModBlocks.darkDreamBricks);
		setBlock(world, i + 4, j + 3, k + 4, ModBlocks.darkDreamBricks);
		setBlock(world, i + 4, j + 3, k + 5, ModBlocks.darkDreamBricks);
		setBlock(world, i + 4, j + 4, k + 0, ModBlocks.darkDreamBricks);
		setBlock(world, i + 4, j + 4, k + 1, ModBlocks.darkDreamBricks);
		setBlock(world, i + 4, j + 4, k + 2, ModBlocks.darkDreamBricks);
		setBlock(world, i + 4, j + 4, k + 3, ModBlocks.darkDreamBricks);
		setBlock(world, i + 4, j + 4, k + 4, ModBlocks.darkDreamBricks);
		setBlock(world, i + 4, j + 4, k + 5, ModBlocks.darkDreamBricks);
		setBlock(world, i + 4, j + 5, k + 0, ModBlocks.lightDreamBricks);
		setBlock(world, i + 4, j + 5, k + 5, ModBlocks.lightDreamBricks);
		setBlock(world, i + 4, j + 6, k + 0, ModBlocks.lightDreamBricks);
		setBlock(world, i + 4, j + 6, k + 5, ModBlocks.lightDreamBricks);
		setBlock(world, i + 4, j + 7, k + 0, ModBlocks.darkDreamBricks);
		setBlock(world, i + 4, j + 7, k + 1, ModBlocks.smoothGlass);
		setBlock(world, i + 4, j + 7, k + 2, ModBlocks.smoothGlass);
		setBlock(world, i + 4, j + 7, k + 3, ModBlocks.smoothGlass);
		setBlock(world, i + 4, j + 7, k + 4, ModBlocks.smoothGlass);
		setBlock(world, i + 4, j + 7, k + 5, ModBlocks.darkDreamBricks);
		setBlock(world, i + 5, j + 3, k + 1, ModBlocks.darkDreamBricks);
		setBlock(world, i + 5, j + 3, k + 2, ModBlocks.darkDreamBricks);
		setBlock(world, i + 5, j + 3, k + 3, ModBlocks.darkDreamBricks);
		setBlock(world, i + 5, j + 3, k + 4, ModBlocks.darkDreamBricks);
		setBlock(world, i + 5, j + 4, k + 0, ModBlocks.darkDreamBricks);
		setBlock(world, i + 5, j + 4, k + 1, ModBlocks.lunaStone);
		setBlock(world, i + 5, j + 4, k + 2, ModBlocks.lunaStone);
		setBlock(world, i + 5, j + 4, k + 3, ModBlocks.lunaStone);
		setBlock(world, i + 5, j + 4, k + 4, ModBlocks.lunaStone);
		setBlock(world, i + 5, j + 4, k + 5, ModBlocks.darkDreamBricks);
		setBlock(world, i + 5, j + 5, k + 0, ModBlocks.lightDreamBricks);
		setBlock(world, i + 5, j + 5, k + 5, ModBlocks.lightDreamBricks);
		setBlock(world, i + 5, j + 6, k + 0, ModBlocks.smoothGlass);
		setBlock(world, i + 5, j + 6, k + 5, ModBlocks.smoothGlass);
		setBlock(world, i + 5, j + 7, k + 0, ModBlocks.darkDreamBricks);
		setBlock(world, i + 5, j + 7, k + 1, ModBlocks.smoothGlass);
		setBlock(world, i + 5, j + 7, k + 2, ModBlocks.smoothGlass);
		setBlock(world, i + 5, j + 7, k + 3, ModBlocks.smoothGlass);
		setBlock(world, i + 5, j + 7, k + 4, ModBlocks.smoothGlass);
		setBlock(world, i + 5, j + 7, k + 5, ModBlocks.darkDreamBricks);
		setBlock(world, i + 6, j + 3, k + 1, ModBlocks.darkDreamBricks);
		setBlock(world, i + 6, j + 3, k + 2, ModBlocks.darkDreamBricks);
		setBlock(world, i + 6, j + 3, k + 3, ModBlocks.darkDreamBricks);
		setBlock(world, i + 6, j + 3, k + 4, ModBlocks.darkDreamBricks);
		setBlock(world, i + 6, j + 4, k + 0, ModBlocks.darkDreamBricks);
		setBlock(world, i + 6, j + 4, k + 1, ModBlocks.lunaStone);
		setBlock(world, i + 6, j + 4, k + 2, ModBlocks.lunaStone);
		setBlock(world, i + 6, j + 4, k + 3, ModBlocks.lunaStone);
		setBlock(world, i + 6, j + 4, k + 4, ModBlocks.lunaStone);
		setBlock(world, i + 6, j + 4, k + 5, ModBlocks.darkDreamBricks);
		setBlock(world, i + 6, j + 5, k + 0, ModBlocks.lightDreamBricks);
		setBlock(world, i + 6, j + 5, k + 5, ModBlocks.lightDreamBricks);
		setBlock(world, i + 6, j + 6, k + 0, ModBlocks.smoothGlass);
		setBlock(world, i + 6, j + 6, k + 5, ModBlocks.smoothGlass);
		setBlock(world, i + 6, j + 7, k + 0, ModBlocks.darkDreamBricks);
		setBlock(world, i + 6, j + 7, k + 1, ModBlocks.smoothGlass);
		setBlock(world, i + 6, j + 7, k + 2, ModBlocks.smoothGlass);
		setBlock(world, i + 6, j + 7, k + 3, ModBlocks.smoothGlass);
		setBlock(world, i + 6, j + 7, k + 4, ModBlocks.smoothGlass);
		setBlock(world, i + 6, j + 7, k + 5, ModBlocks.darkDreamBricks);
		setBlock(world, i + 7, j + 3, k + 1, ModBlocks.darkDreamBricks);
		setBlock(world, i + 7, j + 3, k + 2, ModBlocks.darkDreamBricks);
		setBlock(world, i + 7, j + 3, k + 3, ModBlocks.darkDreamBricks);
		setBlock(world, i + 7, j + 3, k + 4, ModBlocks.darkDreamBricks);
		setBlock(world, i + 7, j + 4, k + 0, ModBlocks.darkDreamBricks);
		setBlock(world, i + 7, j + 4, k + 1, ModBlocks.lunaStone);
		setBlock(world, i + 7, j + 4, k + 2, ModBlocks.lunaStone);
		setBlock(world, i + 7, j + 4, k + 3, ModBlocks.lunaStone);
		setBlock(world, i + 7, j + 4, k + 4, ModBlocks.lunaStone);
		setBlock(world, i + 7, j + 4, k + 5, ModBlocks.darkDreamBricks);
		setBlock(world, i + 7, j + 5, k + 0, ModBlocks.lightDreamBricks);
		setBlock(world, i + 7, j + 5, k + 5, ModBlocks.lightDreamBricks);
		setBlock(world, i + 7, j + 6, k + 0, ModBlocks.smoothGlass);
		setBlock(world, i + 7, j + 6, k + 5, ModBlocks.smoothGlass);
		setBlock(world, i + 7, j + 7, k + 0, ModBlocks.darkDreamBricks);
		setBlock(world, i + 7, j + 7, k + 1, ModBlocks.smoothGlass);
		setBlock(world, i + 7, j + 7, k + 2, ModBlocks.smoothGlass);
		setBlock(world, i + 7, j + 7, k + 3, ModBlocks.smoothGlass);
		setBlock(world, i + 7, j + 7, k + 4, ModBlocks.smoothGlass);
		setBlock(world, i + 7, j + 7, k + 5, ModBlocks.darkDreamBricks);
		setBlock(world, i + 8, j + 0, k + 0, ModBlocks.darkDreamBricks);
		setBlock(world, i + 8, j + 0, k + 1, ModBlocks.darkDreamBricks);
		setBlock(world, i + 8, j + 0, k + 2, ModBlocks.darkDreamBricks);
		setBlock(world, i + 8, j + 0, k + 3, ModBlocks.darkDreamBricks);
		setBlock(world, i + 8, j + 0, k + 4, ModBlocks.darkDreamBricks);
		setBlock(world, i + 8, j + 0, k + 5, ModBlocks.darkDreamBricks);
		setBlock(world, i + 8, j + 1, k + 0, ModBlocks.darkDreamBricks);
		setBlock(world, i + 8, j + 1, k + 1, ModBlocks.darkDreamBricks);
		setBlock(world, i + 8, j + 1, k + 2, ModBlocks.darkDreamBricks);
		setBlock(world, i + 8, j + 1, k + 3, ModBlocks.darkDreamBricks);
		setBlock(world, i + 8, j + 1, k + 4, ModBlocks.darkDreamBricks);
		setBlock(world, i + 8, j + 1, k + 5, ModBlocks.darkDreamBricks);
		setBlock(world, i + 8, j + 2, k + 0, ModBlocks.darkDreamBricks);
		setBlock(world, i + 8, j + 2, k + 1, ModBlocks.lightDreamBricks);
		setBlock(world, i + 8, j + 2, k + 2, ModBlocks.lightDreamBricks);
		setBlock(world, i + 8, j + 2, k + 3, ModBlocks.lightDreamBricks);
		setBlock(world, i + 8, j + 2, k + 4, ModBlocks.lightDreamBricks);
		setBlock(world, i + 8, j + 2, k + 5, ModBlocks.darkDreamBricks);
		setBlock(world, i + 8, j + 3, k + 0, ModBlocks.darkDreamBricks);
		setBlock(world, i + 8, j + 3, k + 1, ModBlocks.lightDreamBricks);
		setBlock(world, i + 8, j + 3, k + 2, ModBlocks.lightDreamBricks);
		setBlock(world, i + 8, j + 3, k + 3, ModBlocks.lightDreamBricks);
		setBlock(world, i + 8, j + 3, k + 4, ModBlocks.lightDreamBricks);
		setBlock(world, i + 8, j + 3, k + 5, ModBlocks.darkDreamBricks);
		setBlock(world, i + 8, j + 4, k + 0, ModBlocks.darkDreamBricks);
		setBlock(world, i + 8, j + 4, k + 1, ModBlocks.darkDreamBricks);
		setBlock(world, i + 8, j + 4, k + 2, ModBlocks.darkDreamBricks);
		setBlock(world, i + 8, j + 4, k + 3, ModBlocks.darkDreamBricks);
		setBlock(world, i + 8, j + 4, k + 4, ModBlocks.darkDreamBricks);
		setBlock(world, i + 8, j + 4, k + 5, ModBlocks.darkDreamBricks);
		setBlock(world, i + 8, j + 5, k + 0, ModBlocks.lightDreamBricks);
		setBlock(world, i + 8, j + 5, k + 5, ModBlocks.lightDreamBricks);
		setBlock(world, i + 8, j + 6, k + 0, ModBlocks.lightDreamBricks);
		setBlock(world, i + 8, j + 6, k + 5, ModBlocks.lightDreamBricks);
		setBlock(world, i + 8, j + 7, k + 0, ModBlocks.darkDreamBricks);
		setBlock(world, i + 8, j + 7, k + 1, ModBlocks.smoothGlass);
		setBlock(world, i + 8, j + 7, k + 2, ModBlocks.smoothGlass);
		setBlock(world, i + 8, j + 7, k + 3, ModBlocks.smoothGlass);
		setBlock(world, i + 8, j + 7, k + 4, ModBlocks.smoothGlass);
		setBlock(world, i + 8, j + 7, k + 5, ModBlocks.darkDreamBricks);
		setBlock(world, i + 9, j + 0, k + 0, ModBlocks.darkDreamBricks);
		setBlock(world, i + 9, j + 0, k + 1, ModBlocks.lunaStone);
		setBlock(world, i + 9, j + 0, k + 2, ModBlocks.lunaStone);
		setBlock(world, i + 9, j + 0, k + 3, ModBlocks.lunaStone);
		setBlock(world, i + 9, j + 0, k + 4, ModBlocks.lunaStone);
		setBlock(world, i + 9, j + 0, k + 5, ModBlocks.darkDreamBricks);
		setBlock(world, i + 9, j + 1, k + 0, ModBlocks.lightDreamBricks);
		setBlock(world, i + 9, j + 1, k + 3, ModBlocks.lightDreamBricks);
		setBlock(world, i + 9, j + 1, k + 4, ModBlocks.lightDreamBricks);
		setBlock(world, i + 9, j + 1, k + 5, ModBlocks.lightDreamBricks);
		setBlock(world, i + 9, j + 2, k + 0, ModBlocks.smoothGlass);
		setBlock(world, i + 9, j + 2, k + 3, ModBlocks.lightDreamBricks);
		setBlock(world, i + 9, j + 2, k + 4, ModBlocks.lightDreamBricks);
		setBlock(world, i + 9, j + 2, k + 5, ModBlocks.lightDreamBricks);
		setBlock(world, i + 9, j + 3, k + 0, ModBlocks.lightDreamBricks);
		setBlock(world, i + 9, j + 3, k + 3, ModBlocks.lightDreamBricks);
		setBlock(world, i + 9, j + 3, k + 4, ModBlocks.lightDreamBricks);
		setBlock(world, i + 9, j + 3, k + 5, ModBlocks.lightDreamBricks);
		setBlock(world, i + 9, j + 4, k + 0, ModBlocks.darkDreamBricks);
		setBlock(world, i + 9, j + 4, k + 5, ModBlocks.darkDreamBricks);
		setBlock(world, i + 9, j + 5, k + 0, ModBlocks.lightDreamBricks);
		setBlock(world, i + 9, j + 5, k + 5, ModBlocks.lightDreamBricks);
		setBlock(world, i + 9, j + 6, k + 0, ModBlocks.lightDreamBricks);
		setBlock(world, i + 9, j + 6, k + 5, ModBlocks.lightDreamBricks);
		setBlock(world, i + 9, j + 7, k + 0, ModBlocks.darkDreamBricks);
		setBlock(world, i + 9, j + 7, k + 1, ModBlocks.smoothGlass);
		setBlock(world, i + 9, j + 7, k + 2, ModBlocks.smoothGlass);
		setBlock(world, i + 9, j + 7, k + 3, ModBlocks.smoothGlass);
		setBlock(world, i + 9, j + 7, k + 4, ModBlocks.smoothGlass);
		setBlock(world, i + 9, j + 7, k + 5, ModBlocks.darkDreamBricks);
		setBlock(world, i + 10, j + 0, k + 0, ModBlocks.darkDreamBricks);
		setBlock(world, i + 10, j + 0, k + 1, ModBlocks.lunaStone);
		setBlock(world, i + 10, j + 0, k + 2, ModBlocks.lunaStone);
		setBlock(world, i + 10, j + 0, k + 3, ModBlocks.lunaStone);
		setBlock(world, i + 10, j + 0, k + 4, ModBlocks.lunaStone);
		setBlock(world, i + 10, j + 0, k + 5, ModBlocks.darkDreamBricks);
		setBlock(world, i + 10, j + 1, k + 0, ModBlocks.lightDreamBricks);
		setBlock(world, i + 10, j + 1, k + 3, ModBlocks.lightDreamBricks);
		setBlock(world, i + 10, j + 1, k + 4, ModBlocks.lightDreamBricks);
		setBlock(world, i + 10, j + 1, k + 5, ModBlocks.lightDreamBricks);
		setBlock(world, i + 10, j + 2, k + 0, ModBlocks.lightDreamBricks);
		setBlock(world, i + 10, j + 2, k + 3, ModBlocks.lightDreamBricks);
		setBlock(world, i + 10, j + 2, k + 4, ModBlocks.lightDreamBricks);
		setBlock(world, i + 10, j + 2, k + 5, ModBlocks.lightDreamBricks);
		setBlock(world, i + 10, j + 3, k + 0, ModBlocks.lightDreamBricks);
		setBlock(world, i + 10, j + 3, k + 5, ModBlocks.lightDreamBricks);
		setBlock(world, i + 10, j + 4, k + 0, ModBlocks.darkDreamBricks);
		setBlock(world, i + 10, j + 4, k + 5, ModBlocks.darkDreamBricks);
		setBlock(world, i + 10, j + 5, k + 0, ModBlocks.lightDreamBricks);
		setBlock(world, i + 10, j + 5, k + 5, ModBlocks.lightDreamBricks);
		setBlock(world, i + 10, j + 6, k + 0, ModBlocks.darkDreamBricks);
		setBlock(world, i + 10, j + 6, k + 1, ModBlocks.firelight);
		setBlock(world, i + 10, j + 6, k + 5, ModBlocks.darkDreamBricks);
		setBlock(world, i + 10, j + 7, k + 0, ModBlocks.darkDreamBricks);
		setBlock(world, i + 10, j + 7, k + 1, ModBlocks.darkDreamBricks);
		setBlock(world, i + 10, j + 7, k + 2, ModBlocks.darkDreamBricks);
		setBlock(world, i + 10, j + 7, k + 3, ModBlocks.darkDreamBricks);
		setBlock(world, i + 10, j + 7, k + 4, ModBlocks.darkDreamBricks);
		setBlock(world, i + 10, j + 7, k + 5, ModBlocks.darkDreamBricks);
		setBlock(world, i + 11, j + 0, k + 0, ModBlocks.darkDreamBricks);
		setBlock(world, i + 11, j + 0, k + 1, ModBlocks.lunaStone);
		setBlock(world, i + 11, j + 0, k + 2, ModBlocks.lunaStone);
		setBlock(world, i + 11, j + 0, k + 3, ModBlocks.lunaStone);
		setBlock(world, i + 11, j + 0, k + 4, ModBlocks.lunaStone);
		setBlock(world, i + 11, j + 0, k + 5, ModBlocks.darkDreamBricks);
		setBlock(world, i + 11, j + 1, k + 3, ModBlocks.lightDreamBricks);
		setBlock(world, i + 11, j + 1, k + 4, ModBlocks.lightDreamBricks);
		setBlock(world, i + 11, j + 1, k + 5, ModBlocks.lightDreamBricks);
		setBlock(world, i + 11, j + 2, k + 5, ModBlocks.lightDreamBricks);
		setBlock(world, i + 11, j + 3, k + 0, ModBlocks.lightDreamBricks);
		setBlock(world, i + 11, j + 3, k + 5, ModBlocks.lightDreamBricks);
		setBlock(world, i + 11, j + 4, k + 0, ModBlocks.darkDreamBricks);
		setBlock(world, i + 11, j + 4, k + 5, ModBlocks.darkDreamBricks);
		setBlock(world, i + 11, j + 5, k + 0, ModBlocks.darkDreamBricks);
		setBlock(world, i + 11, j + 5, k + 5, ModBlocks.darkDreamBricks);
		setBlock(world, i + 11, j + 6, k + 0, ModBlocks.darkDreamBricks);
		setBlock(world, i + 11, j + 6, k + 1, ModBlocks.darkDreamBricks);
		setBlock(world, i + 11, j + 6, k + 2, ModBlocks.darkDreamBricks);
		setBlock(world, i + 11, j + 6, k + 3, ModBlocks.darkDreamBricks);
		setBlock(world, i + 11, j + 6, k + 4, ModBlocks.darkDreamBricks);
		setBlock(world, i + 11, j + 6, k + 5, ModBlocks.darkDreamBricks);
		setBlock(world, i + 12, j + 0, k + 0, ModBlocks.darkDreamBricks);
		setBlock(world, i + 12, j + 0, k + 1, ModBlocks.lunaStone);
		setBlock(world, i + 12, j + 0, k + 2, ModBlocks.lunaStone);
		setBlock(world, i + 12, j + 0, k + 3, ModBlocks.lunaStone);
		setBlock(world, i + 12, j + 0, k + 4, ModBlocks.lunaStone);
		setBlock(world, i + 12, j + 0, k + 5, ModBlocks.darkDreamBricks);
		setBlock(world, i + 12, j + 1, k + 0, ModBlocks.lightDreamBricks);
		setBlock(world, i + 12, j + 1, k + 5, ModBlocks.lightDreamBricks);
		setBlock(world, i + 12, j + 2, k + 0, ModBlocks.lightDreamBricks);
		setBlock(world, i + 12, j + 2, k + 5, ModBlocks.lightDreamBricks);
		setBlock(world, i + 12, j + 3, k + 0, ModBlocks.lightDreamBricks);
		setBlock(world, i + 12, j + 3, k + 5, ModBlocks.lightDreamBricks);
		setBlock(world, i + 12, j + 4, k + 0, ModBlocks.darkDreamBricks);
		setBlock(world, i + 12, j + 4, k + 5, ModBlocks.darkDreamBricks);
		setBlock(world, i + 12, j + 5, k + 0, ModBlocks.darkDreamBricks);
		setBlock(world, i + 12, j + 5, k + 1, ModBlocks.darkDreamBricks);
		setBlock(world, i + 12, j + 5, k + 2, ModBlocks.darkDreamBricks);
		setBlock(world, i + 12, j + 5, k + 3, ModBlocks.darkDreamBricks);
		setBlock(world, i + 12, j + 5, k + 4, ModBlocks.darkDreamBricks);
		setBlock(world, i + 12, j + 5, k + 5, ModBlocks.darkDreamBricks);
		setBlock(world, i + 13, j + 0, k + 0, ModBlocks.darkDreamBricks);
		setBlock(world, i + 13, j + 0, k + 1, ModBlocks.darkDreamBricks);
		setBlock(world, i + 13, j + 0, k + 2, ModBlocks.darkDreamBricks);
		setBlock(world, i + 13, j + 0, k + 3, ModBlocks.darkDreamBricks);
		setBlock(world, i + 13, j + 0, k + 4, ModBlocks.darkDreamBricks);
		setBlock(world, i + 13, j + 0, k + 5, ModBlocks.darkDreamBricks);
		setBlock(world, i + 13, j + 1, k + 0, ModBlocks.darkDreamBricks);
		setBlock(world, i + 13, j + 1, k + 1, ModBlocks.lightDreamBricks);
		setBlock(world, i + 13, j + 1, k + 2, ModBlocks.lightDreamBricks);
		setBlock(world, i + 13, j + 1, k + 3, ModBlocks.lightDreamBricks);
		setBlock(world, i + 13, j + 1, k + 4, ModBlocks.lightDreamBricks);
		setBlock(world, i + 13, j + 1, k + 5, ModBlocks.darkDreamBricks);
		setBlock(world, i + 13, j + 2, k + 0, ModBlocks.darkDreamBricks);
		setBlock(world, i + 13, j + 2, k + 1, ModBlocks.lightDreamBricks);
		setBlock(world, i + 13, j + 2, k + 2, ModBlocks.smoothGlass);
		setBlock(world, i + 13, j + 2, k + 3, ModBlocks.smoothGlass);
		setBlock(world, i + 13, j + 2, k + 4, ModBlocks.lightDreamBricks);
		setBlock(world, i + 13, j + 2, k + 5, ModBlocks.darkDreamBricks);
		setBlock(world, i + 13, j + 3, k + 0, ModBlocks.darkDreamBricks);
		setBlock(world, i + 13, j + 3, k + 1, ModBlocks.lightDreamBricks);
		setBlock(world, i + 13, j + 3, k + 2, ModBlocks.lightDreamBricks);
		setBlock(world, i + 13, j + 3, k + 3, ModBlocks.lightDreamBricks);
		setBlock(world, i + 13, j + 3, k + 4, ModBlocks.lightDreamBricks);
		setBlock(world, i + 13, j + 3, k + 5, ModBlocks.darkDreamBricks);
		setBlock(world, i + 13, j + 4, k + 0, ModBlocks.darkDreamBricks);
		setBlock(world, i + 13, j + 4, k + 1, ModBlocks.darkDreamBricks);
		setBlock(world, i + 13, j + 4, k + 2, ModBlocks.darkDreamBricks);
		setBlock(world, i + 13, j + 4, k + 3, ModBlocks.darkDreamBricks);
		setBlock(world, i + 13, j + 4, k + 4, ModBlocks.darkDreamBricks);
		setBlock(world, i + 13, j + 4, k + 5, ModBlocks.darkDreamBricks);

		return true;
	}
}