package divinerpg.dimensions.vethea.layer3;
import java.util.Random;

import divinerpg.dimensions.vethea.VetheaWorldGenerator;
import divinerpg.registry.ModBlocks;
import net.minecraft.init.Blocks;
import net.minecraft.world.World;

public class KarosMadhouse extends VetheaWorldGenerator {

	public boolean generate(World world, Random rand, int i, int j, int k) {

		for(int x = 0; x < 31; x++) {
			for(int y = 0; y < 6; y++) {
				for(int z = 0; z < 20; z++) {
					setBlock(world, i+x, j+y, k+z, Blocks.AIR);
				}
			}
		}
		setBlock(world, i + 0, j + 0, k + 2, ModBlocks.blackKarosBricks);
		setBlock(world, i + 0, j + 0, k + 3, ModBlocks.blackKarosBricks);
		setBlock(world, i + 0, j + 0, k + 4, ModBlocks.blackKarosBricks);
		setBlock(world, i + 0, j + 0, k + 5, ModBlocks.blackKarosBricks);
		setBlock(world, i + 0, j + 0, k + 6, ModBlocks.blackKarosBricks);
		setBlock(world, i + 0, j + 0, k + 7, ModBlocks.blackKarosBricks);
		setBlock(world, i + 0, j + 0, k + 8, ModBlocks.blackKarosBricks);
		setBlock(world, i + 0, j + 0, k + 9, ModBlocks.blackKarosBricks);
		setBlock(world, i + 0, j + 0, k + 10, ModBlocks.blackKarosBricks);
		setBlock(world, i + 0, j + 0, k + 11, ModBlocks.blackKarosBricks);
		setBlock(world, i + 0, j + 1, k + 3, ModBlocks.blackKarosBricks);
		setBlock(world, i + 0, j + 1, k + 4, ModBlocks.blackKarosBricks);
		setBlock(world, i + 0, j + 1, k + 5, ModBlocks.blackKarosBricks);
		setBlock(world, i + 0, j + 1, k + 6, ModBlocks.blackKarosBricks);
		setBlock(world, i + 0, j + 1, k + 7, ModBlocks.blackKarosBricks);
		setBlock(world, i + 0, j + 1, k + 8, ModBlocks.blackKarosBricks);
		setBlock(world, i + 0, j + 1, k + 9, ModBlocks.blackKarosBricks);
		setBlock(world, i + 0, j + 1, k + 10, ModBlocks.blackKarosBricks);
		setBlock(world, i + 0, j + 1, k + 11, ModBlocks.blackKarosBricks);
		setBlock(world, i + 0, j + 2, k + 4, ModBlocks.blackKarosBricks);
		setBlock(world, i + 0, j + 2, k + 5, ModBlocks.blueKarosBricks);
		setBlock(world, i + 0, j + 2, k + 6, ModBlocks.blueKarosBricks);
		setBlock(world, i + 0, j + 2, k + 7, ModBlocks.blueKarosBricks);
		setBlock(world, i + 0, j + 2, k + 8, ModBlocks.blueKarosBricks);
		setBlock(world, i + 0, j + 2, k + 9, ModBlocks.blueKarosBricks);
		setBlock(world, i + 0, j + 2, k + 10, ModBlocks.blueKarosBricks);
		setBlock(world, i + 0, j + 2, k + 11, ModBlocks.blueKarosBricks);
		setBlock(world, i + 1, j + 0, k + 4, ModBlocks.blackKarosBricks);
		setBlock(world, i + 1, j + 0, k + 5, ModBlocks.karosHeatTileRed);
		setBlock(world, i + 1, j + 0, k + 6, ModBlocks.karosHeatTileGreen);
		setBlock(world, i + 1, j + 0, k + 7, ModBlocks.karosHeatTileRed);
		setBlock(world, i + 1, j + 0, k + 8, ModBlocks.karosHeatTileGreen);
		setBlock(world, i + 1, j + 0, k + 9, ModBlocks.karosHeatTileRed);
		setBlock(world, i + 1, j + 0, k + 10, ModBlocks.karosHeatTileGreen);
		setBlock(world, i + 1, j + 0, k + 11, ModBlocks.blackKarosBricks);
		setBlock(world, i + 1, j + 1, k + 11, ModBlocks.blackKarosBricks);
		setBlock(world, i + 1, j + 2, k + 11, ModBlocks.blueKarosBricks);
		setBlock(world, i + 1, j + 3, k + 5, ModBlocks.blackKarosBricks);
		setBlock(world, i + 1, j + 3, k + 6, ModBlocks.blackKarosBricks);
		setBlock(world, i + 1, j + 3, k + 7, ModBlocks.blackKarosBricks);
		setBlock(world, i + 1, j + 3, k + 8, ModBlocks.blackKarosBricks);
		setBlock(world, i + 1, j + 3, k + 9, ModBlocks.blackKarosBricks);
		setBlock(world, i + 1, j + 3, k + 10, ModBlocks.blackKarosBricks);
		setBlock(world, i + 2, j + 0, k + 4, ModBlocks.blackKarosBricks);
		setBlock(world, i + 2, j + 0, k + 5, ModBlocks.karosHeatTileGreen);
		setBlock(world, i + 2, j + 0, k + 6, ModBlocks.karosHeatTileRed);
		setBlock(world, i + 2, j + 0, k + 7, ModBlocks.karosHeatTileGreen);
		setBlock(world, i + 2, j + 0, k + 8, ModBlocks.karosHeatTileRed);
		setBlock(world, i + 2, j + 0, k + 9, ModBlocks.karosHeatTileGreen);
		setBlock(world, i + 2, j + 0, k + 10, ModBlocks.karosHeatTileRed);
		setBlock(world, i + 2, j + 0, k + 11, ModBlocks.blackKarosBricks);
		setBlock(world, i + 2, j + 1, k + 11, ModBlocks.blackKarosBricks);
		setBlock(world, i + 2, j + 2, k + 11, ModBlocks.blueKarosBricks);
		setBlock(world, i + 2, j + 3, k + 5, ModBlocks.blackKarosBricks);
		setBlock(world, i + 2, j + 3, k + 6, ModBlocks.blackKarosBricks);
		setBlock(world, i + 2, j + 3, k + 7, ModBlocks.blackKarosBricks);
		setBlock(world, i + 2, j + 3, k + 8, ModBlocks.blackKarosBricks);
		setBlock(world, i + 2, j + 3, k + 9, ModBlocks.blackKarosBricks);
		setBlock(world, i + 2, j + 3, k + 10, ModBlocks.blackKarosBricks);
		setBlock(world, i + 3, j + 0, k + 2, ModBlocks.blackKarosBricks);
		setBlock(world, i + 3, j + 0, k + 3, ModBlocks.blackKarosBricks);
		setBlock(world, i + 3, j + 0, k + 4, ModBlocks.blackKarosBricks);
		setBlock(world, i + 3, j + 0, k + 5, ModBlocks.blackKarosBricks);
		setBlock(world, i + 3, j + 0, k + 6, ModBlocks.blackKarosBricks);
		setBlock(world, i + 3, j + 0, k + 7, ModBlocks.blackKarosBricks);
		setBlock(world, i + 3, j + 0, k + 8, ModBlocks.blackKarosBricks);
		setBlock(world, i + 3, j + 0, k + 9, ModBlocks.karosHeatTileRed);
		setBlock(world, i + 3, j + 0, k + 10, ModBlocks.karosHeatTileGreen);
		setBlock(world, i + 3, j + 0, k + 11, ModBlocks.blackKarosBricks);
		setBlock(world, i + 3, j + 1, k + 3, ModBlocks.blackKarosBricks);
		setBlock(world, i + 3, j + 1, k + 4, ModBlocks.blackKarosBricks);
		setBlock(world, i + 3, j + 1, k + 5, ModBlocks.blackKarosBricks);
		setBlock(world, i + 3, j + 1, k + 6, ModBlocks.blackKarosBricks);
		setBlock(world, i + 3, j + 1, k + 7, ModBlocks.blackKarosBricks);
		setBlock(world, i + 3, j + 1, k + 8, ModBlocks.blackKarosBricks);
		setBlock(world, i + 3, j + 1, k + 11, ModBlocks.blackKarosBricks);
		setBlock(world, i + 3, j + 2, k + 4, ModBlocks.blackKarosBricks);
		setBlock(world, i + 3, j + 2, k + 5, ModBlocks.blueKarosBricks);
		setBlock(world, i + 3, j + 2, k + 6, ModBlocks.blueKarosBricks);
		setBlock(world, i + 3, j + 2, k + 7, ModBlocks.blueKarosBricks);
		setBlock(world, i + 3, j + 2, k + 8, ModBlocks.blueKarosBricks);
		setBlock(world, i + 3, j + 2, k + 11, ModBlocks.blueKarosBricks);
		setBlock(world, i + 3, j + 3, k + 9, ModBlocks.blackKarosBricks);
		setBlock(world, i + 3, j + 3, k + 10, ModBlocks.blackKarosBricks);
		setBlock(world, i + 4, j + 0, k + 8, ModBlocks.blackKarosBricks);
		setBlock(world, i + 4, j + 0, k + 9, ModBlocks.karosHeatTileGreen);
		setBlock(world, i + 4, j + 0, k + 10, ModBlocks.karosHeatTileRed);
		setBlock(world, i + 4, j + 0, k + 11, ModBlocks.blackKarosBricks);
		setBlock(world, i + 4, j + 1, k + 8, ModBlocks.blackKarosBricks);
		setBlock(world, i + 4, j + 1, k + 11, ModBlocks.blackKarosBricks);
		setBlock(world, i + 4, j + 2, k + 8, ModBlocks.blueKarosBricks);
		setBlock(world, i + 4, j + 2, k + 11, ModBlocks.blueKarosBricks);
		setBlock(world, i + 4, j + 3, k + 9, ModBlocks.blackKarosBricks);
		setBlock(world, i + 4, j + 3, k + 10, ModBlocks.blackKarosBricks);
		setBlock(world, i + 5, j + 0, k + 8, ModBlocks.blackKarosBricks);
		setBlock(world, i + 5, j + 0, k + 9, ModBlocks.karosHeatTileRed);
		setBlock(world, i + 5, j + 0, k + 10, ModBlocks.karosHeatTileGreen);
		setBlock(world, i + 5, j + 0, k + 11, ModBlocks.blackKarosBricks);
		setBlock(world, i + 5, j + 1, k + 8, ModBlocks.blackKarosBricks);
		setBlock(world, i + 5, j + 1, k + 11, ModBlocks.blackKarosBricks);
		setBlock(world, i + 5, j + 2, k + 8, ModBlocks.blueKarosBricks);
		setBlock(world, i + 5, j + 2, k + 11, ModBlocks.blueKarosBricks);
		setBlock(world, i + 5, j + 3, k + 9, ModBlocks.blackKarosBricks);
		setBlock(world, i + 5, j + 3, k + 10, ModBlocks.blackKarosBricks);
		setBlock(world, i + 6, j + 0, k + 8, ModBlocks.blackKarosBricks);
		setBlock(world, i + 6, j + 0, k + 9, ModBlocks.karosHeatTileGreen);
		setBlock(world, i + 6, j + 0, k + 10, ModBlocks.karosHeatTileRed);
		setBlock(world, i + 6, j + 0, k + 11, ModBlocks.blackKarosBricks);
		setBlock(world, i + 6, j + 1, k + 8, ModBlocks.blackKarosBricks);
		setBlock(world, i + 6, j + 1, k + 11, ModBlocks.blackKarosBricks);
		setBlock(world, i + 6, j + 2, k + 8, ModBlocks.blueKarosBricks);
		setBlock(world, i + 6, j + 2, k + 11, ModBlocks.blueKarosBricks);
		setBlock(world, i + 6, j + 3, k + 9, ModBlocks.blackKarosBricks);
		setBlock(world, i + 6, j + 3, k + 10, ModBlocks.blackKarosBricks);
		setBlock(world, i + 7, j + 0, k + 8, ModBlocks.blackKarosBricks);
		setBlock(world, i + 7, j + 0, k + 9, ModBlocks.karosHeatTileRed);
		setBlock(world, i + 7, j + 0, k + 10, ModBlocks.karosHeatTileGreen);
		setBlock(world, i + 7, j + 0, k + 11, ModBlocks.blackKarosBricks);
		setBlock(world, i + 7, j + 1, k + 8, ModBlocks.blackKarosBricks);
		setBlock(world, i + 7, j + 1, k + 11, ModBlocks.blackKarosBricks);
		setBlock(world, i + 7, j + 2, k + 8, ModBlocks.blueKarosBricks);
		setBlock(world, i + 7, j + 2, k + 11, ModBlocks.blueKarosBricks);
		setBlock(world, i + 7, j + 3, k + 9, ModBlocks.blackKarosBricks);
		setBlock(world, i + 7, j + 3, k + 10, ModBlocks.blackKarosBricks);
		setBlock(world, i + 8, j + 0, k + 8, ModBlocks.blackKarosBricks);
		setBlock(world, i + 8, j + 0, k + 9, ModBlocks.karosHeatTileGreen);
		setBlock(world, i + 8, j + 0, k + 10, ModBlocks.karosHeatTileRed);
		setBlock(world, i + 8, j + 0, k + 11, ModBlocks.blackKarosBricks);
		setBlock(world, i + 8, j + 1, k + 8, ModBlocks.blackKarosBricks);
		setBlock(world, i + 8, j + 1, k + 11, ModBlocks.blackKarosBricks);
		setBlock(world, i + 8, j + 2, k + 8, ModBlocks.blueKarosBricks);
		setBlock(world, i + 8, j + 2, k + 11, ModBlocks.blueKarosBricks);
		setBlock(world, i + 8, j + 3, k + 8, ModBlocks.blueKarosBricks);
		setBlock(world, i + 8, j + 3, k + 9, ModBlocks.blackKarosBricks);
		setBlock(world, i + 8, j + 3, k + 10, ModBlocks.blackKarosBricks);
		setBlock(world, i + 8, j + 3, k + 11, ModBlocks.blueKarosBricks);
		setBlock(world, i + 8, j + 4, k + 8, ModBlocks.blueKarosBricks);
		setBlock(world, i + 8, j + 4, k + 11, ModBlocks.blueKarosBricks);
		setBlock(world, i + 9, j + 0, k + 3, ModBlocks.blackKarosBricks);
		setBlock(world, i + 9, j + 0, k + 5, ModBlocks.blackKarosBricks);
		setBlock(world, i + 9, j + 0, k + 7, ModBlocks.blackKarosBricks);
		setBlock(world, i + 9, j + 0, k + 8, ModBlocks.blackKarosBricks);
		setBlock(world, i + 9, j + 0, k + 9, ModBlocks.karosHeatTileRed);
		setBlock(world, i + 9, j + 0, k + 10, ModBlocks.karosHeatTileGreen);
		setBlock(world, i + 9, j + 0, k + 11, ModBlocks.blackKarosBricks);
		setBlock(world, i + 9, j + 0, k + 12, ModBlocks.blackKarosBricks);
		setBlock(world, i + 9, j + 0, k + 14, ModBlocks.blackKarosBricks);
		setBlock(world, i + 9, j + 0, k + 16, ModBlocks.blackKarosBricks);
		setBlock(world, i + 9, j + 1, k + 3, ModBlocks.blackKarosBricks);
		setBlock(world, i + 9, j + 1, k + 5, ModBlocks.blackKarosBricks);
		setBlock(world, i + 9, j + 1, k + 7, ModBlocks.blackKarosBricks);
		setBlock(world, i + 9, j + 1, k + 8, ModBlocks.blackKarosBricks);
		setBlock(world, i + 9, j + 1, k + 11, ModBlocks.blackKarosBricks);
		setBlock(world, i + 9, j + 1, k + 12, ModBlocks.blackKarosBricks);
		setBlock(world, i + 9, j + 1, k + 14, ModBlocks.blackKarosBricks);
		setBlock(world, i + 9, j + 1, k + 16, ModBlocks.blackKarosBricks);
		setBlock(world, i + 9, j + 2, k + 3, ModBlocks.blackKarosBricks);
		setBlock(world, i + 9, j + 2, k + 5, ModBlocks.blackKarosBricks);
		setBlock(world, i + 9, j + 2, k + 7, ModBlocks.blackKarosBricks);
		setBlock(world, i + 9, j + 2, k + 8, ModBlocks.blackKarosBricks);
		setBlock(world, i + 9, j + 2, k + 11, ModBlocks.blackKarosBricks);
		setBlock(world, i + 9, j + 2, k + 12, ModBlocks.blackKarosBricks);
		setBlock(world, i + 9, j + 2, k + 14, ModBlocks.blackKarosBricks);
		setBlock(world, i + 9, j + 2, k + 16, ModBlocks.blackKarosBricks);
		setBlock(world, i + 9, j + 3, k + 8, ModBlocks.blackKarosBricks);
		setBlock(world, i + 9, j + 3, k + 9, ModBlocks.blackKarosBricks);
		setBlock(world, i + 9, j + 3, k + 10, ModBlocks.blackKarosBricks);
		setBlock(world, i + 9, j + 3, k + 11, ModBlocks.blackKarosBricks);
		setBlock(world, i + 9, j + 4, k + 8, ModBlocks.blueKarosBricks);
		setBlock(world, i + 9, j + 4, k + 11, ModBlocks.blueKarosBricks);
		setBlock(world, i + 10, j + 0, k + 1, ModBlocks.blackKarosBricks);
		setBlock(world, i + 10, j + 0, k + 2, ModBlocks.blackKarosBricks);
		setBlock(world, i + 10, j + 0, k + 3, ModBlocks.blackKarosBricks);
		setBlock(world, i + 10, j + 0, k + 4, ModBlocks.blackKarosBricks);
		setBlock(world, i + 10, j + 0, k + 5, ModBlocks.blackKarosBricks);
		setBlock(world, i + 10, j + 0, k + 6, ModBlocks.blackKarosBricks);
		setBlock(world, i + 10, j + 0, k + 7, ModBlocks.blackKarosBricks);
		setBlock(world, i + 10, j + 0, k + 8, ModBlocks.blackKarosBricks);
		setBlock(world, i + 10, j + 0, k + 9, ModBlocks.karosHeatTileGreen);
		setBlock(world, i + 10, j + 0, k + 10, ModBlocks.karosHeatTileRed);
		setBlock(world, i + 10, j + 0, k + 11, ModBlocks.blackKarosBricks);
		setBlock(world, i + 10, j + 0, k + 12, ModBlocks.blackKarosBricks);
		setBlock(world, i + 10, j + 0, k + 13, ModBlocks.blackKarosBricks);
		setBlock(world, i + 10, j + 0, k + 14, ModBlocks.blackKarosBricks);
		setBlock(world, i + 10, j + 0, k + 15, ModBlocks.blackKarosBricks);
		setBlock(world, i + 10, j + 0, k + 16, ModBlocks.blackKarosBricks);
		setBlock(world, i + 10, j + 0, k + 17, ModBlocks.blackKarosBricks);
		setBlock(world, i + 10, j + 0, k + 18, ModBlocks.blackKarosBricks);
		setBlock(world, i + 10, j + 1, k + 1, ModBlocks.blackKarosBricks);
		setBlock(world, i + 10, j + 1, k + 2, ModBlocks.blackKarosBricks);
		setBlock(world, i + 10, j + 1, k + 3, ModBlocks.blackKarosBricks);
		setBlock(world, i + 10, j + 1, k + 4, ModBlocks.blackKarosBricks);
		setBlock(world, i + 10, j + 1, k + 5, ModBlocks.blackKarosBricks);
		setBlock(world, i + 10, j + 1, k + 6, ModBlocks.blackKarosBricks);
		setBlock(world, i + 10, j + 1, k + 7, ModBlocks.blackKarosBricks);
		setBlock(world, i + 10, j + 1, k + 8, ModBlocks.blackKarosBricks);
		setBlock(world, i + 10, j + 1, k + 11, ModBlocks.blackKarosBricks);
		setBlock(world, i + 10, j + 1, k + 12, ModBlocks.blackKarosBricks);
		setBlock(world, i + 10, j + 1, k + 13, ModBlocks.blackKarosBricks);
		setBlock(world, i + 10, j + 1, k + 14, ModBlocks.blackKarosBricks);
		setBlock(world, i + 10, j + 1, k + 15, ModBlocks.blackKarosBricks);
		setBlock(world, i + 10, j + 1, k + 16, ModBlocks.blackKarosBricks);
		setBlock(world, i + 10, j + 1, k + 17, ModBlocks.blackKarosBricks);
		setBlock(world, i + 10, j + 1, k + 18, ModBlocks.blackKarosBricks);
		setBlock(world, i + 10, j + 2, k + 1, ModBlocks.blueKarosBricks);
		setBlock(world, i + 10, j + 2, k + 2, ModBlocks.blueKarosBricks);
		setBlock(world, i + 10, j + 2, k + 3, ModBlocks.karosDispenser);
		setBlock(world, i + 10, j + 2, k + 4, ModBlocks.blueKarosBricks);
		setBlock(world, i + 10, j + 2, k + 5, ModBlocks.karosDispenser);
		setBlock(world, i + 10, j + 2, k + 6, ModBlocks.blueKarosBricks);
		setBlock(world, i + 10, j + 2, k + 7, ModBlocks.karosDispenser);
		setBlock(world, i + 10, j + 2, k + 8, ModBlocks.blackKarosBricks);
		setBlock(world, i + 10, j + 2, k + 11, ModBlocks.blackKarosBricks);
		setBlock(world, i + 10, j + 2, k + 12, ModBlocks.karosDispenser);
		setBlock(world, i + 10, j + 2, k + 13, ModBlocks.blueKarosBricks);
		setBlock(world, i + 10, j + 2, k + 14, ModBlocks.karosDispenser);
		setBlock(world, i + 10, j + 2, k + 15, ModBlocks.blueKarosBricks);
		setBlock(world, i + 10, j + 2, k + 16, ModBlocks.karosDispenser);
		setBlock(world, i + 10, j + 2, k + 17, ModBlocks.blueKarosBricks);
		setBlock(world, i + 10, j + 2, k + 18, ModBlocks.blueKarosBricks);
		setBlock(world, i + 10, j + 3, k + 1, ModBlocks.blueKarosBricks);
		setBlock(world, i + 10, j + 3, k + 2, ModBlocks.blueKarosBricks);
		setBlock(world, i + 10, j + 3, k + 3, ModBlocks.blueKarosBricks);
		setBlock(world, i + 10, j + 3, k + 4, ModBlocks.blueKarosBricks);
		setBlock(world, i + 10, j + 3, k + 5, ModBlocks.blueKarosBricks);
		setBlock(world, i + 10, j + 3, k + 6, ModBlocks.blueKarosBricks);
		setBlock(world, i + 10, j + 3, k + 7, ModBlocks.blueKarosBricks);
		setBlock(world, i + 10, j + 3, k + 8, ModBlocks.blackKarosBricks);
		setBlock(world, i + 10, j + 3, k + 9, ModBlocks.blackKarosBricks);
		setBlock(world, i + 10, j + 3, k + 10, ModBlocks.blackKarosBricks);
		setBlock(world, i + 10, j + 3, k + 11, ModBlocks.blackKarosBricks);
		setBlock(world, i + 10, j + 3, k + 12, ModBlocks.blueKarosBricks);
		setBlock(world, i + 10, j + 3, k + 13, ModBlocks.blueKarosBricks);
		setBlock(world, i + 10, j + 3, k + 14, ModBlocks.blueKarosBricks);
		setBlock(world, i + 10, j + 3, k + 15, ModBlocks.blueKarosBricks);
		setBlock(world, i + 10, j + 3, k + 16, ModBlocks.blueKarosBricks);
		setBlock(world, i + 10, j + 3, k + 17, ModBlocks.blueKarosBricks);
		setBlock(world, i + 10, j + 3, k + 18, ModBlocks.blueKarosBricks);
		setBlock(world, i + 10, j + 4, k + 8, ModBlocks.blueKarosBricks);
		setBlock(world, i + 10, j + 4, k + 11, ModBlocks.blueKarosBricks);
		setBlock(world, i + 11, j + 0, k + 1, ModBlocks.blackKarosBricks);
		setBlock(world, i + 11, j + 0, k + 2, ModBlocks.karosHeatTileGreen);
		setBlock(world, i + 11, j + 0, k + 3, ModBlocks.karosHeatTileGreen);
		setBlock(world, i + 11, j + 0, k + 4, ModBlocks.karosHeatTileRed);
		setBlock(world, i + 11, j + 0, k + 5, ModBlocks.karosHeatTileRed);
		setBlock(world, i + 11, j + 0, k + 6, ModBlocks.karosHeatTileGreen);
		setBlock(world, i + 11, j + 0, k + 7, ModBlocks.karosHeatTileGreen);
		setBlock(world, i + 11, j + 0, k + 8, ModBlocks.karosHeatTileRed);
		setBlock(world, i + 11, j + 0, k + 9, ModBlocks.karosHeatTileRed);
		setBlock(world, i + 11, j + 0, k + 10, ModBlocks.karosHeatTileGreen);
		setBlock(world, i + 11, j + 0, k + 11, ModBlocks.karosHeatTileGreen);
		setBlock(world, i + 11, j + 0, k + 12, ModBlocks.karosHeatTileRed);
		setBlock(world, i + 11, j + 0, k + 13, ModBlocks.karosHeatTileRed);
		setBlock(world, i + 11, j + 0, k + 14, ModBlocks.karosHeatTileGreen);
		setBlock(world, i + 11, j + 0, k + 15, ModBlocks.karosHeatTileGreen);
		setBlock(world, i + 11, j + 0, k + 16, ModBlocks.karosHeatTileRed);
		setBlock(world, i + 11, j + 0, k + 17, ModBlocks.karosHeatTileRed);
		setBlock(world, i + 11, j + 0, k + 18, ModBlocks.blackKarosBricks);
		setBlock(world, i + 11, j + 1, k + 1, ModBlocks.blackKarosBricks);
		setBlock(world, i + 11, j + 1, k + 18, ModBlocks.blackKarosBricks);
		setBlock(world, i + 11, j + 2, k + 1, ModBlocks.blueKarosBricks);
		setBlock(world, i + 11, j + 2, k + 18, ModBlocks.blueKarosBricks);
		setBlock(world, i + 11, j + 3, k + 1, ModBlocks.blueKarosBricks);
		setBlock(world, i + 11, j + 3, k + 18, ModBlocks.blueKarosBricks);
		setBlock(world, i + 11, j + 4, k + 2, ModBlocks.blueKarosBricks);
		setBlock(world, i + 11, j + 4, k + 3, ModBlocks.blueKarosBricks);
		setBlock(world, i + 11, j + 4, k + 4, ModBlocks.blueKarosBricks);
		setBlock(world, i + 11, j + 4, k + 5, ModBlocks.blueKarosBricks);
		setBlock(world, i + 11, j + 4, k + 6, ModBlocks.blueKarosBricks);
		setBlock(world, i + 11, j + 4, k + 7, ModBlocks.blueKarosBricks);
		setBlock(world, i + 11, j + 4, k + 8, ModBlocks.blueKarosBricks);
		setBlock(world, i + 11, j + 4, k + 9, ModBlocks.blueKarosBricks);
		setBlock(world, i + 11, j + 4, k + 10, ModBlocks.blueKarosBricks);
		setBlock(world, i + 11, j + 4, k + 11, ModBlocks.blueKarosBricks);
		setBlock(world, i + 11, j + 4, k + 12, ModBlocks.blueKarosBricks);
		setBlock(world, i + 11, j + 4, k + 13, ModBlocks.blueKarosBricks);
		setBlock(world, i + 11, j + 4, k + 14, ModBlocks.blueKarosBricks);
		setBlock(world, i + 11, j + 4, k + 15, ModBlocks.blueKarosBricks);
		setBlock(world, i + 11, j + 4, k + 16, ModBlocks.blueKarosBricks);
		setBlock(world, i + 11, j + 4, k + 17, ModBlocks.blueKarosBricks);
		setBlock(world, i + 12, j + 0, k + 0, ModBlocks.blackKarosBricks);
		setBlock(world, i + 12, j + 0, k + 1, ModBlocks.blackKarosBricks);
		setBlock(world, i + 12, j + 0, k + 2, ModBlocks.karosHeatTileGreen);
		setBlock(world, i + 12, j + 0, k + 3, ModBlocks.karosHeatTileGreen);
		setBlock(world, i + 12, j + 0, k + 4, ModBlocks.karosHeatTileRed);
		setBlock(world, i + 12, j + 0, k + 5, ModBlocks.karosHeatTileRed);
		setBlock(world, i + 12, j + 0, k + 6, ModBlocks.karosHeatTileGreen);
		setBlock(world, i + 12, j + 0, k + 7, ModBlocks.karosHeatTileGreen);
		setBlock(world, i + 12, j + 0, k + 8, ModBlocks.karosHeatTileRed);
		setBlock(world, i + 12, j + 0, k + 9, ModBlocks.karosHeatTileRed);
		setBlock(world, i + 12, j + 0, k + 10, ModBlocks.karosHeatTileGreen);
		setBlock(world, i + 12, j + 0, k + 11, ModBlocks.karosHeatTileGreen);
		setBlock(world, i + 12, j + 0, k + 12, ModBlocks.karosHeatTileRed);
		setBlock(world, i + 12, j + 0, k + 13, ModBlocks.karosHeatTileRed);
		setBlock(world, i + 12, j + 0, k + 14, ModBlocks.karosHeatTileGreen);
		setBlock(world, i + 12, j + 0, k + 15, ModBlocks.karosHeatTileGreen);
		setBlock(world, i + 12, j + 0, k + 16, ModBlocks.karosHeatTileRed);
		setBlock(world, i + 12, j + 0, k + 17, ModBlocks.karosHeatTileRed);
		setBlock(world, i + 12, j + 0, k + 18, ModBlocks.blackKarosBricks);
		setBlock(world, i + 12, j + 0, k + 19, ModBlocks.blackKarosBricks);
		setBlock(world, i + 12, j + 1, k + 0, ModBlocks.blackKarosBricks);
		setBlock(world, i + 12, j + 1, k + 1, ModBlocks.blackKarosBricks);
		setBlock(world, i + 12, j + 1, k + 18, ModBlocks.blackKarosBricks);
		setBlock(world, i + 12, j + 1, k + 19, ModBlocks.blackKarosBricks);
		setBlock(world, i + 12, j + 2, k + 0, ModBlocks.blackKarosBricks);
		setBlock(world, i + 12, j + 2, k + 1, ModBlocks.karosDispenser);
		setBlock(world, i + 12, j + 2, k + 18, ModBlocks.karosDispenser);
		setBlock(world, i + 12, j + 2, k + 19, ModBlocks.blackKarosBricks);
		setBlock(world, i + 12, j + 3, k + 1, ModBlocks.blueKarosBricks);
		setBlock(world, i + 12, j + 3, k + 18, ModBlocks.blueKarosBricks);
		setBlock(world, i + 12, j + 4, k + 2, ModBlocks.blueKarosBricks);
		setBlock(world, i + 12, j + 4, k + 17, ModBlocks.blueKarosBricks);
		setBlock(world, i + 12, j + 5, k + 3, ModBlocks.blueKarosBricks);
		setBlock(world, i + 12, j + 5, k + 4, ModBlocks.blueKarosBricks);
		setBlock(world, i + 12, j + 5, k + 5, ModBlocks.blueKarosBricks);
		setBlock(world, i + 12, j + 5, k + 6, ModBlocks.blueKarosBricks);
		setBlock(world, i + 12, j + 5, k + 7, ModBlocks.blueKarosBricks);
		setBlock(world, i + 12, j + 5, k + 8, ModBlocks.blueKarosBricks);
		setBlock(world, i + 12, j + 5, k + 9, ModBlocks.blueKarosBricks);
		setBlock(world, i + 12, j + 5, k + 10, ModBlocks.blueKarosBricks);
		setBlock(world, i + 12, j + 5, k + 11, ModBlocks.blueKarosBricks);
		setBlock(world, i + 12, j + 5, k + 12, ModBlocks.blueKarosBricks);
		setBlock(world, i + 12, j + 5, k + 13, ModBlocks.blueKarosBricks);
		setBlock(world, i + 12, j + 5, k + 14, ModBlocks.blueKarosBricks);
		setBlock(world, i + 12, j + 5, k + 15, ModBlocks.blueKarosBricks);
		setBlock(world, i + 12, j + 5, k + 16, ModBlocks.blueKarosBricks);
		setBlock(world, i + 13, j + 0, k + 1, ModBlocks.blackKarosBricks);
		setBlock(world, i + 13, j + 0, k + 2, ModBlocks.karosHeatTileRed);
		setBlock(world, i + 13, j + 0, k + 3, ModBlocks.karosHeatTileRed);
		setBlock(world, i + 13, j + 0, k + 4, ModBlocks.karosHeatTileGreen);
		setBlock(world, i + 13, j + 0, k + 5, ModBlocks.karosHeatTileGreen);
		setBlock(world, i + 13, j + 0, k + 6, ModBlocks.karosHeatTileRed);
		setBlock(world, i + 13, j + 0, k + 7, ModBlocks.karosHeatTileRed);
		setBlock(world, i + 13, j + 0, k + 8, ModBlocks.karosHeatTileGreen);
		setBlock(world, i + 13, j + 0, k + 9, ModBlocks.karosHeatTileGreen);
		setBlock(world, i + 13, j + 0, k + 10, ModBlocks.karosHeatTileRed);
		setBlock(world, i + 13, j + 0, k + 11, ModBlocks.karosHeatTileRed);
		setBlock(world, i + 13, j + 0, k + 12, ModBlocks.karosHeatTileGreen);
		setBlock(world, i + 13, j + 0, k + 13, ModBlocks.karosHeatTileGreen);
		setBlock(world, i + 13, j + 0, k + 14, ModBlocks.karosHeatTileRed);
		setBlock(world, i + 13, j + 0, k + 15, ModBlocks.karosHeatTileRed);
		setBlock(world, i + 13, j + 0, k + 16, ModBlocks.karosHeatTileGreen);
		setBlock(world, i + 13, j + 0, k + 17, ModBlocks.karosHeatTileGreen);
		setBlock(world, i + 13, j + 0, k + 18, ModBlocks.blackKarosBricks);
		setBlock(world, i + 13, j + 1, k + 1, ModBlocks.blackKarosBricks);
		setBlock(world, i + 13, j + 1, k + 18, ModBlocks.blackKarosBricks);
		setBlock(world, i + 13, j + 2, k + 1, ModBlocks.blueKarosBricks);
		setBlock(world, i + 13, j + 2, k + 18, ModBlocks.blueKarosBricks);
		setBlock(world, i + 13, j + 3, k + 1, ModBlocks.blueKarosBricks);
		setBlock(world, i + 13, j + 3, k + 18, ModBlocks.blueKarosBricks);
		setBlock(world, i + 13, j + 4, k + 2, ModBlocks.blueKarosBricks);
		setBlock(world, i + 13, j + 4, k + 4, ModBlocks.helioticBeam);
		setBlock(world, i + 13, j + 4, k + 5, ModBlocks.helioticBeam);
		setBlock(world, i + 13, j + 4, k + 6, ModBlocks.helioticBeam);
		setBlock(world, i + 13, j + 4, k + 14, ModBlocks.helioticBeam);
		setBlock(world, i + 13, j + 4, k + 15, ModBlocks.helioticBeam);
		setBlock(world, i + 13, j + 4, k + 16, ModBlocks.helioticBeam);
		setBlock(world, i + 13, j + 4, k + 17, ModBlocks.blueKarosBricks);
		setBlock(world, i + 13, j + 5, k + 3, ModBlocks.blueKarosBricks);
		setBlock(world, i + 13, j + 5, k + 4, ModBlocks.blackKarosBricks);
		setBlock(world, i + 13, j + 5, k + 5, ModBlocks.blackKarosBricks);
		setBlock(world, i + 13, j + 5, k + 6, ModBlocks.blackKarosBricks);
		setBlock(world, i + 13, j + 5, k + 7, ModBlocks.blackKarosBricks);
		setBlock(world, i + 13, j + 5, k + 8, ModBlocks.blackKarosBricks);
		setBlock(world, i + 13, j + 5, k + 9, ModBlocks.blackKarosBricks);
		setBlock(world, i + 13, j + 5, k + 10, ModBlocks.blackKarosBricks);
		setBlock(world, i + 13, j + 5, k + 11, ModBlocks.blackKarosBricks);
		setBlock(world, i + 13, j + 5, k + 12, ModBlocks.blackKarosBricks);
		setBlock(world, i + 13, j + 5, k + 13, ModBlocks.blackKarosBricks);
		setBlock(world, i + 13, j + 5, k + 14, ModBlocks.blackKarosBricks);
		setBlock(world, i + 13, j + 5, k + 15, ModBlocks.blackKarosBricks);
		setBlock(world, i + 13, j + 5, k + 16, ModBlocks.blueKarosBricks);
		setBlock(world, i + 14, j + 0, k + 0, ModBlocks.blackKarosBricks);
		setBlock(world, i + 14, j + 0, k + 1, ModBlocks.blackKarosBricks);
		setBlock(world, i + 14, j + 0, k + 2, ModBlocks.karosHeatTileRed);
		setBlock(world, i + 14, j + 0, k + 3, ModBlocks.karosHeatTileRed);
		setBlock(world, i + 14, j + 0, k + 4, ModBlocks.karosHeatTileGreen);
		setBlock(world, i + 14, j + 0, k + 5, ModBlocks.karosHeatTileGreen);
		setBlock(world, i + 14, j + 0, k + 6, ModBlocks.karosHeatTileRed);
		setBlock(world, i + 14, j + 0, k + 7, ModBlocks.karosHeatTileRed);
		setBlock(world, i + 14, j + 0, k + 8, ModBlocks.karosHeatTileGreen);
		setBlock(world, i + 14, j + 0, k + 9, ModBlocks.karosHeatTileGreen);
		setBlock(world, i + 14, j + 0, k + 10, ModBlocks.karosHeatTileRed);
		setBlock(world, i + 14, j + 0, k + 11, ModBlocks.karosHeatTileRed);
		setBlock(world, i + 14, j + 0, k + 12, ModBlocks.karosHeatTileGreen);
		setBlock(world, i + 14, j + 0, k + 13, ModBlocks.karosHeatTileGreen);
		setBlock(world, i + 14, j + 0, k + 14, ModBlocks.karosHeatTileRed);
		setBlock(world, i + 14, j + 0, k + 15, ModBlocks.karosHeatTileRed);
		setBlock(world, i + 14, j + 0, k + 16, ModBlocks.karosHeatTileGreen);
		setBlock(world, i + 14, j + 0, k + 17, ModBlocks.karosHeatTileGreen);
		setBlock(world, i + 14, j + 0, k + 18, ModBlocks.blackKarosBricks);
		setBlock(world, i + 14, j + 0, k + 19, ModBlocks.blackKarosBricks);
		setBlock(world, i + 14, j + 1, k + 0, ModBlocks.blackKarosBricks);
		setBlock(world, i + 14, j + 1, k + 1, ModBlocks.blackKarosBricks);
		setBlock(world, i + 14, j + 1, k + 18, ModBlocks.blackKarosBricks);
		setBlock(world, i + 14, j + 1, k + 19, ModBlocks.blackKarosBricks);
		setBlock(world, i + 14, j + 2, k + 0, ModBlocks.blackKarosBricks);
		setBlock(world, i + 14, j + 2, k + 1, ModBlocks.karosDispenser);
		setBlock(world, i + 14, j + 2, k + 18, ModBlocks.karosDispenser);
		setBlock(world, i + 14, j + 2, k + 19, ModBlocks.blackKarosBricks);
		setBlock(world, i + 14, j + 3, k + 1, ModBlocks.blueKarosBricks);
		setBlock(world, i + 14, j + 3, k + 18, ModBlocks.blueKarosBricks);
		setBlock(world, i + 14, j + 4, k + 2, ModBlocks.blueKarosBricks);
		setBlock(world, i + 14, j + 4, k + 4, ModBlocks.helioticBeam);
		setBlock(world, i + 14, j + 4, k + 5, ModBlocks.helioticBeam);
		setBlock(world, i + 14, j + 4, k + 6, ModBlocks.helioticBeam);
		setBlock(world, i + 14, j + 4, k + 14, ModBlocks.helioticBeam);
		setBlock(world, i + 14, j + 4, k + 15, ModBlocks.helioticBeam);
		setBlock(world, i + 14, j + 4, k + 16, ModBlocks.helioticBeam);
		setBlock(world, i + 14, j + 4, k + 17, ModBlocks.blueKarosBricks);
		setBlock(world, i + 14, j + 5, k + 3, ModBlocks.blueKarosBricks);
		setBlock(world, i + 14, j + 5, k + 4, ModBlocks.blackKarosBricks);
		setBlock(world, i + 14, j + 5, k + 5, ModBlocks.blueKarosBricks);
		setBlock(world, i + 14, j + 5, k + 6, ModBlocks.blueKarosBricks);
		setBlock(world, i + 14, j + 5, k + 7, ModBlocks.blueKarosBricks);
		setBlock(world, i + 14, j + 5, k + 8, ModBlocks.blueKarosBricks);
		setBlock(world, i + 14, j + 5, k + 9, ModBlocks.blueKarosBricks);
		setBlock(world, i + 14, j + 5, k + 10, ModBlocks.blueKarosBricks);
		setBlock(world, i + 14, j + 5, k + 11, ModBlocks.blueKarosBricks);
		setBlock(world, i + 14, j + 5, k + 12, ModBlocks.blueKarosBricks);
		setBlock(world, i + 14, j + 5, k + 13, ModBlocks.blueKarosBricks);
		setBlock(world, i + 14, j + 5, k + 14, ModBlocks.blueKarosBricks);
		setBlock(world, i + 14, j + 5, k + 15, ModBlocks.blackKarosBricks);
		setBlock(world, i + 14, j + 5, k + 16, ModBlocks.blueKarosBricks);
		setBlock(world, i + 15, j + 0, k + 1, ModBlocks.blackKarosBricks);
		setBlock(world, i + 15, j + 0, k + 2, ModBlocks.karosHeatTileGreen);
		setBlock(world, i + 15, j + 0, k + 3, ModBlocks.karosHeatTileGreen);
		setBlock(world, i + 15, j + 0, k + 4, ModBlocks.karosHeatTileRed);
		setBlock(world, i + 15, j + 0, k + 5, ModBlocks.karosHeatTileRed);
		setBlock(world, i + 15, j + 0, k + 6, ModBlocks.karosHeatTileGreen);
		setBlock(world, i + 15, j + 0, k + 7, ModBlocks.karosHeatTileGreen);
		setBlock(world, i + 15, j + 0, k + 8, ModBlocks.karosHeatTileRed);
		setBlock(world, i + 15, j + 0, k + 9, ModBlocks.karosHeatTileRed);
		setBlock(world, i + 15, j + 0, k + 10, ModBlocks.karosHeatTileGreen);
		setBlock(world, i + 15, j + 0, k + 11, ModBlocks.karosHeatTileGreen);
		setBlock(world, i + 15, j + 0, k + 12, ModBlocks.karosHeatTileRed);
		setBlock(world, i + 15, j + 0, k + 13, ModBlocks.karosHeatTileRed);
		setBlock(world, i + 15, j + 0, k + 14, ModBlocks.karosHeatTileGreen);
		setBlock(world, i + 15, j + 0, k + 15, ModBlocks.karosHeatTileGreen);
		setBlock(world, i + 15, j + 0, k + 16, ModBlocks.karosHeatTileRed);
		setBlock(world, i + 15, j + 0, k + 17, ModBlocks.karosHeatTileRed);
		setBlock(world, i + 15, j + 0, k + 18, ModBlocks.blackKarosBricks);
		setBlock(world, i + 15, j + 1, k + 1, ModBlocks.blackKarosBricks);
		setBlock(world, i + 15, j + 1, k + 18, ModBlocks.blackKarosBricks);
		setBlock(world, i + 15, j + 2, k + 1, ModBlocks.blueKarosBricks);
		setBlock(world, i + 15, j + 2, k + 18, ModBlocks.blueKarosBricks);
		setBlock(world, i + 15, j + 3, k + 1, ModBlocks.blueKarosBricks);
		setBlock(world, i + 15, j + 3, k + 18, ModBlocks.blueKarosBricks);
		setBlock(world, i + 15, j + 4, k + 2, ModBlocks.blueKarosBricks);
		setBlock(world, i + 15, j + 4, k + 4, ModBlocks.helioticBeam);
		setBlock(world, i + 15, j + 4, k + 5, ModBlocks.helioticBeam);
		setBlock(world, i + 15, j + 4, k + 6, ModBlocks.helioticBeam);
		setBlock(world, i + 15, j + 4, k + 14, ModBlocks.helioticBeam);
		setBlock(world, i + 15, j + 4, k + 15, ModBlocks.helioticBeam);
		setBlock(world, i + 15, j + 4, k + 16, ModBlocks.helioticBeam);
		setBlock(world, i + 15, j + 4, k + 17, ModBlocks.blueKarosBricks);
		setBlock(world, i + 15, j + 5, k + 3, ModBlocks.blueKarosBricks);
		setBlock(world, i + 15, j + 5, k + 4, ModBlocks.blackKarosBricks);
		setBlock(world, i + 15, j + 5, k + 5, ModBlocks.blueKarosBricks);
		setBlock(world, i + 15, j + 5, k + 6, ModBlocks.blackKarosBricks);
		setBlock(world, i + 15, j + 5, k + 7, ModBlocks.blackKarosBricks);
		setBlock(world, i + 15, j + 5, k + 8, ModBlocks.blackKarosBricks);
		setBlock(world, i + 15, j + 5, k + 9, ModBlocks.blackKarosBricks);
		setBlock(world, i + 15, j + 5, k + 10, ModBlocks.blackKarosBricks);
		setBlock(world, i + 15, j + 5, k + 11, ModBlocks.blackKarosBricks);
		setBlock(world, i + 15, j + 5, k + 12, ModBlocks.blackKarosBricks);
		setBlock(world, i + 15, j + 5, k + 13, ModBlocks.blackKarosBricks);
		setBlock(world, i + 15, j + 5, k + 14, ModBlocks.blueKarosBricks);
		setBlock(world, i + 15, j + 5, k + 15, ModBlocks.blackKarosBricks);
		setBlock(world, i + 15, j + 5, k + 16, ModBlocks.blueKarosBricks);
		setBlock(world, i + 16, j + 0, k + 0, ModBlocks.blackKarosBricks);
		setBlock(world, i + 16, j + 0, k + 1, ModBlocks.blackKarosBricks);
		setBlock(world, i + 16, j + 0, k + 2, ModBlocks.karosHeatTileGreen);
		setBlock(world, i + 16, j + 0, k + 3, ModBlocks.karosHeatTileGreen);
		setBlock(world, i + 16, j + 0, k + 4, ModBlocks.karosHeatTileRed);
		setBlock(world, i + 16, j + 0, k + 5, ModBlocks.karosHeatTileRed);
		setBlock(world, i + 16, j + 0, k + 6, ModBlocks.karosHeatTileGreen);
		setBlock(world, i + 16, j + 0, k + 7, ModBlocks.karosHeatTileGreen);
		setBlock(world, i + 16, j + 0, k + 8, ModBlocks.karosHeatTileRed);
		setBlock(world, i + 16, j + 0, k + 9, ModBlocks.karosHeatTileRed);
		setBlock(world, i + 16, j + 0, k + 10, ModBlocks.karosHeatTileGreen);
		setBlock(world, i + 16, j + 0, k + 11, ModBlocks.karosHeatTileGreen);
		setBlock(world, i + 16, j + 0, k + 12, ModBlocks.karosHeatTileRed);
		setBlock(world, i + 16, j + 0, k + 13, ModBlocks.karosHeatTileRed);
		setBlock(world, i + 16, j + 0, k + 14, ModBlocks.karosHeatTileGreen);
		setBlock(world, i + 16, j + 0, k + 15, ModBlocks.karosHeatTileGreen);
		setBlock(world, i + 16, j + 0, k + 16, ModBlocks.karosHeatTileRed);
		setBlock(world, i + 16, j + 0, k + 17, ModBlocks.karosHeatTileRed);
		setBlock(world, i + 16, j + 0, k + 18, ModBlocks.blackKarosBricks);
		setBlock(world, i + 16, j + 0, k + 19, ModBlocks.blackKarosBricks);
		setBlock(world, i + 16, j + 1, k + 0, ModBlocks.blackKarosBricks);
		setBlock(world, i + 16, j + 1, k + 1, ModBlocks.blackKarosBricks);
		setBlock(world, i + 16, j + 1, k + 18, ModBlocks.blackKarosBricks);
		setBlock(world, i + 16, j + 1, k + 19, ModBlocks.blackKarosBricks);
		setBlock(world, i + 16, j + 2, k + 0, ModBlocks.blackKarosBricks);
		setBlock(world, i + 16, j + 2, k + 1, ModBlocks.karosDispenser);
		setBlock(world, i + 16, j + 2, k + 18, ModBlocks.karosDispenser);
		setBlock(world, i + 16, j + 2, k + 19, ModBlocks.blackKarosBricks);
		setBlock(world, i + 16, j + 3, k + 1, ModBlocks.blueKarosBricks);
		setBlock(world, i + 16, j + 3, k + 18, ModBlocks.blueKarosBricks);
		setBlock(world, i + 16, j + 4, k + 2, ModBlocks.blueKarosBricks);
		setBlock(world, i + 16, j + 4, k + 17, ModBlocks.blueKarosBricks);
		setBlock(world, i + 16, j + 5, k + 3, ModBlocks.blueKarosBricks);
		setBlock(world, i + 16, j + 5, k + 4, ModBlocks.blackKarosBricks);
		setBlock(world, i + 16, j + 5, k + 5, ModBlocks.blueKarosBricks);
		setBlock(world, i + 16, j + 5, k + 6, ModBlocks.blackKarosBricks);
		setBlock(world, i + 16, j + 5, k + 7, ModBlocks.blueKarosBricks);
		setBlock(world, i + 16, j + 5, k + 8, ModBlocks.blackKarosBricks);
		setBlock(world, i + 16, j + 5, k + 9, ModBlocks.blackKarosBricks);
		setBlock(world, i + 16, j + 5, k + 10, ModBlocks.blackKarosBricks);
		setBlock(world, i + 16, j + 5, k + 11, ModBlocks.blueKarosBricks);
		setBlock(world, i + 16, j + 5, k + 12, ModBlocks.blackKarosBricks);
		setBlock(world, i + 16, j + 5, k + 13, ModBlocks.blackKarosBricks);
		setBlock(world, i + 16, j + 5, k + 14, ModBlocks.blueKarosBricks);
		setBlock(world, i + 16, j + 5, k + 15, ModBlocks.blackKarosBricks);
		setBlock(world, i + 16, j + 5, k + 16, ModBlocks.blueKarosBricks);
		setBlock(world, i + 17, j + 0, k + 1, ModBlocks.blackKarosBricks);
		setBlock(world, i + 17, j + 0, k + 2, ModBlocks.karosHeatTileRed);
		setBlock(world, i + 17, j + 0, k + 3, ModBlocks.karosHeatTileRed);
		setBlock(world, i + 17, j + 0, k + 4, ModBlocks.karosHeatTileGreen);
		setBlock(world, i + 17, j + 0, k + 5, ModBlocks.karosHeatTileGreen);
		setBlock(world, i + 17, j + 0, k + 6, ModBlocks.karosHeatTileRed);
		setBlock(world, i + 17, j + 0, k + 7, ModBlocks.karosHeatTileRed);
		setBlock(world, i + 17, j + 0, k + 8, ModBlocks.karosHeatTileGreen);
		setBlock(world, i + 17, j + 0, k + 9, ModBlocks.karosHeatTileGreen);
		setBlock(world, i + 17, j + 0, k + 10, ModBlocks.karosHeatTileRed);
		setBlock(world, i + 17, j + 0, k + 11, ModBlocks.karosHeatTileRed);
		setBlock(world, i + 17, j + 0, k + 12, ModBlocks.karosHeatTileGreen);
		setBlock(world, i + 17, j + 0, k + 13, ModBlocks.karosHeatTileGreen);
		setBlock(world, i + 17, j + 0, k + 14, ModBlocks.karosHeatTileRed);
		setBlock(world, i + 17, j + 0, k + 15, ModBlocks.karosHeatTileRed);
		setBlock(world, i + 17, j + 0, k + 16, ModBlocks.karosHeatTileGreen);
		setBlock(world, i + 17, j + 0, k + 17, ModBlocks.karosHeatTileGreen);
		setBlock(world, i + 17, j + 0, k + 18, ModBlocks.blackKarosBricks);
		setBlock(world, i + 17, j + 1, k + 1, ModBlocks.blackKarosBricks);
		setBlock(world, i + 17, j + 1, k + 18, ModBlocks.blackKarosBricks);
		setBlock(world, i + 17, j + 2, k + 1, ModBlocks.blueKarosBricks);
		setBlock(world, i + 17, j + 2, k + 18, ModBlocks.blueKarosBricks);
		setBlock(world, i + 17, j + 3, k + 1, ModBlocks.blueKarosBricks);
		setBlock(world, i + 17, j + 3, k + 18, ModBlocks.blueKarosBricks);
		setBlock(world, i + 17, j + 4, k + 2, ModBlocks.blueKarosBricks);
		setBlock(world, i + 17, j + 4, k + 17, ModBlocks.blueKarosBricks);
		setBlock(world, i + 17, j + 5, k + 3, ModBlocks.blueKarosBricks);
		setBlock(world, i + 17, j + 5, k + 4, ModBlocks.blackKarosBricks);
		setBlock(world, i + 17, j + 5, k + 5, ModBlocks.blueKarosBricks);
		setBlock(world, i + 17, j + 5, k + 6, ModBlocks.blackKarosBricks);
		setBlock(world, i + 17, j + 5, k + 7, ModBlocks.blueKarosBricks);
		setBlock(world, i + 17, j + 5, k + 8, ModBlocks.blackKarosBricks);
		setBlock(world, i + 17, j + 5, k + 9, ModBlocks.blackKarosBricks);
		setBlock(world, i + 17, j + 5, k + 10, ModBlocks.blueKarosBricks);
		setBlock(world, i + 17, j + 5, k + 11, ModBlocks.blackKarosBricks);
		setBlock(world, i + 17, j + 5, k + 12, ModBlocks.blackKarosBricks);
		setBlock(world, i + 17, j + 5, k + 13, ModBlocks.blackKarosBricks);
		setBlock(world, i + 17, j + 5, k + 14, ModBlocks.blueKarosBricks);
		setBlock(world, i + 17, j + 5, k + 15, ModBlocks.blackKarosBricks);
		setBlock(world, i + 17, j + 5, k + 16, ModBlocks.blueKarosBricks);
		setBlock(world, i + 18, j + 0, k + 0, ModBlocks.blackKarosBricks);
		setBlock(world, i + 18, j + 0, k + 1, ModBlocks.blackKarosBricks);
		setBlock(world, i + 18, j + 0, k + 2, ModBlocks.karosHeatTileRed);
		setBlock(world, i + 18, j + 0, k + 3, ModBlocks.karosHeatTileRed);
		setBlock(world, i + 18, j + 0, k + 4, ModBlocks.karosHeatTileGreen);
		setBlock(world, i + 18, j + 0, k + 5, ModBlocks.karosHeatTileGreen);
		setBlock(world, i + 18, j + 0, k + 6, ModBlocks.karosHeatTileRed);
		setBlock(world, i + 18, j + 0, k + 7, ModBlocks.karosHeatTileRed);
		setBlock(world, i + 18, j + 0, k + 8, ModBlocks.karosHeatTileGreen);
		setBlock(world, i + 18, j + 0, k + 9, ModBlocks.karosHeatTileGreen);
		setBlock(world, i + 18, j + 0, k + 10, ModBlocks.karosHeatTileRed);
		setBlock(world, i + 18, j + 0, k + 11, ModBlocks.karosHeatTileRed);
		setBlock(world, i + 18, j + 0, k + 12, ModBlocks.karosHeatTileGreen);
		setBlock(world, i + 18, j + 0, k + 13, ModBlocks.karosHeatTileGreen);
		setBlock(world, i + 18, j + 0, k + 14, ModBlocks.karosHeatTileRed);
		setBlock(world, i + 18, j + 0, k + 15, ModBlocks.karosHeatTileRed);
		setBlock(world, i + 18, j + 0, k + 16, ModBlocks.karosHeatTileGreen);
		setBlock(world, i + 18, j + 0, k + 17, ModBlocks.karosHeatTileGreen);
		setBlock(world, i + 18, j + 0, k + 18, ModBlocks.blackKarosBricks);
		setBlock(world, i + 18, j + 0, k + 19, ModBlocks.blackKarosBricks);
		setBlock(world, i + 18, j + 1, k + 0, ModBlocks.blackKarosBricks);
		setBlock(world, i + 18, j + 1, k + 1, ModBlocks.blackKarosBricks);
		setBlock(world, i + 18, j + 1, k + 18, ModBlocks.blackKarosBricks);
		setBlock(world, i + 18, j + 1, k + 19, ModBlocks.blackKarosBricks);
		setBlock(world, i + 18, j + 2, k + 0, ModBlocks.blackKarosBricks);
		setBlock(world, i + 18, j + 2, k + 1, ModBlocks.karosDispenser);
		setBlock(world, i + 18, j + 2, k + 18, ModBlocks.karosDispenser);
		setBlock(world, i + 18, j + 2, k + 19, ModBlocks.blackKarosBricks);
		setBlock(world, i + 18, j + 3, k + 1, ModBlocks.blueKarosBricks);
		setBlock(world, i + 18, j + 3, k + 18, ModBlocks.blueKarosBricks);
		setBlock(world, i + 18, j + 4, k + 2, ModBlocks.blueKarosBricks);
		setBlock(world, i + 18, j + 4, k + 9, ModBlocks.helioticBeam);
		setBlock(world, i + 18, j + 4, k + 10, ModBlocks.helioticBeam);
		setBlock(world, i + 18, j + 4, k + 11, ModBlocks.helioticBeam);
		setBlock(world, i + 18, j + 4, k + 17, ModBlocks.blueKarosBricks);
		setBlock(world, i + 18, j + 5, k + 3, ModBlocks.blueKarosBricks);
		setBlock(world, i + 18, j + 5, k + 4, ModBlocks.blackKarosBricks);
		setBlock(world, i + 18, j + 5, k + 5, ModBlocks.blueKarosBricks);
		setBlock(world, i + 18, j + 5, k + 6, ModBlocks.blackKarosBricks);
		setBlock(world, i + 18, j + 5, k + 7, ModBlocks.blueKarosBricks);
		setBlock(world, i + 18, j + 5, k + 8, ModBlocks.blackKarosBricks);
		setBlock(world, i + 18, j + 5, k + 9, ModBlocks.blueKarosBricks);
		setBlock(world, i + 18, j + 5, k + 10, ModBlocks.blackKarosBricks);
		setBlock(world, i + 18, j + 5, k + 11, ModBlocks.blackKarosBricks);
		setBlock(world, i + 18, j + 5, k + 12, ModBlocks.blackKarosBricks);
		setBlock(world, i + 18, j + 5, k + 13, ModBlocks.blackKarosBricks);
		setBlock(world, i + 18, j + 5, k + 14, ModBlocks.blueKarosBricks);
		setBlock(world, i + 18, j + 5, k + 15, ModBlocks.blackKarosBricks);
		setBlock(world, i + 18, j + 5, k + 16, ModBlocks.blueKarosBricks);
		setBlock(world, i + 19, j + 0, k + 1, ModBlocks.blackKarosBricks);
		setBlock(world, i + 19, j + 0, k + 2, ModBlocks.karosHeatTileGreen);
		setBlock(world, i + 19, j + 0, k + 3, ModBlocks.karosHeatTileGreen);
		setBlock(world, i + 19, j + 0, k + 4, ModBlocks.karosHeatTileRed);
		setBlock(world, i + 19, j + 0, k + 5, ModBlocks.karosHeatTileRed);
		setBlock(world, i + 19, j + 0, k + 6, ModBlocks.karosHeatTileGreen);
		setBlock(world, i + 19, j + 0, k + 7, ModBlocks.karosHeatTileGreen);
		setBlock(world, i + 19, j + 0, k + 8, ModBlocks.karosHeatTileRed);
		setBlock(world, i + 19, j + 0, k + 9, ModBlocks.karosHeatTileRed);
		setBlock(world, i + 19, j + 0, k + 10, ModBlocks.karosHeatTileGreen);
		setBlock(world, i + 19, j + 0, k + 11, ModBlocks.karosHeatTileGreen);
		setBlock(world, i + 19, j + 0, k + 12, ModBlocks.karosHeatTileRed);
		setBlock(world, i + 19, j + 0, k + 13, ModBlocks.karosHeatTileRed);
		setBlock(world, i + 19, j + 0, k + 14, ModBlocks.karosHeatTileGreen);
		setBlock(world, i + 19, j + 0, k + 15, ModBlocks.karosHeatTileGreen);
		setBlock(world, i + 19, j + 0, k + 16, ModBlocks.karosHeatTileRed);
		setBlock(world, i + 19, j + 0, k + 17, ModBlocks.karosHeatTileRed);
		setBlock(world, i + 19, j + 0, k + 18, ModBlocks.blackKarosBricks);
		setBlock(world, i + 19, j + 1, k + 1, ModBlocks.blackKarosBricks);
		setBlock(world, i + 19, j + 1, k + 18, ModBlocks.blackKarosBricks);
		setBlock(world, i + 19, j + 2, k + 1, ModBlocks.blueKarosBricks);
		setBlock(world, i + 19, j + 2, k + 18, ModBlocks.blueKarosBricks);
		setBlock(world, i + 19, j + 3, k + 1, ModBlocks.blueKarosBricks);
		setBlock(world, i + 19, j + 3, k + 18, ModBlocks.blueKarosBricks);
		setBlock(world, i + 19, j + 4, k + 2, ModBlocks.blueKarosBricks);
		setBlock(world, i + 19, j + 4, k + 9, ModBlocks.helioticBeam);
		setBlock(world, i + 19, j + 4, k + 10, ModBlocks.helioticBeam);
		setBlock(world, i + 19, j + 4, k + 11, ModBlocks.helioticBeam);
		setBlock(world, i + 19, j + 4, k + 17, ModBlocks.blueKarosBricks);
		setBlock(world, i + 19, j + 5, k + 3, ModBlocks.blueKarosBricks);
		setBlock(world, i + 19, j + 5, k + 4, ModBlocks.blackKarosBricks);
		setBlock(world, i + 19, j + 5, k + 5, ModBlocks.blueKarosBricks);
		setBlock(world, i + 19, j + 5, k + 6, ModBlocks.blackKarosBricks);
		setBlock(world, i + 19, j + 5, k + 7, ModBlocks.blueKarosBricks);
		setBlock(world, i + 19, j + 5, k + 8, ModBlocks.blueKarosBricks);
		setBlock(world, i + 19, j + 5, k + 9, ModBlocks.blackKarosBricks);
		setBlock(world, i + 19, j + 5, k + 10, ModBlocks.blackKarosBricks);
		setBlock(world, i + 19, j + 5, k + 11, ModBlocks.blackKarosBricks);
		setBlock(world, i + 19, j + 5, k + 12, ModBlocks.blackKarosBricks);
		setBlock(world, i + 19, j + 5, k + 13, ModBlocks.blackKarosBricks);
		setBlock(world, i + 19, j + 5, k + 14, ModBlocks.blueKarosBricks);
		setBlock(world, i + 19, j + 5, k + 15, ModBlocks.blackKarosBricks);
		setBlock(world, i + 19, j + 5, k + 16, ModBlocks.blueKarosBricks);
		setBlock(world, i + 20, j + 0, k + 0, ModBlocks.blackKarosBricks);
		setBlock(world, i + 20, j + 0, k + 1, ModBlocks.blackKarosBricks);
		setBlock(world, i + 20, j + 0, k + 2, ModBlocks.karosHeatTileGreen);
		setBlock(world, i + 20, j + 0, k + 3, ModBlocks.karosHeatTileGreen);
		setBlock(world, i + 20, j + 0, k + 4, ModBlocks.karosHeatTileRed);
		setBlock(world, i + 20, j + 0, k + 5, ModBlocks.karosHeatTileRed);
		setBlock(world, i + 20, j + 0, k + 6, ModBlocks.karosHeatTileGreen);
		setBlock(world, i + 20, j + 0, k + 7, ModBlocks.karosHeatTileGreen);
		setBlock(world, i + 20, j + 0, k + 8, ModBlocks.karosHeatTileRed);
		setBlock(world, i + 20, j + 0, k + 9, ModBlocks.karosHeatTileRed);
		setBlock(world, i + 20, j + 0, k + 10, ModBlocks.karosHeatTileGreen);
		setBlock(world, i + 20, j + 0, k + 11, ModBlocks.karosHeatTileGreen);
		setBlock(world, i + 20, j + 0, k + 12, ModBlocks.karosHeatTileRed);
		setBlock(world, i + 20, j + 0, k + 13, ModBlocks.karosHeatTileRed);
		setBlock(world, i + 20, j + 0, k + 14, ModBlocks.karosHeatTileGreen);
		setBlock(world, i + 20, j + 0, k + 15, ModBlocks.karosHeatTileGreen);
		setBlock(world, i + 20, j + 0, k + 16, ModBlocks.karosHeatTileRed);
		setBlock(world, i + 20, j + 0, k + 17, ModBlocks.karosHeatTileRed);
		setBlock(world, i + 20, j + 0, k + 18, ModBlocks.blackKarosBricks);
		setBlock(world, i + 20, j + 0, k + 19, ModBlocks.blackKarosBricks);
		setBlock(world, i + 20, j + 1, k + 0, ModBlocks.blackKarosBricks);
		setBlock(world, i + 20, j + 1, k + 1, ModBlocks.blackKarosBricks);
		setBlock(world, i + 20, j + 1, k + 18, ModBlocks.blackKarosBricks);
		setBlock(world, i + 20, j + 1, k + 19, ModBlocks.blackKarosBricks);
		setBlock(world, i + 20, j + 2, k + 0, ModBlocks.blackKarosBricks);
		setBlock(world, i + 20, j + 2, k + 1, ModBlocks.karosDispenser);
		setBlock(world, i + 20, j + 2, k + 18, ModBlocks.karosDispenser);
		setBlock(world, i + 20, j + 2, k + 19, ModBlocks.blackKarosBricks);
		setBlock(world, i + 20, j + 3, k + 1, ModBlocks.blueKarosBricks);
		setBlock(world, i + 20, j + 3, k + 18, ModBlocks.blueKarosBricks);
		setBlock(world, i + 20, j + 4, k + 2, ModBlocks.blueKarosBricks);
		setBlock(world, i + 20, j + 4, k + 9, ModBlocks.helioticBeam);
		setBlock(world, i + 20, j + 4, k + 10, ModBlocks.helioticBeam);
		setBlock(world, i + 20, j + 4, k + 11, ModBlocks.helioticBeam);
		setBlock(world, i + 20, j + 4, k + 17, ModBlocks.blueKarosBricks);
		setBlock(world, i + 20, j + 5, k + 3, ModBlocks.blueKarosBricks);
		setBlock(world, i + 20, j + 5, k + 4, ModBlocks.blackKarosBricks);
		setBlock(world, i + 20, j + 5, k + 5, ModBlocks.blueKarosBricks);
		setBlock(world, i + 20, j + 5, k + 6, ModBlocks.blackKarosBricks);
		setBlock(world, i + 20, j + 5, k + 7, ModBlocks.blueKarosBricks);
		setBlock(world, i + 20, j + 5, k + 8, ModBlocks.blackKarosBricks);
		setBlock(world, i + 20, j + 5, k + 9, ModBlocks.blackKarosBricks);
		setBlock(world, i + 20, j + 5, k + 10, ModBlocks.blackKarosBricks);
		setBlock(world, i + 20, j + 5, k + 11, ModBlocks.blackKarosBricks);
		setBlock(world, i + 20, j + 5, k + 12, ModBlocks.blackKarosBricks);
		setBlock(world, i + 20, j + 5, k + 13, ModBlocks.blackKarosBricks);
		setBlock(world, i + 20, j + 5, k + 14, ModBlocks.blueKarosBricks);
		setBlock(world, i + 20, j + 5, k + 15, ModBlocks.blackKarosBricks);
		setBlock(world, i + 20, j + 5, k + 16, ModBlocks.blueKarosBricks);
		setBlock(world, i + 21, j + 0, k + 1, ModBlocks.blackKarosBricks);
		setBlock(world, i + 21, j + 0, k + 2, ModBlocks.karosHeatTileRed);
		setBlock(world, i + 21, j + 0, k + 3, ModBlocks.karosHeatTileRed);
		setBlock(world, i + 21, j + 0, k + 4, ModBlocks.karosHeatTileGreen);
		setBlock(world, i + 21, j + 0, k + 5, ModBlocks.karosHeatTileGreen);
		setBlock(world, i + 21, j + 0, k + 6, ModBlocks.karosHeatTileRed);
		setBlock(world, i + 21, j + 0, k + 7, ModBlocks.karosHeatTileRed);
		setBlock(world, i + 21, j + 0, k + 8, ModBlocks.karosHeatTileGreen);
		setBlock(world, i + 21, j + 0, k + 9, ModBlocks.karosHeatTileGreen);
		setBlock(world, i + 21, j + 0, k + 10, ModBlocks.karosHeatTileRed);
		setBlock(world, i + 21, j + 0, k + 11, ModBlocks.karosHeatTileRed);
		setBlock(world, i + 21, j + 0, k + 12, ModBlocks.karosHeatTileGreen);
		setBlock(world, i + 21, j + 0, k + 13, ModBlocks.karosHeatTileGreen);
		setBlock(world, i + 21, j + 0, k + 14, ModBlocks.karosHeatTileRed);
		setBlock(world, i + 21, j + 0, k + 15, ModBlocks.karosHeatTileRed);
		setBlock(world, i + 21, j + 0, k + 16, ModBlocks.karosHeatTileGreen);
		setBlock(world, i + 21, j + 0, k + 17, ModBlocks.karosHeatTileGreen);
		setBlock(world, i + 21, j + 0, k + 18, ModBlocks.blackKarosBricks);
		setBlock(world, i + 21, j + 1, k + 1, ModBlocks.blackKarosBricks);
		setBlock(world, i + 21, j + 1, k + 18, ModBlocks.blackKarosBricks);
		setBlock(world, i + 21, j + 2, k + 1, ModBlocks.blueKarosBricks);
		setBlock(world, i + 21, j + 2, k + 18, ModBlocks.blueKarosBricks);
		setBlock(world, i + 21, j + 3, k + 1, ModBlocks.blueKarosBricks);
		setBlock(world, i + 21, j + 3, k + 18, ModBlocks.blueKarosBricks);
		setBlock(world, i + 21, j + 4, k + 2, ModBlocks.blueKarosBricks);
		setBlock(world, i + 21, j + 4, k + 17, ModBlocks.blueKarosBricks);
		setBlock(world, i + 21, j + 5, k + 3, ModBlocks.blueKarosBricks);
		setBlock(world, i + 21, j + 5, k + 4, ModBlocks.blackKarosBricks);
		setBlock(world, i + 21, j + 5, k + 5, ModBlocks.blueKarosBricks);
		setBlock(world, i + 21, j + 5, k + 6, ModBlocks.blackKarosBricks);
		setBlock(world, i + 21, j + 5, k + 7, ModBlocks.blueKarosBricks);
		setBlock(world, i + 21, j + 5, k + 8, ModBlocks.blueKarosBricks);
		setBlock(world, i + 21, j + 5, k + 9, ModBlocks.blackKarosBricks);
		setBlock(world, i + 21, j + 5, k + 10, ModBlocks.blackKarosBricks);
		setBlock(world, i + 21, j + 5, k + 11, ModBlocks.blackKarosBricks);
		setBlock(world, i + 21, j + 5, k + 12, ModBlocks.blackKarosBricks);
		setBlock(world, i + 21, j + 5, k + 13, ModBlocks.blackKarosBricks);
		setBlock(world, i + 21, j + 5, k + 14, ModBlocks.blueKarosBricks);
		setBlock(world, i + 21, j + 5, k + 15, ModBlocks.blackKarosBricks);
		setBlock(world, i + 21, j + 5, k + 16, ModBlocks.blueKarosBricks);
		setBlock(world, i + 22, j + 0, k + 0, ModBlocks.blackKarosBricks);
		setBlock(world, i + 22, j + 0, k + 1, ModBlocks.blackKarosBricks);
		setBlock(world, i + 22, j + 0, k + 2, ModBlocks.karosHeatTileRed);
		setBlock(world, i + 22, j + 0, k + 3, ModBlocks.karosHeatTileRed);
		setBlock(world, i + 22, j + 0, k + 4, ModBlocks.karosHeatTileGreen);
		setBlock(world, i + 22, j + 0, k + 5, ModBlocks.karosHeatTileGreen);
		setBlock(world, i + 22, j + 0, k + 6, ModBlocks.karosHeatTileRed);
		setBlock(world, i + 22, j + 0, k + 7, ModBlocks.karosHeatTileRed);
		setBlock(world, i + 22, j + 0, k + 8, ModBlocks.karosHeatTileGreen);
		setBlock(world, i + 22, j + 0, k + 9, ModBlocks.karosHeatTileGreen);
		setBlock(world, i + 22, j + 0, k + 10, ModBlocks.karosHeatTileRed);
		setBlock(world, i + 22, j + 0, k + 11, ModBlocks.karosHeatTileRed);
		setBlock(world, i + 22, j + 0, k + 12, ModBlocks.karosHeatTileGreen);
		setBlock(world, i + 22, j + 0, k + 13, ModBlocks.karosHeatTileGreen);
		setBlock(world, i + 22, j + 0, k + 14, ModBlocks.karosHeatTileRed);
		setBlock(world, i + 22, j + 0, k + 15, ModBlocks.karosHeatTileRed);
		setBlock(world, i + 22, j + 0, k + 16, ModBlocks.karosHeatTileGreen);
		setBlock(world, i + 22, j + 0, k + 17, ModBlocks.karosHeatTileGreen);
		setBlock(world, i + 22, j + 0, k + 18, ModBlocks.blackKarosBricks);
		setBlock(world, i + 22, j + 0, k + 19, ModBlocks.blackKarosBricks);
		setBlock(world, i + 22, j + 1, k + 0, ModBlocks.blackKarosBricks);
		setBlock(world, i + 22, j + 1, k + 1, ModBlocks.blackKarosBricks);
		setBlock(world, i + 22, j + 1, k + 18, ModBlocks.blackKarosBricks);
		setBlock(world, i + 22, j + 1, k + 19, ModBlocks.blackKarosBricks);
		setBlock(world, i + 22, j + 2, k + 0, ModBlocks.blackKarosBricks);
		setBlock(world, i + 22, j + 2, k + 1, ModBlocks.karosDispenser);
		setBlock(world, i + 22, j + 2, k + 18, ModBlocks.karosDispenser);
		setBlock(world, i + 22, j + 2, k + 19, ModBlocks.blackKarosBricks);
		setBlock(world, i + 22, j + 3, k + 1, ModBlocks.blueKarosBricks);
		setBlock(world, i + 22, j + 3, k + 18, ModBlocks.blueKarosBricks);
		setBlock(world, i + 22, j + 4, k + 2, ModBlocks.blueKarosBricks);
		setBlock(world, i + 22, j + 4, k + 12, ModBlocks.helioticBeam);
		setBlock(world, i + 22, j + 4, k + 13, ModBlocks.helioticBeam);
		setBlock(world, i + 22, j + 4, k + 14, ModBlocks.helioticBeam);
		setBlock(world, i + 22, j + 4, k + 17, ModBlocks.blueKarosBricks);
		setBlock(world, i + 22, j + 5, k + 3, ModBlocks.blueKarosBricks);
		setBlock(world, i + 22, j + 5, k + 4, ModBlocks.blackKarosBricks);
		setBlock(world, i + 22, j + 5, k + 5, ModBlocks.blueKarosBricks);
		setBlock(world, i + 22, j + 5, k + 6, ModBlocks.blackKarosBricks);
		setBlock(world, i + 22, j + 5, k + 7, ModBlocks.blueKarosBricks);
		setBlock(world, i + 22, j + 5, k + 8, ModBlocks.blackKarosBricks);
		setBlock(world, i + 22, j + 5, k + 9, ModBlocks.blueKarosBricks);
		setBlock(world, i + 22, j + 5, k + 10, ModBlocks.blackKarosBricks);
		setBlock(world, i + 22, j + 5, k + 11, ModBlocks.blackKarosBricks);
		setBlock(world, i + 22, j + 5, k + 12, ModBlocks.blackKarosBricks);
		setBlock(world, i + 22, j + 5, k + 13, ModBlocks.blackKarosBricks);
		setBlock(world, i + 22, j + 5, k + 14, ModBlocks.blueKarosBricks);
		setBlock(world, i + 22, j + 5, k + 15, ModBlocks.blackKarosBricks);
		setBlock(world, i + 22, j + 5, k + 16, ModBlocks.blueKarosBricks);
		setBlock(world, i + 23, j + 0, k + 1, ModBlocks.blackKarosBricks);
		setBlock(world, i + 23, j + 0, k + 2, ModBlocks.karosHeatTileGreen);
		setBlock(world, i + 23, j + 0, k + 3, ModBlocks.karosHeatTileGreen);
		setBlock(world, i + 23, j + 0, k + 4, ModBlocks.karosHeatTileRed);
		setBlock(world, i + 23, j + 0, k + 5, ModBlocks.karosHeatTileRed);
		setBlock(world, i + 23, j + 0, k + 6, ModBlocks.karosHeatTileGreen);
		setBlock(world, i + 23, j + 0, k + 7, ModBlocks.karosHeatTileGreen);
		setBlock(world, i + 23, j + 0, k + 8, ModBlocks.karosHeatTileRed);
		setBlock(world, i + 23, j + 0, k + 9, ModBlocks.karosHeatTileRed);
		setBlock(world, i + 23, j + 0, k + 10, ModBlocks.karosHeatTileGreen);
		setBlock(world, i + 23, j + 0, k + 11, ModBlocks.karosHeatTileGreen);
		setBlock(world, i + 23, j + 0, k + 12, ModBlocks.karosHeatTileRed);
		setBlock(world, i + 23, j + 0, k + 13, ModBlocks.karosHeatTileRed);
		setBlock(world, i + 23, j + 0, k + 14, ModBlocks.karosHeatTileGreen);
		setBlock(world, i + 23, j + 0, k + 15, ModBlocks.karosHeatTileGreen);
		setBlock(world, i + 23, j + 0, k + 16, ModBlocks.karosHeatTileRed);
		setBlock(world, i + 23, j + 0, k + 17, ModBlocks.karosHeatTileRed);
		setBlock(world, i + 23, j + 0, k + 18, ModBlocks.blackKarosBricks);
		setBlock(world, i + 23, j + 1, k + 1, ModBlocks.blackKarosBricks);
		setBlock(world, i + 23, j + 1, k + 18, ModBlocks.blackKarosBricks);
		setBlock(world, i + 23, j + 2, k + 1, ModBlocks.blueKarosBricks);
		setBlock(world, i + 23, j + 2, k + 18, ModBlocks.blueKarosBricks);
		setBlock(world, i + 23, j + 3, k + 1, ModBlocks.blueKarosBricks);
		setBlock(world, i + 23, j + 3, k + 18, ModBlocks.blueKarosBricks);
		setBlock(world, i + 23, j + 4, k + 2, ModBlocks.blueKarosBricks);
		setBlock(world, i + 23, j + 4, k + 4, ModBlocks.helioticBeam);
		setBlock(world, i + 23, j + 4, k + 5, ModBlocks.helioticBeam);
		setBlock(world, i + 23, j + 4, k + 6, ModBlocks.helioticBeam);
		setBlock(world, i + 23, j + 4, k + 12, ModBlocks.helioticBeam);
		setBlock(world, i + 23, j + 4, k + 13, ModBlocks.helioticBeam);
		setBlock(world, i + 23, j + 4, k + 14, ModBlocks.helioticBeam);
		setBlock(world, i + 23, j + 4, k + 17, ModBlocks.blueKarosBricks);
		setBlock(world, i + 23, j + 5, k + 3, ModBlocks.blueKarosBricks);
		setBlock(world, i + 23, j + 5, k + 4, ModBlocks.blackKarosBricks);
		setBlock(world, i + 23, j + 5, k + 5, ModBlocks.blueKarosBricks);
		setBlock(world, i + 23, j + 5, k + 6, ModBlocks.blackKarosBricks);
		setBlock(world, i + 23, j + 5, k + 7, ModBlocks.blueKarosBricks);
		setBlock(world, i + 23, j + 5, k + 8, ModBlocks.blackKarosBricks);
		setBlock(world, i + 23, j + 5, k + 9, ModBlocks.blackKarosBricks);
		setBlock(world, i + 23, j + 5, k + 10, ModBlocks.blueKarosBricks);
		setBlock(world, i + 23, j + 5, k + 11, ModBlocks.blackKarosBricks);
		setBlock(world, i + 23, j + 5, k + 12, ModBlocks.blackKarosBricks);
		setBlock(world, i + 23, j + 5, k + 13, ModBlocks.blackKarosBricks);
		setBlock(world, i + 23, j + 5, k + 14, ModBlocks.blueKarosBricks);
		setBlock(world, i + 23, j + 5, k + 15, ModBlocks.blackKarosBricks);
		setBlock(world, i + 23, j + 5, k + 16, ModBlocks.blueKarosBricks);
		setBlock(world, i + 24, j + 0, k + 0, ModBlocks.blackKarosBricks);
		setBlock(world, i + 24, j + 0, k + 1, ModBlocks.blackKarosBricks);
		setBlock(world, i + 24, j + 0, k + 2, ModBlocks.karosHeatTileGreen);
		setBlock(world, i + 24, j + 0, k + 3, ModBlocks.karosHeatTileGreen);
		setBlock(world, i + 24, j + 0, k + 4, ModBlocks.karosHeatTileRed);
		setBlock(world, i + 24, j + 0, k + 5, ModBlocks.karosHeatTileRed);
		setBlock(world, i + 24, j + 0, k + 6, ModBlocks.karosHeatTileGreen);
		setBlock(world, i + 24, j + 0, k + 7, ModBlocks.karosHeatTileGreen);
		setBlock(world, i + 24, j + 0, k + 8, ModBlocks.karosHeatTileRed);
		setBlock(world, i + 24, j + 0, k + 9, ModBlocks.karosHeatTileRed);
		setBlock(world, i + 24, j + 0, k + 10, ModBlocks.karosHeatTileGreen);
		setBlock(world, i + 24, j + 0, k + 11, ModBlocks.karosHeatTileGreen);
		setBlock(world, i + 24, j + 0, k + 12, ModBlocks.karosHeatTileRed);
		setBlock(world, i + 24, j + 0, k + 13, ModBlocks.karosHeatTileRed);
		setBlock(world, i + 24, j + 0, k + 14, ModBlocks.karosHeatTileGreen);
		setBlock(world, i + 24, j + 0, k + 15, ModBlocks.karosHeatTileGreen);
		setBlock(world, i + 24, j + 0, k + 16, ModBlocks.karosHeatTileRed);
		setBlock(world, i + 24, j + 0, k + 17, ModBlocks.karosHeatTileRed);
		setBlock(world, i + 24, j + 0, k + 18, ModBlocks.blackKarosBricks);
		setBlock(world, i + 24, j + 0, k + 19, ModBlocks.blackKarosBricks);
		setBlock(world, i + 24, j + 1, k + 0, ModBlocks.blackKarosBricks);
		setBlock(world, i + 24, j + 1, k + 1, ModBlocks.blackKarosBricks);
		setBlock(world, i + 24, j + 1, k + 18, ModBlocks.blackKarosBricks);
		setBlock(world, i + 24, j + 1, k + 19, ModBlocks.blackKarosBricks);
		setBlock(world, i + 24, j + 2, k + 0, ModBlocks.blackKarosBricks);
		setBlock(world, i + 24, j + 2, k + 1, ModBlocks.karosDispenser);
		setBlock(world, i + 24, j + 2, k + 18, ModBlocks.karosDispenser);
		setBlock(world, i + 24, j + 2, k + 19, ModBlocks.blackKarosBricks);
		setBlock(world, i + 24, j + 3, k + 1, ModBlocks.blueKarosBricks);
		setBlock(world, i + 24, j + 3, k + 18, ModBlocks.blueKarosBricks);
		setBlock(world, i + 24, j + 4, k + 2, ModBlocks.blueKarosBricks);
		setBlock(world, i + 24, j + 4, k + 4, ModBlocks.helioticBeam);
		setBlock(world, i + 24, j + 4, k + 5, ModBlocks.helioticBeam);
		setBlock(world, i + 24, j + 4, k + 6, ModBlocks.helioticBeam);
		setBlock(world, i + 24, j + 4, k + 12, ModBlocks.helioticBeam);
		setBlock(world, i + 24, j + 4, k + 13, ModBlocks.helioticBeam);
		setBlock(world, i + 24, j + 4, k + 14, ModBlocks.helioticBeam);
		setBlock(world, i + 24, j + 4, k + 17, ModBlocks.blueKarosBricks);
		setBlock(world, i + 24, j + 5, k + 3, ModBlocks.blueKarosBricks);
		setBlock(world, i + 24, j + 5, k + 4, ModBlocks.blackKarosBricks);
		setBlock(world, i + 24, j + 5, k + 5, ModBlocks.blueKarosBricks);
		setBlock(world, i + 24, j + 5, k + 6, ModBlocks.blackKarosBricks);
		setBlock(world, i + 24, j + 5, k + 7, ModBlocks.blackKarosBricks);
		setBlock(world, i + 24, j + 5, k + 8, ModBlocks.blackKarosBricks);
		setBlock(world, i + 24, j + 5, k + 9, ModBlocks.blackKarosBricks);
		setBlock(world, i + 24, j + 5, k + 10, ModBlocks.blackKarosBricks);
		setBlock(world, i + 24, j + 5, k + 11, ModBlocks.blackKarosBricks);
		setBlock(world, i + 24, j + 5, k + 12, ModBlocks.blackKarosBricks);
		setBlock(world, i + 24, j + 5, k + 13, ModBlocks.blackKarosBricks);
		setBlock(world, i + 24, j + 5, k + 14, ModBlocks.blueKarosBricks);
		setBlock(world, i + 24, j + 5, k + 15, ModBlocks.blackKarosBricks);
		setBlock(world, i + 24, j + 5, k + 16, ModBlocks.blueKarosBricks);
		setBlock(world, i + 25, j + 0, k + 1, ModBlocks.blackKarosBricks);
		setBlock(world, i + 25, j + 0, k + 2, ModBlocks.karosHeatTileRed);
		setBlock(world, i + 25, j + 0, k + 3, ModBlocks.karosHeatTileRed);
		setBlock(world, i + 25, j + 0, k + 4, ModBlocks.karosHeatTileGreen);
		setBlock(world, i + 25, j + 0, k + 5, ModBlocks.karosHeatTileGreen);
		setBlock(world, i + 25, j + 0, k + 6, ModBlocks.karosHeatTileRed);
		setBlock(world, i + 25, j + 0, k + 7, ModBlocks.karosHeatTileRed);
		setBlock(world, i + 25, j + 0, k + 8, ModBlocks.karosHeatTileGreen);
		setBlock(world, i + 25, j + 0, k + 9, ModBlocks.karosHeatTileGreen);
		setBlock(world, i + 25, j + 0, k + 10, ModBlocks.karosHeatTileRed);
		setBlock(world, i + 25, j + 0, k + 11, ModBlocks.karosHeatTileRed);
		setBlock(world, i + 25, j + 0, k + 12, ModBlocks.karosHeatTileGreen);
		setBlock(world, i + 25, j + 0, k + 13, ModBlocks.karosHeatTileGreen);
		setBlock(world, i + 25, j + 0, k + 14, ModBlocks.karosHeatTileRed);
		setBlock(world, i + 25, j + 0, k + 15, ModBlocks.karosHeatTileRed);
		setBlock(world, i + 25, j + 0, k + 16, ModBlocks.karosHeatTileGreen);
		setBlock(world, i + 25, j + 0, k + 17, ModBlocks.karosHeatTileGreen);
		setBlock(world, i + 25, j + 0, k + 18, ModBlocks.blackKarosBricks);
		setBlock(world, i + 25, j + 1, k + 1, ModBlocks.blackKarosBricks);
		setBlock(world, i + 25, j + 1, k + 18, ModBlocks.blackKarosBricks);
		setBlock(world, i + 25, j + 2, k + 1, ModBlocks.blueKarosBricks);
		setBlock(world, i + 25, j + 2, k + 18, ModBlocks.blueKarosBricks);
		setBlock(world, i + 25, j + 3, k + 1, ModBlocks.blueKarosBricks);
		setBlock(world, i + 25, j + 3, k + 18, ModBlocks.blueKarosBricks);
		setBlock(world, i + 25, j + 4, k + 2, ModBlocks.blueKarosBricks);
		setBlock(world, i + 25, j + 4, k + 4, ModBlocks.helioticBeam);
		setBlock(world, i + 25, j + 4, k + 5, ModBlocks.helioticBeam);
		setBlock(world, i + 25, j + 4, k + 6, ModBlocks.helioticBeam);
		setBlock(world, i + 25, j + 4, k + 17, ModBlocks.blueKarosBricks);
		setBlock(world, i + 25, j + 5, k + 3, ModBlocks.blueKarosBricks);
		setBlock(world, i + 25, j + 5, k + 4, ModBlocks.blackKarosBricks);
		setBlock(world, i + 25, j + 5, k + 5, ModBlocks.blueKarosBricks);
		setBlock(world, i + 25, j + 5, k + 6, ModBlocks.blueKarosBricks);
		setBlock(world, i + 25, j + 5, k + 7, ModBlocks.blueKarosBricks);
		setBlock(world, i + 25, j + 5, k + 8, ModBlocks.blueKarosBricks);
		setBlock(world, i + 25, j + 5, k + 9, ModBlocks.blueKarosBricks);
		setBlock(world, i + 25, j + 5, k + 10, ModBlocks.blueKarosBricks);
		setBlock(world, i + 25, j + 5, k + 11, ModBlocks.blueKarosBricks);
		setBlock(world, i + 25, j + 5, k + 12, ModBlocks.blueKarosBricks);
		setBlock(world, i + 25, j + 5, k + 13, ModBlocks.blueKarosBricks);
		setBlock(world, i + 25, j + 5, k + 14, ModBlocks.blueKarosBricks);
		setBlock(world, i + 25, j + 5, k + 15, ModBlocks.blackKarosBricks);
		setBlock(world, i + 25, j + 5, k + 16, ModBlocks.blueKarosBricks);
		setBlock(world, i + 26, j + 0, k + 0, ModBlocks.blackKarosBricks);
		setBlock(world, i + 26, j + 0, k + 1, ModBlocks.blackKarosBricks);
		setBlock(world, i + 26, j + 0, k + 2, ModBlocks.karosHeatTileRed);
		setBlock(world, i + 26, j + 0, k + 3, ModBlocks.karosHeatTileRed);
		setBlock(world, i + 26, j + 0, k + 4, ModBlocks.karosHeatTileGreen);
		setBlock(world, i + 26, j + 0, k + 5, ModBlocks.karosHeatTileGreen);
		setBlock(world, i + 26, j + 0, k + 6, ModBlocks.karosHeatTileRed);
		setBlock(world, i + 26, j + 0, k + 7, ModBlocks.karosHeatTileRed);
		setBlock(world, i + 26, j + 0, k + 8, ModBlocks.karosHeatTileGreen);
		setBlock(world, i + 26, j + 0, k + 9, ModBlocks.karosHeatTileGreen);
		setBlock(world, i + 26, j + 0, k + 10, ModBlocks.karosHeatTileRed);
		setBlock(world, i + 26, j + 0, k + 11, ModBlocks.karosHeatTileRed);
		setBlock(world, i + 26, j + 0, k + 12, ModBlocks.karosHeatTileGreen);
		setBlock(world, i + 26, j + 0, k + 13, ModBlocks.karosHeatTileGreen);
		setBlock(world, i + 26, j + 0, k + 14, ModBlocks.karosHeatTileRed);
		setBlock(world, i + 26, j + 0, k + 15, ModBlocks.karosHeatTileRed);
		setBlock(world, i + 26, j + 0, k + 16, ModBlocks.karosHeatTileGreen);
		setBlock(world, i + 26, j + 0, k + 17, ModBlocks.karosHeatTileGreen);
		setBlock(world, i + 26, j + 0, k + 18, ModBlocks.blackKarosBricks);
		setBlock(world, i + 26, j + 0, k + 19, ModBlocks.blackKarosBricks);
		setBlock(world, i + 26, j + 1, k + 0, ModBlocks.blackKarosBricks);
		setBlock(world, i + 26, j + 1, k + 1, ModBlocks.blackKarosBricks);
		setBlock(world, i + 26, j + 1, k + 9, ModBlocks.villageLamp);
		setBlock(world, i + 26, j + 1, k + 10, ModBlocks.villageLamp);
		setBlock(world, i + 26, j + 1, k + 18, ModBlocks.blackKarosBricks);
		setBlock(world, i + 26, j + 1, k + 19, ModBlocks.blackKarosBricks);
		setBlock(world, i + 26, j + 2, k + 0, ModBlocks.blackKarosBricks);
		setBlock(world, i + 26, j + 2, k + 1, ModBlocks.karosDispenser);
		setBlock(world, i + 26, j + 2, k + 18, ModBlocks.karosDispenser);
		setBlock(world, i + 26, j + 2, k + 19, ModBlocks.blackKarosBricks);
		setBlock(world, i + 26, j + 3, k + 1, ModBlocks.blueKarosBricks);
		setBlock(world, i + 26, j + 3, k + 18, ModBlocks.blueKarosBricks);
		setBlock(world, i + 26, j + 4, k + 2, ModBlocks.blueKarosBricks);
		setBlock(world, i + 26, j + 4, k + 17, ModBlocks.blueKarosBricks);
		setBlock(world, i + 26, j + 5, k + 3, ModBlocks.blueKarosBricks);
		setBlock(world, i + 26, j + 5, k + 4, ModBlocks.blackKarosBricks);
		setBlock(world, i + 26, j + 5, k + 5, ModBlocks.blackKarosBricks);
		setBlock(world, i + 26, j + 5, k + 6, ModBlocks.blackKarosBricks);
		setBlock(world, i + 26, j + 5, k + 7, ModBlocks.blackKarosBricks);
		setBlock(world, i + 26, j + 5, k + 8, ModBlocks.blackKarosBricks);
		setBlock(world, i + 26, j + 5, k + 9, ModBlocks.blackKarosBricks);
		setBlock(world, i + 26, j + 5, k + 10, ModBlocks.blackKarosBricks);
		setBlock(world, i + 26, j + 5, k + 11, ModBlocks.blackKarosBricks);
		setBlock(world, i + 26, j + 5, k + 12, ModBlocks.blackKarosBricks);
		setBlock(world, i + 26, j + 5, k + 13, ModBlocks.blackKarosBricks);
		setBlock(world, i + 26, j + 5, k + 14, ModBlocks.blackKarosBricks);
		setBlock(world, i + 26, j + 5, k + 15, ModBlocks.blackKarosBricks);
		setBlock(world, i + 26, j + 5, k + 16, ModBlocks.blueKarosBricks);
		setBlock(world, i + 27, j + 0, k + 1, ModBlocks.blackKarosBricks);
		setBlock(world, i + 27, j + 0, k + 2, ModBlocks.karosHeatTileGreen);
		setBlock(world, i + 27, j + 0, k + 3, ModBlocks.karosHeatTileGreen);
		setBlock(world, i + 27, j + 0, k + 4, ModBlocks.karosHeatTileRed);
		setBlock(world, i + 27, j + 0, k + 5, ModBlocks.karosHeatTileRed);
		setBlock(world, i + 27, j + 0, k + 6, ModBlocks.karosHeatTileGreen);
		setBlock(world, i + 27, j + 0, k + 7, ModBlocks.karosHeatTileGreen);
		setBlock(world, i + 27, j + 0, k + 8, ModBlocks.karosHeatTileRed);
		setBlock(world, i + 27, j + 0, k + 9, ModBlocks.karosHeatTileRed);
		setBlock(world, i + 27, j + 0, k + 10, ModBlocks.karosHeatTileGreen);
		setBlock(world, i + 27, j + 0, k + 11, ModBlocks.karosHeatTileGreen);
		setBlock(world, i + 27, j + 0, k + 12, ModBlocks.karosHeatTileRed);
		setBlock(world, i + 27, j + 0, k + 13, ModBlocks.karosHeatTileRed);
		setBlock(world, i + 27, j + 0, k + 14, ModBlocks.karosHeatTileGreen);
		setBlock(world, i + 27, j + 0, k + 15, ModBlocks.karosHeatTileGreen);
		setBlock(world, i + 27, j + 0, k + 16, ModBlocks.karosHeatTileRed);
		setBlock(world, i + 27, j + 0, k + 17, ModBlocks.karosHeatTileRed);
		setBlock(world, i + 27, j + 0, k + 18, ModBlocks.blackKarosBricks);
		setBlock(world, i + 27, j + 1, k + 1, ModBlocks.blackKarosBricks);
		setBlock(world, i + 27, j + 1, k + 9, ModBlocks.villageLamp);
		setBlock(world, i + 27, j + 1, k + 10, ModBlocks.villageLamp);
		setBlock(world, i + 27, j + 1, k + 18, ModBlocks.blackKarosBricks);
		setBlock(world, i + 27, j + 2, k + 1, ModBlocks.blueKarosBricks);
		setBlock(world, i + 27, j + 2, k + 9, ModBlocks.karosAltar);
		setBlock(world, i + 27, j + 2, k + 18, ModBlocks.blueKarosBricks);
		setBlock(world, i + 27, j + 3, k + 1, ModBlocks.blueKarosBricks);
		setBlock(world, i + 27, j + 3, k + 18, ModBlocks.blueKarosBricks);
		setBlock(world, i + 27, j + 4, k + 2, ModBlocks.blueKarosBricks);
		setBlock(world, i + 27, j + 4, k + 17, ModBlocks.blueKarosBricks);
		setBlock(world, i + 27, j + 5, k + 3, ModBlocks.blueKarosBricks);
		setBlock(world, i + 27, j + 5, k + 4, ModBlocks.blueKarosBricks);
		setBlock(world, i + 27, j + 5, k + 5, ModBlocks.blueKarosBricks);
		setBlock(world, i + 27, j + 5, k + 6, ModBlocks.blueKarosBricks);
		setBlock(world, i + 27, j + 5, k + 7, ModBlocks.blueKarosBricks);
		setBlock(world, i + 27, j + 5, k + 8, ModBlocks.blueKarosBricks);
		setBlock(world, i + 27, j + 5, k + 9, ModBlocks.blueKarosBricks);
		setBlock(world, i + 27, j + 5, k + 10, ModBlocks.blueKarosBricks);
		setBlock(world, i + 27, j + 5, k + 11, ModBlocks.blueKarosBricks);
		setBlock(world, i + 27, j + 5, k + 12, ModBlocks.blueKarosBricks);
		setBlock(world, i + 27, j + 5, k + 13, ModBlocks.blueKarosBricks);
		setBlock(world, i + 27, j + 5, k + 14, ModBlocks.blueKarosBricks);
		setBlock(world, i + 27, j + 5, k + 15, ModBlocks.blueKarosBricks);
		setBlock(world, i + 27, j + 5, k + 16, ModBlocks.blueKarosBricks);
		setBlock(world, i + 28, j + 0, k + 0, ModBlocks.blackKarosBricks);
		setBlock(world, i + 28, j + 0, k + 1, ModBlocks.blackKarosBricks);
		setBlock(world, i + 28, j + 0, k + 2, ModBlocks.karosHeatTileGreen);
		setBlock(world, i + 28, j + 0, k + 3, ModBlocks.karosHeatTileGreen);
		setBlock(world, i + 28, j + 0, k + 4, ModBlocks.karosHeatTileRed);
		setBlock(world, i + 28, j + 0, k + 5, ModBlocks.karosHeatTileRed);
		setBlock(world, i + 28, j + 0, k + 6, ModBlocks.karosHeatTileGreen);
		setBlock(world, i + 28, j + 0, k + 7, ModBlocks.karosHeatTileGreen);
		setBlock(world, i + 28, j + 0, k + 8, ModBlocks.karosHeatTileRed);
		setBlock(world, i + 28, j + 0, k + 9, ModBlocks.karosHeatTileRed);
		setBlock(world, i + 28, j + 0, k + 10, ModBlocks.karosHeatTileGreen);
		setBlock(world, i + 28, j + 0, k + 11, ModBlocks.karosHeatTileGreen);
		setBlock(world, i + 28, j + 0, k + 12, ModBlocks.karosHeatTileRed);
		setBlock(world, i + 28, j + 0, k + 13, ModBlocks.karosHeatTileRed);
		setBlock(world, i + 28, j + 0, k + 14, ModBlocks.karosHeatTileGreen);
		setBlock(world, i + 28, j + 0, k + 15, ModBlocks.karosHeatTileGreen);
		setBlock(world, i + 28, j + 0, k + 16, ModBlocks.karosHeatTileRed);
		setBlock(world, i + 28, j + 0, k + 17, ModBlocks.karosHeatTileRed);
		setBlock(world, i + 28, j + 0, k + 18, ModBlocks.blackKarosBricks);
		setBlock(world, i + 28, j + 0, k + 19, ModBlocks.blackKarosBricks);
		setBlock(world, i + 28, j + 1, k + 0, ModBlocks.blackKarosBricks);
		setBlock(world, i + 28, j + 1, k + 1, ModBlocks.blackKarosBricks);
		setBlock(world, i + 28, j + 1, k + 9, ModBlocks.villageLamp);
		setBlock(world, i + 28, j + 1, k + 10, ModBlocks.villageLamp);
		setBlock(world, i + 28, j + 1, k + 18, ModBlocks.blackKarosBricks);
		setBlock(world, i + 28, j + 1, k + 19, ModBlocks.blackKarosBricks);
		setBlock(world, i + 28, j + 2, k + 0, ModBlocks.blackKarosBricks);
		setBlock(world, i + 28, j + 2, k + 1, ModBlocks.karosDispenser);
		setBlock(world, i + 28, j + 2, k + 18, ModBlocks.karosDispenser);
		setBlock(world, i + 28, j + 2, k + 19, ModBlocks.blackKarosBricks);
		setBlock(world, i + 28, j + 3, k + 1, ModBlocks.blueKarosBricks);
		setBlock(world, i + 28, j + 3, k + 9, ModBlocks.karosDispenser);
		setBlock(world, i + 28, j + 3, k + 10, ModBlocks.karosDispenser);
		setBlock(world, i + 28, j + 3, k + 18, ModBlocks.blueKarosBricks);
		setBlock(world, i + 28, j + 4, k + 2, ModBlocks.blueKarosBricks);
		setBlock(world, i + 28, j + 4, k + 3, ModBlocks.blueKarosBricks);
		setBlock(world, i + 28, j + 4, k + 4, ModBlocks.blueKarosBricks);
		setBlock(world, i + 28, j + 4, k + 5, ModBlocks.blueKarosBricks);
		setBlock(world, i + 28, j + 4, k + 6, ModBlocks.blueKarosBricks);
		setBlock(world, i + 28, j + 4, k + 7, ModBlocks.blueKarosBricks);
		setBlock(world, i + 28, j + 4, k + 8, ModBlocks.blueKarosBricks);
		setBlock(world, i + 28, j + 4, k + 9, ModBlocks.blueKarosBricks);
		setBlock(world, i + 28, j + 4, k + 10, ModBlocks.blueKarosBricks);
		setBlock(world, i + 28, j + 4, k + 11, ModBlocks.blueKarosBricks);
		setBlock(world, i + 28, j + 4, k + 12, ModBlocks.blueKarosBricks);
		setBlock(world, i + 28, j + 4, k + 13, ModBlocks.blueKarosBricks);
		setBlock(world, i + 28, j + 4, k + 14, ModBlocks.blueKarosBricks);
		setBlock(world, i + 28, j + 4, k + 15, ModBlocks.blueKarosBricks);
		setBlock(world, i + 28, j + 4, k + 16, ModBlocks.blueKarosBricks);
		setBlock(world, i + 28, j + 4, k + 17, ModBlocks.blueKarosBricks);
		setBlock(world, i + 29, j + 0, k + 1, ModBlocks.blackKarosBricks);
		setBlock(world, i + 29, j + 0, k + 2, ModBlocks.blackKarosBricks);
		setBlock(world, i + 29, j + 0, k + 3, ModBlocks.blackKarosBricks);
		setBlock(world, i + 29, j + 0, k + 4, ModBlocks.blackKarosBricks);
		setBlock(world, i + 29, j + 0, k + 5, ModBlocks.blackKarosBricks);
		setBlock(world, i + 29, j + 0, k + 6, ModBlocks.blackKarosBricks);
		setBlock(world, i + 29, j + 0, k + 7, ModBlocks.blackKarosBricks);
		setBlock(world, i + 29, j + 0, k + 8, ModBlocks.blackKarosBricks);
		setBlock(world, i + 29, j + 0, k + 9, ModBlocks.blackKarosBricks);
		setBlock(world, i + 29, j + 0, k + 10, ModBlocks.blackKarosBricks);
		setBlock(world, i + 29, j + 0, k + 11, ModBlocks.blackKarosBricks);
		setBlock(world, i + 29, j + 0, k + 12, ModBlocks.blackKarosBricks);
		setBlock(world, i + 29, j + 0, k + 13, ModBlocks.blackKarosBricks);
		setBlock(world, i + 29, j + 0, k + 14, ModBlocks.blackKarosBricks);
		setBlock(world, i + 29, j + 0, k + 15, ModBlocks.blackKarosBricks);
		setBlock(world, i + 29, j + 0, k + 16, ModBlocks.blackKarosBricks);
		setBlock(world, i + 29, j + 0, k + 17, ModBlocks.blackKarosBricks);
		setBlock(world, i + 29, j + 0, k + 18, ModBlocks.blackKarosBricks);
		setBlock(world, i + 29, j + 1, k + 1, ModBlocks.blackKarosBricks);
		setBlock(world, i + 29, j + 1, k + 2, ModBlocks.blackKarosBricks);
		setBlock(world, i + 29, j + 1, k + 3, ModBlocks.blackKarosBricks);
		setBlock(world, i + 29, j + 1, k + 4, ModBlocks.blackKarosBricks);
		setBlock(world, i + 29, j + 1, k + 5, ModBlocks.blackKarosBricks);
		setBlock(world, i + 29, j + 1, k + 6, ModBlocks.blackKarosBricks);
		setBlock(world, i + 29, j + 1, k + 7, ModBlocks.blackKarosBricks);
		setBlock(world, i + 29, j + 1, k + 8, ModBlocks.blackKarosBricks);
		setBlock(world, i + 29, j + 1, k + 9, ModBlocks.blackKarosBricks);
		setBlock(world, i + 29, j + 1, k + 10, ModBlocks.blackKarosBricks);
		setBlock(world, i + 29, j + 1, k + 11, ModBlocks.blackKarosBricks);
		setBlock(world, i + 29, j + 1, k + 12, ModBlocks.blackKarosBricks);
		setBlock(world, i + 29, j + 1, k + 13, ModBlocks.blackKarosBricks);
		setBlock(world, i + 29, j + 1, k + 14, ModBlocks.blackKarosBricks);
		setBlock(world, i + 29, j + 1, k + 15, ModBlocks.blackKarosBricks);
		setBlock(world, i + 29, j + 1, k + 16, ModBlocks.blackKarosBricks);
		setBlock(world, i + 29, j + 1, k + 17, ModBlocks.blackKarosBricks);
		setBlock(world, i + 29, j + 1, k + 18, ModBlocks.blackKarosBricks);
		setBlock(world, i + 29, j + 2, k + 1, ModBlocks.blueKarosBricks);
		setBlock(world, i + 29, j + 2, k + 2, ModBlocks.karosDispenser);
		setBlock(world, i + 29, j + 2, k + 3, ModBlocks.blueKarosBricks);
		setBlock(world, i + 29, j + 2, k + 4, ModBlocks.karosDispenser);
		setBlock(world, i + 29, j + 2, k + 5, ModBlocks.blueKarosBricks);
		setBlock(world, i + 29, j + 2, k + 6, ModBlocks.karosDispenser);
		setBlock(world, i + 29, j + 2, k + 7, ModBlocks.blueKarosBricks);
		setBlock(world, i + 29, j + 2, k + 8, ModBlocks.karosDispenser);
		setBlock(world, i + 29, j + 2, k + 9, ModBlocks.karosDispenser);
		setBlock(world, i + 29, j + 2, k + 10, ModBlocks.karosDispenser);
		setBlock(world, i + 29, j + 2, k + 11, ModBlocks.karosDispenser);
		setBlock(world, i + 29, j + 2, k + 12, ModBlocks.blueKarosBricks);
		setBlock(world, i + 29, j + 2, k + 13, ModBlocks.karosDispenser);
		setBlock(world, i + 29, j + 2, k + 14, ModBlocks.blueKarosBricks);
		setBlock(world, i + 29, j + 2, k + 15, ModBlocks.karosDispenser);
		setBlock(world, i + 29, j + 2, k + 16, ModBlocks.blueKarosBricks);
		setBlock(world, i + 29, j + 2, k + 17, ModBlocks.karosDispenser);
		setBlock(world, i + 29, j + 2, k + 18, ModBlocks.blueKarosBricks);
		setBlock(world, i + 29, j + 3, k + 1, ModBlocks.blueKarosBricks);
		setBlock(world, i + 29, j + 3, k + 2, ModBlocks.blueKarosBricks);
		setBlock(world, i + 29, j + 3, k + 3, ModBlocks.blueKarosBricks);
		setBlock(world, i + 29, j + 3, k + 4, ModBlocks.blueKarosBricks);
		setBlock(world, i + 29, j + 3, k + 5, ModBlocks.blueKarosBricks);
		setBlock(world, i + 29, j + 3, k + 6, ModBlocks.blueKarosBricks);
		setBlock(world, i + 29, j + 3, k + 7, ModBlocks.blueKarosBricks);
		setBlock(world, i + 29, j + 3, k + 8, ModBlocks.blueKarosBricks);
		setBlock(world, i + 29, j + 3, k + 9, ModBlocks.blueKarosBricks);
		setBlock(world, i + 29, j + 3, k + 10, ModBlocks.blueKarosBricks);
		setBlock(world, i + 29, j + 3, k + 11, ModBlocks.blueKarosBricks);
		setBlock(world, i + 29, j + 3, k + 12, ModBlocks.blueKarosBricks);
		setBlock(world, i + 29, j + 3, k + 13, ModBlocks.blueKarosBricks);
		setBlock(world, i + 29, j + 3, k + 14, ModBlocks.blueKarosBricks);
		setBlock(world, i + 29, j + 3, k + 15, ModBlocks.blueKarosBricks);
		setBlock(world, i + 29, j + 3, k + 16, ModBlocks.blueKarosBricks);
		setBlock(world, i + 29, j + 3, k + 17, ModBlocks.blueKarosBricks);
		setBlock(world, i + 29, j + 3, k + 18, ModBlocks.blueKarosBricks);
		setBlock(world, i + 30, j + 0, k + 2, ModBlocks.blackKarosBricks);
		setBlock(world, i + 30, j + 0, k + 4, ModBlocks.blackKarosBricks);
		setBlock(world, i + 30, j + 0, k + 6, ModBlocks.blackKarosBricks);
		setBlock(world, i + 30, j + 0, k + 8, ModBlocks.blackKarosBricks);
		setBlock(world, i + 30, j + 0, k + 11, ModBlocks.blackKarosBricks);
		setBlock(world, i + 30, j + 0, k + 13, ModBlocks.blackKarosBricks);
		setBlock(world, i + 30, j + 0, k + 15, ModBlocks.blackKarosBricks);
		setBlock(world, i + 30, j + 0, k + 17, ModBlocks.blackKarosBricks);
		setBlock(world, i + 30, j + 1, k + 2, ModBlocks.blackKarosBricks);
		setBlock(world, i + 30, j + 1, k + 4, ModBlocks.blackKarosBricks);
		setBlock(world, i + 30, j + 1, k + 6, ModBlocks.blackKarosBricks);
		setBlock(world, i + 30, j + 1, k + 8, ModBlocks.blackKarosBricks);
		setBlock(world, i + 30, j + 1, k + 11, ModBlocks.blackKarosBricks);
		setBlock(world, i + 30, j + 1, k + 13, ModBlocks.blackKarosBricks);
		setBlock(world, i + 30, j + 1, k + 15, ModBlocks.blackKarosBricks);
		setBlock(world, i + 30, j + 1, k + 17, ModBlocks.blackKarosBricks);
		setBlock(world, i + 30, j + 2, k + 2, ModBlocks.blackKarosBricks);
		setBlock(world, i + 30, j + 2, k + 4, ModBlocks.blackKarosBricks);
		setBlock(world, i + 30, j + 2, k + 6, ModBlocks.blackKarosBricks);
		setBlock(world, i + 30, j + 2, k + 8, ModBlocks.blackKarosBricks);
		setBlock(world, i + 30, j + 2, k + 9, ModBlocks.blackKarosBricks);
		setBlock(world, i + 30, j + 2, k + 10, ModBlocks.blackKarosBricks);
		setBlock(world, i + 30, j + 2, k + 11, ModBlocks.blackKarosBricks);
		setBlock(world, i + 30, j + 2, k + 13, ModBlocks.blackKarosBricks);
		setBlock(world, i + 30, j + 2, k + 15, ModBlocks.blackKarosBricks);
		setBlock(world, i + 30, j + 2, k + 17, ModBlocks.blackKarosBricks);

		return true;
	}
}