/*
*** MADE BY MITHION'S .SCHEMATIC TO JAVA CONVERTING TOOL v1.6 ***
*/

package divinerpg.dimensions.vethea.layer3;
import java.util.Random;

import divinerpg.dimensions.vethea.VetheaWorldGenerator;
import divinerpg.registry.ModBlocks;
import net.minecraft.block.Block;
import net.minecraft.util.math.BlockPos;
import net.minecraft.world.World;
import net.minecraft.world.gen.feature.WorldGenerator;

public class Tree8 extends VetheaWorldGenerator
{
	protected int[] GetValidSpawnBlocks() {
		return new int[] {
		};
	}

	public boolean generate(World world, Random rand, int i, int j, int k) {

		setBlock(world, i + 0, j + 14, k + 2, ModBlocks.mintwoodLeaves);
		setBlock(world, i + 0, j + 14, k + 3, ModBlocks.mintwoodLeaves);
		setBlock(world, i + 0, j + 14, k + 4, ModBlocks.mintwoodLeaves);
		setBlock(world, i + 0, j + 15, k + 2, ModBlocks.mintwoodLeaves);
		setBlock(world, i + 0, j + 15, k + 3, ModBlocks.mintwoodLeaves);
		setBlock(world, i + 0, j + 15, k + 4, ModBlocks.mintwoodLeaves);
		setBlock(world, i + 0, j + 16, k + 2, ModBlocks.mintwoodLeaves);
		setBlock(world, i + 0, j + 16, k + 3, ModBlocks.mintwoodLeaves);
		setBlock(world, i + 0, j + 16, k + 4, ModBlocks.mintwoodLeaves);
		setBlock(world, i + 1, j + 13, k + 2, ModBlocks.mintwoodLeaves);
		setBlock(world, i + 1, j + 13, k + 3, ModBlocks.mintwoodLeaves);
		setBlock(world, i + 1, j + 13, k + 4, ModBlocks.mintwoodLeaves);
		setBlock(world, i + 1, j + 13, k + 5, ModBlocks.mintwoodLeaves);
		setBlock(world, i + 1, j + 13, k + 6, ModBlocks.mintwoodLeaves);
		setBlock(world, i + 1, j + 13, k + 7, ModBlocks.mintwoodLeaves);
		setBlock(world, i + 1, j + 14, k + 1, ModBlocks.mintwoodLeaves);
		setBlock(world, i + 1, j + 14, k + 2, ModBlocks.mintwoodLeaves);
		setBlock(world, i + 1, j + 14, k + 3, ModBlocks.mintwoodLeaves);
		setBlock(world, i + 1, j + 14, k + 4, ModBlocks.mintwoodLeaves);
		setBlock(world, i + 1, j + 14, k + 5, ModBlocks.mintwoodLeaves);
		setBlock(world, i + 1, j + 14, k + 6, ModBlocks.mintwoodLeaves);
		setBlock(world, i + 1, j + 14, k + 7, ModBlocks.mintwoodLeaves);
		setBlock(world, i + 1, j + 14, k + 8, ModBlocks.mintwoodLeaves);
		setBlock(world, i + 1, j + 15, k + 1, ModBlocks.mintwoodLeaves);
		setBlock(world, i + 1, j + 15, k + 2, ModBlocks.mintwoodLeaves);
		setBlock(world, i + 1, j + 15, k + 3, ModBlocks.mintwoodLeaves);
		setBlock(world, i + 1, j + 15, k + 4, ModBlocks.mintwoodLeaves);
		setBlock(world, i + 1, j + 15, k + 5, ModBlocks.mintwoodLeaves);
		setBlock(world, i + 1, j + 15, k + 6, ModBlocks.mintwoodLeaves);
		setBlock(world, i + 1, j + 15, k + 7, ModBlocks.mintwoodLeaves);
		setBlock(world, i + 1, j + 15, k + 8, ModBlocks.mintwoodLeaves);
		setBlock(world, i + 1, j + 16, k + 1, ModBlocks.mintwoodLeaves);
		setBlock(world, i + 1, j + 16, k + 2, ModBlocks.mintwoodLeaves);
		setBlock(world, i + 1, j + 16, k + 3, ModBlocks.mintwoodLeaves);
		setBlock(world, i + 1, j + 16, k + 4, ModBlocks.mintwoodLeaves);
		setBlock(world, i + 1, j + 16, k + 5, ModBlocks.mintwoodLeaves);
		setBlock(world, i + 1, j + 16, k + 6, ModBlocks.mintwoodLeaves);
		setBlock(world, i + 1, j + 16, k + 7, ModBlocks.mintwoodLeaves);
		setBlock(world, i + 1, j + 16, k + 8, ModBlocks.mintwoodLeaves);
		setBlock(world, i + 1, j + 17, k + 2, ModBlocks.mintwoodLeaves);
		setBlock(world, i + 1, j + 17, k + 3, ModBlocks.mintwoodLeaves);
		setBlock(world, i + 1, j + 17, k + 4, ModBlocks.mintwoodLeaves);
		setBlock(world, i + 1, j + 17, k + 5, ModBlocks.mintwoodLeaves);
		setBlock(world, i + 1, j + 17, k + 6, ModBlocks.mintwoodLeaves);
		setBlock(world, i + 1, j + 17, k + 7, ModBlocks.mintwoodLeaves);
		setBlock(world, i + 2, j + 12, k + 4, ModBlocks.mintwoodLeaves);
		setBlock(world, i + 2, j + 12, k + 5, ModBlocks.mintwoodLeaves);
		setBlock(world, i + 2, j + 12, k + 6, ModBlocks.mintwoodLeaves);
		setBlock(world, i + 2, j + 12, k + 7, ModBlocks.mintwoodLeaves);
		setBlock(world, i + 2, j + 12, k + 8, ModBlocks.mintwoodLeaves);
		setBlock(world, i + 2, j + 13, k + 2, ModBlocks.mintwoodLeaves);
		setBlock(world, i + 2, j + 13, k + 3, ModBlocks.mintwoodLeaves);
		setBlock(world, i + 2, j + 13, k + 4, ModBlocks.mintwoodLeaves);
		setBlock(world, i + 2, j + 13, k + 5, ModBlocks.mintwoodLeaves);
		setBlock(world, i + 2, j + 13, k + 6, ModBlocks.mintwoodLeaves);
		setBlock(world, i + 2, j + 13, k + 7, ModBlocks.mintwoodLeaves);
		setBlock(world, i + 2, j + 13, k + 8, ModBlocks.mintwoodLeaves);
		setBlock(world, i + 2, j + 13, k + 9, ModBlocks.mintwoodLeaves);
		setBlock(world, i + 2, j + 14, k + 1, ModBlocks.mintwoodLeaves);
		setBlock(world, i + 2, j + 14, k + 2, ModBlocks.mintwoodLeaves);
		setBlock(world, i + 2, j + 14, k + 3, ModBlocks.mintwoodLeaves);
		setBlock(world, i + 2, j + 14, k + 4, ModBlocks.mintwoodLeaves);
		setBlock(world, i + 2, j + 14, k + 5, ModBlocks.mintwoodLeaves);
		setBlock(world, i + 2, j + 14, k + 6, ModBlocks.mintwoodLeaves);
		setBlock(world, i + 2, j + 14, k + 7, ModBlocks.mintwoodLeaves);
		setBlock(world, i + 2, j + 14, k + 8, ModBlocks.mintwoodLeaves);
		setBlock(world, i + 2, j + 14, k + 9, ModBlocks.mintwoodLeaves);
		setBlock(world, i + 2, j + 15, k + 1, ModBlocks.mintwoodLeaves);
		setBlock(world, i + 2, j + 15, k + 2, ModBlocks.mintwoodLeaves);
		setBlock(world, i + 2, j + 15, k + 3, ModBlocks.mintwoodLeaves);
		setBlock(world, i + 2, j + 15, k + 4, ModBlocks.mintwoodLeaves);
		setBlock(world, i + 2, j + 15, k + 5, ModBlocks.mintwoodLeaves);
		setBlock(world, i + 2, j + 15, k + 6, ModBlocks.mintwoodLeaves);
		setBlock(world, i + 2, j + 15, k + 7, ModBlocks.mintwoodLeaves);
		setBlock(world, i + 2, j + 15, k + 8, ModBlocks.mintwoodLeaves);
		setBlock(world, i + 2, j + 15, k + 9, ModBlocks.mintwoodLeaves);
		setBlock(world, i + 2, j + 16, k + 1, ModBlocks.mintwoodLeaves);
		setBlock(world, i + 2, j + 16, k + 2, ModBlocks.mintwoodLeaves);
		setBlock(world, i + 2, j + 16, k + 5, ModBlocks.mintwoodLeaves);
		setBlock(world, i + 2, j + 16, k + 6, ModBlocks.mintwoodLeaves);
		setBlock(world, i + 2, j + 16, k + 7, ModBlocks.mintwoodLeaves);
		setBlock(world, i + 2, j + 16, k + 8, ModBlocks.mintwoodLeaves);
		setBlock(world, i + 2, j + 16, k + 9, ModBlocks.mintwoodLeaves);
		setBlock(world, i + 2, j + 17, k + 2, ModBlocks.mintwoodLeaves);
		setBlock(world, i + 2, j + 17, k + 3, ModBlocks.mintwoodLeaves);
		setBlock(world, i + 2, j + 17, k + 4, ModBlocks.mintwoodLeaves);
		setBlock(world, i + 2, j + 17, k + 5, ModBlocks.mintwoodLeaves);
		setBlock(world, i + 2, j + 17, k + 6, ModBlocks.mintwoodLeaves);
		setBlock(world, i + 2, j + 17, k + 7, ModBlocks.mintwoodLeaves);
		setBlock(world, i + 2, j + 17, k + 8, ModBlocks.mintwoodLeaves);
		setBlock(world, i + 2, j + 17, k + 9, ModBlocks.mintwoodLeaves);
		setBlock(world, i + 2, j + 18, k + 4, ModBlocks.mintwoodLeaves);
		setBlock(world, i + 2, j + 18, k + 5, ModBlocks.mintwoodLeaves);
		setBlock(world, i + 2, j + 18, k + 6, ModBlocks.mintwoodLeaves);
		setBlock(world, i + 2, j + 18, k + 7, ModBlocks.mintwoodLeaves);
		setBlock(world, i + 2, j + 18, k + 8, ModBlocks.mintwoodLeaves);
		setBlock(world, i + 3, j + 11, k + 4, ModBlocks.mintwoodLeaves);
		setBlock(world, i + 3, j + 11, k + 5, ModBlocks.mintwoodLeaves);
		setBlock(world, i + 3, j + 11, k + 6, ModBlocks.mintwoodLeaves);
		setBlock(world, i + 3, j + 11, k + 7, ModBlocks.mintwoodLeaves);
		setBlock(world, i + 3, j + 11, k + 8, ModBlocks.mintwoodLeaves);
		setBlock(world, i + 3, j + 12, k + 3, ModBlocks.mintwoodLeaves);
		setBlock(world, i + 3, j + 12, k + 4, ModBlocks.mintwoodLeaves);
		setBlock(world, i + 3, j + 12, k + 5, ModBlocks.mintwoodLeaves);
		setBlock(world, i + 3, j + 12, k + 6, ModBlocks.mintwoodLeaves);
		setBlock(world, i + 3, j + 12, k + 7, ModBlocks.mintwoodLeaves);
		setBlock(world, i + 3, j + 12, k + 8, ModBlocks.mintwoodLeaves);
		setBlock(world, i + 3, j + 12, k + 9, ModBlocks.mintwoodLeaves);
		setBlock(world, i + 3, j + 13, k + 2, ModBlocks.mintwoodLeaves);
		setBlock(world, i + 3, j + 13, k + 3, ModBlocks.mintwoodLeaves);
		setBlock(world, i + 3, j + 13, k + 4, ModBlocks.mintwoodLeaves);
		setBlock(world, i + 3, j + 13, k + 5, ModBlocks.mintwoodLeaves);
		setBlock(world, i + 3, j + 13, k + 6, ModBlocks.mintwoodLeaves);
		setBlock(world, i + 3, j + 13, k + 7, ModBlocks.mintwoodLeaves);
		setBlock(world, i + 3, j + 13, k + 8, ModBlocks.mintwoodLeaves);
		setBlock(world, i + 3, j + 13, k + 9, ModBlocks.mintwoodLeaves);
		setBlock(world, i + 3, j + 13, k + 10, ModBlocks.mintwoodLeaves);
		setBlock(world, i + 3, j + 14, k + 1, ModBlocks.mintwoodLeaves);
		setBlock(world, i + 3, j + 14, k + 2, ModBlocks.mintwoodLeaves);
		setBlock(world, i + 3, j + 14, k + 3, ModBlocks.mintwoodLeaves);
		setBlock(world, i + 3, j + 14, k + 4, ModBlocks.mintwoodLeaves);
		setBlock(world, i + 3, j + 14, k + 5, ModBlocks.mintwoodLeaves);
		setBlock(world, i + 3, j + 14, k + 6, ModBlocks.mintwoodLeaves);
		setBlock(world, i + 3, j + 14, k + 7, ModBlocks.mintwoodLeaves);
		setBlock(world, i + 3, j + 14, k + 8, ModBlocks.mintwoodLeaves);
		setBlock(world, i + 3, j + 14, k + 9, ModBlocks.mintwoodLeaves);
		setBlock(world, i + 3, j + 14, k + 10, ModBlocks.mintwoodLeaves);
		setBlock(world, i + 3, j + 15, k + 1, ModBlocks.mintwoodLeaves);
		setBlock(world, i + 3, j + 15, k + 2, ModBlocks.mintwoodLeaves);
		setBlock(world, i + 3, j + 15, k + 4, ModBlocks.mintwoodLeaves);
		setBlock(world, i + 3, j + 15, k + 5, ModBlocks.mintwoodLeaves);
		setBlock(world, i + 3, j + 15, k + 6, ModBlocks.mintwoodLeaves);
		setBlock(world, i + 3, j + 15, k + 7, ModBlocks.mintwoodLeaves);
		setBlock(world, i + 3, j + 15, k + 8, ModBlocks.mintwoodLeaves);
		setBlock(world, i + 3, j + 15, k + 9, ModBlocks.mintwoodLeaves);
		setBlock(world, i + 3, j + 15, k + 10, ModBlocks.mintwoodLeaves);
		setBlock(world, i + 3, j + 16, k + 1, ModBlocks.mintwoodLeaves);
		setBlock(world, i + 3, j + 16, k + 2, ModBlocks.mintwoodLeaves);
		setBlock(world, i + 3, j + 16, k + 4, ModBlocks.mintwoodLeaves);
		setBlock(world, i + 3, j + 16, k + 5, ModBlocks.mintwoodLeaves);
		setBlock(world, i + 3, j + 16, k + 6, ModBlocks.mintwoodLeaves);
		setBlock(world, i + 3, j + 16, k + 7, ModBlocks.mintwoodLeaves);
		setBlock(world, i + 3, j + 16, k + 8, ModBlocks.mintwoodLeaves);
		setBlock(world, i + 3, j + 16, k + 9, ModBlocks.mintwoodLeaves);
		setBlock(world, i + 3, j + 16, k + 10, ModBlocks.mintwoodLeaves);
		setBlock(world, i + 3, j + 17, k + 2, ModBlocks.mintwoodLeaves);
		setBlock(world, i + 3, j + 17, k + 3, ModBlocks.mintwoodLeaves);
		setBlock(world, i + 3, j + 17, k + 4, ModBlocks.mintwoodLeaves);
		setBlock(world, i + 3, j + 17, k + 5, ModBlocks.mintwoodLeaves);
		setBlock(world, i + 3, j + 17, k + 6, ModBlocks.mintwoodLeaves);
		setBlock(world, i + 3, j + 17, k + 7, ModBlocks.mintwoodLeaves);
		setBlock(world, i + 3, j + 17, k + 8, ModBlocks.mintwoodLeaves);
		setBlock(world, i + 3, j + 17, k + 9, ModBlocks.mintwoodLeaves);
		setBlock(world, i + 3, j + 17, k + 10, ModBlocks.mintwoodLeaves);
		setBlock(world, i + 3, j + 18, k + 3, ModBlocks.mintwoodLeaves);
		setBlock(world, i + 3, j + 18, k + 4, ModBlocks.mintwoodLeaves);
		setBlock(world, i + 3, j + 18, k + 5, ModBlocks.mintwoodLeaves);
		setBlock(world, i + 3, j + 18, k + 6, ModBlocks.mintwoodLeaves);
		setBlock(world, i + 3, j + 18, k + 7, ModBlocks.mintwoodLeaves);
		setBlock(world, i + 3, j + 18, k + 8, ModBlocks.mintwoodLeaves);
		setBlock(world, i + 3, j + 18, k + 9, ModBlocks.mintwoodLeaves);
		setBlock(world, i + 3, j + 19, k + 4, ModBlocks.mintwoodLeaves);
		setBlock(world, i + 3, j + 19, k + 5, ModBlocks.mintwoodLeaves);
		setBlock(world, i + 3, j + 19, k + 6, ModBlocks.mintwoodLeaves);
		setBlock(world, i + 3, j + 19, k + 7, ModBlocks.mintwoodLeaves);
		setBlock(world, i + 3, j + 19, k + 8, ModBlocks.mintwoodLeaves);
		setBlock(world, i + 4, j + 0, k + 6, ModBlocks.mintwoodLog);
		setBlock(world, i + 4, j + 0, k + 7, ModBlocks.mintwoodLog);
		setBlock(world, i + 4, j + 1, k + 6, ModBlocks.mintwoodLog);
		setBlock(world, i + 4, j + 1, k + 7, ModBlocks.mintwoodLog);
		setBlock(world, i + 4, j + 2, k + 6, ModBlocks.mintwoodLog);
		setBlock(world, i + 4, j + 2, k + 7, ModBlocks.mintwoodLog);
		setBlock(world, i + 4, j + 3, k + 6, ModBlocks.mintwoodLog);
		setBlock(world, i + 4, j + 3, k + 7, ModBlocks.mintwoodLog);
		setBlock(world, i + 4, j + 4, k + 6, ModBlocks.mintwoodLog);
		setBlock(world, i + 4, j + 4, k + 7, ModBlocks.mintwoodLog);
		setBlock(world, i + 4, j + 5, k + 6, ModBlocks.mintwoodLog);
		setBlock(world, i + 4, j + 5, k + 7, ModBlocks.mintwoodLog);
		setBlock(world, i + 4, j + 6, k + 6, ModBlocks.mintwoodLog);
		setBlock(world, i + 4, j + 6, k + 7, ModBlocks.mintwoodLog);
		setBlock(world, i + 4, j + 7, k + 6, ModBlocks.mintwoodLog);
		setBlock(world, i + 4, j + 7, k + 7, ModBlocks.mintwoodLog);
		setBlock(world, i + 4, j + 8, k + 6, ModBlocks.mintwoodLog);
		setBlock(world, i + 4, j + 8, k + 7, ModBlocks.mintwoodLog);
		setBlock(world, i + 4, j + 9, k + 6, ModBlocks.mintwoodLog);
		setBlock(world, i + 4, j + 9, k + 7, ModBlocks.mintwoodLog);
		setBlock(world, i + 4, j + 10, k + 5, ModBlocks.mintwoodLeaves);
		setBlock(world, i + 4, j + 10, k + 6, ModBlocks.mintwoodLeaves);
		setBlock(world, i + 4, j + 10, k + 7, ModBlocks.mintwoodLeaves);
		setBlock(world, i + 4, j + 10, k + 8, ModBlocks.mintwoodLeaves);
		setBlock(world, i + 4, j + 11, k + 3, ModBlocks.mintwoodLeaves);
		setBlock(world, i + 4, j + 11, k + 4, ModBlocks.mintwoodLeaves);
		setBlock(world, i + 4, j + 11, k + 5, ModBlocks.mintwoodLeaves);
		setBlock(world, i + 4, j + 11, k + 6, ModBlocks.mintwoodLeaves);
		setBlock(world, i + 4, j + 11, k + 7, ModBlocks.mintwoodLeaves);
		setBlock(world, i + 4, j + 11, k + 8, ModBlocks.mintwoodLeaves);
		setBlock(world, i + 4, j + 11, k + 9, ModBlocks.mintwoodLeaves);
		setBlock(world, i + 4, j + 12, k + 2, ModBlocks.mintwoodLeaves);
		setBlock(world, i + 4, j + 12, k + 3, ModBlocks.mintwoodLeaves);
		setBlock(world, i + 4, j + 12, k + 4, ModBlocks.mintwoodLeaves);
		setBlock(world, i + 4, j + 12, k + 5, ModBlocks.mintwoodLeaves);
		setBlock(world, i + 4, j + 12, k + 6, ModBlocks.mintwoodLeaves);
		setBlock(world, i + 4, j + 12, k + 7, ModBlocks.mintwoodLeaves);
		setBlock(world, i + 4, j + 12, k + 8, ModBlocks.mintwoodLeaves);
		setBlock(world, i + 4, j + 12, k + 9, ModBlocks.mintwoodLeaves);
		setBlock(world, i + 4, j + 12, k + 10, ModBlocks.mintwoodLeaves);
		setBlock(world, i + 4, j + 13, k + 2, ModBlocks.mintwoodLeaves);
		setBlock(world, i + 4, j + 13, k + 3, ModBlocks.mintwoodLeaves);
		setBlock(world, i + 4, j + 13, k + 4, ModBlocks.mintwoodLeaves);
		setBlock(world, i + 4, j + 13, k + 5, ModBlocks.mintwoodLeaves);
		setBlock(world, i + 4, j + 13, k + 6, ModBlocks.mintwoodLeaves);
		setBlock(world, i + 4, j + 13, k + 7, ModBlocks.mintwoodLeaves);
		setBlock(world, i + 4, j + 13, k + 8, ModBlocks.mintwoodLeaves);
		setBlock(world, i + 4, j + 13, k + 9, ModBlocks.mintwoodLeaves);
		setBlock(world, i + 4, j + 13, k + 10, ModBlocks.mintwoodLeaves);
		setBlock(world, i + 4, j + 14, k + 1, ModBlocks.mintwoodLeaves);
		setBlock(world, i + 4, j + 14, k + 2, ModBlocks.mintwoodLeaves);
		setBlock(world, i + 4, j + 14, k + 3, ModBlocks.mintwoodLeaves);
		setBlock(world, i + 4, j + 14, k + 4, ModBlocks.mintwoodLeaves);
		setBlock(world, i + 4, j + 14, k + 5, ModBlocks.mintwoodLeaves);
		setBlock(world, i + 4, j + 14, k + 6, ModBlocks.mintwoodLeaves);
		setBlock(world, i + 4, j + 14, k + 7, ModBlocks.mintwoodLeaves);
		setBlock(world, i + 4, j + 14, k + 8, ModBlocks.mintwoodLeaves);
		setBlock(world, i + 4, j + 14, k + 9, ModBlocks.mintwoodLeaves);
		setBlock(world, i + 4, j + 14, k + 10, ModBlocks.mintwoodLeaves);
		setBlock(world, i + 4, j + 14, k + 11, ModBlocks.mintwoodLeaves);
		setBlock(world, i + 4, j + 15, k + 1, ModBlocks.mintwoodLeaves);
		setBlock(world, i + 4, j + 15, k + 2, ModBlocks.mintwoodLeaves);
		setBlock(world, i + 4, j + 15, k + 3, ModBlocks.mintwoodLeaves);
		setBlock(world, i + 4, j + 15, k + 4, ModBlocks.mintwoodLeaves);
		setBlock(world, i + 4, j + 15, k + 5, ModBlocks.mintwoodLeaves);
		setBlock(world, i + 4, j + 15, k + 6, ModBlocks.mintwoodLeaves);
		setBlock(world, i + 4, j + 15, k + 7, ModBlocks.mintwoodLeaves);
		setBlock(world, i + 4, j + 15, k + 8, ModBlocks.mintwoodLeaves);
		setBlock(world, i + 4, j + 15, k + 9, ModBlocks.mintwoodLeaves);
		setBlock(world, i + 4, j + 15, k + 10, ModBlocks.mintwoodLeaves);
		setBlock(world, i + 4, j + 15, k + 11, ModBlocks.mintwoodLeaves);
		setBlock(world, i + 4, j + 16, k + 1, ModBlocks.mintwoodLeaves);
		setBlock(world, i + 4, j + 16, k + 2, ModBlocks.mintwoodLeaves);
		setBlock(world, i + 4, j + 16, k + 3, ModBlocks.mintwoodLeaves);
		setBlock(world, i + 4, j + 16, k + 4, ModBlocks.mintwoodLeaves);
		setBlock(world, i + 4, j + 16, k + 5, ModBlocks.mintwoodLeaves);
		setBlock(world, i + 4, j + 16, k + 6, ModBlocks.mintwoodLeaves);
		setBlock(world, i + 4, j + 16, k + 7, ModBlocks.mintwoodLeaves);
		setBlock(world, i + 4, j + 16, k + 8, ModBlocks.mintwoodLeaves);
		setBlock(world, i + 4, j + 16, k + 9, ModBlocks.mintwoodLeaves);
		setBlock(world, i + 4, j + 16, k + 10, ModBlocks.mintwoodLeaves);
		setBlock(world, i + 4, j + 16, k + 11, ModBlocks.mintwoodLeaves);
		setBlock(world, i + 4, j + 17, k + 1, ModBlocks.mintwoodLeaves);
		setBlock(world, i + 4, j + 17, k + 2, ModBlocks.mintwoodLeaves);
		setBlock(world, i + 4, j + 17, k + 3, ModBlocks.mintwoodLeaves);
		setBlock(world, i + 4, j + 17, k + 4, ModBlocks.mintwoodLeaves);
		setBlock(world, i + 4, j + 17, k + 5, ModBlocks.mintwoodLeaves);
		setBlock(world, i + 4, j + 17, k + 6, ModBlocks.mintwoodLeaves);
		setBlock(world, i + 4, j + 17, k + 7, ModBlocks.mintwoodLeaves);
		setBlock(world, i + 4, j + 17, k + 8, ModBlocks.mintwoodLeaves);
		setBlock(world, i + 4, j + 17, k + 9, ModBlocks.mintwoodLeaves);
		setBlock(world, i + 4, j + 17, k + 10, ModBlocks.mintwoodLeaves);
		setBlock(world, i + 4, j + 18, k + 2, ModBlocks.mintwoodLeaves);
		setBlock(world, i + 4, j + 18, k + 3, ModBlocks.mintwoodLeaves);
		setBlock(world, i + 4, j + 18, k + 4, ModBlocks.mintwoodLeaves);
		setBlock(world, i + 4, j + 18, k + 5, ModBlocks.mintwoodLeaves);
		setBlock(world, i + 4, j + 18, k + 6, ModBlocks.mintwoodLeaves);
		setBlock(world, i + 4, j + 18, k + 7, ModBlocks.mintwoodLeaves);
		setBlock(world, i + 4, j + 18, k + 8, ModBlocks.mintwoodLeaves);
		setBlock(world, i + 4, j + 18, k + 9, ModBlocks.mintwoodLeaves);
		setBlock(world, i + 4, j + 18, k + 10, ModBlocks.mintwoodLeaves);
		setBlock(world, i + 4, j + 19, k + 3, ModBlocks.mintwoodLeaves);
		setBlock(world, i + 4, j + 19, k + 4, ModBlocks.mintwoodLeaves);
		setBlock(world, i + 4, j + 19, k + 5, ModBlocks.mintwoodLeaves);
		setBlock(world, i + 4, j + 19, k + 6, ModBlocks.mintwoodLeaves);
		setBlock(world, i + 4, j + 19, k + 7, ModBlocks.mintwoodLeaves);
		setBlock(world, i + 4, j + 19, k + 8, ModBlocks.mintwoodLeaves);
		setBlock(world, i + 4, j + 19, k + 9, ModBlocks.mintwoodLeaves);
		setBlock(world, i + 4, j + 20, k + 5, ModBlocks.mintwoodLeaves);
		setBlock(world, i + 4, j + 20, k + 6, ModBlocks.mintwoodLeaves);
		setBlock(world, i + 4, j + 20, k + 7, ModBlocks.mintwoodLeaves);
		setBlock(world, i + 5, j + 0, k + 6, ModBlocks.mintwoodLog);
		setBlock(world, i + 5, j + 0, k + 7, ModBlocks.mintwoodLog);
		setBlock(world, i + 5, j + 1, k + 6, ModBlocks.mintwoodLog);
		setBlock(world, i + 5, j + 1, k + 7, ModBlocks.mintwoodLog);
		setBlock(world, i + 5, j + 2, k + 6, ModBlocks.mintwoodLog);
		setBlock(world, i + 5, j + 2, k + 7, ModBlocks.mintwoodLog);
		setBlock(world, i + 5, j + 3, k + 6, ModBlocks.mintwoodLog);
		setBlock(world, i + 5, j + 3, k + 7, ModBlocks.mintwoodLog);
		setBlock(world, i + 5, j + 4, k + 6, ModBlocks.mintwoodLog);
		setBlock(world, i + 5, j + 4, k + 7, ModBlocks.mintwoodLog);
		setBlock(world, i + 5, j + 5, k + 6, ModBlocks.mintwoodLog);
		setBlock(world, i + 5, j + 5, k + 7, ModBlocks.mintwoodLog);
		setBlock(world, i + 5, j + 6, k + 6, ModBlocks.mintwoodLog);
		setBlock(world, i + 5, j + 6, k + 7, ModBlocks.mintwoodLog);
		setBlock(world, i + 5, j + 7, k + 6, ModBlocks.mintwoodLog);
		setBlock(world, i + 5, j + 7, k + 7, ModBlocks.mintwoodLog);
		setBlock(world, i + 5, j + 8, k + 6, ModBlocks.mintwoodLog);
		setBlock(world, i + 5, j + 8, k + 7, ModBlocks.mintwoodLog);
		setBlock(world, i + 5, j + 9, k + 5, ModBlocks.mintwoodLeaves);
		setBlock(world, i + 5, j + 9, k + 6, ModBlocks.mintwoodLog);
		setBlock(world, i + 5, j + 9, k + 7, ModBlocks.mintwoodLog);
		setBlock(world, i + 5, j + 9, k + 8, ModBlocks.mintwoodLeaves);
		setBlock(world, i + 5, j + 10, k + 4, ModBlocks.mintwoodLeaves);
		setBlock(world, i + 5, j + 10, k + 5, ModBlocks.mintwoodLeaves);
		setBlock(world, i + 5, j + 10, k + 6, ModBlocks.mintwoodLeaves);
		setBlock(world, i + 5, j + 10, k + 7, ModBlocks.mintwoodLeaves);
		setBlock(world, i + 5, j + 10, k + 8, ModBlocks.mintwoodLeaves);
		setBlock(world, i + 5, j + 11, k + 3, ModBlocks.mintwoodLeaves);
		setBlock(world, i + 5, j + 11, k + 4, ModBlocks.mintwoodLeaves);
		setBlock(world, i + 5, j + 11, k + 5, ModBlocks.mintwoodLeaves);
		setBlock(world, i + 5, j + 11, k + 6, ModBlocks.mintwoodLeaves);
		setBlock(world, i + 5, j + 11, k + 7, ModBlocks.mintwoodLeaves);
		setBlock(world, i + 5, j + 11, k + 8, ModBlocks.mintwoodLeaves);
		setBlock(world, i + 5, j + 11, k + 9, ModBlocks.mintwoodLeaves);
		setBlock(world, i + 5, j + 12, k + 2, ModBlocks.mintwoodLeaves);
		setBlock(world, i + 5, j + 12, k + 3, ModBlocks.mintwoodLeaves);
		setBlock(world, i + 5, j + 12, k + 4, ModBlocks.mintwoodLeaves);
		setBlock(world, i + 5, j + 12, k + 5, ModBlocks.mintwoodLeaves);
		setBlock(world, i + 5, j + 12, k + 6, ModBlocks.mintwoodLeaves);
		setBlock(world, i + 5, j + 12, k + 7, ModBlocks.mintwoodLeaves);
		setBlock(world, i + 5, j + 12, k + 8, ModBlocks.mintwoodLeaves);
		setBlock(world, i + 5, j + 12, k + 9, ModBlocks.mintwoodLeaves);
		setBlock(world, i + 5, j + 12, k + 10, ModBlocks.mintwoodLeaves);
		setBlock(world, i + 5, j + 12, k + 11, ModBlocks.mintwoodLeaves);
		setBlock(world, i + 5, j + 12, k + 12, ModBlocks.mintwoodLeaves);
		setBlock(world, i + 5, j + 13, k + 1, ModBlocks.mintwoodLeaves);
		setBlock(world, i + 5, j + 13, k + 2, ModBlocks.mintwoodLeaves);
		setBlock(world, i + 5, j + 13, k + 4, ModBlocks.mintwoodLeaves);
		setBlock(world, i + 5, j + 13, k + 5, ModBlocks.mintwoodLeaves);
		setBlock(world, i + 5, j + 13, k + 6, ModBlocks.mintwoodLeaves);
		setBlock(world, i + 5, j + 13, k + 7, ModBlocks.mintwoodLeaves);
		setBlock(world, i + 5, j + 13, k + 8, ModBlocks.mintwoodLeaves);
		setBlock(world, i + 5, j + 13, k + 9, ModBlocks.mintwoodLeaves);
		setBlock(world, i + 5, j + 13, k + 10, ModBlocks.mintwoodLeaves);
		setBlock(world, i + 5, j + 13, k + 11, ModBlocks.mintwoodLeaves);
		setBlock(world, i + 5, j + 13, k + 12, ModBlocks.mintwoodLeaves);
		setBlock(world, i + 5, j + 14, k + 1, ModBlocks.mintwoodLeaves);
		setBlock(world, i + 5, j + 14, k + 3, ModBlocks.mintwoodLeaves);
		setBlock(world, i + 5, j + 14, k + 5, ModBlocks.mintwoodLeaves);
		setBlock(world, i + 5, j + 14, k + 6, ModBlocks.mintwoodLeaves);
		setBlock(world, i + 5, j + 14, k + 7, ModBlocks.mintwoodLeaves);
		setBlock(world, i + 5, j + 14, k + 8, ModBlocks.mintwoodLeaves);
		setBlock(world, i + 5, j + 14, k + 9, ModBlocks.mintwoodLeaves);
		setBlock(world, i + 5, j + 14, k + 10, ModBlocks.mintwoodLeaves);
		setBlock(world, i + 5, j + 14, k + 11, ModBlocks.mintwoodLeaves);
		setBlock(world, i + 5, j + 14, k + 12, ModBlocks.mintwoodLeaves);
		setBlock(world, i + 5, j + 15, k + 1, ModBlocks.mintwoodLeaves);
		setBlock(world, i + 5, j + 15, k + 3, ModBlocks.mintwoodLeaves);
		setBlock(world, i + 5, j + 15, k + 5, ModBlocks.mintwoodLeaves);
		setBlock(world, i + 5, j + 15, k + 6, ModBlocks.mintwoodLeaves);
		setBlock(world, i + 5, j + 15, k + 7, ModBlocks.mintwoodLeaves);
		setBlock(world, i + 5, j + 15, k + 8, ModBlocks.mintwoodLeaves);
		setBlock(world, i + 5, j + 15, k + 9, ModBlocks.mintwoodLeaves);
		setBlock(world, i + 5, j + 15, k + 10, ModBlocks.mintwoodLeaves);
		setBlock(world, i + 5, j + 15, k + 11, ModBlocks.mintwoodLeaves);
		setBlock(world, i + 5, j + 16, k + 1, ModBlocks.mintwoodLeaves);
		setBlock(world, i + 5, j + 16, k + 2, ModBlocks.mintwoodLeaves);
		setBlock(world, i + 5, j + 16, k + 3, ModBlocks.mintwoodLeaves);
		setBlock(world, i + 5, j + 16, k + 4, ModBlocks.mintwoodLeaves);
		setBlock(world, i + 5, j + 16, k + 5, ModBlocks.mintwoodLeaves);
		setBlock(world, i + 5, j + 16, k + 6, ModBlocks.mintwoodLeaves);
		setBlock(world, i + 5, j + 16, k + 7, ModBlocks.mintwoodLeaves);
		setBlock(world, i + 5, j + 16, k + 8, ModBlocks.mintwoodLeaves);
		setBlock(world, i + 5, j + 16, k + 9, ModBlocks.mintwoodLeaves);
		setBlock(world, i + 5, j + 16, k + 10, ModBlocks.mintwoodLeaves);
		setBlock(world, i + 5, j + 16, k + 11, ModBlocks.mintwoodLeaves);
		setBlock(world, i + 5, j + 17, k + 1, ModBlocks.mintwoodLeaves);
		setBlock(world, i + 5, j + 17, k + 2, ModBlocks.mintwoodLeaves);
		setBlock(world, i + 5, j + 17, k + 3, ModBlocks.mintwoodLeaves);
		setBlock(world, i + 5, j + 17, k + 4, ModBlocks.mintwoodLeaves);
		setBlock(world, i + 5, j + 17, k + 5, ModBlocks.mintwoodLeaves);
		setBlock(world, i + 5, j + 17, k + 6, ModBlocks.mintwoodLeaves);
		setBlock(world, i + 5, j + 17, k + 7, ModBlocks.mintwoodLeaves);
		setBlock(world, i + 5, j + 17, k + 8, ModBlocks.mintwoodLeaves);
		setBlock(world, i + 5, j + 17, k + 9, ModBlocks.mintwoodLeaves);
		setBlock(world, i + 5, j + 17, k + 10, ModBlocks.mintwoodLeaves);
		setBlock(world, i + 5, j + 17, k + 11, ModBlocks.mintwoodLeaves);
		setBlock(world, i + 5, j + 18, k + 2, ModBlocks.mintwoodLeaves);
		setBlock(world, i + 5, j + 18, k + 3, ModBlocks.mintwoodLeaves);
		setBlock(world, i + 5, j + 18, k + 4, ModBlocks.mintwoodLeaves);
		setBlock(world, i + 5, j + 18, k + 5, ModBlocks.mintwoodLeaves);
		setBlock(world, i + 5, j + 18, k + 6, ModBlocks.mintwoodLeaves);
		setBlock(world, i + 5, j + 18, k + 7, ModBlocks.mintwoodLeaves);
		setBlock(world, i + 5, j + 18, k + 8, ModBlocks.mintwoodLeaves);
		setBlock(world, i + 5, j + 18, k + 9, ModBlocks.mintwoodLeaves);
		setBlock(world, i + 5, j + 18, k + 10, ModBlocks.mintwoodLeaves);
		setBlock(world, i + 5, j + 19, k + 3, ModBlocks.mintwoodLeaves);
		setBlock(world, i + 5, j + 19, k + 4, ModBlocks.mintwoodLeaves);
		setBlock(world, i + 5, j + 19, k + 5, ModBlocks.mintwoodLeaves);
		setBlock(world, i + 5, j + 19, k + 6, ModBlocks.mintwoodLeaves);
		setBlock(world, i + 5, j + 19, k + 7, ModBlocks.mintwoodLeaves);
		setBlock(world, i + 5, j + 19, k + 8, ModBlocks.mintwoodLeaves);
		setBlock(world, i + 5, j + 19, k + 9, ModBlocks.mintwoodLeaves);
		setBlock(world, i + 5, j + 20, k + 4, ModBlocks.mintwoodLeaves);
		setBlock(world, i + 5, j + 20, k + 5, ModBlocks.mintwoodLeaves);
		setBlock(world, i + 5, j + 20, k + 6, ModBlocks.mintwoodLeaves);
		setBlock(world, i + 5, j + 20, k + 7, ModBlocks.mintwoodLeaves);
		setBlock(world, i + 5, j + 20, k + 8, ModBlocks.mintwoodLeaves);
		setBlock(world, i + 6, j + 0, k + 4, ModBlocks.mintwoodLog);
		setBlock(world, i + 6, j + 0, k + 5, ModBlocks.mintwoodLog);
		setBlock(world, i + 6, j + 0, k + 6, ModBlocks.mintwoodLog);
		setBlock(world, i + 6, j + 0, k + 7, ModBlocks.mintwoodLog);
		setBlock(world, i + 6, j + 0, k + 8, ModBlocks.mintwoodLog);
		setBlock(world, i + 6, j + 0, k + 9, ModBlocks.mintwoodLog);
		setBlock(world, i + 6, j + 1, k + 4, ModBlocks.mintwoodLog);
		setBlock(world, i + 6, j + 1, k + 5, ModBlocks.mintwoodLog);
		setBlock(world, i + 6, j + 1, k + 6, ModBlocks.mintwoodLog);
		setBlock(world, i + 6, j + 1, k + 7, ModBlocks.mintwoodLog);
		setBlock(world, i + 6, j + 1, k + 8, ModBlocks.mintwoodLog);
		setBlock(world, i + 6, j + 1, k + 9, ModBlocks.mintwoodLog);
		setBlock(world, i + 6, j + 2, k + 4, ModBlocks.mintwoodLog);
		setBlock(world, i + 6, j + 2, k + 5, ModBlocks.mintwoodLog);
		setBlock(world, i + 6, j + 2, k + 6, ModBlocks.mintwoodLog);
		setBlock(world, i + 6, j + 2, k + 7, ModBlocks.mintwoodLog);
		setBlock(world, i + 6, j + 2, k + 8, ModBlocks.mintwoodLog);
		setBlock(world, i + 6, j + 2, k + 9, ModBlocks.mintwoodLog);
		setBlock(world, i + 6, j + 3, k + 4, ModBlocks.mintwoodLog);
		setBlock(world, i + 6, j + 3, k + 5, ModBlocks.mintwoodLog);
		setBlock(world, i + 6, j + 3, k + 6, ModBlocks.mintwoodLog);
		setBlock(world, i + 6, j + 3, k + 7, ModBlocks.mintwoodLog);
		setBlock(world, i + 6, j + 3, k + 8, ModBlocks.mintwoodLog);
		setBlock(world, i + 6, j + 3, k + 9, ModBlocks.mintwoodLog);
		setBlock(world, i + 6, j + 4, k + 4, ModBlocks.mintwoodLog);
		setBlock(world, i + 6, j + 4, k + 5, ModBlocks.mintwoodLog);
		setBlock(world, i + 6, j + 4, k + 6, ModBlocks.mintwoodLog);
		setBlock(world, i + 6, j + 4, k + 7, ModBlocks.mintwoodLog);
		setBlock(world, i + 6, j + 4, k + 8, ModBlocks.mintwoodLog);
		setBlock(world, i + 6, j + 4, k + 9, ModBlocks.mintwoodLog);
		setBlock(world, i + 6, j + 5, k + 4, ModBlocks.mintwoodLog);
		setBlock(world, i + 6, j + 5, k + 5, ModBlocks.mintwoodLog);
		setBlock(world, i + 6, j + 5, k + 6, ModBlocks.mintwoodLog);
		setBlock(world, i + 6, j + 5, k + 7, ModBlocks.mintwoodLog);
		setBlock(world, i + 6, j + 5, k + 8, ModBlocks.mintwoodLog);
		setBlock(world, i + 6, j + 5, k + 9, ModBlocks.mintwoodLog);
		setBlock(world, i + 6, j + 6, k + 4, ModBlocks.mintwoodLog);
		setBlock(world, i + 6, j + 6, k + 5, ModBlocks.mintwoodLog);
		setBlock(world, i + 6, j + 6, k + 6, ModBlocks.mintwoodLog);
		setBlock(world, i + 6, j + 6, k + 7, ModBlocks.mintwoodLog);
		setBlock(world, i + 6, j + 6, k + 8, ModBlocks.mintwoodLog);
		setBlock(world, i + 6, j + 6, k + 9, ModBlocks.mintwoodLog);
		setBlock(world, i + 6, j + 7, k + 4, ModBlocks.mintwoodLog);
		setBlock(world, i + 6, j + 7, k + 5, ModBlocks.mintwoodLog);
		setBlock(world, i + 6, j + 7, k + 6, ModBlocks.mintwoodLog);
		setBlock(world, i + 6, j + 7, k + 7, ModBlocks.mintwoodLog);
		setBlock(world, i + 6, j + 7, k + 8, ModBlocks.mintwoodLog);
		setBlock(world, i + 6, j + 7, k + 9, ModBlocks.mintwoodLog);
		setBlock(world, i + 6, j + 8, k + 4, ModBlocks.mintwoodLog);
		setBlock(world, i + 6, j + 8, k + 5, ModBlocks.mintwoodLog);
		setBlock(world, i + 6, j + 8, k + 6, ModBlocks.mintwoodLog);
		setBlock(world, i + 6, j + 8, k + 7, ModBlocks.mintwoodLog);
		setBlock(world, i + 6, j + 8, k + 8, ModBlocks.mintwoodLog);
		setBlock(world, i + 6, j + 8, k + 9, ModBlocks.mintwoodLog);
		setBlock(world, i + 6, j + 9, k + 4, ModBlocks.mintwoodLog);
		setBlock(world, i + 6, j + 9, k + 5, ModBlocks.mintwoodLog);
		setBlock(world, i + 6, j + 9, k + 6, ModBlocks.mintwoodLog);
		setBlock(world, i + 6, j + 9, k + 7, ModBlocks.mintwoodLog);
		setBlock(world, i + 6, j + 9, k + 8, ModBlocks.mintwoodLog);
		setBlock(world, i + 6, j + 9, k + 9, ModBlocks.mintwoodLog);
		setBlock(world, i + 6, j + 10, k + 4, ModBlocks.mintwoodLeaves);
		setBlock(world, i + 6, j + 10, k + 5, ModBlocks.mintwoodLeaves);
		setBlock(world, i + 6, j + 10, k + 6, ModBlocks.mintwoodLeaves);
		setBlock(world, i + 6, j + 10, k + 7, ModBlocks.mintwoodLeaves);
		setBlock(world, i + 6, j + 10, k + 8, ModBlocks.mintwoodLeaves);
		setBlock(world, i + 6, j + 10, k + 9, ModBlocks.mintwoodLog);
		setBlock(world, i + 6, j + 11, k + 3, ModBlocks.mintwoodLeaves);
		setBlock(world, i + 6, j + 11, k + 4, ModBlocks.mintwoodLeaves);
		setBlock(world, i + 6, j + 11, k + 5, ModBlocks.mintwoodLeaves);
		setBlock(world, i + 6, j + 11, k + 6, ModBlocks.mintwoodLeaves);
		setBlock(world, i + 6, j + 11, k + 7, ModBlocks.mintwoodLeaves);
		setBlock(world, i + 6, j + 11, k + 8, ModBlocks.mintwoodLeaves);
		setBlock(world, i + 6, j + 11, k + 9, ModBlocks.mintwoodLeaves);
		setBlock(world, i + 6, j + 11, k + 10, ModBlocks.mintwoodLeaves);
		setBlock(world, i + 6, j + 11, k + 11, ModBlocks.mintwoodLeaves);
		setBlock(world, i + 6, j + 11, k + 12, ModBlocks.mintwoodLeaves);
		setBlock(world, i + 6, j + 12, k + 2, ModBlocks.mintwoodLeaves);
		setBlock(world, i + 6, j + 12, k + 3, ModBlocks.mintwoodLeaves);
		setBlock(world, i + 6, j + 12, k + 4, ModBlocks.mintwoodLeaves);
		setBlock(world, i + 6, j + 12, k + 5, ModBlocks.mintwoodLeaves);
		setBlock(world, i + 6, j + 12, k + 6, ModBlocks.mintwoodLeaves);
		setBlock(world, i + 6, j + 12, k + 7, ModBlocks.mintwoodLeaves);
		setBlock(world, i + 6, j + 12, k + 8, ModBlocks.mintwoodLeaves);
		setBlock(world, i + 6, j + 12, k + 9, ModBlocks.mintwoodLeaves);
		setBlock(world, i + 6, j + 12, k + 10, ModBlocks.mintwoodLeaves);
		setBlock(world, i + 6, j + 12, k + 11, ModBlocks.mintwoodLeaves);
		setBlock(world, i + 6, j + 12, k + 12, ModBlocks.mintwoodLeaves);
		setBlock(world, i + 6, j + 12, k + 13, ModBlocks.mintwoodLeaves);
		setBlock(world, i + 6, j + 13, k + 1, ModBlocks.mintwoodLeaves);
		setBlock(world, i + 6, j + 13, k + 2, ModBlocks.mintwoodLeaves);
		setBlock(world, i + 6, j + 13, k + 3, ModBlocks.mintwoodLeaves);
		setBlock(world, i + 6, j + 13, k + 4, ModBlocks.mintwoodLeaves);
		setBlock(world, i + 6, j + 13, k + 5, ModBlocks.mintwoodLeaves);
		setBlock(world, i + 6, j + 13, k + 6, ModBlocks.mintwoodLeaves);
		setBlock(world, i + 6, j + 13, k + 7, ModBlocks.mintwoodLeaves);
		setBlock(world, i + 6, j + 13, k + 8, ModBlocks.mintwoodLeaves);
		setBlock(world, i + 6, j + 13, k + 9, ModBlocks.mintwoodLeaves);
		setBlock(world, i + 6, j + 13, k + 10, ModBlocks.mintwoodLeaves);
		setBlock(world, i + 6, j + 13, k + 11, ModBlocks.mintwoodLeaves);
		setBlock(world, i + 6, j + 13, k + 12, ModBlocks.mintwoodLeaves);
		setBlock(world, i + 6, j + 13, k + 13, ModBlocks.mintwoodLeaves);
		setBlock(world, i + 6, j + 14, k + 1, ModBlocks.mintwoodLeaves);
		setBlock(world, i + 6, j + 14, k + 2, ModBlocks.mintwoodLeaves);
		setBlock(world, i + 6, j + 14, k + 3, ModBlocks.mintwoodLeaves);
		setBlock(world, i + 6, j + 14, k + 5, ModBlocks.mintwoodLeaves);
		setBlock(world, i + 6, j + 14, k + 6, ModBlocks.mintwoodLeaves);
		setBlock(world, i + 6, j + 14, k + 7, ModBlocks.mintwoodLeaves);
		setBlock(world, i + 6, j + 14, k + 8, ModBlocks.mintwoodLeaves);
		setBlock(world, i + 6, j + 14, k + 9, ModBlocks.mintwoodLeaves);
		setBlock(world, i + 6, j + 14, k + 10, ModBlocks.mintwoodLeaves);
		setBlock(world, i + 6, j + 14, k + 11, ModBlocks.mintwoodLeaves);
		setBlock(world, i + 6, j + 14, k + 12, ModBlocks.mintwoodLeaves);
		setBlock(world, i + 6, j + 14, k + 13, ModBlocks.mintwoodLeaves);
		setBlock(world, i + 6, j + 15, k + 1, ModBlocks.mintwoodLeaves);
		setBlock(world, i + 6, j + 15, k + 2, ModBlocks.mintwoodLeaves);
		setBlock(world, i + 6, j + 15, k + 3, ModBlocks.mintwoodLeaves);
		setBlock(world, i + 6, j + 15, k + 7, ModBlocks.mintwoodLeaves);
		setBlock(world, i + 6, j + 15, k + 8, ModBlocks.mintwoodLeaves);
		setBlock(world, i + 6, j + 15, k + 9, ModBlocks.mintwoodLeaves);
		setBlock(world, i + 6, j + 15, k + 10, ModBlocks.mintwoodLeaves);
		setBlock(world, i + 6, j + 15, k + 11, ModBlocks.mintwoodLeaves);
		setBlock(world, i + 6, j + 15, k + 12, ModBlocks.mintwoodLeaves);
		setBlock(world, i + 6, j + 16, k + 1, ModBlocks.mintwoodLeaves);
		setBlock(world, i + 6, j + 16, k + 2, ModBlocks.mintwoodLeaves);
		setBlock(world, i + 6, j + 16, k + 3, ModBlocks.mintwoodLeaves);
		setBlock(world, i + 6, j + 16, k + 4, ModBlocks.mintwoodLeaves);
		setBlock(world, i + 6, j + 16, k + 8, ModBlocks.mintwoodLeaves);
		setBlock(world, i + 6, j + 16, k + 9, ModBlocks.mintwoodLeaves);
		setBlock(world, i + 6, j + 16, k + 10, ModBlocks.mintwoodLeaves);
		setBlock(world, i + 6, j + 16, k + 11, ModBlocks.mintwoodLeaves);
		setBlock(world, i + 6, j + 17, k + 1, ModBlocks.mintwoodLeaves);
		setBlock(world, i + 6, j + 17, k + 2, ModBlocks.mintwoodLeaves);
		setBlock(world, i + 6, j + 17, k + 3, ModBlocks.mintwoodLeaves);
		setBlock(world, i + 6, j + 17, k + 4, ModBlocks.mintwoodLeaves);
		setBlock(world, i + 6, j + 17, k + 5, ModBlocks.mintwoodLeaves);
		setBlock(world, i + 6, j + 17, k + 8, ModBlocks.mintwoodLeaves);
		setBlock(world, i + 6, j + 17, k + 9, ModBlocks.mintwoodLeaves);
		setBlock(world, i + 6, j + 17, k + 10, ModBlocks.mintwoodLeaves);
		setBlock(world, i + 6, j + 17, k + 11, ModBlocks.mintwoodLeaves);
		setBlock(world, i + 6, j + 18, k + 2, ModBlocks.mintwoodLeaves);
		setBlock(world, i + 6, j + 18, k + 3, ModBlocks.mintwoodLeaves);
		setBlock(world, i + 6, j + 18, k + 4, ModBlocks.mintwoodLeaves);
		setBlock(world, i + 6, j + 18, k + 5, ModBlocks.mintwoodLeaves);
		setBlock(world, i + 6, j + 18, k + 6, ModBlocks.mintwoodLeaves);
		setBlock(world, i + 6, j + 18, k + 7, ModBlocks.mintwoodLeaves);
		setBlock(world, i + 6, j + 18, k + 8, ModBlocks.mintwoodLeaves);
		setBlock(world, i + 6, j + 18, k + 9, ModBlocks.mintwoodLeaves);
		setBlock(world, i + 6, j + 18, k + 10, ModBlocks.mintwoodLeaves);
		setBlock(world, i + 6, j + 19, k + 3, ModBlocks.mintwoodLeaves);
		setBlock(world, i + 6, j + 19, k + 4, ModBlocks.mintwoodLeaves);
		setBlock(world, i + 6, j + 19, k + 5, ModBlocks.mintwoodLeaves);
		setBlock(world, i + 6, j + 19, k + 6, ModBlocks.mintwoodLeaves);
		setBlock(world, i + 6, j + 19, k + 7, ModBlocks.mintwoodLeaves);
		setBlock(world, i + 6, j + 19, k + 8, ModBlocks.mintwoodLeaves);
		setBlock(world, i + 6, j + 19, k + 9, ModBlocks.mintwoodLeaves);
		setBlock(world, i + 6, j + 20, k + 4, ModBlocks.mintwoodLeaves);
		setBlock(world, i + 6, j + 20, k + 5, ModBlocks.mintwoodLeaves);
		setBlock(world, i + 6, j + 20, k + 6, ModBlocks.mintwoodLeaves);
		setBlock(world, i + 6, j + 20, k + 7, ModBlocks.mintwoodLeaves);
		setBlock(world, i + 6, j + 20, k + 8, ModBlocks.mintwoodLeaves);
		setBlock(world, i + 7, j + 0, k + 4, ModBlocks.mintwoodLog);
		setBlock(world, i + 7, j + 0, k + 5, ModBlocks.mintwoodLog);
		setBlock(world, i + 7, j + 0, k + 6, ModBlocks.mintwoodLog);
		setBlock(world, i + 7, j + 0, k + 7, ModBlocks.mintwoodLog);
		setBlock(world, i + 7, j + 0, k + 8, ModBlocks.mintwoodLog);
		setBlock(world, i + 7, j + 0, k + 9, ModBlocks.mintwoodLog);
		setBlock(world, i + 7, j + 1, k + 4, ModBlocks.mintwoodLog);
		setBlock(world, i + 7, j + 1, k + 5, ModBlocks.mintwoodLog);
		setBlock(world, i + 7, j + 1, k + 6, ModBlocks.mintwoodLog);
		setBlock(world, i + 7, j + 1, k + 7, ModBlocks.mintwoodLog);
		setBlock(world, i + 7, j + 1, k + 8, ModBlocks.mintwoodLog);
		setBlock(world, i + 7, j + 1, k + 9, ModBlocks.mintwoodLog);
		setBlock(world, i + 7, j + 2, k + 4, ModBlocks.mintwoodLog);
		setBlock(world, i + 7, j + 2, k + 5, ModBlocks.mintwoodLog);
		setBlock(world, i + 7, j + 2, k + 6, ModBlocks.mintwoodLog);
		setBlock(world, i + 7, j + 2, k + 7, ModBlocks.mintwoodLog);
		setBlock(world, i + 7, j + 2, k + 8, ModBlocks.mintwoodLog);
		setBlock(world, i + 7, j + 2, k + 9, ModBlocks.mintwoodLog);
		setBlock(world, i + 7, j + 3, k + 4, ModBlocks.mintwoodLog);
		setBlock(world, i + 7, j + 3, k + 5, ModBlocks.mintwoodLog);
		setBlock(world, i + 7, j + 3, k + 6, ModBlocks.mintwoodLog);
		setBlock(world, i + 7, j + 3, k + 7, ModBlocks.mintwoodLog);
		setBlock(world, i + 7, j + 3, k + 8, ModBlocks.mintwoodLog);
		setBlock(world, i + 7, j + 3, k + 9, ModBlocks.mintwoodLog);
		setBlock(world, i + 7, j + 4, k + 4, ModBlocks.mintwoodLog);
		setBlock(world, i + 7, j + 4, k + 5, ModBlocks.mintwoodLog);
		setBlock(world, i + 7, j + 4, k + 6, ModBlocks.mintwoodLog);
		setBlock(world, i + 7, j + 4, k + 7, ModBlocks.mintwoodLog);
		setBlock(world, i + 7, j + 4, k + 8, ModBlocks.mintwoodLog);
		setBlock(world, i + 7, j + 4, k + 9, ModBlocks.mintwoodLog);
		setBlock(world, i + 7, j + 5, k + 4, ModBlocks.mintwoodLog);
		setBlock(world, i + 7, j + 5, k + 5, ModBlocks.mintwoodLog);
		setBlock(world, i + 7, j + 5, k + 6, ModBlocks.mintwoodLog);
		setBlock(world, i + 7, j + 5, k + 7, ModBlocks.mintwoodLog);
		setBlock(world, i + 7, j + 5, k + 8, ModBlocks.mintwoodLog);
		setBlock(world, i + 7, j + 5, k + 9, ModBlocks.mintwoodLog);
		setBlock(world, i + 7, j + 6, k + 4, ModBlocks.mintwoodLog);
		setBlock(world, i + 7, j + 6, k + 5, ModBlocks.mintwoodLog);
		setBlock(world, i + 7, j + 6, k + 6, ModBlocks.mintwoodLog);
		setBlock(world, i + 7, j + 6, k + 7, ModBlocks.mintwoodLog);
		setBlock(world, i + 7, j + 6, k + 8, ModBlocks.mintwoodLog);
		setBlock(world, i + 7, j + 6, k + 9, ModBlocks.mintwoodLog);
		setBlock(world, i + 7, j + 7, k + 4, ModBlocks.mintwoodLog);
		setBlock(world, i + 7, j + 7, k + 5, ModBlocks.mintwoodLog);
		setBlock(world, i + 7, j + 7, k + 6, ModBlocks.mintwoodLog);
		setBlock(world, i + 7, j + 7, k + 7, ModBlocks.mintwoodLog);
		setBlock(world, i + 7, j + 7, k + 8, ModBlocks.mintwoodLog);
		setBlock(world, i + 7, j + 7, k + 9, ModBlocks.mintwoodLog);
		setBlock(world, i + 7, j + 8, k + 4, ModBlocks.mintwoodLog);
		setBlock(world, i + 7, j + 8, k + 5, ModBlocks.mintwoodLog);
		setBlock(world, i + 7, j + 8, k + 6, ModBlocks.mintwoodLog);
		setBlock(world, i + 7, j + 8, k + 7, ModBlocks.mintwoodLog);
		setBlock(world, i + 7, j + 8, k + 8, ModBlocks.mintwoodLog);
		setBlock(world, i + 7, j + 8, k + 9, ModBlocks.mintwoodLog);
		setBlock(world, i + 7, j + 9, k + 4, ModBlocks.mintwoodLog);
		setBlock(world, i + 7, j + 9, k + 5, ModBlocks.mintwoodLog);
		setBlock(world, i + 7, j + 9, k + 6, ModBlocks.mintwoodLog);
		setBlock(world, i + 7, j + 9, k + 7, ModBlocks.mintwoodLog);
		setBlock(world, i + 7, j + 9, k + 8, ModBlocks.mintwoodLog);
		setBlock(world, i + 7, j + 9, k + 9, ModBlocks.mintwoodLog);
		setBlock(world, i + 7, j + 10, k + 4, ModBlocks.mintwoodLeaves);
		setBlock(world, i + 7, j + 10, k + 5, ModBlocks.mintwoodLeaves);
		setBlock(world, i + 7, j + 10, k + 6, ModBlocks.mintwoodLeaves);
		setBlock(world, i + 7, j + 10, k + 7, ModBlocks.mintwoodLeaves);
		setBlock(world, i + 7, j + 10, k + 8, ModBlocks.mintwoodLeaves);
		setBlock(world, i + 7, j + 10, k + 9, ModBlocks.mintwoodLog);
		setBlock(world, i + 7, j + 11, k + 3, ModBlocks.mintwoodLeaves);
		setBlock(world, i + 7, j + 11, k + 4, ModBlocks.mintwoodLeaves);
		setBlock(world, i + 7, j + 11, k + 5, ModBlocks.mintwoodLeaves);
		setBlock(world, i + 7, j + 11, k + 6, ModBlocks.mintwoodLeaves);
		setBlock(world, i + 7, j + 11, k + 7, ModBlocks.mintwoodLeaves);
		setBlock(world, i + 7, j + 11, k + 8, ModBlocks.mintwoodLeaves);
		setBlock(world, i + 7, j + 11, k + 9, ModBlocks.mintwoodLeaves);
		setBlock(world, i + 7, j + 11, k + 10, ModBlocks.mintwoodLeaves);
		setBlock(world, i + 7, j + 11, k + 11, ModBlocks.mintwoodLeaves);
		setBlock(world, i + 7, j + 11, k + 12, ModBlocks.mintwoodLeaves);
		setBlock(world, i + 7, j + 12, k + 2, ModBlocks.mintwoodLeaves);
		setBlock(world, i + 7, j + 12, k + 3, ModBlocks.mintwoodLeaves);
		setBlock(world, i + 7, j + 12, k + 4, ModBlocks.mintwoodLeaves);
		setBlock(world, i + 7, j + 12, k + 5, ModBlocks.mintwoodLeaves);
		setBlock(world, i + 7, j + 12, k + 6, ModBlocks.mintwoodLeaves);
		setBlock(world, i + 7, j + 12, k + 7, ModBlocks.mintwoodLeaves);
		setBlock(world, i + 7, j + 12, k + 8, ModBlocks.mintwoodLeaves);
		setBlock(world, i + 7, j + 12, k + 9, ModBlocks.mintwoodLeaves);
		setBlock(world, i + 7, j + 12, k + 10, ModBlocks.mintwoodLeaves);
		setBlock(world, i + 7, j + 12, k + 11, ModBlocks.mintwoodLeaves);
		setBlock(world, i + 7, j + 12, k + 12, ModBlocks.mintwoodLeaves);
		setBlock(world, i + 7, j + 12, k + 13, ModBlocks.mintwoodLeaves);
		setBlock(world, i + 7, j + 13, k + 1, ModBlocks.mintwoodLeaves);
		setBlock(world, i + 7, j + 13, k + 2, ModBlocks.mintwoodLeaves);
		setBlock(world, i + 7, j + 13, k + 3, ModBlocks.mintwoodLeaves);
		setBlock(world, i + 7, j + 13, k + 4, ModBlocks.mintwoodLeaves);
		setBlock(world, i + 7, j + 13, k + 5, ModBlocks.mintwoodLeaves);
		setBlock(world, i + 7, j + 13, k + 6, ModBlocks.mintwoodLeaves);
		setBlock(world, i + 7, j + 13, k + 7, ModBlocks.mintwoodLeaves);
		setBlock(world, i + 7, j + 13, k + 8, ModBlocks.mintwoodLeaves);
		setBlock(world, i + 7, j + 13, k + 9, ModBlocks.mintwoodLeaves);
		setBlock(world, i + 7, j + 13, k + 10, ModBlocks.mintwoodLeaves);
		setBlock(world, i + 7, j + 13, k + 11, ModBlocks.mintwoodLeaves);
		setBlock(world, i + 7, j + 13, k + 12, ModBlocks.mintwoodLeaves);
		setBlock(world, i + 7, j + 13, k + 13, ModBlocks.mintwoodLeaves);
		setBlock(world, i + 7, j + 14, k + 1, ModBlocks.mintwoodLeaves);
		setBlock(world, i + 7, j + 14, k + 2, ModBlocks.mintwoodLeaves);
		setBlock(world, i + 7, j + 14, k + 3, ModBlocks.mintwoodLeaves);
		setBlock(world, i + 7, j + 14, k + 4, ModBlocks.mintwoodLeaves);
		setBlock(world, i + 7, j + 14, k + 5, ModBlocks.mintwoodLeaves);
		setBlock(world, i + 7, j + 14, k + 6, ModBlocks.mintwoodLeaves);
		setBlock(world, i + 7, j + 14, k + 7, ModBlocks.mintwoodLeaves);
		setBlock(world, i + 7, j + 14, k + 8, ModBlocks.mintwoodLeaves);
		setBlock(world, i + 7, j + 14, k + 9, ModBlocks.mintwoodLeaves);
		setBlock(world, i + 7, j + 14, k + 10, ModBlocks.mintwoodLeaves);
		setBlock(world, i + 7, j + 14, k + 11, ModBlocks.mintwoodLeaves);
		setBlock(world, i + 7, j + 14, k + 12, ModBlocks.mintwoodLeaves);
		setBlock(world, i + 7, j + 14, k + 13, ModBlocks.mintwoodLeaves);
		setBlock(world, i + 7, j + 15, k + 1, ModBlocks.mintwoodLeaves);
		setBlock(world, i + 7, j + 15, k + 2, ModBlocks.mintwoodLeaves);
		setBlock(world, i + 7, j + 15, k + 3, ModBlocks.mintwoodLeaves);
		setBlock(world, i + 7, j + 15, k + 4, ModBlocks.mintwoodLeaves);
		setBlock(world, i + 7, j + 15, k + 5, ModBlocks.mintwoodLeaves);
		setBlock(world, i + 7, j + 15, k + 6, ModBlocks.mintwoodLeaves);
		setBlock(world, i + 7, j + 15, k + 7, ModBlocks.mintwoodLeaves);
		setBlock(world, i + 7, j + 15, k + 8, ModBlocks.mintwoodLeaves);
		setBlock(world, i + 7, j + 15, k + 9, ModBlocks.mintwoodLeaves);
		setBlock(world, i + 7, j + 15, k + 10, ModBlocks.mintwoodLeaves);
		setBlock(world, i + 7, j + 15, k + 11, ModBlocks.mintwoodLeaves);
		setBlock(world, i + 7, j + 15, k + 12, ModBlocks.mintwoodLeaves);
		setBlock(world, i + 7, j + 16, k + 1, ModBlocks.mintwoodLeaves);
		setBlock(world, i + 7, j + 16, k + 2, ModBlocks.mintwoodLeaves);
		setBlock(world, i + 7, j + 16, k + 3, ModBlocks.mintwoodLeaves);
		setBlock(world, i + 7, j + 16, k + 4, ModBlocks.mintwoodLeaves);
		setBlock(world, i + 7, j + 16, k + 5, ModBlocks.mintwoodLeaves);
		setBlock(world, i + 7, j + 16, k + 6, ModBlocks.mintwoodLeaves);
		setBlock(world, i + 7, j + 16, k + 8, ModBlocks.mintwoodLeaves);
		setBlock(world, i + 7, j + 16, k + 9, ModBlocks.mintwoodLeaves);
		setBlock(world, i + 7, j + 16, k + 10, ModBlocks.mintwoodLeaves);
		setBlock(world, i + 7, j + 16, k + 11, ModBlocks.mintwoodLeaves);
		setBlock(world, i + 7, j + 17, k + 1, ModBlocks.mintwoodLeaves);
		setBlock(world, i + 7, j + 17, k + 2, ModBlocks.mintwoodLeaves);
		setBlock(world, i + 7, j + 17, k + 3, ModBlocks.mintwoodLeaves);
		setBlock(world, i + 7, j + 17, k + 4, ModBlocks.mintwoodLeaves);
		setBlock(world, i + 7, j + 17, k + 5, ModBlocks.mintwoodLeaves);
		setBlock(world, i + 7, j + 17, k + 6, ModBlocks.mintwoodLeaves);
		setBlock(world, i + 7, j + 17, k + 8, ModBlocks.mintwoodLeaves);
		setBlock(world, i + 7, j + 17, k + 9, ModBlocks.mintwoodLeaves);
		setBlock(world, i + 7, j + 17, k + 10, ModBlocks.mintwoodLeaves);
		setBlock(world, i + 7, j + 17, k + 11, ModBlocks.mintwoodLeaves);
		setBlock(world, i + 7, j + 18, k + 2, ModBlocks.mintwoodLeaves);
		setBlock(world, i + 7, j + 18, k + 3, ModBlocks.mintwoodLeaves);
		setBlock(world, i + 7, j + 18, k + 4, ModBlocks.mintwoodLeaves);
		setBlock(world, i + 7, j + 18, k + 5, ModBlocks.mintwoodLeaves);
		setBlock(world, i + 7, j + 18, k + 6, ModBlocks.mintwoodLeaves);
		setBlock(world, i + 7, j + 18, k + 8, ModBlocks.mintwoodLeaves);
		setBlock(world, i + 7, j + 18, k + 9, ModBlocks.mintwoodLeaves);
		setBlock(world, i + 7, j + 18, k + 10, ModBlocks.mintwoodLeaves);
		setBlock(world, i + 7, j + 19, k + 3, ModBlocks.mintwoodLeaves);
		setBlock(world, i + 7, j + 19, k + 4, ModBlocks.mintwoodLeaves);
		setBlock(world, i + 7, j + 19, k + 5, ModBlocks.mintwoodLeaves);
		setBlock(world, i + 7, j + 19, k + 6, ModBlocks.mintwoodLeaves);
		setBlock(world, i + 7, j + 19, k + 7, ModBlocks.mintwoodLeaves);
		setBlock(world, i + 7, j + 19, k + 8, ModBlocks.mintwoodLeaves);
		setBlock(world, i + 7, j + 19, k + 9, ModBlocks.mintwoodLeaves);
		setBlock(world, i + 7, j + 20, k + 4, ModBlocks.mintwoodLeaves);
		setBlock(world, i + 7, j + 20, k + 5, ModBlocks.mintwoodLeaves);
		setBlock(world, i + 7, j + 20, k + 6, ModBlocks.mintwoodLeaves);
		setBlock(world, i + 7, j + 20, k + 7, ModBlocks.mintwoodLeaves);
		setBlock(world, i + 7, j + 20, k + 8, ModBlocks.mintwoodLeaves);
		setBlock(world, i + 8, j + 0, k + 6, ModBlocks.mintwoodLog);
		setBlock(world, i + 8, j + 0, k + 7, ModBlocks.mintwoodLog);
		setBlock(world, i + 8, j + 1, k + 6, ModBlocks.mintwoodLog);
		setBlock(world, i + 8, j + 1, k + 7, ModBlocks.mintwoodLog);
		setBlock(world, i + 8, j + 2, k + 6, ModBlocks.mintwoodLog);
		setBlock(world, i + 8, j + 2, k + 7, ModBlocks.mintwoodLog);
		setBlock(world, i + 8, j + 3, k + 6, ModBlocks.mintwoodLog);
		setBlock(world, i + 8, j + 3, k + 7, ModBlocks.mintwoodLog);
		setBlock(world, i + 8, j + 4, k + 6, ModBlocks.mintwoodLog);
		setBlock(world, i + 8, j + 4, k + 7, ModBlocks.mintwoodLog);
		setBlock(world, i + 8, j + 5, k + 6, ModBlocks.mintwoodLog);
		setBlock(world, i + 8, j + 5, k + 7, ModBlocks.mintwoodLog);
		setBlock(world, i + 8, j + 6, k + 6, ModBlocks.mintwoodLog);
		setBlock(world, i + 8, j + 6, k + 7, ModBlocks.mintwoodLog);
		setBlock(world, i + 8, j + 7, k + 6, ModBlocks.mintwoodLog);
		setBlock(world, i + 8, j + 7, k + 7, ModBlocks.mintwoodLog);
		setBlock(world, i + 8, j + 8, k + 6, ModBlocks.mintwoodLog);
		setBlock(world, i + 8, j + 8, k + 7, ModBlocks.mintwoodLog);
		setBlock(world, i + 8, j + 9, k + 6, ModBlocks.mintwoodLog);
		setBlock(world, i + 8, j + 9, k + 7, ModBlocks.mintwoodLog);
		setBlock(world, i + 8, j + 10, k + 5, ModBlocks.mintwoodLeaves);
		setBlock(world, i + 8, j + 10, k + 6, ModBlocks.mintwoodLeaves);
		setBlock(world, i + 8, j + 10, k + 7, ModBlocks.mintwoodLeaves);
		setBlock(world, i + 8, j + 11, k + 3, ModBlocks.mintwoodLeaves);
		setBlock(world, i + 8, j + 11, k + 4, ModBlocks.mintwoodLeaves);
		setBlock(world, i + 8, j + 11, k + 5, ModBlocks.mintwoodLeaves);
		setBlock(world, i + 8, j + 11, k + 6, ModBlocks.mintwoodLeaves);
		setBlock(world, i + 8, j + 11, k + 7, ModBlocks.mintwoodLeaves);
		setBlock(world, i + 8, j + 11, k + 8, ModBlocks.mintwoodLeaves);
		setBlock(world, i + 8, j + 11, k + 9, ModBlocks.mintwoodLeaves);
		setBlock(world, i + 8, j + 11, k + 10, ModBlocks.mintwoodLeaves);
		setBlock(world, i + 8, j + 11, k + 11, ModBlocks.mintwoodLeaves);
		setBlock(world, i + 8, j + 11, k + 12, ModBlocks.mintwoodLeaves);
		setBlock(world, i + 8, j + 12, k + 2, ModBlocks.mintwoodLeaves);
		setBlock(world, i + 8, j + 12, k + 3, ModBlocks.mintwoodLeaves);
		setBlock(world, i + 8, j + 12, k + 4, ModBlocks.mintwoodLeaves);
		setBlock(world, i + 8, j + 12, k + 5, ModBlocks.mintwoodLeaves);
		setBlock(world, i + 8, j + 12, k + 6, ModBlocks.mintwoodLeaves);
		setBlock(world, i + 8, j + 12, k + 7, ModBlocks.mintwoodLeaves);
		setBlock(world, i + 8, j + 12, k + 8, ModBlocks.mintwoodLeaves);
		setBlock(world, i + 8, j + 12, k + 9, ModBlocks.mintwoodLeaves);
		setBlock(world, i + 8, j + 12, k + 10, ModBlocks.mintwoodLeaves);
		setBlock(world, i + 8, j + 12, k + 11, ModBlocks.mintwoodLeaves);
		setBlock(world, i + 8, j + 12, k + 12, ModBlocks.mintwoodLeaves);
		setBlock(world, i + 8, j + 12, k + 13, ModBlocks.mintwoodLeaves);
		setBlock(world, i + 8, j + 13, k + 2, ModBlocks.mintwoodLeaves);
		setBlock(world, i + 8, j + 13, k + 3, ModBlocks.mintwoodLeaves);
		setBlock(world, i + 8, j + 13, k + 4, ModBlocks.mintwoodLeaves);
		setBlock(world, i + 8, j + 13, k + 5, ModBlocks.mintwoodLeaves);
		setBlock(world, i + 8, j + 13, k + 6, ModBlocks.mintwoodLeaves);
		setBlock(world, i + 8, j + 13, k + 7, ModBlocks.mintwoodLeaves);
		setBlock(world, i + 8, j + 13, k + 8, ModBlocks.mintwoodLeaves);
		setBlock(world, i + 8, j + 13, k + 9, ModBlocks.mintwoodLeaves);
		setBlock(world, i + 8, j + 13, k + 10, ModBlocks.mintwoodLeaves);
		setBlock(world, i + 8, j + 13, k + 11, ModBlocks.mintwoodLeaves);
		setBlock(world, i + 8, j + 13, k + 12, ModBlocks.mintwoodLeaves);
		setBlock(world, i + 8, j + 13, k + 13, ModBlocks.mintwoodLeaves);
		setBlock(world, i + 8, j + 14, k + 1, ModBlocks.mintwoodLeaves);
		setBlock(world, i + 8, j + 14, k + 2, ModBlocks.mintwoodLeaves);
		setBlock(world, i + 8, j + 14, k + 3, ModBlocks.mintwoodLeaves);
		setBlock(world, i + 8, j + 14, k + 4, ModBlocks.mintwoodLeaves);
		setBlock(world, i + 8, j + 14, k + 5, ModBlocks.mintwoodLeaves);
		setBlock(world, i + 8, j + 14, k + 6, ModBlocks.mintwoodLeaves);
		setBlock(world, i + 8, j + 14, k + 7, ModBlocks.mintwoodLeaves);
		setBlock(world, i + 8, j + 14, k + 8, ModBlocks.mintwoodLeaves);
		setBlock(world, i + 8, j + 14, k + 9, ModBlocks.mintwoodLeaves);
		setBlock(world, i + 8, j + 14, k + 10, ModBlocks.mintwoodLeaves);
		setBlock(world, i + 8, j + 14, k + 11, ModBlocks.mintwoodLeaves);
		setBlock(world, i + 8, j + 14, k + 12, ModBlocks.mintwoodLeaves);
		setBlock(world, i + 8, j + 14, k + 13, ModBlocks.mintwoodLeaves);
		setBlock(world, i + 8, j + 15, k + 1, ModBlocks.mintwoodLeaves);
		setBlock(world, i + 8, j + 15, k + 2, ModBlocks.mintwoodLeaves);
		setBlock(world, i + 8, j + 15, k + 3, ModBlocks.mintwoodLeaves);
		setBlock(world, i + 8, j + 15, k + 4, ModBlocks.mintwoodLeaves);
		setBlock(world, i + 8, j + 15, k + 5, ModBlocks.mintwoodLeaves);
		setBlock(world, i + 8, j + 15, k + 6, ModBlocks.mintwoodLeaves);
		setBlock(world, i + 8, j + 15, k + 7, ModBlocks.mintwoodLeaves);
		setBlock(world, i + 8, j + 15, k + 8, ModBlocks.mintwoodLeaves);
		setBlock(world, i + 8, j + 15, k + 9, ModBlocks.mintwoodLeaves);
		setBlock(world, i + 8, j + 15, k + 10, ModBlocks.mintwoodLeaves);
		setBlock(world, i + 8, j + 15, k + 11, ModBlocks.mintwoodLeaves);
		setBlock(world, i + 8, j + 15, k + 12, ModBlocks.mintwoodLeaves);
		setBlock(world, i + 8, j + 16, k + 1, ModBlocks.mintwoodLeaves);
		setBlock(world, i + 8, j + 16, k + 2, ModBlocks.mintwoodLeaves);
		setBlock(world, i + 8, j + 16, k + 3, ModBlocks.mintwoodLeaves);
		setBlock(world, i + 8, j + 16, k + 4, ModBlocks.mintwoodLeaves);
		setBlock(world, i + 8, j + 16, k + 5, ModBlocks.mintwoodLeaves);
		setBlock(world, i + 8, j + 16, k + 6, ModBlocks.mintwoodLeaves);
		setBlock(world, i + 8, j + 16, k + 7, ModBlocks.mintwoodLeaves);
		setBlock(world, i + 8, j + 16, k + 8, ModBlocks.mintwoodLeaves);
		setBlock(world, i + 8, j + 16, k + 9, ModBlocks.mintwoodLeaves);
		setBlock(world, i + 8, j + 16, k + 10, ModBlocks.mintwoodLeaves);
		setBlock(world, i + 8, j + 16, k + 11, ModBlocks.mintwoodLeaves);
		setBlock(world, i + 8, j + 17, k + 2, ModBlocks.mintwoodLeaves);
		setBlock(world, i + 8, j + 17, k + 3, ModBlocks.mintwoodLeaves);
		setBlock(world, i + 8, j + 17, k + 4, ModBlocks.mintwoodLeaves);
		setBlock(world, i + 8, j + 17, k + 5, ModBlocks.mintwoodLeaves);
		setBlock(world, i + 8, j + 17, k + 6, ModBlocks.mintwoodLeaves);
		setBlock(world, i + 8, j + 17, k + 7, ModBlocks.mintwoodLeaves);
		setBlock(world, i + 8, j + 17, k + 8, ModBlocks.mintwoodLeaves);
		setBlock(world, i + 8, j + 17, k + 9, ModBlocks.mintwoodLeaves);
		setBlock(world, i + 8, j + 17, k + 10, ModBlocks.mintwoodLeaves);
		setBlock(world, i + 8, j + 18, k + 2, ModBlocks.mintwoodLeaves);
		setBlock(world, i + 8, j + 18, k + 3, ModBlocks.mintwoodLeaves);
		setBlock(world, i + 8, j + 18, k + 4, ModBlocks.mintwoodLeaves);
		setBlock(world, i + 8, j + 18, k + 5, ModBlocks.mintwoodLeaves);
		setBlock(world, i + 8, j + 18, k + 6, ModBlocks.mintwoodLeaves);
		setBlock(world, i + 8, j + 18, k + 7, ModBlocks.mintwoodLeaves);
		setBlock(world, i + 8, j + 18, k + 8, ModBlocks.mintwoodLeaves);
		setBlock(world, i + 8, j + 18, k + 9, ModBlocks.mintwoodLeaves);
		setBlock(world, i + 8, j + 18, k + 10, ModBlocks.mintwoodLeaves);
		setBlock(world, i + 8, j + 19, k + 2, ModBlocks.mintwoodLeaves);
		setBlock(world, i + 8, j + 19, k + 3, ModBlocks.mintwoodLeaves);
		setBlock(world, i + 8, j + 19, k + 4, ModBlocks.mintwoodLeaves);
		setBlock(world, i + 8, j + 19, k + 5, ModBlocks.mintwoodLeaves);
		setBlock(world, i + 8, j + 19, k + 6, ModBlocks.mintwoodLeaves);
		setBlock(world, i + 8, j + 19, k + 7, ModBlocks.mintwoodLeaves);
		setBlock(world, i + 8, j + 19, k + 8, ModBlocks.mintwoodLeaves);
		setBlock(world, i + 8, j + 19, k + 9, ModBlocks.mintwoodLeaves);
		setBlock(world, i + 8, j + 20, k + 3, ModBlocks.mintwoodLeaves);
		setBlock(world, i + 8, j + 20, k + 4, ModBlocks.mintwoodLeaves);
		setBlock(world, i + 8, j + 20, k + 5, ModBlocks.mintwoodLeaves);
		setBlock(world, i + 8, j + 20, k + 6, ModBlocks.mintwoodLeaves);
		setBlock(world, i + 8, j + 20, k + 7, ModBlocks.mintwoodLeaves);
		setBlock(world, i + 9, j + 0, k + 6, ModBlocks.mintwoodLog);
		setBlock(world, i + 9, j + 0, k + 7, ModBlocks.mintwoodLog);
		setBlock(world, i + 9, j + 1, k + 6, ModBlocks.mintwoodLog);
		setBlock(world, i + 9, j + 1, k + 7, ModBlocks.mintwoodLog);
		setBlock(world, i + 9, j + 2, k + 6, ModBlocks.mintwoodLog);
		setBlock(world, i + 9, j + 2, k + 7, ModBlocks.mintwoodLog);
		setBlock(world, i + 9, j + 3, k + 6, ModBlocks.mintwoodLog);
		setBlock(world, i + 9, j + 3, k + 7, ModBlocks.mintwoodLog);
		setBlock(world, i + 9, j + 4, k + 6, ModBlocks.mintwoodLog);
		setBlock(world, i + 9, j + 4, k + 7, ModBlocks.mintwoodLog);
		setBlock(world, i + 9, j + 5, k + 6, ModBlocks.mintwoodLog);
		setBlock(world, i + 9, j + 5, k + 7, ModBlocks.mintwoodLog);
		setBlock(world, i + 9, j + 6, k + 6, ModBlocks.mintwoodLog);
		setBlock(world, i + 9, j + 6, k + 7, ModBlocks.mintwoodLog);
		setBlock(world, i + 9, j + 7, k + 6, ModBlocks.mintwoodLog);
		setBlock(world, i + 9, j + 7, k + 7, ModBlocks.mintwoodLog);
		setBlock(world, i + 9, j + 8, k + 6, ModBlocks.mintwoodLog);
		setBlock(world, i + 9, j + 8, k + 7, ModBlocks.mintwoodLog);
		setBlock(world, i + 9, j + 9, k + 6, ModBlocks.mintwoodLog);
		setBlock(world, i + 9, j + 9, k + 7, ModBlocks.mintwoodLog);
		setBlock(world, i + 9, j + 10, k + 6, ModBlocks.mintwoodLog);
		setBlock(world, i + 9, j + 10, k + 7, ModBlocks.mintwoodLog);
		setBlock(world, i + 9, j + 11, k + 4, ModBlocks.mintwoodLeaves);
		setBlock(world, i + 9, j + 11, k + 5, ModBlocks.mintwoodLeaves);
		setBlock(world, i + 9, j + 11, k + 6, ModBlocks.mintwoodLeaves);
		setBlock(world, i + 9, j + 11, k + 7, ModBlocks.mintwoodLeaves);
		setBlock(world, i + 9, j + 11, k + 8, ModBlocks.mintwoodLeaves);
		setBlock(world, i + 9, j + 12, k + 3, ModBlocks.mintwoodLeaves);
		setBlock(world, i + 9, j + 12, k + 4, ModBlocks.mintwoodLeaves);
		setBlock(world, i + 9, j + 12, k + 5, ModBlocks.mintwoodLeaves);
		setBlock(world, i + 9, j + 12, k + 6, ModBlocks.mintwoodLeaves);
		setBlock(world, i + 9, j + 12, k + 7, ModBlocks.mintwoodLeaves);
		setBlock(world, i + 9, j + 12, k + 8, ModBlocks.mintwoodLeaves);
		setBlock(world, i + 9, j + 12, k + 9, ModBlocks.mintwoodLeaves);
		setBlock(world, i + 9, j + 12, k + 10, ModBlocks.mintwoodLeaves);
		setBlock(world, i + 9, j + 12, k + 11, ModBlocks.mintwoodLeaves);
		setBlock(world, i + 9, j + 12, k + 12, ModBlocks.mintwoodLeaves);
		setBlock(world, i + 9, j + 13, k + 2, ModBlocks.mintwoodLeaves);
		setBlock(world, i + 9, j + 13, k + 3, ModBlocks.mintwoodLeaves);
		setBlock(world, i + 9, j + 13, k + 4, ModBlocks.mintwoodLeaves);
		setBlock(world, i + 9, j + 13, k + 5, ModBlocks.mintwoodLeaves);
		setBlock(world, i + 9, j + 13, k + 6, ModBlocks.mintwoodLeaves);
		setBlock(world, i + 9, j + 13, k + 7, ModBlocks.mintwoodLeaves);
		setBlock(world, i + 9, j + 13, k + 8, ModBlocks.mintwoodLeaves);
		setBlock(world, i + 9, j + 13, k + 9, ModBlocks.mintwoodLeaves);
		setBlock(world, i + 9, j + 13, k + 10, ModBlocks.mintwoodLeaves);
		setBlock(world, i + 9, j + 13, k + 11, ModBlocks.mintwoodLeaves);
		setBlock(world, i + 9, j + 13, k + 12, ModBlocks.mintwoodLeaves);
		setBlock(world, i + 9, j + 14, k + 2, ModBlocks.mintwoodLeaves);
		setBlock(world, i + 9, j + 14, k + 3, ModBlocks.mintwoodLeaves);
		setBlock(world, i + 9, j + 14, k + 4, ModBlocks.mintwoodLeaves);
		setBlock(world, i + 9, j + 14, k + 5, ModBlocks.mintwoodLeaves);
		setBlock(world, i + 9, j + 14, k + 6, ModBlocks.mintwoodLeaves);
		setBlock(world, i + 9, j + 14, k + 7, ModBlocks.mintwoodLeaves);
		setBlock(world, i + 9, j + 14, k + 8, ModBlocks.mintwoodLeaves);
		setBlock(world, i + 9, j + 14, k + 9, ModBlocks.mintwoodLeaves);
		setBlock(world, i + 9, j + 14, k + 10, ModBlocks.mintwoodLeaves);
		setBlock(world, i + 9, j + 14, k + 11, ModBlocks.mintwoodLeaves);
		setBlock(world, i + 9, j + 14, k + 12, ModBlocks.mintwoodLeaves);
		setBlock(world, i + 9, j + 15, k + 2, ModBlocks.mintwoodLeaves);
		setBlock(world, i + 9, j + 15, k + 3, ModBlocks.mintwoodLeaves);
		setBlock(world, i + 9, j + 15, k + 4, ModBlocks.mintwoodLeaves);
		setBlock(world, i + 9, j + 15, k + 5, ModBlocks.mintwoodLeaves);
		setBlock(world, i + 9, j + 15, k + 6, ModBlocks.mintwoodLeaves);
		setBlock(world, i + 9, j + 15, k + 7, ModBlocks.mintwoodLeaves);
		setBlock(world, i + 9, j + 15, k + 8, ModBlocks.mintwoodLeaves);
		setBlock(world, i + 9, j + 15, k + 9, ModBlocks.mintwoodLeaves);
		setBlock(world, i + 9, j + 15, k + 11, ModBlocks.mintwoodLeaves);
		setBlock(world, i + 9, j + 15, k + 12, ModBlocks.mintwoodLeaves);
		setBlock(world, i + 9, j + 16, k + 2, ModBlocks.mintwoodLeaves);
		setBlock(world, i + 9, j + 16, k + 3, ModBlocks.mintwoodLeaves);
		setBlock(world, i + 9, j + 16, k + 4, ModBlocks.mintwoodLeaves);
		setBlock(world, i + 9, j + 16, k + 5, ModBlocks.mintwoodLeaves);
		setBlock(world, i + 9, j + 16, k + 6, ModBlocks.mintwoodLeaves);
		setBlock(world, i + 9, j + 16, k + 7, ModBlocks.mintwoodLeaves);
		setBlock(world, i + 9, j + 16, k + 8, ModBlocks.mintwoodLeaves);
		setBlock(world, i + 9, j + 16, k + 9, ModBlocks.mintwoodLeaves);
		setBlock(world, i + 9, j + 16, k + 10, ModBlocks.mintwoodLeaves);
		setBlock(world, i + 9, j + 16, k + 11, ModBlocks.mintwoodLeaves);
		setBlock(world, i + 9, j + 17, k + 2, ModBlocks.mintwoodLeaves);
		setBlock(world, i + 9, j + 17, k + 3, ModBlocks.mintwoodLeaves);
		setBlock(world, i + 9, j + 17, k + 4, ModBlocks.mintwoodLeaves);
		setBlock(world, i + 9, j + 17, k + 5, ModBlocks.mintwoodLeaves);
		setBlock(world, i + 9, j + 17, k + 6, ModBlocks.mintwoodLeaves);
		setBlock(world, i + 9, j + 17, k + 7, ModBlocks.mintwoodLeaves);
		setBlock(world, i + 9, j + 17, k + 8, ModBlocks.mintwoodLeaves);
		setBlock(world, i + 9, j + 17, k + 9, ModBlocks.mintwoodLeaves);
		setBlock(world, i + 9, j + 17, k + 10, ModBlocks.mintwoodLeaves);
		setBlock(world, i + 9, j + 18, k + 2, ModBlocks.mintwoodLeaves);
		setBlock(world, i + 9, j + 18, k + 3, ModBlocks.mintwoodLeaves);
		setBlock(world, i + 9, j + 18, k + 4, ModBlocks.mintwoodLeaves);
		setBlock(world, i + 9, j + 18, k + 5, ModBlocks.mintwoodLeaves);
		setBlock(world, i + 9, j + 18, k + 6, ModBlocks.mintwoodLeaves);
		setBlock(world, i + 9, j + 18, k + 7, ModBlocks.mintwoodLeaves);
		setBlock(world, i + 9, j + 18, k + 8, ModBlocks.mintwoodLeaves);
		setBlock(world, i + 9, j + 18, k + 9, ModBlocks.mintwoodLeaves);
		setBlock(world, i + 9, j + 19, k + 2, ModBlocks.mintwoodLeaves);
		setBlock(world, i + 9, j + 19, k + 3, ModBlocks.mintwoodLeaves);
		setBlock(world, i + 9, j + 19, k + 5, ModBlocks.mintwoodLeaves);
		setBlock(world, i + 9, j + 19, k + 6, ModBlocks.mintwoodLeaves);
		setBlock(world, i + 9, j + 19, k + 7, ModBlocks.mintwoodLeaves);
		setBlock(world, i + 9, j + 19, k + 8, ModBlocks.mintwoodLeaves);
		setBlock(world, i + 9, j + 20, k + 3, ModBlocks.mintwoodLeaves);
		setBlock(world, i + 9, j + 20, k + 4, ModBlocks.mintwoodLeaves);
		setBlock(world, i + 9, j + 20, k + 5, ModBlocks.mintwoodLeaves);
		setBlock(world, i + 10, j + 12, k + 4, ModBlocks.mintwoodLeaves);
		setBlock(world, i + 10, j + 12, k + 5, ModBlocks.mintwoodLeaves);
		setBlock(world, i + 10, j + 12, k + 6, ModBlocks.mintwoodLeaves);
		setBlock(world, i + 10, j + 12, k + 7, ModBlocks.mintwoodLeaves);
		setBlock(world, i + 10, j + 12, k + 8, ModBlocks.mintwoodLeaves);
		setBlock(world, i + 10, j + 12, k + 9, ModBlocks.mintwoodLeaves);
		setBlock(world, i + 10, j + 12, k + 10, ModBlocks.mintwoodLeaves);
		setBlock(world, i + 10, j + 12, k + 11, ModBlocks.mintwoodLeaves);
		setBlock(world, i + 10, j + 13, k + 2, ModBlocks.mintwoodLeaves);
		setBlock(world, i + 10, j + 13, k + 3, ModBlocks.mintwoodLeaves);
		setBlock(world, i + 10, j + 13, k + 4, ModBlocks.mintwoodLeaves);
		setBlock(world, i + 10, j + 13, k + 5, ModBlocks.mintwoodLeaves);
		setBlock(world, i + 10, j + 13, k + 6, ModBlocks.mintwoodLeaves);
		setBlock(world, i + 10, j + 13, k + 7, ModBlocks.mintwoodLeaves);
		setBlock(world, i + 10, j + 13, k + 8, ModBlocks.mintwoodLeaves);
		setBlock(world, i + 10, j + 13, k + 9, ModBlocks.mintwoodLeaves);
		setBlock(world, i + 10, j + 13, k + 10, ModBlocks.mintwoodLeaves);
		setBlock(world, i + 10, j + 13, k + 11, ModBlocks.mintwoodLeaves);
		setBlock(world, i + 10, j + 13, k + 12, ModBlocks.mintwoodLeaves);
		setBlock(world, i + 10, j + 14, k + 1, ModBlocks.mintwoodLeaves);
		setBlock(world, i + 10, j + 14, k + 2, ModBlocks.mintwoodLeaves);
		setBlock(world, i + 10, j + 14, k + 3, ModBlocks.mintwoodLeaves);
		setBlock(world, i + 10, j + 14, k + 4, ModBlocks.mintwoodLeaves);
		setBlock(world, i + 10, j + 14, k + 5, ModBlocks.mintwoodLeaves);
		setBlock(world, i + 10, j + 14, k + 6, ModBlocks.mintwoodLeaves);
		setBlock(world, i + 10, j + 14, k + 7, ModBlocks.mintwoodLeaves);
		setBlock(world, i + 10, j + 14, k + 8, ModBlocks.mintwoodLeaves);
		setBlock(world, i + 10, j + 14, k + 9, ModBlocks.mintwoodLeaves);
		setBlock(world, i + 10, j + 14, k + 10, ModBlocks.mintwoodLeaves);
		setBlock(world, i + 10, j + 14, k + 11, ModBlocks.mintwoodLeaves);
		setBlock(world, i + 10, j + 14, k + 12, ModBlocks.mintwoodLeaves);
		setBlock(world, i + 10, j + 15, k + 1, ModBlocks.mintwoodLeaves);
		setBlock(world, i + 10, j + 15, k + 2, ModBlocks.mintwoodLeaves);
		setBlock(world, i + 10, j + 15, k + 3, ModBlocks.mintwoodLeaves);
		setBlock(world, i + 10, j + 15, k + 4, ModBlocks.mintwoodLeaves);
		setBlock(world, i + 10, j + 15, k + 5, ModBlocks.mintwoodLeaves);
		setBlock(world, i + 10, j + 15, k + 6, ModBlocks.mintwoodLeaves);
		setBlock(world, i + 10, j + 15, k + 7, ModBlocks.mintwoodLeaves);
		setBlock(world, i + 10, j + 15, k + 8, ModBlocks.mintwoodLeaves);
		setBlock(world, i + 10, j + 15, k + 9, ModBlocks.mintwoodLeaves);
		setBlock(world, i + 10, j + 15, k + 10, ModBlocks.mintwoodLeaves);
		setBlock(world, i + 10, j + 15, k + 12, ModBlocks.mintwoodLeaves);
		setBlock(world, i + 10, j + 16, k + 1, ModBlocks.mintwoodLeaves);
		setBlock(world, i + 10, j + 16, k + 2, ModBlocks.mintwoodLeaves);
		setBlock(world, i + 10, j + 16, k + 3, ModBlocks.mintwoodLeaves);
		setBlock(world, i + 10, j + 16, k + 4, ModBlocks.mintwoodLeaves);
		setBlock(world, i + 10, j + 16, k + 5, ModBlocks.mintwoodLeaves);
		setBlock(world, i + 10, j + 16, k + 6, ModBlocks.mintwoodLeaves);
		setBlock(world, i + 10, j + 16, k + 7, ModBlocks.mintwoodLeaves);
		setBlock(world, i + 10, j + 16, k + 8, ModBlocks.mintwoodLeaves);
		setBlock(world, i + 10, j + 16, k + 9, ModBlocks.mintwoodLeaves);
		setBlock(world, i + 10, j + 16, k + 10, ModBlocks.mintwoodLeaves);
		setBlock(world, i + 10, j + 16, k + 11, ModBlocks.mintwoodLeaves);
		setBlock(world, i + 10, j + 17, k + 2, ModBlocks.mintwoodLeaves);
		setBlock(world, i + 10, j + 17, k + 3, ModBlocks.mintwoodLeaves);
		setBlock(world, i + 10, j + 17, k + 4, ModBlocks.mintwoodLeaves);
		setBlock(world, i + 10, j + 17, k + 5, ModBlocks.mintwoodLeaves);
		setBlock(world, i + 10, j + 17, k + 6, ModBlocks.mintwoodLeaves);
		setBlock(world, i + 10, j + 17, k + 7, ModBlocks.mintwoodLeaves);
		setBlock(world, i + 10, j + 17, k + 8, ModBlocks.mintwoodLeaves);
		setBlock(world, i + 10, j + 17, k + 9, ModBlocks.mintwoodLeaves);
		setBlock(world, i + 10, j + 18, k + 2, ModBlocks.mintwoodLeaves);
		setBlock(world, i + 10, j + 18, k + 3, ModBlocks.mintwoodLeaves);
		setBlock(world, i + 10, j + 18, k + 4, ModBlocks.mintwoodLeaves);
		setBlock(world, i + 10, j + 18, k + 5, ModBlocks.mintwoodLeaves);
		setBlock(world, i + 10, j + 18, k + 6, ModBlocks.mintwoodLeaves);
		setBlock(world, i + 10, j + 18, k + 7, ModBlocks.mintwoodLeaves);
		setBlock(world, i + 10, j + 18, k + 8, ModBlocks.mintwoodLeaves);
		setBlock(world, i + 10, j + 19, k + 2, ModBlocks.mintwoodLeaves);
		setBlock(world, i + 10, j + 19, k + 3, ModBlocks.mintwoodLeaves);
		setBlock(world, i + 10, j + 19, k + 4, ModBlocks.mintwoodLeaves);
		setBlock(world, i + 10, j + 19, k + 5, ModBlocks.mintwoodLeaves);
		setBlock(world, i + 10, j + 19, k + 6, ModBlocks.mintwoodLeaves);
		setBlock(world, i + 10, j + 20, k + 3, ModBlocks.mintwoodLeaves);
		setBlock(world, i + 10, j + 20, k + 4, ModBlocks.mintwoodLeaves);
		setBlock(world, i + 10, j + 20, k + 5, ModBlocks.mintwoodLeaves);
		setBlock(world, i + 11, j + 12, k + 9, ModBlocks.mintwoodLeaves);
		setBlock(world, i + 11, j + 12, k + 10, ModBlocks.mintwoodLeaves);
		setBlock(world, i + 11, j + 12, k + 11, ModBlocks.mintwoodLeaves);
		setBlock(world, i + 11, j + 13, k + 2, ModBlocks.mintwoodLeaves);
		setBlock(world, i + 11, j + 13, k + 3, ModBlocks.mintwoodLeaves);
		setBlock(world, i + 11, j + 13, k + 4, ModBlocks.mintwoodLeaves);
		setBlock(world, i + 11, j + 13, k + 5, ModBlocks.mintwoodLeaves);
		setBlock(world, i + 11, j + 13, k + 6, ModBlocks.mintwoodLeaves);
		setBlock(world, i + 11, j + 13, k + 7, ModBlocks.mintwoodLeaves);
		setBlock(world, i + 11, j + 13, k + 8, ModBlocks.mintwoodLeaves);
		setBlock(world, i + 11, j + 13, k + 9, ModBlocks.mintwoodLeaves);
		setBlock(world, i + 11, j + 13, k + 10, ModBlocks.mintwoodLeaves);
		setBlock(world, i + 11, j + 13, k + 11, ModBlocks.mintwoodLeaves);
		setBlock(world, i + 11, j + 13, k + 12, ModBlocks.mintwoodLeaves);
		setBlock(world, i + 11, j + 14, k + 1, ModBlocks.mintwoodLeaves);
		setBlock(world, i + 11, j + 14, k + 2, ModBlocks.mintwoodLeaves);
		setBlock(world, i + 11, j + 14, k + 3, ModBlocks.mintwoodLeaves);
		setBlock(world, i + 11, j + 14, k + 4, ModBlocks.mintwoodLeaves);
		setBlock(world, i + 11, j + 14, k + 5, ModBlocks.mintwoodLeaves);
		setBlock(world, i + 11, j + 14, k + 6, ModBlocks.mintwoodLeaves);
		setBlock(world, i + 11, j + 14, k + 7, ModBlocks.mintwoodLeaves);
		setBlock(world, i + 11, j + 14, k + 8, ModBlocks.mintwoodLeaves);
		setBlock(world, i + 11, j + 14, k + 9, ModBlocks.mintwoodLeaves);
		setBlock(world, i + 11, j + 14, k + 10, ModBlocks.mintwoodLeaves);
		setBlock(world, i + 11, j + 14, k + 11, ModBlocks.mintwoodLeaves);
		setBlock(world, i + 11, j + 14, k + 12, ModBlocks.mintwoodLeaves);
		setBlock(world, i + 11, j + 15, k + 1, ModBlocks.mintwoodLeaves);
		setBlock(world, i + 11, j + 15, k + 2, ModBlocks.mintwoodLeaves);
		setBlock(world, i + 11, j + 15, k + 3, ModBlocks.mintwoodLeaves);
		setBlock(world, i + 11, j + 15, k + 4, ModBlocks.mintwoodLeaves);
		setBlock(world, i + 11, j + 15, k + 5, ModBlocks.mintwoodLeaves);
		setBlock(world, i + 11, j + 15, k + 6, ModBlocks.mintwoodLeaves);
		setBlock(world, i + 11, j + 15, k + 7, ModBlocks.mintwoodLeaves);
		setBlock(world, i + 11, j + 15, k + 8, ModBlocks.mintwoodLeaves);
		setBlock(world, i + 11, j + 15, k + 9, ModBlocks.mintwoodLeaves);
		setBlock(world, i + 11, j + 15, k + 10, ModBlocks.mintwoodLeaves);
		setBlock(world, i + 11, j + 15, k + 11, ModBlocks.mintwoodLeaves);
		setBlock(world, i + 11, j + 15, k + 12, ModBlocks.mintwoodLeaves);
		setBlock(world, i + 11, j + 16, k + 1, ModBlocks.mintwoodLeaves);
		setBlock(world, i + 11, j + 16, k + 2, ModBlocks.mintwoodLeaves);
		setBlock(world, i + 11, j + 16, k + 3, ModBlocks.mintwoodLeaves);
		setBlock(world, i + 11, j + 16, k + 4, ModBlocks.mintwoodLeaves);
		setBlock(world, i + 11, j + 16, k + 5, ModBlocks.mintwoodLeaves);
		setBlock(world, i + 11, j + 16, k + 6, ModBlocks.mintwoodLeaves);
		setBlock(world, i + 11, j + 16, k + 7, ModBlocks.mintwoodLeaves);
		setBlock(world, i + 11, j + 16, k + 8, ModBlocks.mintwoodLeaves);
		setBlock(world, i + 11, j + 16, k + 9, ModBlocks.mintwoodLeaves);
		setBlock(world, i + 11, j + 16, k + 10, ModBlocks.mintwoodLeaves);
		setBlock(world, i + 11, j + 16, k + 11, ModBlocks.mintwoodLeaves);
		setBlock(world, i + 11, j + 17, k + 2, ModBlocks.mintwoodLeaves);
		setBlock(world, i + 11, j + 17, k + 3, ModBlocks.mintwoodLeaves);
		setBlock(world, i + 11, j + 17, k + 4, ModBlocks.mintwoodLeaves);
		setBlock(world, i + 11, j + 17, k + 5, ModBlocks.mintwoodLeaves);
		setBlock(world, i + 11, j + 17, k + 6, ModBlocks.mintwoodLeaves);
		setBlock(world, i + 11, j + 17, k + 7, ModBlocks.mintwoodLeaves);
		setBlock(world, i + 11, j + 18, k + 3, ModBlocks.mintwoodLeaves);
		setBlock(world, i + 11, j + 18, k + 4, ModBlocks.mintwoodLeaves);
		setBlock(world, i + 11, j + 18, k + 5, ModBlocks.mintwoodLeaves);
		setBlock(world, i + 11, j + 19, k + 3, ModBlocks.mintwoodLeaves);
		setBlock(world, i + 11, j + 19, k + 4, ModBlocks.mintwoodLeaves);
		setBlock(world, i + 11, j + 19, k + 5, ModBlocks.mintwoodLeaves);
		setBlock(world, i + 12, j + 13, k + 2, ModBlocks.mintwoodLeaves);
		setBlock(world, i + 12, j + 13, k + 3, ModBlocks.mintwoodLeaves);
		setBlock(world, i + 12, j + 13, k + 4, ModBlocks.mintwoodLeaves);
		setBlock(world, i + 12, j + 13, k + 9, ModBlocks.mintwoodLeaves);
		setBlock(world, i + 12, j + 13, k + 10, ModBlocks.mintwoodLeaves);
		setBlock(world, i + 12, j + 13, k + 11, ModBlocks.mintwoodLeaves);
		setBlock(world, i + 12, j + 14, k + 1, ModBlocks.mintwoodLeaves);
		setBlock(world, i + 12, j + 14, k + 2, ModBlocks.mintwoodLeaves);
		setBlock(world, i + 12, j + 14, k + 3, ModBlocks.mintwoodLeaves);
		setBlock(world, i + 12, j + 14, k + 4, ModBlocks.mintwoodLeaves);
		setBlock(world, i + 12, j + 14, k + 5, ModBlocks.mintwoodLeaves);
		setBlock(world, i + 12, j + 14, k + 9, ModBlocks.mintwoodLeaves);
		setBlock(world, i + 12, j + 14, k + 10, ModBlocks.mintwoodLeaves);
		setBlock(world, i + 12, j + 14, k + 11, ModBlocks.mintwoodLeaves);
		setBlock(world, i + 12, j + 15, k + 1, ModBlocks.mintwoodLeaves);
		setBlock(world, i + 12, j + 15, k + 2, ModBlocks.mintwoodLeaves);
		setBlock(world, i + 12, j + 15, k + 3, ModBlocks.mintwoodLeaves);
		setBlock(world, i + 12, j + 15, k + 4, ModBlocks.mintwoodLeaves);
		setBlock(world, i + 12, j + 15, k + 5, ModBlocks.mintwoodLeaves);
		setBlock(world, i + 12, j + 15, k + 9, ModBlocks.mintwoodLeaves);
		setBlock(world, i + 12, j + 15, k + 10, ModBlocks.mintwoodLeaves);
		setBlock(world, i + 12, j + 15, k + 11, ModBlocks.mintwoodLeaves);
		setBlock(world, i + 12, j + 16, k + 1, ModBlocks.mintwoodLeaves);
		setBlock(world, i + 12, j + 16, k + 2, ModBlocks.mintwoodLeaves);
		setBlock(world, i + 12, j + 16, k + 3, ModBlocks.mintwoodLeaves);
		setBlock(world, i + 12, j + 16, k + 4, ModBlocks.mintwoodLeaves);
		setBlock(world, i + 12, j + 16, k + 5, ModBlocks.mintwoodLeaves);
		setBlock(world, i + 12, j + 16, k + 10, ModBlocks.mintwoodLeaves);
		setBlock(world, i + 12, j + 17, k + 2, ModBlocks.mintwoodLeaves);
		setBlock(world, i + 12, j + 17, k + 3, ModBlocks.mintwoodLeaves);
		setBlock(world, i + 12, j + 17, k + 4, ModBlocks.mintwoodLeaves);
		setBlock(world, i + 13, j + 14, k + 2, ModBlocks.mintwoodLeaves);
		setBlock(world, i + 13, j + 14, k + 3, ModBlocks.mintwoodLeaves);
		setBlock(world, i + 13, j + 14, k + 4, ModBlocks.mintwoodLeaves);
		setBlock(world, i + 13, j + 15, k + 2, ModBlocks.mintwoodLeaves);
		setBlock(world, i + 13, j + 15, k + 3, ModBlocks.mintwoodLeaves);
		setBlock(world, i + 13, j + 15, k + 4, ModBlocks.mintwoodLeaves);
		setBlock(world, i + 13, j + 16, k + 2, ModBlocks.mintwoodLeaves);
		setBlock(world, i + 13, j + 16, k + 4, ModBlocks.mintwoodLeaves);

		return true;
	}
}