/*
*** MADE BY MITHION'S .SCHEMATIC TO JAVA CONVERTING TOOL v1.6 ***
*/

package divinerpg.dimensions.vethea.layer3;
import java.util.Random;

import divinerpg.dimensions.vethea.VetheaWorldGenerator;
import divinerpg.registry.ModBlocks;
import net.minecraft.block.Block;
import net.minecraft.util.math.BlockPos;
import net.minecraft.world.World;
import net.minecraft.world.gen.feature.WorldGenerator;

public class Tree7 extends VetheaWorldGenerator
{
	protected int[] GetValidSpawnBlocks() {
		return new int[] {
		};
	}

	public boolean generate(World world, Random rand, int i, int j, int k) {

		setBlock(world, i + 0, j + 7, k + 4, ModBlocks.hyrewoodLeaves);
		setBlock(world, i + 0, j + 8, k + 3, ModBlocks.hyrewoodLeaves);
		setBlock(world, i + 0, j + 8, k + 4, ModBlocks.hyrewoodLeaves);
		setBlock(world, i + 0, j + 8, k + 5, ModBlocks.hyrewoodLeaves);
		setBlock(world, i + 0, j + 9, k + 2, ModBlocks.hyrewoodLeaves);
		setBlock(world, i + 0, j + 9, k + 3, ModBlocks.hyrewoodLeaves);
		setBlock(world, i + 0, j + 9, k + 4, ModBlocks.hyrewoodLeaves);
		setBlock(world, i + 0, j + 9, k + 5, ModBlocks.hyrewoodLeaves);
		setBlock(world, i + 0, j + 9, k + 6, ModBlocks.hyrewoodLeaves);
		setBlock(world, i + 0, j + 10, k + 3, ModBlocks.hyrewoodLeaves);
		setBlock(world, i + 0, j + 10, k + 4, ModBlocks.hyrewoodLeaves);
		setBlock(world, i + 0, j + 10, k + 5, ModBlocks.hyrewoodLeaves);
		setBlock(world, i + 0, j + 11, k + 4, ModBlocks.hyrewoodLeaves);
		setBlock(world, i + 1, j + 6, k + 3, ModBlocks.hyrewoodLeaves);
		setBlock(world, i + 1, j + 6, k + 4, ModBlocks.hyrewoodLeaves);
		setBlock(world, i + 1, j + 6, k + 5, ModBlocks.hyrewoodLeaves);
		setBlock(world, i + 1, j + 7, k + 2, ModBlocks.hyrewoodLeaves);
		setBlock(world, i + 1, j + 7, k + 3, ModBlocks.hyrewoodLeaves);
		setBlock(world, i + 1, j + 7, k + 4, ModBlocks.hyrewoodLeaves);
		setBlock(world, i + 1, j + 7, k + 5, ModBlocks.hyrewoodLeaves);
		setBlock(world, i + 1, j + 7, k + 6, ModBlocks.hyrewoodLeaves);
		setBlock(world, i + 1, j + 8, k + 1, ModBlocks.hyrewoodLeaves);
		setBlock(world, i + 1, j + 8, k + 2, ModBlocks.hyrewoodLeaves);
		setBlock(world, i + 1, j + 8, k + 3, ModBlocks.hyrewoodLeaves);
		setBlock(world, i + 1, j + 8, k + 4, ModBlocks.hyrewoodLeaves);
		setBlock(world, i + 1, j + 8, k + 5, ModBlocks.hyrewoodLeaves);
		setBlock(world, i + 1, j + 8, k + 6, ModBlocks.hyrewoodLeaves);
		setBlock(world, i + 1, j + 8, k + 7, ModBlocks.hyrewoodLeaves);
		setBlock(world, i + 1, j + 9, k + 1, ModBlocks.hyrewoodLeaves);
		setBlock(world, i + 1, j + 9, k + 2, ModBlocks.hyrewoodLeaves);
		setBlock(world, i + 1, j + 9, k + 3, ModBlocks.hyrewoodLeaves);
		setBlock(world, i + 1, j + 9, k + 4, ModBlocks.hyrewoodLeaves);
		setBlock(world, i + 1, j + 9, k + 5, ModBlocks.hyrewoodLeaves);
		setBlock(world, i + 1, j + 9, k + 6, ModBlocks.hyrewoodLeaves);
		setBlock(world, i + 1, j + 9, k + 7, ModBlocks.hyrewoodLeaves);
		setBlock(world, i + 1, j + 10, k + 1, ModBlocks.hyrewoodLeaves);
		setBlock(world, i + 1, j + 10, k + 2, ModBlocks.hyrewoodLeaves);
		setBlock(world, i + 1, j + 10, k + 3, ModBlocks.hyrewoodLeaves);
		setBlock(world, i + 1, j + 10, k + 4, ModBlocks.hyrewoodLeaves);
		setBlock(world, i + 1, j + 10, k + 5, ModBlocks.hyrewoodLeaves);
		setBlock(world, i + 1, j + 10, k + 6, ModBlocks.hyrewoodLeaves);
		setBlock(world, i + 1, j + 10, k + 7, ModBlocks.hyrewoodLeaves);
		setBlock(world, i + 1, j + 11, k + 2, ModBlocks.hyrewoodLeaves);
		setBlock(world, i + 1, j + 11, k + 3, ModBlocks.hyrewoodLeaves);
		setBlock(world, i + 1, j + 11, k + 4, ModBlocks.hyrewoodLeaves);
		setBlock(world, i + 1, j + 11, k + 5, ModBlocks.hyrewoodLeaves);
		setBlock(world, i + 1, j + 11, k + 6, ModBlocks.hyrewoodLeaves);
		setBlock(world, i + 1, j + 12, k + 3, ModBlocks.hyrewoodLeaves);
		setBlock(world, i + 1, j + 12, k + 4, ModBlocks.hyrewoodLeaves);
		setBlock(world, i + 1, j + 12, k + 5, ModBlocks.hyrewoodLeaves);
		setBlock(world, i + 2, j + 0, k + 4, ModBlocks.hyrewood);
		setBlock(world, i + 2, j + 1, k + 4, ModBlocks.hyrewood);
		setBlock(world, i + 2, j + 2, k + 4, ModBlocks.hyrewood);
		setBlock(world, i + 2, j + 3, k + 4, ModBlocks.hyrewood);
		setBlock(world, i + 2, j + 4, k + 4, ModBlocks.hyrewood);
		setBlock(world, i + 2, j + 5, k + 4, ModBlocks.hyrewoodLeaves);
		setBlock(world, i + 2, j + 6, k + 2, ModBlocks.hyrewoodLeaves);
		setBlock(world, i + 2, j + 6, k + 3, ModBlocks.hyrewoodLeaves);
		setBlock(world, i + 2, j + 6, k + 4, ModBlocks.hyrewoodLeaves);
		setBlock(world, i + 2, j + 6, k + 5, ModBlocks.hyrewoodLeaves);
		setBlock(world, i + 2, j + 6, k + 6, ModBlocks.hyrewoodLeaves);
		setBlock(world, i + 2, j + 7, k + 1, ModBlocks.hyrewoodLeaves);
		setBlock(world, i + 2, j + 7, k + 2, ModBlocks.hyrewoodLeaves);
		setBlock(world, i + 2, j + 7, k + 3, ModBlocks.hyrewoodLeaves);
		setBlock(world, i + 2, j + 7, k + 4, ModBlocks.hyrewoodLeaves);
		setBlock(world, i + 2, j + 7, k + 5, ModBlocks.hyrewoodLeaves);
		setBlock(world, i + 2, j + 7, k + 6, ModBlocks.hyrewoodLeaves);
		setBlock(world, i + 2, j + 7, k + 7, ModBlocks.hyrewoodLeaves);
		setBlock(world, i + 2, j + 8, k + 1, ModBlocks.hyrewoodLeaves);
		setBlock(world, i + 2, j + 8, k + 2, ModBlocks.hyrewoodLeaves);
		setBlock(world, i + 2, j + 8, k + 3, ModBlocks.hyrewoodLeaves);
		setBlock(world, i + 2, j + 8, k + 4, ModBlocks.hyrewoodLeaves);
		setBlock(world, i + 2, j + 8, k + 5, ModBlocks.hyrewoodLeaves);
		setBlock(world, i + 2, j + 8, k + 6, ModBlocks.hyrewoodLeaves);
		setBlock(world, i + 2, j + 8, k + 7, ModBlocks.hyrewoodLeaves);
		setBlock(world, i + 2, j + 9, k + 0, ModBlocks.hyrewoodLeaves);
		setBlock(world, i + 2, j + 9, k + 1, ModBlocks.hyrewoodLeaves);
		setBlock(world, i + 2, j + 9, k + 2, ModBlocks.hyrewoodLeaves);
		setBlock(world, i + 2, j + 9, k + 3, ModBlocks.hyrewoodLeaves);
		setBlock(world, i + 2, j + 9, k + 4, ModBlocks.hyrewoodLeaves);
		setBlock(world, i + 2, j + 9, k + 5, ModBlocks.hyrewoodLeaves);
		setBlock(world, i + 2, j + 9, k + 6, ModBlocks.hyrewoodLeaves);
		setBlock(world, i + 2, j + 9, k + 7, ModBlocks.hyrewoodLeaves);
		setBlock(world, i + 2, j + 9, k + 8, ModBlocks.hyrewoodLeaves);
		setBlock(world, i + 2, j + 10, k + 1, ModBlocks.hyrewoodLeaves);
		setBlock(world, i + 2, j + 10, k + 2, ModBlocks.hyrewoodLeaves);
		setBlock(world, i + 2, j + 10, k + 3, ModBlocks.hyrewoodLeaves);
		setBlock(world, i + 2, j + 10, k + 4, ModBlocks.hyrewoodLeaves);
		setBlock(world, i + 2, j + 10, k + 5, ModBlocks.hyrewoodLeaves);
		setBlock(world, i + 2, j + 10, k + 6, ModBlocks.hyrewoodLeaves);
		setBlock(world, i + 2, j + 10, k + 7, ModBlocks.hyrewoodLeaves);
		setBlock(world, i + 2, j + 11, k + 1, ModBlocks.hyrewoodLeaves);
		setBlock(world, i + 2, j + 11, k + 2, ModBlocks.hyrewoodLeaves);
		setBlock(world, i + 2, j + 11, k + 3, ModBlocks.hyrewoodLeaves);
		setBlock(world, i + 2, j + 11, k + 4, ModBlocks.hyrewoodLeaves);
		setBlock(world, i + 2, j + 11, k + 5, ModBlocks.hyrewoodLeaves);
		setBlock(world, i + 2, j + 11, k + 6, ModBlocks.hyrewoodLeaves);
		setBlock(world, i + 2, j + 11, k + 7, ModBlocks.hyrewoodLeaves);
		setBlock(world, i + 2, j + 12, k + 2, ModBlocks.hyrewoodLeaves);
		setBlock(world, i + 2, j + 12, k + 3, ModBlocks.hyrewoodLeaves);
		setBlock(world, i + 2, j + 12, k + 4, ModBlocks.hyrewoodLeaves);
		setBlock(world, i + 2, j + 12, k + 5, ModBlocks.hyrewoodLeaves);
		setBlock(world, i + 2, j + 12, k + 6, ModBlocks.hyrewoodLeaves);
		setBlock(world, i + 2, j + 13, k + 4, ModBlocks.hyrewoodLeaves);
		setBlock(world, i + 3, j + 0, k + 3, ModBlocks.hyrewood);
		setBlock(world, i + 3, j + 0, k + 4, ModBlocks.hyrewood);
		setBlock(world, i + 3, j + 0, k + 5, ModBlocks.hyrewood);
		setBlock(world, i + 3, j + 1, k + 3, ModBlocks.hyrewood);
		setBlock(world, i + 3, j + 1, k + 4, ModBlocks.hyrewood);
		setBlock(world, i + 3, j + 1, k + 5, ModBlocks.hyrewood);
		setBlock(world, i + 3, j + 2, k + 3, ModBlocks.hyrewood);
		setBlock(world, i + 3, j + 2, k + 4, ModBlocks.hyrewood);
		setBlock(world, i + 3, j + 2, k + 5, ModBlocks.hyrewood);
		setBlock(world, i + 3, j + 3, k + 3, ModBlocks.hyrewood);
		setBlock(world, i + 3, j + 3, k + 4, ModBlocks.hyrewood);
		setBlock(world, i + 3, j + 3, k + 5, ModBlocks.hyrewood);
		setBlock(world, i + 3, j + 4, k + 3, ModBlocks.hyrewood);
		setBlock(world, i + 3, j + 4, k + 4, ModBlocks.hyrewood);
		setBlock(world, i + 3, j + 4, k + 5, ModBlocks.hyrewood);
		setBlock(world, i + 3, j + 5, k + 3, ModBlocks.hyrewoodLeaves);
		setBlock(world, i + 3, j + 5, k + 4, ModBlocks.hyrewoodLeaves);
		setBlock(world, i + 3, j + 5, k + 5, ModBlocks.hyrewoodLeaves);
		setBlock(world, i + 3, j + 6, k + 1, ModBlocks.hyrewoodLeaves);
		setBlock(world, i + 3, j + 6, k + 2, ModBlocks.hyrewoodLeaves);
		setBlock(world, i + 3, j + 6, k + 3, ModBlocks.hyrewoodLeaves);
		setBlock(world, i + 3, j + 6, k + 4, ModBlocks.hyrewoodLeaves);
		setBlock(world, i + 3, j + 6, k + 5, ModBlocks.hyrewoodLeaves);
		setBlock(world, i + 3, j + 6, k + 6, ModBlocks.hyrewoodLeaves);
		setBlock(world, i + 3, j + 6, k + 7, ModBlocks.hyrewoodLeaves);
		setBlock(world, i + 3, j + 7, k + 1, ModBlocks.hyrewoodLeaves);
		setBlock(world, i + 3, j + 7, k + 2, ModBlocks.hyrewoodLeaves);
		setBlock(world, i + 3, j + 7, k + 3, ModBlocks.hyrewoodLeaves);
		setBlock(world, i + 3, j + 7, k + 4, ModBlocks.hyrewoodLeaves);
		setBlock(world, i + 3, j + 7, k + 5, ModBlocks.hyrewoodLeaves);
		setBlock(world, i + 3, j + 7, k + 6, ModBlocks.hyrewoodLeaves);
		setBlock(world, i + 3, j + 7, k + 7, ModBlocks.hyrewoodLeaves);
		setBlock(world, i + 3, j + 8, k + 0, ModBlocks.hyrewoodLeaves);
		setBlock(world, i + 3, j + 8, k + 1, ModBlocks.hyrewoodLeaves);
		setBlock(world, i + 3, j + 8, k + 2, ModBlocks.hyrewoodLeaves);
		setBlock(world, i + 3, j + 8, k + 3, ModBlocks.hyrewoodLeaves);
		setBlock(world, i + 3, j + 8, k + 4, ModBlocks.hyrewoodLeaves);
		setBlock(world, i + 3, j + 8, k + 5, ModBlocks.hyrewoodLeaves);
		setBlock(world, i + 3, j + 8, k + 6, ModBlocks.hyrewoodLeaves);
		setBlock(world, i + 3, j + 8, k + 7, ModBlocks.hyrewoodLeaves);
		setBlock(world, i + 3, j + 8, k + 8, ModBlocks.hyrewoodLeaves);
		setBlock(world, i + 3, j + 9, k + 0, ModBlocks.hyrewoodLeaves);
		setBlock(world, i + 3, j + 9, k + 1, ModBlocks.hyrewoodLeaves);
		setBlock(world, i + 3, j + 9, k + 2, ModBlocks.hyrewoodLeaves);
		setBlock(world, i + 3, j + 9, k + 3, ModBlocks.hyrewoodLeaves);
		setBlock(world, i + 3, j + 9, k + 4, ModBlocks.hyrewoodLeaves);
		setBlock(world, i + 3, j + 9, k + 5, ModBlocks.hyrewoodLeaves);
		setBlock(world, i + 3, j + 9, k + 6, ModBlocks.hyrewoodLeaves);
		setBlock(world, i + 3, j + 9, k + 7, ModBlocks.hyrewoodLeaves);
		setBlock(world, i + 3, j + 9, k + 8, ModBlocks.hyrewoodLeaves);
		setBlock(world, i + 3, j + 10, k + 0, ModBlocks.hyrewoodLeaves);
		setBlock(world, i + 3, j + 10, k + 1, ModBlocks.hyrewoodLeaves);
		setBlock(world, i + 3, j + 10, k + 2, ModBlocks.hyrewoodLeaves);
		setBlock(world, i + 3, j + 10, k + 3, ModBlocks.hyrewoodLeaves);
		setBlock(world, i + 3, j + 10, k + 4, ModBlocks.hyrewoodLeaves);
		setBlock(world, i + 3, j + 10, k + 5, ModBlocks.hyrewoodLeaves);
		setBlock(world, i + 3, j + 10, k + 6, ModBlocks.hyrewoodLeaves);
		setBlock(world, i + 3, j + 10, k + 7, ModBlocks.hyrewoodLeaves);
		setBlock(world, i + 3, j + 10, k + 8, ModBlocks.hyrewoodLeaves);
		setBlock(world, i + 3, j + 11, k + 1, ModBlocks.hyrewoodLeaves);
		setBlock(world, i + 3, j + 11, k + 2, ModBlocks.hyrewoodLeaves);
		setBlock(world, i + 3, j + 11, k + 3, ModBlocks.hyrewoodLeaves);
		setBlock(world, i + 3, j + 11, k + 4, ModBlocks.hyrewoodLeaves);
		setBlock(world, i + 3, j + 11, k + 5, ModBlocks.hyrewoodLeaves);
		setBlock(world, i + 3, j + 11, k + 6, ModBlocks.hyrewoodLeaves);
		setBlock(world, i + 3, j + 11, k + 7, ModBlocks.hyrewoodLeaves);
		setBlock(world, i + 3, j + 12, k + 1, ModBlocks.hyrewoodLeaves);
		setBlock(world, i + 3, j + 12, k + 2, ModBlocks.hyrewoodLeaves);
		setBlock(world, i + 3, j + 12, k + 3, ModBlocks.hyrewoodLeaves);
		setBlock(world, i + 3, j + 12, k + 4, ModBlocks.hyrewoodLeaves);
		setBlock(world, i + 3, j + 12, k + 5, ModBlocks.hyrewoodLeaves);
		setBlock(world, i + 3, j + 12, k + 6, ModBlocks.hyrewoodLeaves);
		setBlock(world, i + 3, j + 12, k + 7, ModBlocks.hyrewoodLeaves);
		setBlock(world, i + 3, j + 13, k + 3, ModBlocks.hyrewoodLeaves);
		setBlock(world, i + 3, j + 13, k + 4, ModBlocks.hyrewoodLeaves);
		setBlock(world, i + 3, j + 13, k + 5, ModBlocks.hyrewoodLeaves);
		setBlock(world, i + 4, j + 0, k + 2, ModBlocks.hyrewood);
		setBlock(world, i + 4, j + 0, k + 3, ModBlocks.hyrewood);
		setBlock(world, i + 4, j + 0, k + 4, ModBlocks.hyrewood);
		setBlock(world, i + 4, j + 0, k + 5, ModBlocks.hyrewood);
		setBlock(world, i + 4, j + 0, k + 6, ModBlocks.hyrewood);
		setBlock(world, i + 4, j + 1, k + 2, ModBlocks.hyrewood);
		setBlock(world, i + 4, j + 1, k + 3, ModBlocks.hyrewood);
		setBlock(world, i + 4, j + 1, k + 4, ModBlocks.hyrewood);
		setBlock(world, i + 4, j + 1, k + 5, ModBlocks.hyrewood);
		setBlock(world, i + 4, j + 1, k + 6, ModBlocks.hyrewood);
		setBlock(world, i + 4, j + 2, k + 2, ModBlocks.hyrewood);
		setBlock(world, i + 4, j + 2, k + 3, ModBlocks.hyrewood);
		setBlock(world, i + 4, j + 2, k + 4, ModBlocks.hyrewood);
		setBlock(world, i + 4, j + 2, k + 5, ModBlocks.hyrewood);
		setBlock(world, i + 4, j + 2, k + 6, ModBlocks.hyrewood);
		setBlock(world, i + 4, j + 3, k + 2, ModBlocks.hyrewood);
		setBlock(world, i + 4, j + 3, k + 3, ModBlocks.hyrewood);
		setBlock(world, i + 4, j + 3, k + 4, ModBlocks.hyrewood);
		setBlock(world, i + 4, j + 3, k + 5, ModBlocks.hyrewood);
		setBlock(world, i + 4, j + 3, k + 6, ModBlocks.hyrewood);
		setBlock(world, i + 4, j + 4, k + 2, ModBlocks.hyrewood);
		setBlock(world, i + 4, j + 4, k + 3, ModBlocks.hyrewood);
		setBlock(world, i + 4, j + 4, k + 4, ModBlocks.hyrewood);
		setBlock(world, i + 4, j + 4, k + 5, ModBlocks.hyrewood);
		setBlock(world, i + 4, j + 4, k + 6, ModBlocks.hyrewood);
		setBlock(world, i + 4, j + 5, k + 2, ModBlocks.hyrewoodLeaves);
		setBlock(world, i + 4, j + 5, k + 3, ModBlocks.hyrewoodLeaves);
		setBlock(world, i + 4, j + 5, k + 4, ModBlocks.hyrewoodLeaves);
		setBlock(world, i + 4, j + 5, k + 5, ModBlocks.hyrewoodLeaves);
		setBlock(world, i + 4, j + 5, k + 6, ModBlocks.hyrewoodLeaves);
		setBlock(world, i + 4, j + 6, k + 1, ModBlocks.hyrewoodLeaves);
		setBlock(world, i + 4, j + 6, k + 2, ModBlocks.hyrewoodLeaves);
		setBlock(world, i + 4, j + 6, k + 3, ModBlocks.hyrewoodLeaves);
		setBlock(world, i + 4, j + 6, k + 4, ModBlocks.hyrewoodLeaves);
		setBlock(world, i + 4, j + 6, k + 5, ModBlocks.hyrewoodLeaves);
		setBlock(world, i + 4, j + 6, k + 6, ModBlocks.hyrewoodLeaves);
		setBlock(world, i + 4, j + 6, k + 7, ModBlocks.hyrewoodLeaves);
		setBlock(world, i + 4, j + 7, k + 0, ModBlocks.hyrewoodLeaves);
		setBlock(world, i + 4, j + 7, k + 1, ModBlocks.hyrewoodLeaves);
		setBlock(world, i + 4, j + 7, k + 2, ModBlocks.hyrewoodLeaves);
		setBlock(world, i + 4, j + 7, k + 3, ModBlocks.hyrewoodLeaves);
		setBlock(world, i + 4, j + 7, k + 4, ModBlocks.hyrewoodLeaves);
		setBlock(world, i + 4, j + 7, k + 5, ModBlocks.hyrewoodLeaves);
		setBlock(world, i + 4, j + 7, k + 6, ModBlocks.hyrewoodLeaves);
		setBlock(world, i + 4, j + 7, k + 7, ModBlocks.hyrewoodLeaves);
		setBlock(world, i + 4, j + 7, k + 8, ModBlocks.hyrewoodLeaves);
		setBlock(world, i + 4, j + 8, k + 0, ModBlocks.hyrewoodLeaves);
		setBlock(world, i + 4, j + 8, k + 1, ModBlocks.hyrewoodLeaves);
		setBlock(world, i + 4, j + 8, k + 2, ModBlocks.hyrewoodLeaves);
		setBlock(world, i + 4, j + 8, k + 3, ModBlocks.hyrewoodLeaves);
		setBlock(world, i + 4, j + 8, k + 4, ModBlocks.hyrewoodLeaves);
		setBlock(world, i + 4, j + 8, k + 5, ModBlocks.hyrewoodLeaves);
		setBlock(world, i + 4, j + 8, k + 6, ModBlocks.hyrewoodLeaves);
		setBlock(world, i + 4, j + 8, k + 7, ModBlocks.hyrewoodLeaves);
		setBlock(world, i + 4, j + 8, k + 8, ModBlocks.hyrewoodLeaves);
		setBlock(world, i + 4, j + 9, k + 0, ModBlocks.hyrewoodLeaves);
		setBlock(world, i + 4, j + 9, k + 1, ModBlocks.hyrewoodLeaves);
		setBlock(world, i + 4, j + 9, k + 2, ModBlocks.hyrewoodLeaves);
		setBlock(world, i + 4, j + 9, k + 3, ModBlocks.hyrewoodLeaves);
		setBlock(world, i + 4, j + 9, k + 4, ModBlocks.hyrewoodLeaves);
		setBlock(world, i + 4, j + 9, k + 5, ModBlocks.hyrewoodLeaves);
		setBlock(world, i + 4, j + 9, k + 6, ModBlocks.hyrewoodLeaves);
		setBlock(world, i + 4, j + 9, k + 7, ModBlocks.hyrewoodLeaves);
		setBlock(world, i + 4, j + 9, k + 8, ModBlocks.hyrewoodLeaves);
		setBlock(world, i + 4, j + 10, k + 0, ModBlocks.hyrewoodLeaves);
		setBlock(world, i + 4, j + 10, k + 1, ModBlocks.hyrewoodLeaves);
		setBlock(world, i + 4, j + 10, k + 2, ModBlocks.hyrewoodLeaves);
		setBlock(world, i + 4, j + 10, k + 3, ModBlocks.hyrewoodLeaves);
		setBlock(world, i + 4, j + 10, k + 4, ModBlocks.hyrewoodLeaves);
		setBlock(world, i + 4, j + 10, k + 5, ModBlocks.hyrewoodLeaves);
		setBlock(world, i + 4, j + 10, k + 6, ModBlocks.hyrewoodLeaves);
		setBlock(world, i + 4, j + 10, k + 7, ModBlocks.hyrewoodLeaves);
		setBlock(world, i + 4, j + 10, k + 8, ModBlocks.hyrewoodLeaves);
		setBlock(world, i + 4, j + 11, k + 0, ModBlocks.hyrewoodLeaves);
		setBlock(world, i + 4, j + 11, k + 1, ModBlocks.hyrewoodLeaves);
		setBlock(world, i + 4, j + 11, k + 2, ModBlocks.hyrewoodLeaves);
		setBlock(world, i + 4, j + 11, k + 3, ModBlocks.hyrewoodLeaves);
		setBlock(world, i + 4, j + 11, k + 4, ModBlocks.hyrewoodLeaves);
		setBlock(world, i + 4, j + 11, k + 5, ModBlocks.hyrewoodLeaves);
		setBlock(world, i + 4, j + 11, k + 6, ModBlocks.hyrewoodLeaves);
		setBlock(world, i + 4, j + 11, k + 7, ModBlocks.hyrewoodLeaves);
		setBlock(world, i + 4, j + 11, k + 8, ModBlocks.hyrewoodLeaves);
		setBlock(world, i + 4, j + 12, k + 1, ModBlocks.hyrewoodLeaves);
		setBlock(world, i + 4, j + 12, k + 2, ModBlocks.hyrewoodLeaves);
		setBlock(world, i + 4, j + 12, k + 3, ModBlocks.hyrewoodLeaves);
		setBlock(world, i + 4, j + 12, k + 4, ModBlocks.hyrewoodLeaves);
		setBlock(world, i + 4, j + 12, k + 5, ModBlocks.hyrewoodLeaves);
		setBlock(world, i + 4, j + 12, k + 6, ModBlocks.hyrewoodLeaves);
		setBlock(world, i + 4, j + 12, k + 7, ModBlocks.hyrewoodLeaves);
		setBlock(world, i + 4, j + 13, k + 2, ModBlocks.hyrewoodLeaves);
		setBlock(world, i + 4, j + 13, k + 3, ModBlocks.hyrewoodLeaves);
		setBlock(world, i + 4, j + 13, k + 4, ModBlocks.hyrewoodLeaves);
		setBlock(world, i + 4, j + 13, k + 5, ModBlocks.hyrewoodLeaves);
		setBlock(world, i + 4, j + 13, k + 6, ModBlocks.hyrewoodLeaves);
		setBlock(world, i + 5, j + 0, k + 3, ModBlocks.hyrewood);
		setBlock(world, i + 5, j + 0, k + 4, ModBlocks.hyrewood);
		setBlock(world, i + 5, j + 0, k + 5, ModBlocks.hyrewood);
		setBlock(world, i + 5, j + 1, k + 3, ModBlocks.hyrewood);
		setBlock(world, i + 5, j + 1, k + 4, ModBlocks.hyrewood);
		setBlock(world, i + 5, j + 1, k + 5, ModBlocks.hyrewood);
		setBlock(world, i + 5, j + 2, k + 3, ModBlocks.hyrewood);
		setBlock(world, i + 5, j + 2, k + 4, ModBlocks.hyrewood);
		setBlock(world, i + 5, j + 2, k + 5, ModBlocks.hyrewood);
		setBlock(world, i + 5, j + 3, k + 3, ModBlocks.hyrewood);
		setBlock(world, i + 5, j + 3, k + 4, ModBlocks.hyrewood);
		setBlock(world, i + 5, j + 3, k + 5, ModBlocks.hyrewood);
		setBlock(world, i + 5, j + 4, k + 3, ModBlocks.hyrewood);
		setBlock(world, i + 5, j + 4, k + 4, ModBlocks.hyrewood);
		setBlock(world, i + 5, j + 4, k + 5, ModBlocks.hyrewood);
		setBlock(world, i + 5, j + 5, k + 3, ModBlocks.hyrewoodLeaves);
		setBlock(world, i + 5, j + 5, k + 4, ModBlocks.hyrewoodLeaves);
		setBlock(world, i + 5, j + 5, k + 5, ModBlocks.hyrewoodLeaves);
		setBlock(world, i + 5, j + 6, k + 1, ModBlocks.hyrewoodLeaves);
		setBlock(world, i + 5, j + 6, k + 2, ModBlocks.hyrewoodLeaves);
		setBlock(world, i + 5, j + 6, k + 3, ModBlocks.hyrewoodLeaves);
		setBlock(world, i + 5, j + 6, k + 4, ModBlocks.hyrewoodLeaves);
		setBlock(world, i + 5, j + 6, k + 5, ModBlocks.hyrewoodLeaves);
		setBlock(world, i + 5, j + 6, k + 6, ModBlocks.hyrewoodLeaves);
		setBlock(world, i + 5, j + 6, k + 7, ModBlocks.hyrewoodLeaves);
		setBlock(world, i + 5, j + 7, k + 1, ModBlocks.hyrewoodLeaves);
		setBlock(world, i + 5, j + 7, k + 2, ModBlocks.hyrewoodLeaves);
		setBlock(world, i + 5, j + 7, k + 3, ModBlocks.hyrewoodLeaves);
		setBlock(world, i + 5, j + 7, k + 4, ModBlocks.hyrewoodLeaves);
		setBlock(world, i + 5, j + 7, k + 5, ModBlocks.hyrewoodLeaves);
		setBlock(world, i + 5, j + 7, k + 6, ModBlocks.hyrewoodLeaves);
		setBlock(world, i + 5, j + 7, k + 7, ModBlocks.hyrewoodLeaves);
		setBlock(world, i + 5, j + 8, k + 0, ModBlocks.hyrewoodLeaves);
		setBlock(world, i + 5, j + 8, k + 1, ModBlocks.hyrewoodLeaves);
		setBlock(world, i + 5, j + 8, k + 2, ModBlocks.hyrewoodLeaves);
		setBlock(world, i + 5, j + 8, k + 3, ModBlocks.hyrewoodLeaves);
		setBlock(world, i + 5, j + 8, k + 4, ModBlocks.hyrewoodLeaves);
		setBlock(world, i + 5, j + 8, k + 5, ModBlocks.hyrewoodLeaves);
		setBlock(world, i + 5, j + 8, k + 6, ModBlocks.hyrewoodLeaves);
		setBlock(world, i + 5, j + 8, k + 7, ModBlocks.hyrewoodLeaves);
		setBlock(world, i + 5, j + 8, k + 8, ModBlocks.hyrewoodLeaves);
		setBlock(world, i + 5, j + 9, k + 0, ModBlocks.hyrewoodLeaves);
		setBlock(world, i + 5, j + 9, k + 1, ModBlocks.hyrewoodLeaves);
		setBlock(world, i + 5, j + 9, k + 2, ModBlocks.hyrewoodLeaves);
		setBlock(world, i + 5, j + 9, k + 3, ModBlocks.hyrewoodLeaves);
		setBlock(world, i + 5, j + 9, k + 4, ModBlocks.hyrewoodLeaves);
		setBlock(world, i + 5, j + 9, k + 5, ModBlocks.hyrewoodLeaves);
		setBlock(world, i + 5, j + 9, k + 6, ModBlocks.hyrewoodLeaves);
		setBlock(world, i + 5, j + 9, k + 7, ModBlocks.hyrewoodLeaves);
		setBlock(world, i + 5, j + 9, k + 8, ModBlocks.hyrewoodLeaves);
		setBlock(world, i + 5, j + 10, k + 0, ModBlocks.hyrewoodLeaves);
		setBlock(world, i + 5, j + 10, k + 1, ModBlocks.hyrewoodLeaves);
		setBlock(world, i + 5, j + 10, k + 2, ModBlocks.hyrewoodLeaves);
		setBlock(world, i + 5, j + 10, k + 3, ModBlocks.hyrewoodLeaves);
		setBlock(world, i + 5, j + 10, k + 4, ModBlocks.hyrewoodLeaves);
		setBlock(world, i + 5, j + 10, k + 5, ModBlocks.hyrewoodLeaves);
		setBlock(world, i + 5, j + 10, k + 6, ModBlocks.hyrewoodLeaves);
		setBlock(world, i + 5, j + 10, k + 7, ModBlocks.hyrewoodLeaves);
		setBlock(world, i + 5, j + 10, k + 8, ModBlocks.hyrewoodLeaves);
		setBlock(world, i + 5, j + 11, k + 1, ModBlocks.hyrewoodLeaves);
		setBlock(world, i + 5, j + 11, k + 2, ModBlocks.hyrewoodLeaves);
		setBlock(world, i + 5, j + 11, k + 3, ModBlocks.hyrewoodLeaves);
		setBlock(world, i + 5, j + 11, k + 4, ModBlocks.hyrewoodLeaves);
		setBlock(world, i + 5, j + 11, k + 5, ModBlocks.hyrewoodLeaves);
		setBlock(world, i + 5, j + 11, k + 6, ModBlocks.hyrewoodLeaves);
		setBlock(world, i + 5, j + 11, k + 7, ModBlocks.hyrewoodLeaves);
		setBlock(world, i + 5, j + 12, k + 1, ModBlocks.hyrewoodLeaves);
		setBlock(world, i + 5, j + 12, k + 2, ModBlocks.hyrewoodLeaves);
		setBlock(world, i + 5, j + 12, k + 3, ModBlocks.hyrewoodLeaves);
		setBlock(world, i + 5, j + 12, k + 4, ModBlocks.hyrewoodLeaves);
		setBlock(world, i + 5, j + 12, k + 5, ModBlocks.hyrewoodLeaves);
		setBlock(world, i + 5, j + 12, k + 6, ModBlocks.hyrewoodLeaves);
		setBlock(world, i + 5, j + 12, k + 7, ModBlocks.hyrewoodLeaves);
		setBlock(world, i + 5, j + 13, k + 3, ModBlocks.hyrewoodLeaves);
		setBlock(world, i + 5, j + 13, k + 4, ModBlocks.hyrewoodLeaves);
		setBlock(world, i + 5, j + 13, k + 5, ModBlocks.hyrewoodLeaves);
		setBlock(world, i + 6, j + 0, k + 4, ModBlocks.hyrewood);
		setBlock(world, i + 6, j + 1, k + 4, ModBlocks.hyrewood);
		setBlock(world, i + 6, j + 2, k + 4, ModBlocks.hyrewood);
		setBlock(world, i + 6, j + 3, k + 4, ModBlocks.hyrewood);
		setBlock(world, i + 6, j + 4, k + 4, ModBlocks.hyrewood);
		setBlock(world, i + 6, j + 5, k + 4, ModBlocks.hyrewoodLeaves);
		setBlock(world, i + 6, j + 6, k + 2, ModBlocks.hyrewoodLeaves);
		setBlock(world, i + 6, j + 6, k + 3, ModBlocks.hyrewoodLeaves);
		setBlock(world, i + 6, j + 6, k + 4, ModBlocks.hyrewoodLeaves);
		setBlock(world, i + 6, j + 6, k + 5, ModBlocks.hyrewoodLeaves);
		setBlock(world, i + 6, j + 6, k + 6, ModBlocks.hyrewoodLeaves);
		setBlock(world, i + 6, j + 7, k + 1, ModBlocks.hyrewoodLeaves);
		setBlock(world, i + 6, j + 7, k + 2, ModBlocks.hyrewoodLeaves);
		setBlock(world, i + 6, j + 7, k + 3, ModBlocks.hyrewoodLeaves);
		setBlock(world, i + 6, j + 7, k + 4, ModBlocks.hyrewoodLeaves);
		setBlock(world, i + 6, j + 7, k + 5, ModBlocks.hyrewoodLeaves);
		setBlock(world, i + 6, j + 7, k + 6, ModBlocks.hyrewoodLeaves);
		setBlock(world, i + 6, j + 7, k + 7, ModBlocks.hyrewoodLeaves);
		setBlock(world, i + 6, j + 8, k + 1, ModBlocks.hyrewoodLeaves);
		setBlock(world, i + 6, j + 8, k + 2, ModBlocks.hyrewoodLeaves);
		setBlock(world, i + 6, j + 8, k + 3, ModBlocks.hyrewoodLeaves);
		setBlock(world, i + 6, j + 8, k + 4, ModBlocks.hyrewoodLeaves);
		setBlock(world, i + 6, j + 8, k + 5, ModBlocks.hyrewoodLeaves);
		setBlock(world, i + 6, j + 8, k + 6, ModBlocks.hyrewoodLeaves);
		setBlock(world, i + 6, j + 8, k + 7, ModBlocks.hyrewoodLeaves);
		setBlock(world, i + 6, j + 9, k + 0, ModBlocks.hyrewoodLeaves);
		setBlock(world, i + 6, j + 9, k + 1, ModBlocks.hyrewoodLeaves);
		setBlock(world, i + 6, j + 9, k + 2, ModBlocks.hyrewoodLeaves);
		setBlock(world, i + 6, j + 9, k + 3, ModBlocks.hyrewoodLeaves);
		setBlock(world, i + 6, j + 9, k + 4, ModBlocks.hyrewoodLeaves);
		setBlock(world, i + 6, j + 9, k + 5, ModBlocks.hyrewoodLeaves);
		setBlock(world, i + 6, j + 9, k + 6, ModBlocks.hyrewoodLeaves);
		setBlock(world, i + 6, j + 9, k + 7, ModBlocks.hyrewoodLeaves);
		setBlock(world, i + 6, j + 9, k + 8, ModBlocks.hyrewoodLeaves);
		setBlock(world, i + 6, j + 10, k + 1, ModBlocks.hyrewoodLeaves);
		setBlock(world, i + 6, j + 10, k + 2, ModBlocks.hyrewoodLeaves);
		setBlock(world, i + 6, j + 10, k + 3, ModBlocks.hyrewoodLeaves);
		setBlock(world, i + 6, j + 10, k + 4, ModBlocks.hyrewoodLeaves);
		setBlock(world, i + 6, j + 10, k + 5, ModBlocks.hyrewoodLeaves);
		setBlock(world, i + 6, j + 10, k + 6, ModBlocks.hyrewoodLeaves);
		setBlock(world, i + 6, j + 10, k + 7, ModBlocks.hyrewoodLeaves);
		setBlock(world, i + 6, j + 11, k + 1, ModBlocks.hyrewoodLeaves);
		setBlock(world, i + 6, j + 11, k + 2, ModBlocks.hyrewoodLeaves);
		setBlock(world, i + 6, j + 11, k + 3, ModBlocks.hyrewoodLeaves);
		setBlock(world, i + 6, j + 11, k + 4, ModBlocks.hyrewoodLeaves);
		setBlock(world, i + 6, j + 11, k + 5, ModBlocks.hyrewoodLeaves);
		setBlock(world, i + 6, j + 11, k + 6, ModBlocks.hyrewoodLeaves);
		setBlock(world, i + 6, j + 11, k + 7, ModBlocks.hyrewoodLeaves);
		setBlock(world, i + 6, j + 12, k + 2, ModBlocks.hyrewoodLeaves);
		setBlock(world, i + 6, j + 12, k + 3, ModBlocks.hyrewoodLeaves);
		setBlock(world, i + 6, j + 12, k + 4, ModBlocks.hyrewoodLeaves);
		setBlock(world, i + 6, j + 12, k + 5, ModBlocks.hyrewoodLeaves);
		setBlock(world, i + 6, j + 12, k + 6, ModBlocks.hyrewoodLeaves);
		setBlock(world, i + 6, j + 13, k + 4, ModBlocks.hyrewoodLeaves);
		setBlock(world, i + 7, j + 6, k + 3, ModBlocks.hyrewoodLeaves);
		setBlock(world, i + 7, j + 6, k + 4, ModBlocks.hyrewoodLeaves);
		setBlock(world, i + 7, j + 6, k + 5, ModBlocks.hyrewoodLeaves);
		setBlock(world, i + 7, j + 7, k + 2, ModBlocks.hyrewoodLeaves);
		setBlock(world, i + 7, j + 7, k + 3, ModBlocks.hyrewoodLeaves);
		setBlock(world, i + 7, j + 7, k + 4, ModBlocks.hyrewoodLeaves);
		setBlock(world, i + 7, j + 7, k + 5, ModBlocks.hyrewoodLeaves);
		setBlock(world, i + 7, j + 7, k + 6, ModBlocks.hyrewoodLeaves);
		setBlock(world, i + 7, j + 8, k + 1, ModBlocks.hyrewoodLeaves);
		setBlock(world, i + 7, j + 8, k + 2, ModBlocks.hyrewoodLeaves);
		setBlock(world, i + 7, j + 8, k + 3, ModBlocks.hyrewoodLeaves);
		setBlock(world, i + 7, j + 8, k + 4, ModBlocks.hyrewoodLeaves);
		setBlock(world, i + 7, j + 8, k + 5, ModBlocks.hyrewoodLeaves);
		setBlock(world, i + 7, j + 8, k + 6, ModBlocks.hyrewoodLeaves);
		setBlock(world, i + 7, j + 8, k + 7, ModBlocks.hyrewoodLeaves);
		setBlock(world, i + 7, j + 9, k + 1, ModBlocks.hyrewoodLeaves);
		setBlock(world, i + 7, j + 9, k + 2, ModBlocks.hyrewoodLeaves);
		setBlock(world, i + 7, j + 9, k + 3, ModBlocks.hyrewoodLeaves);
		setBlock(world, i + 7, j + 9, k + 4, ModBlocks.hyrewoodLeaves);
		setBlock(world, i + 7, j + 9, k + 5, ModBlocks.hyrewoodLeaves);
		setBlock(world, i + 7, j + 9, k + 6, ModBlocks.hyrewoodLeaves);
		setBlock(world, i + 7, j + 9, k + 7, ModBlocks.hyrewoodLeaves);
		setBlock(world, i + 7, j + 10, k + 1, ModBlocks.hyrewoodLeaves);
		setBlock(world, i + 7, j + 10, k + 2, ModBlocks.hyrewoodLeaves);
		setBlock(world, i + 7, j + 10, k + 3, ModBlocks.hyrewoodLeaves);
		setBlock(world, i + 7, j + 10, k + 4, ModBlocks.hyrewoodLeaves);
		setBlock(world, i + 7, j + 10, k + 5, ModBlocks.hyrewoodLeaves);
		setBlock(world, i + 7, j + 10, k + 6, ModBlocks.hyrewoodLeaves);
		setBlock(world, i + 7, j + 10, k + 7, ModBlocks.hyrewoodLeaves);
		setBlock(world, i + 7, j + 11, k + 2, ModBlocks.hyrewoodLeaves);
		setBlock(world, i + 7, j + 11, k + 3, ModBlocks.hyrewoodLeaves);
		setBlock(world, i + 7, j + 11, k + 4, ModBlocks.hyrewoodLeaves);
		setBlock(world, i + 7, j + 11, k + 5, ModBlocks.hyrewoodLeaves);
		setBlock(world, i + 7, j + 11, k + 6, ModBlocks.hyrewoodLeaves);
		setBlock(world, i + 7, j + 12, k + 3, ModBlocks.hyrewoodLeaves);
		setBlock(world, i + 7, j + 12, k + 4, ModBlocks.hyrewoodLeaves);
		setBlock(world, i + 7, j + 12, k + 5, ModBlocks.hyrewoodLeaves);
		setBlock(world, i + 8, j + 7, k + 4, ModBlocks.hyrewoodLeaves);
		setBlock(world, i + 8, j + 8, k + 3, ModBlocks.hyrewoodLeaves);
		setBlock(world, i + 8, j + 8, k + 4, ModBlocks.hyrewoodLeaves);
		setBlock(world, i + 8, j + 8, k + 5, ModBlocks.hyrewoodLeaves);
		setBlock(world, i + 8, j + 9, k + 2, ModBlocks.hyrewoodLeaves);
		setBlock(world, i + 8, j + 9, k + 3, ModBlocks.hyrewoodLeaves);
		setBlock(world, i + 8, j + 9, k + 4, ModBlocks.hyrewoodLeaves);
		setBlock(world, i + 8, j + 9, k + 5, ModBlocks.hyrewoodLeaves);
		setBlock(world, i + 8, j + 9, k + 6, ModBlocks.hyrewoodLeaves);
		setBlock(world, i + 8, j + 10, k + 3, ModBlocks.hyrewoodLeaves);
		setBlock(world, i + 8, j + 10, k + 4, ModBlocks.hyrewoodLeaves);
		setBlock(world, i + 8, j + 10, k + 5, ModBlocks.hyrewoodLeaves);
		setBlock(world, i + 8, j + 11, k + 4, ModBlocks.hyrewoodLeaves);

		return true;
	}
}