package divinerpg.dimensions.arcana.components;

import java.util.Random;

import divinerpg.dimensions.arcana.ArcanaChunkPrimer;
import divinerpg.registry.BlockRegistry;
import net.minecraft.block.Block;
import net.minecraft.block.BlockLadder;
import net.minecraft.block.state.IBlockState;
import net.minecraft.init.Blocks;
import net.minecraft.util.EnumFacing;

public class DungeonComponent01 extends DungeonComponentBase {
    @Override
    public boolean generate(ArcanaChunkPrimer chunk, Random rand, int i, int j, int k) {
        Block dungeonBricks = BlockRegistry.degradedBrick;
        Block ancientbricks = BlockRegistry.ancientBrick;
        Block soulStone = BlockRegistry.soulStone;
        Block ancientstone = BlockRegistry.ancientStone;
        Block arcaniteTubes = BlockRegistry.arcaniteTubes;

        this.setBlock(chunk, i + 0, j + 0, k + 0, ancientbricks);
        this.setBlock(chunk, i + 0, j + 0, k + 1, ancientbricks);
        this.setBlock(chunk, i + 0, j + 0, k + 2, ancientbricks);
        this.setBlock(chunk, i + 0, j + 0, k + 3, ancientbricks);
        this.setBlock(chunk, i + 0, j + 0, k + 4, ancientbricks);
        this.setBlock(chunk, i + 0, j + 0, k + 5, ancientbricks);
        this.setBlock(chunk, i + 0, j + 0, k + 6, ancientbricks);
        this.setBlock(chunk, i + 0, j + 0, k + 7, ancientbricks);
        this.setBlock(chunk, i + 0, j + 0, k + 8, ancientbricks);
        this.setBlock(chunk, i + 0, j + 0, k + 9, ancientbricks);
        this.setBlock(chunk, i + 0, j + 0, k + 10, ancientbricks);
        this.setBlock(chunk, i + 0, j + 0, k + 11, ancientbricks);
        this.setBlock(chunk, i + 0, j + 0, k + 12, ancientbricks);
        this.setBlock(chunk, i + 0, j + 0, k + 13, ancientbricks);
        this.setBlock(chunk, i + 0, j + 0, k + 14, ancientbricks);
        this.setBlock(chunk, i + 0, j + 0, k + 15, ancientbricks);
        this.setBlock(chunk, i + 0, j + 1, k + 0, ancientbricks);
        this.setBlock(chunk, i + 0, j + 1, k + 1, ancientbricks);
        this.setBlock(chunk, i + 0, j + 1, k + 2, ancientbricks);
        this.setBlock(chunk, i + 0, j + 1, k + 3, ancientbricks);
        this.setBlock(chunk, i + 0, j + 1, k + 4, ancientbricks);
        this.setBlock(chunk, i + 0, j + 1, k + 5, ancientbricks);
        this.setBlock(chunk, i + 0, j + 1, k + 6, ancientbricks);
        this.setBlock(chunk, i + 0, j + 1, k + 9, ancientbricks);
        this.setBlock(chunk, i + 0, j + 1, k + 10, ancientbricks);
        this.setBlock(chunk, i + 0, j + 1, k + 11, ancientbricks);
        this.setBlock(chunk, i + 0, j + 1, k + 12, ancientbricks);
        this.setBlock(chunk, i + 0, j + 1, k + 13, ancientbricks);
        this.setBlock(chunk, i + 0, j + 1, k + 14, ancientbricks);
        this.setBlock(chunk, i + 0, j + 1, k + 15, ancientbricks);
        this.setBlock(chunk, i + 0, j + 2, k + 0, ancientbricks);
        this.setBlock(chunk, i + 0, j + 2, k + 1, ancientbricks);
        this.setBlock(chunk, i + 0, j + 2, k + 2, ancientbricks);
        this.setBlock(chunk, i + 0, j + 2, k + 3, ancientbricks);
        this.setBlock(chunk, i + 0, j + 2, k + 4, ancientbricks);
        this.setBlock(chunk, i + 0, j + 2, k + 5, ancientbricks);
        this.setBlock(chunk, i + 0, j + 2, k + 6, ancientbricks);
        this.setBlock(chunk, i + 0, j + 2, k + 9, ancientbricks);
        this.setBlock(chunk, i + 0, j + 2, k + 10, ancientbricks);
        this.setBlock(chunk, i + 0, j + 2, k + 11, ancientbricks);
        this.setBlock(chunk, i + 0, j + 2, k + 12, ancientbricks);
        this.setBlock(chunk, i + 0, j + 2, k + 13, ancientbricks);
        this.setBlock(chunk, i + 0, j + 2, k + 14, ancientbricks);
        this.setBlock(chunk, i + 0, j + 2, k + 15, ancientbricks);
        this.setBlock(chunk, i + 0, j + 3, k + 0, ancientbricks);
        this.setBlock(chunk, i + 0, j + 3, k + 1, ancientbricks);
        this.setBlock(chunk, i + 0, j + 3, k + 2, ancientbricks);
        this.setBlock(chunk, i + 0, j + 3, k + 3, ancientbricks);
        this.setBlock(chunk, i + 0, j + 3, k + 4, ancientbricks);
        this.setBlock(chunk, i + 0, j + 3, k + 5, ancientbricks);
        this.setBlock(chunk, i + 0, j + 3, k + 6, ancientbricks);
        this.setBlock(chunk, i + 0, j + 3, k + 7, ancientbricks);
        this.setBlock(chunk, i + 0, j + 3, k + 8, ancientbricks);
        this.setBlock(chunk, i + 0, j + 3, k + 9, ancientbricks);
        this.setBlock(chunk, i + 0, j + 3, k + 10, ancientbricks);
        this.setBlock(chunk, i + 0, j + 3, k + 11, ancientbricks);
        this.setBlock(chunk, i + 0, j + 3, k + 12, ancientbricks);
        this.setBlock(chunk, i + 0, j + 3, k + 13, ancientbricks);
        this.setBlock(chunk, i + 0, j + 3, k + 14, ancientbricks);
        this.setBlock(chunk, i + 0, j + 3, k + 15, ancientbricks);
        this.setBlock(chunk, i + 0, j + 4, k + 0, ancientbricks);
        this.setBlock(chunk, i + 0, j + 4, k + 1, ancientbricks);
        this.setBlock(chunk, i + 0, j + 4, k + 2, ancientbricks);
        this.setBlock(chunk, i + 0, j + 4, k + 3, ancientbricks);
        this.setBlock(chunk, i + 0, j + 4, k + 4, ancientbricks);
        this.setBlock(chunk, i + 0, j + 4, k + 5, ancientbricks);
        this.setBlock(chunk, i + 0, j + 4, k + 6, ancientbricks);
        this.setBlock(chunk, i + 0, j + 4, k + 7, ancientbricks);
        this.setBlock(chunk, i + 0, j + 4, k + 8, ancientbricks);
        this.setBlock(chunk, i + 0, j + 4, k + 9, ancientbricks);
        this.setBlock(chunk, i + 0, j + 4, k + 10, ancientbricks);
        this.setBlock(chunk, i + 0, j + 4, k + 11, ancientbricks);
        this.setBlock(chunk, i + 0, j + 4, k + 12, ancientbricks);
        this.setBlock(chunk, i + 0, j + 4, k + 13, ancientbricks);
        this.setBlock(chunk, i + 0, j + 4, k + 14, ancientbricks);
        this.setBlock(chunk, i + 0, j + 4, k + 15, ancientbricks);
        this.setBlock(chunk, i + 0, j + 5, k + 0, soulStone);
        this.setBlock(chunk, i + 0, j + 5, k + 1, soulStone);
        this.setBlock(chunk, i + 0, j + 5, k + 2, soulStone);
        this.setBlock(chunk, i + 0, j + 5, k + 3, soulStone);
        this.setBlock(chunk, i + 0, j + 5, k + 4, soulStone);
        this.setBlock(chunk, i + 0, j + 5, k + 5, soulStone);
        this.setBlock(chunk, i + 0, j + 5, k + 6, soulStone);
        this.setBlock(chunk, i + 0, j + 5, k + 7, soulStone);
        this.setBlock(chunk, i + 0, j + 5, k + 8, soulStone);
        this.setBlock(chunk, i + 0, j + 5, k + 9, soulStone);
        this.setBlock(chunk, i + 0, j + 5, k + 10, soulStone);
        this.setBlock(chunk, i + 0, j + 5, k + 11, soulStone);
        this.setBlock(chunk, i + 0, j + 5, k + 12, soulStone);
        this.setBlock(chunk, i + 0, j + 5, k + 13, soulStone);
        this.setBlock(chunk, i + 0, j + 5, k + 14, soulStone);
        this.setBlock(chunk, i + 0, j + 5, k + 15, soulStone);
        this.setBlock(chunk, i + 0, j + 6, k + 0, ancientstone);
        this.setBlock(chunk, i + 0, j + 6, k + 1, ancientstone);
        this.setBlock(chunk, i + 0, j + 6, k + 2, ancientstone);
        this.setBlock(chunk, i + 0, j + 6, k + 3, ancientstone);
        this.setBlock(chunk, i + 0, j + 6, k + 4, ancientstone);
        this.setBlock(chunk, i + 0, j + 6, k + 5, ancientstone);
        this.setBlock(chunk, i + 0, j + 6, k + 6, ancientstone);
        this.setBlock(chunk, i + 0, j + 6, k + 7, ancientstone);
        this.setBlock(chunk, i + 0, j + 6, k + 8, ancientstone);
        this.setBlock(chunk, i + 0, j + 6, k + 9, ancientstone);
        this.setBlock(chunk, i + 0, j + 6, k + 10, ancientstone);
        this.setBlock(chunk, i + 0, j + 6, k + 11, ancientstone);
        this.setBlock(chunk, i + 0, j + 6, k + 12, ancientstone);
        this.setBlock(chunk, i + 0, j + 6, k + 13, ancientstone);
        this.setBlock(chunk, i + 0, j + 6, k + 14, ancientstone);
        this.setBlock(chunk, i + 0, j + 6, k + 15, ancientstone);
        this.setBlock(chunk, i + 0, j + 7, k + 0, dungeonBricks);
        this.setBlock(chunk, i + 0, j + 7, k + 1, dungeonBricks);
        this.setBlock(chunk, i + 0, j + 7, k + 2, dungeonBricks);
        this.setBlock(chunk, i + 0, j + 7, k + 3, dungeonBricks);
        this.setBlock(chunk, i + 0, j + 7, k + 4, dungeonBricks);
        this.setBlock(chunk, i + 0, j + 7, k + 5, dungeonBricks);
        this.setBlock(chunk, i + 0, j + 7, k + 6, dungeonBricks);
        this.setBlock(chunk, i + 0, j + 7, k + 7, dungeonBricks);
        this.setBlock(chunk, i + 0, j + 7, k + 8, dungeonBricks);
        this.setBlock(chunk, i + 0, j + 7, k + 9, dungeonBricks);
        this.setBlock(chunk, i + 0, j + 7, k + 10, dungeonBricks);
        this.setBlock(chunk, i + 0, j + 7, k + 11, dungeonBricks);
        this.setBlock(chunk, i + 0, j + 7, k + 12, dungeonBricks);
        this.setBlock(chunk, i + 0, j + 7, k + 13, dungeonBricks);
        this.setBlock(chunk, i + 0, j + 7, k + 14, dungeonBricks);
        this.setBlock(chunk, i + 0, j + 7, k + 15, dungeonBricks);
        this.setBlock(chunk, i + 1, j + 0, k + 0, dungeonBricks);
        this.setBlock(chunk, i + 1, j + 0, k + 1, dungeonBricks);
        this.setBlock(chunk, i + 1, j + 0, k + 2, dungeonBricks);
        this.setBlock(chunk, i + 1, j + 0, k + 3, Blocks.AIR);
        this.setBlock(chunk, i + 1, j + 0, k + 4, dungeonBricks);
        this.setBlock(chunk, i + 1, j + 0, k + 5, dungeonBricks);
        this.setBlock(chunk, i + 1, j + 0, k + 6, BlockRegistry.arcaniumMetal);
        this.setBlock(chunk, i + 1, j + 0, k + 7, BlockRegistry.arcaniumMetal);
        this.setBlock(chunk, i + 1, j + 0, k + 8, dungeonBricks);
        this.setBlock(chunk, i + 1, j + 0, k + 9, dungeonBricks);
        this.setBlock(chunk, i + 1, j + 0, k + 10, BlockRegistry.arcaniumPower);
        this.setBlock(chunk, i + 1, j + 0, k + 11, BlockRegistry.arcaniumMetal);
        this.setBlock(chunk, i + 1, j + 0, k + 12, BlockRegistry.arcaniumMetal);
        this.setBlock(chunk, i + 1, j + 0, k + 13, BlockRegistry.arcaniumMetal);
        this.setBlock(chunk, i + 1, j + 0, k + 14, BlockRegistry.arcaniumMetal);
        this.setBlock(chunk, i + 1, j + 0, k + 15, ancientbricks);
        this.setBlock(chunk, i + 1, j + 1, k + 0, soulStone);
        this.setBlock(chunk, i + 1, j + 1, k + 3, dungeonBricks);
        this.setBlock(chunk, i + 1, j + 1, k + 4, dungeonBricks);
        this.setBlock(chunk, i + 1, j + 1, k + 5, ancientbricks);
        this.setBlock(chunk, i + 1, j + 1, k + 8, ancientbricks);
        this.setBlock(chunk, i + 1, j + 1, k + 9, dungeonBricks);
        //arcanaChunk.setBlockAndMetadata(i + 1, j + 1, k + 14, arcaniteTubes, 1);
        this.setBlock(chunk, i + 1, j + 1, k + 15, BlockRegistry.arcaniumMetal);
        this.setBlock(chunk, i + 1, j + 2, k + 0, soulStone);
        this.setBlock(chunk, i + 1, j + 2, k + 4, ancientbricks);
        this.setBlock(chunk, i + 1, j + 2, k + 5, dungeonBricks);
        this.setBlock(chunk, i + 1, j + 2, k + 8, ancientbricks);
        //arcanaChunk.setBlockAndMetadata(i + 1, j + 2, k + 14, arcaniteTubes, 1);
        this.setBlock(chunk, i + 1, j + 2, k + 15, BlockRegistry.arcaniumMetal);
        this.setBlock(chunk, i + 1, j + 3, k + 0, soulStone);
        this.setBlock(chunk, i + 1, j + 3, k + 5, dungeonBricks);
        this.setBlock(chunk, i + 1, j + 3, k + 6, ancientbricks);
        this.setBlock(chunk, i + 1, j + 3, k + 7, dungeonBricks);
        this.setBlock(chunk, i + 1, j + 3, k + 14, ancientbricks);
        this.setBlock(chunk, i + 1, j + 3, k + 15, ancientbricks);
        this.setBlock(chunk, i + 1, j + 4, k + 0, ancientbricks);
        this.setBlock(chunk, i + 1, j + 4, k + 15, ancientbricks);
        this.setBlock(chunk, i + 1, j + 5, k + 0, soulStone);
        this.setBlock(chunk, i + 1, j + 5, k + 15, soulStone);
        this.setBlock(chunk, i + 1, j + 6, k + 0, ancientstone);
        this.setBlock(chunk, i + 1, j + 6, k + 15, ancientstone);
        this.setBlock(chunk, i + 1, j + 7, k + 0, dungeonBricks);
        this.setBlock(chunk, i + 1, j + 7, k + 15, dungeonBricks);
        this.setBlock(chunk, i + 2, j + 0, k + 0, dungeonBricks);
        this.setBlock(chunk, i + 2, j + 0, k + 1, BlockRegistry.dungeonLamp);
        this.setBlock(chunk, i + 2, j + 0, k + 2, dungeonBricks);
        this.setBlock(chunk, i + 2, j + 0, k + 3, Blocks.AIR);
        this.setBlock(chunk, i + 2, j + 0, k + 4, dungeonBricks);
        this.setBlock(chunk, i + 2, j + 0, k + 5, dungeonBricks);
        this.setBlock(chunk, i + 2, j + 0, k + 6, BlockRegistry.arcaniumMetal);
        this.setBlock(chunk, i + 2, j + 0, k + 7, BlockRegistry.arcaniumMetal);
        this.setBlock(chunk, i + 2, j + 0, k + 8, dungeonBricks);
        this.setBlock(chunk, i + 2, j + 0, k + 9, dungeonBricks);
        this.setBlock(chunk, i + 2, j + 0, k + 10, dungeonBricks);
        this.setBlock(chunk, i + 2, j + 0, k + 11, dungeonBricks);
        this.setBlock(chunk, i + 2, j + 0, k + 12, dungeonBricks);
        this.setBlock(chunk, i + 2, j + 0, k + 13, dungeonBricks);
        this.setBlock(chunk, i + 2, j + 0, k + 14, dungeonBricks);
        this.setBlock(chunk, i + 2, j + 0, k + 15, ancientbricks);
        this.setBlock(chunk, i + 2, j + 1, k + 0, ancientstone);
        this.setBlock(chunk, i + 2, j + 1, k + 3, dungeonBricks);
        this.setBlock(chunk, i + 2, j + 1, k + 4, dungeonBricks);
        this.setBlock(chunk, i + 2, j + 1, k + 5, ancientbricks);
        this.setBlock(chunk, i + 2, j + 1, k + 8, ancientbricks);
        this.setBlock(chunk, i + 2, j + 1, k + 9, dungeonBricks);
        //this.setBlock(chunk, i + 2, j + 1, k + 14, arcaniteTubes);
        this.setBlock(chunk, i + 2, j + 1, k + 15, BlockRegistry.arcaniumMetal);
        this.setBlock(chunk, i + 2, j + 2, k + 0, ancientstone);
        this.setBlock(chunk, i + 2, j + 2, k + 4, ancientbricks);
        //this.setBlock(chunk, i + 2, j + 2, k + 5, arcaniteTubes);
        this.setBlock(chunk, i + 2, j + 2, k + 8, ancientbricks);
        //this.setBlock(chunk, i + 2, j + 2, k + 14, arcaniteTubes);
        this.setBlock(chunk, i + 2, j + 2, k + 15, BlockRegistry.arcaniumMetal);
        this.setBlock(chunk, i + 2, j + 3, k + 0, ancientstone);
        this.setBlock(chunk, i + 2, j + 3, k + 5, dungeonBricks);
        this.setBlock(chunk, i + 2, j + 3, k + 6, soulStone);
        this.setBlock(chunk, i + 2, j + 3, k + 7, dungeonBricks);
        this.setBlock(chunk, i + 2, j + 3, k + 14, BlockRegistry.dungeonLamp);
        this.setBlock(chunk, i + 2, j + 3, k + 15, ancientbricks);
        this.setBlock(chunk, i + 2, j + 4, k + 0, ancientbricks);
        this.setBlock(chunk, i + 2, j + 4, k + 15, ancientbricks);
        this.setBlock(chunk, i + 2, j + 5, k + 0, soulStone);
        this.setBlock(chunk, i + 2, j + 5, k + 15, soulStone);
        this.setBlock(chunk, i + 2, j + 6, k + 0, ancientstone);
        this.setBlock(chunk, i + 2, j + 6, k + 15, ancientstone);
        this.setBlock(chunk, i + 2, j + 7, k + 0, dungeonBricks);
        this.setBlock(chunk, i + 2, j + 7, k + 15, dungeonBricks);
        this.setBlock(chunk, i + 3, j + 0, k + 0, dungeonBricks);
        this.setBlock(chunk, i + 3, j + 0, k + 1, dungeonBricks);
        this.setBlock(chunk, i + 3, j + 0, k + 2, dungeonBricks);
        this.setBlock(chunk, i + 3, j + 0, k + 3, dungeonBricks);
        this.setBlock(chunk, i + 3, j + 0, k + 4, dungeonBricks);
        this.setBlock(chunk, i + 3, j + 0, k + 5, dungeonBricks);
        this.setBlock(chunk, i + 3, j + 0, k + 6, BlockRegistry.arcaniumMetal);
        this.setBlock(chunk, i + 3, j + 0, k + 7, BlockRegistry.arcaniumMetal);
        this.setBlock(chunk, i + 3, j + 0, k + 8, dungeonBricks);
        this.setBlock(chunk, i + 3, j + 0, k + 9, dungeonBricks);
        this.setBlock(chunk, i + 3, j + 0, k + 10, BlockRegistry.arcaniumPower);
        this.setBlock(chunk, i + 3, j + 0, k + 11, BlockRegistry.arcaniumMetal);
        this.setBlock(chunk, i + 3, j + 0, k + 12, BlockRegistry.arcaniumMetal);
        this.setBlock(chunk, i + 3, j + 0, k + 13, BlockRegistry.arcaniumMetal);
        this.setBlock(chunk, i + 3, j + 0, k + 14, BlockRegistry.arcaniumMetal);
        this.setBlock(chunk, i + 3, j + 0, k + 15, ancientbricks);
        this.setBlock(chunk, i + 3, j + 1, k + 0, ancientbricks);
        this.setBlock(chunk, i + 3, j + 1, k + 3, dungeonBricks);
        this.setBlock(chunk, i + 3, j + 1, k + 4, dungeonBricks);
        this.setBlock(chunk, i + 3, j + 1, k + 5, ancientbricks);
        this.setBlock(chunk, i + 3, j + 1, k + 8, ancientbricks);
        this.setBlock(chunk, i + 3, j + 1, k + 9, dungeonBricks);
        //this.setBlock(chunk, i + 3, j + 1, k + 14, arcaniteTubes);
        this.setBlock(chunk, i + 3, j + 1, k + 15, BlockRegistry.arcaniumMetal);
        this.setBlock(chunk, i + 3, j + 2, k + 0, ancientbricks);
        this.setBlock(chunk, i + 3, j + 2, k + 4, ancientbricks);
        this.setBlock(chunk, i + 3, j + 2, k + 5, dungeonBricks);
        this.setBlock(chunk, i + 3, j + 2, k + 8, ancientbricks);
        //this.setBlock(chunk, i + 3, j + 2, k + 14, arcaniteTubes);
        this.setBlock(chunk, i + 3, j + 2, k + 15, BlockRegistry.arcaniumMetal);
        this.setBlock(chunk, i + 3, j + 3, k + 0, dungeonBricks);
        this.setBlock(chunk, i + 3, j + 3, k + 5, dungeonBricks);
        this.setBlock(chunk, i + 3, j + 3, k + 6, ancientbricks);
        this.setBlock(chunk, i + 3, j + 3, k + 7, dungeonBricks);
        this.setBlock(chunk, i + 3, j + 3, k + 14, ancientbricks);
        this.setBlock(chunk, i + 3, j + 3, k + 15, ancientbricks);
        this.setBlock(chunk, i + 3, j + 4, k + 0, ancientbricks);
        this.setBlock(chunk, i + 3, j + 4, k + 15, ancientbricks);
        this.setBlock(chunk, i + 3, j + 5, k + 0, soulStone);
        this.setBlock(chunk, i + 3, j + 5, k + 15, soulStone);
        this.setBlock(chunk, i + 3, j + 6, k + 0, ancientstone);
        this.setBlock(chunk, i + 3, j + 6, k + 15, ancientstone);
        this.setBlock(chunk, i + 3, j + 7, k + 0, dungeonBricks);
        this.setBlock(chunk, i + 3, j + 7, k + 15, dungeonBricks);
        this.setBlock(chunk, i + 4, j + 0, k + 0, dungeonBricks);
        this.setBlock(chunk, i + 4, j + 0, k + 1, BlockRegistry.dungeonLamp);
        this.setBlock(chunk, i + 4, j + 0, k + 2, dungeonBricks);
        this.setBlock(chunk, i + 4, j + 0, k + 3, dungeonBricks);
        this.setBlock(chunk, i + 4, j + 0, k + 4, dungeonBricks);
        this.setBlock(chunk, i + 4, j + 0, k + 5, dungeonBricks);
        this.setBlock(chunk, i + 4, j + 0, k + 6, BlockRegistry.arcaniumMetal);
        this.setBlock(chunk, i + 4, j + 0, k + 7, BlockRegistry.arcaniumMetal);
        this.setBlock(chunk, i + 4, j + 0, k + 8, dungeonBricks);
        this.setBlock(chunk, i + 4, j + 0, k + 9, dungeonBricks);
        this.setBlock(chunk, i + 4, j + 0, k + 10, dungeonBricks);
        this.setBlock(chunk, i + 4, j + 0, k + 11, dungeonBricks);
        this.setBlock(chunk, i + 4, j + 0, k + 12, dungeonBricks);
        this.setBlock(chunk, i + 4, j + 0, k + 13, dungeonBricks);
        this.setBlock(chunk, i + 4, j + 0, k + 14, dungeonBricks);
        this.setBlock(chunk, i + 4, j + 0, k + 15, ancientbricks);
        this.setBlock(chunk, i + 4, j + 1, k + 0, dungeonBricks);
        this.setBlock(chunk, i + 4, j + 1, k + 3, dungeonBricks);
        this.setBlock(chunk, i + 4, j + 1, k + 4, dungeonBricks);
        this.setBlock(chunk, i + 4, j + 1, k + 5, ancientbricks);
        this.setBlock(chunk, i + 4, j + 1, k + 8, ancientbricks);
        this.setBlock(chunk, i + 4, j + 1, k + 9, dungeonBricks);
        this.setBlock(chunk, i + 4, j + 1, k + 15, ancientbricks);
        this.setBlock(chunk, i + 4, j + 2, k + 0, dungeonBricks);
        this.setBlock(chunk, i + 4, j + 2, k + 4, ancientbricks);
        //this.setBlock(chunk, i + 4, j + 2, k + 5, arcaniteTubes);
        this.setBlock(chunk, i + 4, j + 2, k + 8, ancientbricks);
        this.setBlock(chunk, i + 4, j + 2, k + 15, ancientbricks);
        this.setBlock(chunk, i + 4, j + 3, k + 0, dungeonBricks);
        this.setBlock(chunk, i + 4, j + 3, k + 5, dungeonBricks);
        this.setBlock(chunk, i + 4, j + 3, k + 6, soulStone);
        this.setBlock(chunk, i + 4, j + 3, k + 7, dungeonBricks);
        this.setBlock(chunk, i + 4, j + 3, k + 15, ancientbricks);
        this.setBlock(chunk, i + 4, j + 4, k + 0, ancientbricks);
        this.setBlock(chunk, i + 4, j + 4, k + 15, ancientbricks);
        this.setBlock(chunk, i + 4, j + 5, k + 0, soulStone);
        this.setBlock(chunk, i + 4, j + 5, k + 15, soulStone);
        this.setBlock(chunk, i + 4, j + 6, k + 0, ancientstone);
        this.setBlock(chunk, i + 4, j + 6, k + 15, ancientstone);
        this.setBlock(chunk, i + 4, j + 7, k + 0, dungeonBricks);
        this.setBlock(chunk, i + 4, j + 7, k + 15, dungeonBricks);
        this.setBlock(chunk, i + 5, j + 0, k + 0, dungeonBricks);
        this.setBlock(chunk, i + 5, j + 0, k + 1, dungeonBricks);
        this.setBlock(chunk, i + 5, j + 0, k + 2, dungeonBricks);
        this.setBlock(chunk, i + 5, j + 0, k + 3, dungeonBricks);
        this.setBlock(chunk, i + 5, j + 0, k + 4, dungeonBricks);
        this.setBlock(chunk, i + 5, j + 0, k + 5, dungeonBricks);
        this.setBlock(chunk, i + 5, j + 0, k + 6, BlockRegistry.arcaniumMetal);
        this.setBlock(chunk, i + 5, j + 0, k + 7, BlockRegistry.arcaniumMetal);
        this.setBlock(chunk, i + 5, j + 0, k + 8, dungeonBricks);
        this.setBlock(chunk, i + 5, j + 0, k + 9, dungeonBricks);
        this.setBlock(chunk, i + 5, j + 0, k + 10, BlockRegistry.arcaniumPower);
        this.setBlock(chunk, i + 5, j + 0, k + 11, BlockRegistry.arcaniumMetal);
        this.setBlock(chunk, i + 5, j + 0, k + 12, BlockRegistry.arcaniumMetal);
        this.setBlock(chunk, i + 5, j + 0, k + 13, BlockRegistry.arcaniumMetal);
        this.setBlock(chunk, i + 5, j + 0, k + 14, BlockRegistry.arcaniumMetal);
        this.setBlock(chunk, i + 5, j + 0, k + 15, ancientbricks);
        this.setBlock(chunk, i + 5, j + 1, k + 0, ancientbricks);
        this.setBlock(chunk, i + 5, j + 1, k + 3, dungeonBricks);
        this.setBlock(chunk, i + 5, j + 1, k + 4, dungeonBricks);
        this.setBlock(chunk, i + 5, j + 1, k + 5, ancientbricks);
        this.setBlock(chunk, i + 5, j + 1, k + 8, ancientbricks);
        this.setBlock(chunk, i + 5, j + 1, k + 9, dungeonBricks);
        this.setBlock(chunk, i + 5, j + 1, k + 15, ancientbricks);
        this.setBlock(chunk, i + 5, j + 2, k + 0, ancientbricks);
        this.setBlock(chunk, i + 5, j + 2, k + 4, ancientbricks);
        this.setBlock(chunk, i + 5, j + 2, k + 5, dungeonBricks);
        this.setBlock(chunk, i + 5, j + 2, k + 8, ancientbricks);
        this.setBlock(chunk, i + 5, j + 2, k + 15, ancientbricks);
        this.setBlock(chunk, i + 5, j + 3, k + 0, ancientbricks);
        this.setBlock(chunk, i + 5, j + 3, k + 5, dungeonBricks);
        this.setBlock(chunk, i + 5, j + 3, k + 6, ancientbricks);
        this.setBlock(chunk, i + 5, j + 3, k + 7, dungeonBricks);
        this.setBlock(chunk, i + 5, j + 3, k + 15, ancientbricks);
        this.setBlock(chunk, i + 5, j + 4, k + 0, ancientbricks);
        this.setBlock(chunk, i + 5, j + 4, k + 15, ancientbricks);
        this.setBlock(chunk, i + 5, j + 5, k + 0, soulStone);
        this.setBlock(chunk, i + 5, j + 5, k + 15, soulStone);
        this.setBlock(chunk, i + 5, j + 6, k + 0, ancientstone);
        this.setBlock(chunk, i + 5, j + 6, k + 15, ancientstone);
        this.setBlock(chunk, i + 5, j + 7, k + 0, dungeonBricks);
        this.setBlock(chunk, i + 5, j + 7, k + 15, dungeonBricks);
        this.setBlock(chunk, i + 6, j + 0, k + 0, dungeonBricks);
        this.setBlock(chunk, i + 6, j + 0, k + 1, BlockRegistry.dungeonLamp);
        this.setBlock(chunk, i + 6, j + 0, k + 2, dungeonBricks);
        this.setBlock(chunk, i + 6, j + 0, k + 3, dungeonBricks);
        this.setBlock(chunk, i + 6, j + 0, k + 4, dungeonBricks);
        this.setBlock(chunk, i + 6, j + 0, k + 5, dungeonBricks);
        this.setBlock(chunk, i + 6, j + 0, k + 6, BlockRegistry.arcaniumMetal);
        this.setBlock(chunk, i + 6, j + 0, k + 7, BlockRegistry.arcaniumMetal);
        this.setBlock(chunk, i + 6, j + 0, k + 8, dungeonBricks);
        this.setBlock(chunk, i + 6, j + 0, k + 9, dungeonBricks);
        this.setBlock(chunk, i + 6, j + 0, k + 10, dungeonBricks);
        this.setBlock(chunk, i + 6, j + 0, k + 11, dungeonBricks);
        this.setBlock(chunk, i + 6, j + 0, k + 12, dungeonBricks);
        this.setBlock(chunk, i + 6, j + 0, k + 13, dungeonBricks);
        this.setBlock(chunk, i + 6, j + 0, k + 14, dungeonBricks);
        this.setBlock(chunk, i + 6, j + 0, k + 15, ancientbricks);
        this.setBlock(chunk, i + 6, j + 1, k + 0, BlockRegistry.arcaniumMetal);
        this.setBlock(chunk, i + 6, j + 1, k + 3, dungeonBricks);
        this.setBlock(chunk, i + 6, j + 1, k + 4, dungeonBricks);
        this.setBlock(chunk, i + 6, j + 1, k + 5, ancientbricks);
        this.setBlock(chunk, i + 6, j + 1, k + 8, ancientbricks);
        this.setBlock(chunk, i + 6, j + 1, k + 9, dungeonBricks);
        this.setBlock(chunk, i + 6, j + 1, k + 15, BlockRegistry.arcaniumMetal);
        this.setBlock(chunk, i + 6, j + 2, k + 0, BlockRegistry.arcaniumMetal);
        this.setBlock(chunk, i + 6, j + 2, k + 4, ancientbricks);
        //this.setBlock(chunk, i + 6, j + 2, k + 5, arcaniteTubes);
        this.setBlock(chunk, i + 6, j + 2, k + 8, ancientbricks);
        this.setBlock(chunk, i + 6, j + 2, k + 15, BlockRegistry.arcaniumMetal);
        this.setBlock(chunk, i + 6, j + 3, k + 0, BlockRegistry.arcaniumMetal);
        this.setBlock(chunk, i + 6, j + 3, k + 5, dungeonBricks);
        this.setBlock(chunk, i + 6, j + 3, k + 6, soulStone);
        this.setBlock(chunk, i + 6, j + 3, k + 7, dungeonBricks);
        this.setBlock(chunk, i + 6, j + 3, k + 15, BlockRegistry.arcaniumMetal);
        this.setBlock(chunk, i + 6, j + 4, k + 0, ancientbricks);
        this.setBlock(chunk, i + 6, j + 4, k + 15, ancientbricks);
        this.setBlock(chunk, i + 6, j + 5, k + 0, soulStone);
        this.setBlock(chunk, i + 6, j + 5, k + 15, soulStone);
        this.setBlock(chunk, i + 6, j + 6, k + 0, ancientstone);
        this.setBlock(chunk, i + 6, j + 6, k + 15, ancientstone);
        this.setBlock(chunk, i + 6, j + 7, k + 0, dungeonBricks);
        this.setBlock(chunk, i + 6, j + 7, k + 15, dungeonBricks);
        this.setBlock(chunk, i + 7, j + 0, k + 0, dungeonBricks);
        this.setBlock(chunk, i + 7, j + 0, k + 1, dungeonBricks);
        this.setBlock(chunk, i + 7, j + 0, k + 2, dungeonBricks);
        this.setBlock(chunk, i + 7, j + 0, k + 3, dungeonBricks);
        this.setBlock(chunk, i + 7, j + 0, k + 4, dungeonBricks);
        this.setBlock(chunk, i + 7, j + 0, k + 5, dungeonBricks);
        this.setBlock(chunk, i + 7, j + 0, k + 6, BlockRegistry.arcaniumMetal);
        this.setBlock(chunk, i + 7, j + 0, k + 7, BlockRegistry.arcaniumMetal);
        this.setBlock(chunk, i + 7, j + 0, k + 8, dungeonBricks);
        this.setBlock(chunk, i + 7, j + 0, k + 9, dungeonBricks);
        this.setBlock(chunk, i + 7, j + 0, k + 10, dungeonBricks);
        this.setBlock(chunk, i + 7, j + 0, k + 11, ancientbricks);
        this.setBlock(chunk, i + 7, j + 0, k + 12, dungeonBricks);
        this.setBlock(chunk, i + 7, j + 0, k + 13, ancientbricks);
        this.setBlock(chunk, i + 7, j + 0, k + 14, dungeonBricks);
        this.setBlock(chunk, i + 7, j + 0, k + 15, ancientbricks);
        this.setBlock(chunk, i + 7, j + 1, k + 3, dungeonBricks);
        this.setBlock(chunk, i + 7, j + 1, k + 4, dungeonBricks);
        this.setBlock(chunk, i + 7, j + 1, k + 5, ancientbricks);
        this.setBlock(chunk, i + 7, j + 1, k + 8, ancientbricks);
        this.setBlock(chunk, i + 7, j + 1, k + 9, dungeonBricks);
        this.setBlock(chunk, i + 7, j + 2, k + 4, ancientbricks);
        this.setBlock(chunk, i + 7, j + 2, k + 5, dungeonBricks);
        this.setBlock(chunk, i + 7, j + 2, k + 8, ancientbricks);
        this.setBlock(chunk, i + 7, j + 3, k + 0, BlockRegistry.arcaniumPower);
        this.setBlock(chunk, i + 7, j + 3, k + 5, dungeonBricks);
        this.setBlock(chunk, i + 7, j + 3, k + 6, BlockRegistry.dungeonLamp);
        this.setBlock(chunk, i + 7, j + 3, k + 7, dungeonBricks);
        this.setBlock(chunk, i + 7, j + 3, k + 15, BlockRegistry.arcaniumPower);
        this.setBlock(chunk, i + 7, j + 4, k + 0, ancientbricks);
        this.setBlock(chunk, i + 7, j + 4, k + 15, ancientbricks);
        this.setBlock(chunk, i + 7, j + 5, k + 0, soulStone);
        this.setBlock(chunk, i + 7, j + 5, k + 15, soulStone);
        this.setBlock(chunk, i + 7, j + 6, k + 0, ancientstone);
        this.setBlock(chunk, i + 7, j + 6, k + 15, ancientstone);
        this.setBlock(chunk, i + 7, j + 7, k + 0, dungeonBricks);
        this.setBlock(chunk, i + 7, j + 7, k + 15, dungeonBricks);
        this.setBlock(chunk, i + 8, j + 0, k + 0, dungeonBricks);
        this.setBlock(chunk, i + 8, j + 0, k + 1, dungeonBricks);
        this.setBlock(chunk, i + 8, j + 0, k + 2, dungeonBricks);
        this.setBlock(chunk, i + 8, j + 0, k + 3, dungeonBricks);
        this.setBlock(chunk, i + 8, j + 0, k + 4, dungeonBricks);
        this.setBlock(chunk, i + 8, j + 0, k + 5, dungeonBricks);
        this.setBlock(chunk, i + 8, j + 0, k + 6, BlockRegistry.arcaniumMetal);
        this.setBlock(chunk, i + 8, j + 0, k + 7, BlockRegistry.arcaniumMetal);
        this.setBlock(chunk, i + 8, j + 0, k + 8, dungeonBricks);
        this.setBlock(chunk, i + 8, j + 0, k + 9, dungeonBricks);
        this.setBlock(chunk, i + 8, j + 0, k + 10, dungeonBricks);
        this.setBlock(chunk, i + 8, j + 0, k + 11, ancientbricks);
        this.setBlock(chunk, i + 8, j + 0, k + 12, dungeonBricks);
        this.setBlock(chunk, i + 8, j + 0, k + 13, ancientbricks);
        this.setBlock(chunk, i + 8, j + 0, k + 14, dungeonBricks);
        this.setBlock(chunk, i + 8, j + 0, k + 15, ancientbricks);
        this.setBlock(chunk, i + 8, j + 1, k + 3, dungeonBricks);
        this.setBlock(chunk, i + 8, j + 1, k + 4, dungeonBricks);
        this.setBlock(chunk, i + 8, j + 1, k + 5, ancientbricks);
        this.setBlock(chunk, i + 8, j + 1, k + 8, ancientbricks);
        this.setBlock(chunk, i + 8, j + 1, k + 9, dungeonBricks);
        this.setBlock(chunk, i + 8, j + 2, k + 4, ancientbricks);
        this.setBlock(chunk, i + 8, j + 2, k + 5, dungeonBricks);
        this.setBlock(chunk, i + 8, j + 2, k + 8, ancientbricks);
        this.setBlock(chunk, i + 8, j + 3, k + 0, BlockRegistry.arcaniumPower);
        this.setBlock(chunk, i + 8, j + 3, k + 5, dungeonBricks);
        this.setBlock(chunk, i + 8, j + 3, k + 6, BlockRegistry.dungeonLamp);
        this.setBlock(chunk, i + 8, j + 3, k + 7, dungeonBricks);
        this.setBlock(chunk, i + 8, j + 3, k + 15, BlockRegistry.arcaniumPower);
        this.setBlock(chunk, i + 8, j + 4, k + 0, ancientbricks);
        this.setBlock(chunk, i + 8, j + 4, k + 15, ancientbricks);
        this.setBlock(chunk, i + 8, j + 5, k + 0, soulStone);
        this.setBlock(chunk, i + 8, j + 5, k + 15, soulStone);
        this.setBlock(chunk, i + 8, j + 6, k + 0, ancientstone);
        this.setBlock(chunk, i + 8, j + 6, k + 15, ancientstone);
        this.setBlock(chunk, i + 8, j + 7, k + 0, dungeonBricks);
        this.setBlock(chunk, i + 8, j + 7, k + 15, dungeonBricks);
        this.setBlock(chunk, i + 9, j + 0, k + 0, dungeonBricks);
        this.setBlock(chunk, i + 9, j + 0, k + 1, BlockRegistry.dungeonLamp);
        this.setBlock(chunk, i + 9, j + 0, k + 2, dungeonBricks);
        this.setBlock(chunk, i + 9, j + 0, k + 3, dungeonBricks);
        this.setBlock(chunk, i + 9, j + 0, k + 4, dungeonBricks);
        this.setBlock(chunk, i + 9, j + 0, k + 5, dungeonBricks);
        this.setBlock(chunk, i + 9, j + 0, k + 6, BlockRegistry.arcaniumMetal);
        this.setBlock(chunk, i + 9, j + 0, k + 7, BlockRegistry.arcaniumMetal);
        this.setBlock(chunk, i + 9, j + 0, k + 8, dungeonBricks);
        this.setBlock(chunk, i + 9, j + 0, k + 9, dungeonBricks);
        this.setBlock(chunk, i + 9, j + 0, k + 10, dungeonBricks);
        this.setBlock(chunk, i + 9, j + 0, k + 11, dungeonBricks);
        this.setBlock(chunk, i + 9, j + 0, k + 12, dungeonBricks);
        this.setBlock(chunk, i + 9, j + 0, k + 13, dungeonBricks);
        this.setBlock(chunk, i + 9, j + 0, k + 14, dungeonBricks);
        this.setBlock(chunk, i + 9, j + 0, k + 15, ancientbricks);
        this.setBlock(chunk, i + 9, j + 1, k + 0, BlockRegistry.arcaniumMetal);
        this.setBlock(chunk, i + 9, j + 1, k + 3, dungeonBricks);
        this.setBlock(chunk, i + 9, j + 1, k + 4, dungeonBricks);
        this.setBlock(chunk, i + 9, j + 1, k + 5, ancientbricks);
        this.setBlock(chunk, i + 9, j + 1, k + 8, ancientbricks);
        this.setBlock(chunk, i + 9, j + 1, k + 9, dungeonBricks);
        this.setBlock(chunk, i + 9, j + 1, k + 15, BlockRegistry.arcaniumMetal);
        this.setBlock(chunk, i + 9, j + 2, k + 0, BlockRegistry.arcaniumMetal);
        this.setBlock(chunk, i + 9, j + 2, k + 4, ancientbricks);
        //this.setBlock(chunk, i + 9, j + 2, k + 5, arcaniteTubes);
        this.setBlock(chunk, i + 9, j + 2, k + 8, ancientbricks);
        this.setBlock(chunk, i + 9, j + 2, k + 15, BlockRegistry.arcaniumMetal);
        this.setBlock(chunk, i + 9, j + 3, k + 0, BlockRegistry.arcaniumMetal);
        this.setBlock(chunk, i + 9, j + 3, k + 5, dungeonBricks);
        this.setBlock(chunk, i + 9, j + 3, k + 6, soulStone);
        this.setBlock(chunk, i + 9, j + 3, k + 7, dungeonBricks);
        this.setBlock(chunk, i + 9, j + 3, k + 15, BlockRegistry.arcaniumMetal);
        this.setBlock(chunk, i + 9, j + 4, k + 0, ancientbricks);
        this.setBlock(chunk, i + 9, j + 4, k + 15, ancientbricks);
        this.setBlock(chunk, i + 9, j + 5, k + 0, soulStone);
        this.setBlock(chunk, i + 9, j + 5, k + 15, soulStone);
        this.setBlock(chunk, i + 9, j + 6, k + 0, ancientstone);
        this.setBlock(chunk, i + 9, j + 6, k + 15, ancientstone);
        this.setBlock(chunk, i + 9, j + 7, k + 0, dungeonBricks);
        this.setBlock(chunk, i + 9, j + 7, k + 15, dungeonBricks);
        this.setBlock(chunk, i + 10, j + 0, k + 0, dungeonBricks);
        this.setBlock(chunk, i + 10, j + 0, k + 1, dungeonBricks);
        this.setBlock(chunk, i + 10, j + 0, k + 2, dungeonBricks);
        this.setBlock(chunk, i + 10, j + 0, k + 3, dungeonBricks);
        this.setBlock(chunk, i + 10, j + 0, k + 4, dungeonBricks);
        this.setBlock(chunk, i + 10, j + 0, k + 5, dungeonBricks);
        this.setBlock(chunk, i + 10, j + 0, k + 6, BlockRegistry.arcaniumMetal);
        this.setBlock(chunk, i + 10, j + 0, k + 7, BlockRegistry.arcaniumMetal);
        this.setBlock(chunk, i + 10, j + 0, k + 8, dungeonBricks);
        this.setBlock(chunk, i + 10, j + 0, k + 9, dungeonBricks);
        this.setBlock(chunk, i + 10, j + 0, k + 10, BlockRegistry.arcaniumPower);
        this.setBlock(chunk, i + 10, j + 0, k + 11, BlockRegistry.arcaniumMetal);
        this.setBlock(chunk, i + 10, j + 0, k + 12, BlockRegistry.arcaniumMetal);
        this.setBlock(chunk, i + 10, j + 0, k + 13, BlockRegistry.arcaniumMetal);
        this.setBlock(chunk, i + 10, j + 0, k + 14, BlockRegistry.arcaniumMetal);
        this.setBlock(chunk, i + 10, j + 0, k + 15, ancientbricks);
        this.setBlock(chunk, i + 10, j + 1, k + 0, ancientbricks);
        this.setBlock(chunk, i + 10, j + 1, k + 3, dungeonBricks);
        this.setBlock(chunk, i + 10, j + 1, k + 4, dungeonBricks);
        this.setBlock(chunk, i + 10, j + 1, k + 5, ancientbricks);
        this.setBlock(chunk, i + 10, j + 1, k + 8, ancientbricks);
        this.setBlock(chunk, i + 10, j + 1, k + 9, dungeonBricks);
        this.setBlock(chunk, i + 10, j + 1, k + 15, ancientbricks);
        this.setBlock(chunk, i + 10, j + 2, k + 0, ancientbricks);
        this.setBlock(chunk, i + 10, j + 2, k + 4, ancientbricks);
        this.setBlock(chunk, i + 10, j + 2, k + 5, dungeonBricks);
        this.setBlock(chunk, i + 10, j + 2, k + 8, ancientbricks);
        this.setBlock(chunk, i + 10, j + 2, k + 15, ancientbricks);
        this.setBlock(chunk, i + 10, j + 3, k + 0, ancientbricks);
        this.setBlock(chunk, i + 10, j + 3, k + 5, dungeonBricks);
        this.setBlock(chunk, i + 10, j + 3, k + 6, ancientbricks);
        this.setBlock(chunk, i + 10, j + 3, k + 7, dungeonBricks);
        this.setBlock(chunk, i + 10, j + 3, k + 15, ancientbricks);
        this.setBlock(chunk, i + 10, j + 4, k + 0, ancientbricks);
        this.setBlock(chunk, i + 10, j + 4, k + 15, ancientbricks);
        this.setBlock(chunk, i + 10, j + 5, k + 0, soulStone);
        this.setBlock(chunk, i + 10, j + 5, k + 15, soulStone);
        this.setBlock(chunk, i + 10, j + 6, k + 0, ancientstone);
        this.setBlock(chunk, i + 10, j + 6, k + 15, ancientstone);
        this.setBlock(chunk, i + 10, j + 7, k + 0, dungeonBricks);
        this.setBlock(chunk, i + 10, j + 7, k + 15, dungeonBricks);
        this.setBlock(chunk, i + 11, j + 0, k + 0, dungeonBricks);
        this.setBlock(chunk, i + 11, j + 0, k + 1, BlockRegistry.dungeonLamp);
        this.setBlock(chunk, i + 11, j + 0, k + 2, dungeonBricks);
        this.setBlock(chunk, i + 11, j + 0, k + 3, dungeonBricks);
        this.setBlock(chunk, i + 11, j + 0, k + 4, dungeonBricks);
        this.setBlock(chunk, i + 11, j + 0, k + 5, dungeonBricks);
        this.setBlock(chunk, i + 11, j + 0, k + 6, BlockRegistry.arcaniumMetal);
        this.setBlock(chunk, i + 11, j + 0, k + 7, BlockRegistry.arcaniumMetal);
        this.setBlock(chunk, i + 11, j + 0, k + 8, dungeonBricks);
        this.setBlock(chunk, i + 11, j + 0, k + 9, dungeonBricks);
        this.setBlock(chunk, i + 11, j + 0, k + 10, dungeonBricks);
        this.setBlock(chunk, i + 11, j + 0, k + 11, dungeonBricks);
        this.setBlock(chunk, i + 11, j + 0, k + 12, dungeonBricks);
        this.setBlock(chunk, i + 11, j + 0, k + 13, dungeonBricks);
        this.setBlock(chunk, i + 11, j + 0, k + 14, dungeonBricks);
        this.setBlock(chunk, i + 11, j + 0, k + 15, ancientbricks);
        this.setBlock(chunk, i + 11, j + 1, k + 0, dungeonBricks);
        this.setBlock(chunk, i + 11, j + 1, k + 3, dungeonBricks);
        this.setBlock(chunk, i + 11, j + 1, k + 4, dungeonBricks);
        this.setBlock(chunk, i + 11, j + 1, k + 5, ancientbricks);
        this.setBlock(chunk, i + 11, j + 1, k + 8, ancientbricks);
        this.setBlock(chunk, i + 11, j + 1, k + 9, dungeonBricks);
        this.setBlock(chunk, i + 11, j + 1, k + 15, ancientbricks);
        this.setBlock(chunk, i + 11, j + 2, k + 0, dungeonBricks);
        this.setBlock(chunk, i + 11, j + 2, k + 4, ancientbricks);
        //this.setBlock(chunk, i + 11, j + 2, k + 5, arcaniteTubes);
        this.setBlock(chunk, i + 11, j + 2, k + 8, ancientbricks);
        this.setBlock(chunk, i + 11, j + 2, k + 15, ancientbricks);
        this.setBlock(chunk, i + 11, j + 3, k + 0, dungeonBricks);
        this.setBlock(chunk, i + 11, j + 3, k + 5, dungeonBricks);
        this.setBlock(chunk, i + 11, j + 3, k + 6, soulStone);
        this.setBlock(chunk, i + 11, j + 3, k + 7, dungeonBricks);
        this.setBlock(chunk, i + 11, j + 3, k + 15, ancientbricks);
        this.setBlock(chunk, i + 11, j + 4, k + 0, ancientbricks);
        this.setBlock(chunk, i + 11, j + 4, k + 15, ancientbricks);
        this.setBlock(chunk, i + 11, j + 5, k + 0, soulStone);
        this.setBlock(chunk, i + 11, j + 5, k + 15, soulStone);
        this.setBlock(chunk, i + 11, j + 6, k + 0, ancientstone);
        this.setBlock(chunk, i + 11, j + 6, k + 15, ancientstone);
        this.setBlock(chunk, i + 11, j + 7, k + 0, dungeonBricks);
        this.setBlock(chunk, i + 11, j + 7, k + 15, dungeonBricks);
        this.setBlock(chunk, i + 12, j + 0, k + 0, dungeonBricks);
        this.setBlock(chunk, i + 12, j + 0, k + 1, dungeonBricks);
        this.setBlock(chunk, i + 12, j + 0, k + 2, dungeonBricks);
        this.setBlock(chunk, i + 12, j + 0, k + 3, dungeonBricks);
        this.setBlock(chunk, i + 12, j + 0, k + 4, dungeonBricks);
        this.setBlock(chunk, i + 12, j + 0, k + 5, dungeonBricks);
        this.setBlock(chunk, i + 12, j + 0, k + 6, BlockRegistry.arcaniumMetal);
        this.setBlock(chunk, i + 12, j + 0, k + 7, BlockRegistry.arcaniumMetal);
        this.setBlock(chunk, i + 12, j + 0, k + 8, dungeonBricks);
        this.setBlock(chunk, i + 12, j + 0, k + 9, dungeonBricks);
        this.setBlock(chunk, i + 12, j + 0, k + 10, BlockRegistry.arcaniumPower);
        this.setBlock(chunk, i + 12, j + 0, k + 11, BlockRegistry.arcaniumMetal);
        this.setBlock(chunk, i + 12, j + 0, k + 12, BlockRegistry.arcaniumMetal);
        this.setBlock(chunk, i + 12, j + 0, k + 13, BlockRegistry.arcaniumMetal);
        this.setBlock(chunk, i + 12, j + 0, k + 14, BlockRegistry.arcaniumMetal);
        this.setBlock(chunk, i + 12, j + 0, k + 15, ancientbricks);
        this.setBlock(chunk, i + 12, j + 1, k + 0, ancientbricks);
        this.setBlock(chunk, i + 12, j + 1, k + 3, dungeonBricks);
        this.setBlock(chunk, i + 12, j + 1, k + 4, dungeonBricks);
        this.setBlock(chunk, i + 12, j + 1, k + 5, ancientbricks);
        this.setBlock(chunk, i + 12, j + 1, k + 8, ancientbricks);
        this.setBlock(chunk, i + 12, j + 1, k + 9, dungeonBricks);
        //this.setBlock(chunk, i + 12, j + 1, k + 14, arcaniteTubes);
        this.setBlock(chunk, i + 12, j + 1, k + 15, BlockRegistry.arcaniumMetal);
        this.setBlock(chunk, i + 12, j + 2, k + 0, ancientbricks);
        this.setBlock(chunk, i + 12, j + 2, k + 4, ancientbricks);
        this.setBlock(chunk, i + 12, j + 2, k + 5, dungeonBricks);
        this.setBlock(chunk, i + 12, j + 2, k + 8, ancientbricks);
        //this.setBlock(chunk, i + 12, j + 2, k + 14, arcaniteTubes);
        this.setBlock(chunk, i + 12, j + 2, k + 15, BlockRegistry.arcaniumMetal);
        this.setBlock(chunk, i + 12, j + 3, k + 0, dungeonBricks);
        this.setBlock(chunk, i + 12, j + 3, k + 5, dungeonBricks);
        this.setBlock(chunk, i + 12, j + 3, k + 6, ancientbricks);
        this.setBlock(chunk, i + 12, j + 3, k + 7, dungeonBricks);
        this.setBlock(chunk, i + 12, j + 3, k + 14, ancientbricks);
        this.setBlock(chunk, i + 12, j + 3, k + 15, ancientbricks);
        this.setBlock(chunk, i + 12, j + 4, k + 0, ancientbricks);
        this.setBlock(chunk, i + 12, j + 4, k + 15, ancientbricks);
        this.setBlock(chunk, i + 12, j + 5, k + 0, soulStone);
        this.setBlock(chunk, i + 12, j + 5, k + 15, soulStone);
        this.setBlock(chunk, i + 12, j + 6, k + 0, ancientstone);
        this.setBlock(chunk, i + 12, j + 6, k + 15, ancientstone);
        this.setBlock(chunk, i + 12, j + 7, k + 0, dungeonBricks);
        this.setBlock(chunk, i + 12, j + 7, k + 15, dungeonBricks);
        this.setBlock(chunk, i + 13, j + 0, k + 0, dungeonBricks);
        this.setBlock(chunk, i + 13, j + 0, k + 1, BlockRegistry.dungeonLamp);
        this.setBlock(chunk, i + 13, j + 0, k + 2, dungeonBricks);
        this.setBlock(chunk, i + 13, j + 0, k + 3, dungeonBricks);
        this.setBlock(chunk, i + 13, j + 0, k + 4, dungeonBricks);
        this.setBlock(chunk, i + 13, j + 0, k + 5, dungeonBricks);
        this.setBlock(chunk, i + 13, j + 0, k + 6, BlockRegistry.arcaniumMetal);
        this.setBlock(chunk, i + 13, j + 0, k + 7, BlockRegistry.arcaniumMetal);
        this.setBlock(chunk, i + 13, j + 0, k + 8, dungeonBricks);
        this.setBlock(chunk, i + 13, j + 0, k + 9, dungeonBricks);
        this.setBlock(chunk, i + 13, j + 0, k + 10, dungeonBricks);
        this.setBlock(chunk, i + 13, j + 0, k + 11, dungeonBricks);
        this.setBlock(chunk, i + 13, j + 0, k + 12, dungeonBricks);
        this.setBlock(chunk, i + 13, j + 0, k + 13, dungeonBricks);
        this.setBlock(chunk, i + 13, j + 0, k + 14, dungeonBricks);
        this.setBlock(chunk, i + 13, j + 0, k + 15, ancientbricks);
        this.setBlock(chunk, i + 13, j + 1, k + 0, ancientstone);
        this.setBlock(chunk, i + 13, j + 1, k + 3, dungeonBricks);
        this.setBlock(chunk, i + 13, j + 1, k + 4, dungeonBricks);
        this.setBlock(chunk, i + 13, j + 1, k + 5, ancientbricks);
        this.setBlock(chunk, i + 13, j + 1, k + 8, ancientbricks);
        this.setBlock(chunk, i + 13, j + 1, k + 9, dungeonBricks);
        //this.setBlock(chunk, i + 13, j + 1, k + 14, arcaniteTubes);
        this.setBlock(chunk, i + 13, j + 1, k + 15, BlockRegistry.arcaniumMetal);
        this.setBlock(chunk, i + 13, j + 2, k + 0, ancientstone);
        this.setBlock(chunk, i + 13, j + 2, k + 4, ancientbricks);
        //this.setBlock(chunk, i + 13, j + 2, k + 5, arcaniteTubes);
        this.setBlock(chunk, i + 13, j + 2, k + 8, ancientbricks);
        //this.setBlock(chunk, i + 13, j + 2, k + 14, arcaniteTubes);
        this.setBlock(chunk, i + 13, j + 2, k + 15, BlockRegistry.arcaniumMetal);
        this.setBlock(chunk, i + 13, j + 3, k + 0, ancientstone);
        this.setBlock(chunk, i + 13, j + 3, k + 5, dungeonBricks);
        this.setBlock(chunk, i + 13, j + 3, k + 6, soulStone);
        this.setBlock(chunk, i + 13, j + 3, k + 7, dungeonBricks);
        this.setBlock(chunk, i + 13, j + 3, k + 14, BlockRegistry.dungeonLamp);
        this.setBlock(chunk, i + 13, j + 3, k + 15, ancientbricks);
        this.setBlock(chunk, i + 13, j + 4, k + 0, ancientbricks);
        this.setBlock(chunk, i + 13, j + 4, k + 15, ancientbricks);
        this.setBlock(chunk, i + 13, j + 5, k + 0, soulStone);
        this.setBlock(chunk, i + 13, j + 5, k + 15, soulStone);
        this.setBlock(chunk, i + 13, j + 6, k + 0, ancientstone);
        this.setBlock(chunk, i + 13, j + 6, k + 15, ancientstone);
        this.setBlock(chunk, i + 13, j + 7, k + 0, dungeonBricks);
        this.setBlock(chunk, i + 13, j + 7, k + 15, dungeonBricks);
        this.setBlock(chunk, i + 14, j + 0, k + 0, dungeonBricks);
        this.setBlock(chunk, i + 14, j + 0, k + 1, dungeonBricks);
        this.setBlock(chunk, i + 14, j + 0, k + 2, dungeonBricks);
        this.setBlock(chunk, i + 14, j + 0, k + 3, dungeonBricks);
        this.setBlock(chunk, i + 14, j + 0, k + 4, dungeonBricks);
        this.setBlock(chunk, i + 14, j + 0, k + 5, dungeonBricks);
        this.setBlock(chunk, i + 14, j + 0, k + 6, BlockRegistry.arcaniumMetal);
        this.setBlock(chunk, i + 14, j + 0, k + 7, BlockRegistry.arcaniumMetal);
        this.setBlock(chunk, i + 14, j + 0, k + 8, dungeonBricks);
        this.setBlock(chunk, i + 14, j + 0, k + 9, dungeonBricks);
        this.setBlock(chunk, i + 14, j + 0, k + 10, BlockRegistry.arcaniumPower);
        this.setBlock(chunk, i + 14, j + 0, k + 11, BlockRegistry.arcaniumMetal);
        this.setBlock(chunk, i + 14, j + 0, k + 12, BlockRegistry.arcaniumMetal);
        this.setBlock(chunk, i + 14, j + 0, k + 13, BlockRegistry.arcaniumMetal);
        this.setBlock(chunk, i + 14, j + 0, k + 14, BlockRegistry.arcaniumMetal);
        this.setBlock(chunk, i + 14, j + 0, k + 15, ancientbricks);
        this.setBlock(chunk, i + 14, j + 1, k + 0, soulStone);
        this.setBlock(chunk, i + 14, j + 1, k + 3, dungeonBricks);
        this.setBlock(chunk, i + 14, j + 1, k + 4, dungeonBricks);
        this.setBlock(chunk, i + 14, j + 1, k + 5, ancientbricks);
        this.setBlock(chunk, i + 14, j + 1, k + 8, ancientbricks);
        this.setBlock(chunk, i + 14, j + 1, k + 9, dungeonBricks);
        //this.setBlock(chunk, i + 14, j + 1, k + 14, arcaniteTubes);
        this.setBlock(chunk, i + 14, j + 1, k + 15, BlockRegistry.arcaniumMetal);
        this.setBlock(chunk, i + 14, j + 2, k + 0, soulStone);
        this.setBlock(chunk, i + 14, j + 2, k + 4, ancientbricks);
        this.setBlock(chunk, i + 14, j + 2, k + 5, dungeonBricks);
        this.setBlock(chunk, i + 14, j + 2, k + 8, ancientbricks);
        //this.setBlock(chunk, i + 14, j + 2, k + 14, arcaniteTubes);
        this.setBlock(chunk, i + 14, j + 2, k + 15, BlockRegistry.arcaniumMetal);
        this.setBlock(chunk, i + 14, j + 3, k + 0, soulStone);
        this.setBlock(chunk, i + 14, j + 3, k + 5, dungeonBricks);
        this.setBlock(chunk, i + 14, j + 3, k + 6, ancientbricks);
        this.setBlock(chunk, i + 14, j + 3, k + 7, dungeonBricks);
        this.setBlock(chunk, i + 14, j + 3, k + 14, ancientbricks);
        this.setBlock(chunk, i + 14, j + 3, k + 15, ancientbricks);
        this.setBlock(chunk, i + 14, j + 4, k + 0, ancientbricks);
        this.setBlock(chunk, i + 14, j + 4, k + 15, ancientbricks);
        this.setBlock(chunk, i + 14, j + 5, k + 0, soulStone);
        this.setBlock(chunk, i + 14, j + 5, k + 15, soulStone);
        this.setBlock(chunk, i + 14, j + 6, k + 0, ancientstone);
        this.setBlock(chunk, i + 14, j + 6, k + 15, ancientstone);
        this.setBlock(chunk, i + 14, j + 7, k + 0, dungeonBricks);
        this.setBlock(chunk, i + 14, j + 7, k + 15, dungeonBricks);
        this.setBlock(chunk, i + 15, j + 0, k + 0, ancientbricks);
        this.setBlock(chunk, i + 15, j + 0, k + 1, ancientbricks);
        this.setBlock(chunk, i + 15, j + 0, k + 2, ancientbricks);
        this.setBlock(chunk, i + 15, j + 0, k + 3, ancientbricks);
        this.setBlock(chunk, i + 15, j + 0, k + 4, ancientbricks);
        this.setBlock(chunk, i + 15, j + 0, k + 5, ancientbricks);
        this.setBlock(chunk, i + 15, j + 0, k + 6, ancientbricks);
        this.setBlock(chunk, i + 15, j + 0, k + 7, ancientbricks);
        this.setBlock(chunk, i + 15, j + 0, k + 8, ancientbricks);
        this.setBlock(chunk, i + 15, j + 0, k + 9, ancientbricks);
        this.setBlock(chunk, i + 15, j + 0, k + 10, ancientbricks);
        this.setBlock(chunk, i + 15, j + 0, k + 11, ancientbricks);
        this.setBlock(chunk, i + 15, j + 0, k + 12, ancientbricks);
        this.setBlock(chunk, i + 15, j + 0, k + 13, ancientbricks);
        this.setBlock(chunk, i + 15, j + 0, k + 14, ancientbricks);
        this.setBlock(chunk, i + 15, j + 0, k + 15, ancientbricks);
        this.setBlock(chunk, i + 15, j + 1, k + 0, ancientbricks);
        this.setBlock(chunk, i + 15, j + 1, k + 1, ancientbricks);
        this.setBlock(chunk, i + 15, j + 1, k + 2, ancientbricks);
        this.setBlock(chunk, i + 15, j + 1, k + 3, ancientbricks);
        this.setBlock(chunk, i + 15, j + 1, k + 4, ancientbricks);
        this.setBlock(chunk, i + 15, j + 1, k + 5, ancientbricks);
        this.setBlock(chunk, i + 15, j + 1, k + 6, ancientbricks);
        this.setBlock(chunk, i + 15, j + 1, k + 9, ancientbricks);
        this.setBlock(chunk, i + 15, j + 1, k + 10, ancientbricks);
        this.setBlock(chunk, i + 15, j + 1, k + 11, ancientbricks);
        this.setBlock(chunk, i + 15, j + 1, k + 12, ancientbricks);
        this.setBlock(chunk, i + 15, j + 1, k + 13, ancientbricks);
        this.setBlock(chunk, i + 15, j + 1, k + 14, ancientbricks);
        this.setBlock(chunk, i + 15, j + 1, k + 15, ancientbricks);
        this.setBlock(chunk, i + 15, j + 2, k + 0, ancientbricks);
        this.setBlock(chunk, i + 15, j + 2, k + 1, ancientbricks);
        this.setBlock(chunk, i + 15, j + 2, k + 2, ancientbricks);
        this.setBlock(chunk, i + 15, j + 2, k + 3, ancientbricks);
        this.setBlock(chunk, i + 15, j + 2, k + 4, ancientbricks);
        this.setBlock(chunk, i + 15, j + 2, k + 5, ancientbricks);
        this.setBlock(chunk, i + 15, j + 2, k + 6, ancientbricks);
        this.setBlock(chunk, i + 15, j + 2, k + 9, ancientbricks);
        this.setBlock(chunk, i + 15, j + 2, k + 10, ancientbricks);
        this.setBlock(chunk, i + 15, j + 2, k + 11, ancientbricks);
        this.setBlock(chunk, i + 15, j + 2, k + 12, ancientbricks);
        this.setBlock(chunk, i + 15, j + 2, k + 13, ancientbricks);
        this.setBlock(chunk, i + 15, j + 2, k + 14, ancientbricks);
        this.setBlock(chunk, i + 15, j + 2, k + 15, ancientbricks);
        this.setBlock(chunk, i + 15, j + 3, k + 0, ancientbricks);
        this.setBlock(chunk, i + 15, j + 3, k + 1, ancientbricks);
        this.setBlock(chunk, i + 15, j + 3, k + 2, ancientbricks);
        this.setBlock(chunk, i + 15, j + 3, k + 3, ancientbricks);
        this.setBlock(chunk, i + 15, j + 3, k + 4, ancientbricks);
        this.setBlock(chunk, i + 15, j + 3, k + 5, ancientbricks);
        this.setBlock(chunk, i + 15, j + 3, k + 6, ancientbricks);
        this.setBlock(chunk, i + 15, j + 3, k + 7, ancientbricks);
        this.setBlock(chunk, i + 15, j + 3, k + 8, ancientbricks);
        this.setBlock(chunk, i + 15, j + 3, k + 9, ancientbricks);
        this.setBlock(chunk, i + 15, j + 3, k + 10, ancientbricks);
        this.setBlock(chunk, i + 15, j + 3, k + 11, ancientbricks);
        this.setBlock(chunk, i + 15, j + 3, k + 12, ancientbricks);
        this.setBlock(chunk, i + 15, j + 3, k + 13, ancientbricks);
        this.setBlock(chunk, i + 15, j + 3, k + 14, ancientbricks);
        this.setBlock(chunk, i + 15, j + 3, k + 15, ancientbricks);
        this.setBlock(chunk, i + 15, j + 4, k + 0, ancientbricks);
        this.setBlock(chunk, i + 15, j + 4, k + 1, ancientbricks);
        this.setBlock(chunk, i + 15, j + 4, k + 2, ancientbricks);
        this.setBlock(chunk, i + 15, j + 4, k + 3, ancientbricks);
        this.setBlock(chunk, i + 15, j + 4, k + 4, ancientbricks);
        this.setBlock(chunk, i + 15, j + 4, k + 5, ancientbricks);
        this.setBlock(chunk, i + 15, j + 4, k + 6, ancientbricks);
        this.setBlock(chunk, i + 15, j + 4, k + 7, ancientbricks);
        this.setBlock(chunk, i + 15, j + 4, k + 8, ancientbricks);
        this.setBlock(chunk, i + 15, j + 4, k + 9, ancientbricks);
        this.setBlock(chunk, i + 15, j + 4, k + 10, ancientbricks);
        this.setBlock(chunk, i + 15, j + 4, k + 11, ancientbricks);
        this.setBlock(chunk, i + 15, j + 4, k + 12, ancientbricks);
        this.setBlock(chunk, i + 15, j + 4, k + 13, ancientbricks);
        this.setBlock(chunk, i + 15, j + 4, k + 14, ancientbricks);
        this.setBlock(chunk, i + 15, j + 4, k + 15, ancientbricks);
        this.setBlock(chunk, i + 15, j + 5, k + 0, soulStone);
        this.setBlock(chunk, i + 15, j + 5, k + 1, soulStone);
        this.setBlock(chunk, i + 15, j + 5, k + 2, soulStone);
        this.setBlock(chunk, i + 15, j + 5, k + 3, soulStone);
        this.setBlock(chunk, i + 15, j + 5, k + 4, soulStone);
        this.setBlock(chunk, i + 15, j + 5, k + 5, soulStone);
        this.setBlock(chunk, i + 15, j + 5, k + 6, soulStone);
        this.setBlock(chunk, i + 15, j + 5, k + 7, soulStone);
        this.setBlock(chunk, i + 15, j + 5, k + 8, soulStone);
        this.setBlock(chunk, i + 15, j + 5, k + 9, soulStone);
        this.setBlock(chunk, i + 15, j + 5, k + 10, soulStone);
        this.setBlock(chunk, i + 15, j + 5, k + 11, soulStone);
        this.setBlock(chunk, i + 15, j + 5, k + 12, soulStone);
        this.setBlock(chunk, i + 15, j + 5, k + 13, soulStone);
        this.setBlock(chunk, i + 15, j + 5, k + 14, soulStone);
        this.setBlock(chunk, i + 15, j + 5, k + 15, soulStone);
        this.setBlock(chunk, i + 15, j + 6, k + 0, ancientstone);
        this.setBlock(chunk, i + 15, j + 6, k + 1, ancientstone);
        this.setBlock(chunk, i + 15, j + 6, k + 2, ancientstone);
        this.setBlock(chunk, i + 15, j + 6, k + 3, ancientstone);
        this.setBlock(chunk, i + 15, j + 6, k + 4, ancientstone);
        this.setBlock(chunk, i + 15, j + 6, k + 5, ancientstone);
        this.setBlock(chunk, i + 15, j + 6, k + 6, ancientstone);
        this.setBlock(chunk, i + 15, j + 6, k + 7, ancientstone);
        this.setBlock(chunk, i + 15, j + 6, k + 8, ancientstone);
        this.setBlock(chunk, i + 15, j + 6, k + 9, ancientstone);
        this.setBlock(chunk, i + 15, j + 6, k + 10, ancientstone);
        this.setBlock(chunk, i + 15, j + 6, k + 11, ancientstone);
        this.setBlock(chunk, i + 15, j + 6, k + 12, ancientstone);
        this.setBlock(chunk, i + 15, j + 6, k + 13, ancientstone);
        this.setBlock(chunk, i + 15, j + 6, k + 14, ancientstone);
        this.setBlock(chunk, i + 15, j + 6, k + 15, ancientstone);
        this.setBlock(chunk, i + 15, j + 7, k + 0, dungeonBricks);
        this.setBlock(chunk, i + 15, j + 7, k + 1, dungeonBricks);
        this.setBlock(chunk, i + 15, j + 7, k + 2, dungeonBricks);
        this.setBlock(chunk, i + 15, j + 7, k + 3, dungeonBricks);
        this.setBlock(chunk, i + 15, j + 7, k + 4, dungeonBricks);
        this.setBlock(chunk, i + 15, j + 7, k + 5, dungeonBricks);
        this.setBlock(chunk, i + 15, j + 7, k + 6, dungeonBricks);
        this.setBlock(chunk, i + 15, j + 7, k + 7, dungeonBricks);
        this.setBlock(chunk, i + 15, j + 7, k + 8, dungeonBricks);
        this.setBlock(chunk, i + 15, j + 7, k + 9, dungeonBricks);
        this.setBlock(chunk, i + 15, j + 7, k + 10, dungeonBricks);
        this.setBlock(chunk, i + 15, j + 7, k + 11, dungeonBricks);
        this.setBlock(chunk, i + 15, j + 7, k + 12, dungeonBricks);
        this.setBlock(chunk, i + 15, j + 7, k + 13, dungeonBricks);
        this.setBlock(chunk, i + 15, j + 7, k + 14, dungeonBricks);
        this.setBlock(chunk, i + 15, j + 7, k + 15, dungeonBricks);

        IBlockState southTubes = arcaniteTubes.getDefaultState().withProperty(BlockLadder.FACING, EnumFacing.SOUTH);
        this.setBlockState(chunk, i + 13, j + 2, k + 5, southTubes);
        this.setBlockState(chunk, i + 11, j + 2, k + 5, southTubes);
        this.setBlockState(chunk, i + 9, j + 2, k + 5, southTubes);
        this.setBlockState(chunk, i + 6, j + 2, k + 5, southTubes);
        this.setBlockState(chunk, i + 4, j + 2, k + 5, southTubes);
        this.setBlockState(chunk, i + 2, j + 2, k + 5, southTubes);
        return true;
    }
}