package divinerpg.dimensions.arcana.components;

import java.util.Random;

import divinerpg.dimensions.arcana.ArcanaChunkPrimer;
import divinerpg.registry.BlockRegistry;
import net.minecraft.block.Block;
import net.minecraft.block.BlockLadder;
import net.minecraft.block.state.IBlockState;
import net.minecraft.init.Blocks;
import net.minecraft.util.EnumFacing;

public class DungeonComponentParasecta extends DungeonComponentBase {
    @Override
    public boolean generate(ArcanaChunkPrimer chunk, Random rand, int x, int y, int z) {

        Block ancientBrick = BlockRegistry.ancientBrick;
        Block soulStone = BlockRegistry.soulStone;
        Block ancientStone = BlockRegistry.ancientStone;
        Block degradedBrick = BlockRegistry.degradedBrick;
        Block arcaniumMetal = BlockRegistry.arcaniumMetal;
        Block arcaniumPower = BlockRegistry.arcaniumPower;
        Block parasectaAltar = BlockRegistry.parasectaAltar;

        this.setBlock(chunk, x + 0, y + 0, z + 0, ancientBrick);
        this.setBlock(chunk, x + 0, y + 1, z + 0, ancientBrick);
        this.setBlock(chunk, x + 0, y + 2, z + 0, ancientBrick);
        this.setBlock(chunk, x + 0, y + 3, z + 0, ancientBrick);
        this.setBlock(chunk, x + 0, y + 4, z + 0, ancientBrick);
        this.setBlock(chunk, x + 0, y + 5, z + 0, soulStone);
        this.setBlock(chunk, x + 0, y + 6, z + 0, ancientStone);
        this.setBlock(chunk, x + 0, y + 7, z + 0, degradedBrick);
        this.setBlock(chunk, x + 0, y + 0, z + 1, ancientBrick);
        this.setBlock(chunk, x + 0, y + 1, z + 1, ancientBrick);
        this.setBlock(chunk, x + 0, y + 2, z + 1, ancientBrick);
        this.setBlock(chunk, x + 0, y + 3, z + 1, ancientBrick);
        this.setBlock(chunk, x + 0, y + 4, z + 1, ancientBrick);
        this.setBlock(chunk, x + 0, y + 5, z + 1, soulStone);
        this.setBlock(chunk, x + 0, y + 6, z + 1, ancientStone);
        this.setBlock(chunk, x + 0, y + 7, z + 1, degradedBrick);
        this.setBlock(chunk, x + 0, y + 0, z + 2, ancientBrick);
        this.setBlock(chunk, x + 0, y + 1, z + 2, ancientBrick);
        this.setBlock(chunk, x + 0, y + 2, z + 2, ancientBrick);
        this.setBlock(chunk, x + 0, y + 3, z + 2, ancientBrick);
        this.setBlock(chunk, x + 0, y + 4, z + 2, ancientBrick);
        this.setBlock(chunk, x + 0, y + 5, z + 2, soulStone);
        this.setBlock(chunk, x + 0, y + 6, z + 2, ancientStone);
        this.setBlock(chunk, x + 0, y + 7, z + 2, degradedBrick);
        this.setBlock(chunk, x + 0, y + 0, z + 3, ancientBrick);
        this.setBlock(chunk, x + 0, y + 1, z + 3, ancientBrick);
        this.setBlock(chunk, x + 0, y + 2, z + 3, ancientBrick);
        this.setBlock(chunk, x + 0, y + 3, z + 3, ancientBrick);
        this.setBlock(chunk, x + 0, y + 4, z + 3, ancientBrick);
        this.setBlock(chunk, x + 0, y + 5, z + 3, soulStone);
        this.setBlock(chunk, x + 0, y + 6, z + 3, ancientStone);
        this.setBlock(chunk, x + 0, y + 7, z + 3, degradedBrick);
        this.setBlock(chunk, x + 0, y + 0, z + 4, ancientBrick);
        this.setBlock(chunk, x + 0, y + 1, z + 4, ancientBrick);
        this.setBlock(chunk, x + 0, y + 2, z + 4, ancientBrick);
        this.setBlock(chunk, x + 0, y + 3, z + 4, ancientBrick);
        this.setBlock(chunk, x + 0, y + 4, z + 4, ancientBrick);
        this.setBlock(chunk, x + 0, y + 5, z + 4, soulStone);
        this.setBlock(chunk, x + 0, y + 6, z + 4, ancientStone);
        this.setBlock(chunk, x + 0, y + 7, z + 4, degradedBrick);
        this.setBlock(chunk, x + 0, y + 0, z + 5, ancientBrick);
        this.setBlock(chunk, x + 0, y + 1, z + 5, ancientBrick);
        this.setBlock(chunk, x + 0, y + 2, z + 5, ancientBrick);
        this.setBlock(chunk, x + 0, y + 3, z + 5, ancientBrick);
        this.setBlock(chunk, x + 0, y + 4, z + 5, ancientBrick);
        this.setBlock(chunk, x + 0, y + 5, z + 5, soulStone);
        this.setBlock(chunk, x + 0, y + 6, z + 5, ancientStone);
        this.setBlock(chunk, x + 0, y + 7, z + 5, degradedBrick);
        this.setBlock(chunk, x + 0, y + 0, z + 6, ancientBrick);
        this.setBlock(chunk, x + 0, y + 1, z + 6, ancientBrick);
        this.setBlock(chunk, x + 0, y + 2, z + 6, ancientBrick);
        this.setBlock(chunk, x + 0, y + 3, z + 6, ancientBrick);
        this.setBlock(chunk, x + 0, y + 4, z + 6, ancientBrick);
        this.setBlock(chunk, x + 0, y + 5, z + 6, soulStone);
        this.setBlock(chunk, x + 0, y + 6, z + 6, ancientStone);
        this.setBlock(chunk, x + 0, y + 7, z + 6, degradedBrick);
        this.setBlock(chunk, x + 0, y + 0, z + 7, ancientBrick);
        this.setBlock(chunk, x + 0, y + 3, z + 7, ancientBrick);
        this.setBlock(chunk, x + 0, y + 4, z + 7, ancientBrick);
        this.setBlock(chunk, x + 0, y + 5, z + 7, soulStone);
        this.setBlock(chunk, x + 0, y + 6, z + 7, ancientStone);
        this.setBlock(chunk, x + 0, y + 7, z + 7, degradedBrick);
        this.setBlock(chunk, x + 0, y + 0, z + 8, ancientBrick);
        this.setBlock(chunk, x + 0, y + 3, z + 8, ancientBrick);
        this.setBlock(chunk, x + 0, y + 4, z + 8, ancientBrick);
        this.setBlock(chunk, x + 0, y + 5, z + 8, soulStone);
        this.setBlock(chunk, x + 0, y + 6, z + 8, ancientStone);
        this.setBlock(chunk, x + 0, y + 7, z + 8, degradedBrick);
        this.setBlock(chunk, x + 0, y + 0, z + 9, ancientBrick);
        this.setBlock(chunk, x + 0, y + 1, z + 9, ancientBrick);
        this.setBlock(chunk, x + 0, y + 2, z + 9, ancientBrick);
        this.setBlock(chunk, x + 0, y + 3, z + 9, ancientBrick);
        this.setBlock(chunk, x + 0, y + 4, z + 9, ancientBrick);
        this.setBlock(chunk, x + 0, y + 5, z + 9, soulStone);
        this.setBlock(chunk, x + 0, y + 6, z + 9, ancientStone);
        this.setBlock(chunk, x + 0, y + 7, z + 9, degradedBrick);
        this.setBlock(chunk, x + 0, y + 0, z + 10, ancientBrick);
        this.setBlock(chunk, x + 0, y + 1, z + 10, ancientBrick);
        this.setBlock(chunk, x + 0, y + 2, z + 10, ancientBrick);
        this.setBlock(chunk, x + 0, y + 3, z + 10, ancientBrick);
        this.setBlock(chunk, x + 0, y + 4, z + 10, ancientBrick);
        this.setBlock(chunk, x + 0, y + 5, z + 10, soulStone);
        this.setBlock(chunk, x + 0, y + 6, z + 10, ancientStone);
        this.setBlock(chunk, x + 0, y + 7, z + 10, degradedBrick);
        this.setBlock(chunk, x + 0, y + 0, z + 11, ancientBrick);
        this.setBlock(chunk, x + 0, y + 1, z + 11, ancientBrick);
        this.setBlock(chunk, x + 0, y + 2, z + 11, ancientBrick);
        this.setBlock(chunk, x + 0, y + 3, z + 11, ancientBrick);
        this.setBlock(chunk, x + 0, y + 4, z + 11, ancientBrick);
        this.setBlock(chunk, x + 0, y + 5, z + 11, soulStone);
        this.setBlock(chunk, x + 0, y + 6, z + 11, ancientStone);
        this.setBlock(chunk, x + 0, y + 7, z + 11, degradedBrick);
        this.setBlock(chunk, x + 0, y + 0, z + 12, ancientBrick);
        this.setBlock(chunk, x + 0, y + 1, z + 12, ancientBrick);
        this.setBlock(chunk, x + 0, y + 2, z + 12, ancientBrick);
        this.setBlock(chunk, x + 0, y + 3, z + 12, ancientBrick);
        this.setBlock(chunk, x + 0, y + 4, z + 12, ancientBrick);
        this.setBlock(chunk, x + 0, y + 5, z + 12, soulStone);
        this.setBlock(chunk, x + 0, y + 6, z + 12, ancientStone);
        this.setBlock(chunk, x + 0, y + 7, z + 12, degradedBrick);
        this.setBlock(chunk, x + 0, y + 0, z + 13, ancientBrick);
        this.setBlock(chunk, x + 0, y + 1, z + 13, ancientBrick);
        this.setBlock(chunk, x + 0, y + 2, z + 13, ancientBrick);
        this.setBlock(chunk, x + 0, y + 3, z + 13, ancientBrick);
        this.setBlock(chunk, x + 0, y + 4, z + 13, ancientBrick);
        this.setBlock(chunk, x + 0, y + 5, z + 13, soulStone);
        this.setBlock(chunk, x + 0, y + 6, z + 13, ancientStone);
        this.setBlock(chunk, x + 0, y + 7, z + 13, degradedBrick);
        this.setBlock(chunk, x + 0, y + 0, z + 14, ancientBrick);
        this.setBlock(chunk, x + 0, y + 1, z + 14, ancientBrick);
        this.setBlock(chunk, x + 0, y + 2, z + 14, ancientBrick);
        this.setBlock(chunk, x + 0, y + 3, z + 14, ancientBrick);
        this.setBlock(chunk, x + 0, y + 4, z + 14, ancientBrick);
        this.setBlock(chunk, x + 0, y + 5, z + 14, soulStone);
        this.setBlock(chunk, x + 0, y + 6, z + 14, ancientStone);
        this.setBlock(chunk, x + 0, y + 7, z + 14, degradedBrick);
        this.setBlock(chunk, x + 0, y + 0, z + 15, ancientBrick);
        this.setBlock(chunk, x + 0, y + 1, z + 15, ancientBrick);
        this.setBlock(chunk, x + 0, y + 2, z + 15, ancientBrick);
        this.setBlock(chunk, x + 0, y + 3, z + 15, ancientBrick);
        this.setBlock(chunk, x + 0, y + 4, z + 15, ancientBrick);
        this.setBlock(chunk, x + 0, y + 5, z + 15, soulStone);
        this.setBlock(chunk, x + 0, y + 6, z + 15, ancientStone);
        this.setBlock(chunk, x + 0, y + 7, z + 15, degradedBrick);
        this.setBlock(chunk, x + 1, y + 0, z + 0, ancientBrick);
        this.setBlock(chunk, x + 1, y + 1, z + 0, ancientBrick);
        this.setBlock(chunk, x + 1, y + 2, z + 0, ancientBrick);
        this.setBlock(chunk, x + 1, y + 3, z + 0, ancientBrick);
        this.setBlock(chunk, x + 1, y + 4, z + 0, ancientBrick);
        this.setBlock(chunk, x + 1, y + 5, z + 0, soulStone);
        this.setBlock(chunk, x + 1, y + 6, z + 0, ancientStone);
        this.setBlock(chunk, x + 1, y + 7, z + 0, degradedBrick);
        this.setBlock(chunk, x + 1, y + 0, z + 1, degradedBrick);
        this.setBlock(chunk, x + 1, y + 0, z + 2, degradedBrick);
        this.setBlock(chunk, x + 1, y + 0, z + 3, degradedBrick);
        this.setBlock(chunk, x + 1, y + 0, z + 4, degradedBrick);
        this.setBlock(chunk, x + 1, y + 0, z + 5, degradedBrick);
        this.setBlock(chunk, x + 1, y + 0, z + 6, degradedBrick);
        this.setBlock(chunk, x + 1, y + 0, z + 7, degradedBrick);
        this.setBlock(chunk, x + 1, y + 0, z + 8, degradedBrick);
        this.setBlock(chunk, x + 1, y + 0, z + 9, degradedBrick);
        this.setBlock(chunk, x + 1, y + 0, z + 10, degradedBrick);
        this.setBlock(chunk, x + 1, y + 0, z + 11, degradedBrick);
        this.setBlock(chunk, x + 1, y + 0, z + 12, degradedBrick);
        this.setBlock(chunk, x + 1, y + 0, z + 13, degradedBrick);
        this.setBlock(chunk, x + 1, y + 0, z + 14, degradedBrick);
        this.setBlock(chunk, x + 1, y + 0, z + 15, ancientBrick);
        this.setBlock(chunk, x + 1, y + 1, z + 15, ancientBrick);
        this.setBlock(chunk, x + 1, y + 2, z + 15, ancientBrick);
        this.setBlock(chunk, x + 1, y + 3, z + 15, ancientBrick);
        this.setBlock(chunk, x + 1, y + 4, z + 15, ancientBrick);
        this.setBlock(chunk, x + 1, y + 5, z + 15, soulStone);
        this.setBlock(chunk, x + 1, y + 6, z + 15, ancientStone);
        this.setBlock(chunk, x + 1, y + 7, z + 15, degradedBrick);
        this.setBlock(chunk, x + 2, y + 0, z + 0, ancientBrick);
        this.setBlock(chunk, x + 2, y + 1, z + 0, ancientBrick);
        this.setBlock(chunk, x + 2, y + 2, z + 0, ancientBrick);
        this.setBlock(chunk, x + 2, y + 3, z + 0, ancientBrick);
        this.setBlock(chunk, x + 2, y + 4, z + 0, ancientBrick);
        this.setBlock(chunk, x + 2, y + 5, z + 0, soulStone);
        this.setBlock(chunk, x + 2, y + 6, z + 0, ancientStone);
        this.setBlock(chunk, x + 2, y + 7, z + 0, degradedBrick);
        this.setBlock(chunk, x + 2, y + 0, z + 1, degradedBrick);
        this.setBlock(chunk, x + 2, y + 0, z + 2, degradedBrick);
        this.setBlock(chunk, x + 2, y + 0, z + 3, degradedBrick);
        this.setBlock(chunk, x + 2, y + 0, z + 4, degradedBrick);
        this.setBlock(chunk, x + 2, y + 0, z + 5, degradedBrick);
        this.setBlock(chunk, x + 2, y + 0, z + 6, degradedBrick);
        this.setBlock(chunk, x + 2, y + 0, z + 7, degradedBrick);
        this.setBlock(chunk, x + 2, y + 0, z + 8, degradedBrick);
        this.setBlock(chunk, x + 2, y + 0, z + 9, degradedBrick);
        this.setBlock(chunk, x + 2, y + 0, z + 10, degradedBrick);
        this.setBlock(chunk, x + 2, y + 0, z + 11, degradedBrick);
        this.setBlock(chunk, x + 2, y + 0, z + 12, degradedBrick);
        this.setBlock(chunk, x + 2, y + 0, z + 13, degradedBrick);
        this.setBlock(chunk, x + 2, y + 0, z + 14, degradedBrick);
        this.setBlock(chunk, x + 2, y + 0, z + 15, ancientBrick);
        this.setBlock(chunk, x + 2, y + 1, z + 15, ancientBrick);
        this.setBlock(chunk, x + 2, y + 2, z + 15, ancientBrick);
        this.setBlock(chunk, x + 2, y + 3, z + 15, ancientBrick);
        this.setBlock(chunk, x + 2, y + 4, z + 15, ancientBrick);
        this.setBlock(chunk, x + 2, y + 5, z + 15, soulStone);
        this.setBlock(chunk, x + 2, y + 6, z + 15, ancientStone);
        this.setBlock(chunk, x + 2, y + 7, z + 15, degradedBrick);
        this.setBlock(chunk, x + 3, y + 0, z + 0, ancientBrick);
        this.setBlock(chunk, x + 3, y + 1, z + 0, ancientBrick);
        this.setBlock(chunk, x + 3, y + 2, z + 0, ancientBrick);
        this.setBlock(chunk, x + 3, y + 3, z + 0, ancientBrick);
        this.setBlock(chunk, x + 3, y + 4, z + 0, ancientBrick);
        this.setBlock(chunk, x + 3, y + 5, z + 0, soulStone);
        this.setBlock(chunk, x + 3, y + 6, z + 0, ancientStone);
        this.setBlock(chunk, x + 3, y + 7, z + 0, degradedBrick);
        this.setBlock(chunk, x + 3, y + 0, z + 1, degradedBrick);
        this.setBlock(chunk, x + 3, y + 0, z + 2, degradedBrick);
        this.setBlock(chunk, x + 3, y + 0, z + 3, degradedBrick);
        this.setBlock(chunk, x + 3, y + 0, z + 4, degradedBrick);
        this.setBlock(chunk, x + 3, y + 0, z + 5, degradedBrick);
        this.setBlock(chunk, x + 3, y + 0, z + 6, degradedBrick);
        this.setBlock(chunk, x + 3, y + 0, z + 7, degradedBrick);
        this.setBlock(chunk, x + 3, y + 0, z + 8, degradedBrick);
        this.setBlock(chunk, x + 3, y + 0, z + 9, degradedBrick);
        this.setBlock(chunk, x + 3, y + 0, z + 10, degradedBrick);
        this.setBlock(chunk, x + 3, y + 0, z + 11, degradedBrick);
        this.setBlock(chunk, x + 3, y + 0, z + 12, degradedBrick);
        this.setBlock(chunk, x + 3, y + 0, z + 13, degradedBrick);
        this.setBlock(chunk, x + 3, y + 0, z + 14, degradedBrick);
        this.setBlock(chunk, x + 3, y + 0, z + 15, ancientBrick);
        this.setBlock(chunk, x + 3, y + 1, z + 15, ancientBrick);
        this.setBlock(chunk, x + 3, y + 2, z + 15, ancientBrick);
        this.setBlock(chunk, x + 3, y + 3, z + 15, ancientBrick);
        this.setBlock(chunk, x + 3, y + 4, z + 15, ancientBrick);
        this.setBlock(chunk, x + 3, y + 5, z + 15, soulStone);
        this.setBlock(chunk, x + 3, y + 6, z + 15, ancientStone);
        this.setBlock(chunk, x + 3, y + 7, z + 15, degradedBrick);
        this.setBlock(chunk, x + 4, y + 0, z + 0, ancientBrick);
        this.setBlock(chunk, x + 4, y + 1, z + 0, ancientBrick);
        this.setBlock(chunk, x + 4, y + 2, z + 0, ancientBrick);
        this.setBlock(chunk, x + 4, y + 3, z + 0, ancientBrick);
        this.setBlock(chunk, x + 4, y + 4, z + 0, ancientBrick);
        this.setBlock(chunk, x + 4, y + 5, z + 0, soulStone);
        this.setBlock(chunk, x + 4, y + 6, z + 0, ancientStone);
        this.setBlock(chunk, x + 4, y + 7, z + 0, degradedBrick);
        this.setBlock(chunk, x + 4, y + 0, z + 1, degradedBrick);
        this.setBlock(chunk, x + 4, y + 0, z + 2, degradedBrick);
        this.setBlock(chunk, x + 4, y + 0, z + 3, degradedBrick);
        this.setBlock(chunk, x + 4, y + 0, z + 4, degradedBrick);
        this.setBlock(chunk, x + 4, y + 0, z + 5, degradedBrick);
        this.setBlock(chunk, x + 4, y + 0, z + 6, degradedBrick);
        this.setBlock(chunk, x + 4, y + 0, z + 7, degradedBrick);
        this.setBlock(chunk, x + 4, y + 0, z + 8, degradedBrick);
        this.setBlock(chunk, x + 4, y + 0, z + 9, degradedBrick);
        this.setBlock(chunk, x + 4, y + 0, z + 10, degradedBrick);
        this.setBlock(chunk, x + 4, y + 0, z + 11, degradedBrick);
        this.setBlock(chunk, x + 4, y + 0, z + 12, degradedBrick);
        this.setBlock(chunk, x + 4, y + 0, z + 13, degradedBrick);
        this.setBlock(chunk, x + 4, y + 0, z + 14, degradedBrick);
        this.setBlock(chunk, x + 4, y + 0, z + 15, ancientBrick);
        this.setBlock(chunk, x + 4, y + 1, z + 15, ancientBrick);
        this.setBlock(chunk, x + 4, y + 2, z + 15, ancientBrick);
        this.setBlock(chunk, x + 4, y + 3, z + 15, ancientBrick);
        this.setBlock(chunk, x + 4, y + 4, z + 15, ancientBrick);
        this.setBlock(chunk, x + 4, y + 5, z + 15, soulStone);
        this.setBlock(chunk, x + 4, y + 6, z + 15, ancientStone);
        this.setBlock(chunk, x + 4, y + 7, z + 15, degradedBrick);
        this.setBlock(chunk, x + 5, y + 0, z + 0, ancientBrick);
        this.setBlock(chunk, x + 5, y + 1, z + 0, ancientBrick);
        this.setBlock(chunk, x + 5, y + 2, z + 0, ancientBrick);
        this.setBlock(chunk, x + 5, y + 3, z + 0, ancientBrick);
        this.setBlock(chunk, x + 5, y + 4, z + 0, ancientBrick);
        this.setBlock(chunk, x + 5, y + 5, z + 0, soulStone);
        this.setBlock(chunk, x + 5, y + 6, z + 0, ancientStone);
        this.setBlock(chunk, x + 5, y + 7, z + 0, degradedBrick);
        this.setBlock(chunk, x + 5, y + 0, z + 1, degradedBrick);
        this.setBlock(chunk, x + 5, y + 0, z + 2, degradedBrick);
        this.setBlock(chunk, x + 5, y + 0, z + 3, degradedBrick);
        this.setBlock(chunk, x + 5, y + 0, z + 4, degradedBrick);
        this.setBlock(chunk, x + 5, y + 0, z + 5, degradedBrick);
        this.setBlock(chunk, x + 5, y + 0, z + 6, degradedBrick);
        this.setBlock(chunk, x + 5, y + 0, z + 7, degradedBrick);
        this.setBlock(chunk, x + 5, y + 0, z + 8, degradedBrick);
        this.setBlock(chunk, x + 5, y + 0, z + 9, degradedBrick);
        this.setBlock(chunk, x + 5, y + 0, z + 10, degradedBrick);
        this.setBlock(chunk, x + 5, y + 0, z + 11, degradedBrick);
        this.setBlock(chunk, x + 5, y + 0, z + 12, degradedBrick);
        this.setBlock(chunk, x + 5, y + 0, z + 13, degradedBrick);
        this.setBlock(chunk, x + 5, y + 0, z + 14, degradedBrick);
        this.setBlock(chunk, x + 5, y + 0, z + 15, ancientBrick);
        this.setBlock(chunk, x + 5, y + 1, z + 15, ancientBrick);
        this.setBlock(chunk, x + 5, y + 2, z + 15, ancientBrick);
        this.setBlock(chunk, x + 5, y + 3, z + 15, ancientBrick);
        this.setBlock(chunk, x + 5, y + 4, z + 15, ancientBrick);
        this.setBlock(chunk, x + 5, y + 5, z + 15, soulStone);
        this.setBlock(chunk, x + 5, y + 6, z + 15, ancientStone);
        this.setBlock(chunk, x + 5, y + 7, z + 15, degradedBrick);
        this.setBlock(chunk, x + 6, y + 0, z + 0, ancientBrick);
        this.setBlock(chunk, x + 6, y + 1, z + 0, arcaniumMetal);
        this.setBlock(chunk, x + 6, y + 2, z + 0, arcaniumMetal);
        this.setBlock(chunk, x + 6, y + 3, z + 0, arcaniumMetal);
        this.setBlock(chunk, x + 6, y + 4, z + 0, ancientBrick);
        this.setBlock(chunk, x + 6, y + 5, z + 0, soulStone);
        this.setBlock(chunk, x + 6, y + 6, z + 0, ancientStone);
        this.setBlock(chunk, x + 6, y + 7, z + 0, degradedBrick);
        this.setBlock(chunk, x + 6, y + 0, z + 1, degradedBrick);
        this.setBlock(chunk, x + 6, y + 0, z + 2, degradedBrick);
        this.setBlock(chunk, x + 6, y + 0, z + 3, degradedBrick);
        this.setBlock(chunk, x + 6, y + 0, z + 4, degradedBrick);
        this.setBlock(chunk, x + 6, y + 0, z + 5, degradedBrick);
        this.setBlock(chunk, x + 6, y + 0, z + 6, degradedBrick);
        this.setBlock(chunk, x + 6, y + 0, z + 7, degradedBrick);
        this.setBlock(chunk, x + 6, y + 0, z + 8, degradedBrick);
        this.setBlock(chunk, x + 6, y + 0, z + 9, degradedBrick);
        this.setBlock(chunk, x + 6, y + 0, z + 10, degradedBrick);
        this.setBlock(chunk, x + 6, y + 0, z + 11, degradedBrick);
        this.setBlock(chunk, x + 6, y + 0, z + 12, degradedBrick);
        this.setBlock(chunk, x + 6, y + 0, z + 13, degradedBrick);
        this.setBlock(chunk, x + 6, y + 0, z + 14, degradedBrick);
        this.setBlock(chunk, x + 6, y + 0, z + 15, ancientBrick);
        this.setBlock(chunk, x + 6, y + 1, z + 15, arcaniumMetal);
        this.setBlock(chunk, x + 6, y + 2, z + 15, arcaniumMetal);
        this.setBlock(chunk, x + 6, y + 3, z + 15, arcaniumMetal);
        this.setBlock(chunk, x + 6, y + 4, z + 15, ancientBrick);
        this.setBlock(chunk, x + 6, y + 5, z + 15, soulStone);
        this.setBlock(chunk, x + 6, y + 6, z + 15, ancientStone);
        this.setBlock(chunk, x + 6, y + 7, z + 15, degradedBrick);
        this.setBlock(chunk, x + 7, y + 0, z + 0, ancientBrick);
        this.setBlock(chunk, x + 7, y + 3, z + 0, arcaniumPower);
        this.setBlock(chunk, x + 7, y + 4, z + 0, ancientBrick);
        this.setBlock(chunk, x + 7, y + 5, z + 0, soulStone);
        this.setBlock(chunk, x + 7, y + 6, z + 0, ancientStone);
        this.setBlock(chunk, x + 7, y + 7, z + 0, degradedBrick);
        this.setBlock(chunk, x + 7, y + 0, z + 1, degradedBrick);
        this.setBlock(chunk, x + 7, y + 0, z + 2, degradedBrick);
        this.setBlock(chunk, x + 7, y + 0, z + 3, degradedBrick);
        this.setBlock(chunk, x + 7, y + 0, z + 4, degradedBrick);
        this.setBlock(chunk, x + 7, y + 0, z + 5, degradedBrick);
        this.setBlock(chunk, x + 7, y + 0, z + 6, degradedBrick);
        this.setBlock(chunk, x + 7, y + 0, z + 7, degradedBrick);
        this.setBlock(chunk, x + 7, y + 1, z + 7, parasectaAltar);
        this.setBlock(chunk, x + 7, y + 0, z + 8, degradedBrick);
        this.setBlock(chunk, x + 7, y + 1, z + 8, parasectaAltar);
        this.setBlock(chunk, x + 7, y + 0, z + 9, degradedBrick);
        this.setBlock(chunk, x + 7, y + 0, z + 10, degradedBrick);
        this.setBlock(chunk, x + 7, y + 0, z + 11, degradedBrick);
        this.setBlock(chunk, x + 7, y + 0, z + 12, degradedBrick);
        this.setBlock(chunk, x + 7, y + 0, z + 13, degradedBrick);
        this.setBlock(chunk, x + 7, y + 0, z + 14, degradedBrick);
        this.setBlock(chunk, x + 7, y + 0, z + 15, ancientBrick);
        this.setBlock(chunk, x + 7, y + 3, z + 15, arcaniumPower);
        this.setBlock(chunk, x + 7, y + 4, z + 15, ancientBrick);
        this.setBlock(chunk, x + 7, y + 5, z + 15, soulStone);
        this.setBlock(chunk, x + 7, y + 6, z + 15, ancientStone);
        this.setBlock(chunk, x + 7, y + 7, z + 15, degradedBrick);
        this.setBlock(chunk, x + 8, y + 0, z + 0, ancientBrick);
        this.setBlock(chunk, x + 8, y + 3, z + 0, arcaniumPower);
        this.setBlock(chunk, x + 8, y + 4, z + 0, ancientBrick);
        this.setBlock(chunk, x + 8, y + 5, z + 0, soulStone);
        this.setBlock(chunk, x + 8, y + 6, z + 0, ancientStone);
        this.setBlock(chunk, x + 8, y + 7, z + 0, degradedBrick);
        this.setBlock(chunk, x + 8, y + 0, z + 1, degradedBrick);
        this.setBlock(chunk, x + 8, y + 0, z + 2, degradedBrick);
        this.setBlock(chunk, x + 8, y + 0, z + 3, degradedBrick);
        this.setBlock(chunk, x + 8, y + 0, z + 4, degradedBrick);
        this.setBlock(chunk, x + 8, y + 0, z + 5, degradedBrick);
        this.setBlock(chunk, x + 8, y + 0, z + 6, degradedBrick);
        this.setBlock(chunk, x + 8, y + 0, z + 7, degradedBrick);
        this.setBlock(chunk, x + 8, y + 1, z + 7, parasectaAltar);
        this.setBlock(chunk, x + 8, y + 0, z + 8, degradedBrick);
        this.setBlock(chunk, x + 8, y + 1, z + 8, parasectaAltar);
        this.setBlock(chunk, x + 8, y + 0, z + 9, degradedBrick);
        this.setBlock(chunk, x + 8, y + 0, z + 10, degradedBrick);
        this.setBlock(chunk, x + 8, y + 0, z + 11, degradedBrick);
        this.setBlock(chunk, x + 8, y + 0, z + 12, degradedBrick);
        this.setBlock(chunk, x + 8, y + 0, z + 13, degradedBrick);
        this.setBlock(chunk, x + 8, y + 0, z + 14, degradedBrick);
        this.setBlock(chunk, x + 8, y + 0, z + 15, ancientBrick);
        this.setBlock(chunk, x + 8, y + 3, z + 15, arcaniumPower);
        this.setBlock(chunk, x + 8, y + 4, z + 15, ancientBrick);
        this.setBlock(chunk, x + 8, y + 5, z + 15, soulStone);
        this.setBlock(chunk, x + 8, y + 6, z + 15, ancientStone);
        this.setBlock(chunk, x + 8, y + 7, z + 15, degradedBrick);
        this.setBlock(chunk, x + 9, y + 0, z + 0, ancientBrick);
        this.setBlock(chunk, x + 9, y + 1, z + 0, arcaniumMetal);
        this.setBlock(chunk, x + 9, y + 2, z + 0, arcaniumMetal);
        this.setBlock(chunk, x + 9, y + 3, z + 0, arcaniumMetal);
        this.setBlock(chunk, x + 9, y + 4, z + 0, ancientBrick);
        this.setBlock(chunk, x + 9, y + 5, z + 0, soulStone);
        this.setBlock(chunk, x + 9, y + 6, z + 0, ancientStone);
        this.setBlock(chunk, x + 9, y + 7, z + 0, degradedBrick);
        this.setBlock(chunk, x + 9, y + 0, z + 1, degradedBrick);
        this.setBlock(chunk, x + 9, y + 0, z + 2, degradedBrick);
        this.setBlock(chunk, x + 9, y + 0, z + 3, degradedBrick);
        this.setBlock(chunk, x + 9, y + 0, z + 4, degradedBrick);
        this.setBlock(chunk, x + 9, y + 0, z + 5, degradedBrick);
        this.setBlock(chunk, x + 9, y + 0, z + 6, degradedBrick);
        this.setBlock(chunk, x + 9, y + 0, z + 7, degradedBrick);
        this.setBlock(chunk, x + 9, y + 0, z + 8, degradedBrick);
        this.setBlock(chunk, x + 9, y + 0, z + 9, degradedBrick);
        this.setBlock(chunk, x + 9, y + 0, z + 10, degradedBrick);
        this.setBlock(chunk, x + 9, y + 0, z + 11, degradedBrick);
        this.setBlock(chunk, x + 9, y + 0, z + 12, degradedBrick);
        this.setBlock(chunk, x + 9, y + 0, z + 13, degradedBrick);
        this.setBlock(chunk, x + 9, y + 0, z + 14, degradedBrick);
        this.setBlock(chunk, x + 9, y + 0, z + 15, ancientBrick);
        this.setBlock(chunk, x + 9, y + 1, z + 15, arcaniumMetal);
        this.setBlock(chunk, x + 9, y + 2, z + 15, arcaniumMetal);
        this.setBlock(chunk, x + 9, y + 3, z + 15, arcaniumMetal);
        this.setBlock(chunk, x + 9, y + 4, z + 15, ancientBrick);
        this.setBlock(chunk, x + 9, y + 5, z + 15, soulStone);
        this.setBlock(chunk, x + 9, y + 6, z + 15, ancientStone);
        this.setBlock(chunk, x + 9, y + 7, z + 15, degradedBrick);
        this.setBlock(chunk, x + 10, y + 0, z + 0, ancientBrick);
        this.setBlock(chunk, x + 10, y + 1, z + 0, ancientBrick);
        this.setBlock(chunk, x + 10, y + 2, z + 0, ancientBrick);
        this.setBlock(chunk, x + 10, y + 3, z + 0, ancientBrick);
        this.setBlock(chunk, x + 10, y + 4, z + 0, ancientBrick);
        this.setBlock(chunk, x + 10, y + 5, z + 0, soulStone);
        this.setBlock(chunk, x + 10, y + 6, z + 0, ancientStone);
        this.setBlock(chunk, x + 10, y + 7, z + 0, degradedBrick);
        this.setBlock(chunk, x + 10, y + 0, z + 1, degradedBrick);
        this.setBlock(chunk, x + 10, y + 0, z + 2, degradedBrick);
        this.setBlock(chunk, x + 10, y + 0, z + 3, degradedBrick);
        this.setBlock(chunk, x + 10, y + 0, z + 4, degradedBrick);
        this.setBlock(chunk, x + 10, y + 0, z + 5, degradedBrick);
        this.setBlock(chunk, x + 10, y + 0, z + 6, degradedBrick);
        this.setBlock(chunk, x + 10, y + 0, z + 7, degradedBrick);
        this.setBlock(chunk, x + 10, y + 0, z + 8, degradedBrick);
        this.setBlock(chunk, x + 10, y + 0, z + 9, degradedBrick);
        this.setBlock(chunk, x + 10, y + 0, z + 10, degradedBrick);
        this.setBlock(chunk, x + 10, y + 0, z + 11, degradedBrick);
        this.setBlock(chunk, x + 10, y + 0, z + 12, degradedBrick);
        this.setBlock(chunk, x + 10, y + 0, z + 13, degradedBrick);
        this.setBlock(chunk, x + 10, y + 0, z + 14, degradedBrick);
        this.setBlock(chunk, x + 10, y + 0, z + 15, ancientBrick);
        this.setBlock(chunk, x + 10, y + 1, z + 15, ancientBrick);
        this.setBlock(chunk, x + 10, y + 2, z + 15, ancientBrick);
        this.setBlock(chunk, x + 10, y + 3, z + 15, ancientBrick);
        this.setBlock(chunk, x + 10, y + 4, z + 15, ancientBrick);
        this.setBlock(chunk, x + 10, y + 5, z + 15, soulStone);
        this.setBlock(chunk, x + 10, y + 6, z + 15, ancientStone);
        this.setBlock(chunk, x + 10, y + 7, z + 15, degradedBrick);
        this.setBlock(chunk, x + 11, y + 0, z + 0, ancientBrick);
        this.setBlock(chunk, x + 11, y + 1, z + 0, ancientBrick);
        this.setBlock(chunk, x + 11, y + 2, z + 0, ancientBrick);
        this.setBlock(chunk, x + 11, y + 3, z + 0, ancientBrick);
        this.setBlock(chunk, x + 11, y + 4, z + 0, ancientBrick);
        this.setBlock(chunk, x + 11, y + 5, z + 0, soulStone);
        this.setBlock(chunk, x + 11, y + 6, z + 0, ancientStone);
        this.setBlock(chunk, x + 11, y + 7, z + 0, degradedBrick);
        this.setBlock(chunk, x + 11, y + 0, z + 1, degradedBrick);
        this.setBlock(chunk, x + 11, y + 0, z + 2, degradedBrick);
        this.setBlock(chunk, x + 11, y + 0, z + 3, degradedBrick);
        this.setBlock(chunk, x + 11, y + 0, z + 4, degradedBrick);
        this.setBlock(chunk, x + 11, y + 0, z + 5, degradedBrick);
        this.setBlock(chunk, x + 11, y + 0, z + 6, degradedBrick);
        this.setBlock(chunk, x + 11, y + 0, z + 7, degradedBrick);
        this.setBlock(chunk, x + 11, y + 0, z + 8, degradedBrick);
        this.setBlock(chunk, x + 11, y + 0, z + 9, degradedBrick);
        this.setBlock(chunk, x + 11, y + 0, z + 10, degradedBrick);
        this.setBlock(chunk, x + 11, y + 0, z + 11, degradedBrick);
        this.setBlock(chunk, x + 11, y + 0, z + 12, degradedBrick);
        this.setBlock(chunk, x + 11, y + 0, z + 13, degradedBrick);
        this.setBlock(chunk, x + 11, y + 0, z + 14, degradedBrick);
        this.setBlock(chunk, x + 11, y + 0, z + 15, ancientBrick);
        this.setBlock(chunk, x + 11, y + 1, z + 15, ancientBrick);
        this.setBlock(chunk, x + 11, y + 2, z + 15, ancientBrick);
        this.setBlock(chunk, x + 11, y + 3, z + 15, ancientBrick);
        this.setBlock(chunk, x + 11, y + 4, z + 15, ancientBrick);
        this.setBlock(chunk, x + 11, y + 5, z + 15, soulStone);
        this.setBlock(chunk, x + 11, y + 6, z + 15, ancientStone);
        this.setBlock(chunk, x + 11, y + 7, z + 15, degradedBrick);
        this.setBlock(chunk, x + 12, y + 0, z + 0, ancientBrick);
        this.setBlock(chunk, x + 12, y + 1, z + 0, ancientBrick);
        this.setBlock(chunk, x + 12, y + 2, z + 0, ancientBrick);
        this.setBlock(chunk, x + 12, y + 3, z + 0, ancientBrick);
        this.setBlock(chunk, x + 12, y + 4, z + 0, ancientBrick);
        this.setBlock(chunk, x + 12, y + 5, z + 0, soulStone);
        this.setBlock(chunk, x + 12, y + 6, z + 0, ancientStone);
        this.setBlock(chunk, x + 12, y + 7, z + 0, degradedBrick);
        this.setBlock(chunk, x + 12, y + 0, z + 1, degradedBrick);
        this.setBlock(chunk, x + 12, y + 0, z + 2, degradedBrick);
        this.setBlock(chunk, x + 12, y + 0, z + 3, degradedBrick);
        this.setBlock(chunk, x + 12, y + 0, z + 4, degradedBrick);
        this.setBlock(chunk, x + 12, y + 0, z + 5, degradedBrick);
        this.setBlock(chunk, x + 12, y + 0, z + 6, degradedBrick);
        this.setBlock(chunk, x + 12, y + 0, z + 7, degradedBrick);
        this.setBlock(chunk, x + 12, y + 0, z + 8, degradedBrick);
        this.setBlock(chunk, x + 12, y + 0, z + 9, degradedBrick);
        this.setBlock(chunk, x + 12, y + 0, z + 10, degradedBrick);
        this.setBlock(chunk, x + 12, y + 0, z + 11, degradedBrick);
        this.setBlock(chunk, x + 12, y + 0, z + 12, degradedBrick);
        this.setBlock(chunk, x + 12, y + 0, z + 13, degradedBrick);
        this.setBlock(chunk, x + 12, y + 0, z + 14, degradedBrick);
        this.setBlock(chunk, x + 12, y + 0, z + 15, ancientBrick);
        this.setBlock(chunk, x + 12, y + 1, z + 15, ancientBrick);
        this.setBlock(chunk, x + 12, y + 2, z + 15, ancientBrick);
        this.setBlock(chunk, x + 12, y + 3, z + 15, ancientBrick);
        this.setBlock(chunk, x + 12, y + 4, z + 15, ancientBrick);
        this.setBlock(chunk, x + 12, y + 5, z + 15, soulStone);
        this.setBlock(chunk, x + 12, y + 6, z + 15, ancientStone);
        this.setBlock(chunk, x + 12, y + 7, z + 15, degradedBrick);
        this.setBlock(chunk, x + 13, y + 0, z + 0, ancientBrick);
        this.setBlock(chunk, x + 13, y + 1, z + 0, ancientBrick);
        this.setBlock(chunk, x + 13, y + 2, z + 0, ancientBrick);
        this.setBlock(chunk, x + 13, y + 3, z + 0, ancientBrick);
        this.setBlock(chunk, x + 13, y + 4, z + 0, ancientBrick);
        this.setBlock(chunk, x + 13, y + 5, z + 0, soulStone);
        this.setBlock(chunk, x + 13, y + 6, z + 0, ancientStone);
        this.setBlock(chunk, x + 13, y + 7, z + 0, degradedBrick);
        this.setBlock(chunk, x + 13, y + 0, z + 1, degradedBrick);
        this.setBlock(chunk, x + 13, y + 0, z + 2, degradedBrick);
        this.setBlock(chunk, x + 13, y + 0, z + 3, degradedBrick);
        this.setBlock(chunk, x + 13, y + 0, z + 4, degradedBrick);
        this.setBlock(chunk, x + 13, y + 0, z + 5, degradedBrick);
        this.setBlock(chunk, x + 13, y + 0, z + 6, degradedBrick);
        this.setBlock(chunk, x + 13, y + 0, z + 7, degradedBrick);
        this.setBlock(chunk, x + 13, y + 0, z + 8, degradedBrick);
        this.setBlock(chunk, x + 13, y + 0, z + 9, degradedBrick);
        this.setBlock(chunk, x + 13, y + 0, z + 10, degradedBrick);
        this.setBlock(chunk, x + 13, y + 0, z + 11, degradedBrick);
        this.setBlock(chunk, x + 13, y + 0, z + 12, degradedBrick);
        this.setBlock(chunk, x + 13, y + 0, z + 13, degradedBrick);
        this.setBlock(chunk, x + 13, y + 0, z + 14, degradedBrick);
        this.setBlock(chunk, x + 13, y + 0, z + 15, ancientBrick);
        this.setBlock(chunk, x + 13, y + 1, z + 15, ancientBrick);
        this.setBlock(chunk, x + 13, y + 2, z + 15, ancientBrick);
        this.setBlock(chunk, x + 13, y + 3, z + 15, ancientBrick);
        this.setBlock(chunk, x + 13, y + 4, z + 15, ancientBrick);
        this.setBlock(chunk, x + 13, y + 5, z + 15, soulStone);
        this.setBlock(chunk, x + 13, y + 6, z + 15, ancientStone);
        this.setBlock(chunk, x + 13, y + 7, z + 15, degradedBrick);
        this.setBlock(chunk, x + 14, y + 0, z + 0, ancientBrick);
        this.setBlock(chunk, x + 14, y + 1, z + 0, ancientBrick);
        this.setBlock(chunk, x + 14, y + 2, z + 0, ancientBrick);
        this.setBlock(chunk, x + 14, y + 3, z + 0, ancientBrick);
        this.setBlock(chunk, x + 14, y + 4, z + 0, ancientBrick);
        this.setBlock(chunk, x + 14, y + 5, z + 0, soulStone);
        this.setBlock(chunk, x + 14, y + 6, z + 0, ancientStone);
        this.setBlock(chunk, x + 14, y + 7, z + 0, degradedBrick);
        this.setBlock(chunk, x + 14, y + 0, z + 1, degradedBrick);
        this.setBlock(chunk, x + 14, y + 0, z + 2, degradedBrick);
        this.setBlock(chunk, x + 14, y + 0, z + 3, degradedBrick);
        this.setBlock(chunk, x + 14, y + 0, z + 4, degradedBrick);
        this.setBlock(chunk, x + 14, y + 0, z + 5, degradedBrick);
        this.setBlock(chunk, x + 14, y + 0, z + 6, degradedBrick);
        this.setBlock(chunk, x + 14, y + 0, z + 7, degradedBrick);
        this.setBlock(chunk, x + 14, y + 0, z + 8, degradedBrick);
        this.setBlock(chunk, x + 14, y + 0, z + 9, degradedBrick);
        this.setBlock(chunk, x + 14, y + 0, z + 10, degradedBrick);
        this.setBlock(chunk, x + 14, y + 0, z + 11, degradedBrick);
        this.setBlock(chunk, x + 14, y + 0, z + 12, degradedBrick);
        this.setBlock(chunk, x + 14, y + 0, z + 13, degradedBrick);
        this.setBlock(chunk, x + 14, y + 0, z + 14, degradedBrick);
        this.setBlock(chunk, x + 14, y + 0, z + 15, ancientBrick);
        this.setBlock(chunk, x + 14, y + 1, z + 15, ancientBrick);
        this.setBlock(chunk, x + 14, y + 2, z + 15, ancientBrick);
        this.setBlock(chunk, x + 14, y + 3, z + 15, ancientBrick);
        this.setBlock(chunk, x + 14, y + 4, z + 15, ancientBrick);
        this.setBlock(chunk, x + 14, y + 5, z + 15, soulStone);
        this.setBlock(chunk, x + 14, y + 6, z + 15, ancientStone);
        this.setBlock(chunk, x + 14, y + 7, z + 15, degradedBrick);
        this.setBlock(chunk, x + 15, y + 0, z + 0, ancientBrick);
        this.setBlock(chunk, x + 15, y + 1, z + 0, ancientBrick);
        this.setBlock(chunk, x + 15, y + 2, z + 0, ancientBrick);
        this.setBlock(chunk, x + 15, y + 3, z + 0, ancientBrick);
        this.setBlock(chunk, x + 15, y + 4, z + 0, ancientBrick);
        this.setBlock(chunk, x + 15, y + 5, z + 0, soulStone);
        this.setBlock(chunk, x + 15, y + 6, z + 0, ancientStone);
        this.setBlock(chunk, x + 15, y + 7, z + 0, degradedBrick);
        this.setBlock(chunk, x + 15, y + 0, z + 1, ancientBrick);
        this.setBlock(chunk, x + 15, y + 1, z + 1, ancientBrick);
        this.setBlock(chunk, x + 15, y + 2, z + 1, ancientBrick);
        this.setBlock(chunk, x + 15, y + 3, z + 1, ancientBrick);
        this.setBlock(chunk, x + 15, y + 4, z + 1, ancientBrick);
        this.setBlock(chunk, x + 15, y + 5, z + 1, soulStone);
        this.setBlock(chunk, x + 15, y + 6, z + 1, ancientStone);
        this.setBlock(chunk, x + 15, y + 7, z + 1, degradedBrick);
        this.setBlock(chunk, x + 15, y + 0, z + 2, ancientBrick);
        this.setBlock(chunk, x + 15, y + 1, z + 2, ancientBrick);
        this.setBlock(chunk, x + 15, y + 2, z + 2, ancientBrick);
        this.setBlock(chunk, x + 15, y + 3, z + 2, ancientBrick);
        this.setBlock(chunk, x + 15, y + 4, z + 2, ancientBrick);
        this.setBlock(chunk, x + 15, y + 5, z + 2, soulStone);
        this.setBlock(chunk, x + 15, y + 6, z + 2, ancientStone);
        this.setBlock(chunk, x + 15, y + 7, z + 2, degradedBrick);
        this.setBlock(chunk, x + 15, y + 0, z + 3, ancientBrick);
        this.setBlock(chunk, x + 15, y + 1, z + 3, ancientBrick);
        this.setBlock(chunk, x + 15, y + 2, z + 3, ancientBrick);
        this.setBlock(chunk, x + 15, y + 3, z + 3, ancientBrick);
        this.setBlock(chunk, x + 15, y + 4, z + 3, ancientBrick);
        this.setBlock(chunk, x + 15, y + 5, z + 3, soulStone);
        this.setBlock(chunk, x + 15, y + 6, z + 3, ancientStone);
        this.setBlock(chunk, x + 15, y + 7, z + 3, degradedBrick);
        this.setBlock(chunk, x + 15, y + 0, z + 4, ancientBrick);
        this.setBlock(chunk, x + 15, y + 1, z + 4, ancientBrick);
        this.setBlock(chunk, x + 15, y + 2, z + 4, ancientBrick);
        this.setBlock(chunk, x + 15, y + 3, z + 4, ancientBrick);
        this.setBlock(chunk, x + 15, y + 4, z + 4, ancientBrick);
        this.setBlock(chunk, x + 15, y + 5, z + 4, soulStone);
        this.setBlock(chunk, x + 15, y + 6, z + 4, ancientStone);
        this.setBlock(chunk, x + 15, y + 7, z + 4, degradedBrick);
        this.setBlock(chunk, x + 15, y + 0, z + 5, ancientBrick);
        this.setBlock(chunk, x + 15, y + 1, z + 5, ancientBrick);
        this.setBlock(chunk, x + 15, y + 2, z + 5, ancientBrick);
        this.setBlock(chunk, x + 15, y + 3, z + 5, ancientBrick);
        this.setBlock(chunk, x + 15, y + 4, z + 5, ancientBrick);
        this.setBlock(chunk, x + 15, y + 5, z + 5, soulStone);
        this.setBlock(chunk, x + 15, y + 6, z + 5, ancientStone);
        this.setBlock(chunk, x + 15, y + 7, z + 5, degradedBrick);
        this.setBlock(chunk, x + 15, y + 0, z + 6, ancientBrick);
        this.setBlock(chunk, x + 15, y + 1, z + 6, ancientBrick);
        this.setBlock(chunk, x + 15, y + 2, z + 6, ancientBrick);
        this.setBlock(chunk, x + 15, y + 3, z + 6, ancientBrick);
        this.setBlock(chunk, x + 15, y + 4, z + 6, ancientBrick);
        this.setBlock(chunk, x + 15, y + 5, z + 6, soulStone);
        this.setBlock(chunk, x + 15, y + 6, z + 6, ancientStone);
        this.setBlock(chunk, x + 15, y + 7, z + 6, degradedBrick);
        this.setBlock(chunk, x + 15, y + 0, z + 7, ancientBrick);
        this.setBlock(chunk, x + 15, y + 3, z + 7, ancientBrick);
        this.setBlock(chunk, x + 15, y + 4, z + 7, ancientBrick);
        this.setBlock(chunk, x + 15, y + 5, z + 7, soulStone);
        this.setBlock(chunk, x + 15, y + 6, z + 7, ancientStone);
        this.setBlock(chunk, x + 15, y + 7, z + 7, degradedBrick);
        this.setBlock(chunk, x + 15, y + 0, z + 8, ancientBrick);
        this.setBlock(chunk, x + 15, y + 3, z + 8, ancientBrick);
        this.setBlock(chunk, x + 15, y + 4, z + 8, ancientBrick);
        this.setBlock(chunk, x + 15, y + 5, z + 8, soulStone);
        this.setBlock(chunk, x + 15, y + 6, z + 8, ancientStone);
        this.setBlock(chunk, x + 15, y + 7, z + 8, degradedBrick);
        this.setBlock(chunk, x + 15, y + 0, z + 9, ancientBrick);
        this.setBlock(chunk, x + 15, y + 1, z + 9, ancientBrick);
        this.setBlock(chunk, x + 15, y + 2, z + 9, ancientBrick);
        this.setBlock(chunk, x + 15, y + 3, z + 9, ancientBrick);
        this.setBlock(chunk, x + 15, y + 4, z + 9, ancientBrick);
        this.setBlock(chunk, x + 15, y + 5, z + 9, soulStone);
        this.setBlock(chunk, x + 15, y + 6, z + 9, ancientStone);
        this.setBlock(chunk, x + 15, y + 7, z + 9, degradedBrick);
        this.setBlock(chunk, x + 15, y + 0, z + 10, ancientBrick);
        this.setBlock(chunk, x + 15, y + 1, z + 10, ancientBrick);
        this.setBlock(chunk, x + 15, y + 2, z + 10, ancientBrick);
        this.setBlock(chunk, x + 15, y + 3, z + 10, ancientBrick);
        this.setBlock(chunk, x + 15, y + 4, z + 10, ancientBrick);
        this.setBlock(chunk, x + 15, y + 5, z + 10, soulStone);
        this.setBlock(chunk, x + 15, y + 6, z + 10, ancientStone);
        this.setBlock(chunk, x + 15, y + 7, z + 10, degradedBrick);
        this.setBlock(chunk, x + 15, y + 0, z + 11, ancientBrick);
        this.setBlock(chunk, x + 15, y + 1, z + 11, ancientBrick);
        this.setBlock(chunk, x + 15, y + 2, z + 11, ancientBrick);
        this.setBlock(chunk, x + 15, y + 3, z + 11, ancientBrick);
        this.setBlock(chunk, x + 15, y + 4, z + 11, ancientBrick);
        this.setBlock(chunk, x + 15, y + 5, z + 11, soulStone);
        this.setBlock(chunk, x + 15, y + 6, z + 11, ancientStone);
        this.setBlock(chunk, x + 15, y + 7, z + 11, degradedBrick);
        this.setBlock(chunk, x + 15, y + 0, z + 12, ancientBrick);
        this.setBlock(chunk, x + 15, y + 1, z + 12, ancientBrick);
        this.setBlock(chunk, x + 15, y + 2, z + 12, ancientBrick);
        this.setBlock(chunk, x + 15, y + 3, z + 12, ancientBrick);
        this.setBlock(chunk, x + 15, y + 4, z + 12, ancientBrick);
        this.setBlock(chunk, x + 15, y + 5, z + 12, soulStone);
        this.setBlock(chunk, x + 15, y + 6, z + 12, ancientStone);
        this.setBlock(chunk, x + 15, y + 7, z + 12, degradedBrick);
        this.setBlock(chunk, x + 15, y + 0, z + 13, ancientBrick);
        this.setBlock(chunk, x + 15, y + 1, z + 13, ancientBrick);
        this.setBlock(chunk, x + 15, y + 2, z + 13, ancientBrick);
        this.setBlock(chunk, x + 15, y + 3, z + 13, ancientBrick);
        this.setBlock(chunk, x + 15, y + 4, z + 13, ancientBrick);
        this.setBlock(chunk, x + 15, y + 5, z + 13, soulStone);
        this.setBlock(chunk, x + 15, y + 6, z + 13, ancientStone);
        this.setBlock(chunk, x + 15, y + 7, z + 13, degradedBrick);
        this.setBlock(chunk, x + 15, y + 0, z + 14, ancientBrick);
        this.setBlock(chunk, x + 15, y + 1, z + 14, ancientBrick);
        this.setBlock(chunk, x + 15, y + 2, z + 14, ancientBrick);
        this.setBlock(chunk, x + 15, y + 3, z + 14, ancientBrick);
        this.setBlock(chunk, x + 15, y + 4, z + 14, ancientBrick);
        this.setBlock(chunk, x + 15, y + 5, z + 14, soulStone);
        this.setBlock(chunk, x + 15, y + 6, z + 14, ancientStone);
        this.setBlock(chunk, x + 15, y + 7, z + 14, degradedBrick);
        this.setBlock(chunk, x + 15, y + 0, z + 15, ancientBrick);
        this.setBlock(chunk, x + 15, y + 1, z + 15, ancientBrick);
        this.setBlock(chunk, x + 15, y + 2, z + 15, ancientBrick);
        this.setBlock(chunk, x + 15, y + 3, z + 15, ancientBrick);
        this.setBlock(chunk, x + 15, y + 4, z + 15, ancientBrick);
        this.setBlock(chunk, x + 15, y + 5, z + 15, soulStone);
        this.setBlock(chunk, x + 15, y + 6, z + 15, ancientStone);
        this.setBlock(chunk, x + 15, y + 7, z + 15, degradedBrick);
        return true;
    }
}