package divinerpg.dimensions.arcana.components;

import java.util.Random;

import divinerpg.dimensions.arcana.ArcanaChunkPrimer;
import divinerpg.registry.BlockRegistry;
import net.minecraft.block.Block;

public class DungeonComponent00 extends DungeonComponentBase {
    @Override
    public boolean generate(ArcanaChunkPrimer chunk, Random rand, int x, int y, int z) {
        Block heatTraps = BlockRegistry.heatTrap;
        Block dungeonBricks = BlockRegistry.degradedBrick;
        Block ancientbricks = BlockRegistry.ancientBrick;
        Block soulStone = BlockRegistry.soulStone;
        Block ancientStone = BlockRegistry.ancientStone;

        this.setBlock(chunk, x + 0, y + 0, z + 0, heatTraps);
        this.setBlock(chunk, x + 0, y + 0, z + 1, heatTraps);
        this.setBlock(chunk, x + 0, y + 0, z + 2, dungeonBricks);
        this.setBlock(chunk, x + 0, y + 0, z + 3, dungeonBricks);
        this.setBlock(chunk, x + 0, y + 0, z + 4, ancientbricks);
        this.setBlock(chunk, x + 0, y + 0, z + 5, ancientbricks);
        this.setBlock(chunk, x + 0, y + 0, z + 6, ancientbricks);
        this.setBlock(chunk, x + 0, y + 0, z + 7, ancientbricks);
        this.setBlock(chunk, x + 0, y + 0, z + 8, ancientbricks);
        this.setBlock(chunk, x + 0, y + 0, z + 9, ancientbricks);
        this.setBlock(chunk, x + 0, y + 0, z + 10, ancientbricks);
        this.setBlock(chunk, x + 0, y + 0, z + 11, ancientbricks);
        this.setBlock(chunk, x + 0, y + 0, z + 12, dungeonBricks);
        this.setBlock(chunk, x + 0, y + 0, z + 13, dungeonBricks);
        this.setBlock(chunk, x + 0, y + 0, z + 14, heatTraps);
        this.setBlock(chunk, x + 0, y + 0, z + 15, heatTraps);
        this.setBlock(chunk, x + 0, y + 1, z + 0, heatTraps);
        this.setBlock(chunk, x + 0, y + 1, z + 1, heatTraps);
        this.setBlock(chunk, x + 0, y + 1, z + 2, soulStone);
        this.setBlock(chunk, x + 0, y + 1, z + 3, soulStone);
        this.setBlock(chunk, x + 0, y + 1, z + 4, soulStone);
        this.setBlock(chunk, x + 0, y + 1, z + 5, soulStone);
        this.setBlock(chunk, x + 0, y + 1, z + 6, ancientStone);
        this.setBlock(chunk, x + 0, y + 1, z + 9, ancientStone);
        this.setBlock(chunk, x + 0, y + 1, z + 10, soulStone);
        this.setBlock(chunk, x + 0, y + 1, z + 11, soulStone);
        this.setBlock(chunk, x + 0, y + 1, z + 12, soulStone);
        this.setBlock(chunk, x + 0, y + 1, z + 13, soulStone);
        this.setBlock(chunk, x + 0, y + 1, z + 14, heatTraps);
        this.setBlock(chunk, x + 0, y + 1, z + 15, heatTraps);
        this.setBlock(chunk, x + 0, y + 2, z + 0, heatTraps);
        this.setBlock(chunk, x + 0, y + 2, z + 1, heatTraps);
        this.setBlock(chunk, x + 0, y + 2, z + 2, soulStone);
        this.setBlock(chunk, x + 0, y + 2, z + 3, soulStone);
        this.setBlock(chunk, x + 0, y + 2, z + 4, soulStone);
        this.setBlock(chunk, x + 0, y + 2, z + 5, soulStone);
        this.setBlock(chunk, x + 0, y + 2, z + 6, BlockRegistry.dungeonLamp);
        this.setBlock(chunk, x + 0, y + 2, z + 9, BlockRegistry.dungeonLamp);
        this.setBlock(chunk, x + 0, y + 2, z + 10, soulStone);
        this.setBlock(chunk, x + 0, y + 2, z + 11, soulStone);
        this.setBlock(chunk, x + 0, y + 2, z + 12, soulStone);
        this.setBlock(chunk, x + 0, y + 2, z + 13, soulStone);
        this.setBlock(chunk, x + 0, y + 2, z + 14, heatTraps);
        this.setBlock(chunk, x + 0, y + 2, z + 15, heatTraps);
        this.setBlock(chunk, x + 0, y + 3, z + 0, heatTraps);
        this.setBlock(chunk, x + 0, y + 3, z + 1, heatTraps);
        this.setBlock(chunk, x + 0, y + 3, z + 2, soulStone);
        this.setBlock(chunk, x + 0, y + 3, z + 3, soulStone);
        this.setBlock(chunk, x + 0, y + 3, z + 4, soulStone);
        this.setBlock(chunk, x + 0, y + 3, z + 5, soulStone);
        this.setBlock(chunk, x + 0, y + 3, z + 6, ancientStone);
        this.setBlock(chunk, x + 0, y + 3, z + 7, BlockRegistry.arcaniumPower);
        this.setBlock(chunk, x + 0, y + 3, z + 8, BlockRegistry.arcaniumPower);
        this.setBlock(chunk, x + 0, y + 3, z + 9, ancientStone);
        this.setBlock(chunk, x + 0, y + 3, z + 10, soulStone);
        this.setBlock(chunk, x + 0, y + 3, z + 11, soulStone);
        this.setBlock(chunk, x + 0, y + 3, z + 12, soulStone);
        this.setBlock(chunk, x + 0, y + 3, z + 13, soulStone);
        this.setBlock(chunk, x + 0, y + 3, z + 14, heatTraps);
        this.setBlock(chunk, x + 0, y + 3, z + 15, heatTraps);
        this.setBlock(chunk, x + 0, y + 4, z + 0, heatTraps);
        this.setBlock(chunk, x + 0, y + 4, z + 1, heatTraps);
        this.setBlock(chunk, x + 0, y + 4, z + 2, soulStone);
        this.setBlock(chunk, x + 0, y + 4, z + 3, soulStone);
        this.setBlock(chunk, x + 0, y + 4, z + 4, soulStone);
        this.setBlock(chunk, x + 0, y + 4, z + 5, soulStone);
        this.setBlock(chunk, x + 0, y + 4, z + 6, soulStone);
        this.setBlock(chunk, x + 0, y + 4, z + 7, soulStone);
        this.setBlock(chunk, x + 0, y + 4, z + 8, soulStone);
        this.setBlock(chunk, x + 0, y + 4, z + 9, soulStone);
        this.setBlock(chunk, x + 0, y + 4, z + 10, soulStone);
        this.setBlock(chunk, x + 0, y + 4, z + 11, soulStone);
        this.setBlock(chunk, x + 0, y + 4, z + 12, soulStone);
        this.setBlock(chunk, x + 0, y + 4, z + 13, soulStone);
        this.setBlock(chunk, x + 0, y + 4, z + 14, heatTraps);
        this.setBlock(chunk, x + 0, y + 4, z + 15, heatTraps);
        this.setBlock(chunk, x + 0, y + 5, z + 0, heatTraps);
        this.setBlock(chunk, x + 0, y + 5, z + 1, heatTraps);
        this.setBlock(chunk, x + 0, y + 5, z + 2, soulStone);
        this.setBlock(chunk, x + 0, y + 5, z + 3, soulStone);
        this.setBlock(chunk, x + 0, y + 5, z + 4, soulStone);
        this.setBlock(chunk, x + 0, y + 5, z + 5, soulStone);
        this.setBlock(chunk, x + 0, y + 5, z + 6, soulStone);
        this.setBlock(chunk, x + 0, y + 5, z + 7, soulStone);
        this.setBlock(chunk, x + 0, y + 5, z + 8, soulStone);
        this.setBlock(chunk, x + 0, y + 5, z + 9, soulStone);
        this.setBlock(chunk, x + 0, y + 5, z + 10, soulStone);
        this.setBlock(chunk, x + 0, y + 5, z + 11, soulStone);
        this.setBlock(chunk, x + 0, y + 5, z + 12, soulStone);
        this.setBlock(chunk, x + 0, y + 5, z + 13, soulStone);
        this.setBlock(chunk, x + 0, y + 5, z + 14, heatTraps);
        this.setBlock(chunk, x + 0, y + 5, z + 15, heatTraps);
        this.setBlock(chunk, x + 0, y + 6, z + 0, heatTraps);
        this.setBlock(chunk, x + 0, y + 6, z + 1, heatTraps);
        this.setBlock(chunk, x + 0, y + 6, z + 2, ancientStone);
        this.setBlock(chunk, x + 0, y + 6, z + 3, ancientStone);
        this.setBlock(chunk, x + 0, y + 6, z + 4, ancientStone);
        this.setBlock(chunk, x + 0, y + 6, z + 5, ancientStone);
        this.setBlock(chunk, x + 0, y + 6, z + 6, ancientStone);
        this.setBlock(chunk, x + 0, y + 6, z + 7, ancientStone);
        this.setBlock(chunk, x + 0, y + 6, z + 8, ancientStone);
        this.setBlock(chunk, x + 0, y + 6, z + 9, ancientStone);
        this.setBlock(chunk, x + 0, y + 6, z + 10, ancientStone);
        this.setBlock(chunk, x + 0, y + 6, z + 11, ancientStone);
        this.setBlock(chunk, x + 0, y + 6, z + 12, ancientStone);
        this.setBlock(chunk, x + 0, y + 6, z + 13, ancientStone);
        this.setBlock(chunk, x + 0, y + 6, z + 14, heatTraps);
        this.setBlock(chunk, x + 0, y + 6, z + 15, heatTraps);
        this.setBlock(chunk, x + 0, y + 7, z + 0, heatTraps);
        this.setBlock(chunk, x + 0, y + 7, z + 1, heatTraps);
        this.setBlock(chunk, x + 0, y + 7, z + 2, ancientStone);
        this.setBlock(chunk, x + 0, y + 7, z + 3, ancientStone);
        this.setBlock(chunk, x + 0, y + 7, z + 4, ancientStone);
        this.setBlock(chunk, x + 0, y + 7, z + 5, ancientStone);
        this.setBlock(chunk, x + 0, y + 7, z + 6, ancientStone);
        this.setBlock(chunk, x + 0, y + 7, z + 7, ancientStone);
        this.setBlock(chunk, x + 0, y + 7, z + 8, ancientStone);
        this.setBlock(chunk, x + 0, y + 7, z + 9, ancientStone);
        this.setBlock(chunk, x + 0, y + 7, z + 10, ancientStone);
        this.setBlock(chunk, x + 0, y + 7, z + 11, ancientStone);
        this.setBlock(chunk, x + 0, y + 7, z + 12, ancientStone);
        this.setBlock(chunk, x + 0, y + 7, z + 13, ancientStone);
        this.setBlock(chunk, x + 0, y + 7, z + 14, heatTraps);
        this.setBlock(chunk, x + 0, y + 7, z + 15, heatTraps);
        this.setBlock(chunk, x + 1, y + 0, z + 0, heatTraps);
        this.setBlock(chunk, x + 1, y + 0, z + 1, heatTraps);
        this.setBlock(chunk, x + 1, y + 0, z + 2, heatTraps);
        this.setBlock(chunk, x + 1, y + 0, z + 3, dungeonBricks);
        this.setBlock(chunk, x + 1, y + 0, z + 4, dungeonBricks);
        this.setBlock(chunk, x + 1, y + 0, z + 5, ancientbricks);
        this.setBlock(chunk, x + 1, y + 0, z + 6, ancientbricks);
        this.setBlock(chunk, x + 1, y + 0, z + 7, ancientbricks);
        this.setBlock(chunk, x + 1, y + 0, z + 8, ancientbricks);
        this.setBlock(chunk, x + 1, y + 0, z + 9, ancientbricks);
        this.setBlock(chunk, x + 1, y + 0, z + 10, ancientbricks);
        this.setBlock(chunk, x + 1, y + 0, z + 11, dungeonBricks);
        this.setBlock(chunk, x + 1, y + 0, z + 12, dungeonBricks);
        this.setBlock(chunk, x + 1, y + 0, z + 13, heatTraps);
        this.setBlock(chunk, x + 1, y + 0, z + 14, heatTraps);
        this.setBlock(chunk, x + 1, y + 0, z + 15, heatTraps);
        this.setBlock(chunk, x + 1, y + 1, z + 0, heatTraps);
        this.setBlock(chunk, x + 1, y + 1, z + 1, heatTraps);
        this.setBlock(chunk, x + 1, y + 1, z + 14, heatTraps);
        this.setBlock(chunk, x + 1, y + 1, z + 15, heatTraps);
        this.setBlock(chunk, x + 1, y + 2, z + 0, heatTraps);
        this.setBlock(chunk, x + 1, y + 2, z + 1, heatTraps);
        this.setBlock(chunk, x + 1, y + 2, z + 14, heatTraps);
        this.setBlock(chunk, x + 1, y + 2, z + 15, heatTraps);
        this.setBlock(chunk, x + 1, y + 3, z + 0, heatTraps);
        this.setBlock(chunk, x + 1, y + 3, z + 1, heatTraps);
        this.setBlock(chunk, x + 1, y + 3, z + 14, heatTraps);
        this.setBlock(chunk, x + 1, y + 3, z + 15, heatTraps);
        this.setBlock(chunk, x + 1, y + 4, z + 0, heatTraps);
        this.setBlock(chunk, x + 1, y + 4, z + 1, heatTraps);
        this.setBlock(chunk, x + 1, y + 4, z + 14, heatTraps);
        this.setBlock(chunk, x + 1, y + 4, z + 15, heatTraps);
        this.setBlock(chunk, x + 1, y + 5, z + 0, heatTraps);
        this.setBlock(chunk, x + 1, y + 5, z + 1, heatTraps);
        this.setBlock(chunk, x + 1, y + 5, z + 14, heatTraps);
        this.setBlock(chunk, x + 1, y + 5, z + 15, heatTraps);
        this.setBlock(chunk, x + 1, y + 6, z + 0, heatTraps);
        this.setBlock(chunk, x + 1, y + 6, z + 1, heatTraps);
        this.setBlock(chunk, x + 1, y + 6, z + 14, heatTraps);
        this.setBlock(chunk, x + 1, y + 6, z + 15, heatTraps);
        this.setBlock(chunk, x + 1, y + 7, z + 0, heatTraps);
        this.setBlock(chunk, x + 1, y + 7, z + 1, heatTraps);
        this.setBlock(chunk, x + 1, y + 7, z + 2, heatTraps);
        this.setBlock(chunk, x + 1, y + 7, z + 13, heatTraps);
        this.setBlock(chunk, x + 1, y + 7, z + 14, heatTraps);
        this.setBlock(chunk, x + 1, y + 7, z + 15, heatTraps);
        this.setBlock(chunk, x + 2, y + 0, z + 0, dungeonBricks);
        this.setBlock(chunk, x + 2, y + 0, z + 1, heatTraps);
        this.setBlock(chunk, x + 2, y + 0, z + 2, heatTraps);
        this.setBlock(chunk, x + 2, y + 0, z + 3, heatTraps);
        this.setBlock(chunk, x + 2, y + 0, z + 4, dungeonBricks);
        this.setBlock(chunk, x + 2, y + 0, z + 5, dungeonBricks);
        this.setBlock(chunk, x + 2, y + 0, z + 6, ancientbricks);
        this.setBlock(chunk, x + 2, y + 0, z + 7, ancientbricks);
        this.setBlock(chunk, x + 2, y + 0, z + 8, ancientbricks);
        this.setBlock(chunk, x + 2, y + 0, z + 9, ancientbricks);
        this.setBlock(chunk, x + 2, y + 0, z + 10, dungeonBricks);
        this.setBlock(chunk, x + 2, y + 0, z + 11, dungeonBricks);
        this.setBlock(chunk, x + 2, y + 0, z + 12, heatTraps);
        this.setBlock(chunk, x + 2, y + 0, z + 13, heatTraps);
        this.setBlock(chunk, x + 2, y + 0, z + 14, heatTraps);
        this.setBlock(chunk, x + 2, y + 0, z + 15, dungeonBricks);
        this.setBlock(chunk, x + 2, y + 1, z + 0, soulStone);
        this.setBlock(chunk, x + 2, y + 1, z + 7, heatTraps);
        this.setBlock(chunk, x + 2, y + 1, z + 8, heatTraps);
        this.setBlock(chunk, x + 2, y + 1, z + 15, soulStone);
        this.setBlock(chunk, x + 2, y + 2, z + 0, soulStone);
        this.setBlock(chunk, x + 2, y + 2, z + 15, soulStone);
        this.setBlock(chunk, x + 2, y + 3, z + 0, soulStone);
        this.setBlock(chunk, x + 2, y + 3, z + 15, soulStone);
        this.setBlock(chunk, x + 2, y + 4, z + 0, soulStone);
        this.setBlock(chunk, x + 2, y + 4, z + 15, soulStone);
        this.setBlock(chunk, x + 2, y + 5, z + 0, soulStone);
        this.setBlock(chunk, x + 2, y + 5, z + 15, soulStone);
        this.setBlock(chunk, x + 2, y + 6, z + 0, ancientStone);
        this.setBlock(chunk, x + 2, y + 6, z + 15, ancientStone);
        this.setBlock(chunk, x + 2, y + 7, z + 0, ancientStone);
        this.setBlock(chunk, x + 2, y + 7, z + 1, heatTraps);
        this.setBlock(chunk, x + 2, y + 7, z + 2, heatTraps);
        this.setBlock(chunk, x + 2, y + 7, z + 3, heatTraps);
        this.setBlock(chunk, x + 2, y + 7, z + 12, heatTraps);
        this.setBlock(chunk, x + 2, y + 7, z + 13, heatTraps);
        this.setBlock(chunk, x + 2, y + 7, z + 14, heatTraps);
        this.setBlock(chunk, x + 2, y + 7, z + 15, ancientStone);
        this.setBlock(chunk, x + 3, y + 0, z + 0, dungeonBricks);
        this.setBlock(chunk, x + 3, y + 0, z + 1, dungeonBricks);
        this.setBlock(chunk, x + 3, y + 0, z + 2, heatTraps);
        this.setBlock(chunk, x + 3, y + 0, z + 3, heatTraps);
        this.setBlock(chunk, x + 3, y + 0, z + 4, heatTraps);
        this.setBlock(chunk, x + 3, y + 0, z + 5, dungeonBricks);
        this.setBlock(chunk, x + 3, y + 0, z + 6, dungeonBricks);
        this.setBlock(chunk, x + 3, y + 0, z + 7, ancientbricks);
        this.setBlock(chunk, x + 3, y + 0, z + 8, ancientbricks);
        this.setBlock(chunk, x + 3, y + 0, z + 9, dungeonBricks);
        this.setBlock(chunk, x + 3, y + 0, z + 10, dungeonBricks);
        this.setBlock(chunk, x + 3, y + 0, z + 11, heatTraps);
        this.setBlock(chunk, x + 3, y + 0, z + 12, heatTraps);
        this.setBlock(chunk, x + 3, y + 0, z + 13, heatTraps);
        this.setBlock(chunk, x + 3, y + 0, z + 14, dungeonBricks);
        this.setBlock(chunk, x + 3, y + 0, z + 15, dungeonBricks);
        this.setBlock(chunk, x + 3, y + 1, z + 0, soulStone);
        this.setBlock(chunk, x + 3, y + 1, z + 15, soulStone);
        this.setBlock(chunk, x + 3, y + 2, z + 0, soulStone);
        this.setBlock(chunk, x + 3, y + 2, z + 15, soulStone);
        this.setBlock(chunk, x + 3, y + 3, z + 0, soulStone);
        this.setBlock(chunk, x + 3, y + 3, z + 15, soulStone);
        this.setBlock(chunk, x + 3, y + 4, z + 0, soulStone);
        this.setBlock(chunk, x + 3, y + 4, z + 15, soulStone);
        this.setBlock(chunk, x + 3, y + 5, z + 0, soulStone);
        this.setBlock(chunk, x + 3, y + 5, z + 15, soulStone);
        this.setBlock(chunk, x + 3, y + 6, z + 0, ancientStone);
        this.setBlock(chunk, x + 3, y + 6, z + 15, ancientStone);
        this.setBlock(chunk, x + 3, y + 7, z + 0, ancientStone);
        this.setBlock(chunk, x + 3, y + 7, z + 2, heatTraps);
        this.setBlock(chunk, x + 3, y + 7, z + 3, heatTraps);
        this.setBlock(chunk, x + 3, y + 7, z + 4, heatTraps);
        this.setBlock(chunk, x + 3, y + 7, z + 11, heatTraps);
        this.setBlock(chunk, x + 3, y + 7, z + 12, heatTraps);
        this.setBlock(chunk, x + 3, y + 7, z + 13, heatTraps);
        this.setBlock(chunk, x + 3, y + 7, z + 15, ancientStone);
        this.setBlock(chunk, x + 4, y + 0, z + 0, ancientbricks);
        this.setBlock(chunk, x + 4, y + 0, z + 1, dungeonBricks);
        this.setBlock(chunk, x + 4, y + 0, z + 2, dungeonBricks);
        this.setBlock(chunk, x + 4, y + 0, z + 3, heatTraps);
        this.setBlock(chunk, x + 4, y + 0, z + 4, heatTraps);
        this.setBlock(chunk, x + 4, y + 0, z + 5, heatTraps);
        this.setBlock(chunk, x + 4, y + 0, z + 6, dungeonBricks);
        this.setBlock(chunk, x + 4, y + 0, z + 7, dungeonBricks);
        this.setBlock(chunk, x + 4, y + 0, z + 8, dungeonBricks);
        this.setBlock(chunk, x + 4, y + 0, z + 9, dungeonBricks);
        this.setBlock(chunk, x + 4, y + 0, z + 10, heatTraps);
        this.setBlock(chunk, x + 4, y + 0, z + 11, heatTraps);
        this.setBlock(chunk, x + 4, y + 0, z + 12, heatTraps);
        this.setBlock(chunk, x + 4, y + 0, z + 13, dungeonBricks);
        this.setBlock(chunk, x + 4, y + 0, z + 14, dungeonBricks);
        this.setBlock(chunk, x + 4, y + 0, z + 15, ancientbricks);
        this.setBlock(chunk, x + 4, y + 1, z + 0, soulStone);
        this.setBlock(chunk, x + 4, y + 1, z + 15, soulStone);
        this.setBlock(chunk, x + 4, y + 2, z + 0, soulStone);
        this.setBlock(chunk, x + 4, y + 2, z + 15, soulStone);
        this.setBlock(chunk, x + 4, y + 3, z + 0, soulStone);
        this.setBlock(chunk, x + 4, y + 3, z + 15, soulStone);
        this.setBlock(chunk, x + 4, y + 4, z + 0, soulStone);
        this.setBlock(chunk, x + 4, y + 4, z + 15, soulStone);
        this.setBlock(chunk, x + 4, y + 5, z + 0, soulStone);
        this.setBlock(chunk, x + 4, y + 5, z + 15, soulStone);
        this.setBlock(chunk, x + 4, y + 6, z + 0, ancientStone);
        this.setBlock(chunk, x + 4, y + 6, z + 15, ancientStone);
        this.setBlock(chunk, x + 4, y + 7, z + 0, ancientStone);
        this.setBlock(chunk, x + 4, y + 7, z + 3, heatTraps);
        this.setBlock(chunk, x + 4, y + 7, z + 4, heatTraps);
        this.setBlock(chunk, x + 4, y + 7, z + 5, heatTraps);
        this.setBlock(chunk, x + 4, y + 7, z + 10, heatTraps);
        this.setBlock(chunk, x + 4, y + 7, z + 11, heatTraps);
        this.setBlock(chunk, x + 4, y + 7, z + 12, heatTraps);
        this.setBlock(chunk, x + 4, y + 7, z + 15, ancientStone);
        this.setBlock(chunk, x + 5, y + 0, z + 0, ancientbricks);
        this.setBlock(chunk, x + 5, y + 0, z + 1, ancientbricks);
        this.setBlock(chunk, x + 5, y + 0, z + 2, dungeonBricks);
        this.setBlock(chunk, x + 5, y + 0, z + 3, dungeonBricks);
        this.setBlock(chunk, x + 5, y + 0, z + 4, heatTraps);
        this.setBlock(chunk, x + 5, y + 0, z + 5, heatTraps);
        this.setBlock(chunk, x + 5, y + 0, z + 6, heatTraps);
        this.setBlock(chunk, x + 5, y + 0, z + 7, dungeonBricks);
        this.setBlock(chunk, x + 5, y + 0, z + 8, dungeonBricks);
        this.setBlock(chunk, x + 5, y + 0, z + 9, heatTraps);
        this.setBlock(chunk, x + 5, y + 0, z + 10, heatTraps);
        this.setBlock(chunk, x + 5, y + 0, z + 11, heatTraps);
        this.setBlock(chunk, x + 5, y + 0, z + 12, dungeonBricks);
        this.setBlock(chunk, x + 5, y + 0, z + 13, dungeonBricks);
        this.setBlock(chunk, x + 5, y + 0, z + 14, ancientbricks);
        this.setBlock(chunk, x + 5, y + 0, z + 15, ancientbricks);
        this.setBlock(chunk, x + 5, y + 1, z + 0, soulStone);
        this.setBlock(chunk, x + 5, y + 1, z + 15, soulStone);
        this.setBlock(chunk, x + 5, y + 2, z + 0, soulStone);
        this.setBlock(chunk, x + 5, y + 2, z + 15, soulStone);
        this.setBlock(chunk, x + 5, y + 3, z + 0, soulStone);
        this.setBlock(chunk, x + 5, y + 3, z + 15, soulStone);
        this.setBlock(chunk, x + 5, y + 4, z + 0, soulStone);
        this.setBlock(chunk, x + 5, y + 4, z + 15, soulStone);
        this.setBlock(chunk, x + 5, y + 5, z + 0, soulStone);
        this.setBlock(chunk, x + 5, y + 5, z + 15, soulStone);
        this.setBlock(chunk, x + 5, y + 6, z + 0, ancientStone);
        this.setBlock(chunk, x + 5, y + 6, z + 15, ancientStone);
        this.setBlock(chunk, x + 5, y + 7, z + 0, ancientStone);
        this.setBlock(chunk, x + 5, y + 7, z + 4, heatTraps);
        this.setBlock(chunk, x + 5, y + 7, z + 5, heatTraps);
        this.setBlock(chunk, x + 5, y + 7, z + 6, heatTraps);
        this.setBlock(chunk, x + 5, y + 7, z + 9, heatTraps);
        this.setBlock(chunk, x + 5, y + 7, z + 10, heatTraps);
        this.setBlock(chunk, x + 5, y + 7, z + 11, heatTraps);
        this.setBlock(chunk, x + 5, y + 7, z + 15, ancientStone);
        this.setBlock(chunk, x + 6, y + 0, z + 0, ancientbricks);
        this.setBlock(chunk, x + 6, y + 0, z + 1, ancientbricks);
        this.setBlock(chunk, x + 6, y + 0, z + 2, ancientbricks);
        this.setBlock(chunk, x + 6, y + 0, z + 3, dungeonBricks);
        this.setBlock(chunk, x + 6, y + 0, z + 4, dungeonBricks);
        this.setBlock(chunk, x + 6, y + 0, z + 5, heatTraps);
        this.setBlock(chunk, x + 6, y + 0, z + 6, heatTraps);
        this.setBlock(chunk, x + 6, y + 0, z + 7, heatTraps);
        this.setBlock(chunk, x + 6, y + 0, z + 8, heatTraps);
        this.setBlock(chunk, x + 6, y + 0, z + 9, heatTraps);
        this.setBlock(chunk, x + 6, y + 0, z + 10, heatTraps);
        this.setBlock(chunk, x + 6, y + 0, z + 11, dungeonBricks);
        this.setBlock(chunk, x + 6, y + 0, z + 12, dungeonBricks);
        this.setBlock(chunk, x + 6, y + 0, z + 13, ancientbricks);
        this.setBlock(chunk, x + 6, y + 0, z + 14, ancientbricks);
        this.setBlock(chunk, x + 6, y + 0, z + 15, ancientbricks);
        this.setBlock(chunk, x + 6, y + 1, z + 0, ancientStone);
        this.setBlock(chunk, x + 6, y + 1, z + 7, heatTraps);
        this.setBlock(chunk, x + 6, y + 1, z + 8, heatTraps);
        this.setBlock(chunk, x + 6, y + 1, z + 15, ancientStone);
        this.setBlock(chunk, x + 6, y + 2, z + 0, BlockRegistry.dungeonLamp);
        this.setBlock(chunk, x + 6, y + 2, z + 7, heatTraps);
        this.setBlock(chunk, x + 6, y + 2, z + 8, heatTraps);
        this.setBlock(chunk, x + 6, y + 2, z + 15, BlockRegistry.dungeonLamp);
        this.setBlock(chunk, x + 6, y + 3, z + 0, ancientStone);
        this.setBlock(chunk, x + 6, y + 3, z + 7, heatTraps);
        this.setBlock(chunk, x + 6, y + 3, z + 8, heatTraps);
        this.setBlock(chunk, x + 6, y + 3, z + 15, ancientStone);
        this.setBlock(chunk, x + 6, y + 4, z + 0, soulStone);
        this.setBlock(chunk, x + 6, y + 4, z + 7, heatTraps);
        this.setBlock(chunk, x + 6, y + 4, z + 8, heatTraps);
        this.setBlock(chunk, x + 6, y + 4, z + 15, soulStone);
        this.setBlock(chunk, x + 6, y + 5, z + 0, soulStone);
        this.setBlock(chunk, x + 6, y + 5, z + 7, heatTraps);
        this.setBlock(chunk, x + 6, y + 5, z + 8, heatTraps);
        this.setBlock(chunk, x + 6, y + 5, z + 15, soulStone);
        this.setBlock(chunk, x + 6, y + 6, z + 0, ancientStone);
        this.setBlock(chunk, x + 6, y + 6, z + 7, heatTraps);
        this.setBlock(chunk, x + 6, y + 6, z + 8, heatTraps);
        this.setBlock(chunk, x + 6, y + 6, z + 15, ancientStone);
        this.setBlock(chunk, x + 6, y + 7, z + 0, ancientStone);
        this.setBlock(chunk, x + 6, y + 7, z + 5, heatTraps);
        this.setBlock(chunk, x + 6, y + 7, z + 6, heatTraps);
        this.setBlock(chunk, x + 6, y + 7, z + 7, heatTraps);
        this.setBlock(chunk, x + 6, y + 7, z + 8, heatTraps);
        this.setBlock(chunk, x + 6, y + 7, z + 9, heatTraps);
        this.setBlock(chunk, x + 6, y + 7, z + 10, heatTraps);
        this.setBlock(chunk, x + 6, y + 7, z + 15, ancientStone);
        this.setBlock(chunk, x + 7, y + 0, z + 0, ancientbricks);
        this.setBlock(chunk, x + 7, y + 0, z + 1, ancientbricks);
        this.setBlock(chunk, x + 7, y + 0, z + 2, ancientbricks);
        this.setBlock(chunk, x + 7, y + 0, z + 3, ancientbricks);
        this.setBlock(chunk, x + 7, y + 0, z + 4, dungeonBricks);
        this.setBlock(chunk, x + 7, y + 0, z + 5, dungeonBricks);
        this.setBlock(chunk, x + 7, y + 0, z + 6, heatTraps);
        this.setBlock(chunk, x + 7, y + 0, z + 7, heatTraps);
        this.setBlock(chunk, x + 7, y + 0, z + 8, heatTraps);
        this.setBlock(chunk, x + 7, y + 0, z + 9, heatTraps);
        this.setBlock(chunk, x + 7, y + 0, z + 10, dungeonBricks);
        this.setBlock(chunk, x + 7, y + 0, z + 11, dungeonBricks);
        this.setBlock(chunk, x + 7, y + 0, z + 12, ancientbricks);
        this.setBlock(chunk, x + 7, y + 0, z + 13, ancientbricks);
        this.setBlock(chunk, x + 7, y + 0, z + 14, ancientbricks);
        this.setBlock(chunk, x + 7, y + 0, z + 15, ancientbricks);
        this.setBlock(chunk, x + 7, y + 1, z + 2, heatTraps);
        this.setBlock(chunk, x + 7, y + 1, z + 6, heatTraps);
        this.setBlock(chunk, x + 7, y + 1, z + 7, heatTraps);
        this.setBlock(chunk, x + 7, y + 1, z + 8, heatTraps);
        this.setBlock(chunk, x + 7, y + 1, z + 9, heatTraps);
        this.setBlock(chunk, x + 7, y + 1, z + 13, heatTraps);
        this.setBlock(chunk, x + 7, y + 2, z + 6, heatTraps);
        this.setBlock(chunk, x + 7, y + 2, z + 7, heatTraps);
        this.setBlock(chunk, x + 7, y + 2, z + 8, heatTraps);
        this.setBlock(chunk, x + 7, y + 2, z + 9, heatTraps);
        this.setBlock(chunk, x + 7, y + 3, z + 0, BlockRegistry.arcaniumPower);
        this.setBlock(chunk, x + 7, y + 3, z + 6, heatTraps);
        this.setBlock(chunk, x + 7, y + 3, z + 7, heatTraps);
        this.setBlock(chunk, x + 7, y + 3, z + 8, heatTraps);
        this.setBlock(chunk, x + 7, y + 3, z + 9, heatTraps);
        this.setBlock(chunk, x + 7, y + 3, z + 15, BlockRegistry.arcaniumPower);
        this.setBlock(chunk, x + 7, y + 4, z + 0, soulStone);
        this.setBlock(chunk, x + 7, y + 4, z + 6, heatTraps);
        this.setBlock(chunk, x + 7, y + 4, z + 7, heatTraps);
        this.setBlock(chunk, x + 7, y + 4, z + 8, heatTraps);
        this.setBlock(chunk, x + 7, y + 4, z + 9, heatTraps);
        this.setBlock(chunk, x + 7, y + 4, z + 15, soulStone);
        this.setBlock(chunk, x + 7, y + 5, z + 0, soulStone);
        this.setBlock(chunk, x + 7, y + 5, z + 6, heatTraps);
        this.setBlock(chunk, x + 7, y + 5, z + 7, heatTraps);
        this.setBlock(chunk, x + 7, y + 5, z + 8, heatTraps);
        this.setBlock(chunk, x + 7, y + 5, z + 9, heatTraps);
        this.setBlock(chunk, x + 7, y + 5, z + 15, soulStone);
        this.setBlock(chunk, x + 7, y + 6, z + 0, ancientStone);
        this.setBlock(chunk, x + 7, y + 6, z + 6, heatTraps);
        this.setBlock(chunk, x + 7, y + 6, z + 7, heatTraps);
        this.setBlock(chunk, x + 7, y + 6, z + 8, heatTraps);
        this.setBlock(chunk, x + 7, y + 6, z + 9, heatTraps);
        this.setBlock(chunk, x + 7, y + 6, z + 15, ancientStone);
        this.setBlock(chunk, x + 7, y + 7, z + 0, ancientStone);
        this.setBlock(chunk, x + 7, y + 7, z + 6, heatTraps);
        this.setBlock(chunk, x + 7, y + 7, z + 7, heatTraps);
        this.setBlock(chunk, x + 7, y + 7, z + 8, heatTraps);
        this.setBlock(chunk, x + 7, y + 7, z + 9, heatTraps);
        this.setBlock(chunk, x + 7, y + 7, z + 15, ancientStone);
        this.setBlock(chunk, x + 8, y + 0, z + 0, ancientbricks);
        this.setBlock(chunk, x + 8, y + 0, z + 1, ancientbricks);
        this.setBlock(chunk, x + 8, y + 0, z + 2, ancientbricks);
        this.setBlock(chunk, x + 8, y + 0, z + 3, ancientbricks);
        this.setBlock(chunk, x + 8, y + 0, z + 4, dungeonBricks);
        this.setBlock(chunk, x + 8, y + 0, z + 5, dungeonBricks);
        this.setBlock(chunk, x + 8, y + 0, z + 6, heatTraps);
        this.setBlock(chunk, x + 8, y + 0, z + 7, heatTraps);
        this.setBlock(chunk, x + 8, y + 0, z + 8, heatTraps);
        this.setBlock(chunk, x + 8, y + 0, z + 9, heatTraps);
        this.setBlock(chunk, x + 8, y + 0, z + 10, dungeonBricks);
        this.setBlock(chunk, x + 8, y + 0, z + 11, dungeonBricks);
        this.setBlock(chunk, x + 8, y + 0, z + 12, ancientbricks);
        this.setBlock(chunk, x + 8, y + 0, z + 13, ancientbricks);
        this.setBlock(chunk, x + 8, y + 0, z + 14, ancientbricks);
        this.setBlock(chunk, x + 8, y + 0, z + 15, ancientbricks);
        this.setBlock(chunk, x + 8, y + 1, z + 2, heatTraps);
        this.setBlock(chunk, x + 8, y + 1, z + 6, heatTraps);
        this.setBlock(chunk, x + 8, y + 1, z + 7, heatTraps);
        this.setBlock(chunk, x + 8, y + 1, z + 8, heatTraps);
        this.setBlock(chunk, x + 8, y + 1, z + 9, heatTraps);
        this.setBlock(chunk, x + 8, y + 1, z + 13, heatTraps);
        this.setBlock(chunk, x + 8, y + 2, z + 6, heatTraps);
        this.setBlock(chunk, x + 8, y + 2, z + 7, heatTraps);
        this.setBlock(chunk, x + 8, y + 2, z + 8, heatTraps);
        this.setBlock(chunk, x + 8, y + 2, z + 9, heatTraps);
        this.setBlock(chunk, x + 8, y + 3, z + 0, BlockRegistry.arcaniumPower);
        this.setBlock(chunk, x + 8, y + 3, z + 6, heatTraps);
        this.setBlock(chunk, x + 8, y + 3, z + 7, heatTraps);
        this.setBlock(chunk, x + 8, y + 3, z + 8, heatTraps);
        this.setBlock(chunk, x + 8, y + 3, z + 9, heatTraps);
        this.setBlock(chunk, x + 8, y + 3, z + 15, BlockRegistry.arcaniumPower);
        this.setBlock(chunk, x + 8, y + 4, z + 0, soulStone);
        this.setBlock(chunk, x + 8, y + 4, z + 6, heatTraps);
        this.setBlock(chunk, x + 8, y + 4, z + 7, heatTraps);
        this.setBlock(chunk, x + 8, y + 4, z + 8, heatTraps);
        this.setBlock(chunk, x + 8, y + 4, z + 9, heatTraps);
        this.setBlock(chunk, x + 8, y + 4, z + 15, soulStone);
        this.setBlock(chunk, x + 8, y + 5, z + 0, soulStone);
        this.setBlock(chunk, x + 8, y + 5, z + 6, heatTraps);
        this.setBlock(chunk, x + 8, y + 5, z + 7, heatTraps);
        this.setBlock(chunk, x + 8, y + 5, z + 8, heatTraps);
        this.setBlock(chunk, x + 8, y + 5, z + 9, heatTraps);
        this.setBlock(chunk, x + 8, y + 5, z + 15, soulStone);
        this.setBlock(chunk, x + 8, y + 6, z + 0, ancientStone);
        this.setBlock(chunk, x + 8, y + 6, z + 6, heatTraps);
        this.setBlock(chunk, x + 8, y + 6, z + 7, heatTraps);
        this.setBlock(chunk, x + 8, y + 6, z + 8, heatTraps);
        this.setBlock(chunk, x + 8, y + 6, z + 9, heatTraps);
        this.setBlock(chunk, x + 8, y + 6, z + 15, ancientStone);
        this.setBlock(chunk, x + 8, y + 7, z + 0, ancientStone);
        this.setBlock(chunk, x + 8, y + 7, z + 6, heatTraps);
        this.setBlock(chunk, x + 8, y + 7, z + 7, heatTraps);
        this.setBlock(chunk, x + 8, y + 7, z + 8, heatTraps);
        this.setBlock(chunk, x + 8, y + 7, z + 9, heatTraps);
        this.setBlock(chunk, x + 8, y + 7, z + 15, ancientStone);
        this.setBlock(chunk, x + 9, y + 0, z + 0, ancientbricks);
        this.setBlock(chunk, x + 9, y + 0, z + 1, ancientbricks);
        this.setBlock(chunk, x + 9, y + 0, z + 2, ancientbricks);
        this.setBlock(chunk, x + 9, y + 0, z + 3, dungeonBricks);
        this.setBlock(chunk, x + 9, y + 0, z + 4, dungeonBricks);
        this.setBlock(chunk, x + 9, y + 0, z + 5, heatTraps);
        this.setBlock(chunk, x + 9, y + 0, z + 6, heatTraps);
        this.setBlock(chunk, x + 9, y + 0, z + 7, heatTraps);
        this.setBlock(chunk, x + 9, y + 0, z + 8, heatTraps);
        this.setBlock(chunk, x + 9, y + 0, z + 9, heatTraps);
        this.setBlock(chunk, x + 9, y + 0, z + 10, heatTraps);
        this.setBlock(chunk, x + 9, y + 0, z + 11, dungeonBricks);
        this.setBlock(chunk, x + 9, y + 0, z + 12, dungeonBricks);
        this.setBlock(chunk, x + 9, y + 0, z + 13, ancientbricks);
        this.setBlock(chunk, x + 9, y + 0, z + 14, ancientbricks);
        this.setBlock(chunk, x + 9, y + 0, z + 15, ancientbricks);
        this.setBlock(chunk, x + 9, y + 1, z + 0, ancientStone);
        this.setBlockState(chunk, x + 9, y + 1, z + 7, BlockRegistry.dungeonPrisonerSpawner.getDefaultState());
        this.setBlock(chunk, x + 9, y + 1, z + 8, heatTraps);
        this.setBlock(chunk, x + 9, y + 1, z + 15, ancientStone);
        this.setBlock(chunk, x + 9, y + 2, z + 0, BlockRegistry.dungeonLamp);
        this.setBlock(chunk, x + 9, y + 2, z + 7, heatTraps);
        this.setBlock(chunk, x + 9, y + 2, z + 8, heatTraps);
        this.setBlock(chunk, x + 9, y + 2, z + 15, BlockRegistry.dungeonLamp);
        this.setBlock(chunk, x + 9, y + 3, z + 0, ancientStone);
        this.setBlock(chunk, x + 9, y + 3, z + 7, heatTraps);
        this.setBlock(chunk, x + 9, y + 3, z + 8, heatTraps);
        this.setBlock(chunk, x + 9, y + 3, z + 15, ancientStone);
        this.setBlock(chunk, x + 9, y + 4, z + 0, soulStone);
        this.setBlock(chunk, x + 9, y + 4, z + 7, heatTraps);
        this.setBlock(chunk, x + 9, y + 4, z + 8, heatTraps);
        this.setBlock(chunk, x + 9, y + 4, z + 15, soulStone);
        this.setBlock(chunk, x + 9, y + 5, z + 0, soulStone);
        this.setBlock(chunk, x + 9, y + 5, z + 7, heatTraps);
        this.setBlock(chunk, x + 9, y + 5, z + 8, heatTraps);
        this.setBlock(chunk, x + 9, y + 5, z + 15, soulStone);
        this.setBlock(chunk, x + 9, y + 6, z + 0, ancientStone);
        this.setBlock(chunk, x + 9, y + 6, z + 7, heatTraps);
        this.setBlock(chunk, x + 9, y + 6, z + 8, heatTraps);
        this.setBlock(chunk, x + 9, y + 6, z + 15, ancientStone);
        this.setBlock(chunk, x + 9, y + 7, z + 0, ancientStone);
        this.setBlock(chunk, x + 9, y + 7, z + 5, heatTraps);
        this.setBlock(chunk, x + 9, y + 7, z + 6, heatTraps);
        this.setBlock(chunk, x + 9, y + 7, z + 7, heatTraps);
        this.setBlock(chunk, x + 9, y + 7, z + 8, heatTraps);
        this.setBlock(chunk, x + 9, y + 7, z + 9, heatTraps);
        this.setBlock(chunk, x + 9, y + 7, z + 10, heatTraps);
        this.setBlock(chunk, x + 9, y + 7, z + 15, ancientStone);
        this.setBlock(chunk, x + 10, y + 0, z + 0, ancientbricks);
        this.setBlock(chunk, x + 10, y + 0, z + 1, ancientbricks);
        this.setBlock(chunk, x + 10, y + 0, z + 2, dungeonBricks);
        this.setBlock(chunk, x + 10, y + 0, z + 3, dungeonBricks);
        this.setBlock(chunk, x + 10, y + 0, z + 4, heatTraps);
        this.setBlock(chunk, x + 10, y + 0, z + 5, heatTraps);
        this.setBlock(chunk, x + 10, y + 0, z + 6, heatTraps);
        this.setBlock(chunk, x + 10, y + 0, z + 7, dungeonBricks);
        this.setBlock(chunk, x + 10, y + 0, z + 8, dungeonBricks);
        this.setBlock(chunk, x + 10, y + 0, z + 9, heatTraps);
        this.setBlock(chunk, x + 10, y + 0, z + 10, heatTraps);
        this.setBlock(chunk, x + 10, y + 0, z + 11, heatTraps);
        this.setBlock(chunk, x + 10, y + 0, z + 12, dungeonBricks);
        this.setBlock(chunk, x + 10, y + 0, z + 13, dungeonBricks);
        this.setBlock(chunk, x + 10, y + 0, z + 14, ancientbricks);
        this.setBlock(chunk, x + 10, y + 0, z + 15, ancientbricks);
        this.setBlock(chunk, x + 10, y + 1, z + 0, soulStone);
        this.setBlock(chunk, x + 10, y + 1, z + 15, soulStone);
        this.setBlock(chunk, x + 10, y + 2, z + 0, soulStone);
        this.setBlock(chunk, x + 10, y + 2, z + 15, soulStone);
        this.setBlock(chunk, x + 10, y + 3, z + 0, soulStone);
        this.setBlock(chunk, x + 10, y + 3, z + 15, soulStone);
        this.setBlock(chunk, x + 10, y + 4, z + 0, soulStone);
        this.setBlock(chunk, x + 10, y + 4, z + 15, soulStone);
        this.setBlock(chunk, x + 10, y + 5, z + 0, soulStone);
        this.setBlock(chunk, x + 10, y + 5, z + 15, soulStone);
        this.setBlock(chunk, x + 10, y + 6, z + 0, ancientStone);
        this.setBlock(chunk, x + 10, y + 6, z + 15, ancientStone);
        this.setBlock(chunk, x + 10, y + 7, z + 0, ancientStone);
        this.setBlock(chunk, x + 10, y + 7, z + 4, heatTraps);
        this.setBlock(chunk, x + 10, y + 7, z + 5, heatTraps);
        this.setBlock(chunk, x + 10, y + 7, z + 6, heatTraps);
        this.setBlock(chunk, x + 10, y + 7, z + 9, heatTraps);
        this.setBlock(chunk, x + 10, y + 7, z + 10, heatTraps);
        this.setBlock(chunk, x + 10, y + 7, z + 11, heatTraps);
        this.setBlock(chunk, x + 10, y + 7, z + 15, ancientStone);
        this.setBlock(chunk, x + 11, y + 0, z + 0, ancientbricks);
        this.setBlock(chunk, x + 11, y + 0, z + 1, dungeonBricks);
        this.setBlock(chunk, x + 11, y + 0, z + 2, dungeonBricks);
        this.setBlock(chunk, x + 11, y + 0, z + 3, heatTraps);
        this.setBlock(chunk, x + 11, y + 0, z + 4, heatTraps);
        this.setBlock(chunk, x + 11, y + 0, z + 5, heatTraps);
        this.setBlock(chunk, x + 11, y + 0, z + 6, dungeonBricks);
        this.setBlock(chunk, x + 11, y + 0, z + 7, dungeonBricks);
        this.setBlock(chunk, x + 11, y + 0, z + 8, dungeonBricks);
        this.setBlock(chunk, x + 11, y + 0, z + 9, dungeonBricks);
        this.setBlock(chunk, x + 11, y + 0, z + 10, heatTraps);
        this.setBlock(chunk, x + 11, y + 0, z + 11, heatTraps);
        this.setBlock(chunk, x + 11, y + 0, z + 12, heatTraps);
        this.setBlock(chunk, x + 11, y + 0, z + 13, dungeonBricks);
        this.setBlock(chunk, x + 11, y + 0, z + 14, dungeonBricks);
        this.setBlock(chunk, x + 11, y + 0, z + 15, ancientbricks);
        this.setBlock(chunk, x + 11, y + 1, z + 0, soulStone);
        this.setBlock(chunk, x + 11, y + 1, z + 15, soulStone);
        this.setBlock(chunk, x + 11, y + 2, z + 0, soulStone);
        this.setBlock(chunk, x + 11, y + 2, z + 15, soulStone);
        this.setBlock(chunk, x + 11, y + 3, z + 0, soulStone);
        this.setBlock(chunk, x + 11, y + 3, z + 15, soulStone);
        this.setBlock(chunk, x + 11, y + 4, z + 0, soulStone);
        this.setBlock(chunk, x + 11, y + 4, z + 15, soulStone);
        this.setBlock(chunk, x + 11, y + 5, z + 0, soulStone);
        this.setBlock(chunk, x + 11, y + 5, z + 15, soulStone);
        this.setBlock(chunk, x + 11, y + 6, z + 0, ancientStone);
        this.setBlock(chunk, x + 11, y + 6, z + 15, ancientStone);
        this.setBlock(chunk, x + 11, y + 7, z + 0, ancientStone);
        this.setBlock(chunk, x + 11, y + 7, z + 3, heatTraps);
        this.setBlock(chunk, x + 11, y + 7, z + 4, heatTraps);
        this.setBlock(chunk, x + 11, y + 7, z + 5, heatTraps);
        this.setBlock(chunk, x + 11, y + 7, z + 10, heatTraps);
        this.setBlock(chunk, x + 11, y + 7, z + 11, heatTraps);
        this.setBlock(chunk, x + 11, y + 7, z + 12, heatTraps);
        this.setBlock(chunk, x + 11, y + 7, z + 15, ancientStone);
        this.setBlock(chunk, x + 12, y + 0, z + 0, dungeonBricks);
        this.setBlock(chunk, x + 12, y + 0, z + 1, dungeonBricks);
        this.setBlock(chunk, x + 12, y + 0, z + 2, heatTraps);
        this.setBlock(chunk, x + 12, y + 0, z + 3, heatTraps);
        this.setBlock(chunk, x + 12, y + 0, z + 4, heatTraps);
        this.setBlock(chunk, x + 12, y + 0, z + 5, dungeonBricks);
        this.setBlock(chunk, x + 12, y + 0, z + 6, dungeonBricks);
        this.setBlock(chunk, x + 12, y + 0, z + 7, ancientbricks);
        this.setBlock(chunk, x + 12, y + 0, z + 8, ancientbricks);
        this.setBlock(chunk, x + 12, y + 0, z + 9, dungeonBricks);
        this.setBlock(chunk, x + 12, y + 0, z + 10, dungeonBricks);
        this.setBlock(chunk, x + 12, y + 0, z + 11, heatTraps);
        this.setBlock(chunk, x + 12, y + 0, z + 12, heatTraps);
        this.setBlock(chunk, x + 12, y + 0, z + 13, heatTraps);
        this.setBlock(chunk, x + 12, y + 0, z + 14, dungeonBricks);
        this.setBlock(chunk, x + 12, y + 0, z + 15, dungeonBricks);
        this.setBlock(chunk, x + 12, y + 1, z + 0, soulStone);
        this.setBlock(chunk, x + 12, y + 1, z + 15, soulStone);
        this.setBlock(chunk, x + 12, y + 2, z + 0, soulStone);
        this.setBlock(chunk, x + 12, y + 2, z + 15, soulStone);
        this.setBlock(chunk, x + 12, y + 3, z + 0, soulStone);
        this.setBlock(chunk, x + 12, y + 3, z + 15, soulStone);
        this.setBlock(chunk, x + 12, y + 4, z + 0, soulStone);
        this.setBlock(chunk, x + 12, y + 4, z + 15, soulStone);
        this.setBlock(chunk, x + 12, y + 5, z + 0, soulStone);
        this.setBlock(chunk, x + 12, y + 5, z + 15, soulStone);
        this.setBlock(chunk, x + 12, y + 6, z + 0, ancientStone);
        this.setBlock(chunk, x + 12, y + 6, z + 15, ancientStone);
        this.setBlock(chunk, x + 12, y + 7, z + 0, ancientStone);
        this.setBlock(chunk, x + 12, y + 7, z + 2, heatTraps);
        this.setBlock(chunk, x + 12, y + 7, z + 3, heatTraps);
        this.setBlock(chunk, x + 12, y + 7, z + 4, heatTraps);
        this.setBlock(chunk, x + 12, y + 7, z + 11, heatTraps);
        this.setBlock(chunk, x + 12, y + 7, z + 12, heatTraps);
        this.setBlock(chunk, x + 12, y + 7, z + 13, heatTraps);
        this.setBlock(chunk, x + 12, y + 7, z + 15, ancientStone);
        this.setBlock(chunk, x + 13, y + 0, z + 0, dungeonBricks);
        this.setBlock(chunk, x + 13, y + 0, z + 1, heatTraps);
        this.setBlock(chunk, x + 13, y + 0, z + 2, heatTraps);
        this.setBlock(chunk, x + 13, y + 0, z + 3, heatTraps);
        this.setBlock(chunk, x + 13, y + 0, z + 4, dungeonBricks);
        this.setBlock(chunk, x + 13, y + 0, z + 5, dungeonBricks);
        this.setBlock(chunk, x + 13, y + 0, z + 6, ancientbricks);
        this.setBlock(chunk, x + 13, y + 0, z + 7, ancientbricks);
        this.setBlock(chunk, x + 13, y + 0, z + 8, ancientbricks);
        this.setBlock(chunk, x + 13, y + 0, z + 9, ancientbricks);
        this.setBlock(chunk, x + 13, y + 0, z + 10, dungeonBricks);
        this.setBlock(chunk, x + 13, y + 0, z + 11, dungeonBricks);
        this.setBlock(chunk, x + 13, y + 0, z + 12, heatTraps);
        this.setBlock(chunk, x + 13, y + 0, z + 13, heatTraps);
        this.setBlock(chunk, x + 13, y + 0, z + 14, heatTraps);
        this.setBlock(chunk, x + 13, y + 0, z + 15, dungeonBricks);
        this.setBlock(chunk, x + 13, y + 1, z + 0, soulStone);
        this.setBlock(chunk, x + 13, y + 1, z + 7, heatTraps);
        this.setBlock(chunk, x + 13, y + 1, z + 8, heatTraps);
        this.setBlock(chunk, x + 13, y + 1, z + 15, soulStone);
        this.setBlock(chunk, x + 13, y + 2, z + 0, soulStone);
        this.setBlock(chunk, x + 13, y + 2, z + 15, soulStone);
        this.setBlock(chunk, x + 13, y + 3, z + 0, soulStone);
        this.setBlock(chunk, x + 13, y + 3, z + 15, soulStone);
        this.setBlock(chunk, x + 13, y + 4, z + 0, soulStone);
        this.setBlock(chunk, x + 13, y + 4, z + 15, soulStone);
        this.setBlock(chunk, x + 13, y + 5, z + 0, soulStone);
        this.setBlock(chunk, x + 13, y + 5, z + 15, soulStone);
        this.setBlock(chunk, x + 13, y + 6, z + 0, ancientStone);
        this.setBlock(chunk, x + 13, y + 6, z + 15, ancientStone);
        this.setBlock(chunk, x + 13, y + 7, z + 0, ancientStone);
        this.setBlock(chunk, x + 13, y + 7, z + 1, heatTraps);
        this.setBlock(chunk, x + 13, y + 7, z + 2, heatTraps);
        this.setBlock(chunk, x + 13, y + 7, z + 3, heatTraps);
        this.setBlock(chunk, x + 13, y + 7, z + 12, heatTraps);
        this.setBlock(chunk, x + 13, y + 7, z + 13, heatTraps);
        this.setBlock(chunk, x + 13, y + 7, z + 14, heatTraps);
        this.setBlock(chunk, x + 13, y + 7, z + 15, ancientStone);
        this.setBlock(chunk, x + 14, y + 0, z + 0, heatTraps);
        this.setBlock(chunk, x + 14, y + 0, z + 1, heatTraps);
        this.setBlock(chunk, x + 14, y + 0, z + 2, heatTraps);
        this.setBlock(chunk, x + 14, y + 0, z + 3, dungeonBricks);
        this.setBlock(chunk, x + 14, y + 0, z + 4, dungeonBricks);
        this.setBlock(chunk, x + 14, y + 0, z + 5, ancientbricks);
        this.setBlock(chunk, x + 14, y + 0, z + 6, ancientbricks);
        this.setBlock(chunk, x + 14, y + 0, z + 7, ancientbricks);
        this.setBlock(chunk, x + 14, y + 0, z + 8, ancientbricks);
        this.setBlock(chunk, x + 14, y + 0, z + 9, ancientbricks);
        this.setBlock(chunk, x + 14, y + 0, z + 10, ancientbricks);
        this.setBlock(chunk, x + 14, y + 0, z + 11, dungeonBricks);
        this.setBlock(chunk, x + 14, y + 0, z + 12, dungeonBricks);
        this.setBlock(chunk, x + 14, y + 0, z + 13, heatTraps);
        this.setBlock(chunk, x + 14, y + 0, z + 14, heatTraps);
        this.setBlock(chunk, x + 14, y + 0, z + 15, heatTraps);
        this.setBlock(chunk, x + 14, y + 1, z + 0, heatTraps);
        this.setBlock(chunk, x + 14, y + 1, z + 1, heatTraps);
        this.setBlock(chunk, x + 14, y + 1, z + 14, heatTraps);
        this.setBlock(chunk, x + 14, y + 1, z + 15, heatTraps);
        this.setBlock(chunk, x + 14, y + 2, z + 0, heatTraps);
        this.setBlock(chunk, x + 14, y + 2, z + 1, heatTraps);
        this.setBlock(chunk, x + 14, y + 2, z + 14, heatTraps);
        this.setBlock(chunk, x + 14, y + 2, z + 15, heatTraps);
        this.setBlock(chunk, x + 14, y + 3, z + 0, heatTraps);
        this.setBlock(chunk, x + 14, y + 3, z + 1, heatTraps);
        this.setBlock(chunk, x + 14, y + 3, z + 14, heatTraps);
        this.setBlock(chunk, x + 14, y + 3, z + 15, heatTraps);
        this.setBlock(chunk, x + 14, y + 4, z + 0, heatTraps);
        this.setBlock(chunk, x + 14, y + 4, z + 1, heatTraps);
        this.setBlock(chunk, x + 14, y + 4, z + 14, heatTraps);
        this.setBlock(chunk, x + 14, y + 4, z + 15, heatTraps);
        this.setBlock(chunk, x + 14, y + 5, z + 0, heatTraps);
        this.setBlock(chunk, x + 14, y + 5, z + 1, heatTraps);
        this.setBlock(chunk, x + 14, y + 5, z + 14, heatTraps);
        this.setBlock(chunk, x + 14, y + 5, z + 15, heatTraps);
        this.setBlock(chunk, x + 14, y + 6, z + 0, heatTraps);
        this.setBlock(chunk, x + 14, y + 6, z + 1, heatTraps);
        this.setBlock(chunk, x + 14, y + 6, z + 14, heatTraps);
        this.setBlock(chunk, x + 14, y + 6, z + 15, heatTraps);
        this.setBlock(chunk, x + 14, y + 7, z + 0, heatTraps);
        this.setBlock(chunk, x + 14, y + 7, z + 1, heatTraps);
        this.setBlock(chunk, x + 14, y + 7, z + 2, heatTraps);
        this.setBlock(chunk, x + 14, y + 7, z + 13, heatTraps);
        this.setBlock(chunk, x + 14, y + 7, z + 14, heatTraps);
        this.setBlock(chunk, x + 14, y + 7, z + 15, heatTraps);
        this.setBlock(chunk, x + 15, y + 0, z + 0, heatTraps);
        this.setBlock(chunk, x + 15, y + 0, z + 1, heatTraps);
        this.setBlock(chunk, x + 15, y + 0, z + 2, dungeonBricks);
        this.setBlock(chunk, x + 15, y + 0, z + 3, dungeonBricks);
        this.setBlock(chunk, x + 15, y + 0, z + 4, ancientbricks);
        this.setBlock(chunk, x + 15, y + 0, z + 5, ancientbricks);
        this.setBlock(chunk, x + 15, y + 0, z + 6, ancientbricks);
        this.setBlock(chunk, x + 15, y + 0, z + 7, ancientbricks);
        this.setBlock(chunk, x + 15, y + 0, z + 8, ancientbricks);
        this.setBlock(chunk, x + 15, y + 0, z + 9, ancientbricks);
        this.setBlock(chunk, x + 15, y + 0, z + 10, ancientbricks);
        this.setBlock(chunk, x + 15, y + 0, z + 11, ancientbricks);
        this.setBlock(chunk, x + 15, y + 0, z + 12, dungeonBricks);
        this.setBlock(chunk, x + 15, y + 0, z + 13, dungeonBricks);
        this.setBlock(chunk, x + 15, y + 0, z + 14, heatTraps);
        this.setBlock(chunk, x + 15, y + 0, z + 15, heatTraps);
        this.setBlock(chunk, x + 15, y + 1, z + 0, heatTraps);
        this.setBlock(chunk, x + 15, y + 1, z + 1, heatTraps);
        this.setBlock(chunk, x + 15, y + 1, z + 2, soulStone);
        this.setBlock(chunk, x + 15, y + 1, z + 3, soulStone);
        this.setBlock(chunk, x + 15, y + 1, z + 4, soulStone);
        this.setBlock(chunk, x + 15, y + 1, z + 5, soulStone);
        this.setBlock(chunk, x + 15, y + 1, z + 6, ancientStone);
        this.setBlock(chunk, x + 15, y + 1, z + 9, ancientStone);
        this.setBlock(chunk, x + 15, y + 1, z + 10, soulStone);
        this.setBlock(chunk, x + 15, y + 1, z + 11, soulStone);
        this.setBlock(chunk, x + 15, y + 1, z + 12, soulStone);
        this.setBlock(chunk, x + 15, y + 1, z + 13, soulStone);
        this.setBlock(chunk, x + 15, y + 1, z + 14, heatTraps);
        this.setBlock(chunk, x + 15, y + 1, z + 15, heatTraps);
        this.setBlock(chunk, x + 15, y + 2, z + 0, heatTraps);
        this.setBlock(chunk, x + 15, y + 2, z + 1, heatTraps);
        this.setBlock(chunk, x + 15, y + 2, z + 2, soulStone);
        this.setBlock(chunk, x + 15, y + 2, z + 3, soulStone);
        this.setBlock(chunk, x + 15, y + 2, z + 4, soulStone);
        this.setBlock(chunk, x + 15, y + 2, z + 5, soulStone);
        this.setBlock(chunk, x + 15, y + 2, z + 6, BlockRegistry.dungeonLamp);
        this.setBlock(chunk, x + 15, y + 2, z + 9, BlockRegistry.dungeonLamp);
        this.setBlock(chunk, x + 15, y + 2, z + 10, soulStone);
        this.setBlock(chunk, x + 15, y + 2, z + 11, soulStone);
        this.setBlock(chunk, x + 15, y + 2, z + 12, soulStone);
        this.setBlock(chunk, x + 15, y + 2, z + 13, soulStone);
        this.setBlock(chunk, x + 15, y + 2, z + 14, heatTraps);
        this.setBlock(chunk, x + 15, y + 2, z + 15, heatTraps);
        this.setBlock(chunk, x + 15, y + 3, z + 0, heatTraps);
        this.setBlock(chunk, x + 15, y + 3, z + 1, heatTraps);
        this.setBlock(chunk, x + 15, y + 3, z + 2, soulStone);
        this.setBlock(chunk, x + 15, y + 3, z + 3, soulStone);
        this.setBlock(chunk, x + 15, y + 3, z + 4, soulStone);
        this.setBlock(chunk, x + 15, y + 3, z + 5, soulStone);
        this.setBlock(chunk, x + 15, y + 3, z + 6, ancientStone);
        this.setBlock(chunk, x + 15, y + 3, z + 7, BlockRegistry.arcaniumPower);
        this.setBlock(chunk, x + 15, y + 3, z + 8, BlockRegistry.arcaniumPower);
        this.setBlock(chunk, x + 15, y + 3, z + 9, ancientStone);
        this.setBlock(chunk, x + 15, y + 3, z + 10, soulStone);
        this.setBlock(chunk, x + 15, y + 3, z + 11, soulStone);
        this.setBlock(chunk, x + 15, y + 3, z + 12, soulStone);
        this.setBlock(chunk, x + 15, y + 3, z + 13, soulStone);
        this.setBlock(chunk, x + 15, y + 3, z + 14, heatTraps);
        this.setBlock(chunk, x + 15, y + 3, z + 15, heatTraps);
        this.setBlock(chunk, x + 15, y + 4, z + 0, heatTraps);
        this.setBlock(chunk, x + 15, y + 4, z + 1, heatTraps);
        this.setBlock(chunk, x + 15, y + 4, z + 2, soulStone);
        this.setBlock(chunk, x + 15, y + 4, z + 3, soulStone);
        this.setBlock(chunk, x + 15, y + 4, z + 4, soulStone);
        this.setBlock(chunk, x + 15, y + 4, z + 5, soulStone);
        this.setBlock(chunk, x + 15, y + 4, z + 6, soulStone);
        this.setBlock(chunk, x + 15, y + 4, z + 7, soulStone);
        this.setBlock(chunk, x + 15, y + 4, z + 8, soulStone);
        this.setBlock(chunk, x + 15, y + 4, z + 9, soulStone);
        this.setBlock(chunk, x + 15, y + 4, z + 10, soulStone);
        this.setBlock(chunk, x + 15, y + 4, z + 11, soulStone);
        this.setBlock(chunk, x + 15, y + 4, z + 12, soulStone);
        this.setBlock(chunk, x + 15, y + 4, z + 13, soulStone);
        this.setBlock(chunk, x + 15, y + 4, z + 14, heatTraps);
        this.setBlock(chunk, x + 15, y + 4, z + 15, heatTraps);
        this.setBlock(chunk, x + 15, y + 5, z + 0, heatTraps);
        this.setBlock(chunk, x + 15, y + 5, z + 1, heatTraps);
        this.setBlock(chunk, x + 15, y + 5, z + 2, soulStone);
        this.setBlock(chunk, x + 15, y + 5, z + 3, soulStone);
        this.setBlock(chunk, x + 15, y + 5, z + 4, soulStone);
        this.setBlock(chunk, x + 15, y + 5, z + 5, soulStone);
        this.setBlock(chunk, x + 15, y + 5, z + 6, soulStone);
        this.setBlock(chunk, x + 15, y + 5, z + 7, soulStone);
        this.setBlock(chunk, x + 15, y + 5, z + 8, soulStone);
        this.setBlock(chunk, x + 15, y + 5, z + 9, soulStone);
        this.setBlock(chunk, x + 15, y + 5, z + 10, soulStone);
        this.setBlock(chunk, x + 15, y + 5, z + 11, soulStone);
        this.setBlock(chunk, x + 15, y + 5, z + 12, soulStone);
        this.setBlock(chunk, x + 15, y + 5, z + 13, soulStone);
        this.setBlock(chunk, x + 15, y + 5, z + 14, heatTraps);
        this.setBlock(chunk, x + 15, y + 5, z + 15, heatTraps);
        this.setBlock(chunk, x + 15, y + 6, z + 0, heatTraps);
        this.setBlock(chunk, x + 15, y + 6, z + 1, heatTraps);
        this.setBlock(chunk, x + 15, y + 6, z + 2, ancientStone);
        this.setBlock(chunk, x + 15, y + 6, z + 3, ancientStone);
        this.setBlock(chunk, x + 15, y + 6, z + 4, ancientStone);
        this.setBlock(chunk, x + 15, y + 6, z + 5, ancientStone);
        this.setBlock(chunk, x + 15, y + 6, z + 6, ancientStone);
        this.setBlock(chunk, x + 15, y + 6, z + 7, ancientStone);
        this.setBlock(chunk, x + 15, y + 6, z + 8, ancientStone);
        this.setBlock(chunk, x + 15, y + 6, z + 9, ancientStone);
        this.setBlock(chunk, x + 15, y + 6, z + 10, ancientStone);
        this.setBlock(chunk, x + 15, y + 6, z + 11, ancientStone);
        this.setBlock(chunk, x + 15, y + 6, z + 12, ancientStone);
        this.setBlock(chunk, x + 15, y + 6, z + 13, ancientStone);
        this.setBlock(chunk, x + 15, y + 6, z + 14, heatTraps);
        this.setBlock(chunk, x + 15, y + 6, z + 15, heatTraps);
        this.setBlock(chunk, x + 15, y + 7, z + 0, heatTraps);
        this.setBlock(chunk, x + 15, y + 7, z + 1, heatTraps);
        this.setBlock(chunk, x + 15, y + 7, z + 2, ancientStone);
        this.setBlock(chunk, x + 15, y + 7, z + 3, ancientStone);
        this.setBlock(chunk, x + 15, y + 7, z + 4, ancientStone);
        this.setBlock(chunk, x + 15, y + 7, z + 5, ancientStone);
        this.setBlock(chunk, x + 15, y + 7, z + 6, ancientStone);
        this.setBlock(chunk, x + 15, y + 7, z + 7, ancientStone);
        this.setBlock(chunk, x + 15, y + 7, z + 8, ancientStone);
        this.setBlock(chunk, x + 15, y + 7, z + 9, ancientStone);
        this.setBlock(chunk, x + 15, y + 7, z + 10, ancientStone);
        this.setBlock(chunk, x + 15, y + 7, z + 11, ancientStone);
        this.setBlock(chunk, x + 15, y + 7, z + 12, ancientStone);
        this.setBlock(chunk, x + 15, y + 7, z + 13, ancientStone);
        this.setBlock(chunk, x + 15, y + 7, z + 14, heatTraps);
        this.setBlock(chunk, x + 15, y + 7, z + 15, heatTraps);
        return true;
    }
}