package divinerpg.dimensions.arcana.components;

import java.util.Random;

import divinerpg.dimensions.arcana.ArcanaChunkPrimer;
import divinerpg.registry.BlockRegistry;
import net.minecraft.block.Block;
import net.minecraft.init.Blocks;

public class DungeonComponent08 extends DungeonComponentBase {
    @Override
    public boolean generate(ArcanaChunkPrimer chunk, Random rand, int i, int j, int k) {
        Block dungeonBricks = BlockRegistry.degradedBrick;
        Block ancientbricks = BlockRegistry.ancientBrick;
        Block soulStone = BlockRegistry.soulStone;
        Block ancientstone = BlockRegistry.ancientStone;
        Block arcaniumSoulSludge = BlockRegistry.soulSludge;
        Block arcaniteMetal = BlockRegistry.arcaniumMetal;
        Block arcanaPower = BlockRegistry.arcaniumPower;

        for (int n = 0; n < 16; n++) {
            for (int m = 0; m < 16; m++) {
                for (int o = 0; o < 16; o++) {
                    this.setBlock(chunk, i + n, j + o, k + m, Blocks.AIR);
                }
            }
        }

        this.setBlock(chunk, i + 0, j + 0, k + 0, ancientbricks);
        this.setBlock(chunk, i + 0, j + 0, k + 1, ancientbricks);
        this.setBlock(chunk, i + 0, j + 0, k + 2, ancientbricks);
        this.setBlock(chunk, i + 0, j + 0, k + 3, ancientbricks);
        this.setBlock(chunk, i + 0, j + 0, k + 4, ancientbricks);
        this.setBlock(chunk, i + 0, j + 0, k + 5, ancientbricks);
        this.setBlock(chunk, i + 0, j + 0, k + 6, ancientbricks);
        this.setBlock(chunk, i + 0, j + 0, k + 7, ancientbricks);
        this.setBlock(chunk, i + 0, j + 0, k + 8, ancientbricks);
        this.setBlock(chunk, i + 0, j + 0, k + 9, ancientbricks);
        this.setBlock(chunk, i + 0, j + 0, k + 10, ancientbricks);
        this.setBlock(chunk, i + 0, j + 0, k + 11, ancientbricks);
        this.setBlock(chunk, i + 0, j + 0, k + 12, ancientbricks);
        this.setBlock(chunk, i + 0, j + 0, k + 13, ancientbricks);
        this.setBlock(chunk, i + 0, j + 0, k + 14, ancientbricks);
        this.setBlock(chunk, i + 0, j + 0, k + 15, ancientbricks);
        this.setBlock(chunk, i + 0, j + 1, k + 0, arcaniumSoulSludge);
        this.setBlock(chunk, i + 0, j + 1, k + 1, arcaniumSoulSludge);
        this.setBlock(chunk, i + 0, j + 1, k + 2, arcaniumSoulSludge);
        this.setBlock(chunk, i + 0, j + 1, k + 3, arcaniteMetal);
        this.setBlock(chunk, i + 0, j + 1, k + 4, arcaniumSoulSludge);
        this.setBlock(chunk, i + 0, j + 1, k + 5, arcaniumSoulSludge);
        this.setBlock(chunk, i + 0, j + 1, k + 6, arcaniteMetal);
        this.setBlock(chunk, i + 0, j + 1, k + 9, arcaniteMetal);
        this.setBlock(chunk, i + 0, j + 1, k + 10, arcaniumSoulSludge);
        this.setBlock(chunk, i + 0, j + 1, k + 11, arcaniumSoulSludge);
        this.setBlock(chunk, i + 0, j + 1, k + 12, arcaniteMetal);
        this.setBlock(chunk, i + 0, j + 1, k + 13, arcaniumSoulSludge);
        this.setBlock(chunk, i + 0, j + 1, k + 14, arcaniumSoulSludge);
        this.setBlock(chunk, i + 0, j + 1, k + 15, arcaniumSoulSludge);
        this.setBlock(chunk, i + 0, j + 2, k + 0, arcaniumSoulSludge);
        this.setBlock(chunk, i + 0, j + 2, k + 1, arcaniumSoulSludge);
        this.setBlock(chunk, i + 0, j + 2, k + 2, arcaniumSoulSludge);
        this.setBlock(chunk, i + 0, j + 2, k + 3, arcaniteMetal);
        this.setBlock(chunk, i + 0, j + 2, k + 4, arcaniumSoulSludge);
        this.setBlock(chunk, i + 0, j + 2, k + 5, arcaniumSoulSludge);
        this.setBlock(chunk, i + 0, j + 2, k + 6, arcaniteMetal);
        this.setBlock(chunk, i + 0, j + 2, k + 9, arcaniteMetal);
        this.setBlock(chunk, i + 0, j + 2, k + 10, arcaniumSoulSludge);
        this.setBlock(chunk, i + 0, j + 2, k + 11, arcaniumSoulSludge);
        this.setBlock(chunk, i + 0, j + 2, k + 12, arcaniteMetal);
        this.setBlock(chunk, i + 0, j + 2, k + 13, arcaniumSoulSludge);
        this.setBlock(chunk, i + 0, j + 2, k + 14, arcaniumSoulSludge);
        this.setBlock(chunk, i + 0, j + 2, k + 15, arcaniumSoulSludge);
        this.setBlock(chunk, i + 0, j + 3, k + 0, arcaniumSoulSludge);
        this.setBlock(chunk, i + 0, j + 3, k + 1, arcaniumSoulSludge);
        this.setBlock(chunk, i + 0, j + 3, k + 2, arcaniumSoulSludge);
        this.setBlock(chunk, i + 0, j + 3, k + 3, arcaniteMetal);
        this.setBlock(chunk, i + 0, j + 3, k + 4, arcaniumSoulSludge);
        this.setBlock(chunk, i + 0, j + 3, k + 5, arcaniumSoulSludge);
        this.setBlock(chunk, i + 0, j + 3, k + 6, arcaniteMetal);
        this.setBlock(chunk, i + 0, j + 3, k + 7, arcanaPower);
        this.setBlock(chunk, i + 0, j + 3, k + 8, arcanaPower);
        this.setBlock(chunk, i + 0, j + 3, k + 9, arcaniteMetal);
        this.setBlock(chunk, i + 0, j + 3, k + 10, arcaniumSoulSludge);
        this.setBlock(chunk, i + 0, j + 3, k + 11, arcaniumSoulSludge);
        this.setBlock(chunk, i + 0, j + 3, k + 12, arcaniteMetal);
        this.setBlock(chunk, i + 0, j + 3, k + 13, arcaniumSoulSludge);
        this.setBlock(chunk, i + 0, j + 3, k + 14, arcaniumSoulSludge);
        this.setBlock(chunk, i + 0, j + 3, k + 15, arcaniumSoulSludge);
        this.setBlock(chunk, i + 0, j + 4, k + 0, arcaniumSoulSludge);
        this.setBlock(chunk, i + 0, j + 4, k + 1, arcaniumSoulSludge);
        this.setBlock(chunk, i + 0, j + 4, k + 2, arcaniumSoulSludge);
        this.setBlock(chunk, i + 0, j + 4, k + 3, arcaniteMetal);
        this.setBlock(chunk, i + 0, j + 4, k + 4, arcaniumSoulSludge);
        this.setBlock(chunk, i + 0, j + 4, k + 5, arcaniumSoulSludge);
        this.setBlock(chunk, i + 0, j + 4, k + 6, arcaniteMetal);
        this.setBlock(chunk, i + 0, j + 4, k + 7, arcaniumSoulSludge);
        this.setBlock(chunk, i + 0, j + 4, k + 8, arcaniumSoulSludge);
        this.setBlock(chunk, i + 0, j + 4, k + 9, arcaniteMetal);
        this.setBlock(chunk, i + 0, j + 4, k + 10, arcaniumSoulSludge);
        this.setBlock(chunk, i + 0, j + 4, k + 11, arcaniumSoulSludge);
        this.setBlock(chunk, i + 0, j + 4, k + 12, arcaniteMetal);
        this.setBlock(chunk, i + 0, j + 4, k + 13, arcaniumSoulSludge);
        this.setBlock(chunk, i + 0, j + 4, k + 14, arcaniumSoulSludge);
        this.setBlock(chunk, i + 0, j + 4, k + 15, arcaniumSoulSludge);
        this.setBlock(chunk, i + 0, j + 5, k + 0, arcaniumSoulSludge);
        this.setBlock(chunk, i + 0, j + 5, k + 1, arcaniumSoulSludge);
        this.setBlock(chunk, i + 0, j + 5, k + 2, arcaniumSoulSludge);
        this.setBlock(chunk, i + 0, j + 5, k + 3, arcaniteMetal);
        this.setBlock(chunk, i + 0, j + 5, k + 4, arcaniumSoulSludge);
        this.setBlock(chunk, i + 0, j + 5, k + 5, arcaniumSoulSludge);
        this.setBlock(chunk, i + 0, j + 5, k + 6, arcaniteMetal);
        this.setBlock(chunk, i + 0, j + 5, k + 7, arcaniumSoulSludge);
        this.setBlock(chunk, i + 0, j + 5, k + 8, arcaniumSoulSludge);
        this.setBlock(chunk, i + 0, j + 5, k + 9, arcaniteMetal);
        this.setBlock(chunk, i + 0, j + 5, k + 10, arcaniumSoulSludge);
        this.setBlock(chunk, i + 0, j + 5, k + 11, arcaniumSoulSludge);
        this.setBlock(chunk, i + 0, j + 5, k + 12, arcaniteMetal);
        this.setBlock(chunk, i + 0, j + 5, k + 13, arcaniumSoulSludge);
        this.setBlock(chunk, i + 0, j + 5, k + 14, arcaniumSoulSludge);
        this.setBlock(chunk, i + 0, j + 5, k + 15, arcaniumSoulSludge);
        this.setBlock(chunk, i + 0, j + 6, k + 0, arcaniumSoulSludge);
        this.setBlock(chunk, i + 0, j + 6, k + 1, arcaniumSoulSludge);
        this.setBlock(chunk, i + 0, j + 6, k + 2, arcaniumSoulSludge);
        this.setBlock(chunk, i + 0, j + 6, k + 3, arcaniteMetal);
        this.setBlock(chunk, i + 0, j + 6, k + 4, arcaniumSoulSludge);
        this.setBlock(chunk, i + 0, j + 6, k + 5, arcaniumSoulSludge);
        this.setBlock(chunk, i + 0, j + 6, k + 6, arcaniteMetal);
        this.setBlock(chunk, i + 0, j + 6, k + 7, arcaniumSoulSludge);
        this.setBlock(chunk, i + 0, j + 6, k + 8, arcaniumSoulSludge);
        this.setBlock(chunk, i + 0, j + 6, k + 9, arcaniteMetal);
        this.setBlock(chunk, i + 0, j + 6, k + 10, arcaniumSoulSludge);
        this.setBlock(chunk, i + 0, j + 6, k + 11, arcaniumSoulSludge);
        this.setBlock(chunk, i + 0, j + 6, k + 12, arcaniteMetal);
        this.setBlock(chunk, i + 0, j + 6, k + 13, arcaniumSoulSludge);
        this.setBlock(chunk, i + 0, j + 6, k + 14, arcaniumSoulSludge);
        this.setBlock(chunk, i + 0, j + 6, k + 15, arcaniumSoulSludge);
        this.setBlock(chunk, i + 0, j + 7, k + 0, arcaniumSoulSludge);
        this.setBlock(chunk, i + 0, j + 7, k + 1, arcaniumSoulSludge);
        this.setBlock(chunk, i + 0, j + 7, k + 2, arcaniumSoulSludge);
        this.setBlock(chunk, i + 0, j + 7, k + 3, arcaniteMetal);
        this.setBlock(chunk, i + 0, j + 7, k + 4, arcaniumSoulSludge);
        this.setBlock(chunk, i + 0, j + 7, k + 5, arcaniumSoulSludge);
        this.setBlock(chunk, i + 0, j + 7, k + 6, arcaniteMetal);
        this.setBlock(chunk, i + 0, j + 7, k + 7, arcaniumSoulSludge);
        this.setBlock(chunk, i + 0, j + 7, k + 8, arcaniumSoulSludge);
        this.setBlock(chunk, i + 0, j + 7, k + 9, arcaniteMetal);
        this.setBlock(chunk, i + 0, j + 7, k + 10, arcaniumSoulSludge);
        this.setBlock(chunk, i + 0, j + 7, k + 11, arcaniumSoulSludge);
        this.setBlock(chunk, i + 0, j + 7, k + 12, arcaniteMetal);
        this.setBlock(chunk, i + 0, j + 7, k + 13, arcaniumSoulSludge);
        this.setBlock(chunk, i + 0, j + 7, k + 14, arcaniumSoulSludge);
        this.setBlock(chunk, i + 0, j + 7, k + 15, arcaniumSoulSludge);
        this.setBlock(chunk, i + 0, j + 8, k + 0, ancientstone);
        this.setBlock(chunk, i + 0, j + 8, k + 1, ancientstone);
        this.setBlock(chunk, i + 0, j + 8, k + 2, ancientstone);
        this.setBlock(chunk, i + 0, j + 8, k + 3, ancientstone);
        this.setBlock(chunk, i + 0, j + 8, k + 4, ancientstone);
        this.setBlock(chunk, i + 0, j + 8, k + 5, ancientstone);
        this.setBlock(chunk, i + 0, j + 8, k + 6, ancientstone);
        this.setBlock(chunk, i + 0, j + 8, k + 7, ancientstone);
        this.setBlock(chunk, i + 0, j + 8, k + 8, ancientstone);
        this.setBlock(chunk, i + 0, j + 8, k + 9, ancientstone);
        this.setBlock(chunk, i + 0, j + 8, k + 10, ancientstone);
        this.setBlock(chunk, i + 0, j + 8, k + 11, ancientstone);
        this.setBlock(chunk, i + 0, j + 8, k + 12, ancientstone);
        this.setBlock(chunk, i + 0, j + 8, k + 13, ancientstone);
        this.setBlock(chunk, i + 0, j + 8, k + 14, ancientstone);
        this.setBlock(chunk, i + 0, j + 8, k + 15, ancientstone);
        this.setBlock(chunk, i + 0, j + 9, k + 0, soulStone);
        this.setBlock(chunk, i + 0, j + 9, k + 1, soulStone);
        this.setBlock(chunk, i + 0, j + 9, k + 2, soulStone);
        this.setBlock(chunk, i + 0, j + 9, k + 3, soulStone);
        this.setBlock(chunk, i + 0, j + 9, k + 4, soulStone);
        this.setBlock(chunk, i + 0, j + 9, k + 5, soulStone);
        this.setBlock(chunk, i + 0, j + 9, k + 6, arcaniteMetal);
        this.setBlock(chunk, i + 0, j + 9, k + 9, arcaniteMetal);
        this.setBlock(chunk, i + 0, j + 9, k + 10, soulStone);
        this.setBlock(chunk, i + 0, j + 9, k + 11, soulStone);
        this.setBlock(chunk, i + 0, j + 9, k + 12, soulStone);
        this.setBlock(chunk, i + 0, j + 9, k + 13, soulStone);
        this.setBlock(chunk, i + 0, j + 9, k + 14, soulStone);
        this.setBlock(chunk, i + 0, j + 9, k + 15, soulStone);
        this.setBlock(chunk, i + 0, j + 10, k + 0, soulStone);
        this.setBlock(chunk, i + 0, j + 10, k + 1, soulStone);
        this.setBlock(chunk, i + 0, j + 10, k + 2, soulStone);
        this.setBlock(chunk, i + 0, j + 10, k + 3, soulStone);
        this.setBlock(chunk, i + 0, j + 10, k + 4, soulStone);
        this.setBlock(chunk, i + 0, j + 10, k + 5, soulStone);
        this.setBlock(chunk, i + 0, j + 10, k + 6, arcaniteMetal);
        this.setBlock(chunk, i + 0, j + 10, k + 9, arcaniteMetal);
        this.setBlock(chunk, i + 0, j + 10, k + 10, soulStone);
        this.setBlock(chunk, i + 0, j + 10, k + 11, soulStone);
        this.setBlock(chunk, i + 0, j + 10, k + 12, soulStone);
        this.setBlock(chunk, i + 0, j + 10, k + 13, soulStone);
        this.setBlock(chunk, i + 0, j + 10, k + 14, soulStone);
        this.setBlock(chunk, i + 0, j + 10, k + 15, soulStone);
        this.setBlock(chunk, i + 0, j + 11, k + 0, soulStone);
        this.setBlock(chunk, i + 0, j + 11, k + 1, soulStone);
        this.setBlock(chunk, i + 0, j + 11, k + 2, soulStone);
        this.setBlock(chunk, i + 0, j + 11, k + 3, soulStone);
        this.setBlock(chunk, i + 0, j + 11, k + 4, soulStone);
        this.setBlock(chunk, i + 0, j + 11, k + 5, soulStone);
        this.setBlock(chunk, i + 0, j + 11, k + 6, arcaniteMetal);
        this.setBlock(chunk, i + 0, j + 11, k + 7, arcanaPower);
        this.setBlock(chunk, i + 0, j + 11, k + 8, arcanaPower);
        this.setBlock(chunk, i + 0, j + 11, k + 9, arcaniteMetal);
        this.setBlock(chunk, i + 0, j + 11, k + 10, soulStone);
        this.setBlock(chunk, i + 0, j + 11, k + 11, soulStone);
        this.setBlock(chunk, i + 0, j + 11, k + 12, soulStone);
        this.setBlock(chunk, i + 0, j + 11, k + 13, soulStone);
        this.setBlock(chunk, i + 0, j + 11, k + 14, soulStone);
        this.setBlock(chunk, i + 0, j + 11, k + 15, soulStone);
        this.setBlock(chunk, i + 0, j + 12, k + 0, ancientbricks);
        this.setBlock(chunk, i + 0, j + 12, k + 1, ancientbricks);
        this.setBlock(chunk, i + 0, j + 12, k + 2, ancientbricks);
        this.setBlock(chunk, i + 0, j + 12, k + 3, ancientbricks);
        this.setBlock(chunk, i + 0, j + 12, k + 4, ancientbricks);
        this.setBlock(chunk, i + 0, j + 12, k + 5, ancientbricks);
        this.setBlock(chunk, i + 0, j + 12, k + 6, ancientbricks);
        this.setBlock(chunk, i + 0, j + 12, k + 7, ancientbricks);
        this.setBlock(chunk, i + 0, j + 12, k + 8, ancientbricks);
        this.setBlock(chunk, i + 0, j + 12, k + 9, ancientbricks);
        this.setBlock(chunk, i + 0, j + 12, k + 10, ancientbricks);
        this.setBlock(chunk, i + 0, j + 12, k + 11, ancientbricks);
        this.setBlock(chunk, i + 0, j + 12, k + 12, ancientbricks);
        this.setBlock(chunk, i + 0, j + 12, k + 13, ancientbricks);
        this.setBlock(chunk, i + 0, j + 12, k + 14, ancientbricks);
        this.setBlock(chunk, i + 0, j + 12, k + 15, ancientbricks);
        this.setBlock(chunk, i + 0, j + 13, k + 0, ancientstone);
        this.setBlock(chunk, i + 0, j + 13, k + 1, ancientstone);
        this.setBlock(chunk, i + 0, j + 13, k + 2, ancientstone);
        this.setBlock(chunk, i + 0, j + 13, k + 3, ancientstone);
        this.setBlock(chunk, i + 0, j + 13, k + 4, ancientstone);
        this.setBlock(chunk, i + 0, j + 13, k + 5, ancientstone);
        this.setBlock(chunk, i + 0, j + 13, k + 6, ancientstone);
        this.setBlock(chunk, i + 0, j + 13, k + 7, ancientstone);
        this.setBlock(chunk, i + 0, j + 13, k + 8, ancientstone);
        this.setBlock(chunk, i + 0, j + 13, k + 9, ancientstone);
        this.setBlock(chunk, i + 0, j + 13, k + 10, ancientstone);
        this.setBlock(chunk, i + 0, j + 13, k + 11, ancientstone);
        this.setBlock(chunk, i + 0, j + 13, k + 12, ancientstone);
        this.setBlock(chunk, i + 0, j + 13, k + 13, ancientstone);
        this.setBlock(chunk, i + 0, j + 13, k + 14, ancientstone);
        this.setBlock(chunk, i + 0, j + 13, k + 15, ancientstone);
        this.setBlock(chunk, i + 0, j + 14, k + 0, ancientstone);
        this.setBlock(chunk, i + 0, j + 14, k + 1, ancientstone);
        this.setBlock(chunk, i + 0, j + 14, k + 2, ancientstone);
        this.setBlock(chunk, i + 0, j + 14, k + 3, ancientstone);
        this.setBlock(chunk, i + 0, j + 14, k + 4, ancientstone);
        this.setBlock(chunk, i + 0, j + 14, k + 5, ancientstone);
        this.setBlock(chunk, i + 0, j + 14, k + 6, ancientstone);
        this.setBlock(chunk, i + 0, j + 14, k + 7, ancientstone);
        this.setBlock(chunk, i + 0, j + 14, k + 8, ancientstone);
        this.setBlock(chunk, i + 0, j + 14, k + 9, ancientstone);
        this.setBlock(chunk, i + 0, j + 14, k + 10, ancientstone);
        this.setBlock(chunk, i + 0, j + 14, k + 11, ancientstone);
        this.setBlock(chunk, i + 0, j + 14, k + 12, ancientstone);
        this.setBlock(chunk, i + 0, j + 14, k + 13, ancientstone);
        this.setBlock(chunk, i + 0, j + 14, k + 14, ancientstone);
        this.setBlock(chunk, i + 0, j + 14, k + 15, ancientstone);
        this.setBlock(chunk, i + 0, j + 15, k + 0, ancientstone);
        this.setBlock(chunk, i + 0, j + 15, k + 1, ancientstone);
        this.setBlock(chunk, i + 0, j + 15, k + 2, ancientstone);
        this.setBlock(chunk, i + 0, j + 15, k + 3, ancientstone);
        this.setBlock(chunk, i + 0, j + 15, k + 4, ancientstone);
        this.setBlock(chunk, i + 0, j + 15, k + 5, ancientstone);
        this.setBlock(chunk, i + 0, j + 15, k + 6, ancientstone);
        this.setBlock(chunk, i + 0, j + 15, k + 7, ancientstone);
        this.setBlock(chunk, i + 0, j + 15, k + 8, ancientstone);
        this.setBlock(chunk, i + 0, j + 15, k + 9, ancientstone);
        this.setBlock(chunk, i + 0, j + 15, k + 10, ancientstone);
        this.setBlock(chunk, i + 0, j + 15, k + 11, ancientstone);
        this.setBlock(chunk, i + 0, j + 15, k + 12, ancientstone);
        this.setBlock(chunk, i + 0, j + 15, k + 13, ancientstone);
        this.setBlock(chunk, i + 0, j + 15, k + 14, ancientstone);
        this.setBlock(chunk, i + 0, j + 15, k + 15, ancientstone);
        this.setBlock(chunk, i + 1, j + 0, k + 0, ancientbricks);
        this.setBlock(chunk, i + 1, j + 0, k + 1, dungeonBricks);
        this.setBlock(chunk, i + 1, j + 0, k + 2, dungeonBricks);
        this.setBlock(chunk, i + 1, j + 0, k + 3, dungeonBricks);
        this.setBlock(chunk, i + 1, j + 0, k + 4, dungeonBricks);
        this.setBlock(chunk, i + 1, j + 0, k + 5, dungeonBricks);
        this.setBlock(chunk, i + 1, j + 0, k + 6, dungeonBricks);
        this.setBlock(chunk, i + 1, j + 0, k + 7, dungeonBricks);
        this.setBlock(chunk, i + 1, j + 0, k + 8, dungeonBricks);
        this.setBlock(chunk, i + 1, j + 0, k + 9, dungeonBricks);
        this.setBlock(chunk, i + 1, j + 0, k + 10, dungeonBricks);
        this.setBlock(chunk, i + 1, j + 0, k + 11, dungeonBricks);
        this.setBlock(chunk, i + 1, j + 0, k + 12, dungeonBricks);
        this.setBlock(chunk, i + 1, j + 0, k + 13, dungeonBricks);
        this.setBlock(chunk, i + 1, j + 0, k + 14, dungeonBricks);
        this.setBlock(chunk, i + 1, j + 0, k + 15, ancientbricks);
        this.setBlock(chunk, i + 1, j + 1, k + 0, arcaniumSoulSludge);
        this.setBlock(chunk, i + 1, j + 1, k + 15, arcaniumSoulSludge);
        this.setBlock(chunk, i + 1, j + 2, k + 0, arcaniumSoulSludge);
        this.setBlock(chunk, i + 1, j + 2, k + 15, arcaniumSoulSludge);
        this.setBlock(chunk, i + 1, j + 3, k + 0, arcaniumSoulSludge);
        this.setBlock(chunk, i + 1, j + 3, k + 15, arcaniumSoulSludge);
        this.setBlock(chunk, i + 1, j + 4, k + 0, arcaniumSoulSludge);
        this.setBlock(chunk, i + 1, j + 4, k + 15, arcaniumSoulSludge);
        this.setBlock(chunk, i + 1, j + 5, k + 0, arcaniumSoulSludge);
        this.setBlock(chunk, i + 1, j + 5, k + 15, arcaniumSoulSludge);
        this.setBlock(chunk, i + 1, j + 6, k + 0, arcaniumSoulSludge);
        this.setBlock(chunk, i + 1, j + 6, k + 15, arcaniumSoulSludge);
        this.setBlock(chunk, i + 1, j + 7, k + 0, arcaniumSoulSludge);
        this.setBlock(chunk, i + 1, j + 7, k + 15, arcaniumSoulSludge);
        this.setBlock(chunk, i + 1, j + 8, k + 0, ancientstone);
        this.setBlock(chunk, i + 1, j + 8, k + 1, dungeonBricks);
        this.setBlock(chunk, i + 1, j + 8, k + 2, dungeonBricks);
        this.setBlock(chunk, i + 1, j + 8, k + 3, dungeonBricks);
        this.setBlock(chunk, i + 1, j + 8, k + 4, dungeonBricks);
        this.setBlock(chunk, i + 1, j + 8, k + 5, dungeonBricks);
        this.setBlock(chunk, i + 1, j + 8, k + 6, dungeonBricks);
        this.setBlock(chunk, i + 1, j + 8, k + 7, dungeonBricks);
        this.setBlock(chunk, i + 1, j + 8, k + 8, dungeonBricks);
        this.setBlock(chunk, i + 1, j + 8, k + 9, dungeonBricks);
        this.setBlock(chunk, i + 1, j + 8, k + 10, dungeonBricks);
        this.setBlock(chunk, i + 1, j + 8, k + 15, ancientstone);
        this.setBlock(chunk, i + 1, j + 9, k + 0, soulStone);
        this.setBlock(chunk, i + 1, j + 9, k + 15, soulStone);
        this.setBlock(chunk, i + 1, j + 10, k + 0, soulStone);
        this.setBlock(chunk, i + 1, j + 10, k + 15, soulStone);
        this.setBlock(chunk, i + 1, j + 11, k + 0, soulStone);
        this.setBlock(chunk, i + 1, j + 11, k + 15, soulStone);
        this.setBlock(chunk, i + 1, j + 12, k + 0, ancientbricks);
        this.setBlock(chunk, i + 1, j + 12, k + 15, ancientbricks);
        this.setBlock(chunk, i + 1, j + 13, k + 0, ancientstone);
        this.setBlock(chunk, i + 1, j + 13, k + 15, ancientstone);
        this.setBlock(chunk, i + 1, j + 14, k + 0, ancientstone);
        this.setBlock(chunk, i + 1, j + 14, k + 15, ancientstone);
        this.setBlock(chunk, i + 1, j + 15, k + 0, ancientstone);
        this.setBlock(chunk, i + 1, j + 15, k + 15, ancientstone);
        this.setBlock(chunk, i + 2, j + 0, k + 0, ancientbricks);
        this.setBlock(chunk, i + 2, j + 0, k + 1, dungeonBricks);
        this.setBlock(chunk, i + 2, j + 0, k + 2, dungeonBricks);
        this.setBlock(chunk, i + 2, j + 0, k + 3, dungeonBricks);
        this.setBlock(chunk, i + 2, j + 0, k + 4, dungeonBricks);
        this.setBlock(chunk, i + 2, j + 0, k + 5, dungeonBricks);
        this.setBlock(chunk, i + 2, j + 0, k + 6, dungeonBricks);
        this.setBlock(chunk, i + 2, j + 0, k + 7, dungeonBricks);
        this.setBlock(chunk, i + 2, j + 0, k + 8, dungeonBricks);
        this.setBlock(chunk, i + 2, j + 0, k + 9, dungeonBricks);
        this.setBlock(chunk, i + 2, j + 0, k + 10, dungeonBricks);
        this.setBlock(chunk, i + 2, j + 0, k + 11, dungeonBricks);
        this.setBlock(chunk, i + 2, j + 0, k + 12, dungeonBricks);
        this.setBlock(chunk, i + 2, j + 0, k + 13, dungeonBricks);
        this.setBlock(chunk, i + 2, j + 0, k + 14, dungeonBricks);
        this.setBlock(chunk, i + 2, j + 0, k + 15, ancientbricks);
        this.setBlock(chunk, i + 2, j + 1, k + 0, arcaniumSoulSludge);
        this.setBlock(chunk, i + 2, j + 1, k + 15, arcaniumSoulSludge);
        this.setBlock(chunk, i + 2, j + 2, k + 0, arcaniumSoulSludge);
        this.setBlock(chunk, i + 2, j + 2, k + 15, arcaniumSoulSludge);
        this.setBlock(chunk, i + 2, j + 3, k + 0, arcaniumSoulSludge);
        this.setBlock(chunk, i + 2, j + 3, k + 15, arcaniumSoulSludge);
        this.setBlock(chunk, i + 2, j + 4, k + 0, arcaniumSoulSludge);
        this.setBlock(chunk, i + 2, j + 4, k + 15, arcaniumSoulSludge);
        this.setBlock(chunk, i + 2, j + 5, k + 0, arcaniumSoulSludge);
        this.setBlock(chunk, i + 2, j + 5, k + 15, arcaniumSoulSludge);
        this.setBlock(chunk, i + 2, j + 6, k + 0, arcaniumSoulSludge);
        this.setBlock(chunk, i + 2, j + 6, k + 15, arcaniumSoulSludge);
        this.setBlock(chunk, i + 2, j + 7, k + 0, arcaniumSoulSludge);
        this.setBlock(chunk, i + 2, j + 7, k + 15, arcaniumSoulSludge);
        this.setBlock(chunk, i + 2, j + 8, k + 0, ancientstone);
        this.setBlock(chunk, i + 2, j + 8, k + 1, dungeonBricks);
        this.setBlock(chunk, i + 2, j + 8, k + 2, dungeonBricks);
        this.setBlock(chunk, i + 2, j + 8, k + 3, dungeonBricks);
        this.setBlock(chunk, i + 2, j + 8, k + 4, dungeonBricks);
        this.setBlock(chunk, i + 2, j + 8, k + 5, dungeonBricks);
        this.setBlock(chunk, i + 2, j + 8, k + 6, dungeonBricks);
        this.setBlock(chunk, i + 2, j + 8, k + 7, dungeonBricks);
        this.setBlock(chunk, i + 2, j + 8, k + 8, dungeonBricks);
        this.setBlock(chunk, i + 2, j + 8, k + 9, dungeonBricks);
        this.setBlock(chunk, i + 2, j + 8, k + 10, dungeonBricks);
        this.setBlock(chunk, i + 2, j + 8, k + 15, ancientstone);
        this.setBlock(chunk, i + 2, j + 9, k + 0, soulStone);
        this.setBlock(chunk, i + 2, j + 9, k + 15, soulStone);
        this.setBlock(chunk, i + 2, j + 10, k + 0, soulStone);
        this.setBlock(chunk, i + 2, j + 10, k + 15, soulStone);
        this.setBlock(chunk, i + 2, j + 11, k + 0, soulStone);
        this.setBlock(chunk, i + 2, j + 11, k + 15, soulStone);
        this.setBlock(chunk, i + 2, j + 12, k + 0, ancientbricks);
        this.setBlock(chunk, i + 2, j + 12, k + 15, ancientbricks);
        this.setBlock(chunk, i + 2, j + 13, k + 0, ancientstone);
        this.setBlock(chunk, i + 2, j + 13, k + 15, ancientstone);
        this.setBlock(chunk, i + 2, j + 14, k + 0, ancientstone);
        this.setBlock(chunk, i + 2, j + 14, k + 15, ancientstone);
        this.setBlock(chunk, i + 2, j + 15, k + 0, ancientstone);
        this.setBlock(chunk, i + 2, j + 15, k + 15, ancientstone);
        this.setBlock(chunk, i + 3, j + 0, k + 0, ancientbricks);
        this.setBlock(chunk, i + 3, j + 0, k + 1, dungeonBricks);
        this.setBlock(chunk, i + 3, j + 0, k + 2, dungeonBricks);
        this.setBlock(chunk, i + 3, j + 0, k + 3, dungeonBricks);
        this.setBlock(chunk, i + 3, j + 0, k + 4, dungeonBricks);
        this.setBlock(chunk, i + 3, j + 0, k + 5, dungeonBricks);
        this.setBlock(chunk, i + 3, j + 0, k + 6, dungeonBricks);
        this.setBlock(chunk, i + 3, j + 0, k + 7, dungeonBricks);
        this.setBlock(chunk, i + 3, j + 0, k + 8, dungeonBricks);
        this.setBlock(chunk, i + 3, j + 0, k + 9, dungeonBricks);
        this.setBlock(chunk, i + 3, j + 0, k + 10, dungeonBricks);
        this.setBlock(chunk, i + 3, j + 0, k + 11, dungeonBricks);
        this.setBlock(chunk, i + 3, j + 0, k + 12, dungeonBricks);
        this.setBlock(chunk, i + 3, j + 0, k + 13, dungeonBricks);
        this.setBlock(chunk, i + 3, j + 0, k + 14, dungeonBricks);
        this.setBlock(chunk, i + 3, j + 0, k + 15, ancientbricks);
        this.setBlock(chunk, i + 3, j + 1, k + 0, arcaniteMetal);
        this.setBlock(chunk, i + 3, j + 1, k + 7, dungeonBricks);
        this.setBlock(chunk, i + 3, j + 1, k + 8, dungeonBricks);
        this.setBlock(chunk, i + 3, j + 1, k + 15, arcaniteMetal);
        this.setBlock(chunk, i + 3, j + 2, k + 0, arcaniteMetal);
        this.setBlock(chunk, i + 3, j + 2, k + 15, arcaniteMetal);
        this.setBlock(chunk, i + 3, j + 3, k + 0, arcaniteMetal);
        this.setBlock(chunk, i + 3, j + 3, k + 15, arcaniteMetal);
        this.setBlock(chunk, i + 3, j + 4, k + 0, arcaniteMetal);
        this.setBlock(chunk, i + 3, j + 4, k + 15, arcaniteMetal);
        this.setBlock(chunk, i + 3, j + 5, k + 0, arcaniteMetal);
        this.setBlock(chunk, i + 3, j + 5, k + 15, arcaniteMetal);
        this.setBlock(chunk, i + 3, j + 6, k + 0, arcaniteMetal);
        this.setBlock(chunk, i + 3, j + 6, k + 15, arcaniteMetal);
        this.setBlock(chunk, i + 3, j + 7, k + 0, arcaniteMetal);
        this.setBlock(chunk, i + 3, j + 7, k + 5, dungeonBricks);
        this.setBlock(chunk, i + 3, j + 7, k + 6, dungeonBricks);
        this.setBlock(chunk, i + 3, j + 7, k + 9, dungeonBricks);
        this.setBlock(chunk, i + 3, j + 7, k + 10, dungeonBricks);
        this.setBlock(chunk, i + 3, j + 7, k + 15, arcaniteMetal);
        this.setBlock(chunk, i + 3, j + 8, k + 0, ancientstone);
        this.setBlock(chunk, i + 3, j + 8, k + 1, dungeonBricks);
        this.setBlock(chunk, i + 3, j + 8, k + 2, dungeonBricks);
        this.setBlock(chunk, i + 3, j + 8, k + 5, dungeonBricks);
        this.setBlock(chunk, i + 3, j + 8, k + 6, dungeonBricks);
        this.setBlock(chunk, i + 3, j + 8, k + 9, dungeonBricks);
        this.setBlock(chunk, i + 3, j + 8, k + 10, dungeonBricks);
        this.setBlock(chunk, i + 3, j + 8, k + 15, ancientstone);
        this.setBlock(chunk, i + 3, j + 9, k + 0, soulStone);
        this.setBlock(chunk, i + 3, j + 9, k + 15, soulStone);
        this.setBlock(chunk, i + 3, j + 10, k + 0, soulStone);
        this.setBlock(chunk, i + 3, j + 10, k + 15, soulStone);
        this.setBlock(chunk, i + 3, j + 11, k + 0, soulStone);
        this.setBlock(chunk, i + 3, j + 11, k + 15, soulStone);
        this.setBlock(chunk, i + 3, j + 12, k + 0, ancientbricks);
        this.setBlock(chunk, i + 3, j + 12, k + 15, ancientbricks);
        this.setBlock(chunk, i + 3, j + 13, k + 0, ancientstone);
        this.setBlock(chunk, i + 3, j + 13, k + 15, ancientstone);
        this.setBlock(chunk, i + 3, j + 14, k + 0, ancientstone);
        this.setBlock(chunk, i + 3, j + 14, k + 15, ancientstone);
        this.setBlock(chunk, i + 3, j + 15, k + 0, ancientstone);
        this.setBlock(chunk, i + 3, j + 15, k + 15, ancientstone);
        this.setBlock(chunk, i + 4, j + 0, k + 0, ancientbricks);
        this.setBlock(chunk, i + 4, j + 0, k + 1, dungeonBricks);
        this.setBlock(chunk, i + 4, j + 0, k + 2, dungeonBricks);
        this.setBlock(chunk, i + 4, j + 0, k + 3, dungeonBricks);
        this.setBlock(chunk, i + 4, j + 0, k + 4, dungeonBricks);
        this.setBlock(chunk, i + 4, j + 0, k + 5, dungeonBricks);
        this.setBlock(chunk, i + 4, j + 0, k + 6, dungeonBricks);
        this.setBlock(chunk, i + 4, j + 0, k + 7, dungeonBricks);
        this.setBlock(chunk, i + 4, j + 0, k + 8, dungeonBricks);
        this.setBlock(chunk, i + 4, j + 0, k + 9, dungeonBricks);
        this.setBlock(chunk, i + 4, j + 0, k + 10, dungeonBricks);
        this.setBlock(chunk, i + 4, j + 0, k + 11, dungeonBricks);
        this.setBlock(chunk, i + 4, j + 0, k + 12, dungeonBricks);
        this.setBlock(chunk, i + 4, j + 0, k + 13, dungeonBricks);
        this.setBlock(chunk, i + 4, j + 0, k + 14, dungeonBricks);
        this.setBlock(chunk, i + 4, j + 0, k + 15, ancientbricks);
        this.setBlock(chunk, i + 4, j + 1, k + 0, arcaniumSoulSludge);
        this.setBlock(chunk, i + 4, j + 1, k + 7, dungeonBricks);
        this.setBlock(chunk, i + 4, j + 1, k + 8, dungeonBricks);
        this.setBlock(chunk, i + 4, j + 1, k + 15, arcaniumSoulSludge);
        this.setBlock(chunk, i + 4, j + 2, k + 0, arcaniumSoulSludge);
        this.setBlock(chunk, i + 4, j + 2, k + 7, dungeonBricks);
        this.setBlock(chunk, i + 4, j + 2, k + 8, dungeonBricks);
        this.setBlock(chunk, i + 4, j + 2, k + 15, arcaniumSoulSludge);
        this.setBlock(chunk, i + 4, j + 3, k + 0, arcaniumSoulSludge);
        this.setBlock(chunk, i + 4, j + 3, k + 15, arcaniumSoulSludge);
        this.setBlock(chunk, i + 4, j + 4, k + 0, arcaniumSoulSludge);
        this.setBlock(chunk, i + 4, j + 4, k + 15, arcaniumSoulSludge);
        this.setBlock(chunk, i + 4, j + 5, k + 0, arcaniumSoulSludge);
        this.setBlock(chunk, i + 4, j + 5, k + 15, arcaniumSoulSludge);
        this.setBlock(chunk, i + 4, j + 6, k + 0, arcaniumSoulSludge);
        this.setBlock(chunk, i + 4, j + 6, k + 5, dungeonBricks);
        this.setBlock(chunk, i + 4, j + 6, k + 6, dungeonBricks);
        this.setBlock(chunk, i + 4, j + 6, k + 9, dungeonBricks);
        this.setBlock(chunk, i + 4, j + 6, k + 10, dungeonBricks);
        this.setBlock(chunk, i + 4, j + 6, k + 15, arcaniumSoulSludge);
        this.setBlock(chunk, i + 4, j + 7, k + 0, arcaniumSoulSludge);
        this.setBlock(chunk, i + 4, j + 7, k + 5, dungeonBricks);
        this.setBlock(chunk, i + 4, j + 7, k + 6, dungeonBricks);
        this.setBlock(chunk, i + 4, j + 7, k + 9, dungeonBricks);
        this.setBlock(chunk, i + 4, j + 7, k + 10, dungeonBricks);
        this.setBlock(chunk, i + 4, j + 7, k + 15, arcaniumSoulSludge);
        this.setBlock(chunk, i + 4, j + 8, k + 0, ancientstone);
        this.setBlock(chunk, i + 4, j + 8, k + 1, dungeonBricks);
        this.setBlock(chunk, i + 4, j + 8, k + 2, dungeonBricks);
        this.setBlock(chunk, i + 4, j + 8, k + 15, ancientstone);
        this.setBlock(chunk, i + 4, j + 9, k + 0, soulStone);
        this.setBlock(chunk, i + 4, j + 9, k + 15, soulStone);
        this.setBlock(chunk, i + 4, j + 10, k + 0, soulStone);
        this.setBlock(chunk, i + 4, j + 10, k + 15, soulStone);
        this.setBlock(chunk, i + 4, j + 11, k + 0, soulStone);
        this.setBlock(chunk, i + 4, j + 11, k + 15, soulStone);
        this.setBlock(chunk, i + 4, j + 12, k + 0, ancientbricks);
        this.setBlock(chunk, i + 4, j + 12, k + 15, ancientbricks);
        this.setBlock(chunk, i + 4, j + 13, k + 0, ancientstone);
        this.setBlock(chunk, i + 4, j + 13, k + 15, ancientstone);
        this.setBlock(chunk, i + 4, j + 14, k + 0, ancientstone);
        this.setBlock(chunk, i + 4, j + 14, k + 15, ancientstone);
        this.setBlock(chunk, i + 4, j + 15, k + 0, ancientstone);
        this.setBlock(chunk, i + 4, j + 15, k + 15, ancientstone);
        this.setBlock(chunk, i + 5, j + 0, k + 0, ancientbricks);
        this.setBlock(chunk, i + 5, j + 0, k + 1, dungeonBricks);
        this.setBlock(chunk, i + 5, j + 0, k + 2, dungeonBricks);
        this.setBlock(chunk, i + 5, j + 0, k + 3, dungeonBricks);
        this.setBlock(chunk, i + 5, j + 0, k + 4, dungeonBricks);
        this.setBlock(chunk, i + 5, j + 0, k + 5, dungeonBricks);
        this.setBlock(chunk, i + 5, j + 0, k + 6, dungeonBricks);
        this.setBlock(chunk, i + 5, j + 0, k + 7, dungeonBricks);
        this.setBlock(chunk, i + 5, j + 0, k + 8, dungeonBricks);
        this.setBlock(chunk, i + 5, j + 0, k + 9, dungeonBricks);
        this.setBlock(chunk, i + 5, j + 0, k + 10, dungeonBricks);
        this.setBlock(chunk, i + 5, j + 0, k + 11, dungeonBricks);
        this.setBlock(chunk, i + 5, j + 0, k + 12, dungeonBricks);
        this.setBlock(chunk, i + 5, j + 0, k + 13, dungeonBricks);
        this.setBlock(chunk, i + 5, j + 0, k + 14, dungeonBricks);
        this.setBlock(chunk, i + 5, j + 0, k + 15, ancientbricks);
        this.setBlock(chunk, i + 5, j + 1, k + 0, arcaniumSoulSludge);
        this.setBlock(chunk, i + 5, j + 1, k + 7, dungeonBricks);
        this.setBlock(chunk, i + 5, j + 1, k + 8, dungeonBricks);
        this.setBlock(chunk, i + 5, j + 1, k + 15, arcaniumSoulSludge);
        this.setBlock(chunk, i + 5, j + 2, k + 0, arcaniumSoulSludge);
        this.setBlock(chunk, i + 5, j + 2, k + 7, dungeonBricks);
        this.setBlock(chunk, i + 5, j + 2, k + 8, dungeonBricks);
        this.setBlock(chunk, i + 5, j + 2, k + 15, arcaniumSoulSludge);
        this.setBlock(chunk, i + 5, j + 3, k + 0, arcaniumSoulSludge);
        this.setBlock(chunk, i + 5, j + 3, k + 7, dungeonBricks);
        this.setBlock(chunk, i + 5, j + 3, k + 8, dungeonBricks);
        this.setBlock(chunk, i + 5, j + 3, k + 15, arcaniumSoulSludge);
        this.setBlock(chunk, i + 5, j + 4, k + 0, arcaniumSoulSludge);
        this.setBlock(chunk, i + 5, j + 4, k + 15, arcaniumSoulSludge);
        this.setBlock(chunk, i + 5, j + 5, k + 0, arcaniumSoulSludge);
        this.setBlock(chunk, i + 5, j + 5, k + 5, dungeonBricks);
        this.setBlock(chunk, i + 5, j + 5, k + 6, dungeonBricks);
        this.setBlock(chunk, i + 5, j + 5, k + 9, dungeonBricks);
        this.setBlock(chunk, i + 5, j + 5, k + 10, dungeonBricks);
        this.setBlock(chunk, i + 5, j + 5, k + 15, arcaniumSoulSludge);
        this.setBlock(chunk, i + 5, j + 6, k + 0, arcaniumSoulSludge);
        this.setBlock(chunk, i + 5, j + 6, k + 5, dungeonBricks);
        this.setBlock(chunk, i + 5, j + 6, k + 6, dungeonBricks);
        this.setBlock(chunk, i + 5, j + 6, k + 9, dungeonBricks);
        this.setBlock(chunk, i + 5, j + 6, k + 10, dungeonBricks);
        this.setBlock(chunk, i + 5, j + 6, k + 15, arcaniumSoulSludge);
        this.setBlock(chunk, i + 5, j + 7, k + 0, arcaniumSoulSludge);
        this.setBlock(chunk, i + 5, j + 7, k + 15, arcaniumSoulSludge);
        this.setBlock(chunk, i + 5, j + 8, k + 0, ancientstone);
        this.setBlock(chunk, i + 5, j + 8, k + 1, dungeonBricks);
        this.setBlock(chunk, i + 5, j + 8, k + 2, dungeonBricks);
        this.setBlock(chunk, i + 5, j + 8, k + 15, ancientstone);
        this.setBlock(chunk, i + 5, j + 9, k + 0, soulStone);
        this.setBlock(chunk, i + 5, j + 9, k + 15, soulStone);
        this.setBlock(chunk, i + 5, j + 10, k + 0, soulStone);
        this.setBlock(chunk, i + 5, j + 10, k + 15, soulStone);
        this.setBlock(chunk, i + 5, j + 11, k + 0, soulStone);
        this.setBlock(chunk, i + 5, j + 11, k + 15, soulStone);
        this.setBlock(chunk, i + 5, j + 12, k + 0, ancientbricks);
        this.setBlock(chunk, i + 5, j + 12, k + 15, ancientbricks);
        this.setBlock(chunk, i + 5, j + 13, k + 0, ancientstone);
        this.setBlock(chunk, i + 5, j + 13, k + 15, ancientstone);
        this.setBlock(chunk, i + 5, j + 14, k + 0, ancientstone);
        this.setBlock(chunk, i + 5, j + 14, k + 15, ancientstone);
        this.setBlock(chunk, i + 5, j + 15, k + 0, ancientstone);
        this.setBlock(chunk, i + 5, j + 15, k + 15, ancientstone);
        this.setBlock(chunk, i + 6, j + 0, k + 0, ancientbricks);
        this.setBlock(chunk, i + 6, j + 0, k + 1, dungeonBricks);
        this.setBlock(chunk, i + 6, j + 0, k + 2, dungeonBricks);
        this.setBlock(chunk, i + 6, j + 0, k + 3, dungeonBricks);
        this.setBlock(chunk, i + 6, j + 0, k + 4, dungeonBricks);
        this.setBlock(chunk, i + 6, j + 0, k + 5, dungeonBricks);
        this.setBlock(chunk, i + 6, j + 0, k + 6, dungeonBricks);
        this.setBlock(chunk, i + 6, j + 0, k + 7, dungeonBricks);
        this.setBlock(chunk, i + 6, j + 0, k + 8, dungeonBricks);
        this.setBlock(chunk, i + 6, j + 0, k + 9, dungeonBricks);
        this.setBlock(chunk, i + 6, j + 0, k + 10, dungeonBricks);
        this.setBlock(chunk, i + 6, j + 0, k + 11, dungeonBricks);
        this.setBlock(chunk, i + 6, j + 0, k + 12, dungeonBricks);
        this.setBlock(chunk, i + 6, j + 0, k + 13, dungeonBricks);
        this.setBlock(chunk, i + 6, j + 0, k + 14, dungeonBricks);
        this.setBlock(chunk, i + 6, j + 0, k + 15, ancientbricks);
        this.setBlock(chunk, i + 6, j + 1, k + 0, arcaniteMetal);
        this.setBlock(chunk, i + 6, j + 1, k + 7, BlockRegistry.dungeonLamp);
        this.setBlock(chunk, i + 6, j + 1, k + 8, BlockRegistry.dungeonLamp);
        this.setBlock(chunk, i + 6, j + 1, k + 15, arcaniteMetal);
        this.setBlock(chunk, i + 6, j + 2, k + 0, arcaniteMetal);
        this.setBlock(chunk, i + 6, j + 2, k + 7, dungeonBricks);
        this.setBlock(chunk, i + 6, j + 2, k + 8, dungeonBricks);
        this.setBlock(chunk, i + 6, j + 2, k + 15, arcaniteMetal);
        this.setBlock(chunk, i + 6, j + 3, k + 0, arcaniteMetal);
        this.setBlock(chunk, i + 6, j + 3, k + 7, dungeonBricks);
        this.setBlock(chunk, i + 6, j + 3, k + 8, dungeonBricks);
        this.setBlock(chunk, i + 6, j + 3, k + 15, arcaniteMetal);
        this.setBlock(chunk, i + 6, j + 4, k + 0, arcaniteMetal);
        this.setBlock(chunk, i + 6, j + 4, k + 7, dungeonBricks);
        this.setBlock(chunk, i + 6, j + 4, k + 8, dungeonBricks);
        this.setBlock(chunk, i + 6, j + 4, k + 15, arcaniteMetal);
        this.setBlock(chunk, i + 6, j + 5, k + 0, arcaniteMetal);
        this.setBlock(chunk, i + 6, j + 5, k + 5, dungeonBricks);
        this.setBlock(chunk, i + 6, j + 5, k + 6, dungeonBricks);
        this.setBlock(chunk, i + 6, j + 5, k + 9, dungeonBricks);
        this.setBlock(chunk, i + 6, j + 5, k + 10, dungeonBricks);
        this.setBlock(chunk, i + 6, j + 5, k + 15, arcaniteMetal);
        this.setBlock(chunk, i + 6, j + 6, k + 0, arcaniteMetal);
        this.setBlock(chunk, i + 6, j + 6, k + 15, arcaniteMetal);
        this.setBlock(chunk, i + 6, j + 7, k + 0, arcaniteMetal);
        this.setBlock(chunk, i + 6, j + 7, k + 15, arcaniteMetal);
        this.setBlock(chunk, i + 6, j + 8, k + 0, ancientstone);
        this.setBlock(chunk, i + 6, j + 8, k + 1, dungeonBricks);
        this.setBlock(chunk, i + 6, j + 8, k + 2, dungeonBricks);
        this.setBlock(chunk, i + 6, j + 8, k + 15, ancientstone);
        this.setBlock(chunk, i + 6, j + 9, k + 0, arcaniteMetal);
        this.setBlock(chunk, i + 6, j + 9, k + 15, soulStone);
        this.setBlock(chunk, i + 6, j + 10, k + 0, arcaniteMetal);
        this.setBlock(chunk, i + 6, j + 10, k + 15, soulStone);
        this.setBlock(chunk, i + 6, j + 11, k + 0, arcaniteMetal);
        this.setBlock(chunk, i + 6, j + 11, k + 15, soulStone);
        this.setBlock(chunk, i + 6, j + 12, k + 0, ancientbricks);
        this.setBlock(chunk, i + 6, j + 12, k + 15, ancientbricks);
        this.setBlock(chunk, i + 6, j + 13, k + 0, ancientstone);
        this.setBlock(chunk, i + 6, j + 13, k + 15, ancientstone);
        this.setBlock(chunk, i + 6, j + 14, k + 0, ancientstone);
        this.setBlock(chunk, i + 6, j + 14, k + 15, ancientstone);
        this.setBlock(chunk, i + 6, j + 15, k + 0, ancientstone);
        this.setBlock(chunk, i + 6, j + 15, k + 15, ancientstone);
        this.setBlock(chunk, i + 7, j + 0, k + 0, ancientbricks);
        this.setBlock(chunk, i + 7, j + 0, k + 1, dungeonBricks);
        this.setBlock(chunk, i + 7, j + 0, k + 2, dungeonBricks);
        this.setBlock(chunk, i + 7, j + 0, k + 3, dungeonBricks);
        this.setBlock(chunk, i + 7, j + 0, k + 4, dungeonBricks);
        this.setBlock(chunk, i + 7, j + 0, k + 5, dungeonBricks);
        this.setBlock(chunk, i + 7, j + 0, k + 6, dungeonBricks);
        this.setBlock(chunk, i + 7, j + 0, k + 7, dungeonBricks);
        this.setBlock(chunk, i + 7, j + 0, k + 8, dungeonBricks);
        this.setBlock(chunk, i + 7, j + 0, k + 9, dungeonBricks);
        this.setBlock(chunk, i + 7, j + 0, k + 10, dungeonBricks);
        this.setBlock(chunk, i + 7, j + 0, k + 11, dungeonBricks);
        this.setBlock(chunk, i + 7, j + 0, k + 12, dungeonBricks);
        this.setBlock(chunk, i + 7, j + 0, k + 13, dungeonBricks);
        this.setBlock(chunk, i + 7, j + 0, k + 14, dungeonBricks);
        this.setBlock(chunk, i + 7, j + 0, k + 15, ancientbricks);
        this.setBlock(chunk, i + 7, j + 1, k + 0, arcaniumSoulSludge);
        this.setBlock(chunk, i + 7, j + 1, k + 15, arcaniumSoulSludge);
        this.setBlock(chunk, i + 7, j + 2, k + 0, arcaniumSoulSludge);
        this.setBlock(chunk, i + 7, j + 2, k + 15, arcaniumSoulSludge);
        this.setBlock(chunk, i + 7, j + 3, k + 0, arcaniumSoulSludge);
        this.setBlock(chunk, i + 7, j + 3, k + 15, arcaniumSoulSludge);
        this.setBlock(chunk, i + 7, j + 4, k + 0, arcaniumSoulSludge);
        this.setBlock(chunk, i + 7, j + 4, k + 5, dungeonBricks);
        this.setBlock(chunk, i + 7, j + 4, k + 6, dungeonBricks);
        this.setBlock(chunk, i + 7, j + 4, k + 7, dungeonBricks);
        this.setBlock(chunk, i + 7, j + 4, k + 8, dungeonBricks);
        this.setBlock(chunk, i + 7, j + 4, k + 9, dungeonBricks);
        this.setBlock(chunk, i + 7, j + 4, k + 10, dungeonBricks);
        this.setBlock(chunk, i + 7, j + 4, k + 15, arcaniumSoulSludge);
        this.setBlock(chunk, i + 7, j + 5, k + 0, arcaniumSoulSludge);
        this.setBlock(chunk, i + 7, j + 5, k + 15, arcaniumSoulSludge);
        this.setBlock(chunk, i + 7, j + 6, k + 0, arcaniumSoulSludge);
        this.setBlock(chunk, i + 7, j + 6, k + 15, arcaniumSoulSludge);
        this.setBlock(chunk, i + 7, j + 7, k + 0, arcaniumSoulSludge);
        this.setBlock(chunk, i + 7, j + 7, k + 15, arcaniumSoulSludge);
        this.setBlock(chunk, i + 7, j + 8, k + 0, ancientstone);
        this.setBlock(chunk, i + 7, j + 8, k + 1, dungeonBricks);
        this.setBlock(chunk, i + 7, j + 8, k + 2, dungeonBricks);
        this.setBlock(chunk, i + 7, j + 8, k + 15, ancientstone);
        this.setBlock(chunk, i + 7, j + 9, k + 15, soulStone);
        this.setBlock(chunk, i + 7, j + 10, k + 15, soulStone);
        this.setBlock(chunk, i + 7, j + 11, k + 0, arcanaPower);
        this.setBlock(chunk, i + 7, j + 11, k + 15, soulStone);
        this.setBlock(chunk, i + 7, j + 12, k + 0, ancientbricks);
        this.setBlock(chunk, i + 7, j + 12, k + 15, ancientbricks);
        this.setBlock(chunk, i + 7, j + 13, k + 0, ancientstone);
        this.setBlock(chunk, i + 7, j + 13, k + 15, ancientstone);
        this.setBlock(chunk, i + 7, j + 14, k + 0, ancientstone);
        this.setBlock(chunk, i + 7, j + 14, k + 15, ancientstone);
        this.setBlock(chunk, i + 7, j + 15, k + 0, ancientstone);
        this.setBlock(chunk, i + 7, j + 15, k + 15, ancientstone);
        this.setBlock(chunk, i + 8, j + 0, k + 0, ancientbricks);
        this.setBlock(chunk, i + 8, j + 0, k + 1, dungeonBricks);
        this.setBlock(chunk, i + 8, j + 0, k + 2, dungeonBricks);
        this.setBlock(chunk, i + 8, j + 0, k + 3, dungeonBricks);
        this.setBlock(chunk, i + 8, j + 0, k + 4, dungeonBricks);
        this.setBlock(chunk, i + 8, j + 0, k + 5, dungeonBricks);
        this.setBlock(chunk, i + 8, j + 0, k + 6, dungeonBricks);
        this.setBlock(chunk, i + 8, j + 0, k + 7, dungeonBricks);
        this.setBlock(chunk, i + 8, j + 0, k + 8, dungeonBricks);
        this.setBlock(chunk, i + 8, j + 0, k + 9, dungeonBricks);
        this.setBlock(chunk, i + 8, j + 0, k + 10, dungeonBricks);
        this.setBlock(chunk, i + 8, j + 0, k + 11, dungeonBricks);
        this.setBlock(chunk, i + 8, j + 0, k + 12, dungeonBricks);
        this.setBlock(chunk, i + 8, j + 0, k + 13, dungeonBricks);
        this.setBlock(chunk, i + 8, j + 0, k + 14, dungeonBricks);
        this.setBlock(chunk, i + 8, j + 0, k + 15, ancientbricks);
        this.setBlock(chunk, i + 8, j + 1, k + 0, arcaniumSoulSludge);
        this.setBlock(chunk, i + 8, j + 1, k + 15, arcaniumSoulSludge);
        this.setBlock(chunk, i + 8, j + 2, k + 0, arcaniumSoulSludge);
        this.setBlock(chunk, i + 8, j + 2, k + 15, arcaniumSoulSludge);
        this.setBlock(chunk, i + 8, j + 3, k + 0, arcaniumSoulSludge);
        this.setBlock(chunk, i + 8, j + 3, k + 7, dungeonBricks);
        this.setBlock(chunk, i + 8, j + 3, k + 8, dungeonBricks);
        this.setBlock(chunk, i + 8, j + 3, k + 15, arcaniumSoulSludge);
        this.setBlock(chunk, i + 8, j + 4, k + 0, arcaniumSoulSludge);
        this.setBlock(chunk, i + 8, j + 4, k + 5, dungeonBricks);
        this.setBlock(chunk, i + 8, j + 4, k + 6, dungeonBricks);
        this.setBlock(chunk, i + 8, j + 4, k + 7, dungeonBricks);
        this.setBlock(chunk, i + 8, j + 4, k + 8, dungeonBricks);
        this.setBlock(chunk, i + 8, j + 4, k + 9, dungeonBricks);
        this.setBlock(chunk, i + 8, j + 4, k + 10, dungeonBricks);
        this.setBlock(chunk, i + 8, j + 4, k + 15, arcaniumSoulSludge);
        this.setBlock(chunk, i + 8, j + 5, k + 0, arcaniumSoulSludge);
        this.setBlock(chunk, i + 8, j + 5, k + 15, arcaniumSoulSludge);
        this.setBlock(chunk, i + 8, j + 6, k + 0, arcaniumSoulSludge);
        this.setBlock(chunk, i + 8, j + 6, k + 15, arcaniumSoulSludge);
        this.setBlock(chunk, i + 8, j + 7, k + 0, arcaniumSoulSludge);
        this.setBlock(chunk, i + 8, j + 7, k + 15, arcaniumSoulSludge);
        this.setBlock(chunk, i + 8, j + 8, k + 0, ancientstone);
        this.setBlock(chunk, i + 8, j + 8, k + 1, dungeonBricks);
        this.setBlock(chunk, i + 8, j + 8, k + 2, dungeonBricks);
        this.setBlock(chunk, i + 8, j + 8, k + 15, ancientstone);
        this.setBlock(chunk, i + 8, j + 9, k + 15, soulStone);
        this.setBlock(chunk, i + 8, j + 10, k + 15, soulStone);
        this.setBlock(chunk, i + 8, j + 11, k + 0, arcanaPower);
        this.setBlock(chunk, i + 8, j + 11, k + 15, soulStone);
        this.setBlock(chunk, i + 8, j + 12, k + 0, ancientbricks);
        this.setBlock(chunk, i + 8, j + 12, k + 15, ancientbricks);
        this.setBlock(chunk, i + 8, j + 13, k + 0, ancientstone);
        this.setBlock(chunk, i + 8, j + 13, k + 15, ancientstone);
        this.setBlock(chunk, i + 8, j + 14, k + 0, ancientstone);
        this.setBlock(chunk, i + 8, j + 14, k + 15, ancientstone);
        this.setBlock(chunk, i + 8, j + 15, k + 0, ancientstone);
        this.setBlock(chunk, i + 8, j + 15, k + 15, ancientstone);
        this.setBlock(chunk, i + 9, j + 0, k + 0, ancientbricks);
        this.setBlock(chunk, i + 9, j + 0, k + 1, dungeonBricks);
        this.setBlock(chunk, i + 9, j + 0, k + 2, dungeonBricks);
        this.setBlock(chunk, i + 9, j + 0, k + 3, dungeonBricks);
        this.setBlock(chunk, i + 9, j + 0, k + 4, dungeonBricks);
        this.setBlock(chunk, i + 9, j + 0, k + 5, dungeonBricks);
        this.setBlock(chunk, i + 9, j + 0, k + 6, dungeonBricks);
        this.setBlock(chunk, i + 9, j + 0, k + 7, dungeonBricks);
        this.setBlock(chunk, i + 9, j + 0, k + 8, dungeonBricks);
        this.setBlock(chunk, i + 9, j + 0, k + 9, dungeonBricks);
        this.setBlock(chunk, i + 9, j + 0, k + 10, dungeonBricks);
        this.setBlock(chunk, i + 9, j + 0, k + 11, dungeonBricks);
        this.setBlock(chunk, i + 9, j + 0, k + 12, dungeonBricks);
        this.setBlock(chunk, i + 9, j + 0, k + 13, dungeonBricks);
        this.setBlock(chunk, i + 9, j + 0, k + 14, dungeonBricks);
        this.setBlock(chunk, i + 9, j + 0, k + 15, ancientbricks);
        this.setBlock(chunk, i + 9, j + 1, k + 0, arcaniteMetal);
        this.setBlock(chunk, i + 9, j + 1, k + 7, BlockRegistry.dungeonLamp);
        this.setBlock(chunk, i + 9, j + 1, k + 8, BlockRegistry.dungeonLamp);
        this.setBlock(chunk, i + 9, j + 1, k + 15, arcaniteMetal);
        this.setBlock(chunk, i + 9, j + 2, k + 0, arcaniteMetal);
        this.setBlock(chunk, i + 9, j + 2, k + 7, dungeonBricks);
        this.setBlock(chunk, i + 9, j + 2, k + 8, dungeonBricks);
        this.setBlock(chunk, i + 9, j + 2, k + 15, arcaniteMetal);
        this.setBlock(chunk, i + 9, j + 3, k + 0, arcaniteMetal);
        this.setBlock(chunk, i + 9, j + 3, k + 7, dungeonBricks);
        this.setBlock(chunk, i + 9, j + 3, k + 8, dungeonBricks);
        this.setBlock(chunk, i + 9, j + 3, k + 15, arcaniteMetal);
        this.setBlock(chunk, i + 9, j + 4, k + 0, arcaniteMetal);
        this.setBlock(chunk, i + 9, j + 4, k + 15, arcaniteMetal);
        this.setBlock(chunk, i + 9, j + 5, k + 0, arcaniteMetal);
        this.setBlock(chunk, i + 9, j + 5, k + 15, arcaniteMetal);
        this.setBlock(chunk, i + 9, j + 6, k + 0, arcaniteMetal);
        this.setBlock(chunk, i + 9, j + 6, k + 15, arcaniteMetal);
        this.setBlock(chunk, i + 9, j + 7, k + 0, arcaniteMetal);
        this.setBlock(chunk, i + 9, j + 7, k + 15, arcaniteMetal);
        this.setBlock(chunk, i + 9, j + 8, k + 0, ancientstone);
        this.setBlock(chunk, i + 9, j + 8, k + 15, ancientstone);
        this.setBlock(chunk, i + 9, j + 9, k + 0, arcaniteMetal);
        this.setBlock(chunk, i + 9, j + 9, k + 15, soulStone);
        this.setBlock(chunk, i + 9, j + 10, k + 0, arcaniteMetal);
        this.setBlock(chunk, i + 9, j + 10, k + 15, soulStone);
        this.setBlock(chunk, i + 9, j + 11, k + 0, arcaniteMetal);
        this.setBlock(chunk, i + 9, j + 11, k + 15, soulStone);
        this.setBlock(chunk, i + 9, j + 12, k + 0, ancientbricks);
        this.setBlock(chunk, i + 9, j + 12, k + 4, dungeonBricks);
        this.setBlock(chunk, i + 9, j + 12, k + 11, dungeonBricks);
        this.setBlock(chunk, i + 9, j + 12, k + 15, ancientbricks);
        this.setBlock(chunk, i + 9, j + 13, k + 0, ancientstone);
        this.setBlock(chunk, i + 9, j + 13, k + 4, BlockRegistry.dungeonLamp);
        this.setBlock(chunk, i + 9, j + 13, k + 11, BlockRegistry.dungeonLamp);
        this.setBlock(chunk, i + 9, j + 13, k + 15, ancientstone);
        this.setBlock(chunk, i + 9, j + 14, k + 0, ancientstone);
        this.setBlock(chunk, i + 9, j + 14, k + 15, ancientstone);
        this.setBlock(chunk, i + 9, j + 15, k + 0, ancientstone);
        this.setBlock(chunk, i + 9, j + 15, k + 15, ancientstone);
        this.setBlock(chunk, i + 10, j + 0, k + 0, ancientbricks);
        this.setBlock(chunk, i + 10, j + 0, k + 1, dungeonBricks);
        this.setBlock(chunk, i + 10, j + 0, k + 2, dungeonBricks);
        this.setBlock(chunk, i + 10, j + 0, k + 3, dungeonBricks);
        this.setBlock(chunk, i + 10, j + 0, k + 4, dungeonBricks);
        this.setBlock(chunk, i + 10, j + 0, k + 5, dungeonBricks);
        this.setBlock(chunk, i + 10, j + 0, k + 6, dungeonBricks);
        this.setBlock(chunk, i + 10, j + 0, k + 7, dungeonBricks);
        this.setBlock(chunk, i + 10, j + 0, k + 8, dungeonBricks);
        this.setBlock(chunk, i + 10, j + 0, k + 9, dungeonBricks);
        this.setBlock(chunk, i + 10, j + 0, k + 10, dungeonBricks);
        this.setBlock(chunk, i + 10, j + 0, k + 11, dungeonBricks);
        this.setBlock(chunk, i + 10, j + 0, k + 12, dungeonBricks);
        this.setBlock(chunk, i + 10, j + 0, k + 13, dungeonBricks);
        this.setBlock(chunk, i + 10, j + 0, k + 14, dungeonBricks);
        this.setBlock(chunk, i + 10, j + 0, k + 15, ancientbricks);
        this.setBlock(chunk, i + 10, j + 1, k + 0, arcaniumSoulSludge);
        this.setBlock(chunk, i + 10, j + 1, k + 7, dungeonBricks);
        this.setBlock(chunk, i + 10, j + 1, k + 8, dungeonBricks);
        this.setBlock(chunk, i + 10, j + 1, k + 15, arcaniumSoulSludge);
        this.setBlock(chunk, i + 10, j + 2, k + 0, arcaniumSoulSludge);
        this.setBlock(chunk, i + 10, j + 2, k + 7, dungeonBricks);
        this.setBlock(chunk, i + 10, j + 2, k + 8, dungeonBricks);
        this.setBlock(chunk, i + 10, j + 2, k + 15, arcaniumSoulSludge);
        this.setBlock(chunk, i + 10, j + 3, k + 0, arcaniumSoulSludge);
        this.setBlock(chunk, i + 10, j + 3, k + 15, arcaniumSoulSludge);
        this.setBlock(chunk, i + 10, j + 4, k + 0, arcaniumSoulSludge);
        this.setBlock(chunk, i + 10, j + 4, k + 15, arcaniumSoulSludge);
        this.setBlock(chunk, i + 10, j + 5, k + 0, arcaniumSoulSludge);
        this.setBlock(chunk, i + 10, j + 5, k + 15, arcaniumSoulSludge);
        this.setBlock(chunk, i + 10, j + 6, k + 0, arcaniumSoulSludge);
        this.setBlock(chunk, i + 10, j + 6, k + 15, arcaniumSoulSludge);
        this.setBlock(chunk, i + 10, j + 7, k + 0, arcaniumSoulSludge);
        this.setBlock(chunk, i + 10, j + 7, k + 15, arcaniumSoulSludge);
        this.setBlock(chunk, i + 10, j + 8, k + 0, ancientstone);
        this.setBlock(chunk, i + 10, j + 8, k + 15, ancientstone);
        this.setBlock(chunk, i + 10, j + 9, k + 0, soulStone);
        this.setBlock(chunk, i + 10, j + 9, k + 15, soulStone);
        this.setBlock(chunk, i + 10, j + 10, k + 0, soulStone);
        this.setBlock(chunk, i + 10, j + 10, k + 15, soulStone);
        this.setBlock(chunk, i + 10, j + 11, k + 0, soulStone);
        this.setBlock(chunk, i + 10, j + 11, k + 15, soulStone);
        this.setBlock(chunk, i + 10, j + 12, k + 0, ancientbricks);
        this.setBlock(chunk, i + 10, j + 12, k + 4, dungeonBricks);
        this.setBlock(chunk, i + 10, j + 12, k + 11, dungeonBricks);
        this.setBlock(chunk, i + 10, j + 12, k + 15, ancientbricks);
        this.setBlock(chunk, i + 10, j + 13, k + 0, ancientstone);
        this.setBlock(chunk, i + 10, j + 13, k + 15, ancientstone);
        this.setBlock(chunk, i + 10, j + 14, k + 0, ancientstone);
        this.setBlock(chunk, i + 10, j + 14, k + 15, ancientstone);
        this.setBlock(chunk, i + 10, j + 15, k + 0, ancientstone);
        this.setBlock(chunk, i + 10, j + 15, k + 15, ancientstone);
        this.setBlock(chunk, i + 11, j + 0, k + 0, ancientbricks);
        this.setBlock(chunk, i + 11, j + 0, k + 1, dungeonBricks);
        this.setBlock(chunk, i + 11, j + 0, k + 2, dungeonBricks);
        this.setBlock(chunk, i + 11, j + 0, k + 3, dungeonBricks);
        this.setBlock(chunk, i + 11, j + 0, k + 4, dungeonBricks);
        this.setBlock(chunk, i + 11, j + 0, k + 5, dungeonBricks);
        this.setBlock(chunk, i + 11, j + 0, k + 6, dungeonBricks);
        this.setBlock(chunk, i + 11, j + 0, k + 7, dungeonBricks);
        this.setBlock(chunk, i + 11, j + 0, k + 8, dungeonBricks);
        this.setBlock(chunk, i + 11, j + 0, k + 9, dungeonBricks);
        this.setBlock(chunk, i + 11, j + 0, k + 10, dungeonBricks);
        this.setBlock(chunk, i + 11, j + 0, k + 11, dungeonBricks);
        this.setBlock(chunk, i + 11, j + 0, k + 12, dungeonBricks);
        this.setBlock(chunk, i + 11, j + 0, k + 13, dungeonBricks);
        this.setBlock(chunk, i + 11, j + 0, k + 14, dungeonBricks);
        this.setBlock(chunk, i + 11, j + 0, k + 15, ancientbricks);
        this.setBlock(chunk, i + 11, j + 1, k + 0, arcaniumSoulSludge);
        this.setBlock(chunk, i + 11, j + 1, k + 7, dungeonBricks);
        this.setBlock(chunk, i + 11, j + 1, k + 8, dungeonBricks);
        this.setBlock(chunk, i + 11, j + 1, k + 15, arcaniumSoulSludge);
        this.setBlock(chunk, i + 11, j + 2, k + 0, arcaniumSoulSludge);
        this.setBlock(chunk, i + 11, j + 2, k + 15, arcaniumSoulSludge);
        this.setBlock(chunk, i + 11, j + 3, k + 0, arcaniumSoulSludge);
        this.setBlock(chunk, i + 11, j + 3, k + 15, arcaniumSoulSludge);
        this.setBlock(chunk, i + 11, j + 4, k + 0, arcaniumSoulSludge);
        this.setBlock(chunk, i + 11, j + 4, k + 15, arcaniumSoulSludge);
        this.setBlock(chunk, i + 11, j + 5, k + 0, arcaniumSoulSludge);
        this.setBlock(chunk, i + 11, j + 5, k + 15, arcaniumSoulSludge);
        this.setBlock(chunk, i + 11, j + 6, k + 0, arcaniumSoulSludge);
        this.setBlock(chunk, i + 11, j + 6, k + 15, arcaniumSoulSludge);
        this.setBlock(chunk, i + 11, j + 7, k + 0, arcaniumSoulSludge);
        this.setBlock(chunk, i + 11, j + 7, k + 15, arcaniumSoulSludge);
        this.setBlock(chunk, i + 11, j + 8, k + 0, ancientstone);
        this.setBlock(chunk, i + 11, j + 8, k + 15, ancientstone);
        this.setBlock(chunk, i + 11, j + 9, k + 0, soulStone);
        this.setBlock(chunk, i + 11, j + 9, k + 15, soulStone);
        this.setBlock(chunk, i + 11, j + 10, k + 0, soulStone);
        this.setBlock(chunk, i + 11, j + 10, k + 15, soulStone);
        this.setBlock(chunk, i + 11, j + 11, k + 0, soulStone);
        this.setBlock(chunk, i + 11, j + 11, k + 15, soulStone);
        this.setBlock(chunk, i + 11, j + 12, k + 0, ancientbricks);
        this.setBlock(chunk, i + 11, j + 12, k + 2, dungeonBricks);
        this.setBlock(chunk, i + 11, j + 12, k + 3, dungeonBricks);
        this.setBlock(chunk, i + 11, j + 12, k + 4, dungeonBricks);
        this.setBlock(chunk, i + 11, j + 12, k + 5, dungeonBricks);
        this.setBlock(chunk, i + 11, j + 12, k + 6, dungeonBricks);
        this.setBlock(chunk, i + 11, j + 12, k + 9, dungeonBricks);
        this.setBlock(chunk, i + 11, j + 12, k + 10, dungeonBricks);
        this.setBlock(chunk, i + 11, j + 12, k + 11, dungeonBricks);
        this.setBlock(chunk, i + 11, j + 12, k + 12, dungeonBricks);
        this.setBlock(chunk, i + 11, j + 12, k + 13, dungeonBricks);
        this.setBlock(chunk, i + 11, j + 12, k + 15, ancientbricks);
        this.setBlock(chunk, i + 11, j + 13, k + 0, ancientstone);
        this.setBlock(chunk, i + 11, j + 13, k + 2, BlockRegistry.dungeonLamp);
        this.setBlock(chunk, i + 11, j + 13, k + 4, dungeonBricks);
        this.setBlock(chunk, i + 11, j + 13, k + 6, BlockRegistry.dungeonLamp);
        this.setBlock(chunk, i + 11, j + 13, k + 9, BlockRegistry.dungeonLamp);
        this.setBlock(chunk, i + 11, j + 13, k + 11, dungeonBricks);
        this.setBlock(chunk, i + 11, j + 13, k + 13, BlockRegistry.dungeonLamp);
        this.setBlock(chunk, i + 11, j + 13, k + 15, ancientstone);
        this.setBlock(chunk, i + 11, j + 14, k + 0, ancientstone);
        this.setBlock(chunk, i + 11, j + 14, k + 4, dungeonBricks);
        this.setBlock(chunk, i + 11, j + 14, k + 11, dungeonBricks);
        this.setBlock(chunk, i + 11, j + 14, k + 15, ancientstone);
        this.setBlock(chunk, i + 11, j + 15, k + 0, ancientstone);
        this.setBlock(chunk, i + 11, j + 15, k + 11, dungeonBricks);
        this.setBlock(chunk, i + 11, j + 15, k + 15, ancientstone);
        this.setBlock(chunk, i + 12, j + 0, k + 0, ancientbricks);
        this.setBlock(chunk, i + 12, j + 0, k + 1, dungeonBricks);
        this.setBlock(chunk, i + 12, j + 0, k + 2, dungeonBricks);
        this.setBlock(chunk, i + 12, j + 0, k + 3, dungeonBricks);
        this.setBlock(chunk, i + 12, j + 0, k + 4, dungeonBricks);
        this.setBlock(chunk, i + 12, j + 0, k + 5, dungeonBricks);
        this.setBlock(chunk, i + 12, j + 0, k + 6, dungeonBricks);
        this.setBlock(chunk, i + 12, j + 0, k + 7, dungeonBricks);
        this.setBlock(chunk, i + 12, j + 0, k + 8, dungeonBricks);
        this.setBlock(chunk, i + 12, j + 0, k + 9, dungeonBricks);
        this.setBlock(chunk, i + 12, j + 0, k + 10, dungeonBricks);
        this.setBlock(chunk, i + 12, j + 0, k + 11, dungeonBricks);
        this.setBlock(chunk, i + 12, j + 0, k + 12, dungeonBricks);
        this.setBlock(chunk, i + 12, j + 0, k + 13, dungeonBricks);
        this.setBlock(chunk, i + 12, j + 0, k + 14, dungeonBricks);
        this.setBlock(chunk, i + 12, j + 0, k + 15, ancientbricks);
        this.setBlock(chunk, i + 12, j + 1, k + 0, arcaniteMetal);
        this.setBlock(chunk, i + 12, j + 1, k + 15, arcaniteMetal);
        this.setBlock(chunk, i + 12, j + 2, k + 0, arcaniteMetal);
        this.setBlock(chunk, i + 12, j + 2, k + 15, arcaniteMetal);
        this.setBlock(chunk, i + 12, j + 3, k + 0, arcaniteMetal);
        this.setBlock(chunk, i + 12, j + 3, k + 15, arcaniteMetal);
        this.setBlock(chunk, i + 12, j + 4, k + 0, arcaniteMetal);
        this.setBlock(chunk, i + 12, j + 4, k + 15, arcaniteMetal);
        this.setBlock(chunk, i + 12, j + 5, k + 0, arcaniteMetal);
        this.setBlock(chunk, i + 12, j + 5, k + 15, arcaniteMetal);
        this.setBlock(chunk, i + 12, j + 6, k + 0, arcaniteMetal);
        this.setBlock(chunk, i + 12, j + 6, k + 15, arcaniteMetal);
        this.setBlock(chunk, i + 12, j + 7, k + 0, arcaniteMetal);
        this.setBlock(chunk, i + 12, j + 7, k + 15, arcaniteMetal);
        this.setBlock(chunk, i + 12, j + 8, k + 0, ancientstone);
        this.setBlock(chunk, i + 12, j + 8, k + 15, ancientstone);
        this.setBlock(chunk, i + 12, j + 9, k + 0, soulStone);
        this.setBlock(chunk, i + 12, j + 9, k + 15, soulStone);
        this.setBlock(chunk, i + 12, j + 10, k + 0, soulStone);
        this.setBlock(chunk, i + 12, j + 10, k + 15, soulStone);
        this.setBlock(chunk, i + 12, j + 11, k + 0, soulStone);
        this.setBlock(chunk, i + 12, j + 11, k + 15, soulStone);
        this.setBlock(chunk, i + 12, j + 12, k + 0, ancientbricks);
        this.setBlock(chunk, i + 12, j + 12, k + 15, ancientbricks);
        this.setBlock(chunk, i + 12, j + 13, k + 0, ancientstone);
        this.setBlock(chunk, i + 12, j + 13, k + 15, ancientstone);
        this.setBlock(chunk, i + 12, j + 14, k + 0, ancientstone);
        this.setBlock(chunk, i + 12, j + 14, k + 15, ancientstone);
        this.setBlock(chunk, i + 12, j + 15, k + 0, ancientstone);
        this.setBlock(chunk, i + 12, j + 15, k + 15, ancientstone);
        this.setBlock(chunk, i + 13, j + 0, k + 0, ancientbricks);
        this.setBlock(chunk, i + 13, j + 0, k + 1, dungeonBricks);
        this.setBlock(chunk, i + 13, j + 0, k + 2, dungeonBricks);
        this.setBlock(chunk, i + 13, j + 0, k + 3, dungeonBricks);
        this.setBlock(chunk, i + 13, j + 0, k + 4, dungeonBricks);
        this.setBlock(chunk, i + 13, j + 0, k + 5, dungeonBricks);
        this.setBlock(chunk, i + 13, j + 0, k + 6, dungeonBricks);
        this.setBlock(chunk, i + 13, j + 0, k + 7, dungeonBricks);
        this.setBlock(chunk, i + 13, j + 0, k + 8, dungeonBricks);
        this.setBlock(chunk, i + 13, j + 0, k + 9, dungeonBricks);
        this.setBlock(chunk, i + 13, j + 0, k + 10, dungeonBricks);
        this.setBlock(chunk, i + 13, j + 0, k + 11, dungeonBricks);
        this.setBlock(chunk, i + 13, j + 0, k + 12, dungeonBricks);
        this.setBlock(chunk, i + 13, j + 0, k + 13, dungeonBricks);
        this.setBlock(chunk, i + 13, j + 0, k + 14, dungeonBricks);
        this.setBlock(chunk, i + 13, j + 0, k + 15, ancientbricks);
        this.setBlock(chunk, i + 13, j + 1, k + 0, arcaniumSoulSludge);
        this.setBlock(chunk, i + 13, j + 1, k + 15, arcaniumSoulSludge);
        this.setBlock(chunk, i + 13, j + 2, k + 0, arcaniumSoulSludge);
        this.setBlock(chunk, i + 13, j + 2, k + 15, arcaniumSoulSludge);
        this.setBlock(chunk, i + 13, j + 3, k + 0, arcaniumSoulSludge);
        this.setBlock(chunk, i + 13, j + 3, k + 15, arcaniumSoulSludge);
        this.setBlock(chunk, i + 13, j + 4, k + 0, arcaniumSoulSludge);
        this.setBlock(chunk, i + 13, j + 4, k + 15, arcaniumSoulSludge);
        this.setBlock(chunk, i + 13, j + 5, k + 0, arcaniumSoulSludge);
        this.setBlock(chunk, i + 13, j + 5, k + 15, arcaniumSoulSludge);
        this.setBlock(chunk, i + 13, j + 6, k + 0, arcaniumSoulSludge);
        this.setBlock(chunk, i + 13, j + 6, k + 15, arcaniumSoulSludge);
        this.setBlock(chunk, i + 13, j + 7, k + 0, arcaniumSoulSludge);
        this.setBlock(chunk, i + 13, j + 7, k + 15, arcaniumSoulSludge);
        this.setBlock(chunk, i + 13, j + 8, k + 0, ancientstone);
        this.setBlock(chunk, i + 13, j + 8, k + 15, ancientstone);
        this.setBlock(chunk, i + 13, j + 9, k + 0, soulStone);
        this.setBlock(chunk, i + 13, j + 9, k + 15, soulStone);
        this.setBlock(chunk, i + 13, j + 10, k + 0, soulStone);
        this.setBlock(chunk, i + 13, j + 10, k + 15, soulStone);
        this.setBlock(chunk, i + 13, j + 11, k + 0, soulStone);
        this.setBlock(chunk, i + 13, j + 11, k + 15, soulStone);
        this.setBlock(chunk, i + 13, j + 12, k + 0, ancientbricks);
        this.setBlock(chunk, i + 13, j + 12, k + 15, ancientbricks);
        this.setBlock(chunk, i + 13, j + 13, k + 0, ancientstone);
        this.setBlock(chunk, i + 13, j + 13, k + 15, ancientstone);
        this.setBlock(chunk, i + 13, j + 14, k + 0, ancientstone);
        this.setBlock(chunk, i + 13, j + 14, k + 15, ancientstone);
        this.setBlock(chunk, i + 13, j + 15, k + 0, ancientstone);
        this.setBlock(chunk, i + 13, j + 15, k + 15, ancientstone);
        this.setBlock(chunk, i + 14, j + 0, k + 0, ancientbricks);
        this.setBlock(chunk, i + 14, j + 0, k + 1, dungeonBricks);
        this.setBlock(chunk, i + 14, j + 0, k + 2, dungeonBricks);
        this.setBlock(chunk, i + 14, j + 0, k + 3, dungeonBricks);
        this.setBlock(chunk, i + 14, j + 0, k + 4, dungeonBricks);
        this.setBlock(chunk, i + 14, j + 0, k + 5, dungeonBricks);
        this.setBlock(chunk, i + 14, j + 0, k + 6, dungeonBricks);
        this.setBlock(chunk, i + 14, j + 0, k + 7, dungeonBricks);
        this.setBlock(chunk, i + 14, j + 0, k + 8, dungeonBricks);
        this.setBlock(chunk, i + 14, j + 0, k + 9, dungeonBricks);
        this.setBlock(chunk, i + 14, j + 0, k + 10, dungeonBricks);
        this.setBlock(chunk, i + 14, j + 0, k + 11, dungeonBricks);
        this.setBlock(chunk, i + 14, j + 0, k + 12, dungeonBricks);
        this.setBlock(chunk, i + 14, j + 0, k + 13, dungeonBricks);
        this.setBlock(chunk, i + 14, j + 0, k + 14, dungeonBricks);
        this.setBlock(chunk, i + 14, j + 0, k + 15, ancientbricks);
        this.setBlock(chunk, i + 14, j + 1, k + 0, arcaniumSoulSludge);
        this.setBlock(chunk, i + 14, j + 1, k + 15, arcaniumSoulSludge);
        this.setBlock(chunk, i + 14, j + 2, k + 0, arcaniumSoulSludge);
        this.setBlock(chunk, i + 14, j + 2, k + 15, arcaniumSoulSludge);
        this.setBlock(chunk, i + 14, j + 3, k + 0, arcaniumSoulSludge);
        this.setBlock(chunk, i + 14, j + 3, k + 15, arcaniumSoulSludge);
        this.setBlock(chunk, i + 14, j + 4, k + 0, arcaniumSoulSludge);
        this.setBlock(chunk, i + 14, j + 4, k + 15, arcaniumSoulSludge);
        this.setBlock(chunk, i + 14, j + 5, k + 0, arcaniumSoulSludge);
        this.setBlock(chunk, i + 14, j + 5, k + 15, arcaniumSoulSludge);
        this.setBlock(chunk, i + 14, j + 6, k + 0, arcaniumSoulSludge);
        this.setBlock(chunk, i + 14, j + 6, k + 15, arcaniumSoulSludge);
        this.setBlock(chunk, i + 14, j + 7, k + 0, arcaniumSoulSludge);
        this.setBlock(chunk, i + 14, j + 7, k + 15, arcaniumSoulSludge);
        this.setBlock(chunk, i + 14, j + 8, k + 0, ancientstone);
        this.setBlock(chunk, i + 14, j + 8, k + 15, ancientstone);
        this.setBlock(chunk, i + 14, j + 9, k + 0, soulStone);
        this.setBlock(chunk, i + 14, j + 9, k + 15, soulStone);
        this.setBlock(chunk, i + 14, j + 10, k + 0, soulStone);
        this.setBlock(chunk, i + 14, j + 10, k + 15, soulStone);
        this.setBlock(chunk, i + 14, j + 11, k + 0, soulStone);
        this.setBlock(chunk, i + 14, j + 11, k + 15, soulStone);
        this.setBlock(chunk, i + 14, j + 12, k + 0, ancientbricks);
        this.setBlock(chunk, i + 14, j + 12, k + 15, ancientbricks);
        this.setBlock(chunk, i + 14, j + 13, k + 0, ancientstone);
        this.setBlock(chunk, i + 14, j + 13, k + 15, ancientstone);
        this.setBlock(chunk, i + 14, j + 14, k + 0, ancientstone);
        this.setBlock(chunk, i + 14, j + 14, k + 15, ancientstone);
        this.setBlock(chunk, i + 14, j + 15, k + 0, ancientstone);
        this.setBlock(chunk, i + 14, j + 15, k + 15, ancientstone);
        this.setBlock(chunk, i + 15, j + 0, k + 0, ancientbricks);
        this.setBlock(chunk, i + 15, j + 0, k + 1, ancientbricks);
        this.setBlock(chunk, i + 15, j + 0, k + 2, ancientbricks);
        this.setBlock(chunk, i + 15, j + 0, k + 3, ancientbricks);
        this.setBlock(chunk, i + 15, j + 0, k + 4, ancientbricks);
        this.setBlock(chunk, i + 15, j + 0, k + 5, ancientbricks);
        this.setBlock(chunk, i + 15, j + 0, k + 6, ancientbricks);
        this.setBlock(chunk, i + 15, j + 0, k + 7, ancientbricks);
        this.setBlock(chunk, i + 15, j + 0, k + 8, ancientbricks);
        this.setBlock(chunk, i + 15, j + 0, k + 9, ancientbricks);
        this.setBlock(chunk, i + 15, j + 0, k + 10, ancientbricks);
        this.setBlock(chunk, i + 15, j + 0, k + 11, ancientbricks);
        this.setBlock(chunk, i + 15, j + 0, k + 12, ancientbricks);
        this.setBlock(chunk, i + 15, j + 0, k + 13, ancientbricks);
        this.setBlock(chunk, i + 15, j + 0, k + 14, ancientbricks);
        this.setBlock(chunk, i + 15, j + 0, k + 15, ancientbricks);
        this.setBlock(chunk, i + 15, j + 1, k + 0, arcaniteMetal);
        this.setBlock(chunk, i + 15, j + 1, k + 1, arcaniumSoulSludge);
        this.setBlock(chunk, i + 15, j + 1, k + 2, arcaniumSoulSludge);
        this.setBlock(chunk, i + 15, j + 1, k + 3, arcaniteMetal);
        this.setBlock(chunk, i + 15, j + 1, k + 4, arcaniumSoulSludge);
        this.setBlock(chunk, i + 15, j + 1, k + 5, arcaniumSoulSludge);
        this.setBlock(chunk, i + 15, j + 1, k + 6, arcaniteMetal);
        this.setBlock(chunk, i + 15, j + 1, k + 9, arcaniteMetal);
        this.setBlock(chunk, i + 15, j + 1, k + 10, arcaniumSoulSludge);
        this.setBlock(chunk, i + 15, j + 1, k + 11, arcaniumSoulSludge);
        this.setBlock(chunk, i + 15, j + 1, k + 12, arcaniteMetal);
        this.setBlock(chunk, i + 15, j + 1, k + 13, arcaniumSoulSludge);
        this.setBlock(chunk, i + 15, j + 1, k + 14, arcaniumSoulSludge);
        this.setBlock(chunk, i + 15, j + 1, k + 15, arcaniteMetal);
        this.setBlock(chunk, i + 15, j + 2, k + 0, arcaniteMetal);
        this.setBlock(chunk, i + 15, j + 2, k + 1, arcaniumSoulSludge);
        this.setBlock(chunk, i + 15, j + 2, k + 2, arcaniumSoulSludge);
        this.setBlock(chunk, i + 15, j + 2, k + 3, arcaniteMetal);
        this.setBlock(chunk, i + 15, j + 2, k + 4, arcaniumSoulSludge);
        this.setBlock(chunk, i + 15, j + 2, k + 5, arcaniumSoulSludge);
        this.setBlock(chunk, i + 15, j + 2, k + 6, arcaniteMetal);
        this.setBlock(chunk, i + 15, j + 2, k + 9, arcaniteMetal);
        this.setBlock(chunk, i + 15, j + 2, k + 10, arcaniumSoulSludge);
        this.setBlock(chunk, i + 15, j + 2, k + 11, arcaniumSoulSludge);
        this.setBlock(chunk, i + 15, j + 2, k + 12, arcaniteMetal);
        this.setBlock(chunk, i + 15, j + 2, k + 13, arcaniumSoulSludge);
        this.setBlock(chunk, i + 15, j + 2, k + 14, arcaniumSoulSludge);
        this.setBlock(chunk, i + 15, j + 2, k + 15, arcaniteMetal);
        this.setBlock(chunk, i + 15, j + 3, k + 0, arcaniteMetal);
        this.setBlock(chunk, i + 15, j + 3, k + 1, arcaniumSoulSludge);
        this.setBlock(chunk, i + 15, j + 3, k + 2, arcaniumSoulSludge);
        this.setBlock(chunk, i + 15, j + 3, k + 3, arcaniteMetal);
        this.setBlock(chunk, i + 15, j + 3, k + 4, arcaniumSoulSludge);
        this.setBlock(chunk, i + 15, j + 3, k + 5, arcaniumSoulSludge);
        this.setBlock(chunk, i + 15, j + 3, k + 6, arcaniteMetal);
        this.setBlock(chunk, i + 15, j + 3, k + 7, arcanaPower);
        this.setBlock(chunk, i + 15, j + 3, k + 8, arcanaPower);
        this.setBlock(chunk, i + 15, j + 3, k + 9, arcaniteMetal);
        this.setBlock(chunk, i + 15, j + 3, k + 10, arcaniumSoulSludge);
        this.setBlock(chunk, i + 15, j + 3, k + 11, arcaniumSoulSludge);
        this.setBlock(chunk, i + 15, j + 3, k + 12, arcaniteMetal);
        this.setBlock(chunk, i + 15, j + 3, k + 13, arcaniumSoulSludge);
        this.setBlock(chunk, i + 15, j + 3, k + 14, arcaniumSoulSludge);
        this.setBlock(chunk, i + 15, j + 3, k + 15, arcaniteMetal);
        this.setBlock(chunk, i + 15, j + 4, k + 0, arcaniteMetal);
        this.setBlock(chunk, i + 15, j + 4, k + 1, arcaniumSoulSludge);
        this.setBlock(chunk, i + 15, j + 4, k + 2, arcaniumSoulSludge);
        this.setBlock(chunk, i + 15, j + 4, k + 3, arcaniteMetal);
        this.setBlock(chunk, i + 15, j + 4, k + 4, arcaniumSoulSludge);
        this.setBlock(chunk, i + 15, j + 4, k + 5, arcaniumSoulSludge);
        this.setBlock(chunk, i + 15, j + 4, k + 6, arcaniteMetal);
        this.setBlock(chunk, i + 15, j + 4, k + 7, arcaniumSoulSludge);
        this.setBlock(chunk, i + 15, j + 4, k + 8, arcaniumSoulSludge);
        this.setBlock(chunk, i + 15, j + 4, k + 9, arcaniteMetal);
        this.setBlock(chunk, i + 15, j + 4, k + 10, arcaniumSoulSludge);
        this.setBlock(chunk, i + 15, j + 4, k + 11, arcaniumSoulSludge);
        this.setBlock(chunk, i + 15, j + 4, k + 12, arcaniteMetal);
        this.setBlock(chunk, i + 15, j + 4, k + 13, arcaniumSoulSludge);
        this.setBlock(chunk, i + 15, j + 4, k + 14, arcaniumSoulSludge);
        this.setBlock(chunk, i + 15, j + 4, k + 15, arcaniteMetal);
        this.setBlock(chunk, i + 15, j + 5, k + 0, arcaniteMetal);
        this.setBlock(chunk, i + 15, j + 5, k + 1, arcaniumSoulSludge);
        this.setBlock(chunk, i + 15, j + 5, k + 2, arcaniumSoulSludge);
        this.setBlock(chunk, i + 15, j + 5, k + 3, arcaniteMetal);
        this.setBlock(chunk, i + 15, j + 5, k + 4, arcaniumSoulSludge);
        this.setBlock(chunk, i + 15, j + 5, k + 5, arcaniumSoulSludge);
        this.setBlock(chunk, i + 15, j + 5, k + 6, arcaniteMetal);
        this.setBlock(chunk, i + 15, j + 5, k + 7, arcaniumSoulSludge);
        this.setBlock(chunk, i + 15, j + 5, k + 8, arcaniumSoulSludge);
        this.setBlock(chunk, i + 15, j + 5, k + 9, arcaniteMetal);
        this.setBlock(chunk, i + 15, j + 5, k + 10, arcaniumSoulSludge);
        this.setBlock(chunk, i + 15, j + 5, k + 11, arcaniumSoulSludge);
        this.setBlock(chunk, i + 15, j + 5, k + 12, arcaniteMetal);
        this.setBlock(chunk, i + 15, j + 5, k + 13, arcaniumSoulSludge);
        this.setBlock(chunk, i + 15, j + 5, k + 14, arcaniumSoulSludge);
        this.setBlock(chunk, i + 15, j + 5, k + 15, arcaniteMetal);
        this.setBlock(chunk, i + 15, j + 6, k + 0, arcaniteMetal);
        this.setBlock(chunk, i + 15, j + 6, k + 1, arcaniumSoulSludge);
        this.setBlock(chunk, i + 15, j + 6, k + 2, arcaniumSoulSludge);
        this.setBlock(chunk, i + 15, j + 6, k + 3, arcaniteMetal);
        this.setBlock(chunk, i + 15, j + 6, k + 4, arcaniumSoulSludge);
        this.setBlock(chunk, i + 15, j + 6, k + 5, arcaniumSoulSludge);
        this.setBlock(chunk, i + 15, j + 6, k + 6, arcaniteMetal);
        this.setBlock(chunk, i + 15, j + 6, k + 7, arcaniumSoulSludge);
        this.setBlock(chunk, i + 15, j + 6, k + 8, arcaniumSoulSludge);
        this.setBlock(chunk, i + 15, j + 6, k + 9, arcaniteMetal);
        this.setBlock(chunk, i + 15, j + 6, k + 10, arcaniumSoulSludge);
        this.setBlock(chunk, i + 15, j + 6, k + 11, arcaniumSoulSludge);
        this.setBlock(chunk, i + 15, j + 6, k + 12, arcaniteMetal);
        this.setBlock(chunk, i + 15, j + 6, k + 13, arcaniumSoulSludge);
        this.setBlock(chunk, i + 15, j + 6, k + 14, arcaniumSoulSludge);
        this.setBlock(chunk, i + 15, j + 6, k + 15, arcaniteMetal);
        this.setBlock(chunk, i + 15, j + 7, k + 0, arcaniteMetal);
        this.setBlock(chunk, i + 15, j + 7, k + 1, arcaniumSoulSludge);
        this.setBlock(chunk, i + 15, j + 7, k + 2, arcaniumSoulSludge);
        this.setBlock(chunk, i + 15, j + 7, k + 3, arcaniteMetal);
        this.setBlock(chunk, i + 15, j + 7, k + 4, arcaniumSoulSludge);
        this.setBlock(chunk, i + 15, j + 7, k + 5, arcaniumSoulSludge);
        this.setBlock(chunk, i + 15, j + 7, k + 6, arcaniteMetal);
        this.setBlock(chunk, i + 15, j + 7, k + 7, arcaniumSoulSludge);
        this.setBlock(chunk, i + 15, j + 7, k + 8, arcaniumSoulSludge);
        this.setBlock(chunk, i + 15, j + 7, k + 9, arcaniteMetal);
        this.setBlock(chunk, i + 15, j + 7, k + 10, arcaniumSoulSludge);
        this.setBlock(chunk, i + 15, j + 7, k + 11, arcaniumSoulSludge);
        this.setBlock(chunk, i + 15, j + 7, k + 12, arcaniteMetal);
        this.setBlock(chunk, i + 15, j + 7, k + 13, arcaniumSoulSludge);
        this.setBlock(chunk, i + 15, j + 7, k + 14, arcaniumSoulSludge);
        this.setBlock(chunk, i + 15, j + 7, k + 15, arcaniteMetal);
        this.setBlock(chunk, i + 15, j + 8, k + 0, ancientstone);
        this.setBlock(chunk, i + 15, j + 8, k + 1, ancientstone);
        this.setBlock(chunk, i + 15, j + 8, k + 2, ancientstone);
        this.setBlock(chunk, i + 15, j + 8, k + 3, ancientstone);
        this.setBlock(chunk, i + 15, j + 8, k + 4, ancientstone);
        this.setBlock(chunk, i + 15, j + 8, k + 5, ancientstone);
        this.setBlock(chunk, i + 15, j + 8, k + 6, ancientstone);
        this.setBlock(chunk, i + 15, j + 8, k + 7, ancientstone);
        this.setBlock(chunk, i + 15, j + 8, k + 8, ancientstone);
        this.setBlock(chunk, i + 15, j + 8, k + 9, ancientstone);
        this.setBlock(chunk, i + 15, j + 8, k + 10, ancientstone);
        this.setBlock(chunk, i + 15, j + 8, k + 11, ancientstone);
        this.setBlock(chunk, i + 15, j + 8, k + 12, ancientstone);
        this.setBlock(chunk, i + 15, j + 8, k + 13, ancientstone);
        this.setBlock(chunk, i + 15, j + 8, k + 14, ancientstone);
        this.setBlock(chunk, i + 15, j + 8, k + 15, ancientstone);
        this.setBlock(chunk, i + 15, j + 9, k + 0, soulStone);
        this.setBlock(chunk, i + 15, j + 9, k + 1, soulStone);
        this.setBlock(chunk, i + 15, j + 9, k + 2, soulStone);
        this.setBlock(chunk, i + 15, j + 9, k + 3, soulStone);
        this.setBlock(chunk, i + 15, j + 9, k + 4, soulStone);
        this.setBlock(chunk, i + 15, j + 9, k + 5, soulStone);
        this.setBlock(chunk, i + 15, j + 9, k + 6, soulStone);
        this.setBlock(chunk, i + 15, j + 9, k + 7, soulStone);
        this.setBlock(chunk, i + 15, j + 9, k + 8, soulStone);
        this.setBlock(chunk, i + 15, j + 9, k + 9, soulStone);
        this.setBlock(chunk, i + 15, j + 9, k + 10, soulStone);
        this.setBlock(chunk, i + 15, j + 9, k + 11, soulStone);
        this.setBlock(chunk, i + 15, j + 9, k + 12, soulStone);
        this.setBlock(chunk, i + 15, j + 9, k + 13, soulStone);
        this.setBlock(chunk, i + 15, j + 9, k + 14, soulStone);
        this.setBlock(chunk, i + 15, j + 9, k + 15, soulStone);
        this.setBlock(chunk, i + 15, j + 10, k + 0, soulStone);
        this.setBlock(chunk, i + 15, j + 10, k + 1, soulStone);
        this.setBlock(chunk, i + 15, j + 10, k + 2, soulStone);
        this.setBlock(chunk, i + 15, j + 10, k + 3, soulStone);
        this.setBlock(chunk, i + 15, j + 10, k + 4, soulStone);
        this.setBlock(chunk, i + 15, j + 10, k + 5, soulStone);
        this.setBlock(chunk, i + 15, j + 10, k + 6, soulStone);
        this.setBlock(chunk, i + 15, j + 10, k + 7, soulStone);
        this.setBlock(chunk, i + 15, j + 10, k + 8, soulStone);
        this.setBlock(chunk, i + 15, j + 10, k + 9, soulStone);
        this.setBlock(chunk, i + 15, j + 10, k + 10, soulStone);
        this.setBlock(chunk, i + 15, j + 10, k + 11, soulStone);
        this.setBlock(chunk, i + 15, j + 10, k + 12, soulStone);
        this.setBlock(chunk, i + 15, j + 10, k + 13, soulStone);
        this.setBlock(chunk, i + 15, j + 10, k + 14, soulStone);
        this.setBlock(chunk, i + 15, j + 10, k + 15, soulStone);
        this.setBlock(chunk, i + 15, j + 11, k + 0, soulStone);
        this.setBlock(chunk, i + 15, j + 11, k + 1, soulStone);
        this.setBlock(chunk, i + 15, j + 11, k + 2, soulStone);
        this.setBlock(chunk, i + 15, j + 11, k + 3, soulStone);
        this.setBlock(chunk, i + 15, j + 11, k + 4, soulStone);
        this.setBlock(chunk, i + 15, j + 11, k + 5, soulStone);
        this.setBlock(chunk, i + 15, j + 11, k + 6, soulStone);
        this.setBlock(chunk, i + 15, j + 11, k + 7, soulStone);
        this.setBlock(chunk, i + 15, j + 11, k + 8, soulStone);
        this.setBlock(chunk, i + 15, j + 11, k + 9, soulStone);
        this.setBlock(chunk, i + 15, j + 11, k + 10, soulStone);
        this.setBlock(chunk, i + 15, j + 11, k + 11, soulStone);
        this.setBlock(chunk, i + 15, j + 11, k + 12, soulStone);
        this.setBlock(chunk, i + 15, j + 11, k + 13, soulStone);
        this.setBlock(chunk, i + 15, j + 11, k + 14, soulStone);
        this.setBlock(chunk, i + 15, j + 11, k + 15, soulStone);
        this.setBlock(chunk, i + 15, j + 12, k + 0, ancientbricks);
        this.setBlock(chunk, i + 15, j + 12, k + 1, ancientbricks);
        this.setBlock(chunk, i + 15, j + 12, k + 2, ancientbricks);
        this.setBlock(chunk, i + 15, j + 12, k + 3, ancientbricks);
        this.setBlock(chunk, i + 15, j + 12, k + 4, ancientbricks);
        this.setBlock(chunk, i + 15, j + 12, k + 5, ancientbricks);
        this.setBlock(chunk, i + 15, j + 12, k + 6, ancientbricks);
        this.setBlock(chunk, i + 15, j + 12, k + 7, ancientbricks);
        this.setBlock(chunk, i + 15, j + 12, k + 8, ancientbricks);
        this.setBlock(chunk, i + 15, j + 12, k + 9, ancientbricks);
        this.setBlock(chunk, i + 15, j + 12, k + 10, ancientbricks);
        this.setBlock(chunk, i + 15, j + 12, k + 11, ancientbricks);
        this.setBlock(chunk, i + 15, j + 12, k + 12, ancientbricks);
        this.setBlock(chunk, i + 15, j + 12, k + 13, ancientbricks);
        this.setBlock(chunk, i + 15, j + 12, k + 14, ancientbricks);
        this.setBlock(chunk, i + 15, j + 12, k + 15, ancientbricks);
        this.setBlock(chunk, i + 15, j + 13, k + 0, ancientstone);
        this.setBlock(chunk, i + 15, j + 13, k + 1, ancientstone);
        this.setBlock(chunk, i + 15, j + 13, k + 2, ancientstone);
        this.setBlock(chunk, i + 15, j + 13, k + 3, ancientstone);
        this.setBlock(chunk, i + 15, j + 13, k + 4, ancientstone);
        this.setBlock(chunk, i + 15, j + 13, k + 5, ancientstone);
        this.setBlock(chunk, i + 15, j + 13, k + 6, ancientstone);
        this.setBlock(chunk, i + 15, j + 13, k + 7, ancientstone);
        this.setBlock(chunk, i + 15, j + 13, k + 8, ancientstone);
        this.setBlock(chunk, i + 15, j + 13, k + 9, ancientstone);
        this.setBlock(chunk, i + 15, j + 13, k + 10, ancientstone);
        this.setBlock(chunk, i + 15, j + 13, k + 11, ancientstone);
        this.setBlock(chunk, i + 15, j + 13, k + 12, ancientstone);
        this.setBlock(chunk, i + 15, j + 13, k + 13, ancientstone);
        this.setBlock(chunk, i + 15, j + 13, k + 14, ancientstone);
        this.setBlock(chunk, i + 15, j + 13, k + 15, ancientstone);
        this.setBlock(chunk, i + 15, j + 14, k + 0, ancientstone);
        this.setBlock(chunk, i + 15, j + 14, k + 1, ancientstone);
        this.setBlock(chunk, i + 15, j + 14, k + 2, ancientstone);
        this.setBlock(chunk, i + 15, j + 14, k + 3, ancientstone);
        this.setBlock(chunk, i + 15, j + 14, k + 4, ancientstone);
        this.setBlock(chunk, i + 15, j + 14, k + 5, ancientstone);
        this.setBlock(chunk, i + 15, j + 14, k + 6, ancientstone);
        this.setBlock(chunk, i + 15, j + 14, k + 7, ancientstone);
        this.setBlock(chunk, i + 15, j + 14, k + 8, ancientstone);
        this.setBlock(chunk, i + 15, j + 14, k + 9, ancientstone);
        this.setBlock(chunk, i + 15, j + 14, k + 10, ancientstone);
        this.setBlock(chunk, i + 15, j + 14, k + 11, ancientstone);
        this.setBlock(chunk, i + 15, j + 14, k + 12, ancientstone);
        this.setBlock(chunk, i + 15, j + 14, k + 13, ancientstone);
        this.setBlock(chunk, i + 15, j + 14, k + 14, ancientstone);
        this.setBlock(chunk, i + 15, j + 14, k + 15, ancientstone);
        this.setBlock(chunk, i + 15, j + 15, k + 0, ancientstone);
        this.setBlock(chunk, i + 15, j + 15, k + 1, ancientstone);
        this.setBlock(chunk, i + 15, j + 15, k + 2, ancientstone);
        this.setBlock(chunk, i + 15, j + 15, k + 3, ancientstone);
        this.setBlock(chunk, i + 15, j + 15, k + 4, ancientstone);
        this.setBlock(chunk, i + 15, j + 15, k + 5, ancientstone);
        this.setBlock(chunk, i + 15, j + 15, k + 6, ancientstone);
        this.setBlock(chunk, i + 15, j + 15, k + 7, ancientstone);
        this.setBlock(chunk, i + 15, j + 15, k + 8, ancientstone);
        this.setBlock(chunk, i + 15, j + 15, k + 9, ancientstone);
        this.setBlock(chunk, i + 15, j + 15, k + 10, ancientstone);
        this.setBlock(chunk, i + 15, j + 15, k + 11, ancientstone);
        this.setBlock(chunk, i + 15, j + 15, k + 12, ancientstone);
        this.setBlock(chunk, i + 15, j + 15, k + 13, ancientstone);
        this.setBlock(chunk, i + 15, j + 15, k + 14, ancientstone);
        this.setBlock(chunk, i + 15, j + 15, k + 15, ancientstone);
        return true;
    }
}