package divinerpg.dimensions.arcana.components;

import java.util.Random;

import divinerpg.registry.BlockRegistry;
import net.minecraft.block.Block;
import net.minecraft.init.Blocks;
import net.minecraft.util.math.BlockPos;
import net.minecraft.world.World;
import net.minecraft.world.gen.feature.WorldGenerator;


public class DungeonComponentDramix extends WorldGenerator {
    @Override
    public boolean generate(World world, Random rand, BlockPos position) {
        int i = position.getX();
        int j = position.getY();
        int k = position.getZ();
        for (int n = 0; n < 32; n++) {
            for (int m = 0; m < 32; m++) {
                for (int o = 0; o < 16; o++) {
                    this.setBlock(world, i + n, j + o, k + m, Blocks.AIR);
                }
            }
        }

        this.setBlock(world, i + 0, j + 0, k + 0, BlockRegistry.ancientBrick);
        this.setBlock(world, i + 0, j + 0, k + 1, BlockRegistry.ancientBrick);
        this.setBlock(world, i + 0, j + 0, k + 2, BlockRegistry.ancientBrick);
        this.setBlock(world, i + 0, j + 0, k + 3, BlockRegistry.ancientBrick);
        this.setBlock(world, i + 0, j + 0, k + 4, BlockRegistry.ancientBrick);
        this.setBlock(world, i + 0, j + 0, k + 5, BlockRegistry.ancientBrick);
        this.setBlock(world, i + 0, j + 0, k + 6, BlockRegistry.ancientBrick);
        this.setBlock(world, i + 0, j + 0, k + 7, BlockRegistry.ancientBrick);
        this.setBlock(world, i + 0, j + 0, k + 8, BlockRegistry.ancientBrick);
        this.setBlock(world, i + 0, j + 0, k + 9, BlockRegistry.ancientBrick);
        this.setBlock(world, i + 0, j + 0, k + 10, BlockRegistry.ancientBrick);
        this.setBlock(world, i + 0, j + 0, k + 11, BlockRegistry.ancientBrick);
        this.setBlock(world, i + 0, j + 0, k + 12, BlockRegistry.ancientBrick);
        this.setBlock(world, i + 0, j + 0, k + 13, BlockRegistry.ancientBrick);
        this.setBlock(world, i + 0, j + 0, k + 14, BlockRegistry.ancientBrick);
        this.setBlock(world, i + 0, j + 0, k + 15, BlockRegistry.ancientBrick);
        this.setBlock(world, i + 0, j + 0, k + 16, BlockRegistry.ancientBrick);
        this.setBlock(world, i + 0, j + 0, k + 17, BlockRegistry.ancientBrick);
        this.setBlock(world, i + 0, j + 0, k + 18, BlockRegistry.ancientBrick);
        this.setBlock(world, i + 0, j + 0, k + 19, BlockRegistry.ancientBrick);
        this.setBlock(world, i + 0, j + 0, k + 20, BlockRegistry.ancientBrick);
        this.setBlock(world, i + 0, j + 0, k + 21, BlockRegistry.ancientBrick);
        this.setBlock(world, i + 0, j + 0, k + 22, BlockRegistry.ancientBrick);
        this.setBlock(world, i + 0, j + 0, k + 23, BlockRegistry.ancientBrick);
        this.setBlock(world, i + 0, j + 0, k + 24, BlockRegistry.ancientBrick);
        this.setBlock(world, i + 0, j + 0, k + 25, BlockRegistry.ancientBrick);
        this.setBlock(world, i + 0, j + 0, k + 26, BlockRegistry.ancientBrick);
        this.setBlock(world, i + 0, j + 0, k + 27, BlockRegistry.ancientBrick);
        this.setBlock(world, i + 0, j + 0, k + 28, BlockRegistry.ancientBrick);
        this.setBlock(world, i + 0, j + 0, k + 29, BlockRegistry.ancientBrick);
        this.setBlock(world, i + 0, j + 0, k + 30, BlockRegistry.ancientBrick);
        this.setBlock(world, i + 0, j + 0, k + 31, BlockRegistry.ancientBrick);
        this.setBlock(world, i + 0, j + 1, k + 0, BlockRegistry.ancientBrick);
        this.setBlock(world, i + 0, j + 1, k + 1, BlockRegistry.ancientBrick);
        this.setBlock(world, i + 0, j + 1, k + 2, BlockRegistry.ancientBrick);
        this.setBlock(world, i + 0, j + 1, k + 3, BlockRegistry.ancientBrick);
        this.setBlock(world, i + 0, j + 1, k + 4, BlockRegistry.ancientBrick);
        this.setBlock(world, i + 0, j + 1, k + 5, BlockRegistry.ancientBrick);
        this.setBlock(world, i + 0, j + 1, k + 6, BlockRegistry.ancientBrick);
        this.setBlock(world, i + 0, j + 1, k + 7, BlockRegistry.ancientBrick);
        this.setBlock(world, i + 0, j + 1, k + 8, BlockRegistry.ancientBrick);
        this.setBlock(world, i + 0, j + 1, k + 9, BlockRegistry.ancientBrick);
        this.setBlock(world, i + 0, j + 1, k + 10, BlockRegistry.ancientBrick);
        this.setBlock(world, i + 0, j + 1, k + 11, BlockRegistry.ancientBrick);
        this.setBlock(world, i + 0, j + 1, k + 12, BlockRegistry.ancientBrick);
        this.setBlock(world, i + 0, j + 1, k + 13, BlockRegistry.ancientBrick);
        this.setBlock(world, i + 0, j + 1, k + 14, BlockRegistry.ancientBrick);
        this.setBlock(world, i + 0, j + 1, k + 15, BlockRegistry.ancientBrick);
        this.setBlock(world, i + 0, j + 1, k + 16, BlockRegistry.ancientBrick);
        this.setBlock(world, i + 0, j + 1, k + 17, BlockRegistry.ancientBrick);
        this.setBlock(world, i + 0, j + 1, k + 18, BlockRegistry.ancientBrick);
        this.setBlock(world, i + 0, j + 1, k + 19, BlockRegistry.ancientBrick);
        this.setBlock(world, i + 0, j + 1, k + 20, BlockRegistry.ancientBrick);
        this.setBlock(world, i + 0, j + 1, k + 21, BlockRegistry.ancientBrick);
        this.setBlock(world, i + 0, j + 1, k + 22, BlockRegistry.ancientBrick);
        this.setBlock(world, i + 0, j + 1, k + 23, BlockRegistry.ancientBrick);
        this.setBlock(world, i + 0, j + 1, k + 24, BlockRegistry.ancientBrick);
        this.setBlock(world, i + 0, j + 1, k + 25, BlockRegistry.ancientBrick);
        this.setBlock(world, i + 0, j + 1, k + 26, BlockRegistry.ancientBrick);
        this.setBlock(world, i + 0, j + 1, k + 27, BlockRegistry.ancientBrick);
        this.setBlock(world, i + 0, j + 1, k + 28, BlockRegistry.ancientBrick);
        this.setBlock(world, i + 0, j + 1, k + 29, BlockRegistry.ancientBrick);
        this.setBlock(world, i + 0, j + 1, k + 30, BlockRegistry.ancientBrick);
        this.setBlock(world, i + 0, j + 1, k + 31, BlockRegistry.ancientBrick);
        this.setBlock(world, i + 0, j + 2, k + 0, BlockRegistry.ancientBrick);
        this.setBlock(world, i + 0, j + 2, k + 1, BlockRegistry.ancientBrick);
        this.setBlock(world, i + 0, j + 2, k + 2, BlockRegistry.ancientBrick);
        this.setBlock(world, i + 0, j + 2, k + 3, BlockRegistry.ancientBrick);
        this.setBlock(world, i + 0, j + 2, k + 4, BlockRegistry.ancientBrick);
        this.setBlock(world, i + 0, j + 2, k + 5, BlockRegistry.ancientBrick);
        this.setBlock(world, i + 0, j + 2, k + 6, BlockRegistry.ancientBrick);
        this.setBlock(world, i + 0, j + 2, k + 7, BlockRegistry.ancientBrick);
        this.setBlock(world, i + 0, j + 2, k + 8, BlockRegistry.ancientBrick);
        this.setBlock(world, i + 0, j + 2, k + 9, BlockRegistry.ancientBrick);
        this.setBlock(world, i + 0, j + 2, k + 10, BlockRegistry.ancientBrick);
        this.setBlock(world, i + 0, j + 2, k + 11, BlockRegistry.ancientBrick);
        this.setBlock(world, i + 0, j + 2, k + 12, BlockRegistry.ancientBrick);
        this.setBlock(world, i + 0, j + 2, k + 13, BlockRegistry.ancientBrick);
        this.setBlock(world, i + 0, j + 2, k + 14, BlockRegistry.ancientBrick);
        this.setBlock(world, i + 0, j + 2, k + 15, BlockRegistry.ancientBrick);
        this.setBlock(world, i + 0, j + 2, k + 16, BlockRegistry.ancientBrick);
        this.setBlock(world, i + 0, j + 2, k + 17, BlockRegistry.ancientBrick);
        this.setBlock(world, i + 0, j + 2, k + 18, BlockRegistry.ancientBrick);
        this.setBlock(world, i + 0, j + 2, k + 19, BlockRegistry.ancientBrick);
        this.setBlock(world, i + 0, j + 2, k + 20, BlockRegistry.ancientBrick);
        this.setBlock(world, i + 0, j + 2, k + 21, BlockRegistry.ancientBrick);
        this.setBlock(world, i + 0, j + 2, k + 22, BlockRegistry.ancientBrick);
        this.setBlock(world, i + 0, j + 2, k + 23, BlockRegistry.ancientBrick);
        this.setBlock(world, i + 0, j + 2, k + 24, BlockRegistry.ancientBrick);
        this.setBlock(world, i + 0, j + 2, k + 25, BlockRegistry.ancientBrick);
        this.setBlock(world, i + 0, j + 2, k + 26, BlockRegistry.ancientBrick);
        this.setBlock(world, i + 0, j + 2, k + 27, BlockRegistry.ancientBrick);
        this.setBlock(world, i + 0, j + 2, k + 28, BlockRegistry.ancientBrick);
        this.setBlock(world, i + 0, j + 2, k + 29, BlockRegistry.ancientBrick);
        this.setBlock(world, i + 0, j + 2, k + 30, BlockRegistry.ancientBrick);
        this.setBlock(world, i + 0, j + 2, k + 31, BlockRegistry.ancientBrick);
        this.setBlock(world, i + 0, j + 3, k + 0, BlockRegistry.ancientBrick);
        this.setBlock(world, i + 0, j + 3, k + 1, BlockRegistry.ancientBrick);
        this.setBlock(world, i + 0, j + 3, k + 2, BlockRegistry.ancientBrick);
        this.setBlock(world, i + 0, j + 3, k + 3, BlockRegistry.ancientBrick);
        this.setBlock(world, i + 0, j + 3, k + 4, BlockRegistry.ancientBrick);
        this.setBlock(world, i + 0, j + 3, k + 5, BlockRegistry.ancientBrick);
        this.setBlock(world, i + 0, j + 3, k + 6, BlockRegistry.ancientBrick);
        this.setBlock(world, i + 0, j + 3, k + 7, BlockRegistry.ancientBrick);
        this.setBlock(world, i + 0, j + 3, k + 8, BlockRegistry.ancientBrick);
        this.setBlock(world, i + 0, j + 3, k + 9, BlockRegistry.ancientBrick);
        this.setBlock(world, i + 0, j + 3, k + 10, BlockRegistry.ancientBrick);
        this.setBlock(world, i + 0, j + 3, k + 11, BlockRegistry.ancientBrick);
        this.setBlock(world, i + 0, j + 3, k + 12, BlockRegistry.ancientBrick);
        this.setBlock(world, i + 0, j + 3, k + 13, BlockRegistry.ancientBrick);
        this.setBlock(world, i + 0, j + 3, k + 14, BlockRegistry.ancientBrick);
        this.setBlock(world, i + 0, j + 3, k + 15, BlockRegistry.ancientBrick);
        this.setBlock(world, i + 0, j + 3, k + 16, BlockRegistry.ancientBrick);
        this.setBlock(world, i + 0, j + 3, k + 17, BlockRegistry.ancientBrick);
        this.setBlock(world, i + 0, j + 3, k + 18, BlockRegistry.ancientBrick);
        this.setBlock(world, i + 0, j + 3, k + 19, BlockRegistry.ancientBrick);
        this.setBlock(world, i + 0, j + 3, k + 20, BlockRegistry.ancientBrick);
        this.setBlock(world, i + 0, j + 3, k + 21, BlockRegistry.ancientBrick);
        this.setBlock(world, i + 0, j + 3, k + 22, BlockRegistry.ancientBrick);
        this.setBlock(world, i + 0, j + 3, k + 23, BlockRegistry.ancientBrick);
        this.setBlock(world, i + 0, j + 3, k + 24, BlockRegistry.ancientBrick);
        this.setBlock(world, i + 0, j + 3, k + 25, BlockRegistry.ancientBrick);
        this.setBlock(world, i + 0, j + 3, k + 26, BlockRegistry.ancientBrick);
        this.setBlock(world, i + 0, j + 3, k + 27, BlockRegistry.ancientBrick);
        this.setBlock(world, i + 0, j + 3, k + 28, BlockRegistry.ancientBrick);
        this.setBlock(world, i + 0, j + 3, k + 29, BlockRegistry.ancientBrick);
        this.setBlock(world, i + 0, j + 3, k + 30, BlockRegistry.ancientBrick);
        this.setBlock(world, i + 0, j + 3, k + 31, BlockRegistry.ancientBrick);
        this.setBlock(world, i + 0, j + 4, k + 0, BlockRegistry.soulStone);
        this.setBlock(world, i + 0, j + 4, k + 1, BlockRegistry.soulStone);
        this.setBlock(world, i + 0, j + 4, k + 2, BlockRegistry.soulStone);
        this.setBlock(world, i + 0, j + 4, k + 3, BlockRegistry.soulStone);
        this.setBlock(world, i + 0, j + 4, k + 4, BlockRegistry.soulStone);
        this.setBlock(world, i + 0, j + 4, k + 5, BlockRegistry.soulStone);
        this.setBlock(world, i + 0, j + 4, k + 6, BlockRegistry.soulStone);
        this.setBlock(world, i + 0, j + 4, k + 7, BlockRegistry.soulStone);
        this.setBlock(world, i + 0, j + 4, k + 8, BlockRegistry.soulStone);
        this.setBlock(world, i + 0, j + 4, k + 9, BlockRegistry.soulStone);
        this.setBlock(world, i + 0, j + 4, k + 10, BlockRegistry.soulStone);
        this.setBlock(world, i + 0, j + 4, k + 11, BlockRegistry.soulStone);
        this.setBlock(world, i + 0, j + 4, k + 12, BlockRegistry.soulStone);
        this.setBlock(world, i + 0, j + 4, k + 13, BlockRegistry.soulStone);
        this.setBlock(world, i + 0, j + 4, k + 14, BlockRegistry.soulStone);
        this.setBlock(world, i + 0, j + 4, k + 15, BlockRegistry.soulStone);
        this.setBlock(world, i + 0, j + 4, k + 16, BlockRegistry.soulStone);
        this.setBlock(world, i + 0, j + 4, k + 17, BlockRegistry.soulStone);
        this.setBlock(world, i + 0, j + 4, k + 18, BlockRegistry.soulStone);
        this.setBlock(world, i + 0, j + 4, k + 19, BlockRegistry.soulStone);
        this.setBlock(world, i + 0, j + 4, k + 20, BlockRegistry.soulStone);
        this.setBlock(world, i + 0, j + 4, k + 21, BlockRegistry.soulStone);
        this.setBlock(world, i + 0, j + 4, k + 22, BlockRegistry.soulStone);
        this.setBlock(world, i + 0, j + 4, k + 23, BlockRegistry.soulStone);
        this.setBlock(world, i + 0, j + 4, k + 24, BlockRegistry.soulStone);
        this.setBlock(world, i + 0, j + 4, k + 25, BlockRegistry.soulStone);
        this.setBlock(world, i + 0, j + 4, k + 26, BlockRegistry.soulStone);
        this.setBlock(world, i + 0, j + 4, k + 27, BlockRegistry.soulStone);
        this.setBlock(world, i + 0, j + 4, k + 28, BlockRegistry.soulStone);
        this.setBlock(world, i + 0, j + 4, k + 29, BlockRegistry.soulStone);
        this.setBlock(world, i + 0, j + 4, k + 30, BlockRegistry.soulStone);
        this.setBlock(world, i + 0, j + 4, k + 31, BlockRegistry.soulStone);
        this.setBlock(world, i + 0, j + 5, k + 0, BlockRegistry.soulStone);
        this.setBlock(world, i + 0, j + 5, k + 1, BlockRegistry.soulStone);
        this.setBlock(world, i + 0, j + 5, k + 2, BlockRegistry.soulStone);
        this.setBlock(world, i + 0, j + 5, k + 3, BlockRegistry.soulStone);
        this.setBlock(world, i + 0, j + 5, k + 4, BlockRegistry.soulStone);
        this.setBlock(world, i + 0, j + 5, k + 5, BlockRegistry.soulStone);
        this.setBlock(world, i + 0, j + 5, k + 6, BlockRegistry.soulStone);
        this.setBlock(world, i + 0, j + 5, k + 7, BlockRegistry.soulStone);
        this.setBlock(world, i + 0, j + 5, k + 8, BlockRegistry.soulStone);
        this.setBlock(world, i + 0, j + 5, k + 9, BlockRegistry.soulStone);
        this.setBlock(world, i + 0, j + 5, k + 10, BlockRegistry.soulStone);
        this.setBlock(world, i + 0, j + 5, k + 11, BlockRegistry.soulStone);
        this.setBlock(world, i + 0, j + 5, k + 12, BlockRegistry.soulStone);
        this.setBlock(world, i + 0, j + 5, k + 13, BlockRegistry.soulStone);
        this.setBlock(world, i + 0, j + 5, k + 14, BlockRegistry.soulStone);
        this.setBlock(world, i + 0, j + 5, k + 15, BlockRegistry.soulStone);
        this.setBlock(world, i + 0, j + 5, k + 16, BlockRegistry.soulStone);
        this.setBlock(world, i + 0, j + 5, k + 17, BlockRegistry.soulStone);
        this.setBlock(world, i + 0, j + 5, k + 18, BlockRegistry.soulStone);
        this.setBlock(world, i + 0, j + 5, k + 19, BlockRegistry.soulStone);
        this.setBlock(world, i + 0, j + 5, k + 20, BlockRegistry.soulStone);
        this.setBlock(world, i + 0, j + 5, k + 21, BlockRegistry.soulStone);
        this.setBlock(world, i + 0, j + 5, k + 22, BlockRegistry.soulStone);
        this.setBlock(world, i + 0, j + 5, k + 23, BlockRegistry.soulStone);
        this.setBlock(world, i + 0, j + 5, k + 24, BlockRegistry.soulStone);
        this.setBlock(world, i + 0, j + 5, k + 25, BlockRegistry.soulStone);
        this.setBlock(world, i + 0, j + 5, k + 26, BlockRegistry.soulStone);
        this.setBlock(world, i + 0, j + 5, k + 27, BlockRegistry.soulStone);
        this.setBlock(world, i + 0, j + 5, k + 28, BlockRegistry.soulStone);
        this.setBlock(world, i + 0, j + 5, k + 29, BlockRegistry.soulStone);
        this.setBlock(world, i + 0, j + 5, k + 30, BlockRegistry.soulStone);
        this.setBlock(world, i + 0, j + 5, k + 31, BlockRegistry.soulStone);
        this.setBlock(world, i + 0, j + 6, k + 0, BlockRegistry.ancientStone);
        this.setBlock(world, i + 0, j + 6, k + 1, BlockRegistry.ancientStone);
        this.setBlock(world, i + 0, j + 6, k + 2, BlockRegistry.ancientStone);
        this.setBlock(world, i + 0, j + 6, k + 3, BlockRegistry.ancientStone);
        this.setBlock(world, i + 0, j + 6, k + 4, BlockRegistry.ancientStone);
        this.setBlock(world, i + 0, j + 6, k + 5, BlockRegistry.ancientStone);
        this.setBlock(world, i + 0, j + 6, k + 6, BlockRegistry.ancientStone);
        this.setBlock(world, i + 0, j + 6, k + 7, BlockRegistry.ancientStone);
        this.setBlock(world, i + 0, j + 6, k + 8, BlockRegistry.ancientStone);
        this.setBlock(world, i + 0, j + 6, k + 9, BlockRegistry.ancientStone);
        this.setBlock(world, i + 0, j + 6, k + 10, BlockRegistry.ancientStone);
        this.setBlock(world, i + 0, j + 6, k + 11, BlockRegistry.ancientStone);
        this.setBlock(world, i + 0, j + 6, k + 12, BlockRegistry.ancientStone);
        this.setBlock(world, i + 0, j + 6, k + 13, BlockRegistry.ancientStone);
        this.setBlock(world, i + 0, j + 6, k + 14, BlockRegistry.ancientStone);
        this.setBlock(world, i + 0, j + 6, k + 15, BlockRegistry.ancientStone);
        this.setBlock(world, i + 0, j + 6, k + 16, BlockRegistry.ancientStone);
        this.setBlock(world, i + 0, j + 6, k + 17, BlockRegistry.ancientStone);
        this.setBlock(world, i + 0, j + 6, k + 18, BlockRegistry.ancientStone);
        this.setBlock(world, i + 0, j + 6, k + 19, BlockRegistry.ancientStone);
        this.setBlock(world, i + 0, j + 6, k + 20, BlockRegistry.ancientStone);
        this.setBlock(world, i + 0, j + 6, k + 21, BlockRegistry.ancientStone);
        this.setBlock(world, i + 0, j + 6, k + 22, BlockRegistry.ancientStone);
        this.setBlock(world, i + 0, j + 6, k + 23, BlockRegistry.ancientStone);
        this.setBlock(world, i + 0, j + 6, k + 24, BlockRegistry.ancientStone);
        this.setBlock(world, i + 0, j + 6, k + 25, BlockRegistry.ancientStone);
        this.setBlock(world, i + 0, j + 6, k + 26, BlockRegistry.ancientStone);
        this.setBlock(world, i + 0, j + 6, k + 27, BlockRegistry.ancientStone);
        this.setBlock(world, i + 0, j + 6, k + 28, BlockRegistry.ancientStone);
        this.setBlock(world, i + 0, j + 6, k + 29, BlockRegistry.ancientStone);
        this.setBlock(world, i + 0, j + 6, k + 30, BlockRegistry.ancientStone);
        this.setBlock(world, i + 0, j + 6, k + 31, BlockRegistry.ancientStone);
        this.setBlock(world, i + 0, j + 7, k + 0, BlockRegistry.ancientStone);
        this.setBlock(world, i + 0, j + 7, k + 1, BlockRegistry.ancientStone);
        this.setBlock(world, i + 0, j + 7, k + 2, BlockRegistry.ancientStone);
        this.setBlock(world, i + 0, j + 7, k + 3, BlockRegistry.ancientStone);
        this.setBlock(world, i + 0, j + 7, k + 4, BlockRegistry.ancientStone);
        this.setBlock(world, i + 0, j + 7, k + 5, BlockRegistry.ancientStone);
        this.setBlock(world, i + 0, j + 7, k + 6, BlockRegistry.ancientStone);
        this.setBlock(world, i + 0, j + 7, k + 7, BlockRegistry.ancientStone);
        this.setBlock(world, i + 0, j + 7, k + 8, BlockRegistry.ancientStone);
        this.setBlock(world, i + 0, j + 7, k + 9, BlockRegistry.ancientStone);
        this.setBlock(world, i + 0, j + 7, k + 10, BlockRegistry.ancientStone);
        this.setBlock(world, i + 0, j + 7, k + 11, BlockRegistry.ancientStone);
        this.setBlock(world, i + 0, j + 7, k + 12, BlockRegistry.ancientStone);
        this.setBlock(world, i + 0, j + 7, k + 13, BlockRegistry.ancientStone);
        this.setBlock(world, i + 0, j + 7, k + 14, BlockRegistry.ancientStone);
        this.setBlock(world, i + 0, j + 7, k + 15, BlockRegistry.ancientStone);
        this.setBlock(world, i + 0, j + 7, k + 16, BlockRegistry.ancientStone);
        this.setBlock(world, i + 0, j + 7, k + 17, BlockRegistry.ancientStone);
        this.setBlock(world, i + 0, j + 7, k + 18, BlockRegistry.ancientStone);
        this.setBlock(world, i + 0, j + 7, k + 19, BlockRegistry.ancientStone);
        this.setBlock(world, i + 0, j + 7, k + 20, BlockRegistry.ancientStone);
        this.setBlock(world, i + 0, j + 7, k + 21, BlockRegistry.ancientStone);
        this.setBlock(world, i + 0, j + 7, k + 22, BlockRegistry.ancientStone);
        this.setBlock(world, i + 0, j + 7, k + 23, BlockRegistry.ancientStone);
        this.setBlock(world, i + 0, j + 7, k + 24, BlockRegistry.ancientStone);
        this.setBlock(world, i + 0, j + 7, k + 25, BlockRegistry.ancientStone);
        this.setBlock(world, i + 0, j + 7, k + 26, BlockRegistry.ancientStone);
        this.setBlock(world, i + 0, j + 7, k + 27, BlockRegistry.ancientStone);
        this.setBlock(world, i + 0, j + 7, k + 28, BlockRegistry.ancientStone);
        this.setBlock(world, i + 0, j + 7, k + 29, BlockRegistry.ancientStone);
        this.setBlock(world, i + 0, j + 7, k + 30, BlockRegistry.ancientStone);
        this.setBlock(world, i + 0, j + 7, k + 31, BlockRegistry.ancientStone);
        this.setBlock(world, i + 0, j + 8, k + 0, BlockRegistry.ancientStone);
        this.setBlock(world, i + 0, j + 8, k + 1, BlockRegistry.ancientStone);
        this.setBlock(world, i + 0, j + 8, k + 2, BlockRegistry.ancientStone);
        this.setBlock(world, i + 0, j + 8, k + 3, BlockRegistry.ancientStone);
        this.setBlock(world, i + 0, j + 8, k + 4, BlockRegistry.ancientStone);
        this.setBlock(world, i + 0, j + 8, k + 5, BlockRegistry.ancientStone);
        this.setBlock(world, i + 0, j + 8, k + 6, BlockRegistry.ancientStone);
        this.setBlock(world, i + 0, j + 8, k + 7, BlockRegistry.ancientStone);
        this.setBlock(world, i + 0, j + 8, k + 8, BlockRegistry.ancientStone);
        this.setBlock(world, i + 0, j + 8, k + 9, BlockRegistry.ancientStone);
        this.setBlock(world, i + 0, j + 8, k + 10, BlockRegistry.ancientStone);
        this.setBlock(world, i + 0, j + 8, k + 11, BlockRegistry.ancientStone);
        this.setBlock(world, i + 0, j + 8, k + 12, BlockRegistry.ancientStone);
        this.setBlock(world, i + 0, j + 8, k + 13, BlockRegistry.ancientStone);
        this.setBlock(world, i + 0, j + 8, k + 14, BlockRegistry.ancientStone);
        this.setBlock(world, i + 0, j + 8, k + 15, BlockRegistry.ancientStone);
        this.setBlock(world, i + 0, j + 8, k + 16, BlockRegistry.ancientStone);
        this.setBlock(world, i + 0, j + 8, k + 17, BlockRegistry.ancientStone);
        this.setBlock(world, i + 0, j + 8, k + 18, BlockRegistry.ancientStone);
        this.setBlock(world, i + 0, j + 8, k + 19, BlockRegistry.ancientStone);
        this.setBlock(world, i + 0, j + 8, k + 20, BlockRegistry.ancientStone);
        this.setBlock(world, i + 0, j + 8, k + 21, BlockRegistry.ancientStone);
        this.setBlock(world, i + 0, j + 8, k + 22, BlockRegistry.ancientStone);
        this.setBlock(world, i + 0, j + 8, k + 23, BlockRegistry.ancientStone);
        this.setBlock(world, i + 0, j + 8, k + 24, BlockRegistry.ancientStone);
        this.setBlock(world, i + 0, j + 8, k + 25, BlockRegistry.ancientStone);
        this.setBlock(world, i + 0, j + 8, k + 26, BlockRegistry.ancientStone);
        this.setBlock(world, i + 0, j + 8, k + 27, BlockRegistry.ancientStone);
        this.setBlock(world, i + 0, j + 8, k + 28, BlockRegistry.ancientStone);
        this.setBlock(world, i + 0, j + 8, k + 29, BlockRegistry.ancientStone);
        this.setBlock(world, i + 0, j + 8, k + 30, BlockRegistry.ancientStone);
        this.setBlock(world, i + 0, j + 8, k + 31, BlockRegistry.ancientStone);
        this.setBlock(world, i + 0, j + 9, k + 0, BlockRegistry.degradedBrick);
        this.setBlock(world, i + 0, j + 9, k + 1, BlockRegistry.degradedBrick);
        this.setBlock(world, i + 0, j + 9, k + 2, BlockRegistry.degradedBrick);
        this.setBlock(world, i + 0, j + 9, k + 3, BlockRegistry.degradedBrick);
        this.setBlock(world, i + 0, j + 9, k + 4, BlockRegistry.degradedBrick);
        this.setBlock(world, i + 0, j + 9, k + 5, BlockRegistry.degradedBrick);
        this.setBlock(world, i + 0, j + 9, k + 6, BlockRegistry.degradedBrick);
        this.setBlock(world, i + 0, j + 9, k + 7, BlockRegistry.degradedBrick);
        this.setBlock(world, i + 0, j + 9, k + 8, BlockRegistry.degradedBrick);
        this.setBlock(world, i + 0, j + 9, k + 9, BlockRegistry.degradedBrick);
        this.setBlock(world, i + 0, j + 9, k + 10, BlockRegistry.degradedBrick);
        this.setBlock(world, i + 0, j + 9, k + 11, BlockRegistry.degradedBrick);
        this.setBlock(world, i + 0, j + 9, k + 12, BlockRegistry.degradedBrick);
        this.setBlock(world, i + 0, j + 9, k + 13, BlockRegistry.degradedBrick);
        this.setBlock(world, i + 0, j + 9, k + 14, BlockRegistry.degradedBrick);
        this.setBlock(world, i + 0, j + 9, k + 15, BlockRegistry.degradedBrick);
        this.setBlock(world, i + 0, j + 9, k + 16, BlockRegistry.degradedBrick);
        this.setBlock(world, i + 0, j + 9, k + 17, BlockRegistry.degradedBrick);
        this.setBlock(world, i + 0, j + 9, k + 18, BlockRegistry.degradedBrick);
        this.setBlock(world, i + 0, j + 9, k + 19, BlockRegistry.degradedBrick);
        this.setBlock(world, i + 0, j + 9, k + 20, BlockRegistry.degradedBrick);
        this.setBlock(world, i + 0, j + 9, k + 21, BlockRegistry.degradedBrick);
        this.setBlock(world, i + 0, j + 9, k + 22, BlockRegistry.degradedBrick);
        this.setBlock(world, i + 0, j + 9, k + 23, BlockRegistry.degradedBrick);
        this.setBlock(world, i + 0, j + 9, k + 24, BlockRegistry.degradedBrick);
        this.setBlock(world, i + 0, j + 9, k + 25, BlockRegistry.degradedBrick);
        this.setBlock(world, i + 0, j + 9, k + 26, BlockRegistry.degradedBrick);
        this.setBlock(world, i + 0, j + 9, k + 27, BlockRegistry.degradedBrick);
        this.setBlock(world, i + 0, j + 9, k + 28, BlockRegistry.degradedBrick);
        this.setBlock(world, i + 0, j + 9, k + 29, BlockRegistry.degradedBrick);
        this.setBlock(world, i + 0, j + 9, k + 30, BlockRegistry.degradedBrick);
        this.setBlock(world, i + 0, j + 9, k + 31, BlockRegistry.degradedBrick);
        this.setBlock(world, i + 0, j + 10, k + 0, BlockRegistry.degradedBrick);
        this.setBlock(world, i + 0, j + 10, k + 1, BlockRegistry.degradedBrick);
        this.setBlock(world, i + 0, j + 10, k + 2, BlockRegistry.degradedBrick);
        this.setBlock(world, i + 0, j + 10, k + 3, BlockRegistry.degradedBrick);
        this.setBlock(world, i + 0, j + 10, k + 4, BlockRegistry.degradedBrick);
        this.setBlock(world, i + 0, j + 10, k + 5, BlockRegistry.degradedBrick);
        this.setBlock(world, i + 0, j + 10, k + 6, BlockRegistry.degradedBrick);
        this.setBlock(world, i + 0, j + 10, k + 7, BlockRegistry.degradedBrick);
        this.setBlock(world, i + 0, j + 10, k + 8, BlockRegistry.degradedBrick);
        this.setBlock(world, i + 0, j + 10, k + 9, BlockRegistry.degradedBrick);
        this.setBlock(world, i + 0, j + 10, k + 10, BlockRegistry.degradedBrick);
        this.setBlock(world, i + 0, j + 10, k + 11, BlockRegistry.degradedBrick);
        this.setBlock(world, i + 0, j + 10, k + 12, BlockRegistry.degradedBrick);
        this.setBlock(world, i + 0, j + 10, k + 13, BlockRegistry.degradedBrick);
        this.setBlock(world, i + 0, j + 10, k + 14, BlockRegistry.degradedBrick);
        this.setBlock(world, i + 0, j + 10, k + 15, BlockRegistry.degradedBrick);
        this.setBlock(world, i + 0, j + 10, k + 16, BlockRegistry.degradedBrick);
        this.setBlock(world, i + 0, j + 10, k + 17, BlockRegistry.degradedBrick);
        this.setBlock(world, i + 0, j + 10, k + 18, BlockRegistry.degradedBrick);
        this.setBlock(world, i + 0, j + 10, k + 19, BlockRegistry.degradedBrick);
        this.setBlock(world, i + 0, j + 10, k + 20, BlockRegistry.degradedBrick);
        this.setBlock(world, i + 0, j + 10, k + 21, BlockRegistry.degradedBrick);
        this.setBlock(world, i + 0, j + 10, k + 22, BlockRegistry.degradedBrick);
        this.setBlock(world, i + 0, j + 10, k + 23, BlockRegistry.degradedBrick);
        this.setBlock(world, i + 0, j + 10, k + 24, BlockRegistry.degradedBrick);
        this.setBlock(world, i + 0, j + 10, k + 25, BlockRegistry.degradedBrick);
        this.setBlock(world, i + 0, j + 10, k + 26, BlockRegistry.degradedBrick);
        this.setBlock(world, i + 0, j + 10, k + 27, BlockRegistry.degradedBrick);
        this.setBlock(world, i + 0, j + 10, k + 28, BlockRegistry.degradedBrick);
        this.setBlock(world, i + 0, j + 10, k + 29, BlockRegistry.degradedBrick);
        this.setBlock(world, i + 0, j + 10, k + 30, BlockRegistry.degradedBrick);
        this.setBlock(world, i + 0, j + 10, k + 31, BlockRegistry.degradedBrick);
        this.setBlock(world, i + 0, j + 11, k + 0, BlockRegistry.degradedBrick);
        this.setBlock(world, i + 0, j + 11, k + 1, BlockRegistry.degradedBrick);
        this.setBlock(world, i + 0, j + 11, k + 2, BlockRegistry.degradedBrick);
        this.setBlock(world, i + 0, j + 11, k + 3, BlockRegistry.degradedBrick);
        this.setBlock(world, i + 0, j + 11, k + 4, BlockRegistry.degradedBrick);
        this.setBlock(world, i + 0, j + 11, k + 5, BlockRegistry.ancientBrick);
        this.setBlock(world, i + 0, j + 11, k + 6, BlockRegistry.degradedBrick);
        this.setBlock(world, i + 0, j + 11, k + 7, BlockRegistry.degradedBrick);
        this.setBlock(world, i + 0, j + 11, k + 8, BlockRegistry.degradedBrick);
        this.setBlock(world, i + 0, j + 11, k + 9, BlockRegistry.degradedBrick);
        this.setBlock(world, i + 0, j + 11, k + 10, BlockRegistry.degradedBrick);
        this.setBlock(world, i + 0, j + 11, k + 11, BlockRegistry.ancientBrick);
        this.setBlock(world, i + 0, j + 11, k + 12, BlockRegistry.ancientBrick);
        this.setBlock(world, i + 0, j + 11, k + 13, BlockRegistry.ancientBrick);
        this.setBlock(world, i + 0, j + 11, k + 14, BlockRegistry.ancientBrick);
        this.setBlock(world, i + 0, j + 11, k + 15, BlockRegistry.ancientBrick);
        this.setBlock(world, i + 0, j + 11, k + 16, BlockRegistry.ancientBrick);
        this.setBlock(world, i + 0, j + 11, k + 17, BlockRegistry.ancientBrick);
        this.setBlock(world, i + 0, j + 11, k + 18, BlockRegistry.ancientBrick);
        this.setBlock(world, i + 0, j + 11, k + 19, BlockRegistry.ancientBrick);
        this.setBlock(world, i + 0, j + 11, k + 20, BlockRegistry.ancientBrick);
        this.setBlock(world, i + 0, j + 11, k + 21, BlockRegistry.degradedBrick);
        this.setBlock(world, i + 0, j + 11, k + 22, BlockRegistry.degradedBrick);
        this.setBlock(world, i + 0, j + 11, k + 23, BlockRegistry.degradedBrick);
        this.setBlock(world, i + 0, j + 11, k + 24, BlockRegistry.degradedBrick);
        this.setBlock(world, i + 0, j + 11, k + 25, BlockRegistry.degradedBrick);
        this.setBlock(world, i + 0, j + 11, k + 26, BlockRegistry.ancientBrick);
        this.setBlock(world, i + 0, j + 11, k + 27, BlockRegistry.degradedBrick);
        this.setBlock(world, i + 0, j + 11, k + 28, BlockRegistry.degradedBrick);
        this.setBlock(world, i + 0, j + 11, k + 29, BlockRegistry.degradedBrick);
        this.setBlock(world, i + 0, j + 11, k + 30, BlockRegistry.degradedBrick);
        this.setBlock(world, i + 0, j + 11, k + 31, BlockRegistry.degradedBrick);
        this.setBlock(world, i + 0, j + 12, k + 0, BlockRegistry.degradedBrick);
        this.setBlock(world, i + 0, j + 12, k + 1, BlockRegistry.degradedBrick);
        this.setBlock(world, i + 0, j + 12, k + 2, BlockRegistry.degradedBrick);
        this.setBlock(world, i + 0, j + 12, k + 3, BlockRegistry.degradedBrick);
        this.setBlock(world, i + 0, j + 12, k + 4, BlockRegistry.ancientBrick);
        this.setBlock(world, i + 0, j + 12, k + 5, BlockRegistry.ancientBrick);
        this.setBlock(world, i + 0, j + 12, k + 6, BlockRegistry.ancientBrick);
        this.setBlock(world, i + 0, j + 12, k + 7, BlockRegistry.degradedBrick);
        this.setBlock(world, i + 0, j + 12, k + 8, BlockRegistry.degradedBrick);
        this.setBlock(world, i + 0, j + 12, k + 9, BlockRegistry.degradedBrick);
        this.setBlock(world, i + 0, j + 12, k + 10, BlockRegistry.ancientBrick);
        this.setBlock(world, i + 0, j + 12, k + 11, BlockRegistry.ancientBrick);
        this.setBlock(world, i + 0, j + 12, k + 12, BlockRegistry.ancientBrick);
        this.setBlock(world, i + 0, j + 12, k + 13, BlockRegistry.ancientBrick);
        this.setBlock(world, i + 0, j + 12, k + 14, BlockRegistry.ancientBrick);
        this.setBlock(world, i + 0, j + 12, k + 15, BlockRegistry.ancientBrick);
        this.setBlock(world, i + 0, j + 12, k + 16, BlockRegistry.ancientBrick);
        this.setBlock(world, i + 0, j + 12, k + 17, BlockRegistry.ancientBrick);
        this.setBlock(world, i + 0, j + 12, k + 18, BlockRegistry.ancientBrick);
        this.setBlock(world, i + 0, j + 12, k + 19, BlockRegistry.ancientBrick);
        this.setBlock(world, i + 0, j + 12, k + 20, BlockRegistry.ancientBrick);
        this.setBlock(world, i + 0, j + 12, k + 21, BlockRegistry.ancientBrick);
        this.setBlock(world, i + 0, j + 12, k + 22, BlockRegistry.degradedBrick);
        this.setBlock(world, i + 0, j + 12, k + 23, BlockRegistry.degradedBrick);
        this.setBlock(world, i + 0, j + 12, k + 24, BlockRegistry.degradedBrick);
        this.setBlock(world, i + 0, j + 12, k + 25, BlockRegistry.ancientBrick);
        this.setBlock(world, i + 0, j + 12, k + 26, BlockRegistry.ancientBrick);
        this.setBlock(world, i + 0, j + 12, k + 27, BlockRegistry.ancientBrick);
        this.setBlock(world, i + 0, j + 12, k + 28, BlockRegistry.degradedBrick);
        this.setBlock(world, i + 0, j + 12, k + 29, BlockRegistry.degradedBrick);
        this.setBlock(world, i + 0, j + 12, k + 30, BlockRegistry.degradedBrick);
        this.setBlock(world, i + 0, j + 12, k + 31, BlockRegistry.degradedBrick);
        this.setBlock(world, i + 0, j + 13, k + 0, BlockRegistry.degradedBrick);
        this.setBlock(world, i + 0, j + 13, k + 1, BlockRegistry.degradedBrick);
        this.setBlock(world, i + 0, j + 13, k + 2, BlockRegistry.degradedBrick);
        this.setBlock(world, i + 0, j + 13, k + 3, BlockRegistry.ancientBrick);
        this.setBlock(world, i + 0, j + 13, k + 4, BlockRegistry.ancientBrick);
        this.setBlock(world, i + 0, j + 13, k + 5, BlockRegistry.ancientBrick);
        this.setBlock(world, i + 0, j + 13, k + 6, BlockRegistry.ancientBrick);
        this.setBlock(world, i + 0, j + 13, k + 7, BlockRegistry.ancientBrick);
        this.setBlock(world, i + 0, j + 13, k + 8, BlockRegistry.degradedBrick);
        this.setBlock(world, i + 0, j + 13, k + 9, BlockRegistry.ancientBrick);
        this.setBlock(world, i + 0, j + 13, k + 10, BlockRegistry.ancientBrick);
        this.setBlock(world, i + 0, j + 13, k + 11, BlockRegistry.ancientBrick);
        this.setBlock(world, i + 0, j + 13, k + 12, BlockRegistry.ancientBrick);
        this.setBlock(world, i + 0, j + 13, k + 13, BlockRegistry.ancientBrick);
        this.setBlock(world, i + 0, j + 13, k + 14, BlockRegistry.ancientBrick);
        this.setBlock(world, i + 0, j + 13, k + 15, BlockRegistry.ancientBrick);
        this.setBlock(world, i + 0, j + 13, k + 16, BlockRegistry.ancientBrick);
        this.setBlock(world, i + 0, j + 13, k + 17, BlockRegistry.ancientBrick);
        this.setBlock(world, i + 0, j + 13, k + 18, BlockRegistry.ancientBrick);
        this.setBlock(world, i + 0, j + 13, k + 19, BlockRegistry.ancientBrick);
        this.setBlock(world, i + 0, j + 13, k + 20, BlockRegistry.ancientBrick);
        this.setBlock(world, i + 0, j + 13, k + 21, BlockRegistry.ancientBrick);
        this.setBlock(world, i + 0, j + 13, k + 22, BlockRegistry.ancientBrick);
        this.setBlock(world, i + 0, j + 13, k + 23, BlockRegistry.degradedBrick);
        this.setBlock(world, i + 0, j + 13, k + 24, BlockRegistry.ancientBrick);
        this.setBlock(world, i + 0, j + 13, k + 25, BlockRegistry.ancientBrick);
        this.setBlock(world, i + 0, j + 13, k + 26, BlockRegistry.ancientBrick);
        this.setBlock(world, i + 0, j + 13, k + 27, BlockRegistry.ancientBrick);
        this.setBlock(world, i + 0, j + 13, k + 28, BlockRegistry.ancientBrick);
        this.setBlock(world, i + 0, j + 13, k + 29, BlockRegistry.degradedBrick);
        this.setBlock(world, i + 0, j + 13, k + 30, BlockRegistry.degradedBrick);
        this.setBlock(world, i + 0, j + 13, k + 31, BlockRegistry.degradedBrick);
        this.setBlock(world, i + 0, j + 14, k + 0, BlockRegistry.degradedBrick);
        this.setBlock(world, i + 0, j + 14, k + 1, BlockRegistry.dungeonLamp);
        this.setBlock(world, i + 0, j + 14, k + 2, BlockRegistry.ancientBrick);
        this.setBlock(world, i + 0, j + 14, k + 3, BlockRegistry.ancientBrick);
        this.setBlock(world, i + 0, j + 14, k + 4, BlockRegistry.ancientBrick);
        this.setBlock(world, i + 0, j + 14, k + 5, BlockRegistry.ancientBrick);
        this.setBlock(world, i + 0, j + 14, k + 6, BlockRegistry.ancientBrick);
        this.setBlock(world, i + 0, j + 14, k + 7, BlockRegistry.ancientBrick);
        this.setBlock(world, i + 0, j + 14, k + 8, BlockRegistry.ancientBrick);
        this.setBlock(world, i + 0, j + 14, k + 9, BlockRegistry.ancientBrick);
        this.setBlock(world, i + 0, j + 14, k + 10, BlockRegistry.ancientBrick);
        this.setBlock(world, i + 0, j + 14, k + 11, BlockRegistry.ancientBrick);
        this.setBlock(world, i + 0, j + 14, k + 12, BlockRegistry.ancientBrick);
        this.setBlock(world, i + 0, j + 14, k + 13, BlockRegistry.ancientBrick);
        this.setBlock(world, i + 0, j + 14, k + 14, BlockRegistry.ancientBrick);
        this.setBlock(world, i + 0, j + 14, k + 15, BlockRegistry.ancientBrick);
        this.setBlock(world, i + 0, j + 14, k + 16, BlockRegistry.ancientBrick);
        this.setBlock(world, i + 0, j + 14, k + 17, BlockRegistry.ancientBrick);
        this.setBlock(world, i + 0, j + 14, k + 18, BlockRegistry.ancientBrick);
        this.setBlock(world, i + 0, j + 14, k + 19, BlockRegistry.ancientBrick);
        this.setBlock(world, i + 0, j + 14, k + 20, BlockRegistry.ancientBrick);
        this.setBlock(world, i + 0, j + 14, k + 21, BlockRegistry.ancientBrick);
        this.setBlock(world, i + 0, j + 14, k + 22, BlockRegistry.ancientBrick);
        this.setBlock(world, i + 0, j + 14, k + 23, BlockRegistry.ancientBrick);
        this.setBlock(world, i + 0, j + 14, k + 24, BlockRegistry.ancientBrick);
        this.setBlock(world, i + 0, j + 14, k + 25, BlockRegistry.ancientBrick);
        this.setBlock(world, i + 0, j + 14, k + 26, BlockRegistry.ancientBrick);
        this.setBlock(world, i + 0, j + 14, k + 27, BlockRegistry.ancientBrick);
        this.setBlock(world, i + 0, j + 14, k + 28, BlockRegistry.ancientBrick);
        this.setBlock(world, i + 0, j + 14, k + 29, BlockRegistry.ancientBrick);
        this.setBlock(world, i + 0, j + 14, k + 30, BlockRegistry.dungeonLamp);
        this.setBlock(world, i + 0, j + 14, k + 31, BlockRegistry.degradedBrick);
        this.setBlock(world, i + 0, j + 15, k + 0, BlockRegistry.degradedBrick);
        this.setBlock(world, i + 0, j + 15, k + 1, BlockRegistry.ancientBrick);
        this.setBlock(world, i + 0, j + 15, k + 2, BlockRegistry.ancientBrick);
        this.setBlock(world, i + 0, j + 15, k + 3, BlockRegistry.ancientBrick);
        this.setBlock(world, i + 0, j + 15, k + 4, BlockRegistry.ancientBrick);
        this.setBlock(world, i + 0, j + 15, k + 5, BlockRegistry.ancientBrick);
        this.setBlock(world, i + 0, j + 15, k + 6, BlockRegistry.ancientBrick);
        this.setBlock(world, i + 0, j + 15, k + 7, BlockRegistry.ancientBrick);
        this.setBlock(world, i + 0, j + 15, k + 8, BlockRegistry.ancientBrick);
        this.setBlock(world, i + 0, j + 15, k + 9, BlockRegistry.ancientBrick);
        this.setBlock(world, i + 0, j + 15, k + 10, BlockRegistry.ancientBrick);
        this.setBlock(world, i + 0, j + 15, k + 11, BlockRegistry.ancientBrick);
        this.setBlock(world, i + 0, j + 15, k + 12, BlockRegistry.ancientBrick);
        this.setBlock(world, i + 0, j + 15, k + 13, BlockRegistry.ancientBrick);
        this.setBlock(world, i + 0, j + 15, k + 14, BlockRegistry.ancientBrick);
        this.setBlock(world, i + 0, j + 15, k + 15, BlockRegistry.ancientBrick);
        this.setBlock(world, i + 0, j + 15, k + 16, BlockRegistry.ancientBrick);
        this.setBlock(world, i + 0, j + 15, k + 17, BlockRegistry.ancientBrick);
        this.setBlock(world, i + 0, j + 15, k + 18, BlockRegistry.ancientBrick);
        this.setBlock(world, i + 0, j + 15, k + 19, BlockRegistry.ancientBrick);
        this.setBlock(world, i + 0, j + 15, k + 20, BlockRegistry.ancientBrick);
        this.setBlock(world, i + 0, j + 15, k + 21, BlockRegistry.ancientBrick);
        this.setBlock(world, i + 0, j + 15, k + 22, BlockRegistry.ancientBrick);
        this.setBlock(world, i + 0, j + 15, k + 23, BlockRegistry.ancientBrick);
        this.setBlock(world, i + 0, j + 15, k + 24, BlockRegistry.ancientBrick);
        this.setBlock(world, i + 0, j + 15, k + 25, BlockRegistry.ancientBrick);
        this.setBlock(world, i + 0, j + 15, k + 26, BlockRegistry.ancientBrick);
        this.setBlock(world, i + 0, j + 15, k + 27, BlockRegistry.ancientBrick);
        this.setBlock(world, i + 0, j + 15, k + 28, BlockRegistry.ancientBrick);
        this.setBlock(world, i + 0, j + 15, k + 29, BlockRegistry.ancientBrick);
        this.setBlock(world, i + 0, j + 15, k + 30, BlockRegistry.ancientBrick);
        this.setBlock(world, i + 0, j + 15, k + 31, BlockRegistry.degradedBrick);
        this.setBlock(world, i + 1, j + 0, k + 0, BlockRegistry.ancientBrick);
        this.setBlock(world, i + 1, j + 0, k + 1, BlockRegistry.degradedBrick);
        this.setBlock(world, i + 1, j + 0, k + 2, BlockRegistry.degradedBrick);
        this.setBlock(world, i + 1, j + 0, k + 3, BlockRegistry.degradedBrick);
        this.setBlock(world, i + 1, j + 0, k + 4, BlockRegistry.degradedBrick);
        this.setBlock(world, i + 1, j + 0, k + 5, BlockRegistry.degradedBrick);
        this.setBlock(world, i + 1, j + 0, k + 6, BlockRegistry.degradedBrick);
        this.setBlock(world, i + 1, j + 0, k + 7, BlockRegistry.degradedBrick);
        this.setBlock(world, i + 1, j + 0, k + 8, BlockRegistry.degradedBrick);
        this.setBlock(world, i + 1, j + 0, k + 9, BlockRegistry.degradedBrick);
        this.setBlock(world, i + 1, j + 0, k + 10, BlockRegistry.degradedBrick);
        this.setBlock(world, i + 1, j + 0, k + 11, BlockRegistry.degradedBrick);
        this.setBlock(world, i + 1, j + 0, k + 12, BlockRegistry.degradedBrick);
        this.setBlock(world, i + 1, j + 0, k + 13, BlockRegistry.degradedBrick);
        this.setBlock(world, i + 1, j + 0, k + 14, BlockRegistry.degradedBrick);
        this.setBlock(world, i + 1, j + 0, k + 15, BlockRegistry.degradedBrick);
        this.setBlock(world, i + 1, j + 0, k + 16, BlockRegistry.degradedBrick);
        this.setBlock(world, i + 1, j + 0, k + 17, BlockRegistry.degradedBrick);
        this.setBlock(world, i + 1, j + 0, k + 18, BlockRegistry.degradedBrick);
        this.setBlock(world, i + 1, j + 0, k + 19, BlockRegistry.degradedBrick);
        this.setBlock(world, i + 1, j + 0, k + 20, BlockRegistry.degradedBrick);
        this.setBlock(world, i + 1, j + 0, k + 21, BlockRegistry.degradedBrick);
        this.setBlock(world, i + 1, j + 0, k + 22, BlockRegistry.degradedBrick);
        this.setBlock(world, i + 1, j + 0, k + 23, BlockRegistry.degradedBrick);
        this.setBlock(world, i + 1, j + 0, k + 24, BlockRegistry.degradedBrick);
        this.setBlock(world, i + 1, j + 0, k + 25, BlockRegistry.degradedBrick);
        this.setBlock(world, i + 1, j + 0, k + 26, BlockRegistry.degradedBrick);
        this.setBlock(world, i + 1, j + 0, k + 27, BlockRegistry.degradedBrick);
        this.setBlock(world, i + 1, j + 0, k + 28, BlockRegistry.degradedBrick);
        this.setBlock(world, i + 1, j + 0, k + 29, BlockRegistry.degradedBrick);
        this.setBlock(world, i + 1, j + 0, k + 30, BlockRegistry.degradedBrick);
        this.setBlock(world, i + 1, j + 0, k + 31, BlockRegistry.ancientBrick);
        this.setBlock(world, i + 1, j + 1, k + 0, BlockRegistry.ancientBrick);
        this.setBlock(world, i + 1, j + 1, k + 31, BlockRegistry.ancientBrick);
        this.setBlock(world, i + 1, j + 2, k + 0, BlockRegistry.ancientBrick);
        this.setBlock(world, i + 1, j + 2, k + 31, BlockRegistry.ancientBrick);
        this.setBlock(world, i + 1, j + 3, k + 0, BlockRegistry.ancientBrick);
        this.setBlock(world, i + 1, j + 3, k + 31, BlockRegistry.ancientBrick);
        this.setBlock(world, i + 1, j + 4, k + 0, BlockRegistry.soulStone);
        this.setBlock(world, i + 1, j + 4, k + 31, BlockRegistry.soulStone);
        this.setBlock(world, i + 1, j + 5, k + 0, BlockRegistry.soulStone);
        this.setBlock(world, i + 1, j + 5, k + 31, BlockRegistry.soulStone);
        this.setBlock(world, i + 1, j + 6, k + 0, BlockRegistry.ancientStone);
        this.setBlock(world, i + 1, j + 6, k + 31, BlockRegistry.ancientStone);
        this.setBlock(world, i + 1, j + 7, k + 0, BlockRegistry.ancientStone);
        this.setBlock(world, i + 1, j + 7, k + 31, BlockRegistry.ancientStone);
        this.setBlock(world, i + 1, j + 8, k + 0, BlockRegistry.ancientStone);
        this.setBlock(world, i + 1, j + 8, k + 31, BlockRegistry.ancientStone);
        this.setBlock(world, i + 1, j + 9, k + 0, BlockRegistry.degradedBrick);
        this.setBlock(world, i + 1, j + 9, k + 31, BlockRegistry.degradedBrick);
        this.setBlock(world, i + 1, j + 10, k + 0, BlockRegistry.degradedBrick);
        this.setBlock(world, i + 1, j + 10, k + 31, BlockRegistry.degradedBrick);
        this.setBlock(world, i + 1, j + 11, k + 0, BlockRegistry.degradedBrick);
        this.setBlock(world, i + 1, j + 11, k + 31, BlockRegistry.degradedBrick);
        this.setBlock(world, i + 1, j + 12, k + 0, BlockRegistry.degradedBrick);
        this.setBlock(world, i + 1, j + 12, k + 31, BlockRegistry.degradedBrick);
        this.setBlock(world, i + 1, j + 13, k + 0, BlockRegistry.degradedBrick);
        this.setBlock(world, i + 1, j + 13, k + 31, BlockRegistry.degradedBrick);
        this.setBlock(world, i + 1, j + 14, k + 0, BlockRegistry.dungeonLamp);
        this.setBlock(world, i + 1, j + 14, k + 31, BlockRegistry.dungeonLamp);
        this.setBlock(world, i + 1, j + 15, k + 0, BlockRegistry.ancientBrick);
        this.setBlock(world, i + 1, j + 15, k + 31, BlockRegistry.ancientBrick);
        this.setBlock(world, i + 2, j + 0, k + 0, BlockRegistry.ancientBrick);
        this.setBlock(world, i + 2, j + 0, k + 1, BlockRegistry.degradedBrick);
        this.setBlock(world, i + 2, j + 0, k + 2, BlockRegistry.degradedBrick);
        this.setBlock(world, i + 2, j + 0, k + 3, BlockRegistry.degradedBrick);
        this.setBlock(world, i + 2, j + 0, k + 4, BlockRegistry.degradedBrick);
        this.setBlock(world, i + 2, j + 0, k + 5, BlockRegistry.degradedBrick);
        this.setBlock(world, i + 2, j + 0, k + 6, BlockRegistry.degradedBrick);
        this.setBlock(world, i + 2, j + 0, k + 7, BlockRegistry.degradedBrick);
        this.setBlock(world, i + 2, j + 0, k + 8, BlockRegistry.degradedBrick);
        this.setBlock(world, i + 2, j + 0, k + 9, BlockRegistry.degradedBrick);
        this.setBlock(world, i + 2, j + 0, k + 10, BlockRegistry.degradedBrick);
        this.setBlock(world, i + 2, j + 0, k + 11, BlockRegistry.degradedBrick);
        this.setBlock(world, i + 2, j + 0, k + 12, BlockRegistry.degradedBrick);
        this.setBlock(world, i + 2, j + 0, k + 13, BlockRegistry.degradedBrick);
        this.setBlock(world, i + 2, j + 0, k + 14, BlockRegistry.degradedBrick);
        this.setBlock(world, i + 2, j + 0, k + 15, BlockRegistry.degradedBrick);
        this.setBlock(world, i + 2, j + 0, k + 16, BlockRegistry.degradedBrick);
        this.setBlock(world, i + 2, j + 0, k + 17, BlockRegistry.degradedBrick);
        this.setBlock(world, i + 2, j + 0, k + 18, BlockRegistry.degradedBrick);
        this.setBlock(world, i + 2, j + 0, k + 19, BlockRegistry.degradedBrick);
        this.setBlock(world, i + 2, j + 0, k + 20, BlockRegistry.degradedBrick);
        this.setBlock(world, i + 2, j + 0, k + 21, BlockRegistry.degradedBrick);
        this.setBlock(world, i + 2, j + 0, k + 22, BlockRegistry.degradedBrick);
        this.setBlock(world, i + 2, j + 0, k + 23, BlockRegistry.degradedBrick);
        this.setBlock(world, i + 2, j + 0, k + 24, BlockRegistry.degradedBrick);
        this.setBlock(world, i + 2, j + 0, k + 25, BlockRegistry.degradedBrick);
        this.setBlock(world, i + 2, j + 0, k + 26, BlockRegistry.degradedBrick);
        this.setBlock(world, i + 2, j + 0, k + 27, BlockRegistry.degradedBrick);
        this.setBlock(world, i + 2, j + 0, k + 28, BlockRegistry.degradedBrick);
        this.setBlock(world, i + 2, j + 0, k + 29, BlockRegistry.degradedBrick);
        this.setBlock(world, i + 2, j + 0, k + 30, BlockRegistry.degradedBrick);
        this.setBlock(world, i + 2, j + 0, k + 31, BlockRegistry.ancientBrick);
        this.setBlock(world, i + 2, j + 1, k + 0, BlockRegistry.ancientBrick);
        this.setBlock(world, i + 2, j + 1, k + 31, BlockRegistry.ancientBrick);
        this.setBlock(world, i + 2, j + 2, k + 0, BlockRegistry.ancientBrick);
        this.setBlock(world, i + 2, j + 2, k + 31, BlockRegistry.ancientBrick);
        this.setBlock(world, i + 2, j + 3, k + 0, BlockRegistry.ancientBrick);
        this.setBlock(world, i + 2, j + 3, k + 31, BlockRegistry.ancientBrick);
        this.setBlock(world, i + 2, j + 4, k + 0, BlockRegistry.soulStone);
        this.setBlock(world, i + 2, j + 4, k + 31, BlockRegistry.soulStone);
        this.setBlock(world, i + 2, j + 5, k + 0, BlockRegistry.soulStone);
        this.setBlock(world, i + 2, j + 5, k + 31, BlockRegistry.soulStone);
        this.setBlock(world, i + 2, j + 6, k + 0, BlockRegistry.ancientStone);
        this.setBlock(world, i + 2, j + 6, k + 31, BlockRegistry.ancientStone);
        this.setBlock(world, i + 2, j + 7, k + 0, BlockRegistry.ancientStone);
        this.setBlock(world, i + 2, j + 7, k + 31, BlockRegistry.ancientStone);
        this.setBlock(world, i + 2, j + 8, k + 0, BlockRegistry.ancientStone);
        this.setBlock(world, i + 2, j + 8, k + 31, BlockRegistry.ancientStone);
        this.setBlock(world, i + 2, j + 9, k + 0, BlockRegistry.degradedBrick);
        this.setBlock(world, i + 2, j + 9, k + 31, BlockRegistry.degradedBrick);
        this.setBlock(world, i + 2, j + 10, k + 0, BlockRegistry.degradedBrick);
        this.setBlock(world, i + 2, j + 10, k + 31, BlockRegistry.degradedBrick);
        this.setBlock(world, i + 2, j + 11, k + 0, BlockRegistry.degradedBrick);
        this.setBlock(world, i + 2, j + 11, k + 31, BlockRegistry.degradedBrick);
        this.setBlock(world, i + 2, j + 12, k + 0, BlockRegistry.degradedBrick);
        this.setBlock(world, i + 2, j + 12, k + 31, BlockRegistry.degradedBrick);
        this.setBlock(world, i + 2, j + 13, k + 0, BlockRegistry.degradedBrick);
        this.setBlock(world, i + 2, j + 13, k + 31, BlockRegistry.degradedBrick);
        this.setBlock(world, i + 2, j + 14, k + 0, BlockRegistry.ancientBrick);
        this.setBlock(world, i + 2, j + 14, k + 31, BlockRegistry.ancientBrick);
        this.setBlock(world, i + 2, j + 15, k + 0, BlockRegistry.ancientBrick);
        this.setBlock(world, i + 2, j + 15, k + 31, BlockRegistry.ancientBrick);
        this.setBlock(world, i + 3, j + 0, k + 0, BlockRegistry.ancientBrick);
        this.setBlock(world, i + 3, j + 0, k + 1, BlockRegistry.degradedBrick);
        this.setBlock(world, i + 3, j + 0, k + 2, BlockRegistry.degradedBrick);
        this.setBlock(world, i + 3, j + 0, k + 3, BlockRegistry.ancientBrick);
        this.setBlock(world, i + 3, j + 0, k + 4, BlockRegistry.ancientBrick);
        this.setBlock(world, i + 3, j + 0, k + 5, BlockRegistry.ancientBrick);
        this.setBlock(world, i + 3, j + 0, k + 6, BlockRegistry.ancientBrick);
        this.setBlock(world, i + 3, j + 0, k + 7, BlockRegistry.ancientBrick);
        this.setBlock(world, i + 3, j + 0, k + 8, BlockRegistry.ancientBrick);
        this.setBlock(world, i + 3, j + 0, k + 9, BlockRegistry.ancientBrick);
        this.setBlock(world, i + 3, j + 0, k + 10, BlockRegistry.ancientBrick);
        this.setBlock(world, i + 3, j + 0, k + 11, BlockRegistry.ancientBrick);
        this.setBlock(world, i + 3, j + 0, k + 12, BlockRegistry.ancientBrick);
        this.setBlock(world, i + 3, j + 0, k + 13, BlockRegistry.ancientBrick);
        this.setBlock(world, i + 3, j + 0, k + 14, BlockRegistry.ancientBrick);
        this.setBlock(world, i + 3, j + 0, k + 15, BlockRegistry.ancientBrick);
        this.setBlock(world, i + 3, j + 0, k + 16, BlockRegistry.ancientBrick);
        this.setBlock(world, i + 3, j + 0, k + 17, BlockRegistry.ancientBrick);
        this.setBlock(world, i + 3, j + 0, k + 18, BlockRegistry.ancientBrick);
        this.setBlock(world, i + 3, j + 0, k + 19, BlockRegistry.ancientBrick);
        this.setBlock(world, i + 3, j + 0, k + 20, BlockRegistry.ancientBrick);
        this.setBlock(world, i + 3, j + 0, k + 21, BlockRegistry.ancientBrick);
        this.setBlock(world, i + 3, j + 0, k + 22, BlockRegistry.ancientBrick);
        this.setBlock(world, i + 3, j + 0, k + 23, BlockRegistry.ancientBrick);
        this.setBlock(world, i + 3, j + 0, k + 24, BlockRegistry.ancientBrick);
        this.setBlock(world, i + 3, j + 0, k + 25, BlockRegistry.ancientBrick);
        this.setBlock(world, i + 3, j + 0, k + 26, BlockRegistry.ancientBrick);
        this.setBlock(world, i + 3, j + 0, k + 27, BlockRegistry.ancientBrick);
        this.setBlock(world, i + 3, j + 0, k + 28, BlockRegistry.ancientBrick);
        this.setBlock(world, i + 3, j + 0, k + 29, BlockRegistry.degradedBrick);
        this.setBlock(world, i + 3, j + 0, k + 30, BlockRegistry.degradedBrick);
        this.setBlock(world, i + 3, j + 0, k + 31, BlockRegistry.ancientBrick);
        this.setBlock(world, i + 3, j + 1, k + 0, BlockRegistry.ancientBrick);
        this.setBlock(world, i + 3, j + 1, k + 3, BlockRegistry.ancientBrick);
        this.setBlock(world, i + 3, j + 1, k + 4, BlockRegistry.ancientBrick);
        this.setBlock(world, i + 3, j + 1, k + 5, BlockRegistry.ancientBrick);
        this.setBlock(world, i + 3, j + 1, k + 6, BlockRegistry.ancientBrick);
        this.setBlock(world, i + 3, j + 1, k + 7, BlockRegistry.ancientBrick);
        this.setBlock(world, i + 3, j + 1, k + 8, BlockRegistry.ancientBrick);
        this.setBlock(world, i + 3, j + 1, k + 31, BlockRegistry.ancientBrick);
        this.setBlock(world, i + 3, j + 2, k + 0, BlockRegistry.ancientBrick);
        this.setBlock(world, i + 3, j + 2, k + 31, BlockRegistry.ancientBrick);
        this.setBlock(world, i + 3, j + 3, k + 0, BlockRegistry.ancientBrick);
        this.setBlock(world, i + 3, j + 3, k + 31, BlockRegistry.ancientBrick);
        this.setBlock(world, i + 3, j + 4, k + 0, BlockRegistry.soulStone);
        this.setBlock(world, i + 3, j + 4, k + 31, BlockRegistry.soulStone);
        this.setBlock(world, i + 3, j + 5, k + 0, BlockRegistry.soulStone);
        this.setBlock(world, i + 3, j + 5, k + 31, BlockRegistry.soulStone);
        this.setBlock(world, i + 3, j + 6, k + 0, BlockRegistry.ancientStone);
        this.setBlock(world, i + 3, j + 6, k + 31, BlockRegistry.ancientStone);
        this.setBlock(world, i + 3, j + 7, k + 0, BlockRegistry.ancientStone);
        this.setBlock(world, i + 3, j + 7, k + 31, BlockRegistry.ancientStone);
        this.setBlock(world, i + 3, j + 8, k + 0, BlockRegistry.ancientStone);
        this.setBlock(world, i + 3, j + 8, k + 31, BlockRegistry.ancientStone);
        this.setBlock(world, i + 3, j + 9, k + 0, BlockRegistry.degradedBrick);
        this.setBlock(world, i + 3, j + 9, k + 31, BlockRegistry.degradedBrick);
        this.setBlock(world, i + 3, j + 10, k + 0, BlockRegistry.degradedBrick);
        this.setBlock(world, i + 3, j + 10, k + 31, BlockRegistry.degradedBrick);
        this.setBlock(world, i + 3, j + 11, k + 0, BlockRegistry.degradedBrick);
        this.setBlock(world, i + 3, j + 11, k + 31, BlockRegistry.degradedBrick);
        this.setBlock(world, i + 3, j + 12, k + 0, BlockRegistry.degradedBrick);
        this.setBlock(world, i + 3, j + 12, k + 31, BlockRegistry.degradedBrick);
        this.setBlock(world, i + 3, j + 13, k + 0, BlockRegistry.ancientBrick);
        this.setBlock(world, i + 3, j + 13, k + 31, BlockRegistry.ancientBrick);
        this.setBlock(world, i + 3, j + 14, k + 0, BlockRegistry.ancientBrick);
        this.setBlock(world, i + 3, j + 14, k + 31, BlockRegistry.ancientBrick);
        this.setBlock(world, i + 3, j + 15, k + 0, BlockRegistry.ancientBrick);
        this.setBlock(world, i + 3, j + 15, k + 31, BlockRegistry.ancientBrick);
        this.setBlock(world, i + 4, j + 0, k + 0, BlockRegistry.ancientBrick);
        this.setBlock(world, i + 4, j + 0, k + 1, BlockRegistry.degradedBrick);
        this.setBlock(world, i + 4, j + 0, k + 2, BlockRegistry.degradedBrick);
        this.setBlock(world, i + 4, j + 0, k + 3, BlockRegistry.ancientBrick);
        this.setBlock(world, i + 4, j + 0, k + 4, BlockRegistry.ancientBrick);
        this.setBlock(world, i + 4, j + 0, k + 5, BlockRegistry.ancientBrick);
        this.setBlock(world, i + 4, j + 0, k + 6, BlockRegistry.ancientBrick);
        this.setBlock(world, i + 4, j + 0, k + 7, BlockRegistry.ancientBrick);
        this.setBlock(world, i + 4, j + 0, k + 8, BlockRegistry.ancientBrick);
        this.setBlock(world, i + 4, j + 0, k + 9, BlockRegistry.ancientBrick);
        this.setBlock(world, i + 4, j + 0, k + 10, BlockRegistry.ancientBrick);
        this.setBlock(world, i + 4, j + 0, k + 11, BlockRegistry.ancientBrick);
        this.setBlock(world, i + 4, j + 0, k + 12, BlockRegistry.ancientBrick);
        this.setBlock(world, i + 4, j + 0, k + 13, BlockRegistry.ancientBrick);
        this.setBlock(world, i + 4, j + 0, k + 14, BlockRegistry.ancientBrick);
        this.setBlock(world, i + 4, j + 0, k + 15, BlockRegistry.ancientBrick);
        this.setBlock(world, i + 4, j + 0, k + 16, BlockRegistry.ancientBrick);
        this.setBlock(world, i + 4, j + 0, k + 17, BlockRegistry.ancientBrick);
        this.setBlock(world, i + 4, j + 0, k + 18, BlockRegistry.ancientBrick);
        this.setBlock(world, i + 4, j + 0, k + 19, BlockRegistry.ancientBrick);
        this.setBlock(world, i + 4, j + 0, k + 20, BlockRegistry.ancientBrick);
        this.setBlock(world, i + 4, j + 0, k + 21, BlockRegistry.ancientBrick);
        this.setBlock(world, i + 4, j + 0, k + 22, BlockRegistry.ancientBrick);
        this.setBlock(world, i + 4, j + 0, k + 23, BlockRegistry.ancientBrick);
        this.setBlock(world, i + 4, j + 0, k + 24, BlockRegistry.ancientBrick);
        this.setBlock(world, i + 4, j + 0, k + 25, BlockRegistry.ancientBrick);
        this.setBlock(world, i + 4, j + 0, k + 26, BlockRegistry.ancientBrick);
        this.setBlock(world, i + 4, j + 0, k + 27, BlockRegistry.ancientBrick);
        this.setBlock(world, i + 4, j + 0, k + 28, BlockRegistry.ancientBrick);
        this.setBlock(world, i + 4, j + 0, k + 29, BlockRegistry.degradedBrick);
        this.setBlock(world, i + 4, j + 0, k + 30, BlockRegistry.degradedBrick);
        this.setBlock(world, i + 4, j + 0, k + 31, BlockRegistry.ancientBrick);
        this.setBlock(world, i + 4, j + 1, k + 0, BlockRegistry.ancientBrick);
        this.setBlock(world, i + 4, j + 1, k + 3, BlockRegistry.ancientBrick);
        this.setBlock(world, i + 4, j + 1, k + 4, BlockRegistry.ancientBrick);
        this.setBlock(world, i + 4, j + 1, k + 5, BlockRegistry.ancientBrick);
        this.setBlock(world, i + 4, j + 1, k + 6, BlockRegistry.ancientBrick);
        this.setBlock(world, i + 4, j + 1, k + 7, BlockRegistry.ancientBrick);
        this.setBlock(world, i + 4, j + 1, k + 8, BlockRegistry.ancientBrick);
        this.setBlock(world, i + 4, j + 1, k + 24, BlockRegistry.ancientBrick);
        this.setBlock(world, i + 4, j + 1, k + 25, BlockRegistry.ancientBrick);
        this.setBlock(world, i + 4, j + 1, k + 26, BlockRegistry.ancientBrick);
        this.setBlock(world, i + 4, j + 1, k + 27, BlockRegistry.ancientBrick);
        this.setBlock(world, i + 4, j + 1, k + 31, BlockRegistry.ancientBrick);
        this.setBlock(world, i + 4, j + 2, k + 0, BlockRegistry.ancientBrick);
        this.setBlock(world, i + 4, j + 2, k + 31, BlockRegistry.ancientBrick);
        this.setBlock(world, i + 4, j + 3, k + 0, BlockRegistry.ancientBrick);
        this.setBlock(world, i + 4, j + 3, k + 31, BlockRegistry.ancientBrick);
        this.setBlock(world, i + 4, j + 4, k + 0, BlockRegistry.soulStone);
        this.setBlock(world, i + 4, j + 4, k + 31, BlockRegistry.soulStone);
        this.setBlock(world, i + 4, j + 5, k + 0, BlockRegistry.soulStone);
        this.setBlock(world, i + 4, j + 5, k + 31, BlockRegistry.soulStone);
        this.setBlock(world, i + 4, j + 6, k + 0, BlockRegistry.ancientStone);
        this.setBlock(world, i + 4, j + 6, k + 31, BlockRegistry.ancientStone);
        this.setBlock(world, i + 4, j + 7, k + 0, BlockRegistry.ancientStone);
        this.setBlock(world, i + 4, j + 7, k + 31, BlockRegistry.ancientStone);
        this.setBlock(world, i + 4, j + 8, k + 0, BlockRegistry.ancientStone);
        this.setBlock(world, i + 4, j + 8, k + 31, BlockRegistry.ancientStone);
        this.setBlock(world, i + 4, j + 9, k + 0, BlockRegistry.degradedBrick);
        this.setBlock(world, i + 4, j + 9, k + 31, BlockRegistry.degradedBrick);
        this.setBlock(world, i + 4, j + 10, k + 0, BlockRegistry.degradedBrick);
        this.setBlock(world, i + 4, j + 10, k + 31, BlockRegistry.degradedBrick);
        this.setBlock(world, i + 4, j + 11, k + 0, BlockRegistry.degradedBrick);
        this.setBlock(world, i + 4, j + 11, k + 31, BlockRegistry.degradedBrick);
        this.setBlock(world, i + 4, j + 12, k + 0, BlockRegistry.ancientBrick);
        this.setBlock(world, i + 4, j + 12, k + 31, BlockRegistry.ancientBrick);
        this.setBlock(world, i + 4, j + 13, k + 0, BlockRegistry.ancientBrick);
        this.setBlock(world, i + 4, j + 13, k + 31, BlockRegistry.ancientBrick);
        this.setBlock(world, i + 4, j + 14, k + 0, BlockRegistry.ancientBrick);
        this.setBlock(world, i + 4, j + 14, k + 31, BlockRegistry.ancientBrick);
        this.setBlock(world, i + 4, j + 15, k + 0, BlockRegistry.ancientBrick);
        this.setBlock(world, i + 4, j + 15, k + 31, BlockRegistry.ancientBrick);
        this.setBlock(world, i + 5, j + 0, k + 0, BlockRegistry.ancientBrick);
        this.setBlock(world, i + 5, j + 0, k + 1, BlockRegistry.degradedBrick);
        this.setBlock(world, i + 5, j + 0, k + 2, BlockRegistry.degradedBrick);
        this.setBlock(world, i + 5, j + 0, k + 3, BlockRegistry.ancientBrick);
        this.setBlock(world, i + 5, j + 0, k + 4, BlockRegistry.ancientBrick);
        this.setBlock(world, i + 5, j + 0, k + 5, BlockRegistry.degradedBrick);
        this.setBlock(world, i + 5, j + 0, k + 6, BlockRegistry.degradedBrick);
        this.setBlock(world, i + 5, j + 0, k + 7, BlockRegistry.degradedBrick);
        this.setBlock(world, i + 5, j + 0, k + 8, BlockRegistry.degradedBrick);
        this.setBlock(world, i + 5, j + 0, k + 9, BlockRegistry.degradedBrick);
        this.setBlock(world, i + 5, j + 0, k + 10, BlockRegistry.degradedBrick);
        this.setBlock(world, i + 5, j + 0, k + 11, BlockRegistry.degradedBrick);
        this.setBlock(world, i + 5, j + 0, k + 12, BlockRegistry.degradedBrick);
        this.setBlock(world, i + 5, j + 0, k + 13, BlockRegistry.degradedBrick);
        this.setBlock(world, i + 5, j + 0, k + 14, BlockRegistry.degradedBrick);
        this.setBlock(world, i + 5, j + 0, k + 15, BlockRegistry.degradedBrick);
        this.setBlock(world, i + 5, j + 0, k + 16, BlockRegistry.degradedBrick);
        this.setBlock(world, i + 5, j + 0, k + 17, BlockRegistry.degradedBrick);
        this.setBlock(world, i + 5, j + 0, k + 18, BlockRegistry.degradedBrick);
        this.setBlock(world, i + 5, j + 0, k + 19, BlockRegistry.degradedBrick);
        this.setBlock(world, i + 5, j + 0, k + 20, BlockRegistry.degradedBrick);
        this.setBlock(world, i + 5, j + 0, k + 21, BlockRegistry.degradedBrick);
        this.setBlock(world, i + 5, j + 0, k + 22, BlockRegistry.degradedBrick);
        this.setBlock(world, i + 5, j + 0, k + 23, BlockRegistry.degradedBrick);
        this.setBlock(world, i + 5, j + 0, k + 24, BlockRegistry.degradedBrick);
        this.setBlock(world, i + 5, j + 0, k + 25, BlockRegistry.degradedBrick);
        this.setBlock(world, i + 5, j + 0, k + 26, BlockRegistry.degradedBrick);
        this.setBlock(world, i + 5, j + 0, k + 27, BlockRegistry.ancientBrick);
        this.setBlock(world, i + 5, j + 0, k + 28, BlockRegistry.ancientBrick);
        this.setBlock(world, i + 5, j + 0, k + 29, BlockRegistry.degradedBrick);
        this.setBlock(world, i + 5, j + 0, k + 30, BlockRegistry.degradedBrick);
        this.setBlock(world, i + 5, j + 0, k + 31, BlockRegistry.ancientBrick);
        this.setBlock(world, i + 5, j + 1, k + 0, BlockRegistry.ancientBrick);
        this.setBlock(world, i + 5, j + 1, k + 3, BlockRegistry.ancientBrick);
        this.setBlock(world, i + 5, j + 1, k + 4, BlockRegistry.ancientBrick);
        this.setBlock(world, i + 5, j + 1, k + 5, BlockRegistry.degradedBrick);
        this.setBlock(world, i + 5, j + 1, k + 6, BlockRegistry.degradedBrick);
        this.setBlock(world, i + 5, j + 1, k + 7, BlockRegistry.degradedBrick);
        this.setBlock(world, i + 5, j + 1, k + 8, BlockRegistry.degradedBrick);
        this.setBlock(world, i + 5, j + 1, k + 24, BlockRegistry.degradedBrick);
        this.setBlock(world, i + 5, j + 1, k + 25, BlockRegistry.degradedBrick);
        this.setBlock(world, i + 5, j + 1, k + 26, BlockRegistry.degradedBrick);
        this.setBlock(world, i + 5, j + 1, k + 27, BlockRegistry.ancientBrick);
        this.setBlock(world, i + 5, j + 1, k + 31, BlockRegistry.ancientBrick);
        this.setBlock(world, i + 5, j + 2, k + 0, BlockRegistry.ancientBrick);
        this.setBlock(world, i + 5, j + 2, k + 5, BlockRegistry.degradedBrick);
        this.setBlock(world, i + 5, j + 2, k + 6, BlockRegistry.degradedBrick);
        this.setBlock(world, i + 5, j + 2, k + 31, BlockRegistry.ancientBrick);
        this.setBlock(world, i + 5, j + 3, k + 0, BlockRegistry.ancientBrick);
        this.setBlock(world, i + 5, j + 3, k + 31, BlockRegistry.ancientBrick);
        this.setBlock(world, i + 5, j + 4, k + 0, BlockRegistry.soulStone);
        this.setBlock(world, i + 5, j + 4, k + 31, BlockRegistry.soulStone);
        this.setBlock(world, i + 5, j + 5, k + 0, BlockRegistry.soulStone);
        this.setBlock(world, i + 5, j + 5, k + 31, BlockRegistry.soulStone);
        this.setBlock(world, i + 5, j + 6, k + 0, BlockRegistry.ancientStone);
        this.setBlock(world, i + 5, j + 6, k + 31, BlockRegistry.ancientStone);
        this.setBlock(world, i + 5, j + 7, k + 0, BlockRegistry.ancientStone);
        this.setBlock(world, i + 5, j + 7, k + 31, BlockRegistry.ancientStone);
        this.setBlock(world, i + 5, j + 8, k + 0, BlockRegistry.ancientStone);
        this.setBlock(world, i + 5, j + 8, k + 31, BlockRegistry.ancientStone);
        this.setBlock(world, i + 5, j + 9, k + 0, BlockRegistry.degradedBrick);
        this.setBlock(world, i + 5, j + 9, k + 31, BlockRegistry.degradedBrick);
        this.setBlock(world, i + 5, j + 10, k + 0, BlockRegistry.degradedBrick);
        this.setBlock(world, i + 5, j + 10, k + 31, BlockRegistry.degradedBrick);
        this.setBlock(world, i + 5, j + 11, k + 0, BlockRegistry.ancientBrick);
        this.setBlock(world, i + 5, j + 11, k + 31, BlockRegistry.ancientBrick);
        this.setBlock(world, i + 5, j + 12, k + 0, BlockRegistry.ancientBrick);
        this.setBlock(world, i + 5, j + 12, k + 31, BlockRegistry.ancientBrick);
        this.setBlock(world, i + 5, j + 13, k + 0, BlockRegistry.ancientBrick);
        this.setBlock(world, i + 5, j + 13, k + 31, BlockRegistry.ancientBrick);
        this.setBlock(world, i + 5, j + 14, k + 0, BlockRegistry.ancientBrick);
        this.setBlock(world, i + 5, j + 14, k + 31, BlockRegistry.ancientBrick);
        this.setBlock(world, i + 5, j + 15, k + 0, BlockRegistry.ancientBrick);
        this.setBlock(world, i + 5, j + 15, k + 31, BlockRegistry.ancientBrick);
        this.setBlock(world, i + 6, j + 0, k + 0, BlockRegistry.ancientBrick);
        this.setBlock(world, i + 6, j + 0, k + 1, BlockRegistry.degradedBrick);
        this.setBlock(world, i + 6, j + 0, k + 2, BlockRegistry.degradedBrick);
        this.setBlock(world, i + 6, j + 0, k + 3, BlockRegistry.ancientBrick);
        this.setBlock(world, i + 6, j + 0, k + 4, BlockRegistry.ancientBrick);
        this.setBlock(world, i + 6, j + 0, k + 5, BlockRegistry.degradedBrick);
        this.setBlock(world, i + 6, j + 0, k + 6, BlockRegistry.degradedBrick);
        this.setBlock(world, i + 6, j + 0, k + 7, BlockRegistry.degradedBrick);
        this.setBlock(world, i + 6, j + 0, k + 8, BlockRegistry.degradedBrick);
        this.setBlock(world, i + 6, j + 0, k + 9, BlockRegistry.degradedBrick);
        this.setBlock(world, i + 6, j + 0, k + 10, BlockRegistry.degradedBrick);
        this.setBlock(world, i + 6, j + 0, k + 11, BlockRegistry.degradedBrick);
        this.setBlock(world, i + 6, j + 0, k + 12, BlockRegistry.degradedBrick);
        this.setBlock(world, i + 6, j + 0, k + 13, BlockRegistry.degradedBrick);
        this.setBlock(world, i + 6, j + 0, k + 14, BlockRegistry.degradedBrick);
        this.setBlock(world, i + 6, j + 0, k + 15, BlockRegistry.degradedBrick);
        this.setBlock(world, i + 6, j + 0, k + 16, BlockRegistry.degradedBrick);
        this.setBlock(world, i + 6, j + 0, k + 17, BlockRegistry.degradedBrick);
        this.setBlock(world, i + 6, j + 0, k + 18, BlockRegistry.degradedBrick);
        this.setBlock(world, i + 6, j + 0, k + 19, BlockRegistry.degradedBrick);
        this.setBlock(world, i + 6, j + 0, k + 20, BlockRegistry.degradedBrick);
        this.setBlock(world, i + 6, j + 0, k + 21, BlockRegistry.degradedBrick);
        this.setBlock(world, i + 6, j + 0, k + 22, BlockRegistry.degradedBrick);
        this.setBlock(world, i + 6, j + 0, k + 23, BlockRegistry.degradedBrick);
        this.setBlock(world, i + 6, j + 0, k + 24, BlockRegistry.degradedBrick);
        this.setBlock(world, i + 6, j + 0, k + 25, BlockRegistry.degradedBrick);
        this.setBlock(world, i + 6, j + 0, k + 26, BlockRegistry.degradedBrick);
        this.setBlock(world, i + 6, j + 0, k + 27, BlockRegistry.ancientBrick);
        this.setBlock(world, i + 6, j + 0, k + 28, BlockRegistry.ancientBrick);
        this.setBlock(world, i + 6, j + 0, k + 29, BlockRegistry.degradedBrick);
        this.setBlock(world, i + 6, j + 0, k + 30, BlockRegistry.degradedBrick);
        this.setBlock(world, i + 6, j + 0, k + 31, BlockRegistry.ancientBrick);
        this.setBlock(world, i + 6, j + 1, k + 0, BlockRegistry.ancientBrick);
        this.setBlock(world, i + 6, j + 1, k + 3, BlockRegistry.ancientBrick);
        this.setBlock(world, i + 6, j + 1, k + 4, BlockRegistry.ancientBrick);
        this.setBlock(world, i + 6, j + 1, k + 5, BlockRegistry.degradedBrick);
        this.setBlock(world, i + 6, j + 1, k + 6, BlockRegistry.degradedBrick);
        this.setBlock(world, i + 6, j + 1, k + 7, BlockRegistry.degradedBrick);
        this.setBlock(world, i + 6, j + 1, k + 8, BlockRegistry.degradedBrick);
        this.setBlock(world, i + 6, j + 1, k + 24, BlockRegistry.degradedBrick);
        this.setBlock(world, i + 6, j + 1, k + 25, BlockRegistry.degradedBrick);
        this.setBlock(world, i + 6, j + 1, k + 26, BlockRegistry.degradedBrick);
        this.setBlock(world, i + 6, j + 1, k + 27, BlockRegistry.ancientBrick);
        this.setBlock(world, i + 6, j + 1, k + 31, BlockRegistry.ancientBrick);
        this.setBlock(world, i + 6, j + 2, k + 0, BlockRegistry.ancientBrick);
        this.setBlock(world, i + 6, j + 2, k + 5, BlockRegistry.degradedBrick);
        this.setBlock(world, i + 6, j + 2, k + 6, BlockRegistry.degradedBrick);
        this.setBlock(world, i + 6, j + 2, k + 31, BlockRegistry.ancientBrick);
        this.setBlock(world, i + 6, j + 3, k + 0, BlockRegistry.ancientBrick);
        this.setBlock(world, i + 6, j + 3, k + 31, BlockRegistry.ancientBrick);
        this.setBlock(world, i + 6, j + 4, k + 0, BlockRegistry.soulStone);
        this.setBlock(world, i + 6, j + 4, k + 31, BlockRegistry.soulStone);
        this.setBlock(world, i + 6, j + 5, k + 0, BlockRegistry.soulStone);
        this.setBlock(world, i + 6, j + 5, k + 31, BlockRegistry.soulStone);
        this.setBlock(world, i + 6, j + 6, k + 0, BlockRegistry.ancientStone);
        this.setBlock(world, i + 6, j + 6, k + 31, BlockRegistry.ancientStone);
        this.setBlock(world, i + 6, j + 7, k + 0, BlockRegistry.ancientStone);
        this.setBlock(world, i + 6, j + 7, k + 31, BlockRegistry.ancientStone);
        this.setBlock(world, i + 6, j + 8, k + 0, BlockRegistry.ancientStone);
        this.setBlock(world, i + 6, j + 8, k + 31, BlockRegistry.ancientStone);
        this.setBlock(world, i + 6, j + 9, k + 0, BlockRegistry.degradedBrick);
        this.setBlock(world, i + 6, j + 9, k + 31, BlockRegistry.degradedBrick);
        this.setBlock(world, i + 6, j + 10, k + 0, BlockRegistry.degradedBrick);
        this.setBlock(world, i + 6, j + 10, k + 31, BlockRegistry.degradedBrick);
        this.setBlock(world, i + 6, j + 11, k + 0, BlockRegistry.degradedBrick);
        this.setBlock(world, i + 6, j + 11, k + 31, BlockRegistry.ancientBrick);
        this.setBlock(world, i + 6, j + 12, k + 0, BlockRegistry.ancientBrick);
        this.setBlock(world, i + 6, j + 12, k + 31, BlockRegistry.ancientBrick);
        this.setBlock(world, i + 6, j + 13, k + 0, BlockRegistry.ancientBrick);
        this.setBlock(world, i + 6, j + 13, k + 31, BlockRegistry.ancientBrick);
        this.setBlock(world, i + 6, j + 14, k + 0, BlockRegistry.ancientBrick);
        this.setBlock(world, i + 6, j + 14, k + 31, BlockRegistry.ancientBrick);
        this.setBlock(world, i + 6, j + 15, k + 0, BlockRegistry.ancientBrick);
        this.setBlock(world, i + 6, j + 15, k + 31, BlockRegistry.ancientBrick);
        this.setBlock(world, i + 7, j + 0, k + 0, BlockRegistry.ancientBrick);
        this.setBlock(world, i + 7, j + 0, k + 1, BlockRegistry.degradedBrick);
        this.setBlock(world, i + 7, j + 0, k + 2, BlockRegistry.degradedBrick);
        this.setBlock(world, i + 7, j + 0, k + 3, BlockRegistry.ancientBrick);
        this.setBlock(world, i + 7, j + 0, k + 4, BlockRegistry.ancientBrick);
        this.setBlock(world, i + 7, j + 0, k + 5, BlockRegistry.degradedBrick);
        this.setBlock(world, i + 7, j + 0, k + 6, BlockRegistry.degradedBrick);
        this.setBlock(world, i + 7, j + 0, k + 7, BlockRegistry.ancientBrick);
        this.setBlock(world, i + 7, j + 0, k + 8, BlockRegistry.ancientBrick);
        this.setBlock(world, i + 7, j + 0, k + 9, BlockRegistry.ancientBrick);
        this.setBlock(world, i + 7, j + 0, k + 10, BlockRegistry.ancientBrick);
        this.setBlock(world, i + 7, j + 0, k + 11, BlockRegistry.ancientBrick);
        this.setBlock(world, i + 7, j + 0, k + 12, BlockRegistry.ancientBrick);
        this.setBlock(world, i + 7, j + 0, k + 13, BlockRegistry.ancientBrick);
        this.setBlock(world, i + 7, j + 0, k + 14, BlockRegistry.ancientBrick);
        this.setBlock(world, i + 7, j + 0, k + 15, BlockRegistry.ancientBrick);
        this.setBlock(world, i + 7, j + 0, k + 16, BlockRegistry.ancientBrick);
        this.setBlock(world, i + 7, j + 0, k + 17, BlockRegistry.ancientBrick);
        this.setBlock(world, i + 7, j + 0, k + 18, BlockRegistry.ancientBrick);
        this.setBlock(world, i + 7, j + 0, k + 19, BlockRegistry.ancientBrick);
        this.setBlock(world, i + 7, j + 0, k + 20, BlockRegistry.ancientBrick);
        this.setBlock(world, i + 7, j + 0, k + 21, BlockRegistry.ancientBrick);
        this.setBlock(world, i + 7, j + 0, k + 22, BlockRegistry.ancientBrick);
        this.setBlock(world, i + 7, j + 0, k + 23, BlockRegistry.ancientBrick);
        this.setBlock(world, i + 7, j + 0, k + 24, BlockRegistry.ancientBrick);
        this.setBlock(world, i + 7, j + 0, k + 25, BlockRegistry.degradedBrick);
        this.setBlock(world, i + 7, j + 0, k + 26, BlockRegistry.degradedBrick);
        this.setBlock(world, i + 7, j + 0, k + 27, BlockRegistry.ancientBrick);
        this.setBlock(world, i + 7, j + 0, k + 28, BlockRegistry.ancientBrick);
        this.setBlock(world, i + 7, j + 0, k + 29, BlockRegistry.degradedBrick);
        this.setBlock(world, i + 7, j + 0, k + 30, BlockRegistry.degradedBrick);
        this.setBlock(world, i + 7, j + 0, k + 31, BlockRegistry.ancientBrick);
        this.setBlock(world, i + 7, j + 1, k + 0, BlockRegistry.ancientBrick);
        this.setBlock(world, i + 7, j + 1, k + 3, BlockRegistry.ancientBrick);
        this.setBlock(world, i + 7, j + 1, k + 4, BlockRegistry.ancientBrick);
        this.setBlock(world, i + 7, j + 1, k + 5, BlockRegistry.degradedBrick);
        this.setBlock(world, i + 7, j + 1, k + 6, BlockRegistry.degradedBrick);
        this.setBlock(world, i + 7, j + 1, k + 7, BlockRegistry.ancientBrick);
        this.setBlock(world, i + 7, j + 1, k + 8, BlockRegistry.ancientBrick);
        this.setBlock(world, i + 7, j + 1, k + 24, BlockRegistry.ancientBrick);
        this.setBlock(world, i + 7, j + 1, k + 25, BlockRegistry.degradedBrick);
        this.setBlock(world, i + 7, j + 1, k + 26, BlockRegistry.degradedBrick);
        this.setBlock(world, i + 7, j + 1, k + 27, BlockRegistry.ancientBrick);
        this.setBlock(world, i + 7, j + 1, k + 31, BlockRegistry.ancientBrick);
        this.setBlock(world, i + 7, j + 2, k + 0, BlockRegistry.ancientBrick);
        this.setBlock(world, i + 7, j + 2, k + 31, BlockRegistry.ancientBrick);
        this.setBlock(world, i + 7, j + 3, k + 0, BlockRegistry.ancientBrick);
        this.setBlock(world, i + 7, j + 3, k + 31, BlockRegistry.ancientBrick);
        this.setBlock(world, i + 7, j + 4, k + 0, BlockRegistry.soulStone);
        this.setBlock(world, i + 7, j + 4, k + 31, BlockRegistry.soulStone);
        this.setBlock(world, i + 7, j + 5, k + 0, BlockRegistry.soulStone);
        this.setBlock(world, i + 7, j + 5, k + 31, BlockRegistry.soulStone);
        this.setBlock(world, i + 7, j + 6, k + 0, BlockRegistry.ancientStone);
        this.setBlock(world, i + 7, j + 6, k + 31, BlockRegistry.ancientStone);
        this.setBlock(world, i + 7, j + 7, k + 0, BlockRegistry.ancientStone);
        this.setBlock(world, i + 7, j + 7, k + 31, BlockRegistry.ancientStone);
        this.setBlock(world, i + 7, j + 8, k + 0, BlockRegistry.ancientStone);
        this.setBlock(world, i + 7, j + 8, k + 31, BlockRegistry.ancientStone);
        this.setBlock(world, i + 7, j + 9, k + 0, BlockRegistry.degradedBrick);
        this.setBlock(world, i + 7, j + 9, k + 31, BlockRegistry.degradedBrick);
        this.setBlock(world, i + 7, j + 10, k + 0, BlockRegistry.degradedBrick);
        this.setBlock(world, i + 7, j + 10, k + 31, BlockRegistry.degradedBrick);
        this.setBlock(world, i + 7, j + 11, k + 0, BlockRegistry.degradedBrick);
        this.setBlock(world, i + 7, j + 11, k + 31, BlockRegistry.ancientBrick);
        this.setBlock(world, i + 7, j + 12, k + 0, BlockRegistry.degradedBrick);
        this.setBlock(world, i + 7, j + 12, k + 31, BlockRegistry.ancientBrick);
        this.setBlock(world, i + 7, j + 13, k + 0, BlockRegistry.ancientBrick);
        this.setBlock(world, i + 7, j + 13, k + 31, BlockRegistry.ancientBrick);
        this.setBlock(world, i + 7, j + 14, k + 0, BlockRegistry.ancientBrick);
        this.setBlock(world, i + 7, j + 14, k + 31, BlockRegistry.ancientBrick);
        this.setBlock(world, i + 7, j + 15, k + 0, BlockRegistry.ancientBrick);
        this.setBlock(world, i + 7, j + 15, k + 31, BlockRegistry.ancientBrick);
        this.setBlock(world, i + 8, j + 0, k + 0, BlockRegistry.ancientBrick);
        this.setBlock(world, i + 8, j + 0, k + 1, BlockRegistry.degradedBrick);
        this.setBlock(world, i + 8, j + 0, k + 2, BlockRegistry.degradedBrick);
        this.setBlock(world, i + 8, j + 0, k + 3, BlockRegistry.ancientBrick);
        this.setBlock(world, i + 8, j + 0, k + 4, BlockRegistry.ancientBrick);
        this.setBlock(world, i + 8, j + 0, k + 5, BlockRegistry.degradedBrick);
        this.setBlock(world, i + 8, j + 0, k + 6, BlockRegistry.degradedBrick);
        this.setBlock(world, i + 8, j + 0, k + 7, BlockRegistry.ancientBrick);
        this.setBlock(world, i + 8, j + 0, k + 8, BlockRegistry.ancientBrick);
        this.setBlock(world, i + 8, j + 0, k + 9, BlockRegistry.ancientBrick);
        this.setBlock(world, i + 8, j + 0, k + 10, BlockRegistry.ancientBrick);
        this.setBlock(world, i + 8, j + 0, k + 11, BlockRegistry.ancientBrick);
        this.setBlock(world, i + 8, j + 0, k + 12, BlockRegistry.ancientBrick);
        this.setBlock(world, i + 8, j + 0, k + 13, BlockRegistry.ancientBrick);
        this.setBlock(world, i + 8, j + 0, k + 14, BlockRegistry.ancientBrick);
        this.setBlock(world, i + 8, j + 0, k + 15, BlockRegistry.ancientBrick);
        this.setBlock(world, i + 8, j + 0, k + 16, BlockRegistry.ancientBrick);
        this.setBlock(world, i + 8, j + 0, k + 17, BlockRegistry.ancientBrick);
        this.setBlock(world, i + 8, j + 0, k + 18, BlockRegistry.ancientBrick);
        this.setBlock(world, i + 8, j + 0, k + 19, BlockRegistry.ancientBrick);
        this.setBlock(world, i + 8, j + 0, k + 20, BlockRegistry.ancientBrick);
        this.setBlock(world, i + 8, j + 0, k + 21, BlockRegistry.ancientBrick);
        this.setBlock(world, i + 8, j + 0, k + 22, BlockRegistry.ancientBrick);
        this.setBlock(world, i + 8, j + 0, k + 23, BlockRegistry.ancientBrick);
        this.setBlock(world, i + 8, j + 0, k + 24, BlockRegistry.ancientBrick);
        this.setBlock(world, i + 8, j + 0, k + 25, BlockRegistry.degradedBrick);
        this.setBlock(world, i + 8, j + 0, k + 26, BlockRegistry.degradedBrick);
        this.setBlock(world, i + 8, j + 0, k + 27, BlockRegistry.ancientBrick);
        this.setBlock(world, i + 8, j + 0, k + 28, BlockRegistry.ancientBrick);
        this.setBlock(world, i + 8, j + 0, k + 29, BlockRegistry.degradedBrick);
        this.setBlock(world, i + 8, j + 0, k + 30, BlockRegistry.degradedBrick);
        this.setBlock(world, i + 8, j + 0, k + 31, BlockRegistry.ancientBrick);
        this.setBlock(world, i + 8, j + 1, k + 0, BlockRegistry.ancientBrick);
        this.setBlock(world, i + 8, j + 1, k + 3, BlockRegistry.ancientBrick);
        this.setBlock(world, i + 8, j + 1, k + 4, BlockRegistry.ancientBrick);
        this.setBlock(world, i + 8, j + 1, k + 5, BlockRegistry.degradedBrick);
        this.setBlock(world, i + 8, j + 1, k + 6, BlockRegistry.degradedBrick);
        this.setBlock(world, i + 8, j + 1, k + 7, BlockRegistry.ancientBrick);
        this.setBlock(world, i + 8, j + 1, k + 8, BlockRegistry.ancientBrick);
        this.setBlock(world, i + 8, j + 1, k + 31, BlockRegistry.ancientBrick);
        this.setBlock(world, i + 8, j + 2, k + 0, BlockRegistry.ancientBrick);
        this.setBlock(world, i + 8, j + 2, k + 31, BlockRegistry.ancientBrick);
        this.setBlock(world, i + 8, j + 3, k + 0, BlockRegistry.ancientBrick);
        this.setBlock(world, i + 8, j + 3, k + 31, BlockRegistry.ancientBrick);
        this.setBlock(world, i + 8, j + 4, k + 0, BlockRegistry.soulStone);
        this.setBlock(world, i + 8, j + 4, k + 31, BlockRegistry.soulStone);
        this.setBlock(world, i + 8, j + 5, k + 0, BlockRegistry.soulStone);
        this.setBlock(world, i + 8, j + 5, k + 31, BlockRegistry.soulStone);
        this.setBlock(world, i + 8, j + 6, k + 0, BlockRegistry.ancientStone);
        this.setBlock(world, i + 8, j + 6, k + 31, BlockRegistry.ancientStone);
        this.setBlock(world, i + 8, j + 7, k + 0, BlockRegistry.ancientStone);
        this.setBlock(world, i + 8, j + 7, k + 31, BlockRegistry.ancientStone);
        this.setBlock(world, i + 8, j + 8, k + 0, BlockRegistry.ancientStone);
        this.setBlock(world, i + 8, j + 8, k + 31, BlockRegistry.ancientStone);
        this.setBlock(world, i + 8, j + 9, k + 0, BlockRegistry.degradedBrick);
        this.setBlock(world, i + 8, j + 9, k + 31, BlockRegistry.degradedBrick);
        this.setBlock(world, i + 8, j + 10, k + 0, BlockRegistry.degradedBrick);
        this.setBlock(world, i + 8, j + 10, k + 31, BlockRegistry.degradedBrick);
        this.setBlock(world, i + 8, j + 11, k + 0, BlockRegistry.degradedBrick);
        this.setBlock(world, i + 8, j + 11, k + 31, BlockRegistry.ancientBrick);
        this.setBlock(world, i + 8, j + 12, k + 0, BlockRegistry.degradedBrick);
        this.setBlock(world, i + 8, j + 12, k + 31, BlockRegistry.ancientBrick);
        this.setBlock(world, i + 8, j + 13, k + 0, BlockRegistry.degradedBrick);
        this.setBlock(world, i + 8, j + 13, k + 31, BlockRegistry.ancientBrick);
        this.setBlock(world, i + 8, j + 14, k + 0, BlockRegistry.ancientBrick);
        this.setBlock(world, i + 8, j + 14, k + 31, BlockRegistry.ancientBrick);
        this.setBlock(world, i + 8, j + 15, k + 0, BlockRegistry.ancientBrick);
        this.setBlock(world, i + 8, j + 15, k + 31, BlockRegistry.ancientBrick);
        this.setBlock(world, i + 9, j + 0, k + 0, BlockRegistry.ancientBrick);
        this.setBlock(world, i + 9, j + 0, k + 1, BlockRegistry.degradedBrick);
        this.setBlock(world, i + 9, j + 0, k + 2, BlockRegistry.degradedBrick);
        this.setBlock(world, i + 9, j + 0, k + 3, BlockRegistry.ancientBrick);
        this.setBlock(world, i + 9, j + 0, k + 4, BlockRegistry.ancientBrick);
        this.setBlock(world, i + 9, j + 0, k + 5, BlockRegistry.degradedBrick);
        this.setBlock(world, i + 9, j + 0, k + 6, BlockRegistry.degradedBrick);
        this.setBlock(world, i + 9, j + 0, k + 7, BlockRegistry.ancientBrick);
        this.setBlock(world, i + 9, j + 0, k + 8, BlockRegistry.ancientBrick);
        this.setBlock(world, i + 9, j + 0, k + 9, BlockRegistry.degradedBrick);
        this.setBlock(world, i + 9, j + 0, k + 10, BlockRegistry.degradedBrick);
        this.setBlock(world, i + 9, j + 0, k + 11, BlockRegistry.degradedBrick);
        this.setBlock(world, i + 9, j + 0, k + 12, BlockRegistry.degradedBrick);
        this.setBlock(world, i + 9, j + 0, k + 13, BlockRegistry.degradedBrick);
        this.setBlock(world, i + 9, j + 0, k + 14, BlockRegistry.degradedBrick);
        this.setBlock(world, i + 9, j + 0, k + 15, BlockRegistry.degradedBrick);
        this.setBlock(world, i + 9, j + 0, k + 16, BlockRegistry.degradedBrick);
        this.setBlock(world, i + 9, j + 0, k + 17, BlockRegistry.degradedBrick);
        this.setBlock(world, i + 9, j + 0, k + 18, BlockRegistry.degradedBrick);
        this.setBlock(world, i + 9, j + 0, k + 19, BlockRegistry.degradedBrick);
        this.setBlock(world, i + 9, j + 0, k + 20, BlockRegistry.degradedBrick);
        this.setBlock(world, i + 9, j + 0, k + 21, BlockRegistry.degradedBrick);
        this.setBlock(world, i + 9, j + 0, k + 22, BlockRegistry.degradedBrick);
        this.setBlock(world, i + 9, j + 0, k + 23, BlockRegistry.ancientBrick);
        this.setBlock(world, i + 9, j + 0, k + 24, BlockRegistry.ancientBrick);
        this.setBlock(world, i + 9, j + 0, k + 25, BlockRegistry.degradedBrick);
        this.setBlock(world, i + 9, j + 0, k + 26, BlockRegistry.degradedBrick);
        this.setBlock(world, i + 9, j + 0, k + 27, BlockRegistry.ancientBrick);
        this.setBlock(world, i + 9, j + 0, k + 28, BlockRegistry.ancientBrick);
        this.setBlock(world, i + 9, j + 0, k + 29, BlockRegistry.degradedBrick);
        this.setBlock(world, i + 9, j + 0, k + 30, BlockRegistry.degradedBrick);
        this.setBlock(world, i + 9, j + 0, k + 31, BlockRegistry.ancientBrick);
        this.setBlock(world, i + 9, j + 1, k + 0, BlockRegistry.ancientBrick);
        this.setBlock(world, i + 9, j + 1, k + 31, BlockRegistry.ancientBrick);
        this.setBlock(world, i + 9, j + 2, k + 0, BlockRegistry.ancientBrick);
        this.setBlock(world, i + 9, j + 2, k + 31, BlockRegistry.ancientBrick);
        this.setBlock(world, i + 9, j + 3, k + 0, BlockRegistry.ancientBrick);
        this.setBlock(world, i + 9, j + 3, k + 31, BlockRegistry.ancientBrick);
        this.setBlock(world, i + 9, j + 4, k + 0, BlockRegistry.soulStone);
        this.setBlock(world, i + 9, j + 4, k + 31, BlockRegistry.soulStone);
        this.setBlock(world, i + 9, j + 5, k + 0, BlockRegistry.soulStone);
        this.setBlock(world, i + 9, j + 5, k + 31, BlockRegistry.soulStone);
        this.setBlock(world, i + 9, j + 6, k + 0, BlockRegistry.ancientStone);
        this.setBlock(world, i + 9, j + 6, k + 31, BlockRegistry.ancientStone);
        this.setBlock(world, i + 9, j + 7, k + 0, BlockRegistry.ancientStone);
        this.setBlock(world, i + 9, j + 7, k + 31, BlockRegistry.ancientStone);
        this.setBlock(world, i + 9, j + 8, k + 0, BlockRegistry.ancientStone);
        this.setBlock(world, i + 9, j + 8, k + 31, BlockRegistry.ancientStone);
        this.setBlock(world, i + 9, j + 9, k + 0, BlockRegistry.degradedBrick);
        this.setBlock(world, i + 9, j + 9, k + 31, BlockRegistry.degradedBrick);
        this.setBlock(world, i + 9, j + 10, k + 0, BlockRegistry.degradedBrick);
        this.setBlock(world, i + 9, j + 10, k + 31, BlockRegistry.degradedBrick);
        this.setBlock(world, i + 9, j + 11, k + 0, BlockRegistry.degradedBrick);
        this.setBlock(world, i + 9, j + 11, k + 31, BlockRegistry.ancientBrick);
        this.setBlock(world, i + 9, j + 12, k + 0, BlockRegistry.degradedBrick);
        this.setBlock(world, i + 9, j + 12, k + 31, BlockRegistry.ancientBrick);
        this.setBlock(world, i + 9, j + 13, k + 0, BlockRegistry.ancientBrick);
        this.setBlock(world, i + 9, j + 13, k + 31, BlockRegistry.ancientBrick);
        this.setBlock(world, i + 9, j + 14, k + 0, BlockRegistry.ancientBrick);
        this.setBlock(world, i + 9, j + 14, k + 31, BlockRegistry.ancientBrick);
        this.setBlock(world, i + 9, j + 15, k + 0, BlockRegistry.ancientBrick);
        this.setBlock(world, i + 9, j + 15, k + 31, BlockRegistry.ancientBrick);
        this.setBlock(world, i + 10, j + 0, k + 0, BlockRegistry.ancientBrick);
        this.setBlock(world, i + 10, j + 0, k + 1, BlockRegistry.degradedBrick);
        this.setBlock(world, i + 10, j + 0, k + 2, BlockRegistry.degradedBrick);
        this.setBlock(world, i + 10, j + 0, k + 3, BlockRegistry.ancientBrick);
        this.setBlock(world, i + 10, j + 0, k + 4, BlockRegistry.ancientBrick);
        this.setBlock(world, i + 10, j + 0, k + 5, BlockRegistry.degradedBrick);
        this.setBlock(world, i + 10, j + 0, k + 6, BlockRegistry.degradedBrick);
        this.setBlock(world, i + 10, j + 0, k + 7, BlockRegistry.ancientBrick);
        this.setBlock(world, i + 10, j + 0, k + 8, BlockRegistry.ancientBrick);
        this.setBlock(world, i + 10, j + 0, k + 9, BlockRegistry.degradedBrick);
        this.setBlock(world, i + 10, j + 0, k + 10, BlockRegistry.degradedBrick);
        this.setBlock(world, i + 10, j + 0, k + 11, BlockRegistry.degradedBrick);
        this.setBlock(world, i + 10, j + 0, k + 12, BlockRegistry.degradedBrick);
        this.setBlock(world, i + 10, j + 0, k + 13, BlockRegistry.degradedBrick);
        this.setBlock(world, i + 10, j + 0, k + 14, BlockRegistry.degradedBrick);
        this.setBlock(world, i + 10, j + 0, k + 15, BlockRegistry.degradedBrick);
        this.setBlock(world, i + 10, j + 0, k + 16, BlockRegistry.degradedBrick);
        this.setBlock(world, i + 10, j + 0, k + 17, BlockRegistry.degradedBrick);
        this.setBlock(world, i + 10, j + 0, k + 18, BlockRegistry.degradedBrick);
        this.setBlock(world, i + 10, j + 0, k + 19, BlockRegistry.degradedBrick);
        this.setBlock(world, i + 10, j + 0, k + 20, BlockRegistry.degradedBrick);
        this.setBlock(world, i + 10, j + 0, k + 21, BlockRegistry.degradedBrick);
        this.setBlock(world, i + 10, j + 0, k + 22, BlockRegistry.degradedBrick);
        this.setBlock(world, i + 10, j + 0, k + 23, BlockRegistry.ancientBrick);
        this.setBlock(world, i + 10, j + 0, k + 24, BlockRegistry.ancientBrick);
        this.setBlock(world, i + 10, j + 0, k + 25, BlockRegistry.degradedBrick);
        this.setBlock(world, i + 10, j + 0, k + 26, BlockRegistry.degradedBrick);
        this.setBlock(world, i + 10, j + 0, k + 27, BlockRegistry.ancientBrick);
        this.setBlock(world, i + 10, j + 0, k + 28, BlockRegistry.ancientBrick);
        this.setBlock(world, i + 10, j + 0, k + 29, BlockRegistry.degradedBrick);
        this.setBlock(world, i + 10, j + 0, k + 30, BlockRegistry.degradedBrick);
        this.setBlock(world, i + 10, j + 0, k + 31, BlockRegistry.ancientBrick);
        this.setBlock(world, i + 10, j + 1, k + 0, BlockRegistry.ancientBrick);
        this.setBlock(world, i + 10, j + 1, k + 31, BlockRegistry.ancientBrick);
        this.setBlock(world, i + 10, j + 2, k + 0, BlockRegistry.ancientBrick);
        this.setBlock(world, i + 10, j + 2, k + 31, BlockRegistry.ancientBrick);
        this.setBlock(world, i + 10, j + 3, k + 0, BlockRegistry.ancientBrick);
        this.setBlock(world, i + 10, j + 3, k + 31, BlockRegistry.ancientBrick);
        this.setBlock(world, i + 10, j + 4, k + 0, BlockRegistry.soulStone);
        this.setBlock(world, i + 10, j + 4, k + 31, BlockRegistry.soulStone);
        this.setBlock(world, i + 10, j + 5, k + 0, BlockRegistry.soulStone);
        this.setBlock(world, i + 10, j + 5, k + 31, BlockRegistry.soulStone);
        this.setBlock(world, i + 10, j + 6, k + 0, BlockRegistry.ancientStone);
        this.setBlock(world, i + 10, j + 6, k + 31, BlockRegistry.ancientStone);
        this.setBlock(world, i + 10, j + 7, k + 0, BlockRegistry.ancientStone);
        this.setBlock(world, i + 10, j + 7, k + 31, BlockRegistry.ancientStone);
        this.setBlock(world, i + 10, j + 8, k + 0, BlockRegistry.ancientStone);
        this.setBlock(world, i + 10, j + 8, k + 31, BlockRegistry.ancientStone);
        this.setBlock(world, i + 10, j + 9, k + 0, BlockRegistry.degradedBrick);
        this.setBlock(world, i + 10, j + 9, k + 31, BlockRegistry.degradedBrick);
        this.setBlock(world, i + 10, j + 10, k + 0, BlockRegistry.degradedBrick);
        this.setBlock(world, i + 10, j + 10, k + 31, BlockRegistry.degradedBrick);
        this.setBlock(world, i + 10, j + 11, k + 0, BlockRegistry.degradedBrick);
        this.setBlock(world, i + 10, j + 11, k + 31, BlockRegistry.ancientBrick);
        this.setBlock(world, i + 10, j + 12, k + 0, BlockRegistry.ancientBrick);
        this.setBlock(world, i + 10, j + 12, k + 31, BlockRegistry.ancientBrick);
        this.setBlock(world, i + 10, j + 13, k + 0, BlockRegistry.ancientBrick);
        this.setBlock(world, i + 10, j + 13, k + 31, BlockRegistry.ancientBrick);
        this.setBlock(world, i + 10, j + 14, k + 0, BlockRegistry.ancientBrick);
        this.setBlock(world, i + 10, j + 14, k + 31, BlockRegistry.ancientBrick);
        this.setBlock(world, i + 10, j + 15, k + 0, BlockRegistry.ancientBrick);
        this.setBlock(world, i + 10, j + 15, k + 31, BlockRegistry.ancientBrick);
        this.setBlock(world, i + 11, j + 0, k + 0, BlockRegistry.ancientBrick);
        this.setBlock(world, i + 11, j + 0, k + 1, BlockRegistry.degradedBrick);
        this.setBlock(world, i + 11, j + 0, k + 2, BlockRegistry.degradedBrick);
        this.setBlock(world, i + 11, j + 0, k + 3, BlockRegistry.ancientBrick);
        this.setBlock(world, i + 11, j + 0, k + 4, BlockRegistry.ancientBrick);
        this.setBlock(world, i + 11, j + 0, k + 5, BlockRegistry.degradedBrick);
        this.setBlock(world, i + 11, j + 0, k + 6, BlockRegistry.degradedBrick);
        this.setBlock(world, i + 11, j + 0, k + 7, BlockRegistry.ancientBrick);
        this.setBlock(world, i + 11, j + 0, k + 8, BlockRegistry.ancientBrick);
        this.setBlock(world, i + 11, j + 0, k + 9, BlockRegistry.degradedBrick);
        this.setBlock(world, i + 11, j + 0, k + 10, BlockRegistry.degradedBrick);
        this.setBlock(world, i + 11, j + 0, k + 11, BlockRegistry.ancientBrick);
        this.setBlock(world, i + 11, j + 0, k + 12, BlockRegistry.ancientBrick);
        this.setBlock(world, i + 11, j + 0, k + 13, BlockRegistry.ancientBrick);
        this.setBlock(world, i + 11, j + 0, k + 14, BlockRegistry.ancientBrick);
        this.setBlock(world, i + 11, j + 0, k + 15, BlockRegistry.ancientBrick);
        this.setBlock(world, i + 11, j + 0, k + 16, BlockRegistry.ancientBrick);
        this.setBlock(world, i + 11, j + 0, k + 17, BlockRegistry.ancientBrick);
        this.setBlock(world, i + 11, j + 0, k + 18, BlockRegistry.ancientBrick);
        this.setBlock(world, i + 11, j + 0, k + 19, BlockRegistry.ancientBrick);
        this.setBlock(world, i + 11, j + 0, k + 20, BlockRegistry.ancientBrick);
        this.setBlock(world, i + 11, j + 0, k + 21, BlockRegistry.degradedBrick);
        this.setBlock(world, i + 11, j + 0, k + 22, BlockRegistry.degradedBrick);
        this.setBlock(world, i + 11, j + 0, k + 23, BlockRegistry.ancientBrick);
        this.setBlock(world, i + 11, j + 0, k + 24, BlockRegistry.ancientBrick);
        this.setBlock(world, i + 11, j + 0, k + 25, BlockRegistry.degradedBrick);
        this.setBlock(world, i + 11, j + 0, k + 26, BlockRegistry.degradedBrick);
        this.setBlock(world, i + 11, j + 0, k + 27, BlockRegistry.ancientBrick);
        this.setBlock(world, i + 11, j + 0, k + 28, BlockRegistry.ancientBrick);
        this.setBlock(world, i + 11, j + 0, k + 29, BlockRegistry.degradedBrick);
        this.setBlock(world, i + 11, j + 0, k + 30, BlockRegistry.degradedBrick);
        this.setBlock(world, i + 11, j + 0, k + 31, BlockRegistry.ancientBrick);
        this.setBlock(world, i + 11, j + 1, k + 0, BlockRegistry.ancientBrick);
        this.setBlock(world, i + 11, j + 1, k + 11, BlockRegistry.degradedBrick);
        this.setBlock(world, i + 11, j + 1, k + 12, BlockRegistry.degradedBrick);
        this.setBlock(world, i + 11, j + 1, k + 13, BlockRegistry.degradedBrick);
        this.setBlock(world, i + 11, j + 1, k + 14, BlockRegistry.degradedBrick);
        this.setBlock(world, i + 11, j + 1, k + 15, BlockRegistry.degradedBrick);
        this.setBlock(world, i + 11, j + 1, k + 16, BlockRegistry.degradedBrick);
        this.setBlock(world, i + 11, j + 1, k + 17, BlockRegistry.degradedBrick);
        this.setBlock(world, i + 11, j + 1, k + 18, BlockRegistry.degradedBrick);
        this.setBlock(world, i + 11, j + 1, k + 19, BlockRegistry.degradedBrick);
        this.setBlock(world, i + 11, j + 1, k + 20, BlockRegistry.degradedBrick);
        this.setBlock(world, i + 11, j + 1, k + 31, BlockRegistry.ancientBrick);
        this.setBlock(world, i + 11, j + 2, k + 0, BlockRegistry.ancientBrick);
        this.setBlock(world, i + 11, j + 2, k + 31, BlockRegistry.ancientBrick);
        this.setBlock(world, i + 11, j + 3, k + 0, BlockRegistry.ancientBrick);
        this.setBlock(world, i + 11, j + 3, k + 31, BlockRegistry.ancientBrick);
        this.setBlock(world, i + 11, j + 4, k + 0, BlockRegistry.soulStone);
        this.setBlock(world, i + 11, j + 4, k + 31, BlockRegistry.soulStone);
        this.setBlock(world, i + 11, j + 5, k + 0, BlockRegistry.soulStone);
