package net.divinerpg.dimensions.arcana.components;
import java.util.Random;

import net.divinerpg.blocks.arcana.BlockArcanaFrame;
import net.divinerpg.blocks.arcana.BlockArcanaPortal;
import net.divinerpg.blocks.base.BlockMod;
import net.divinerpg.dimensions.arcana.ArcanaChunk;
import net.divinerpg.utils.blocks.ArcanaBlocks;
import net.minecraft.block.Block;

public class DungeonComponentPortal extends DungeonComponentBase {

    @Override
    public boolean generate(ArcanaChunk arcanaChunk, Random rand, int x, int y, int z) {

    	Block arcanaPortal = ArcanaBlocks.arcanaPortal;
	    Block arcanaHardPortalFrame = ArcanaBlocks.arcanaHardPortalFrame;
        Block dungeonBricks = ArcanaBlocks.degradedBrick;
        Block ancientbricks = ArcanaBlocks.ancientBrick;
        Block ancientTile = ArcanaBlocks.ancientTile;
        Block arcanaPower = ArcanaBlocks.arcaniumPower;

        arcanaChunk.setBlock(x + 0, y + 0, z + 0, ancientbricks);
        arcanaChunk.setBlock(x + 0, y + 0, z + 1, ancientbricks);
        arcanaChunk.setBlock(x + 0, y + 0, z + 2, ancientbricks);
        arcanaChunk.setBlock(x + 0, y + 0, z + 3, ancientbricks);
        arcanaChunk.setBlock(x + 0, y + 0, z + 4, ancientbricks);
        arcanaChunk.setBlock(x + 0, y + 0, z + 5, ancientbricks);
        arcanaChunk.setBlock(x + 0, y + 0, z + 6, ancientbricks);
        arcanaChunk.setBlock(x + 0, y + 0, z + 7, ancientbricks);
        arcanaChunk.setBlock(x + 0, y + 0, z + 8, ancientbricks);
        arcanaChunk.setBlock(x + 0, y + 0, z + 9, ancientbricks);
        arcanaChunk.setBlock(x + 0, y + 0, z + 10, ancientbricks);
        arcanaChunk.setBlock(x + 0, y + 0, z + 11, ancientbricks);
        arcanaChunk.setBlock(x + 0, y + 0, z + 12, ancientbricks);
        arcanaChunk.setBlock(x + 0, y + 0, z + 13, ancientbricks);
        arcanaChunk.setBlock(x + 0, y + 0, z + 14, ancientbricks);
        arcanaChunk.setBlock(x + 0, y + 0, z + 15, ancientbricks);
        arcanaChunk.setBlock(x + 0, y + 1, z + 0, dungeonBricks);
        arcanaChunk.setBlock(x + 0, y + 1, z + 1, dungeonBricks);
        arcanaChunk.setBlock(x + 0, y + 1, z + 2, dungeonBricks);
        arcanaChunk.setBlock(x + 0, y + 1, z + 3, dungeonBricks);
        arcanaChunk.setBlock(x + 0, y + 1, z + 4, dungeonBricks);
        arcanaChunk.setBlock(x + 0, y + 1, z + 5, dungeonBricks);
        arcanaChunk.setBlock(x + 0, y + 1, z + 6, dungeonBricks);
        arcanaChunk.setBlock(x + 0, y + 1, z + 9, dungeonBricks);
        arcanaChunk.setBlock(x + 0, y + 1, z + 10, dungeonBricks);
        arcanaChunk.setBlock(x + 0, y + 1, z + 11, dungeonBricks);
        arcanaChunk.setBlock(x + 0, y + 1, z + 12, dungeonBricks);
        arcanaChunk.setBlock(x + 0, y + 1, z + 13, dungeonBricks);
        arcanaChunk.setBlock(x + 0, y + 1, z + 14, dungeonBricks);
        arcanaChunk.setBlock(x + 0, y + 1, z + 15, dungeonBricks);
        arcanaChunk.setBlock(x + 0, y + 2, z + 0, dungeonBricks);
        arcanaChunk.setBlock(x + 0, y + 2, z + 1, ancientTile);
        arcanaChunk.setBlock(x + 0, y + 2, z + 2, dungeonBricks);
        arcanaChunk.setBlock(x + 0, y + 2, z + 3, ancientTile);
        arcanaChunk.setBlock(x + 0, y + 2, z + 4, dungeonBricks);
        arcanaChunk.setBlock(x + 0, y + 2, z + 5, ancientTile);
        arcanaChunk.setBlock(x + 0, y + 2, z + 6, dungeonBricks);
        arcanaChunk.setBlock(x + 0, y + 2, z + 9, dungeonBricks);
        arcanaChunk.setBlock(x + 0, y + 2, z + 10, ancientTile);
        arcanaChunk.setBlock(x + 0, y + 2, z + 11, dungeonBricks);
        arcanaChunk.setBlock(x + 0, y + 2, z + 12, ancientTile);
        arcanaChunk.setBlock(x + 0, y + 2, z + 13, dungeonBricks);
        arcanaChunk.setBlock(x + 0, y + 2, z + 14, dungeonBricks);
        arcanaChunk.setBlock(x + 0, y + 2, z + 15, dungeonBricks);
        arcanaChunk.setBlock(x + 0, y + 3, z + 0, dungeonBricks);
        arcanaChunk.setBlock(x + 0, y + 3, z + 1, dungeonBricks);
        arcanaChunk.setBlock(x + 0, y + 3, z + 2, dungeonBricks);
        arcanaChunk.setBlock(x + 0, y + 3, z + 3, dungeonBricks);
        arcanaChunk.setBlock(x + 0, y + 3, z + 4, dungeonBricks);
        arcanaChunk.setBlock(x + 0, y + 3, z + 5, dungeonBricks);
        arcanaChunk.setBlock(x + 0, y + 3, z + 6, dungeonBricks);
        arcanaChunk.setBlock(x + 0, y + 3, z + 7, arcanaPower);
        arcanaChunk.setBlock(x + 0, y + 3, z + 8, arcanaPower);
        arcanaChunk.setBlock(x + 0, y + 3, z + 9, dungeonBricks);
        arcanaChunk.setBlock(x + 0, y + 3, z + 10, dungeonBricks);
        arcanaChunk.setBlock(x + 0, y + 3, z + 11, dungeonBricks);
        arcanaChunk.setBlock(x + 0, y + 3, z + 12, dungeonBricks);
        arcanaChunk.setBlock(x + 0, y + 3, z + 13, dungeonBricks);
        arcanaChunk.setBlock(x + 0, y + 3, z + 14, dungeonBricks);
        arcanaChunk.setBlock(x + 0, y + 3, z + 15, dungeonBricks);
        arcanaChunk.setBlock(x + 0, y + 4, z + 0, ancientbricks);
        arcanaChunk.setBlock(x + 0, y + 4, z + 1, ancientbricks);
        arcanaChunk.setBlock(x + 0, y + 4, z + 2, ancientbricks);
        arcanaChunk.setBlock(x + 0, y + 4, z + 3, ancientbricks);
        arcanaChunk.setBlock(x + 0, y + 4, z + 4, ancientbricks);
        arcanaChunk.setBlock(x + 0, y + 4, z + 5, ancientbricks);
        arcanaChunk.setBlock(x + 0, y + 4, z + 6, ancientbricks);
        arcanaChunk.setBlock(x + 0, y + 4, z + 7, ancientbricks);
        arcanaChunk.setBlock(x + 0, y + 4, z + 8, ancientbricks);
        arcanaChunk.setBlock(x + 0, y + 4, z + 9, ancientbricks);
        arcanaChunk.setBlock(x + 0, y + 4, z + 10, ancientbricks);
        arcanaChunk.setBlock(x + 0, y + 4, z + 11, ancientbricks);
        arcanaChunk.setBlock(x + 0, y + 4, z + 12, ancientbricks);
        arcanaChunk.setBlock(x + 0, y + 4, z + 13, ancientbricks);
        arcanaChunk.setBlock(x + 0, y + 4, z + 14, ancientbricks);
        arcanaChunk.setBlock(x + 0, y + 4, z + 15, dungeonBricks);
        arcanaChunk.setBlock(x + 0, y + 5, z + 0, ancientbricks);
        arcanaChunk.setBlock(x + 0, y + 5, z + 1, ancientTile);
        arcanaChunk.setBlock(x + 0, y + 5, z + 2, ancientbricks);
        arcanaChunk.setBlock(x + 0, y + 5, z + 3, ancientTile);
        arcanaChunk.setBlock(x + 0, y + 5, z + 4, ancientbricks);
        arcanaChunk.setBlock(x + 0, y + 5, z + 5, ancientTile);
        arcanaChunk.setBlock(x + 0, y + 5, z + 6, ancientbricks);
        arcanaChunk.setBlock(x + 0, y + 5, z + 7, ancientTile);
        arcanaChunk.setBlock(x + 0, y + 5, z + 8, ancientbricks);
        arcanaChunk.setBlock(x + 0, y + 5, z + 9, ancientTile);
        arcanaChunk.setBlock(x + 0, y + 5, z + 10, ancientbricks);
        arcanaChunk.setBlock(x + 0, y + 5, z + 11, ancientTile);
        arcanaChunk.setBlock(x + 0, y + 5, z + 12, ancientbricks);
        arcanaChunk.setBlock(x + 0, y + 5, z + 13, ancientTile);
        arcanaChunk.setBlock(x + 0, y + 5, z + 14, ancientbricks);
        arcanaChunk.setBlock(x + 0, y + 5, z + 15, dungeonBricks);
        arcanaChunk.setBlock(x + 0, y + 6, z + 0, ancientbricks);
        arcanaChunk.setBlock(x + 0, y + 6, z + 1, ancientbricks);
        arcanaChunk.setBlock(x + 0, y + 6, z + 2, ancientbricks);
        arcanaChunk.setBlock(x + 0, y + 6, z + 3, ancientbricks);
        arcanaChunk.setBlock(x + 0, y + 6, z + 4, ancientbricks);
        arcanaChunk.setBlock(x + 0, y + 6, z + 5, ancientbricks);
        arcanaChunk.setBlock(x + 0, y + 6, z + 6, ancientbricks);
        arcanaChunk.setBlock(x + 0, y + 6, z + 7, ancientbricks);
        arcanaChunk.setBlock(x + 0, y + 6, z + 8, ancientbricks);
        arcanaChunk.setBlock(x + 0, y + 6, z + 9, ancientbricks);
        arcanaChunk.setBlock(x + 0, y + 6, z + 10, ancientbricks);
        arcanaChunk.setBlock(x + 0, y + 6, z + 11, ancientbricks);
        arcanaChunk.setBlock(x + 0, y + 6, z + 12, ancientbricks);
        arcanaChunk.setBlock(x + 0, y + 6, z + 13, ancientbricks);
        arcanaChunk.setBlock(x + 0, y + 6, z + 14, ancientbricks);
        arcanaChunk.setBlock(x + 0, y + 6, z + 15, dungeonBricks);
        arcanaChunk.setBlock(x + 0, y + 7, z + 0, dungeonBricks);
        arcanaChunk.setBlock(x + 0, y + 7, z + 1, dungeonBricks);
        arcanaChunk.setBlock(x + 0, y + 7, z + 2, dungeonBricks);
        arcanaChunk.setBlock(x + 0, y + 7, z + 3, dungeonBricks);
        arcanaChunk.setBlock(x + 0, y + 7, z + 4, dungeonBricks);
        arcanaChunk.setBlock(x + 0, y + 7, z + 5, dungeonBricks);
        arcanaChunk.setBlock(x + 0, y + 7, z + 6, dungeonBricks);
        arcanaChunk.setBlock(x + 0, y + 7, z + 7, dungeonBricks);
        arcanaChunk.setBlock(x + 0, y + 7, z + 8, dungeonBricks);
        arcanaChunk.setBlock(x + 0, y + 7, z + 9, dungeonBricks);
        arcanaChunk.setBlock(x + 0, y + 7, z + 10, dungeonBricks);
        arcanaChunk.setBlock(x + 0, y + 7, z + 11, dungeonBricks);
        arcanaChunk.setBlock(x + 0, y + 7, z + 12, dungeonBricks);
        arcanaChunk.setBlock(x + 0, y + 7, z + 13, dungeonBricks);
        arcanaChunk.setBlock(x + 0, y + 7, z + 14, dungeonBricks);
        arcanaChunk.setBlock(x + 0, y + 7, z + 15, dungeonBricks);
        arcanaChunk.setBlock(x + 1, y + 0, z + 0, ancientbricks);
        arcanaChunk.setBlock(x + 1, y + 0, z + 1, ArcanaBlocks.dungenLamp);
        arcanaChunk.setBlock(x + 1, y + 0, z + 2, dungeonBricks);
        arcanaChunk.setBlock(x + 1, y + 0, z + 3, dungeonBricks);
        arcanaChunk.setBlock(x + 1, y + 0, z + 4, dungeonBricks);
        arcanaChunk.setBlock(x + 1, y + 0, z + 5, dungeonBricks);
        arcanaChunk.setBlock(x + 1, y + 0, z + 6, dungeonBricks);
        arcanaChunk.setBlock(x + 1, y + 0, z + 7, ancientbricks);
        arcanaChunk.setBlock(x + 1, y + 0, z + 8, ancientbricks);
        arcanaChunk.setBlock(x + 1, y + 0, z + 9, dungeonBricks);
        arcanaChunk.setBlock(x + 1, y + 0, z + 10, dungeonBricks);
        arcanaChunk.setBlock(x + 1, y + 0, z + 11, dungeonBricks);
        arcanaChunk.setBlock(x + 1, y + 0, z + 12, dungeonBricks);
        arcanaChunk.setBlock(x + 1, y + 0, z + 13, dungeonBricks);
        arcanaChunk.setBlock(x + 1, y + 0, z + 14, ArcanaBlocks.dungenLamp);
        arcanaChunk.setBlock(x + 1, y + 0, z + 15, ancientbricks);
        arcanaChunk.setBlock(x + 1, y + 1, z + 0, dungeonBricks);
        arcanaChunk.setBlock(x + 1, y + 1, z + 15, dungeonBricks);
        arcanaChunk.setBlock(x + 1, y + 2, z + 0, ancientTile);
        arcanaChunk.setBlock(x + 1, y + 2, z + 15, ancientTile);
        arcanaChunk.setBlock(x + 1, y + 3, z + 0, dungeonBricks);
        arcanaChunk.setBlock(x + 1, y + 3, z + 15, dungeonBricks);
        arcanaChunk.setBlock(x + 1, y + 4, z + 0, ancientbricks);
        arcanaChunk.setBlock(x + 1, y + 4, z + 15, ancientbricks);
        arcanaChunk.setBlock(x + 1, y + 5, z + 0, ancientTile);
        arcanaChunk.setBlock(x + 1, y + 5, z + 15, ancientbricks);
        arcanaChunk.setBlock(x + 1, y + 6, z + 0, ancientbricks);
        arcanaChunk.setBlock(x + 1, y + 6, z + 15, ancientbricks);
        arcanaChunk.setBlock(x + 1, y + 7, z + 0, dungeonBricks);
        arcanaChunk.setBlock(x + 1, y + 7, z + 15, dungeonBricks);
        arcanaChunk.setBlock(x + 2, y + 0, z + 0, ancientbricks);
        arcanaChunk.setBlock(x + 2, y + 0, z + 1, dungeonBricks);
        arcanaChunk.setBlock(x + 2, y + 0, z + 2, dungeonBricks);
        arcanaChunk.setBlock(x + 2, y + 0, z + 3, dungeonBricks);
        arcanaChunk.setBlock(x + 2, y + 0, z + 4, dungeonBricks);
        arcanaChunk.setBlock(x + 2, y + 0, z + 5, dungeonBricks);
        arcanaChunk.setBlock(x + 2, y + 0, z + 6, dungeonBricks);
        arcanaChunk.setBlock(x + 2, y + 0, z + 7, ancientbricks);
        arcanaChunk.setBlock(x + 2, y + 0, z + 8, ancientbricks);
        arcanaChunk.setBlock(x + 2, y + 0, z + 9, dungeonBricks);
        arcanaChunk.setBlock(x + 2, y + 0, z + 10, dungeonBricks);
        arcanaChunk.setBlock(x + 2, y + 0, z + 11, dungeonBricks);
        arcanaChunk.setBlock(x + 2, y + 0, z + 12, dungeonBricks);
        arcanaChunk.setBlock(x + 2, y + 0, z + 13, dungeonBricks);
        arcanaChunk.setBlock(x + 2, y + 0, z + 14, dungeonBricks);
        arcanaChunk.setBlock(x + 2, y + 0, z + 15, ancientbricks);
        arcanaChunk.setBlock(x + 2, y + 1, z + 0, dungeonBricks);
        arcanaChunk.setBlock(x + 2, y + 1, z + 15, dungeonBricks);
        arcanaChunk.setBlock(x + 2, y + 2, z + 0, dungeonBricks);
        arcanaChunk.setBlock(x + 2, y + 2, z + 15, dungeonBricks);
        arcanaChunk.setBlock(x + 2, y + 3, z + 0, dungeonBricks);
        arcanaChunk.setBlock(x + 2, y + 3, z + 15, dungeonBricks);
        arcanaChunk.setBlock(x + 2, y + 4, z + 0, ancientbricks);
        arcanaChunk.setBlock(x + 2, y + 4, z + 15, ancientbricks);
        arcanaChunk.setBlock(x + 2, y + 5, z + 0, ancientbricks);
        arcanaChunk.setBlock(x + 2, y + 5, z + 15, ancientTile);
        arcanaChunk.setBlock(x + 2, y + 6, z + 0, ancientbricks);
        arcanaChunk.setBlock(x + 2, y + 6, z + 15, ancientbricks);
        arcanaChunk.setBlock(x + 2, y + 7, z + 0, dungeonBricks);
        arcanaChunk.setBlock(x + 2, y + 7, z + 15, dungeonBricks);
        arcanaChunk.setBlock(x + 3, y + 0, z + 0, ancientbricks);
        arcanaChunk.setBlock(x + 3, y + 0, z + 1, dungeonBricks);
        arcanaChunk.setBlock(x + 3, y + 0, z + 2, dungeonBricks);
        arcanaChunk.setBlock(x + 3, y + 0, z + 3, dungeonBricks);
        arcanaChunk.setBlock(x + 3, y + 0, z + 4, dungeonBricks);
        arcanaChunk.setBlock(x + 3, y + 0, z + 5, dungeonBricks);
        arcanaChunk.setBlock(x + 3, y + 0, z + 6, dungeonBricks);
        arcanaChunk.setBlock(x + 3, y + 0, z + 7, ancientbricks);
        arcanaChunk.setBlock(x + 3, y + 0, z + 8, ancientbricks);
        arcanaChunk.setBlock(x + 3, y + 0, z + 9, dungeonBricks);
        arcanaChunk.setBlock(x + 3, y + 0, z + 10, dungeonBricks);
        arcanaChunk.setBlock(x + 3, y + 0, z + 11, dungeonBricks);
        arcanaChunk.setBlock(x + 3, y + 0, z + 12, dungeonBricks);
        arcanaChunk.setBlock(x + 3, y + 0, z + 13, dungeonBricks);
        arcanaChunk.setBlock(x + 3, y + 0, z + 14, dungeonBricks);
        arcanaChunk.setBlock(x + 3, y + 0, z + 15, ancientbricks);
        arcanaChunk.setBlock(x + 3, y + 1, z + 0, dungeonBricks);
        arcanaChunk.setBlock(x + 3, y + 1, z + 15, dungeonBricks);
        arcanaChunk.setBlock(x + 3, y + 2, z + 0, ancientTile);
        arcanaChunk.setBlock(x + 3, y + 2, z + 15, ancientTile);
        arcanaChunk.setBlock(x + 3, y + 3, z + 0, dungeonBricks);
        arcanaChunk.setBlock(x + 3, y + 3, z + 15, dungeonBricks);
        arcanaChunk.setBlock(x + 3, y + 4, z + 0, ancientbricks);
        arcanaChunk.setBlock(x + 3, y + 4, z + 15, ancientbricks);
        arcanaChunk.setBlock(x + 3, y + 5, z + 0, ancientTile);
        arcanaChunk.setBlock(x + 3, y + 5, z + 15, ancientbricks);
        arcanaChunk.setBlock(x + 3, y + 6, z + 0, ancientbricks);
        arcanaChunk.setBlock(x + 3, y + 6, z + 15, ancientbricks);
        arcanaChunk.setBlock(x + 3, y + 7, z + 0, dungeonBricks);
        arcanaChunk.setBlock(x + 3, y + 7, z + 15, dungeonBricks);
        arcanaChunk.setBlock(x + 4, y + 0, z + 0, ancientbricks);
        arcanaChunk.setBlock(x + 4, y + 0, z + 1, dungeonBricks);
        arcanaChunk.setBlock(x + 4, y + 0, z + 2, dungeonBricks);
        arcanaChunk.setBlock(x + 4, y + 0, z + 3, dungeonBricks);
        arcanaChunk.setBlock(x + 4, y + 0, z + 4, dungeonBricks);
        arcanaChunk.setBlock(x + 4, y + 0, z + 5, dungeonBricks);
        arcanaChunk.setBlock(x + 4, y + 0, z + 6, ancientbricks);
        arcanaChunk.setBlock(x + 4, y + 0, z + 7, ancientbricks);
        arcanaChunk.setBlock(x + 4, y + 0, z + 8, ancientbricks);
        arcanaChunk.setBlock(x + 4, y + 0, z + 9, ancientbricks);
        arcanaChunk.setBlock(x + 4, y + 0, z + 10, dungeonBricks);
        arcanaChunk.setBlock(x + 4, y + 0, z + 11, dungeonBricks);
        arcanaChunk.setBlock(x + 4, y + 0, z + 12, dungeonBricks);
        arcanaChunk.setBlock(x + 4, y + 0, z + 13, dungeonBricks);
        arcanaChunk.setBlock(x + 4, y + 0, z + 14, dungeonBricks);
        arcanaChunk.setBlock(x + 4, y + 0, z + 15, ancientbricks);
        arcanaChunk.setBlock(x + 4, y + 1, z + 0, dungeonBricks);
        arcanaChunk.setBlock(x + 4, y + 1, z + 15, dungeonBricks);
        arcanaChunk.setBlock(x + 4, y + 2, z + 0, dungeonBricks);
        arcanaChunk.setBlock(x + 4, y + 2, z + 15, dungeonBricks);
        arcanaChunk.setBlock(x + 4, y + 3, z + 0, dungeonBricks);
        arcanaChunk.setBlock(x + 4, y + 3, z + 15, dungeonBricks);
        arcanaChunk.setBlock(x + 4, y + 4, z + 0, ancientbricks);
        arcanaChunk.setBlock(x + 4, y + 4, z + 15, ancientbricks);
        arcanaChunk.setBlock(x + 4, y + 5, z + 0, ancientbricks);
        arcanaChunk.setBlock(x + 4, y + 5, z + 15, ancientTile);
        arcanaChunk.setBlock(x + 4, y + 6, z + 0, ancientbricks);
        arcanaChunk.setBlock(x + 4, y + 6, z + 15, ancientbricks);
        arcanaChunk.setBlock(x + 4, y + 7, z + 0, dungeonBricks);
        arcanaChunk.setBlock(x + 4, y + 7, z + 15, dungeonBricks);
        arcanaChunk.setBlock(x + 5, y + 0, z + 0, ancientbricks);
        arcanaChunk.setBlock(x + 5, y + 0, z + 1, dungeonBricks);
        arcanaChunk.setBlock(x + 5, y + 0, z + 2, dungeonBricks);
        arcanaChunk.setBlock(x + 5, y + 0, z + 3, dungeonBricks);
        arcanaChunk.setBlock(x + 5, y + 0, z + 4, dungeonBricks);
        arcanaChunk.setBlock(x + 5, y + 0, z + 5, ancientbricks);
        arcanaChunk.setBlock(x + 5, y + 0, z + 6, ancientbricks);
        arcanaChunk.setBlock(x + 5, y + 0, z + 7, ancientbricks);
        arcanaChunk.setBlock(x + 5, y + 0, z + 8, ancientbricks);
        arcanaChunk.setBlock(x + 5, y + 0, z + 9, ancientbricks);
        arcanaChunk.setBlock(x + 5, y + 0, z + 10, ancientbricks);
        arcanaChunk.setBlock(x + 5, y + 0, z + 11, dungeonBricks);
        arcanaChunk.setBlock(x + 5, y + 0, z + 12, dungeonBricks);
        arcanaChunk.setBlock(x + 5, y + 0, z + 13, dungeonBricks);
        arcanaChunk.setBlock(x + 5, y + 0, z + 14, dungeonBricks);
        arcanaChunk.setBlock(x + 5, y + 0, z + 15, ancientbricks);
        arcanaChunk.setBlock(x + 5, y + 1, z + 0, dungeonBricks);
        arcanaChunk.setBlock(x + 5, y + 1, z + 6, arcanaHardPortalFrame);
        arcanaChunk.setBlock(x + 5, y + 1, z + 7, arcanaHardPortalFrame);
        arcanaChunk.setBlock(x + 5, y + 1, z + 8, arcanaHardPortalFrame);
        arcanaChunk.setBlock(x + 5, y + 1, z + 9, arcanaHardPortalFrame);
        arcanaChunk.setBlock(x + 5, y + 1, z + 15, dungeonBricks);
        arcanaChunk.setBlock(x + 5, y + 2, z + 0, ancientTile);
        arcanaChunk.setBlock(x + 5, y + 2, z + 15, ancientTile);
        arcanaChunk.setBlock(x + 5, y + 3, z + 0, dungeonBricks);
        arcanaChunk.setBlock(x + 5, y + 3, z + 15, dungeonBricks);
        arcanaChunk.setBlock(x + 5, y + 4, z + 0, ancientbricks);
        arcanaChunk.setBlock(x + 5, y + 4, z + 15, ancientbricks);
        arcanaChunk.setBlock(x + 5, y + 5, z + 0, ancientTile);
        arcanaChunk.setBlock(x + 5, y + 5, z + 15, ancientbricks);
        arcanaChunk.setBlock(x + 5, y + 6, z + 0, ancientbricks);
        arcanaChunk.setBlock(x + 5, y + 6, z + 15, ancientbricks);
        arcanaChunk.setBlock(x + 5, y + 7, z + 0, dungeonBricks);
        arcanaChunk.setBlock(x + 5, y + 7, z + 15, dungeonBricks);
        arcanaChunk.setBlock(x + 6, y + 0, z + 0, ancientbricks);
        arcanaChunk.setBlock(x + 6, y + 0, z + 1, dungeonBricks);
        arcanaChunk.setBlock(x + 6, y + 0, z + 2, dungeonBricks);
        arcanaChunk.setBlock(x + 6, y + 0, z + 3, dungeonBricks);
        arcanaChunk.setBlock(x + 6, y + 0, z + 4, ancientbricks);
        arcanaChunk.setBlock(x + 6, y + 0, z + 5, ancientbricks);
        arcanaChunk.setBlock(x + 6, y + 0, z + 6, ancientbricks);
        arcanaChunk.setBlock(x + 6, y + 0, z + 7, ancientbricks);
        arcanaChunk.setBlock(x + 6, y + 0, z + 8, ancientbricks);
        arcanaChunk.setBlock(x + 6, y + 0, z + 9, ancientbricks);
        arcanaChunk.setBlock(x + 6, y + 0, z + 10, ancientbricks);
        arcanaChunk.setBlock(x + 6, y + 0, z + 11, ancientbricks);
        arcanaChunk.setBlock(x + 6, y + 0, z + 12, dungeonBricks);
        arcanaChunk.setBlock(x + 6, y + 0, z + 13, dungeonBricks);
        arcanaChunk.setBlock(x + 6, y + 0, z + 14, dungeonBricks);
        arcanaChunk.setBlock(x + 6, y + 0, z + 15, ancientbricks);
        arcanaChunk.setBlock(x + 6, y + 1, z + 0, dungeonBricks);
        arcanaChunk.setBlock(x + 6, y + 1, z + 5, arcanaHardPortalFrame);
        arcanaChunk.setBlock(x + 6, y + 1, z + 6, arcanaPortal);
        arcanaChunk.setBlock(x + 6, y + 1, z + 7, arcanaPortal);
        arcanaChunk.setBlock(x + 6, y + 1, z + 8, arcanaPortal);
        arcanaChunk.setBlock(x + 6, y + 1, z + 9, arcanaPortal);
        arcanaChunk.setBlock(x + 6, y + 1, z + 10, arcanaHardPortalFrame);
        arcanaChunk.setBlock(x + 6, y + 1, z + 15, dungeonBricks);
        arcanaChunk.setBlock(x + 6, y + 2, z + 0, dungeonBricks);
        arcanaChunk.setBlock(x + 6, y + 2, z + 15, dungeonBricks);
        arcanaChunk.setBlock(x + 6, y + 3, z + 0, dungeonBricks);
        arcanaChunk.setBlock(x + 6, y + 3, z + 15, dungeonBricks);
        arcanaChunk.setBlock(x + 6, y + 4, z + 0, ancientbricks);
        arcanaChunk.setBlock(x + 6, y + 4, z + 15, ancientbricks);
        arcanaChunk.setBlock(x + 6, y + 5, z + 0, ancientbricks);
        arcanaChunk.setBlock(x + 6, y + 5, z + 15, ancientTile);
        arcanaChunk.setBlock(x + 6, y + 6, z + 0, ancientbricks);
        arcanaChunk.setBlock(x + 6, y + 6, z + 15, ancientbricks);
        arcanaChunk.setBlock(x + 6, y + 7, z + 0, dungeonBricks);
        arcanaChunk.setBlock(x + 6, y + 7, z + 15, dungeonBricks);
        arcanaChunk.setBlock(x + 7, y + 0, z + 0, ancientbricks);
        arcanaChunk.setBlock(x + 7, y + 0, z + 1, ancientbricks);
        arcanaChunk.setBlock(x + 7, y + 0, z + 2, ancientbricks);
        arcanaChunk.setBlock(x + 7, y + 0, z + 3, ancientbricks);
        arcanaChunk.setBlock(x + 7, y + 0, z + 4, ancientbricks);
        arcanaChunk.setBlock(x + 7, y + 0, z + 5, ancientbricks);
        arcanaChunk.setBlock(x + 7, y + 0, z + 6, ancientbricks);
        arcanaChunk.setBlock(x + 7, y + 0, z + 7, ancientbricks);
        arcanaChunk.setBlock(x + 7, y + 0, z + 8, ancientbricks);
        arcanaChunk.setBlock(x + 7, y + 0, z + 9, ancientbricks);
        arcanaChunk.setBlock(x + 7, y + 0, z + 10, ancientbricks);
        arcanaChunk.setBlock(x + 7, y + 0, z + 11, ancientbricks);
        arcanaChunk.setBlock(x + 7, y + 0, z + 12, ancientbricks);
        arcanaChunk.setBlock(x + 7, y + 0, z + 13, ancientbricks);
        arcanaChunk.setBlock(x + 7, y + 0, z + 14, ancientbricks);
        arcanaChunk.setBlock(x + 7, y + 0, z + 15, ancientbricks);
        arcanaChunk.setBlock(x + 7, y + 1, z + 5, arcanaHardPortalFrame);
        arcanaChunk.setBlock(x + 7, y + 1, z + 6, arcanaPortal);
        arcanaChunk.setBlock(x + 7, y + 1, z + 7, arcanaPortal);
        arcanaChunk.setBlock(x + 7, y + 1, z + 8, arcanaPortal);
        arcanaChunk.setBlock(x + 7, y + 1, z + 9, arcanaPortal);
        arcanaChunk.setBlock(x + 7, y + 1, z + 10, arcanaHardPortalFrame);
        arcanaChunk.setBlock(x + 7, y + 3, z + 0, arcanaPower);
        arcanaChunk.setBlock(x + 7, y + 3, z + 15, arcanaPower);
        arcanaChunk.setBlock(x + 7, y + 4, z + 0, ancientbricks);
        arcanaChunk.setBlock(x + 7, y + 4, z + 15, ancientbricks);
        arcanaChunk.setBlock(x + 7, y + 5, z + 0, ancientTile);
        arcanaChunk.setBlock(x + 7, y + 5, z + 15, ancientbricks);
        arcanaChunk.setBlock(x + 7, y + 6, z + 0, ancientbricks);
        arcanaChunk.setBlock(x + 7, y + 6, z + 15, ancientbricks);
        arcanaChunk.setBlock(x + 7, y + 7, z + 0, dungeonBricks);
        arcanaChunk.setBlock(x + 7, y + 7, z + 15, dungeonBricks);
        arcanaChunk.setBlock(x + 8, y + 0, z + 0, ancientbricks);
        arcanaChunk.setBlock(x + 8, y + 0, z + 1, ancientbricks);
        arcanaChunk.setBlock(x + 8, y + 0, z + 2, ancientbricks);
        arcanaChunk.setBlock(x + 8, y + 0, z + 3, ancientbricks);
        arcanaChunk.setBlock(x + 8, y + 0, z + 4, ancientbricks);
        arcanaChunk.setBlock(x + 8, y + 0, z + 5, ancientbricks);
        arcanaChunk.setBlock(x + 8, y + 0, z + 6, ancientbricks);
        arcanaChunk.setBlock(x + 8, y + 0, z + 7, ancientbricks);
        arcanaChunk.setBlock(x + 8, y + 0, z + 8, ancientbricks);
        arcanaChunk.setBlock(x + 8, y + 0, z + 9, ancientbricks);
        arcanaChunk.setBlock(x + 8, y + 0, z + 10, ancientbricks);
        arcanaChunk.setBlock(x + 8, y + 0, z + 11, ancientbricks);
        arcanaChunk.setBlock(x + 8, y + 0, z + 12, ancientbricks);
        arcanaChunk.setBlock(x + 8, y + 0, z + 13, ancientbricks);
        arcanaChunk.setBlock(x + 8, y + 0, z + 14, ancientbricks);
        arcanaChunk.setBlock(x + 8, y + 0, z + 15, ancientbricks);
        arcanaChunk.setBlock(x + 8, y + 1, z + 5, arcanaHardPortalFrame);
        arcanaChunk.setBlock(x + 8, y + 1, z + 6, arcanaPortal);
        arcanaChunk.setBlock(x + 8, y + 1, z + 7, arcanaPortal);
        arcanaChunk.setBlock(x + 8, y + 1, z + 8, arcanaPortal);
        arcanaChunk.setBlock(x + 8, y + 1, z + 9, arcanaPortal);
        arcanaChunk.setBlock(x + 8, y + 1, z + 10, arcanaHardPortalFrame);
        arcanaChunk.setBlock(x + 8, y + 3, z + 0, arcanaPower);
        arcanaChunk.setBlock(x + 8, y + 3, z + 15, arcanaPower);
        arcanaChunk.setBlock(x + 8, y + 4, z + 0, ancientbricks);
        arcanaChunk.setBlock(x + 8, y + 4, z + 15, ancientbricks);
        arcanaChunk.setBlock(x + 8, y + 5, z + 0, ancientbricks);
        arcanaChunk.setBlock(x + 8, y + 5, z + 15, ancientTile);
        arcanaChunk.setBlock(x + 8, y + 6, z + 0, ancientbricks);
        arcanaChunk.setBlock(x + 8, y + 6, z + 15, ancientbricks);
        arcanaChunk.setBlock(x + 8, y + 7, z + 0, dungeonBricks);
        arcanaChunk.setBlock(x + 8, y + 7, z + 15, dungeonBricks);
        arcanaChunk.setBlock(x + 9, y + 0, z + 0, ancientbricks);
        arcanaChunk.setBlock(x + 9, y + 0, z + 1, dungeonBricks);
        arcanaChunk.setBlock(x + 9, y + 0, z + 2, dungeonBricks);
        arcanaChunk.setBlock(x + 9, y + 0, z + 3, dungeonBricks);
        arcanaChunk.setBlock(x + 9, y + 0, z + 4, ancientbricks);
        arcanaChunk.setBlock(x + 9, y + 0, z + 5, ancientbricks);
        arcanaChunk.setBlock(x + 9, y + 0, z + 6, ancientbricks);
        arcanaChunk.setBlock(x + 9, y + 0, z + 7, ancientbricks);
        arcanaChunk.setBlock(x + 9, y + 0, z + 8, ancientbricks);
        arcanaChunk.setBlock(x + 9, y + 0, z + 9, ancientbricks);
        arcanaChunk.setBlock(x + 9, y + 0, z + 10, ancientbricks);
        arcanaChunk.setBlock(x + 9, y + 0, z + 11, ancientbricks);
        arcanaChunk.setBlock(x + 9, y + 0, z + 12, dungeonBricks);
        arcanaChunk.setBlock(x + 9, y + 0, z + 13, dungeonBricks);
        arcanaChunk.setBlock(x + 9, y + 0, z + 14, dungeonBricks);
        arcanaChunk.setBlock(x + 9, y + 0, z + 15, ancientbricks);
        arcanaChunk.setBlock(x + 9, y + 1, z + 0, dungeonBricks);
        arcanaChunk.setBlock(x + 9, y + 1, z + 5, arcanaHardPortalFrame);
        arcanaChunk.setBlock(x + 9, y + 1, z + 6, arcanaPortal);
        arcanaChunk.setBlock(x + 9, y + 1, z + 7, arcanaPortal);
        arcanaChunk.setBlock(x + 9, y + 1, z + 8, arcanaPortal);
        arcanaChunk.setBlock(x + 9, y + 1, z + 9, arcanaPortal);
        arcanaChunk.setBlock(x + 9, y + 1, z + 10, arcanaHardPortalFrame);
        arcanaChunk.setBlock(x + 9, y + 1, z + 15, dungeonBricks);
        arcanaChunk.setBlock(x + 9, y + 2, z + 0, dungeonBricks);
        arcanaChunk.setBlock(x + 9, y + 2, z + 15, dungeonBricks);
        arcanaChunk.setBlock(x + 9, y + 3, z + 0, dungeonBricks);
        arcanaChunk.setBlock(x + 9, y + 3, z + 15, dungeonBricks);
        arcanaChunk.setBlock(x + 9, y + 4, z + 0, ancientbricks);
        arcanaChunk.setBlock(x + 9, y + 4, z + 15, ancientbricks);
        arcanaChunk.setBlock(x + 9, y + 5, z + 0, ancientTile);
        arcanaChunk.setBlock(x + 9, y + 5, z + 15, ancientbricks);
        arcanaChunk.setBlock(x + 9, y + 6, z + 0, ancientbricks);
        arcanaChunk.setBlock(x + 9, y + 6, z + 15, ancientbricks);
        arcanaChunk.setBlock(x + 9, y + 7, z + 0, dungeonBricks);
        arcanaChunk.setBlock(x + 9, y + 7, z + 15, dungeonBricks);
        arcanaChunk.setBlock(x + 10, y + 0, z + 0, ancientbricks);
        arcanaChunk.setBlock(x + 10, y + 0, z + 1, dungeonBricks);
        arcanaChunk.setBlock(x + 10, y + 0, z + 2, dungeonBricks);
        arcanaChunk.setBlock(x + 10, y + 0, z + 3, dungeonBricks);
        arcanaChunk.setBlock(x + 10, y + 0, z + 4, dungeonBricks);
        arcanaChunk.setBlock(x + 10, y + 0, z + 5, ancientbricks);
        arcanaChunk.setBlock(x + 10, y + 0, z + 6, ancientbricks);
        arcanaChunk.setBlock(x + 10, y + 0, z + 7, ancientbricks);
        arcanaChunk.setBlock(x + 10, y + 0, z + 8, ancientbricks);
        arcanaChunk.setBlock(x + 10, y + 0, z + 9, ancientbricks);
        arcanaChunk.setBlock(x + 10, y + 0, z + 10, ancientbricks);
        arcanaChunk.setBlock(x + 10, y + 0, z + 11, dungeonBricks);
        arcanaChunk.setBlock(x + 10, y + 0, z + 12, dungeonBricks);
        arcanaChunk.setBlock(x + 10, y + 0, z + 13, dungeonBricks);
        arcanaChunk.setBlock(x + 10, y + 0, z + 14, dungeonBricks);
        arcanaChunk.setBlock(x + 10, y + 0, z + 15, ancientbricks);
        arcanaChunk.setBlock(x + 10, y + 1, z + 0, dungeonBricks);
        arcanaChunk.setBlock(x + 10, y + 1, z + 6, arcanaHardPortalFrame);
        arcanaChunk.setBlock(x + 10, y + 1, z + 7, arcanaHardPortalFrame);
        arcanaChunk.setBlock(x + 10, y + 1, z + 8, arcanaHardPortalFrame);
        arcanaChunk.setBlock(x + 10, y + 1, z + 9, arcanaHardPortalFrame);
        arcanaChunk.setBlock(x + 10, y + 1, z + 15, dungeonBricks);
        arcanaChunk.setBlock(x + 10, y + 2, z + 0, ancientTile);
        arcanaChunk.setBlock(x + 10, y + 2, z + 15, ancientTile);
        arcanaChunk.setBlock(x + 10, y + 3, z + 0, dungeonBricks);
        arcanaChunk.setBlock(x + 10, y + 3, z + 15, dungeonBricks);
        arcanaChunk.setBlock(x + 10, y + 4, z + 0, ancientbricks);
        arcanaChunk.setBlock(x + 10, y + 4, z + 15, ancientbricks);
        arcanaChunk.setBlock(x + 10, y + 5, z + 0, ancientbricks);
        arcanaChunk.setBlock(x + 10, y + 5, z + 15, ancientTile);
        arcanaChunk.setBlock(x + 10, y + 6, z + 0, ancientbricks);
        arcanaChunk.setBlock(x + 10, y + 6, z + 15, ancientbricks);
        arcanaChunk.setBlock(x + 10, y + 7, z + 0, dungeonBricks);
        arcanaChunk.setBlock(x + 10, y + 7, z + 15, dungeonBricks);
        arcanaChunk.setBlock(x + 11, y + 0, z + 0, ancientbricks);
        arcanaChunk.setBlock(x + 11, y + 0, z + 1, dungeonBricks);
        arcanaChunk.setBlock(x + 11, y + 0, z + 2, dungeonBricks);
        arcanaChunk.setBlock(x + 11, y + 0, z + 3, dungeonBricks);
        arcanaChunk.setBlock(x + 11, y + 0, z + 4, dungeonBricks);
        arcanaChunk.setBlock(x + 11, y + 0, z + 5, dungeonBricks);
        arcanaChunk.setBlock(x + 11, y + 0, z + 6, ancientbricks);
        arcanaChunk.setBlock(x + 11, y + 0, z + 7, ancientbricks);
        arcanaChunk.setBlock(x + 11, y + 0, z + 8, ancientbricks);
        arcanaChunk.setBlock(x + 11, y + 0, z + 9, ancientbricks);
        arcanaChunk.setBlock(x + 11, y + 0, z + 10, dungeonBricks);
        arcanaChunk.setBlock(x + 11, y + 0, z + 11, dungeonBricks);
        arcanaChunk.setBlock(x + 11, y + 0, z + 12, dungeonBricks);
        arcanaChunk.setBlock(x + 11, y + 0, z + 13, dungeonBricks);
        arcanaChunk.setBlock(x + 11, y + 0, z + 14, dungeonBricks);
        arcanaChunk.setBlock(x + 11, y + 0, z + 15, ancientbricks);
        arcanaChunk.setBlock(x + 11, y + 1, z + 0, dungeonBricks);
        arcanaChunk.setBlock(x + 11, y + 1, z + 15, dungeonBricks);
        arcanaChunk.setBlock(x + 11, y + 2, z + 0, dungeonBricks);
        arcanaChunk.setBlock(x + 11, y + 2, z + 15, dungeonBricks);
        arcanaChunk.setBlock(x + 11, y + 3, z + 0, dungeonBricks);
        arcanaChunk.setBlock(x + 11, y + 3, z + 15, dungeonBricks);
        arcanaChunk.setBlock(x + 11, y + 4, z + 0, ancientbricks);
        arcanaChunk.setBlock(x + 11, y + 4, z + 15, ancientbricks);
        arcanaChunk.setBlock(x + 11, y + 5, z + 0, ancientTile);
        arcanaChunk.setBlock(x + 11, y + 5, z + 15, ancientbricks);
        arcanaChunk.setBlock(x + 11, y + 6, z + 0, ancientbricks);
        arcanaChunk.setBlock(x + 11, y + 6, z + 15, ancientbricks);
        arcanaChunk.setBlock(x + 11, y + 7, z + 0, dungeonBricks);
        arcanaChunk.setBlock(x + 11, y + 7, z + 15, dungeonBricks);
        arcanaChunk.setBlock(x + 12, y + 0, z + 0, ancientbricks);
        arcanaChunk.setBlock(x + 12, y + 0, z + 1, dungeonBricks);
        arcanaChunk.setBlock(x + 12, y + 0, z + 2, dungeonBricks);
        arcanaChunk.setBlock(x + 12, y + 0, z + 3, dungeonBricks);
        arcanaChunk.setBlock(x + 12, y + 0, z + 4, dungeonBricks);
        arcanaChunk.setBlock(x + 12, y + 0, z + 5, dungeonBricks);
        arcanaChunk.setBlock(x + 12, y + 0, z + 6, dungeonBricks);
        arcanaChunk.setBlock(x + 12, y + 0, z + 7, ancientbricks);
        arcanaChunk.setBlock(x + 12, y + 0, z + 8, ancientbricks);
        arcanaChunk.setBlock(x + 12, y + 0, z + 9, dungeonBricks);
        arcanaChunk.setBlock(x + 12, y + 0, z + 10, dungeonBricks);
        arcanaChunk.setBlock(x + 12, y + 0, z + 11, dungeonBricks);
        arcanaChunk.setBlock(x + 12, y + 0, z + 12, dungeonBricks);
        arcanaChunk.setBlock(x + 12, y + 0, z + 13, dungeonBricks);
        arcanaChunk.setBlock(x + 12, y + 0, z + 14, dungeonBricks);
        arcanaChunk.setBlock(x + 12, y + 0, z + 15, ancientbricks);
        arcanaChunk.setBlock(x + 12, y + 1, z + 0, dungeonBricks);
        arcanaChunk.setBlock(x + 12, y + 1, z + 15, dungeonBricks);
        arcanaChunk.setBlock(x + 12, y + 2, z + 0, ancientTile);
        arcanaChunk.setBlock(x + 12, y + 2, z + 15, ancientTile);
        arcanaChunk.setBlock(x + 12, y + 3, z + 0, dungeonBricks);
        arcanaChunk.setBlock(x + 12, y + 3, z + 15, dungeonBricks);
        arcanaChunk.setBlock(x + 12, y + 4, z + 0, ancientbricks);
        arcanaChunk.setBlock(x + 12, y + 4, z + 15, ancientbricks);
        arcanaChunk.setBlock(x + 12, y + 5, z + 0, ancientbricks);
        arcanaChunk.setBlock(x + 12, y + 5, z + 15, ancientTile);
        arcanaChunk.setBlock(x + 12, y + 6, z + 0, ancientbricks);
        arcanaChunk.setBlock(x + 12, y + 6, z + 15, ancientbricks);
        arcanaChunk.setBlock(x + 12, y + 7, z + 0, dungeonBricks);
        arcanaChunk.setBlock(x + 12, y + 7, z + 15, dungeonBricks);
        arcanaChunk.setBlock(x + 13, y + 0, z + 0, ancientbricks);
        arcanaChunk.setBlock(x + 13, y + 0, z + 1, dungeonBricks);
        arcanaChunk.setBlock(x + 13, y + 0, z + 2, dungeonBricks);
        arcanaChunk.setBlock(x + 13, y + 0, z + 3, dungeonBricks);
        arcanaChunk.setBlock(x + 13, y + 0, z + 4, dungeonBricks);
        arcanaChunk.setBlock(x + 13, y + 0, z + 5, dungeonBricks);
        arcanaChunk.setBlock(x + 13, y + 0, z + 6, dungeonBricks);
        arcanaChunk.setBlock(x + 13, y + 0, z + 7, ancientbricks);
        arcanaChunk.setBlock(x + 13, y + 0, z + 8, ancientbricks);
        arcanaChunk.setBlock(x + 13, y + 0, z + 9, dungeonBricks);
        arcanaChunk.setBlock(x + 13, y + 0, z + 10, dungeonBricks);
        arcanaChunk.setBlock(x + 13, y + 0, z + 11, dungeonBricks);
        arcanaChunk.setBlock(x + 13, y + 0, z + 12, dungeonBricks);
        arcanaChunk.setBlock(x + 13, y + 0, z + 13, dungeonBricks);
        arcanaChunk.setBlock(x + 13, y + 0, z + 14, dungeonBricks);
        arcanaChunk.setBlock(x + 13, y + 0, z + 15, ancientbricks);
        arcanaChunk.setBlock(x + 13, y + 1, z + 0, dungeonBricks);
        arcanaChunk.setBlock(x + 13, y + 1, z + 15, dungeonBricks);
        arcanaChunk.setBlock(x + 13, y + 2, z + 0, dungeonBricks);
        arcanaChunk.setBlock(x + 13, y + 2, z + 15, dungeonBricks);
        arcanaChunk.setBlock(x + 13, y + 3, z + 0, dungeonBricks);
        arcanaChunk.setBlock(x + 13, y + 3, z + 15, dungeonBricks);
        arcanaChunk.setBlock(x + 13, y + 4, z + 0, ancientbricks);
        arcanaChunk.setBlock(x + 13, y + 4, z + 15, ancientbricks);
        arcanaChunk.setBlock(x + 13, y + 5, z + 0, ancientTile);
        arcanaChunk.setBlock(x + 13, y + 5, z + 15, ancientbricks);
        arcanaChunk.setBlock(x + 13, y + 6, z + 0, ancientbricks);
        arcanaChunk.setBlock(x + 13, y + 6, z + 15, ancientbricks);
        arcanaChunk.setBlock(x + 13, y + 7, z + 0, dungeonBricks);
        arcanaChunk.setBlock(x + 13, y + 7, z + 15, dungeonBricks);
        arcanaChunk.setBlock(x + 14, y + 0, z + 0, ancientbricks);
        arcanaChunk.setBlock(x + 14, y + 0, z + 1, ArcanaBlocks.dungenLamp);
        arcanaChunk.setBlock(x + 14, y + 0, z + 2, dungeonBricks);
        arcanaChunk.setBlock(x + 14, y + 0, z + 3, dungeonBricks);
        arcanaChunk.setBlock(x + 14, y + 0, z + 4, dungeonBricks);
        arcanaChunk.setBlock(x + 14, y + 0, z + 5, dungeonBricks);
        arcanaChunk.setBlock(x + 14, y + 0, z + 6, dungeonBricks);
        arcanaChunk.setBlock(x + 14, y + 0, z + 7, ancientbricks);
        arcanaChunk.setBlock(x + 14, y + 0, z + 8, ancientbricks);
        arcanaChunk.setBlock(x + 14, y + 0, z + 9, dungeonBricks);
        arcanaChunk.setBlock(x + 14, y + 0, z + 10, dungeonBricks);
        arcanaChunk.setBlock(x + 14, y + 0, z + 11, dungeonBricks);
        arcanaChunk.setBlock(x + 14, y + 0, z + 12, dungeonBricks);
        arcanaChunk.setBlock(x + 14, y + 0, z + 13, dungeonBricks);
        arcanaChunk.setBlock(x + 14, y + 0, z + 14, ArcanaBlocks.dungenLamp);
        arcanaChunk.setBlock(x + 14, y + 0, z + 15, ancientbricks);
        arcanaChunk.setBlock(x + 14, y + 1, z + 0, dungeonBricks);
        arcanaChunk.setBlock(x + 14, y + 1, z + 15, dungeonBricks);
        arcanaChunk.setBlock(x + 14, y + 2, z + 0, ancientTile);
        arcanaChunk.setBlock(x + 14, y + 2, z + 15, ancientTile);
        arcanaChunk.setBlock(x + 14, y + 3, z + 0, dungeonBricks);
        arcanaChunk.setBlock(x + 14, y + 3, z + 15, dungeonBricks);
        arcanaChunk.setBlock(x + 14, y + 4, z + 0, ancientbricks);
        arcanaChunk.setBlock(x + 14, y + 4, z + 15, ancientbricks);
        arcanaChunk.setBlock(x + 14, y + 5, z + 0, ancientbricks);
        arcanaChunk.setBlock(x + 14, y + 5, z + 15, ancientTile);
        arcanaChunk.setBlock(x + 14, y + 6, z + 0, ancientbricks);
        arcanaChunk.setBlock(x + 14, y + 6, z + 15, ancientbricks);
        arcanaChunk.setBlock(x + 14, y + 7, z + 0, dungeonBricks);
        arcanaChunk.setBlock(x + 14, y + 7, z + 15, dungeonBricks);
        arcanaChunk.setBlock(x + 15, y + 0, z + 0, ancientbricks);
        arcanaChunk.setBlock(x + 15, y + 0, z + 1, ancientbricks);
        arcanaChunk.setBlock(x + 15, y + 0, z + 2, ancientbricks);
        arcanaChunk.setBlock(x + 15, y + 0, z + 3, ancientbricks);
        arcanaChunk.setBlock(x + 15, y + 0, z + 4, ancientbricks);
        arcanaChunk.setBlock(x + 15, y + 0, z + 5, ancientbricks);
        arcanaChunk.setBlock(x + 15, y + 0, z + 6, ancientbricks);
        arcanaChunk.setBlock(x + 15, y + 0, z + 7, ancientbricks);
        arcanaChunk.setBlock(x + 15, y + 0, z + 8, ancientbricks);
        arcanaChunk.setBlock(x + 15, y + 0, z + 9, ancientbricks);
        arcanaChunk.setBlock(x + 15, y + 0, z + 10, ancientbricks);
        arcanaChunk.setBlock(x + 15, y + 0, z + 11, ancientbricks);
        arcanaChunk.setBlock(x + 15, y + 0, z + 12, ancientbricks);
        arcanaChunk.setBlock(x + 15, y + 0, z + 13, ancientbricks);
        arcanaChunk.setBlock(x + 15, y + 0, z + 14, dungeonBricks);
        arcanaChunk.setBlock(x + 15, y + 0, z + 15, ancientbricks);
        arcanaChunk.setBlock(x + 15, y + 1, z + 0, dungeonBricks);
        arcanaChunk.setBlock(x + 15, y + 1, z + 1, dungeonBricks);
        arcanaChunk.setBlock(x + 15, y + 1, z + 2, dungeonBricks);
        arcanaChunk.setBlock(x + 15, y + 1, z + 3, dungeonBricks);
        arcanaChunk.setBlock(x + 15, y + 1, z + 4, dungeonBricks);
        arcanaChunk.setBlock(x + 15, y + 1, z + 5, dungeonBricks);
        arcanaChunk.setBlock(x + 15, y + 1, z + 6, dungeonBricks);
        arcanaChunk.setBlock(x + 15, y + 1, z + 9, dungeonBricks);
        arcanaChunk.setBlock(x + 15, y + 1, z + 10, dungeonBricks);
        arcanaChunk.setBlock(x + 15, y + 1, z + 11, dungeonBricks);
        arcanaChunk.setBlock(x + 15, y + 1, z + 12, dungeonBricks);
        arcanaChunk.setBlock(x + 15, y + 1, z + 13, dungeonBricks);
        arcanaChunk.setBlock(x + 15, y + 1, z + 14, dungeonBricks);
        arcanaChunk.setBlock(x + 15, y + 1, z + 15, dungeonBricks);
        arcanaChunk.setBlock(x + 15, y + 2, z + 0, dungeonBricks);
        arcanaChunk.setBlock(x + 15, y + 2, z + 1, ancientTile);
        arcanaChunk.setBlock(x + 15, y + 2, z + 2, dungeonBricks);
        arcanaChunk.setBlock(x + 15, y + 2, z + 3, ancientTile);
        arcanaChunk.setBlock(x + 15, y + 2, z + 4, dungeonBricks);
        arcanaChunk.setBlock(x + 15, y + 2, z + 5, ancientTile);
        arcanaChunk.setBlock(x + 15, y + 2, z + 6, dungeonBricks);
        arcanaChunk.setBlock(x + 15, y + 2, z + 9, dungeonBricks);
        arcanaChunk.setBlock(x + 15, y + 2, z + 10, ancientTile);
        arcanaChunk.setBlock(x + 15, y + 2, z + 11, dungeonBricks);
        arcanaChunk.setBlock(x + 15, y + 2, z + 12, ancientTile);
        arcanaChunk.setBlock(x + 15, y + 2, z + 13, dungeonBricks);
        arcanaChunk.setBlock(x + 15, y + 2, z + 14, ancientTile);
        arcanaChunk.setBlock(x + 15, y + 2, z + 15, dungeonBricks);
        arcanaChunk.setBlock(x + 15, y + 3, z + 0, dungeonBricks);
        arcanaChunk.setBlock(x + 15, y + 3, z + 1, dungeonBricks);
        arcanaChunk.setBlock(x + 15, y + 3, z + 2, dungeonBricks);
        arcanaChunk.setBlock(x + 15, y + 3, z + 3, dungeonBricks);
        arcanaChunk.setBlock(x + 15, y + 3, z + 4, dungeonBricks);
        arcanaChunk.setBlock(x + 15, y + 3, z + 5, dungeonBricks);
        arcanaChunk.setBlock(x + 15, y + 3, z + 6, dungeonBricks);
        arcanaChunk.setBlock(x + 15, y + 3, z + 7, arcanaPower);
        arcanaChunk.setBlock(x + 15, y + 3, z + 8, arcanaPower);
        arcanaChunk.setBlock(x + 15, y + 3, z + 9, dungeonBricks);
        arcanaChunk.setBlock(x + 15, y + 3, z + 10, dungeonBricks);
        arcanaChunk.setBlock(x + 15, y + 3, z + 11, dungeonBricks);
        arcanaChunk.setBlock(x + 15, y + 3, z + 12, dungeonBricks);
        arcanaChunk.setBlock(x + 15, y + 3, z + 13, dungeonBricks);
        arcanaChunk.setBlock(x + 15, y + 3, z + 14, dungeonBricks);
        arcanaChunk.setBlock(x + 15, y + 3, z + 15, dungeonBricks);
        arcanaChunk.setBlock(x + 15, y + 4, z + 0, ancientbricks);
        arcanaChunk.setBlock(x + 15, y + 4, z + 1, ancientbricks);
        arcanaChunk.setBlock(x + 15, y + 4, z + 2, ancientbricks);
        arcanaChunk.setBlock(x + 15, y + 4, z + 3, ancientbricks);
        arcanaChunk.setBlock(x + 15, y + 4, z + 4, ancientbricks);
        arcanaChunk.setBlock(x + 15, y + 4, z + 5, ancientbricks);
        arcanaChunk.setBlock(x + 15, y + 4, z + 6, ancientbricks);
        arcanaChunk.setBlock(x + 15, y + 4, z + 7, ancientbricks);
        arcanaChunk.setBlock(x + 15, y + 4, z + 8, ancientbricks);
        arcanaChunk.setBlock(x + 15, y + 4, z + 9, ancientbricks);
        arcanaChunk.setBlock(x + 15, y + 4, z + 10, ancientbricks);
        arcanaChunk.setBlock(x + 15, y + 4, z + 11, ancientbricks);
        arcanaChunk.setBlock(x + 15, y + 4, z + 12, ancientbricks);
        arcanaChunk.setBlock(x + 15, y + 4, z + 13, ancientbricks);
        arcanaChunk.setBlock(x + 15, y + 4, z + 14, ancientbricks);
        arcanaChunk.setBlock(x + 15, y + 4, z + 15, dungeonBricks);
        arcanaChunk.setBlock(x + 15, y + 5, z + 0, ancientbricks);
        arcanaChunk.setBlock(x + 15, y + 5, z + 1, ancientTile);
        arcanaChunk.setBlock(x + 15, y + 5, z + 2, ancientbricks);
        arcanaChunk.setBlock(x + 15, y + 5, z + 3, ancientTile);
        arcanaChunk.setBlock(x + 15, y + 5, z + 4, ancientbricks);
        arcanaChunk.setBlock(x + 15, y + 5, z + 5, ancientTile);
        arcanaChunk.setBlock(x + 15, y + 5, z + 6, ancientbricks);
        arcanaChunk.setBlock(x + 15, y + 5, z + 7, ancientTile);
        arcanaChunk.setBlock(x + 15, y + 5, z + 8, ancientbricks);
        arcanaChunk.setBlock(x + 15, y + 5, z + 9, ancientTile);
        arcanaChunk.setBlock(x + 15, y + 5, z + 10, ancientbricks);
        arcanaChunk.setBlock(x + 15, y + 5, z + 11, ancientTile);
        arcanaChunk.setBlock(x + 15, y + 5, z + 12, ancientbricks);
        arcanaChunk.setBlock(x + 15, y + 5, z + 13, ancientTile);
        arcanaChunk.setBlock(x + 15, y + 5, z + 14, ancientbricks);
        arcanaChunk.setBlock(x + 15, y + 5, z + 15, dungeonBricks);
        arcanaChunk.setBlock(x + 15, y + 6, z + 0, ancientbricks);
        arcanaChunk.setBlock(x + 15, y + 6, z + 1, ancientbricks);
        arcanaChunk.setBlock(x + 15, y + 6, z + 2, ancientbricks);
        arcanaChunk.setBlock(x + 15, y + 6, z + 3, ancientbricks);
        arcanaChunk.setBlock(x + 15, y + 6, z + 4, ancientbricks);
        arcanaChunk.setBlock(x + 15, y + 6, z + 5, ancientbricks);
        arcanaChunk.setBlock(x + 15, y + 6, z + 6, ancientbricks);
        arcanaChunk.setBlock(x + 15, y + 6, z + 7, ancientbricks);
        arcanaChunk.setBlock(x + 15, y + 6, z + 8, ancientbricks);
        arcanaChunk.setBlock(x + 15, y + 6, z + 9, ancientbricks);
        arcanaChunk.setBlock(x + 15, y + 6, z + 10, ancientbricks);
        arcanaChunk.setBlock(x + 15, y + 6, z + 11, ancientbricks);
        arcanaChunk.setBlock(x + 15, y + 6, z + 12, ancientbricks);
        arcanaChunk.setBlock(x + 15, y + 6, z + 13, ancientbricks);
        arcanaChunk.setBlock(x + 15, y + 6, z + 14, ancientbricks);
        arcanaChunk.setBlock(x + 15, y + 6, z + 15, dungeonBricks);
        arcanaChunk.setBlock(x + 15, y + 7, z + 0, dungeonBricks);
        arcanaChunk.setBlock(x + 15, y + 7, z + 1, dungeonBricks);
        arcanaChunk.setBlock(x + 15, y + 7, z + 2, dungeonBricks);
        arcanaChunk.setBlock(x + 15, y + 7, z + 3, dungeonBricks);
        arcanaChunk.setBlock(x + 15, y + 7, z + 4, dungeonBricks);
        arcanaChunk.setBlock(x + 15, y + 7, z + 5, dungeonBricks);
        arcanaChunk.setBlock(x + 15, y + 7, z + 6, dungeonBricks);
        arcanaChunk.setBlock(x + 15, y + 7, z + 7, dungeonBricks);
        arcanaChunk.setBlock(x + 15, y + 7, z + 8, dungeonBricks);
        arcanaChunk.setBlock(x + 15, y + 7, z + 9, dungeonBricks);
        arcanaChunk.setBlock(x + 15, y + 7, z + 10, dungeonBricks);
        arcanaChunk.setBlock(x + 15, y + 7, z + 11, dungeonBricks);
        arcanaChunk.setBlock(x + 15, y + 7, z + 12, dungeonBricks);
        arcanaChunk.setBlock(x + 15, y + 7, z + 13, dungeonBricks);
        arcanaChunk.setBlock(x + 15, y + 7, z + 14, dungeonBricks);
        arcanaChunk.setBlock(x + 15, y + 7, z + 15, dungeonBricks);
        return true;
    }
}
