package net.divinerpg.dimensions.arcana.components;
import java.util.Random;

import net.divinerpg.dimensions.arcana.ArcanaChunk;
import net.divinerpg.utils.blocks.ArcanaBlocks;
import net.minecraft.block.Block;

public class DungeonComponent extends DungeonComponentBase {

    @Override
    public boolean generate(ArcanaChunk world, Random rand, int x, int y, int z) {

        Block heatTraps = ArcanaBlocks.heatTrap;
        Block dungeonBricks = ArcanaBlocks.degradedBrick;
        Block ancientbricks = ArcanaBlocks.ancientBrick;
        Block soulStone = ArcanaBlocks.soulStone;
        Block ancientStone = ArcanaBlocks.ancientStone;

        world.setBlock(x + 0, y + 0, z + 0, heatTraps);
        world.setBlock(x + 0, y + 0, z + 1, heatTraps);
        world.setBlock(x + 0, y + 0, z + 2, dungeonBricks);
        world.setBlock(x + 0, y + 0, z + 3, dungeonBricks);
        world.setBlock(x + 0, y + 0, z + 4, ancientbricks);
        world.setBlock(x + 0, y + 0, z + 5, ancientbricks);
        world.setBlock(x + 0, y + 0, z + 6, ancientbricks);
        world.setBlock(x + 0, y + 0, z + 7, ancientbricks);
        world.setBlock(x + 0, y + 0, z + 8, ancientbricks);
        world.setBlock(x + 0, y + 0, z + 9, ancientbricks);
        world.setBlock(x + 0, y + 0, z + 10, ancientbricks);
        world.setBlock(x + 0, y + 0, z + 11, ancientbricks);
        world.setBlock(x + 0, y + 0, z + 12, dungeonBricks);
        world.setBlock(x + 0, y + 0, z + 13, dungeonBricks);
        world.setBlock(x + 0, y + 0, z + 14, heatTraps);
        world.setBlock(x + 0, y + 0, z + 15, heatTraps);
        world.setBlock(x + 0, y + 1, z + 0, heatTraps);
        world.setBlock(x + 0, y + 1, z + 1, heatTraps);
        world.setBlock(x + 0, y + 1, z + 2, soulStone);
        world.setBlock(x + 0, y + 1, z + 3, soulStone);
        world.setBlock(x + 0, y + 1, z + 4, soulStone);
        world.setBlock(x + 0, y + 1, z + 5, soulStone);
        world.setBlock(x + 0, y + 1, z + 6, ancientStone);
        world.setBlock(x + 0, y + 1, z + 9, ancientStone);
        world.setBlock(x + 0, y + 1, z + 10, soulStone);
        world.setBlock(x + 0, y + 1, z + 11, soulStone);
        world.setBlock(x + 0, y + 1, z + 12, soulStone);
        world.setBlock(x + 0, y + 1, z + 13, soulStone);
        world.setBlock(x + 0, y + 1, z + 14, heatTraps);
        world.setBlock(x + 0, y + 1, z + 15, heatTraps);
        world.setBlock(x + 0, y + 2, z + 0, heatTraps);
        world.setBlock(x + 0, y + 2, z + 1, heatTraps);
        world.setBlock(x + 0, y + 2, z + 2, soulStone);
        world.setBlock(x + 0, y + 2, z + 3, soulStone);
        world.setBlock(x + 0, y + 2, z + 4, soulStone);
        world.setBlock(x + 0, y + 2, z + 5, soulStone);
        world.setBlock(x + 0, y + 2, z + 6, ArcanaBlocks.dungenLamp);
        world.setBlock(x + 0, y + 2, z + 9, ArcanaBlocks.dungenLamp);
        world.setBlock(x + 0, y + 2, z + 10, soulStone);
        world.setBlock(x + 0, y + 2, z + 11, soulStone);
        world.setBlock(x + 0, y + 2, z + 12, soulStone);
        world.setBlock(x + 0, y + 2, z + 13, soulStone);
        world.setBlock(x + 0, y + 2, z + 14, heatTraps);
        world.setBlock(x + 0, y + 2, z + 15, heatTraps);
        world.setBlock(x + 0, y + 3, z + 0, heatTraps);
        world.setBlock(x + 0, y + 3, z + 1, heatTraps);
        world.setBlock(x + 0, y + 3, z + 2, soulStone);
        world.setBlock(x + 0, y + 3, z + 3, soulStone);
        world.setBlock(x + 0, y + 3, z + 4, soulStone);
        world.setBlock(x + 0, y + 3, z + 5, soulStone);
        world.setBlock(x + 0, y + 3, z + 6, ancientStone);
        world.setBlock(x + 0, y + 3, z + 7, ArcanaBlocks.arcaniumPower);
        world.setBlock(x + 0, y + 3, z + 8, ArcanaBlocks.arcaniumPower);
        world.setBlock(x + 0, y + 3, z + 9, ancientStone);
        world.setBlock(x + 0, y + 3, z + 10, soulStone);
        world.setBlock(x + 0, y + 3, z + 11, soulStone);
        world.setBlock(x + 0, y + 3, z + 12, soulStone);
        world.setBlock(x + 0, y + 3, z + 13, soulStone);
        world.setBlock(x + 0, y + 3, z + 14, heatTraps);
        world.setBlock(x + 0, y + 3, z + 15, heatTraps);
        world.setBlock(x + 0, y + 4, z + 0, heatTraps);
        world.setBlock(x + 0, y + 4, z + 1, heatTraps);
        world.setBlock(x + 0, y + 4, z + 2, soulStone);
        world.setBlock(x + 0, y + 4, z + 3, soulStone);
        world.setBlock(x + 0, y + 4, z + 4, soulStone);
        world.setBlock(x + 0, y + 4, z + 5, soulStone);
        world.setBlock(x + 0, y + 4, z + 6, soulStone);
        world.setBlock(x + 0, y + 4, z + 7, soulStone);
        world.setBlock(x + 0, y + 4, z + 8, soulStone);
        world.setBlock(x + 0, y + 4, z + 9, soulStone);
        world.setBlock(x + 0, y + 4, z + 10, soulStone);
        world.setBlock(x + 0, y + 4, z + 11, soulStone);
        world.setBlock(x + 0, y + 4, z + 12, soulStone);
        world.setBlock(x + 0, y + 4, z + 13, soulStone);
        world.setBlock(x + 0, y + 4, z + 14, heatTraps);
        world.setBlock(x + 0, y + 4, z + 15, heatTraps);
        world.setBlock(x + 0, y + 5, z + 0, heatTraps);
        world.setBlock(x + 0, y + 5, z + 1, heatTraps);
        world.setBlock(x + 0, y + 5, z + 2, soulStone);
        world.setBlock(x + 0, y + 5, z + 3, soulStone);
        world.setBlock(x + 0, y + 5, z + 4, soulStone);
        world.setBlock(x + 0, y + 5, z + 5, soulStone);
        world.setBlock(x + 0, y + 5, z + 6, soulStone);
        world.setBlock(x + 0, y + 5, z + 7, soulStone);
        world.setBlock(x + 0, y + 5, z + 8, soulStone);
        world.setBlock(x + 0, y + 5, z + 9, soulStone);
        world.setBlock(x + 0, y + 5, z + 10, soulStone);
        world.setBlock(x + 0, y + 5, z + 11, soulStone);
        world.setBlock(x + 0, y + 5, z + 12, soulStone);
        world.setBlock(x + 0, y + 5, z + 13, soulStone);
        world.setBlock(x + 0, y + 5, z + 14, heatTraps);
        world.setBlock(x + 0, y + 5, z + 15, heatTraps);
        world.setBlock(x + 0, y + 6, z + 0, heatTraps);
        world.setBlock(x + 0, y + 6, z + 1, heatTraps);
        world.setBlock(x + 0, y + 6, z + 2, ancientStone);
        world.setBlock(x + 0, y + 6, z + 3, ancientStone);
        world.setBlock(x + 0, y + 6, z + 4, ancientStone);
        world.setBlock(x + 0, y + 6, z + 5, ancientStone);
        world.setBlock(x + 0, y + 6, z + 6, ancientStone);
        world.setBlock(x + 0, y + 6, z + 7, ancientStone);
        world.setBlock(x + 0, y + 6, z + 8, ancientStone);
        world.setBlock(x + 0, y + 6, z + 9, ancientStone);
        world.setBlock(x + 0, y + 6, z + 10, ancientStone);
        world.setBlock(x + 0, y + 6, z + 11, ancientStone);
        world.setBlock(x + 0, y + 6, z + 12, ancientStone);
        world.setBlock(x + 0, y + 6, z + 13, ancientStone);
        world.setBlock(x + 0, y + 6, z + 14, heatTraps);
        world.setBlock(x + 0, y + 6, z + 15, heatTraps);
        world.setBlock(x + 0, y + 7, z + 0, heatTraps);
        world.setBlock(x + 0, y + 7, z + 1, heatTraps);
        world.setBlock(x + 0, y + 7, z + 2, ancientStone);
        world.setBlock(x + 0, y + 7, z + 3, ancientStone);
        world.setBlock(x + 0, y + 7, z + 4, ancientStone);
        world.setBlock(x + 0, y + 7, z + 5, ancientStone);
        world.setBlock(x + 0, y + 7, z + 6, ancientStone);
        world.setBlock(x + 0, y + 7, z + 7, ancientStone);
        world.setBlock(x + 0, y + 7, z + 8, ancientStone);
        world.setBlock(x + 0, y + 7, z + 9, ancientStone);
        world.setBlock(x + 0, y + 7, z + 10, ancientStone);
        world.setBlock(x + 0, y + 7, z + 11, ancientStone);
        world.setBlock(x + 0, y + 7, z + 12, ancientStone);
        world.setBlock(x + 0, y + 7, z + 13, ancientStone);
        world.setBlock(x + 0, y + 7, z + 14, heatTraps);
        world.setBlock(x + 0, y + 7, z + 15, heatTraps);
        world.setBlock(x + 1, y + 0, z + 0, heatTraps);
        world.setBlock(x + 1, y + 0, z + 1, heatTraps);
        world.setBlock(x + 1, y + 0, z + 2, heatTraps);
        world.setBlock(x + 1, y + 0, z + 3, dungeonBricks);
        world.setBlock(x + 1, y + 0, z + 4, dungeonBricks);
        world.setBlock(x + 1, y + 0, z + 5, ancientbricks);
        world.setBlock(x + 1, y + 0, z + 6, ancientbricks);
        world.setBlock(x + 1, y + 0, z + 7, ancientbricks);
        world.setBlock(x + 1, y + 0, z + 8, ancientbricks);
        world.setBlock(x + 1, y + 0, z + 9, ancientbricks);
        world.setBlock(x + 1, y + 0, z + 10, ancientbricks);
        world.setBlock(x + 1, y + 0, z + 11, dungeonBricks);
        world.setBlock(x + 1, y + 0, z + 12, dungeonBricks);
        world.setBlock(x + 1, y + 0, z + 13, heatTraps);
        world.setBlock(x + 1, y + 0, z + 14, heatTraps);
        world.setBlock(x + 1, y + 0, z + 15, heatTraps);
        world.setBlock(x + 1, y + 1, z + 0, heatTraps);
        world.setBlock(x + 1, y + 1, z + 1, heatTraps);
        world.setBlock(x + 1, y + 1, z + 14, heatTraps);
        world.setBlock(x + 1, y + 1, z + 15, heatTraps);
        world.setBlock(x + 1, y + 2, z + 0, heatTraps);
        world.setBlock(x + 1, y + 2, z + 1, heatTraps);
        world.setBlock(x + 1, y + 2, z + 14, heatTraps);
        world.setBlock(x + 1, y + 2, z + 15, heatTraps);
        world.setBlock(x + 1, y + 3, z + 0, heatTraps);
        world.setBlock(x + 1, y + 3, z + 1, heatTraps);
        world.setBlock(x + 1, y + 3, z + 14, heatTraps);
        world.setBlock(x + 1, y + 3, z + 15, heatTraps);
        world.setBlock(x + 1, y + 4, z + 0, heatTraps);
        world.setBlock(x + 1, y + 4, z + 1, heatTraps);
        world.setBlock(x + 1, y + 4, z + 14, heatTraps);
        world.setBlock(x + 1, y + 4, z + 15, heatTraps);
        world.setBlock(x + 1, y + 5, z + 0, heatTraps);
        world.setBlock(x + 1, y + 5, z + 1, heatTraps);
        world.setBlock(x + 1, y + 5, z + 14, heatTraps);
        world.setBlock(x + 1, y + 5, z + 15, heatTraps);
        world.setBlock(x + 1, y + 6, z + 0, heatTraps);
        world.setBlock(x + 1, y + 6, z + 1, heatTraps);
        world.setBlock(x + 1, y + 6, z + 14, heatTraps);
        world.setBlock(x + 1, y + 6, z + 15, heatTraps);
        world.setBlock(x + 1, y + 7, z + 0, heatTraps);
        world.setBlock(x + 1, y + 7, z + 1, heatTraps);
        world.setBlock(x + 1, y + 7, z + 2, heatTraps);
        world.setBlock(x + 1, y + 7, z + 13, heatTraps);
        world.setBlock(x + 1, y + 7, z + 14, heatTraps);
        world.setBlock(x + 1, y + 7, z + 15, heatTraps);
        world.setBlock(x + 2, y + 0, z + 0, dungeonBricks);
        world.setBlock(x + 2, y + 0, z + 1, heatTraps);
        world.setBlock(x + 2, y + 0, z + 2, heatTraps);
        world.setBlock(x + 2, y + 0, z + 3, heatTraps);
        world.setBlock(x + 2, y + 0, z + 4, dungeonBricks);
        world.setBlock(x + 2, y + 0, z + 5, dungeonBricks);
        world.setBlock(x + 2, y + 0, z + 6, ancientbricks);
        world.setBlock(x + 2, y + 0, z + 7, ancientbricks);
        world.setBlock(x + 2, y + 0, z + 8, ancientbricks);
        world.setBlock(x + 2, y + 0, z + 9, ancientbricks);
        world.setBlock(x + 2, y + 0, z + 10, dungeonBricks);
        world.setBlock(x + 2, y + 0, z + 11, dungeonBricks);
        world.setBlock(x + 2, y + 0, z + 12, heatTraps);
        world.setBlock(x + 2, y + 0, z + 13, heatTraps);
        world.setBlock(x + 2, y + 0, z + 14, heatTraps);
        world.setBlock(x + 2, y + 0, z + 15, dungeonBricks);
        world.setBlock(x + 2, y + 1, z + 0, soulStone);
        world.setBlock(x + 2, y + 1, z + 7, heatTraps);
        world.setBlock(x + 2, y + 1, z + 8, heatTraps);
        world.setBlock(x + 2, y + 1, z + 15, soulStone);
        world.setBlock(x + 2, y + 2, z + 0, soulStone);
        world.setBlock(x + 2, y + 2, z + 15, soulStone);
        world.setBlock(x + 2, y + 3, z + 0, soulStone);
        world.setBlock(x + 2, y + 3, z + 15, soulStone);
        world.setBlock(x + 2, y + 4, z + 0, soulStone);
        world.setBlock(x + 2, y + 4, z + 15, soulStone);
        world.setBlock(x + 2, y + 5, z + 0, soulStone);
        world.setBlock(x + 2, y + 5, z + 15, soulStone);
        world.setBlock(x + 2, y + 6, z + 0, ancientStone);
        world.setBlock(x + 2, y + 6, z + 15, ancientStone);
        world.setBlock(x + 2, y + 7, z + 0, ancientStone);
        world.setBlock(x + 2, y + 7, z + 1, heatTraps);
        world.setBlock(x + 2, y + 7, z + 2, heatTraps);
        world.setBlock(x + 2, y + 7, z + 3, heatTraps);
        world.setBlock(x + 2, y + 7, z + 12, heatTraps);
        world.setBlock(x + 2, y + 7, z + 13, heatTraps);
        world.setBlock(x + 2, y + 7, z + 14, heatTraps);
        world.setBlock(x + 2, y + 7, z + 15, ancientStone);
        world.setBlock(x + 3, y + 0, z + 0, dungeonBricks);
        world.setBlock(x + 3, y + 0, z + 1, dungeonBricks);
        world.setBlock(x + 3, y + 0, z + 2, heatTraps);
        world.setBlock(x + 3, y + 0, z + 3, heatTraps);
        world.setBlock(x + 3, y + 0, z + 4, heatTraps);
        world.setBlock(x + 3, y + 0, z + 5, dungeonBricks);
        world.setBlock(x + 3, y + 0, z + 6, dungeonBricks);
        world.setBlock(x + 3, y + 0, z + 7, ancientbricks);
        world.setBlock(x + 3, y + 0, z + 8, ancientbricks);
        world.setBlock(x + 3, y + 0, z + 9, dungeonBricks);
        world.setBlock(x + 3, y + 0, z + 10, dungeonBricks);
        world.setBlock(x + 3, y + 0, z + 11, heatTraps);
        world.setBlock(x + 3, y + 0, z + 12, heatTraps);
        world.setBlock(x + 3, y + 0, z + 13, heatTraps);
        world.setBlock(x + 3, y + 0, z + 14, dungeonBricks);
        world.setBlock(x + 3, y + 0, z + 15, dungeonBricks);
        world.setBlock(x + 3, y + 1, z + 0, soulStone);
        world.setBlock(x + 3, y + 1, z + 15, soulStone);
        world.setBlock(x + 3, y + 2, z + 0, soulStone);
        world.setBlock(x + 3, y + 2, z + 15, soulStone);
        world.setBlock(x + 3, y + 3, z + 0, soulStone);
        world.setBlock(x + 3, y + 3, z + 15, soulStone);
        world.setBlock(x + 3, y + 4, z + 0, soulStone);
        world.setBlock(x + 3, y + 4, z + 15, soulStone);
        world.setBlock(x + 3, y + 5, z + 0, soulStone);
        world.setBlock(x + 3, y + 5, z + 15, soulStone);
        world.setBlock(x + 3, y + 6, z + 0, ancientStone);
        world.setBlock(x + 3, y + 6, z + 15, ancientStone);
        world.setBlock(x + 3, y + 7, z + 0, ancientStone);
        world.setBlock(x + 3, y + 7, z + 2, heatTraps);
        world.setBlock(x + 3, y + 7, z + 3, heatTraps);
        world.setBlock(x + 3, y + 7, z + 4, heatTraps);
        world.setBlock(x + 3, y + 7, z + 11, heatTraps);
        world.setBlock(x + 3, y + 7, z + 12, heatTraps);
        world.setBlock(x + 3, y + 7, z + 13, heatTraps);
        world.setBlock(x + 3, y + 7, z + 15, ancientStone);
        world.setBlock(x + 4, y + 0, z + 0, ancientbricks);
        world.setBlock(x + 4, y + 0, z + 1, dungeonBricks);
        world.setBlock(x + 4, y + 0, z + 2, dungeonBricks);
        world.setBlock(x + 4, y + 0, z + 3, heatTraps);
        world.setBlock(x + 4, y + 0, z + 4, heatTraps);
        world.setBlock(x + 4, y + 0, z + 5, heatTraps);
        world.setBlock(x + 4, y + 0, z + 6, dungeonBricks);
        world.setBlock(x + 4, y + 0, z + 7, dungeonBricks);
        world.setBlock(x + 4, y + 0, z + 8, dungeonBricks);
        world.setBlock(x + 4, y + 0, z + 9, dungeonBricks);
        world.setBlock(x + 4, y + 0, z + 10, heatTraps);
        world.setBlock(x + 4, y + 0, z + 11, heatTraps);
        world.setBlock(x + 4, y + 0, z + 12, heatTraps);
        world.setBlock(x + 4, y + 0, z + 13, dungeonBricks);
        world.setBlock(x + 4, y + 0, z + 14, dungeonBricks);
        world.setBlock(x + 4, y + 0, z + 15, ancientbricks);
        world.setBlock(x + 4, y + 1, z + 0, soulStone);
        world.setBlock(x + 4, y + 1, z + 15, soulStone);
        world.setBlock(x + 4, y + 2, z + 0, soulStone);
        world.setBlock(x + 4, y + 2, z + 15, soulStone);
        world.setBlock(x + 4, y + 3, z + 0, soulStone);
        world.setBlock(x + 4, y + 3, z + 15, soulStone);
        world.setBlock(x + 4, y + 4, z + 0, soulStone);
        world.setBlock(x + 4, y + 4, z + 15, soulStone);
        world.setBlock(x + 4, y + 5, z + 0, soulStone);
        world.setBlock(x + 4, y + 5, z + 15, soulStone);
        world.setBlock(x + 4, y + 6, z + 0, ancientStone);
        world.setBlock(x + 4, y + 6, z + 15, ancientStone);
        world.setBlock(x + 4, y + 7, z + 0, ancientStone);
        world.setBlock(x + 4, y + 7, z + 3, heatTraps);
        world.setBlock(x + 4, y + 7, z + 4, heatTraps);
        world.setBlock(x + 4, y + 7, z + 5, heatTraps);
        world.setBlock(x + 4, y + 7, z + 10, heatTraps);
        world.setBlock(x + 4, y + 7, z + 11, heatTraps);
        world.setBlock(x + 4, y + 7, z + 12, heatTraps);
        world.setBlock(x + 4, y + 7, z + 15, ancientStone);
        world.setBlock(x + 5, y + 0, z + 0, ancientbricks);
        world.setBlock(x + 5, y + 0, z + 1, ancientbricks);
        world.setBlock(x + 5, y + 0, z + 2, dungeonBricks);
        world.setBlock(x + 5, y + 0, z + 3, dungeonBricks);
        world.setBlock(x + 5, y + 0, z + 4, heatTraps);
        world.setBlock(x + 5, y + 0, z + 5, heatTraps);
        world.setBlock(x + 5, y + 0, z + 6, heatTraps);
        world.setBlock(x + 5, y + 0, z + 7, dungeonBricks);
        world.setBlock(x + 5, y + 0, z + 8, dungeonBricks);
        world.setBlock(x + 5, y + 0, z + 9, heatTraps);
        world.setBlock(x + 5, y + 0, z + 10, heatTraps);
        world.setBlock(x + 5, y + 0, z + 11, heatTraps);
        world.setBlock(x + 5, y + 0, z + 12, dungeonBricks);
        world.setBlock(x + 5, y + 0, z + 13, dungeonBricks);
        world.setBlock(x + 5, y + 0, z + 14, ancientbricks);
        world.setBlock(x + 5, y + 0, z + 15, ancientbricks);
        world.setBlock(x + 5, y + 1, z + 0, soulStone);
        world.setBlock(x + 5, y + 1, z + 15, soulStone);
        world.setBlock(x + 5, y + 2, z + 0, soulStone);
        world.setBlock(x + 5, y + 2, z + 15, soulStone);
        world.setBlock(x + 5, y + 3, z + 0, soulStone);
        world.setBlock(x + 5, y + 3, z + 15, soulStone);
        world.setBlock(x + 5, y + 4, z + 0, soulStone);
        world.setBlock(x + 5, y + 4, z + 15, soulStone);
        world.setBlock(x + 5, y + 5, z + 0, soulStone);
        world.setBlock(x + 5, y + 5, z + 15, soulStone);
        world.setBlock(x + 5, y + 6, z + 0, ancientStone);
        world.setBlock(x + 5, y + 6, z + 15, ancientStone);
        world.setBlock(x + 5, y + 7, z + 0, ancientStone);
        world.setBlock(x + 5, y + 7, z + 4, heatTraps);
        world.setBlock(x + 5, y + 7, z + 5, heatTraps);
        world.setBlock(x + 5, y + 7, z + 6, heatTraps);
        world.setBlock(x + 5, y + 7, z + 9, heatTraps);
        world.setBlock(x + 5, y + 7, z + 10, heatTraps);
        world.setBlock(x + 5, y + 7, z + 11, heatTraps);
        world.setBlock(x + 5, y + 7, z + 15, ancientStone);
        world.setBlock(x + 6, y + 0, z + 0, ancientbricks);
        world.setBlock(x + 6, y + 0, z + 1, ancientbricks);
        world.setBlock(x + 6, y + 0, z + 2, ancientbricks);
        world.setBlock(x + 6, y + 0, z + 3, dungeonBricks);
        world.setBlock(x + 6, y + 0, z + 4, dungeonBricks);
        world.setBlock(x + 6, y + 0, z + 5, heatTraps);
        world.setBlock(x + 6, y + 0, z + 6, heatTraps);
        world.setBlock(x + 6, y + 0, z + 7, heatTraps);
        world.setBlock(x + 6, y + 0, z + 8, heatTraps);
        world.setBlock(x + 6, y + 0, z + 9, heatTraps);
        world.setBlock(x + 6, y + 0, z + 10, heatTraps);
        world.setBlock(x + 6, y + 0, z + 11, dungeonBricks);
        world.setBlock(x + 6, y + 0, z + 12, dungeonBricks);
        world.setBlock(x + 6, y + 0, z + 13, ancientbricks);
        world.setBlock(x + 6, y + 0, z + 14, ancientbricks);
        world.setBlock(x + 6, y + 0, z + 15, ancientbricks);
        world.setBlock(x + 6, y + 1, z + 0, ancientStone);
        world.setBlock(x + 6, y + 1, z + 7, heatTraps);
        world.setBlock(x + 6, y + 1, z + 8, heatTraps);
        world.setBlock(x + 6, y + 1, z + 15, ancientStone);
        world.setBlock(x + 6, y + 2, z + 0, ArcanaBlocks.dungenLamp);
        world.setBlock(x + 6, y + 2, z + 7, heatTraps);
        world.setBlock(x + 6, y + 2, z + 8, heatTraps);
        world.setBlock(x + 6, y + 2, z + 15, ArcanaBlocks.dungenLamp);
        world.setBlock(x + 6, y + 3, z + 0, ancientStone);
        world.setBlock(x + 6, y + 3, z + 7, heatTraps);
        world.setBlock(x + 6, y + 3, z + 8, heatTraps);
        world.setBlock(x + 6, y + 3, z + 15, ancientStone);
        world.setBlock(x + 6, y + 4, z + 0, soulStone);
        world.setBlock(x + 6, y + 4, z + 7, heatTraps);
        world.setBlock(x + 6, y + 4, z + 8, heatTraps);
        world.setBlock(x + 6, y + 4, z + 15, soulStone);
        world.setBlock(x + 6, y + 5, z + 0, soulStone);
        world.setBlock(x + 6, y + 5, z + 7, heatTraps);
        world.setBlock(x + 6, y + 5, z + 8, heatTraps);
        world.setBlock(x + 6, y + 5, z + 15, soulStone);
        world.setBlock(x + 6, y + 6, z + 0, ancientStone);
        world.setBlock(x + 6, y + 6, z + 7, heatTraps);
        world.setBlock(x + 6, y + 6, z + 8, heatTraps);
        world.setBlock(x + 6, y + 6, z + 15, ancientStone);
        world.setBlock(x + 6, y + 7, z + 0, ancientStone);
        world.setBlock(x + 6, y + 7, z + 5, heatTraps);
        world.setBlock(x + 6, y + 7, z + 6, heatTraps);
        world.setBlock(x + 6, y + 7, z + 7, heatTraps);
        world.setBlock(x + 6, y + 7, z + 8, heatTraps);
        world.setBlock(x + 6, y + 7, z + 9, heatTraps);
        world.setBlock(x + 6, y + 7, z + 10, heatTraps);
        world.setBlock(x + 6, y + 7, z + 15, ancientStone);
        world.setBlock(x + 7, y + 0, z + 0, ancientbricks);
        world.setBlock(x + 7, y + 0, z + 1, ancientbricks);
        world.setBlock(x + 7, y + 0, z + 2, ancientbricks);
        world.setBlock(x + 7, y + 0, z + 3, ancientbricks);
        world.setBlock(x + 7, y + 0, z + 4, dungeonBricks);
        world.setBlock(x + 7, y + 0, z + 5, dungeonBricks);
        world.setBlock(x + 7, y + 0, z + 6, heatTraps);
        world.setBlock(x + 7, y + 0, z + 7, ArcanaBlocks.arcanitetubes);
        world.setBlock(x + 7, y + 0, z + 8, ArcanaBlocks.arcanitetubes);
        world.setBlock(x + 7, y + 0, z + 9, heatTraps);
        world.setBlock(x + 7, y + 0, z + 10, dungeonBricks);
        world.setBlock(x + 7, y + 0, z + 11, dungeonBricks);
        world.setBlock(x + 7, y + 0, z + 12, ancientbricks);
        world.setBlock(x + 7, y + 0, z + 13, ancientbricks);
        world.setBlock(x + 7, y + 0, z + 14, ancientbricks);
        world.setBlock(x + 7, y + 0, z + 15, ancientbricks);
        world.setBlock(x + 7, y + 1, z + 2, heatTraps);
        world.setBlock(x + 7, y + 1, z + 6, heatTraps);
        world.setBlock(x + 7, y + 1, z + 7, heatTraps);
        world.setBlock(x + 7, y + 1, z + 8, heatTraps);
        world.setBlock(x + 7, y + 1, z + 9, heatTraps);
        world.setBlock(x + 7, y + 1, z + 13, heatTraps);
        world.setBlock(x + 7, y + 2, z + 6, heatTraps);
        world.setBlock(x + 7, y + 2, z + 7, heatTraps);
        world.setBlock(x + 7, y + 2, z + 8, heatTraps);
        world.setBlock(x + 7, y + 2, z + 9, heatTraps);
        world.setBlock(x + 7, y + 3, z + 0, ArcanaBlocks.arcaniumPower);
        world.setBlock(x + 7, y + 3, z + 6, heatTraps);
        world.setBlock(x + 7, y + 3, z + 7, heatTraps);
        world.setBlock(x + 7, y + 3, z + 8, heatTraps);
        world.setBlock(x + 7, y + 3, z + 9, heatTraps);
        world.setBlock(x + 7, y + 3, z + 15, ArcanaBlocks.arcaniumPower);
        world.setBlock(x + 7, y + 4, z + 0, soulStone);
        world.setBlock(x + 7, y + 4, z + 6, heatTraps);
        world.setBlock(x + 7, y + 4, z + 7, heatTraps);
        world.setBlock(x + 7, y + 4, z + 8, heatTraps);
        world.setBlock(x + 7, y + 4, z + 9, heatTraps);
        world.setBlock(x + 7, y + 4, z + 15, soulStone);
        world.setBlock(x + 7, y + 5, z + 0, soulStone);
        world.setBlock(x + 7, y + 5, z + 6, heatTraps);
        world.setBlock(x + 7, y + 5, z + 7, heatTraps);
        world.setBlock(x + 7, y + 5, z + 8, heatTraps);
        world.setBlock(x + 7, y + 5, z + 9, heatTraps);
        world.setBlock(x + 7, y + 5, z + 15, soulStone);
        world.setBlock(x + 7, y + 6, z + 0, ancientStone);
        world.setBlock(x + 7, y + 6, z + 6, heatTraps);
        world.setBlock(x + 7, y + 6, z + 7, heatTraps);
        world.setBlock(x + 7, y + 6, z + 8, heatTraps);
        world.setBlock(x + 7, y + 6, z + 9, heatTraps);
        world.setBlock(x + 7, y + 6, z + 15, ancientStone);
        world.setBlock(x + 7, y + 7, z + 0, ancientStone);
        world.setBlock(x + 7, y + 7, z + 6, heatTraps);
        world.setBlock(x + 7, y + 7, z + 7, heatTraps);
        world.setBlock(x + 7, y + 7, z + 8, heatTraps);
        world.setBlock(x + 7, y + 7, z + 9, heatTraps);
        world.setBlock(x + 7, y + 7, z + 15, ancientStone);
        world.setBlock(x + 8, y + 0, z + 0, ancientbricks);
        world.setBlock(x + 8, y + 0, z + 1, ancientbricks);
        world.setBlock(x + 8, y + 0, z + 2, ancientbricks);
        world.setBlock(x + 8, y + 0, z + 3, ancientbricks);
        world.setBlock(x + 8, y + 0, z + 4, dungeonBricks);
        world.setBlock(x + 8, y + 0, z + 5, dungeonBricks);
        world.setBlock(x + 8, y + 0, z + 6, heatTraps);
        world.setBlock(x + 8, y + 0, z + 7, ArcanaBlocks.arcanitetubes);
        world.setBlock(x + 8, y + 0, z + 8, ArcanaBlocks.arcanitetubes);
        world.setBlock(x + 8, y + 0, z + 9, heatTraps);
        world.setBlock(x + 8, y + 0, z + 10, dungeonBricks);
        world.setBlock(x + 8, y + 0, z + 11, dungeonBricks);
        world.setBlock(x + 8, y + 0, z + 12, ancientbricks);
        world.setBlock(x + 8, y + 0, z + 13, ancientbricks);
        world.setBlock(x + 8, y + 0, z + 14, ancientbricks);
        world.setBlock(x + 8, y + 0, z + 15, ancientbricks);
        world.setBlock(x + 8, y + 1, z + 2, heatTraps);
        world.setBlock(x + 8, y + 1, z + 6, heatTraps);
        world.setBlock(x + 8, y + 1, z + 7, heatTraps);
        world.setBlock(x + 8, y + 1, z + 8, heatTraps);
        world.setBlock(x + 8, y + 1, z + 9, heatTraps);
        world.setBlock(x + 8, y + 1, z + 13, heatTraps);
        world.setBlock(x + 8, y + 2, z + 6, heatTraps);
        world.setBlock(x + 8, y + 2, z + 7, heatTraps);
        world.setBlock(x + 8, y + 2, z + 8, heatTraps);
        world.setBlock(x + 8, y + 2, z + 9, heatTraps);
        world.setBlock(x + 8, y + 3, z + 0, ArcanaBlocks.arcaniumPower);
        world.setBlock(x + 8, y + 3, z + 6, heatTraps);
        world.setBlock(x + 8, y + 3, z + 7, heatTraps);
        world.setBlock(x + 8, y + 3, z + 8, heatTraps);
        world.setBlock(x + 8, y + 3, z + 9, heatTraps);
        world.setBlock(x + 8, y + 3, z + 15, ArcanaBlocks.arcaniumPower);
        world.setBlock(x + 8, y + 4, z + 0, soulStone);
        world.setBlock(x + 8, y + 4, z + 6, heatTraps);
        world.setBlock(x + 8, y + 4, z + 7, heatTraps);
        world.setBlock(x + 8, y + 4, z + 8, heatTraps);
        world.setBlock(x + 8, y + 4, z + 9, heatTraps);
        world.setBlock(x + 8, y + 4, z + 15, soulStone);
        world.setBlock(x + 8, y + 5, z + 0, soulStone);
        world.setBlock(x + 8, y + 5, z + 6, heatTraps);
        world.setBlock(x + 8, y + 5, z + 7, heatTraps);
        world.setBlock(x + 8, y + 5, z + 8, heatTraps);
        world.setBlock(x + 8, y + 5, z + 9, heatTraps);
        world.setBlock(x + 8, y + 5, z + 15, soulStone);
        world.setBlock(x + 8, y + 6, z + 0, ancientStone);
        world.setBlock(x + 8, y + 6, z + 6, heatTraps);
        world.setBlock(x + 8, y + 6, z + 7, heatTraps);
        world.setBlock(x + 8, y + 6, z + 8, heatTraps);
        world.setBlock(x + 8, y + 6, z + 9, heatTraps);
        world.setBlock(x + 8, y + 6, z + 15, ancientStone);
        world.setBlock(x + 8, y + 7, z + 0, ancientStone);
        world.setBlock(x + 8, y + 7, z + 6, heatTraps);
        world.setBlock(x + 8, y + 7, z + 7, heatTraps);
        world.setBlock(x + 8, y + 7, z + 8, heatTraps);
        world.setBlock(x + 8, y + 7, z + 9, heatTraps);
        world.setBlock(x + 8, y + 7, z + 15, ancientStone);
        world.setBlock(x + 9, y + 0, z + 0, ancientbricks);
        world.setBlock(x + 9, y + 0, z + 1, ancientbricks);
        world.setBlock(x + 9, y + 0, z + 2, ancientbricks);
        world.setBlock(x + 9, y + 0, z + 3, dungeonBricks);
        world.setBlock(x + 9, y + 0, z + 4, dungeonBricks);
        world.setBlock(x + 9, y + 0, z + 5, heatTraps);
        world.setBlock(x + 9, y + 0, z + 6, heatTraps);
        world.setBlock(x + 9, y + 0, z + 7, heatTraps);
        world.setBlock(x + 9, y + 0, z + 8, heatTraps);
        world.setBlock(x + 9, y + 0, z + 9, heatTraps);
        world.setBlock(x + 9, y + 0, z + 10, heatTraps);
        world.setBlock(x + 9, y + 0, z + 11, dungeonBricks);
        world.setBlock(x + 9, y + 0, z + 12, dungeonBricks);
        world.setBlock(x + 9, y + 0, z + 13, ancientbricks);
        world.setBlock(x + 9, y + 0, z + 14, ancientbricks);
        world.setBlock(x + 9, y + 0, z + 15, ancientbricks);
        world.setBlock(x + 9, y + 1, z + 0, ancientStone);
        world.setBlock(x + 9, y + 1, z + 7, ArcanaBlocks.dungenSpawnerPrisoner);
        world.setBlock(x + 9, y + 1, z + 8, heatTraps);
        world.setBlock(x + 9, y + 1, z + 15, ancientStone);
        world.setBlock(x + 9, y + 2, z + 0, ArcanaBlocks.dungenLamp);
        world.setBlock(x + 9, y + 2, z + 7, heatTraps);
        world.setBlock(x + 9, y + 2, z + 8, heatTraps);
        world.setBlock(x + 9, y + 2, z + 15, ArcanaBlocks.dungenLamp);
        world.setBlock(x + 9, y + 3, z + 0, ancientStone);
        world.setBlock(x + 9, y + 3, z + 7, heatTraps);
        world.setBlock(x + 9, y + 3, z + 8, heatTraps);
        world.setBlock(x + 9, y + 3, z + 15, ancientStone);
        world.setBlock(x + 9, y + 4, z + 0, soulStone);
        world.setBlock(x + 9, y + 4, z + 7, heatTraps);
        world.setBlock(x + 9, y + 4, z + 8, heatTraps);
        world.setBlock(x + 9, y + 4, z + 15, soulStone);
        world.setBlock(x + 9, y + 5, z + 0, soulStone);
        world.setBlock(x + 9, y + 5, z + 7, heatTraps);
        world.setBlock(x + 9, y + 5, z + 8, heatTraps);
        world.setBlock(x + 9, y + 5, z + 15, soulStone);
        world.setBlock(x + 9, y + 6, z + 0, ancientStone);
        world.setBlock(x + 9, y + 6, z + 7, heatTraps);
        world.setBlock(x + 9, y + 6, z + 8, heatTraps);
        world.setBlock(x + 9, y + 6, z + 15, ancientStone);
        world.setBlock(x + 9, y + 7, z + 0, ancientStone);
        world.setBlock(x + 9, y + 7, z + 5, heatTraps);
        world.setBlock(x + 9, y + 7, z + 6, heatTraps);
        world.setBlock(x + 9, y + 7, z + 7, heatTraps);
        world.setBlock(x + 9, y + 7, z + 8, heatTraps);
        world.setBlock(x + 9, y + 7, z + 9, heatTraps);
        world.setBlock(x + 9, y + 7, z + 10, heatTraps);
        world.setBlock(x + 9, y + 7, z + 15, ancientStone);
        world.setBlock(x + 10, y + 0, z + 0, ancientbricks);
        world.setBlock(x + 10, y + 0, z + 1, ancientbricks);
        world.setBlock(x + 10, y + 0, z + 2, dungeonBricks);
        world.setBlock(x + 10, y + 0, z + 3, dungeonBricks);
        world.setBlock(x + 10, y + 0, z + 4, heatTraps);
        world.setBlock(x + 10, y + 0, z + 5, heatTraps);
        world.setBlock(x + 10, y + 0, z + 6, heatTraps);
        world.setBlock(x + 10, y + 0, z + 7, dungeonBricks);
        world.setBlock(x + 10, y + 0, z + 8, dungeonBricks);
        world.setBlock(x + 10, y + 0, z + 9, heatTraps);
        world.setBlock(x + 10, y + 0, z + 10, heatTraps);
        world.setBlock(x + 10, y + 0, z + 11, heatTraps);
        world.setBlock(x + 10, y + 0, z + 12, dungeonBricks);
        world.setBlock(x + 10, y + 0, z + 13, dungeonBricks);
        world.setBlock(x + 10, y + 0, z + 14, ancientbricks);
        world.setBlock(x + 10, y + 0, z + 15, ancientbricks);
        world.setBlock(x + 10, y + 1, z + 0, soulStone);
        world.setBlock(x + 10, y + 1, z + 15, soulStone);
        world.setBlock(x + 10, y + 2, z + 0, soulStone);
        world.setBlock(x + 10, y + 2, z + 15, soulStone);
        world.setBlock(x + 10, y + 3, z + 0, soulStone);
        world.setBlock(x + 10, y + 3, z + 15, soulStone);
        world.setBlock(x + 10, y + 4, z + 0, soulStone);
        world.setBlock(x + 10, y + 4, z + 15, soulStone);
        world.setBlock(x + 10, y + 5, z + 0, soulStone);
        world.setBlock(x + 10, y + 5, z + 15, soulStone);
        world.setBlock(x + 10, y + 6, z + 0, ancientStone);
        world.setBlock(x + 10, y + 6, z + 15, ancientStone);
        world.setBlock(x + 10, y + 7, z + 0, ancientStone);
        world.setBlock(x + 10, y + 7, z + 4, heatTraps);
        world.setBlock(x + 10, y + 7, z + 5, heatTraps);
        world.setBlock(x + 10, y + 7, z + 6, heatTraps);
        world.setBlock(x + 10, y + 7, z + 9, heatTraps);
        world.setBlock(x + 10, y + 7, z + 10, heatTraps);
        world.setBlock(x + 10, y + 7, z + 11, heatTraps);
        world.setBlock(x + 10, y + 7, z + 15, ancientStone);
        world.setBlock(x + 11, y + 0, z + 0, ancientbricks);
        world.setBlock(x + 11, y + 0, z + 1, dungeonBricks);
        world.setBlock(x + 11, y + 0, z + 2, dungeonBricks);
        world.setBlock(x + 11, y + 0, z + 3, heatTraps);
        world.setBlock(x + 11, y + 0, z + 4, heatTraps);
        world.setBlock(x + 11, y + 0, z + 5, heatTraps);
        world.setBlock(x + 11, y + 0, z + 6, dungeonBricks);
        world.setBlock(x + 11, y + 0, z + 7, dungeonBricks);
        world.setBlock(x + 11, y + 0, z + 8, dungeonBricks);
        world.setBlock(x + 11, y + 0, z + 9, dungeonBricks);
        world.setBlock(x + 11, y + 0, z + 10, heatTraps);
        world.setBlock(x + 11, y + 0, z + 11, heatTraps);
        world.setBlock(x + 11, y + 0, z + 12, heatTraps);
        world.setBlock(x + 11, y + 0, z + 13, dungeonBricks);
        world.setBlock(x + 11, y + 0, z + 14, dungeonBricks);
        world.setBlock(x + 11, y + 0, z + 15, ancientbricks);
        world.setBlock(x + 11, y + 1, z + 0, soulStone);
        world.setBlock(x + 11, y + 1, z + 15, soulStone);
        world.setBlock(x + 11, y + 2, z + 0, soulStone);
        world.setBlock(x + 11, y + 2, z + 15, soulStone);
        world.setBlock(x + 11, y + 3, z + 0, soulStone);
        world.setBlock(x + 11, y + 3, z + 15, soulStone);
        world.setBlock(x + 11, y + 4, z + 0, soulStone);
        world.setBlock(x + 11, y + 4, z + 15, soulStone);
        world.setBlock(x + 11, y + 5, z + 0, soulStone);
        world.setBlock(x + 11, y + 5, z + 15, soulStone);
        world.setBlock(x + 11, y + 6, z + 0, ancientStone);
        world.setBlock(x + 11, y + 6, z + 15, ancientStone);
        world.setBlock(x + 11, y + 7, z + 0, ancientStone);
        world.setBlock(x + 11, y + 7, z + 3, heatTraps);
        world.setBlock(x + 11, y + 7, z + 4, heatTraps);
        world.setBlock(x + 11, y + 7, z + 5, heatTraps);
        world.setBlock(x + 11, y + 7, z + 10, heatTraps);
        world.setBlock(x + 11, y + 7, z + 11, heatTraps);
        world.setBlock(x + 11, y + 7, z + 12, heatTraps);
        world.setBlock(x + 11, y + 7, z + 15, ancientStone);
        world.setBlock(x + 12, y + 0, z + 0, dungeonBricks);
        world.setBlock(x + 12, y + 0, z + 1, dungeonBricks);
        world.setBlock(x + 12, y + 0, z + 2, heatTraps);
        world.setBlock(x + 12, y + 0, z + 3, heatTraps);
        world.setBlock(x + 12, y + 0, z + 4, heatTraps);
        world.setBlock(x + 12, y + 0, z + 5, dungeonBricks);
        world.setBlock(x + 12, y + 0, z + 6, dungeonBricks);
        world.setBlock(x + 12, y + 0, z + 7, ancientbricks);
        world.setBlock(x + 12, y + 0, z + 8, ancientbricks);
        world.setBlock(x + 12, y + 0, z + 9, dungeonBricks);
        world.setBlock(x + 12, y + 0, z + 10, dungeonBricks);
        world.setBlock(x + 12, y + 0, z + 11, heatTraps);
        world.setBlock(x + 12, y + 0, z + 12, heatTraps);
        world.setBlock(x + 12, y + 0, z + 13, heatTraps);
        world.setBlock(x + 12, y + 0, z + 14, dungeonBricks);
        world.setBlock(x + 12, y + 0, z + 15, dungeonBricks);
        world.setBlock(x + 12, y + 1, z + 0, soulStone);
        world.setBlock(x + 12, y + 1, z + 15, soulStone);
        world.setBlock(x + 12, y + 2, z + 0, soulStone);
        world.setBlock(x + 12, y + 2, z + 15, soulStone);
        world.setBlock(x + 12, y + 3, z + 0, soulStone);
        world.setBlock(x + 12, y + 3, z + 15, soulStone);
        world.setBlock(x + 12, y + 4, z + 0, soulStone);
        world.setBlock(x + 12, y + 4, z + 15, soulStone);
        world.setBlock(x + 12, y + 5, z + 0, soulStone);
        world.setBlock(x + 12, y + 5, z + 15, soulStone);
        world.setBlock(x + 12, y + 6, z + 0, ancientStone);
        world.setBlock(x + 12, y + 6, z + 15, ancientStone);
        world.setBlock(x + 12, y + 7, z + 0, ancientStone);
        world.setBlock(x + 12, y + 7, z + 2, heatTraps);
        world.setBlock(x + 12, y + 7, z + 3, heatTraps);
        world.setBlock(x + 12, y + 7, z + 4, heatTraps);
        world.setBlock(x + 12, y + 7, z + 11, heatTraps);
        world.setBlock(x + 12, y + 7, z + 12, heatTraps);
        world.setBlock(x + 12, y + 7, z + 13, heatTraps);
        world.setBlock(x + 12, y + 7, z + 15, ancientStone);
        world.setBlock(x + 13, y + 0, z + 0, dungeonBricks);
        world.setBlock(x + 13, y + 0, z + 1, heatTraps);
        world.setBlock(x + 13, y + 0, z + 2, heatTraps);
        world.setBlock(x + 13, y + 0, z + 3, heatTraps);
        world.setBlock(x + 13, y + 0, z + 4, dungeonBricks);
        world.setBlock(x + 13, y + 0, z + 5, dungeonBricks);
        world.setBlock(x + 13, y + 0, z + 6, ancientbricks);
        world.setBlock(x + 13, y + 0, z + 7, ancientbricks);
        world.setBlock(x + 13, y + 0, z + 8, ancientbricks);
        world.setBlock(x + 13, y + 0, z + 9, ancientbricks);
        world.setBlock(x + 13, y + 0, z + 10, dungeonBricks);
        world.setBlock(x + 13, y + 0, z + 11, dungeonBricks);
        world.setBlock(x + 13, y + 0, z + 12, heatTraps);
        world.setBlock(x + 13, y + 0, z + 13, heatTraps);
        world.setBlock(x + 13, y + 0, z + 14, heatTraps);
        world.setBlock(x + 13, y + 0, z + 15, dungeonBricks);
        world.setBlock(x + 13, y + 1, z + 0, soulStone);
        world.setBlock(x + 13, y + 1, z + 7, heatTraps);
        world.setBlock(x + 13, y + 1, z + 8, heatTraps);
        world.setBlock(x + 13, y + 1, z + 15, soulStone);
        world.setBlock(x + 13, y + 2, z + 0, soulStone);
        world.setBlock(x + 13, y + 2, z + 15, soulStone);
        world.setBlock(x + 13, y + 3, z + 0, soulStone);
        world.setBlock(x + 13, y + 3, z + 15, soulStone);
        world.setBlock(x + 13, y + 4, z + 0, soulStone);
        world.setBlock(x + 13, y + 4, z + 15, soulStone);
        world.setBlock(x + 13, y + 5, z + 0, soulStone);
        world.setBlock(x + 13, y + 5, z + 15, soulStone);
        world.setBlock(x + 13, y + 6, z + 0, ancientStone);
        world.setBlock(x + 13, y + 6, z + 15, ancientStone);
        world.setBlock(x + 13, y + 7, z + 0, ancientStone);
        world.setBlock(x + 13, y + 7, z + 1, heatTraps);
        world.setBlock(x + 13, y + 7, z + 2, heatTraps);
        world.setBlock(x + 13, y + 7, z + 3, heatTraps);
        world.setBlock(x + 13, y + 7, z + 12, heatTraps);
        world.setBlock(x + 13, y + 7, z + 13, heatTraps);
        world.setBlock(x + 13, y + 7, z + 14, heatTraps);
        world.setBlock(x + 13, y + 7, z + 15, ancientStone);
        world.setBlock(x + 14, y + 0, z + 0, heatTraps);
        world.setBlock(x + 14, y + 0, z + 1, heatTraps);
        world.setBlock(x + 14, y + 0, z + 2, heatTraps);
        world.setBlock(x + 14, y + 0, z + 3, dungeonBricks);
        world.setBlock(x + 14, y + 0, z + 4, dungeonBricks);
        world.setBlock(x + 14, y + 0, z + 5, ancientbricks);
        world.setBlock(x + 14, y + 0, z + 6, ancientbricks);
        world.setBlock(x + 14, y + 0, z + 7, ancientbricks);
        world.setBlock(x + 14, y + 0, z + 8, ancientbricks);
        world.setBlock(x + 14, y + 0, z + 9, ancientbricks);
        world.setBlock(x + 14, y + 0, z + 10, ancientbricks);
        world.setBlock(x + 14, y + 0, z + 11, dungeonBricks);
        world.setBlock(x + 14, y + 0, z + 12, dungeonBricks);
        world.setBlock(x + 14, y + 0, z + 13, heatTraps);
        world.setBlock(x + 14, y + 0, z + 14, heatTraps);
        world.setBlock(x + 14, y + 0, z + 15, heatTraps);
        world.setBlock(x + 14, y + 1, z + 0, heatTraps);
        world.setBlock(x + 14, y + 1, z + 1, heatTraps);
        world.setBlock(x + 14, y + 1, z + 14, heatTraps);
        world.setBlock(x + 14, y + 1, z + 15, heatTraps);
        world.setBlock(x + 14, y + 2, z + 0, heatTraps);
        world.setBlock(x + 14, y + 2, z + 1, heatTraps);
        world.setBlock(x + 14, y + 2, z + 14, heatTraps);
        world.setBlock(x + 14, y + 2, z + 15, heatTraps);
        world.setBlock(x + 14, y + 3, z + 0, heatTraps);
        world.setBlock(x + 14, y + 3, z + 1, heatTraps);
        world.setBlock(x + 14, y + 3, z + 14, heatTraps);
        world.setBlock(x + 14, y + 3, z + 15, heatTraps);
        world.setBlock(x + 14, y + 4, z + 0, heatTraps);
        world.setBlock(x + 14, y + 4, z + 1, heatTraps);
        world.setBlock(x + 14, y + 4, z + 14, heatTraps);
        world.setBlock(x + 14, y + 4, z + 15, heatTraps);
        world.setBlock(x + 14, y + 5, z + 0, heatTraps);
        world.setBlock(x + 14, y + 5, z + 1, heatTraps);
        world.setBlock(x + 14, y + 5, z + 14, heatTraps);
        world.setBlock(x + 14, y + 5, z + 15, heatTraps);
        world.setBlock(x + 14, y + 6, z + 0, heatTraps);
        world.setBlock(x + 14, y + 6, z + 1, heatTraps);
        world.setBlock(x + 14, y + 6, z + 14, heatTraps);
        world.setBlock(x + 14, y + 6, z + 15, heatTraps);
        world.setBlock(x + 14, y + 7, z + 0, heatTraps);
        world.setBlock(x + 14, y + 7, z + 1, heatTraps);
        world.setBlock(x + 14, y + 7, z + 2, heatTraps);
        world.setBlock(x + 14, y + 7, z + 13, heatTraps);
        world.setBlock(x + 14, y + 7, z + 14, heatTraps);
        world.setBlock(x + 14, y + 7, z + 15, heatTraps);
        world.setBlock(x + 15, y + 0, z + 0, heatTraps);
        world.setBlock(x + 15, y + 0, z + 1, heatTraps);
        world.setBlock(x + 15, y + 0, z + 2, dungeonBricks);
        world.setBlock(x + 15, y + 0, z + 3, dungeonBricks);
        world.setBlock(x + 15, y + 0, z + 4, ancientbricks);
        world.setBlock(x + 15, y + 0, z + 5, ancientbricks);
        world.setBlock(x + 15, y + 0, z + 6, ancientbricks);
        world.setBlock(x + 15, y + 0, z + 7, ancientbricks);
        world.setBlock(x + 15, y + 0, z + 8, ancientbricks);
        world.setBlock(x + 15, y + 0, z + 9, ancientbricks);
        world.setBlock(x + 15, y + 0, z + 10, ancientbricks);
        world.setBlock(x + 15, y + 0, z + 11, ancientbricks);
        world.setBlock(x + 15, y + 0, z + 12, dungeonBricks);
        world.setBlock(x + 15, y + 0, z + 13, dungeonBricks);
        world.setBlock(x + 15, y + 0, z + 14, heatTraps);
        world.setBlock(x + 15, y + 0, z + 15, heatTraps);
        world.setBlock(x + 15, y + 1, z + 0, heatTraps);
        world.setBlock(x + 15, y + 1, z + 1, heatTraps);
        world.setBlock(x + 15, y + 1, z + 2, soulStone);
        world.setBlock(x + 15, y + 1, z + 3, soulStone);
        world.setBlock(x + 15, y + 1, z + 4, soulStone);
        world.setBlock(x + 15, y + 1, z + 5, soulStone);
        world.setBlock(x + 15, y + 1, z + 6, ancientStone);
        world.setBlock(x + 15, y + 1, z + 9, ancientStone);
        world.setBlock(x + 15, y + 1, z + 10, soulStone);
        world.setBlock(x + 15, y + 1, z + 11, soulStone);
        world.setBlock(x + 15, y + 1, z + 12, soulStone);
        world.setBlock(x + 15, y + 1, z + 13, soulStone);
        world.setBlock(x + 15, y + 1, z + 14, heatTraps);
        world.setBlock(x + 15, y + 1, z + 15, heatTraps);
        world.setBlock(x + 15, y + 2, z + 0, heatTraps);
        world.setBlock(x + 15, y + 2, z + 1, heatTraps);
        world.setBlock(x + 15, y + 2, z + 2, soulStone);
        world.setBlock(x + 15, y + 2, z + 3, soulStone);
        world.setBlock(x + 15, y + 2, z + 4, soulStone);
        world.setBlock(x + 15, y + 2, z + 5, soulStone);
        world.setBlock(x + 15, y + 2, z + 6, ArcanaBlocks.dungenLamp);
        world.setBlock(x + 15, y + 2, z + 9, ArcanaBlocks.dungenLamp);
        world.setBlock(x + 15, y + 2, z + 10, soulStone);
        world.setBlock(x + 15, y + 2, z + 11, soulStone);
        world.setBlock(x + 15, y + 2, z + 12, soulStone);
        world.setBlock(x + 15, y + 2, z + 13, soulStone);
        world.setBlock(x + 15, y + 2, z + 14, heatTraps);
        world.setBlock(x + 15, y + 2, z + 15, heatTraps);
        world.setBlock(x + 15, y + 3, z + 0, heatTraps);
        world.setBlock(x + 15, y + 3, z + 1, heatTraps);
        world.setBlock(x + 15, y + 3, z + 2, soulStone);
        world.setBlock(x + 15, y + 3, z + 3, soulStone);
        world.setBlock(x + 15, y + 3, z + 4, soulStone);
        world.setBlock(x + 15, y + 3, z + 5, soulStone);
        world.setBlock(x + 15, y + 3, z + 6, ancientStone);
        world.setBlock(x + 15, y + 3, z + 7, ArcanaBlocks.arcaniumPower);
        world.setBlock(x + 15, y + 3, z + 8, ArcanaBlocks.arcaniumPower);
        world.setBlock(x + 15, y + 3, z + 9, ancientStone);
        world.setBlock(x + 15, y + 3, z + 10, soulStone);
        world.setBlock(x + 15, y + 3, z + 11, soulStone);
        world.setBlock(x + 15, y + 3, z + 12, soulStone);
        world.setBlock(x + 15, y + 3, z + 13, soulStone);
        world.setBlock(x + 15, y + 3, z + 14, heatTraps);
        world.setBlock(x + 15, y + 3, z + 15, heatTraps);
        world.setBlock(x + 15, y + 4, z + 0, heatTraps);
        world.setBlock(x + 15, y + 4, z + 1, heatTraps);
        world.setBlock(x + 15, y + 4, z + 2, soulStone);
        world.setBlock(x + 15, y + 4, z + 3, soulStone);
        world.setBlock(x + 15, y + 4, z + 4, soulStone);
        world.setBlock(x + 15, y + 4, z + 5, soulStone);
        world.setBlock(x + 15, y + 4, z + 6, soulStone);
        world.setBlock(x + 15, y + 4, z + 7, soulStone);
        world.setBlock(x + 15, y + 4, z + 8, soulStone);
        world.setBlock(x + 15, y + 4, z + 9, soulStone);
        world.setBlock(x + 15, y + 4, z + 10, soulStone);
        world.setBlock(x + 15, y + 4, z + 11, soulStone);
        world.setBlock(x + 15, y + 4, z + 12, soulStone);
        world.setBlock(x + 15, y + 4, z + 13, soulStone);
        world.setBlock(x + 15, y + 4, z + 14, heatTraps);
        world.setBlock(x + 15, y + 4, z + 15, heatTraps);
        world.setBlock(x + 15, y + 5, z + 0, heatTraps);
        world.setBlock(x + 15, y + 5, z + 1, heatTraps);
        world.setBlock(x + 15, y + 5, z + 2, soulStone);
        world.setBlock(x + 15, y + 5, z + 3, soulStone);
        world.setBlock(x + 15, y + 5, z + 4, soulStone);
        world.setBlock(x + 15, y + 5, z + 5, soulStone);
        world.setBlock(x + 15, y + 5, z + 6, soulStone);
        world.setBlock(x + 15, y + 5, z + 7, soulStone);
        world.setBlock(x + 15, y + 5, z + 8, soulStone);
        world.setBlock(x + 15, y + 5, z + 9, soulStone);
        world.setBlock(x + 15, y + 5, z + 10, soulStone);
        world.setBlock(x + 15, y + 5, z + 11, soulStone);
        world.setBlock(x + 15, y + 5, z + 12, soulStone);
        world.setBlock(x + 15, y + 5, z + 13, soulStone);
        world.setBlock(x + 15, y + 5, z + 14, heatTraps);
        world.setBlock(x + 15, y + 5, z + 15, heatTraps);
        world.setBlock(x + 15, y + 6, z + 0, heatTraps);
        world.setBlock(x + 15, y + 6, z + 1, heatTraps);
        world.setBlock(x + 15, y + 6, z + 2, ancientStone);
        world.setBlock(x + 15, y + 6, z + 3, ancientStone);
        world.setBlock(x + 15, y + 6, z + 4, ancientStone);
        world.setBlock(x + 15, y + 6, z + 5, ancientStone);
        world.setBlock(x + 15, y + 6, z + 6, ancientStone);
        world.setBlock(x + 15, y + 6, z + 7, ancientStone);
        world.setBlock(x + 15, y + 6, z + 8, ancientStone);
        world.setBlock(x + 15, y + 6, z + 9, ancientStone);
        world.setBlock(x + 15, y + 6, z + 10, ancientStone);
        world.setBlock(x + 15, y + 6, z + 11, ancientStone);
        world.setBlock(x + 15, y + 6, z + 12, ancientStone);
        world.setBlock(x + 15, y + 6, z + 13, ancientStone);
        world.setBlock(x + 15, y + 6, z + 14, heatTraps);
        world.setBlock(x + 15, y + 6, z + 15, heatTraps);
        world.setBlock(x + 15, y + 7, z + 0, heatTraps);
        world.setBlock(x + 15, y + 7, z + 1, heatTraps);
        world.setBlock(x + 15, y + 7, z + 2, ancientStone);
        world.setBlock(x + 15, y + 7, z + 3, ancientStone);
        world.setBlock(x + 15, y + 7, z + 4, ancientStone);
        world.setBlock(x + 15, y + 7, z + 5, ancientStone);
        world.setBlock(x + 15, y + 7, z + 6, ancientStone);
        world.setBlock(x + 15, y + 7, z + 7, ancientStone);
        world.setBlock(x + 15, y + 7, z + 8, ancientStone);
        world.setBlock(x + 15, y + 7, z + 9, ancientStone);
        world.setBlock(x + 15, y + 7, z + 10, ancientStone);
        world.setBlock(x + 15, y + 7, z + 11, ancientStone);
        world.setBlock(x + 15, y + 7, z + 12, ancientStone);
        world.setBlock(x + 15, y + 7, z + 13, ancientStone);
        world.setBlock(x + 15, y + 7, z + 14, heatTraps);
        world.setBlock(x + 15, y + 7, z + 15, heatTraps);
        return true;
    }
}