/*
 *** MADE BY MITHION'S .SCHEMATIC TO JAVA CONVERTING TOOL v1.6 ***
 */

package net.divinerpg.dimensions.arcana.components;
import java.util.Random;

import net.divinerpg.dimensions.arcana.ArcanaChunk;
import net.divinerpg.utils.blocks.ArcanaBlocks;
import net.minecraft.block.Block;

public class DungeonComponent10 extends DungeonComponentBase {

    @Override
    public boolean generate(ArcanaChunk world, Random rand, int i, int j, int k) {

        Block heatTraps = ArcanaBlocks.heatTrap;
        Block dungeonBricks = ArcanaBlocks.degradedBrick;
        Block ancientbricks = ArcanaBlocks.ancientBrick;
        Block arcaniteMetal = ArcanaBlocks.arcaniumMetal;
        Block arcanaPower = ArcanaBlocks.arcaniumPower;

        world.setBlock(i + 0, j + 0, k + 0, dungeonBricks);
        world.setBlock(i + 0, j + 0, k + 1, dungeonBricks);
        world.setBlock(i + 0, j + 0, k + 2, dungeonBricks);
        world.setBlock(i + 0, j + 0, k + 3, dungeonBricks);
        world.setBlock(i + 0, j + 0, k + 4, dungeonBricks);
        world.setBlock(i + 0, j + 0, k + 5, dungeonBricks);
        world.setBlock(i + 0, j + 0, k + 6, dungeonBricks);
        world.setBlock(i + 0, j + 0, k + 7, dungeonBricks);
        world.setBlock(i + 0, j + 0, k + 8, dungeonBricks);
        world.setBlock(i + 0, j + 0, k + 9, dungeonBricks);
        world.setBlock(i + 0, j + 0, k + 10, dungeonBricks);
        world.setBlock(i + 0, j + 0, k + 11, dungeonBricks);
        world.setBlock(i + 0, j + 0, k + 12, dungeonBricks);
        world.setBlock(i + 0, j + 0, k + 13, dungeonBricks);
        world.setBlock(i + 0, j + 0, k + 14, dungeonBricks);
        world.setBlock(i + 0, j + 0, k + 15, dungeonBricks);
        world.setBlock(i + 0, j + 1, k + 0, dungeonBricks);
        world.setBlock(i + 0, j + 1, k + 1, dungeonBricks);
        world.setBlock(i + 0, j + 1, k + 2, dungeonBricks);
        world.setBlock(i + 0, j + 1, k + 3, dungeonBricks);
        world.setBlock(i + 0, j + 1, k + 4, dungeonBricks);
        world.setBlock(i + 0, j + 1, k + 5, dungeonBricks);
        world.setBlock(i + 0, j + 1, k + 6, arcaniteMetal);
        world.setBlock(i + 0, j + 1, k + 9, arcaniteMetal);
        world.setBlock(i + 0, j + 1, k + 10, dungeonBricks);
        world.setBlock(i + 0, j + 1, k + 11, dungeonBricks);
        world.setBlock(i + 0, j + 1, k + 12, dungeonBricks);
        world.setBlock(i + 0, j + 1, k + 13, dungeonBricks);
        world.setBlock(i + 0, j + 1, k + 14, dungeonBricks);
        world.setBlock(i + 0, j + 1, k + 15, dungeonBricks);
        world.setBlock(i + 0, j + 2, k + 0, dungeonBricks);
        world.setBlock(i + 0, j + 2, k + 1, dungeonBricks);
        world.setBlock(i + 0, j + 2, k + 2, dungeonBricks);
        world.setBlock(i + 0, j + 2, k + 3, dungeonBricks);
        world.setBlock(i + 0, j + 2, k + 4, dungeonBricks);
        world.setBlock(i + 0, j + 2, k + 5, dungeonBricks);
        world.setBlock(i + 0, j + 2, k + 6, arcaniteMetal);
        world.setBlock(i + 0, j + 2, k + 9, arcaniteMetal);
        world.setBlock(i + 0, j + 2, k + 10, dungeonBricks);
        world.setBlock(i + 0, j + 2, k + 11, dungeonBricks);
        world.setBlock(i + 0, j + 2, k + 12, dungeonBricks);
        world.setBlock(i + 0, j + 2, k + 13, dungeonBricks);
        world.setBlock(i + 0, j + 2, k + 14, dungeonBricks);
        world.setBlock(i + 0, j + 2, k + 15, dungeonBricks);
        world.setBlock(i + 0, j + 3, k + 0, dungeonBricks);
        world.setBlock(i + 0, j + 3, k + 1, dungeonBricks);
        world.setBlock(i + 0, j + 3, k + 2, dungeonBricks);
        world.setBlock(i + 0, j + 3, k + 3, dungeonBricks);
        world.setBlock(i + 0, j + 3, k + 4, dungeonBricks);
        world.setBlock(i + 0, j + 3, k + 5, dungeonBricks);
        world.setBlock(i + 0, j + 3, k + 6, arcaniteMetal);
        world.setBlock(i + 0, j + 3, k + 7, arcanaPower);
        world.setBlock(i + 0, j + 3, k + 8, arcanaPower);
        world.setBlock(i + 0, j + 3, k + 9, arcaniteMetal);
        world.setBlock(i + 0, j + 3, k + 10, dungeonBricks);
        world.setBlock(i + 0, j + 3, k + 11, dungeonBricks);
        world.setBlock(i + 0, j + 3, k + 12, dungeonBricks);
        world.setBlock(i + 0, j + 3, k + 13, dungeonBricks);
        world.setBlock(i + 0, j + 3, k + 14, dungeonBricks);
        world.setBlock(i + 0, j + 3, k + 15, dungeonBricks);
        world.setBlock(i + 0, j + 4, k + 0, dungeonBricks);
        world.setBlock(i + 0, j + 4, k + 1, dungeonBricks);
        world.setBlock(i + 0, j + 4, k + 2, dungeonBricks);
        world.setBlock(i + 0, j + 4, k + 3, dungeonBricks);
        world.setBlock(i + 0, j + 4, k + 4, dungeonBricks);
        world.setBlock(i + 0, j + 4, k + 5, dungeonBricks);
        world.setBlock(i + 0, j + 4, k + 6, dungeonBricks);
        world.setBlock(i + 0, j + 4, k + 7, dungeonBricks);
        world.setBlock(i + 0, j + 4, k + 8, dungeonBricks);
        world.setBlock(i + 0, j + 4, k + 9, dungeonBricks);
        world.setBlock(i + 0, j + 4, k + 10, dungeonBricks);
        world.setBlock(i + 0, j + 4, k + 11, dungeonBricks);
        world.setBlock(i + 0, j + 4, k + 12, dungeonBricks);
        world.setBlock(i + 0, j + 4, k + 13, dungeonBricks);
        world.setBlock(i + 0, j + 4, k + 14, dungeonBricks);
        world.setBlock(i + 0, j + 4, k + 15, dungeonBricks);
        world.setBlock(i + 0, j + 5, k + 0, dungeonBricks);
        world.setBlock(i + 0, j + 5, k + 1, dungeonBricks);
        world.setBlock(i + 0, j + 5, k + 2, dungeonBricks);
        world.setBlock(i + 0, j + 5, k + 3, dungeonBricks);
        world.setBlock(i + 0, j + 5, k + 4, dungeonBricks);
        world.setBlock(i + 0, j + 5, k + 5, dungeonBricks);
        world.setBlock(i + 0, j + 5, k + 6, dungeonBricks);
        world.setBlock(i + 0, j + 5, k + 7, dungeonBricks);
        world.setBlock(i + 0, j + 5, k + 8, dungeonBricks);
        world.setBlock(i + 0, j + 5, k + 9, dungeonBricks);
        world.setBlock(i + 0, j + 5, k + 10, dungeonBricks);
        world.setBlock(i + 0, j + 5, k + 11, dungeonBricks);
        world.setBlock(i + 0, j + 5, k + 12, dungeonBricks);
        world.setBlock(i + 0, j + 5, k + 13, dungeonBricks);
        world.setBlock(i + 0, j + 5, k + 14, dungeonBricks);
        world.setBlock(i + 0, j + 5, k + 15, dungeonBricks);
        world.setBlock(i + 0, j + 6, k + 0, dungeonBricks);
        world.setBlock(i + 0, j + 6, k + 1, dungeonBricks);
        world.setBlock(i + 0, j + 6, k + 2, dungeonBricks);
        world.setBlock(i + 0, j + 6, k + 3, dungeonBricks);
        world.setBlock(i + 0, j + 6, k + 4, dungeonBricks);
        world.setBlock(i + 0, j + 6, k + 5, dungeonBricks);
        world.setBlock(i + 0, j + 6, k + 6, dungeonBricks);
        world.setBlock(i + 0, j + 6, k + 7, dungeonBricks);
        world.setBlock(i + 0, j + 6, k + 8, dungeonBricks);
        world.setBlock(i + 0, j + 6, k + 9, dungeonBricks);
        world.setBlock(i + 0, j + 6, k + 10, dungeonBricks);
        world.setBlock(i + 0, j + 6, k + 11, dungeonBricks);
        world.setBlock(i + 0, j + 6, k + 12, dungeonBricks);
        world.setBlock(i + 0, j + 6, k + 13, dungeonBricks);
        world.setBlock(i + 0, j + 6, k + 14, dungeonBricks);
        world.setBlock(i + 0, j + 6, k + 15, dungeonBricks);
        world.setBlock(i + 0, j + 7, k + 0, dungeonBricks);
        world.setBlock(i + 0, j + 7, k + 1, dungeonBricks);
        world.setBlock(i + 0, j + 7, k + 2, dungeonBricks);
        world.setBlock(i + 0, j + 7, k + 3, dungeonBricks);
        world.setBlock(i + 0, j + 7, k + 4, dungeonBricks);
        world.setBlock(i + 0, j + 7, k + 5, dungeonBricks);
        world.setBlock(i + 0, j + 7, k + 6, dungeonBricks);
        world.setBlock(i + 0, j + 7, k + 7, dungeonBricks);
        world.setBlock(i + 0, j + 7, k + 8, dungeonBricks);
        world.setBlock(i + 0, j + 7, k + 9, dungeonBricks);
        world.setBlock(i + 0, j + 7, k + 10, dungeonBricks);
        world.setBlock(i + 0, j + 7, k + 11, dungeonBricks);
        world.setBlock(i + 0, j + 7, k + 12, dungeonBricks);
        world.setBlock(i + 0, j + 7, k + 13, dungeonBricks);
        world.setBlock(i + 0, j + 7, k + 14, dungeonBricks);
        world.setBlock(i + 0, j + 7, k + 15, dungeonBricks);
        world.setBlock(i + 1, j + 0, k + 0, dungeonBricks);
        world.setBlock(i + 1, j + 0, k + 1, dungeonBricks);
        world.setBlock(i + 1, j + 0, k + 2, dungeonBricks);
        world.setBlock(i + 1, j + 0, k + 3, dungeonBricks);
        world.setBlock(i + 1, j + 0, k + 4, dungeonBricks);
        world.setBlock(i + 1, j + 0, k + 5, dungeonBricks);
        world.setBlock(i + 1, j + 0, k + 6, dungeonBricks);
        world.setBlock(i + 1, j + 0, k + 7, dungeonBricks);
        world.setBlock(i + 1, j + 0, k + 8, dungeonBricks);
        world.setBlock(i + 1, j + 0, k + 9, dungeonBricks);
        world.setBlock(i + 1, j + 0, k + 10, dungeonBricks);
        world.setBlock(i + 1, j + 0, k + 11, dungeonBricks);
        world.setBlock(i + 1, j + 0, k + 12, dungeonBricks);
        world.setBlock(i + 1, j + 0, k + 13, dungeonBricks);
        world.setBlock(i + 1, j + 0, k + 14, dungeonBricks);
        world.setBlock(i + 1, j + 0, k + 15, dungeonBricks);
        world.setBlock(i + 1, j + 1, k + 0, dungeonBricks);
        world.setBlock(i + 1, j + 1, k + 1, heatTraps);
        world.setBlock(i + 1, j + 1, k + 6, heatTraps);
        world.setBlock(i + 1, j + 1, k + 9, heatTraps);
        world.setBlock(i + 1, j + 1, k + 10, ancientbricks);
        world.setBlock(i + 1, j + 1, k + 11, ancientbricks);
        world.setBlock(i + 1, j + 1, k + 14, heatTraps);
        world.setBlock(i + 1, j + 1, k + 15, dungeonBricks);
        world.setBlock(i + 1, j + 2, k + 0, dungeonBricks);
        world.setBlock(i + 1, j + 2, k + 11, ancientbricks);
        world.setBlock(i + 1, j + 2, k + 12, ancientbricks);
        world.setBlock(i + 1, j + 2, k + 15, dungeonBricks);
        world.setBlock(i + 1, j + 3, k + 0, dungeonBricks);
        world.setBlock(i + 1, j + 3, k + 1, ancientbricks);
        world.setBlock(i + 1, j + 3, k + 2, ancientbricks);
        world.setBlock(i + 1, j + 3, k + 3, ancientbricks);
        world.setBlock(i + 1, j + 3, k + 4, ancientbricks);
        world.setBlock(i + 1, j + 3, k + 5, ancientbricks);
        world.setBlock(i + 1, j + 3, k + 6, ancientbricks);
        world.setBlock(i + 1, j + 3, k + 12, ancientbricks);
        world.setBlock(i + 1, j + 3, k + 13, ancientbricks);
        world.setBlock(i + 1, j + 3, k + 14, ancientbricks);
        world.setBlock(i + 1, j + 3, k + 15, dungeonBricks);
        world.setBlock(i + 1, j + 4, k + 0, dungeonBricks);
        world.setBlock(i + 1, j + 4, k + 1, heatTraps);
        world.setBlock(i + 1, j + 4, k + 14, heatTraps);
        world.setBlock(i + 1, j + 4, k + 15, dungeonBricks);
        world.setBlock(i + 1, j + 5, k + 0, dungeonBricks);
        world.setBlock(i + 1, j + 5, k + 15, dungeonBricks);
        world.setBlock(i + 1, j + 6, k + 0, dungeonBricks);
        world.setBlock(i + 1, j + 6, k + 15, dungeonBricks);
        world.setBlock(i + 1, j + 7, k + 0, dungeonBricks);
        world.setBlock(i + 1, j + 7, k + 1, ArcanaBlocks.dungenLamp);
        world.setBlock(i + 1, j + 7, k + 14, ArcanaBlocks.dungenLamp);
        world.setBlock(i + 1, j + 7, k + 15, dungeonBricks);
        world.setBlock(i + 2, j + 0, k + 0, dungeonBricks);
        world.setBlock(i + 2, j + 0, k + 1, dungeonBricks);
        world.setBlock(i + 2, j + 0, k + 2, dungeonBricks);
        world.setBlock(i + 2, j + 0, k + 3, dungeonBricks);
        world.setBlock(i + 2, j + 0, k + 4, dungeonBricks);
        world.setBlock(i + 2, j + 0, k + 5, dungeonBricks);
        world.setBlock(i + 2, j + 0, k + 6, dungeonBricks);
        world.setBlock(i + 2, j + 0, k + 7, dungeonBricks);
        world.setBlock(i + 2, j + 0, k + 8, dungeonBricks);
        world.setBlock(i + 2, j + 0, k + 9, dungeonBricks);
        world.setBlock(i + 2, j + 0, k + 10, dungeonBricks);
        world.setBlock(i + 2, j + 0, k + 11, dungeonBricks);
        world.setBlock(i + 2, j + 0, k + 12, dungeonBricks);
        world.setBlock(i + 2, j + 0, k + 13, dungeonBricks);
        world.setBlock(i + 2, j + 0, k + 14, dungeonBricks);
        world.setBlock(i + 2, j + 0, k + 15, dungeonBricks);
        world.setBlock(i + 2, j + 1, k + 0, dungeonBricks);
        world.setBlock(i + 2, j + 1, k + 10, ancientbricks);
        world.setBlock(i + 2, j + 1, k + 11, ancientbricks);
        world.setBlock(i + 2, j + 1, k + 15, dungeonBricks);
        world.setBlock(i + 2, j + 2, k + 0, dungeonBricks);
        world.setBlock(i + 2, j + 2, k + 11, ancientbricks);
        world.setBlock(i + 2, j + 2, k + 12, ancientbricks);
        world.setBlock(i + 2, j + 2, k + 15, dungeonBricks);
        world.setBlock(i + 2, j + 3, k + 0, dungeonBricks);
        world.setBlock(i + 2, j + 3, k + 1, ancientbricks);
        world.setBlock(i + 2, j + 3, k + 2, ancientbricks);
        world.setBlock(i + 2, j + 3, k + 3, ancientbricks);
        world.setBlock(i + 2, j + 3, k + 4, ancientbricks);
        world.setBlock(i + 2, j + 3, k + 5, ancientbricks);
        world.setBlock(i + 2, j + 3, k + 6, ancientbricks);
        world.setBlock(i + 2, j + 3, k + 12, ancientbricks);
        world.setBlock(i + 2, j + 3, k + 13, ancientbricks);
        world.setBlock(i + 2, j + 3, k + 14, ancientbricks);
        world.setBlock(i + 2, j + 3, k + 15, dungeonBricks);
        world.setBlock(i + 2, j + 4, k + 0, dungeonBricks);
        world.setBlock(i + 2, j + 4, k + 15, dungeonBricks);
        world.setBlock(i + 2, j + 5, k + 0, dungeonBricks);
        world.setBlock(i + 2, j + 5, k + 15, dungeonBricks);
        world.setBlock(i + 2, j + 6, k + 0, dungeonBricks);
        world.setBlock(i + 2, j + 6, k + 15, dungeonBricks);
        world.setBlock(i + 2, j + 7, k + 0, dungeonBricks);
        world.setBlock(i + 2, j + 7, k + 15, dungeonBricks);
        world.setBlock(i + 3, j + 0, k + 0, dungeonBricks);
        world.setBlock(i + 3, j + 0, k + 1, dungeonBricks);
        world.setBlock(i + 3, j + 0, k + 2, dungeonBricks);
        world.setBlock(i + 3, j + 0, k + 3, dungeonBricks);
        world.setBlock(i + 3, j + 0, k + 4, dungeonBricks);
        world.setBlock(i + 3, j + 0, k + 5, dungeonBricks);
        world.setBlock(i + 3, j + 0, k + 6, dungeonBricks);
        world.setBlock(i + 3, j + 0, k + 7, dungeonBricks);
        world.setBlock(i + 3, j + 0, k + 8, dungeonBricks);
        world.setBlock(i + 3, j + 0, k + 9, dungeonBricks);
        world.setBlock(i + 3, j + 0, k + 10, dungeonBricks);
        world.setBlock(i + 3, j + 0, k + 11, dungeonBricks);
        world.setBlock(i + 3, j + 0, k + 12, dungeonBricks);
        world.setBlock(i + 3, j + 0, k + 13, dungeonBricks);
        world.setBlock(i + 3, j + 0, k + 14, dungeonBricks);
        world.setBlock(i + 3, j + 0, k + 15, dungeonBricks);
        world.setBlock(i + 3, j + 1, k + 0, dungeonBricks);
        world.setBlock(i + 3, j + 1, k + 10, ancientbricks);
        world.setBlock(i + 3, j + 1, k + 11, ancientbricks);
        world.setBlock(i + 3, j + 1, k + 15, dungeonBricks);
        world.setBlock(i + 3, j + 2, k + 0, dungeonBricks);
        world.setBlock(i + 3, j + 2, k + 1, ancientbricks);
        world.setBlock(i + 3, j + 2, k + 2, ancientbricks);
        world.setBlock(i + 3, j + 2, k + 3, ancientbricks);
        world.setBlock(i + 3, j + 2, k + 11, ancientbricks);
        world.setBlock(i + 3, j + 2, k + 12, ancientbricks);
        world.setBlock(i + 3, j + 2, k + 15, dungeonBricks);
        world.setBlock(i + 3, j + 3, k + 0, dungeonBricks);
        world.setBlock(i + 3, j + 3, k + 1, ancientbricks);
        world.setBlock(i + 3, j + 3, k + 2, ancientbricks);
        world.setBlock(i + 3, j + 3, k + 3, ancientbricks);
        world.setBlock(i + 3, j + 3, k + 4, ancientbricks);
        world.setBlock(i + 3, j + 3, k + 5, ancientbricks);
        world.setBlock(i + 3, j + 3, k + 6, ancientbricks);
        world.setBlock(i + 3, j + 3, k + 12, ancientbricks);
        world.setBlock(i + 3, j + 3, k + 13, ancientbricks);
        world.setBlock(i + 3, j + 3, k + 14, ancientbricks);
        world.setBlock(i + 3, j + 3, k + 15, dungeonBricks);
        world.setBlock(i + 3, j + 4, k + 0, dungeonBricks);
        world.setBlock(i + 3, j + 4, k + 15, dungeonBricks);
        world.setBlock(i + 3, j + 5, k + 0, dungeonBricks);
        world.setBlock(i + 3, j + 5, k + 15, dungeonBricks);
        world.setBlock(i + 3, j + 6, k + 0, dungeonBricks);
        world.setBlock(i + 3, j + 6, k + 15, dungeonBricks);
        world.setBlock(i + 3, j + 7, k + 0, dungeonBricks);
        world.setBlock(i + 3, j + 7, k + 15, dungeonBricks);
        world.setBlock(i + 4, j + 0, k + 0, dungeonBricks);
        world.setBlock(i + 4, j + 0, k + 1, dungeonBricks);
        world.setBlock(i + 4, j + 0, k + 2, dungeonBricks);
        world.setBlock(i + 4, j + 0, k + 3, dungeonBricks);
        world.setBlock(i + 4, j + 0, k + 4, dungeonBricks);
        world.setBlock(i + 4, j + 0, k + 5, dungeonBricks);
        world.setBlock(i + 4, j + 0, k + 6, dungeonBricks);
        world.setBlock(i + 4, j + 0, k + 7, dungeonBricks);
        world.setBlock(i + 4, j + 0, k + 8, dungeonBricks);
        world.setBlock(i + 4, j + 0, k + 9, dungeonBricks);
        world.setBlock(i + 4, j + 0, k + 10, dungeonBricks);
        world.setBlock(i + 4, j + 0, k + 11, dungeonBricks);
        world.setBlock(i + 4, j + 0, k + 12, dungeonBricks);
        world.setBlock(i + 4, j + 0, k + 13, dungeonBricks);
        world.setBlock(i + 4, j + 0, k + 14, dungeonBricks);
        world.setBlock(i + 4, j + 0, k + 15, dungeonBricks);
        world.setBlock(i + 4, j + 1, k + 0, dungeonBricks);
        world.setBlock(i + 4, j + 1, k + 1, ancientbricks);
        world.setBlock(i + 4, j + 1, k + 2, ancientbricks);
        world.setBlock(i + 4, j + 1, k + 3, ancientbricks);
        world.setBlock(i + 4, j + 1, k + 4, heatTraps);
        world.setBlock(i + 4, j + 1, k + 5, heatTraps);
        world.setBlock(i + 4, j + 1, k + 6, heatTraps);
        world.setBlock(i + 4, j + 1, k + 7, heatTraps);
        world.setBlock(i + 4, j + 1, k + 8, heatTraps);
        world.setBlock(i + 4, j + 1, k + 9, heatTraps);
        world.setBlock(i + 4, j + 1, k + 10, heatTraps);
        world.setBlock(i + 4, j + 1, k + 11, heatTraps);
        world.setBlock(i + 4, j + 1, k + 15, dungeonBricks);
        world.setBlock(i + 4, j + 2, k + 0, dungeonBricks);
        world.setBlock(i + 4, j + 2, k + 1, ancientbricks);
        world.setBlock(i + 4, j + 2, k + 2, ancientbricks);
        world.setBlock(i + 4, j + 2, k + 3, ancientbricks);
        world.setBlock(i + 4, j + 2, k + 15, dungeonBricks);
        world.setBlock(i + 4, j + 3, k + 0, dungeonBricks);
        world.setBlock(i + 4, j + 3, k + 12, ancientbricks);
        world.setBlock(i + 4, j + 3, k + 13, ancientbricks);
        world.setBlock(i + 4, j + 3, k + 14, ancientbricks);
        world.setBlock(i + 4, j + 3, k + 15, dungeonBricks);
        world.setBlock(i + 4, j + 4, k + 0, dungeonBricks);
        world.setBlock(i + 4, j + 4, k + 15, dungeonBricks);
        world.setBlock(i + 4, j + 5, k + 0, dungeonBricks);
        world.setBlock(i + 4, j + 5, k + 15, dungeonBricks);
        world.setBlock(i + 4, j + 6, k + 0, dungeonBricks);
        world.setBlock(i + 4, j + 6, k + 15, dungeonBricks);
        world.setBlock(i + 4, j + 7, k + 0, dungeonBricks);
        world.setBlock(i + 4, j + 7, k + 4, heatTraps);
        world.setBlock(i + 4, j + 7, k + 5, heatTraps);
        world.setBlock(i + 4, j + 7, k + 6, heatTraps);
        world.setBlock(i + 4, j + 7, k + 7, heatTraps);
        world.setBlock(i + 4, j + 7, k + 8, heatTraps);
        world.setBlock(i + 4, j + 7, k + 9, heatTraps);
        world.setBlock(i + 4, j + 7, k + 10, heatTraps);
        world.setBlock(i + 4, j + 7, k + 11, heatTraps);
        world.setBlock(i + 4, j + 7, k + 15, dungeonBricks);
        world.setBlock(i + 5, j + 0, k + 0, dungeonBricks);
        world.setBlock(i + 5, j + 0, k + 1, dungeonBricks);
        world.setBlock(i + 5, j + 0, k + 2, dungeonBricks);
        world.setBlock(i + 5, j + 0, k + 3, dungeonBricks);
        world.setBlock(i + 5, j + 0, k + 4, dungeonBricks);
        world.setBlock(i + 5, j + 0, k + 5, dungeonBricks);
        world.setBlock(i + 5, j + 0, k + 6, dungeonBricks);
        world.setBlock(i + 5, j + 0, k + 7, dungeonBricks);
        world.setBlock(i + 5, j + 0, k + 8, dungeonBricks);
        world.setBlock(i + 5, j + 0, k + 9, dungeonBricks);
        world.setBlock(i + 5, j + 0, k + 10, dungeonBricks);
        world.setBlock(i + 5, j + 0, k + 11, dungeonBricks);
        world.setBlock(i + 5, j + 0, k + 12, dungeonBricks);
        world.setBlock(i + 5, j + 0, k + 13, dungeonBricks);
        world.setBlock(i + 5, j + 0, k + 14, dungeonBricks);
        world.setBlock(i + 5, j + 0, k + 15, dungeonBricks);
        world.setBlock(i + 5, j + 1, k + 0, dungeonBricks);
        world.setBlock(i + 5, j + 1, k + 1, ancientbricks);
        world.setBlock(i + 5, j + 1, k + 2, ancientbricks);
        world.setBlock(i + 5, j + 1, k + 3, ancientbricks);
        world.setBlock(i + 5, j + 1, k + 4, heatTraps);
        world.setBlock(i + 5, j + 1, k + 5, heatTraps);
        world.setBlock(i + 5, j + 1, k + 6, heatTraps);
        world.setBlock(i + 5, j + 1, k + 7, heatTraps);
        world.setBlock(i + 5, j + 1, k + 8, heatTraps);
        world.setBlock(i + 5, j + 1, k + 9, heatTraps);
        world.setBlock(i + 5, j + 1, k + 10, heatTraps);
        world.setBlock(i + 5, j + 1, k + 11, heatTraps);
        world.setBlock(i + 5, j + 1, k + 15, dungeonBricks);
        world.setBlock(i + 5, j + 2, k + 0, dungeonBricks);
        world.setBlock(i + 5, j + 2, k + 5, heatTraps);
        world.setBlock(i + 5, j + 2, k + 6, heatTraps);
        world.setBlock(i + 5, j + 2, k + 7, heatTraps);
        world.setBlock(i + 5, j + 2, k + 8, heatTraps);
        world.setBlock(i + 5, j + 2, k + 9, heatTraps);
        world.setBlock(i + 5, j + 2, k + 10, heatTraps);
        world.setBlock(i + 5, j + 2, k + 15, dungeonBricks);
        world.setBlock(i + 5, j + 3, k + 0, dungeonBricks);
        world.setBlock(i + 5, j + 3, k + 12, ancientbricks);
        world.setBlock(i + 5, j + 3, k + 13, ancientbricks);
        world.setBlock(i + 5, j + 3, k + 14, ancientbricks);
        world.setBlock(i + 5, j + 3, k + 15, dungeonBricks);
        world.setBlock(i + 5, j + 4, k + 0, dungeonBricks);
        world.setBlock(i + 5, j + 4, k + 15, dungeonBricks);
        world.setBlock(i + 5, j + 5, k + 0, dungeonBricks);
        world.setBlock(i + 5, j + 5, k + 15, dungeonBricks);
        world.setBlock(i + 5, j + 6, k + 0, dungeonBricks);
        world.setBlock(i + 5, j + 6, k + 5, heatTraps);
        world.setBlock(i + 5, j + 6, k + 6, heatTraps);
        world.setBlock(i + 5, j + 6, k + 7, heatTraps);
        world.setBlock(i + 5, j + 6, k + 8, heatTraps);
        world.setBlock(i + 5, j + 6, k + 9, heatTraps);
        world.setBlock(i + 5, j + 6, k + 10, heatTraps);
        world.setBlock(i + 5, j + 6, k + 15, dungeonBricks);
        world.setBlock(i + 5, j + 7, k + 0, dungeonBricks);
        world.setBlock(i + 5, j + 7, k + 4, heatTraps);
        world.setBlock(i + 5, j + 7, k + 5, heatTraps);
        world.setBlock(i + 5, j + 7, k + 6, heatTraps);
        world.setBlock(i + 5, j + 7, k + 7, heatTraps);
        world.setBlock(i + 5, j + 7, k + 8, heatTraps);
        world.setBlock(i + 5, j + 7, k + 9, heatTraps);
        world.setBlock(i + 5, j + 7, k + 10, heatTraps);
        world.setBlock(i + 5, j + 7, k + 11, heatTraps);
        world.setBlock(i + 5, j + 7, k + 15, dungeonBricks);
        world.setBlock(i + 6, j + 0, k + 0, dungeonBricks);
        world.setBlock(i + 6, j + 0, k + 1, dungeonBricks);
        world.setBlock(i + 6, j + 0, k + 2, dungeonBricks);
        world.setBlock(i + 6, j + 0, k + 3, dungeonBricks);
        world.setBlock(i + 6, j + 0, k + 4, dungeonBricks);
        world.setBlock(i + 6, j + 0, k + 5, dungeonBricks);
        world.setBlock(i + 6, j + 0, k + 6, dungeonBricks);
        world.setBlock(i + 6, j + 0, k + 7, dungeonBricks);
        world.setBlock(i + 6, j + 0, k + 8, dungeonBricks);
        world.setBlock(i + 6, j + 0, k + 9, dungeonBricks);
        world.setBlock(i + 6, j + 0, k + 10, dungeonBricks);
        world.setBlock(i + 6, j + 0, k + 11, dungeonBricks);
        world.setBlock(i + 6, j + 0, k + 12, dungeonBricks);
        world.setBlock(i + 6, j + 0, k + 13, dungeonBricks);
        world.setBlock(i + 6, j + 0, k + 14, dungeonBricks);
        world.setBlock(i + 6, j + 0, k + 15, dungeonBricks);
        world.setBlock(i + 6, j + 1, k + 0, arcaniteMetal);
        world.setBlock(i + 6, j + 1, k + 4, heatTraps);
        world.setBlock(i + 6, j + 1, k + 5, heatTraps);
        world.setBlock(i + 6, j + 1, k + 6, heatTraps);
        world.setBlock(i + 6, j + 1, k + 7, heatTraps);
        world.setBlock(i + 6, j + 1, k + 8, heatTraps);
        world.setBlock(i + 6, j + 1, k + 9, heatTraps);
        world.setBlock(i + 6, j + 1, k + 10, heatTraps);
        world.setBlock(i + 6, j + 1, k + 11, heatTraps);
        world.setBlock(i + 6, j + 1, k + 14, heatTraps);
        world.setBlock(i + 6, j + 1, k + 15, arcaniteMetal);
        world.setBlock(i + 6, j + 2, k + 0, arcaniteMetal);
        world.setBlock(i + 6, j + 2, k + 5, heatTraps);
        world.setBlock(i + 6, j + 2, k + 6, heatTraps);
        world.setBlock(i + 6, j + 2, k + 7, heatTraps);
        world.setBlock(i + 6, j + 2, k + 8, heatTraps);
        world.setBlock(i + 6, j + 2, k + 9, heatTraps);
        world.setBlock(i + 6, j + 2, k + 10, heatTraps);
        world.setBlock(i + 6, j + 2, k + 15, arcaniteMetal);
        world.setBlock(i + 6, j + 3, k + 0, arcaniteMetal);
        world.setBlock(i + 6, j + 3, k + 6, heatTraps);
        world.setBlock(i + 6, j + 3, k + 7, heatTraps);
        world.setBlock(i + 6, j + 3, k + 8, heatTraps);
        world.setBlock(i + 6, j + 3, k + 9, heatTraps);
        world.setBlock(i + 6, j + 3, k + 12, ancientbricks);
        world.setBlock(i + 6, j + 3, k + 13, ancientbricks);
        world.setBlock(i + 6, j + 3, k + 14, ancientbricks);
        world.setBlock(i + 6, j + 3, k + 15, arcaniteMetal);
        world.setBlock(i + 6, j + 4, k + 0, dungeonBricks);
        world.setBlock(i + 6, j + 4, k + 15, dungeonBricks);
        world.setBlock(i + 6, j + 5, k + 0, dungeonBricks);
        world.setBlock(i + 6, j + 5, k + 6, heatTraps);
        world.setBlock(i + 6, j + 5, k + 7, heatTraps);
        world.setBlock(i + 6, j + 5, k + 8, heatTraps);
        world.setBlock(i + 6, j + 5, k + 9, heatTraps);
        world.setBlock(i + 6, j + 5, k + 15, dungeonBricks);
        world.setBlock(i + 6, j + 6, k + 0, dungeonBricks);
        world.setBlock(i + 6, j + 6, k + 5, heatTraps);
        world.setBlock(i + 6, j + 6, k + 6, heatTraps);
        world.setBlock(i + 6, j + 6, k + 7, heatTraps);
        world.setBlock(i + 6, j + 6, k + 8, heatTraps);
        world.setBlock(i + 6, j + 6, k + 9, heatTraps);
        world.setBlock(i + 6, j + 6, k + 10, heatTraps);
        world.setBlock(i + 6, j + 6, k + 15, dungeonBricks);
        world.setBlock(i + 6, j + 7, k + 0, dungeonBricks);
        world.setBlock(i + 6, j + 7, k + 4, heatTraps);
        world.setBlock(i + 6, j + 7, k + 5, heatTraps);
        world.setBlock(i + 6, j + 7, k + 6, heatTraps);
        world.setBlock(i + 6, j + 7, k + 7, heatTraps);
        world.setBlock(i + 6, j + 7, k + 8, heatTraps);
        world.setBlock(i + 6, j + 7, k + 9, heatTraps);
        world.setBlock(i + 6, j + 7, k + 10, heatTraps);
        world.setBlock(i + 6, j + 7, k + 11, heatTraps);
        world.setBlock(i + 6, j + 7, k + 15, dungeonBricks);
        world.setBlock(i + 7, j + 0, k + 0, dungeonBricks);
        world.setBlock(i + 7, j + 0, k + 1, dungeonBricks);
        world.setBlock(i + 7, j + 0, k + 2, dungeonBricks);
        world.setBlock(i + 7, j + 0, k + 3, dungeonBricks);
        world.setBlock(i + 7, j + 0, k + 4, dungeonBricks);
        world.setBlock(i + 7, j + 0, k + 5, dungeonBricks);
        world.setBlock(i + 7, j + 0, k + 6, dungeonBricks);
        world.setBlock(i + 7, j + 0, k + 7, dungeonBricks);
        world.setBlock(i + 7, j + 0, k + 8, dungeonBricks);
        world.setBlock(i + 7, j + 0, k + 9, dungeonBricks);
        world.setBlock(i + 7, j + 0, k + 10, dungeonBricks);
        world.setBlock(i + 7, j + 0, k + 11, dungeonBricks);
        world.setBlock(i + 7, j + 0, k + 12, dungeonBricks);
        world.setBlock(i + 7, j + 0, k + 13, dungeonBricks);
        world.setBlock(i + 7, j + 0, k + 14, dungeonBricks);
        world.setBlock(i + 7, j + 0, k + 15, dungeonBricks);
        world.setBlock(i + 7, j + 1, k + 4, heatTraps);
        world.setBlock(i + 7, j + 1, k + 5, heatTraps);
        world.setBlock(i + 7, j + 1, k + 6, heatTraps);
        world.setBlock(i + 7, j + 1, k + 7, heatTraps);
        world.setBlock(i + 7, j + 1, k + 8, heatTraps);
        world.setBlock(i + 7, j + 1, k + 9, heatTraps);
        world.setBlock(i + 7, j + 1, k + 10, heatTraps);
        world.setBlock(i + 7, j + 1, k + 11, heatTraps);
        world.setBlock(i + 7, j + 2, k + 5, heatTraps);
        world.setBlock(i + 7, j + 2, k + 6, heatTraps);
        world.setBlock(i + 7, j + 2, k + 7, heatTraps);
        world.setBlock(i + 7, j + 2, k + 8, heatTraps);
        world.setBlock(i + 7, j + 2, k + 9, heatTraps);
        world.setBlock(i + 7, j + 2, k + 10, heatTraps);
        world.setBlock(i + 7, j + 3, k + 0, arcanaPower);
        world.setBlock(i + 7, j + 3, k + 6, heatTraps);
        world.setBlock(i + 7, j + 3, k + 7, heatTraps);
        world.setBlock(i + 7, j + 3, k + 8, heatTraps);
        world.setBlock(i + 7, j + 3, k + 9, heatTraps);
        world.setBlock(i + 7, j + 3, k + 15, arcanaPower);
        world.setBlock(i + 7, j + 4, k + 0, dungeonBricks);
        world.setBlock(i + 7, j + 4, k + 7, heatTraps);
        world.setBlock(i + 7, j + 4, k + 8, heatTraps);
        world.setBlock(i + 7, j + 4, k + 15, dungeonBricks);
        world.setBlock(i + 7, j + 5, k + 0, dungeonBricks);
        world.setBlock(i + 7, j + 5, k + 6, heatTraps);
        world.setBlock(i + 7, j + 5, k + 7, heatTraps);
        world.setBlock(i + 7, j + 5, k + 8, heatTraps);
        world.setBlock(i + 7, j + 5, k + 9, heatTraps);
        world.setBlock(i + 7, j + 5, k + 15, dungeonBricks);
        world.setBlock(i + 7, j + 6, k + 0, dungeonBricks);
        world.setBlock(i + 7, j + 6, k + 5, heatTraps);
        world.setBlock(i + 7, j + 6, k + 6, heatTraps);
        world.setBlock(i + 7, j + 6, k + 7, heatTraps);
        world.setBlock(i + 7, j + 6, k + 8, heatTraps);
        world.setBlock(i + 7, j + 6, k + 9, heatTraps);
        world.setBlock(i + 7, j + 6, k + 10, heatTraps);
        world.setBlock(i + 7, j + 6, k + 15, dungeonBricks);
        world.setBlock(i + 7, j + 7, k + 0, dungeonBricks);
        world.setBlock(i + 7, j + 7, k + 4, heatTraps);
        world.setBlock(i + 7, j + 7, k + 5, heatTraps);
        world.setBlock(i + 7, j + 7, k + 6, heatTraps);
        world.setBlock(i + 7, j + 7, k + 7, heatTraps);
        world.setBlock(i + 7, j + 7, k + 8, heatTraps);
        world.setBlock(i + 7, j + 7, k + 9, heatTraps);
        world.setBlock(i + 7, j + 7, k + 10, heatTraps);
        world.setBlock(i + 7, j + 7, k + 11, heatTraps);
        world.setBlock(i + 7, j + 7, k + 15, dungeonBricks);
        world.setBlock(i + 8, j + 0, k + 0, dungeonBricks);
        world.setBlock(i + 8, j + 0, k + 1, dungeonBricks);
        world.setBlock(i + 8, j + 0, k + 2, dungeonBricks);
        world.setBlock(i + 8, j + 0, k + 3, dungeonBricks);
        world.setBlock(i + 8, j + 0, k + 4, dungeonBricks);
        world.setBlock(i + 8, j + 0, k + 5, dungeonBricks);
        world.setBlock(i + 8, j + 0, k + 6, dungeonBricks);
        world.setBlock(i + 8, j + 0, k + 7, dungeonBricks);
        world.setBlock(i + 8, j + 0, k + 8, dungeonBricks);
        world.setBlock(i + 8, j + 0, k + 9, dungeonBricks);
        world.setBlock(i + 8, j + 0, k + 10, dungeonBricks);
        world.setBlock(i + 8, j + 0, k + 11, dungeonBricks);
        world.setBlock(i + 8, j + 0, k + 12, dungeonBricks);
        world.setBlock(i + 8, j + 0, k + 13, dungeonBricks);
        world.setBlock(i + 8, j + 0, k + 14, dungeonBricks);
        world.setBlock(i + 8, j + 0, k + 15, dungeonBricks);
        world.setBlock(i + 8, j + 1, k + 4, heatTraps);
        world.setBlock(i + 8, j + 1, k + 5, heatTraps);
        world.setBlock(i + 8, j + 1, k + 6, heatTraps);
        world.setBlock(i + 8, j + 1, k + 7, heatTraps);
        world.setBlock(i + 8, j + 1, k + 8, heatTraps);
        world.setBlock(i + 8, j + 1, k + 9, heatTraps);
        world.setBlock(i + 8, j + 1, k + 10, heatTraps);
        world.setBlock(i + 8, j + 1, k + 11, heatTraps);
        world.setBlock(i + 8, j + 2, k + 5, heatTraps);
        world.setBlock(i + 8, j + 2, k + 6, heatTraps);
        world.setBlock(i + 8, j + 2, k + 7, heatTraps);
        world.setBlock(i + 8, j + 2, k + 8, heatTraps);
        world.setBlock(i + 8, j + 2, k + 9, heatTraps);
        world.setBlock(i + 8, j + 2, k + 10, heatTraps);
        world.setBlock(i + 8, j + 3, k + 0, arcanaPower);
        world.setBlock(i + 8, j + 3, k + 6, heatTraps);
        world.setBlock(i + 8, j + 3, k + 7, heatTraps);
        world.setBlock(i + 8, j + 3, k + 8, heatTraps);
        world.setBlock(i + 8, j + 3, k + 9, heatTraps);
        world.setBlock(i + 8, j + 3, k + 15, arcanaPower);
        world.setBlock(i + 8, j + 4, k + 0, dungeonBricks);
        world.setBlock(i + 8, j + 4, k + 7, heatTraps);
        world.setBlock(i + 8, j + 4, k + 8, heatTraps);
        world.setBlock(i + 8, j + 4, k + 15, dungeonBricks);
        world.setBlock(i + 8, j + 5, k + 0, dungeonBricks);
        world.setBlock(i + 8, j + 5, k + 6, heatTraps);
        world.setBlock(i + 8, j + 5, k + 7, heatTraps);
        world.setBlock(i + 8, j + 5, k + 8, heatTraps);
        world.setBlock(i + 8, j + 5, k + 9, heatTraps);
        world.setBlock(i + 8, j + 5, k + 15, dungeonBricks);
        world.setBlock(i + 8, j + 6, k + 0, dungeonBricks);
        world.setBlock(i + 8, j + 6, k + 5, heatTraps);
        world.setBlock(i + 8, j + 6, k + 6, heatTraps);
        world.setBlock(i + 8, j + 6, k + 7, heatTraps);
        world.setBlock(i + 8, j + 6, k + 8, heatTraps);
        world.setBlock(i + 8, j + 6, k + 9, heatTraps);
        world.setBlock(i + 8, j + 6, k + 10, heatTraps);
        world.setBlock(i + 8, j + 6, k + 15, dungeonBricks);
        world.setBlock(i + 8, j + 7, k + 0, dungeonBricks);
        world.setBlock(i + 8, j + 7, k + 4, heatTraps);
        world.setBlock(i + 8, j + 7, k + 5, heatTraps);
        world.setBlock(i + 8, j + 7, k + 6, heatTraps);
        world.setBlock(i + 8, j + 7, k + 7, heatTraps);
        world.setBlock(i + 8, j + 7, k + 8, heatTraps);
        world.setBlock(i + 8, j + 7, k + 9, heatTraps);
        world.setBlock(i + 8, j + 7, k + 10, heatTraps);
        world.setBlock(i + 8, j + 7, k + 11, heatTraps);
        world.setBlock(i + 8, j + 7, k + 15, dungeonBricks);
        world.setBlock(i + 9, j + 0, k + 0, dungeonBricks);
        world.setBlock(i + 9, j + 0, k + 1, dungeonBricks);
        world.setBlock(i + 9, j + 0, k + 2, dungeonBricks);
        world.setBlock(i + 9, j + 0, k + 3, dungeonBricks);
        world.setBlock(i + 9, j + 0, k + 4, dungeonBricks);
        world.setBlock(i + 9, j + 0, k + 5, dungeonBricks);
        world.setBlock(i + 9, j + 0, k + 6, dungeonBricks);
        world.setBlock(i + 9, j + 0, k + 7, dungeonBricks);
        world.setBlock(i + 9, j + 0, k + 8, dungeonBricks);
        world.setBlock(i + 9, j + 0, k + 9, dungeonBricks);
        world.setBlock(i + 9, j + 0, k + 10, dungeonBricks);
        world.setBlock(i + 9, j + 0, k + 11, dungeonBricks);
        world.setBlock(i + 9, j + 0, k + 12, dungeonBricks);
        world.setBlock(i + 9, j + 0, k + 13, dungeonBricks);
        world.setBlock(i + 9, j + 0, k + 14, dungeonBricks);
        world.setBlock(i + 9, j + 0, k + 15, dungeonBricks);
        world.setBlock(i + 9, j + 1, k + 0, arcaniteMetal);
        world.setBlock(i + 9, j + 1, k + 1, heatTraps);
        world.setBlock(i + 9, j + 1, k + 4, heatTraps);
        world.setBlock(i + 9, j + 1, k + 5, heatTraps);
        world.setBlock(i + 9, j + 1, k + 6, heatTraps);
        world.setBlock(i + 9, j + 1, k + 7, heatTraps);
        world.setBlock(i + 9, j + 1, k + 8, heatTraps);
        world.setBlock(i + 9, j + 1, k + 9, heatTraps);
        world.setBlock(i + 9, j + 1, k + 10, heatTraps);
        world.setBlock(i + 9, j + 1, k + 11, heatTraps);
        world.setBlock(i + 9, j + 1, k + 14, heatTraps);
        world.setBlock(i + 9, j + 1, k + 15, arcaniteMetal);
        world.setBlock(i + 9, j + 2, k + 0, arcaniteMetal);
        world.setBlock(i + 9, j + 2, k + 5, heatTraps);
        world.setBlock(i + 9, j + 2, k + 6, heatTraps);
        world.setBlock(i + 9, j + 2, k + 7, heatTraps);
        world.setBlock(i + 9, j + 2, k + 8, heatTraps);
        world.setBlock(i + 9, j + 2, k + 9, heatTraps);
        world.setBlock(i + 9, j + 2, k + 10, heatTraps);
        world.setBlock(i + 9, j + 2, k + 15, arcaniteMetal);
        world.setBlock(i + 9, j + 3, k + 0, arcaniteMetal);
        world.setBlock(i + 9, j + 3, k + 1, ancientbricks);
        world.setBlock(i + 9, j + 3, k + 2, ancientbricks);
        world.setBlock(i + 9, j + 3, k + 3, ancientbricks);
        world.setBlock(i + 9, j + 3, k + 6, heatTraps);
        world.setBlock(i + 9, j + 3, k + 7, heatTraps);
        world.setBlock(i + 9, j + 3, k + 8, heatTraps);
        world.setBlock(i + 9, j + 3, k + 9, heatTraps);
        world.setBlock(i + 9, j + 3, k + 15, arcaniteMetal);
        world.setBlock(i + 9, j + 4, k + 0, dungeonBricks);
        world.setBlock(i + 9, j + 4, k + 15, dungeonBricks);
        world.setBlock(i + 9, j + 5, k + 0, dungeonBricks);
        world.setBlock(i + 9, j + 5, k + 6, heatTraps);
        world.setBlock(i + 9, j + 5, k + 7, heatTraps);
        world.setBlock(i + 9, j + 5, k + 8, heatTraps);
        world.setBlock(i + 9, j + 5, k + 9, heatTraps);
        world.setBlock(i + 9, j + 5, k + 15, dungeonBricks);
        world.setBlock(i + 9, j + 6, k + 0, dungeonBricks);
        world.setBlock(i + 9, j + 6, k + 5, heatTraps);
        world.setBlock(i + 9, j + 6, k + 6, heatTraps);
        world.setBlock(i + 9, j + 6, k + 7, heatTraps);
        world.setBlock(i + 9, j + 6, k + 8, heatTraps);
        world.setBlock(i + 9, j + 6, k + 9, heatTraps);
        world.setBlock(i + 9, j + 6, k + 10, heatTraps);
        world.setBlock(i + 9, j + 6, k + 15, dungeonBricks);
        world.setBlock(i + 9, j + 7, k + 0, dungeonBricks);
        world.setBlock(i + 9, j + 7, k + 4, heatTraps);
        world.setBlock(i + 9, j + 7, k + 5, heatTraps);
        world.setBlock(i + 9, j + 7, k + 6, heatTraps);
        world.setBlock(i + 9, j + 7, k + 7, heatTraps);
        world.setBlock(i + 9, j + 7, k + 8, heatTraps);
        world.setBlock(i + 9, j + 7, k + 9, heatTraps);
        world.setBlock(i + 9, j + 7, k + 10, heatTraps);
        world.setBlock(i + 9, j + 7, k + 11, heatTraps);
        world.setBlock(i + 9, j + 7, k + 15, dungeonBricks);
        world.setBlock(i + 10, j + 0, k + 0, dungeonBricks);
        world.setBlock(i + 10, j + 0, k + 1, dungeonBricks);
        world.setBlock(i + 10, j + 0, k + 2, dungeonBricks);
        world.setBlock(i + 10, j + 0, k + 3, dungeonBricks);
        world.setBlock(i + 10, j + 0, k + 4, dungeonBricks);
        world.setBlock(i + 10, j + 0, k + 5, dungeonBricks);
        world.setBlock(i + 10, j + 0, k + 6, dungeonBricks);
        world.setBlock(i + 10, j + 0, k + 7, dungeonBricks);
        world.setBlock(i + 10, j + 0, k + 8, dungeonBricks);
        world.setBlock(i + 10, j + 0, k + 9, dungeonBricks);
        world.setBlock(i + 10, j + 0, k + 10, dungeonBricks);
        world.setBlock(i + 10, j + 0, k + 11, dungeonBricks);
        world.setBlock(i + 10, j + 0, k + 12, dungeonBricks);
        world.setBlock(i + 10, j + 0, k + 13, dungeonBricks);
        world.setBlock(i + 10, j + 0, k + 14, dungeonBricks);
        world.setBlock(i + 10, j + 0, k + 15, dungeonBricks);
        world.setBlock(i + 10, j + 1, k + 0, dungeonBricks);
        world.setBlock(i + 10, j + 1, k + 4, heatTraps);
        world.setBlock(i + 10, j + 1, k + 5, heatTraps);
        world.setBlock(i + 10, j + 1, k + 6, heatTraps);
        world.setBlock(i + 10, j + 1, k + 7, heatTraps);
        world.setBlock(i + 10, j + 1, k + 8, heatTraps);
        world.setBlock(i + 10, j + 1, k + 9, heatTraps);
        world.setBlock(i + 10, j + 1, k + 10, heatTraps);
        world.setBlock(i + 10, j + 1, k + 11, heatTraps);
        world.setBlock(i + 10, j + 1, k + 12, ancientbricks);
        world.setBlock(i + 10, j + 1, k + 13, ancientbricks);
        world.setBlock(i + 10, j + 1, k + 14, ancientbricks);
        world.setBlock(i + 10, j + 1, k + 15, dungeonBricks);
        world.setBlock(i + 10, j + 2, k + 0, dungeonBricks);
        world.setBlock(i + 10, j + 2, k + 5, heatTraps);
        world.setBlock(i + 10, j + 2, k + 6, heatTraps);
        world.setBlock(i + 10, j + 2, k + 7, heatTraps);
        world.setBlock(i + 10, j + 2, k + 8, heatTraps);
        world.setBlock(i + 10, j + 2, k + 9, heatTraps);
        world.setBlock(i + 10, j + 2, k + 10, heatTraps);
        world.setBlock(i + 10, j + 2, k + 15, dungeonBricks);
        world.setBlock(i + 10, j + 3, k + 0, dungeonBricks);
        world.setBlock(i + 10, j + 3, k + 1, ancientbricks);
        world.setBlock(i + 10, j + 3, k + 2, ancientbricks);
        world.setBlock(i + 10, j + 3, k + 3, ancientbricks);
        world.setBlock(i + 10, j + 3, k + 15, dungeonBricks);
        world.setBlock(i + 10, j + 4, k + 0, dungeonBricks);
        world.setBlock(i + 10, j + 4, k + 15, dungeonBricks);
        world.setBlock(i + 10, j + 5, k + 0, dungeonBricks);
        world.setBlock(i + 10, j + 5, k + 15, dungeonBricks);
        world.setBlock(i + 10, j + 6, k + 0, dungeonBricks);
        world.setBlock(i + 10, j + 6, k + 5, heatTraps);
        world.setBlock(i + 10, j + 6, k + 6, heatTraps);
        world.setBlock(i + 10, j + 6, k + 7, heatTraps);
        world.setBlock(i + 10, j + 6, k + 8, heatTraps);
        world.setBlock(i + 10, j + 6, k + 9, heatTraps);
        world.setBlock(i + 10, j + 6, k + 10, heatTraps);
        world.setBlock(i + 10, j + 6, k + 15, dungeonBricks);
        world.setBlock(i + 10, j + 7, k + 0, dungeonBricks);
        world.setBlock(i + 10, j + 7, k + 4, heatTraps);
        world.setBlock(i + 10, j + 7, k + 5, heatTraps);
        world.setBlock(i + 10, j + 7, k + 6, heatTraps);
        world.setBlock(i + 10, j + 7, k + 7, heatTraps);
        world.setBlock(i + 10, j + 7, k + 8, heatTraps);
        world.setBlock(i + 10, j + 7, k + 9, heatTraps);
        world.setBlock(i + 10, j + 7, k + 10, heatTraps);
        world.setBlock(i + 10, j + 7, k + 11, heatTraps);
        world.setBlock(i + 10, j + 7, k + 15, dungeonBricks);
        world.setBlock(i + 11, j + 0, k + 0, dungeonBricks);
        world.setBlock(i + 11, j + 0, k + 1, dungeonBricks);
        world.setBlock(i + 11, j + 0, k + 2, dungeonBricks);
        world.setBlock(i + 11, j + 0, k + 3, dungeonBricks);
        world.setBlock(i + 11, j + 0, k + 4, dungeonBricks);
        world.setBlock(i + 11, j + 0, k + 5, dungeonBricks);
        world.setBlock(i + 11, j + 0, k + 6, dungeonBricks);
        world.setBlock(i + 11, j + 0, k + 7, dungeonBricks);
        world.setBlock(i + 11, j + 0, k + 8, dungeonBricks);
        world.setBlock(i + 11, j + 0, k + 9, dungeonBricks);
        world.setBlock(i + 11, j + 0, k + 10, dungeonBricks);
        world.setBlock(i + 11, j + 0, k + 11, dungeonBricks);
        world.setBlock(i + 11, j + 0, k + 12, dungeonBricks);
        world.setBlock(i + 11, j + 0, k + 13, dungeonBricks);
        world.setBlock(i + 11, j + 0, k + 14, dungeonBricks);
        world.setBlock(i + 11, j + 0, k + 15, dungeonBricks);
        world.setBlock(i + 11, j + 1, k + 0, dungeonBricks);
        world.setBlock(i + 11, j + 1, k + 4, heatTraps);
        world.setBlock(i + 11, j + 1, k + 5, heatTraps);
        world.setBlock(i + 11, j + 1, k + 6, heatTraps);
        world.setBlock(i + 11, j + 1, k + 7, heatTraps);
        world.setBlock(i + 11, j + 1, k + 8, heatTraps);
        world.setBlock(i + 11, j + 1, k + 9, heatTraps);
        world.setBlock(i + 11, j + 1, k + 10, heatTraps);
        world.setBlock(i + 11, j + 1, k + 11, heatTraps);
        world.setBlock(i + 11, j + 1, k + 12, ancientbricks);
        world.setBlock(i + 11, j + 1, k + 13, ancientbricks);
        world.setBlock(i + 11, j + 1, k + 14, ancientbricks);
        world.setBlock(i + 11, j + 1, k + 15, dungeonBricks);
        world.setBlock(i + 11, j + 2, k + 0, dungeonBricks);
        world.setBlock(i + 11, j + 2, k + 12, ancientbricks);
        world.setBlock(i + 11, j + 2, k + 13, ancientbricks);
        world.setBlock(i + 11, j + 2, k + 14, ancientbricks);
        world.setBlock(i + 11, j + 2, k + 15, dungeonBricks);
        world.setBlock(i + 11, j + 3, k + 0, dungeonBricks);
        world.setBlock(i + 11, j + 3, k + 1, ancientbricks);
        world.setBlock(i + 11, j + 3, k + 2, ancientbricks);
        world.setBlock(i + 11, j + 3, k + 3, ancientbricks);
        world.setBlock(i + 11, j + 3, k + 15, dungeonBricks);
        world.setBlock(i + 11, j + 4, k + 0, dungeonBricks);
        world.setBlock(i + 11, j + 4, k + 15, dungeonBricks);
        world.setBlock(i + 11, j + 5, k + 0, dungeonBricks);
        world.setBlock(i + 11, j + 5, k + 15, dungeonBricks);
        world.setBlock(i + 11, j + 6, k + 0, dungeonBricks);
        world.setBlock(i + 11, j + 6, k + 15, dungeonBricks);
        world.setBlock(i + 11, j + 7, k + 0, dungeonBricks);
        world.setBlock(i + 11, j + 7, k + 4, heatTraps);
        world.setBlock(i + 11, j + 7, k + 5, heatTraps);
        world.setBlock(i + 11, j + 7, k + 6, heatTraps);
        world.setBlock(i + 11, j + 7, k + 7, heatTraps);
        world.setBlock(i + 11, j + 7, k + 8, heatTraps);
        world.setBlock(i + 11, j + 7, k + 9, heatTraps);
        world.setBlock(i + 11, j + 7, k + 10, heatTraps);
        world.setBlock(i + 11, j + 7, k + 11, heatTraps);
        world.setBlock(i + 11, j + 7, k + 15, dungeonBricks);
        world.setBlock(i + 12, j + 0, k + 0, dungeonBricks);
        world.setBlock(i + 12, j + 0, k + 1, dungeonBricks);
        world.setBlock(i + 12, j + 0, k + 2, dungeonBricks);
        world.setBlock(i + 12, j + 0, k + 3, dungeonBricks);
        world.setBlock(i + 12, j + 0, k + 4, dungeonBricks);
        world.setBlock(i + 12, j + 0, k + 5, dungeonBricks);
        world.setBlock(i + 12, j + 0, k + 6, dungeonBricks);
        world.setBlock(i + 12, j + 0, k + 7, dungeonBricks);
        world.setBlock(i + 12, j + 0, k + 8, dungeonBricks);
        world.setBlock(i + 12, j + 0, k + 9, dungeonBricks);
        world.setBlock(i + 12, j + 0, k + 10, dungeonBricks);
        world.setBlock(i + 12, j + 0, k + 11, dungeonBricks);
        world.setBlock(i + 12, j + 0, k + 12, dungeonBricks);
        world.setBlock(i + 12, j + 0, k + 13, dungeonBricks);
        world.setBlock(i + 12, j + 0, k + 14, dungeonBricks);
        world.setBlock(i + 12, j + 0, k + 15, dungeonBricks);
        world.setBlock(i + 12, j + 1, k + 0, dungeonBricks);
        world.setBlock(i + 12, j + 1, k + 4, ancientbricks);
        world.setBlock(i + 12, j + 1, k + 5, ancientbricks);
        world.setBlock(i + 12, j + 1, k + 15, dungeonBricks);
        world.setBlock(i + 12, j + 2, k + 0, dungeonBricks);
        world.setBlock(i + 12, j + 2, k + 3, ancientbricks);
        world.setBlock(i + 12, j + 2, k + 4, ancientbricks);
        world.setBlock(i + 12, j + 2, k + 12, ancientbricks);
        world.setBlock(i + 12, j + 2, k + 13, ancientbricks);
        world.setBlock(i + 12, j + 2, k + 14, ancientbricks);
        world.setBlock(i + 12, j + 2, k + 15, dungeonBricks);
        world.setBlock(i + 12, j + 3, k + 0, dungeonBricks);
        world.setBlock(i + 12, j + 3, k + 1, ancientbricks);
        world.setBlock(i + 12, j + 3, k + 2, ancientbricks);
        world.setBlock(i + 12, j + 3, k + 3, ancientbricks);
        world.setBlock(i + 12, j + 3, k + 9, ancientbricks);
        world.setBlock(i + 12, j + 3, k + 10, ancientbricks);
        world.setBlock(i + 12, j + 3, k + 11, ancientbricks);
        world.setBlock(i + 12, j + 3, k + 12, ancientbricks);
        world.setBlock(i + 12, j + 3, k + 13, ancientbricks);
        world.setBlock(i + 12, j + 3, k + 14, ancientbricks);
        world.setBlock(i + 12, j + 3, k + 15, dungeonBricks);
        world.setBlock(i + 12, j + 4, k + 0, dungeonBricks);
        world.setBlock(i + 12, j + 4, k + 15, dungeonBricks);
        world.setBlock(i + 12, j + 5, k + 0, dungeonBricks);
        world.setBlock(i + 12, j + 5, k + 15, dungeonBricks);
        world.setBlock(i + 12, j + 6, k + 0, dungeonBricks);
        world.setBlock(i + 12, j + 6, k + 15, dungeonBricks);
        world.setBlock(i + 12, j + 7, k + 0, dungeonBricks);
        world.setBlock(i + 12, j + 7, k + 15, dungeonBricks);
        world.setBlock(i + 13, j + 0, k + 0, dungeonBricks);
        world.setBlock(i + 13, j + 0, k + 1, dungeonBricks);
        world.setBlock(i + 13, j + 0, k + 2, dungeonBricks);
        world.setBlock(i + 13, j + 0, k + 3, dungeonBricks);
        world.setBlock(i + 13, j + 0, k + 4, dungeonBricks);
        world.setBlock(i + 13, j + 0, k + 5, dungeonBricks);
        world.setBlock(i + 13, j + 0, k + 6, dungeonBricks);
        world.setBlock(i + 13, j + 0, k + 7, dungeonBricks);
        world.setBlock(i + 13, j + 0, k + 8, dungeonBricks);
        world.setBlock(i + 13, j + 0, k + 9, dungeonBricks);
        world.setBlock(i + 13, j + 0, k + 10, dungeonBricks);
        world.setBlock(i + 13, j + 0, k + 11, dungeonBricks);
        world.setBlock(i + 13, j + 0, k + 12, dungeonBricks);
        world.setBlock(i + 13, j + 0, k + 13, dungeonBricks);
        world.setBlock(i + 13, j + 0, k + 14, dungeonBricks);
        world.setBlock(i + 13, j + 0, k + 15, dungeonBricks);
        world.setBlock(i + 13, j + 1, k + 0, dungeonBricks);
        world.setBlock(i + 13, j + 1, k + 4, ancientbricks);
        world.setBlock(i + 13, j + 1, k + 5, ancientbricks);
        world.setBlock(i + 13, j + 1, k + 15, dungeonBricks);
        world.setBlock(i + 13, j + 2, k + 0, dungeonBricks);
        world.setBlock(i + 13, j + 2, k + 3, ancientbricks);
        world.setBlock(i + 13, j + 2, k + 4, ancientbricks);
        world.setBlock(i + 13, j + 2, k + 15, dungeonBricks);
        world.setBlock(i + 13, j + 3, k + 0, dungeonBricks);
        world.setBlock(i + 13, j + 3, k + 1, ancientbricks);
        world.setBlock(i + 13, j + 3, k + 2, ancientbricks);
        world.setBlock(i + 13, j + 3, k + 3, ancientbricks);
        world.setBlock(i + 13, j + 3, k + 9, ancientbricks);
        world.setBlock(i + 13, j + 3, k + 10, ancientbricks);
        world.setBlock(i + 13, j + 3, k + 11, ancientbricks);
        world.setBlock(i + 13, j + 3, k + 12, ancientbricks);
        world.setBlock(i + 13, j + 3, k + 13, ancientbricks);
        world.setBlock(i + 13, j + 3, k + 14, ancientbricks);
        world.setBlock(i + 13, j + 3, k + 15, dungeonBricks);
        world.setBlock(i + 13, j + 4, k + 0, dungeonBricks);
        world.setBlock(i + 13, j + 4, k + 15, dungeonBricks);
        world.setBlock(i + 13, j + 5, k + 0, dungeonBricks);
        world.setBlock(i + 13, j + 5, k + 15, dungeonBricks);
        world.setBlock(i + 13, j + 6, k + 0, dungeonBricks);
        world.setBlock(i + 13, j + 6, k + 15, dungeonBricks);
        world.setBlock(i + 13, j + 7, k + 0, dungeonBricks);
        world.setBlock(i + 13, j + 7, k + 15, dungeonBricks);
        world.setBlock(i + 14, j + 0, k + 0, dungeonBricks);
        world.setBlock(i + 14, j + 0, k + 1, dungeonBricks);
        world.setBlock(i + 14, j + 0, k + 2, dungeonBricks);
        world.setBlock(i + 14, j + 0, k + 3, dungeonBricks);
        world.setBlock(i + 14, j + 0, k + 4, dungeonBricks);
        world.setBlock(i + 14, j + 0, k + 5, dungeonBricks);
        world.setBlock(i + 14, j + 0, k + 6, dungeonBricks);
        world.setBlock(i + 14, j + 0, k + 7, dungeonBricks);
        world.setBlock(i + 14, j + 0, k + 8, dungeonBricks);
        world.setBlock(i + 14, j + 0, k + 9, dungeonBricks);
        world.setBlock(i + 14, j + 0, k + 10, dungeonBricks);
        world.setBlock(i + 14, j + 0, k + 11, dungeonBricks);
        world.setBlock(i + 14, j + 0, k + 12, dungeonBricks);
        world.setBlock(i + 14, j + 0, k + 13, dungeonBricks);
        world.setBlock(i + 14, j + 0, k + 14, dungeonBricks);
        world.setBlock(i + 14, j + 0, k + 15, dungeonBricks);
        world.setBlock(i + 14, j + 1, k + 0, dungeonBricks);
        world.setBlock(i + 14, j + 1, k + 1, heatTraps);
        world.setBlock(i + 14, j + 1, k + 4, ancientbricks);
        world.setBlock(i + 14, j + 1, k + 5, ancientbricks);
        world.setBlock(i + 14, j + 1, k + 6, heatTraps);
        world.setBlock(i + 14, j + 1, k + 9, heatTraps);
        world.setBlock(i + 14, j + 1, k + 14, heatTraps);
        world.setBlock(i + 14, j + 1, k + 15, dungeonBricks);
        world.setBlock(i + 14, j + 2, k + 0, dungeonBricks);
        world.setBlock(i + 14, j + 2, k + 3, ancientbricks);
        world.setBlock(i + 14, j + 2, k + 4, ancientbricks);
        world.setBlock(i + 14, j + 2, k + 15, dungeonBricks);
        world.setBlock(i + 14, j + 3, k + 0, dungeonBricks);
        world.setBlock(i + 14, j + 3, k + 1, ancientbricks);
        world.setBlock(i + 14, j + 3, k + 2, ancientbricks);
        world.setBlock(i + 14, j + 3, k + 3, ancientbricks);
        world.setBlock(i + 14, j + 3, k + 9, ancientbricks);
        world.setBlock(i + 14, j + 3, k + 10, ancientbricks);
        world.setBlock(i + 14, j + 3, k + 11, ancientbricks);
        world.setBlock(i + 14, j + 3, k + 12, ancientbricks);
        world.setBlock(i + 14, j + 3, k + 13, ancientbricks);
        world.setBlock(i + 14, j + 3, k + 14, ArcanaBlocks.dungenLamp);
        world.setBlock(i + 14, j + 3, k + 15, dungeonBricks);
        world.setBlock(i + 14, j + 4, k + 0, dungeonBricks);
        world.setBlock(i + 14, j + 4, k + 1, heatTraps);
        world.setBlock(i + 14, j + 4, k + 14, heatTraps);
        world.setBlock(i + 14, j + 4, k + 15, dungeonBricks);
        world.setBlock(i + 14, j + 5, k + 0, dungeonBricks);
        world.setBlock(i + 14, j + 5, k + 15, dungeonBricks);
        world.setBlock(i + 14, j + 6, k + 0, dungeonBricks);
        world.setBlock(i + 14, j + 6, k + 15, dungeonBricks);
        world.setBlock(i + 14, j + 7, k + 0, dungeonBricks);
        world.setBlock(i + 14, j + 7, k + 1, ArcanaBlocks.dungenLamp);
        world.setBlock(i + 14, j + 7, k + 14, ArcanaBlocks.dungenLamp);
        world.setBlock(i + 14, j + 7, k + 15, dungeonBricks);
        world.setBlock(i + 15, j + 0, k + 0, dungeonBricks);
        world.setBlock(i + 15, j + 0, k + 1, dungeonBricks);
        world.setBlock(i + 15, j + 0, k + 2, dungeonBricks);
        world.setBlock(i + 15, j + 0, k + 3, dungeonBricks);
        world.setBlock(i + 15, j + 0, k + 4, dungeonBricks);
        world.setBlock(i + 15, j + 0, k + 5, dungeonBricks);
        world.setBlock(i + 15, j + 0, k + 6, dungeonBricks);
        world.setBlock(i + 15, j + 0, k + 7, dungeonBricks);
        world.setBlock(i + 15, j + 0, k + 8, dungeonBricks);
        world.setBlock(i + 15, j + 0, k + 9, dungeonBricks);
        world.setBlock(i + 15, j + 0, k + 10, dungeonBricks);
        world.setBlock(i + 15, j + 0, k + 11, dungeonBricks);
        world.setBlock(i + 15, j + 0, k + 12, dungeonBricks);
        world.setBlock(i + 15, j + 0, k + 13, dungeonBricks);
        world.setBlock(i + 15, j + 0, k + 14, dungeonBricks);
        world.setBlock(i + 15, j + 0, k + 15, dungeonBricks);
        world.setBlock(i + 15, j + 1, k + 0, dungeonBricks);
        world.setBlock(i + 15, j + 1, k + 1, dungeonBricks);
        world.setBlock(i + 15, j + 1, k + 2, dungeonBricks);
        world.setBlock(i + 15, j + 1, k + 3, dungeonBricks);
        world.setBlock(i + 15, j + 1, k + 4, dungeonBricks);
        world.setBlock(i + 15, j + 1, k + 5, dungeonBricks);
        world.setBlock(i + 15, j + 1, k + 6, arcaniteMetal);
        world.setBlock(i + 15, j + 1, k + 9, arcaniteMetal);
        world.setBlock(i + 15, j + 1, k + 10, dungeonBricks);
        world.setBlock(i + 15, j + 1, k + 11, dungeonBricks);
        world.setBlock(i + 15, j + 1, k + 12, dungeonBricks);
        world.setBlock(i + 15, j + 1, k + 13, dungeonBricks);
        world.setBlock(i + 15, j + 1, k + 14, dungeonBricks);
        world.setBlock(i + 15, j + 1, k + 15, dungeonBricks);
        world.setBlock(i + 15, j + 2, k + 0, dungeonBricks);
        world.setBlock(i + 15, j + 2, k + 1, dungeonBricks);
        world.setBlock(i + 15, j + 2, k + 2, dungeonBricks);
        world.setBlock(i + 15, j + 2, k + 3, dungeonBricks);
        world.setBlock(i + 15, j + 2, k + 4, dungeonBricks);
        world.setBlock(i + 15, j + 2, k + 5, dungeonBricks);
        world.setBlock(i + 15, j + 2, k + 6, arcaniteMetal);
        world.setBlock(i + 15, j + 2, k + 9, arcaniteMetal);
        world.setBlock(i + 15, j + 2, k + 10, dungeonBricks);
        world.setBlock(i + 15, j + 2, k + 11, dungeonBricks);
        world.setBlock(i + 15, j + 2, k + 12, dungeonBricks);
        world.setBlock(i + 15, j + 2, k + 13, dungeonBricks);
        world.setBlock(i + 15, j + 2, k + 14, dungeonBricks);
        world.setBlock(i + 15, j + 2, k + 15, dungeonBricks);
        world.setBlock(i + 15, j + 3, k + 0, dungeonBricks);
        world.setBlock(i + 15, j + 3, k + 1, dungeonBricks);
        world.setBlock(i + 15, j + 3, k + 2, dungeonBricks);
        world.setBlock(i + 15, j + 3, k + 3, dungeonBricks);
        world.setBlock(i + 15, j + 3, k + 4, dungeonBricks);
        world.setBlock(i + 15, j + 3, k + 5, dungeonBricks);
        world.setBlock(i + 15, j + 3, k + 6, arcaniteMetal);
        world.setBlock(i + 15, j + 3, k + 7, arcanaPower);
        world.setBlock(i + 15, j + 3, k + 8, arcanaPower);
        world.setBlock(i + 15, j + 3, k + 9, arcaniteMetal);
        world.setBlock(i + 15, j + 3, k + 10, dungeonBricks);
        world.setBlock(i + 15, j + 3, k + 11, dungeonBricks);
        world.setBlock(i + 15, j + 3, k + 12, dungeonBricks);
        world.setBlock(i + 15, j + 3, k + 13, dungeonBricks);
        world.setBlock(i + 15, j + 3, k + 14, dungeonBricks);
        world.setBlock(i + 15, j + 3, k + 15, dungeonBricks);
        world.setBlock(i + 15, j + 4, k + 0, dungeonBricks);
        world.setBlock(i + 15, j + 4, k + 1, dungeonBricks);
        world.setBlock(i + 15, j + 4, k + 2, dungeonBricks);
        world.setBlock(i + 15, j + 4, k + 3, dungeonBricks);
        world.setBlock(i + 15, j + 4, k + 4, dungeonBricks);
        world.setBlock(i + 15, j + 4, k + 5, dungeonBricks);
        world.setBlock(i + 15, j + 4, k + 6, dungeonBricks);
        world.setBlock(i + 15, j + 4, k + 7, dungeonBricks);
        world.setBlock(i + 15, j + 4, k + 8, dungeonBricks);
        world.setBlock(i + 15, j + 4, k + 9, dungeonBricks);
        world.setBlock(i + 15, j + 4, k + 10, dungeonBricks);
        world.setBlock(i + 15, j + 4, k + 11, dungeonBricks);
        world.setBlock(i + 15, j + 4, k + 12, dungeonBricks);
        world.setBlock(i + 15, j + 4, k + 13, dungeonBricks);
        world.setBlock(i + 15, j + 4, k + 14, dungeonBricks);
        world.setBlock(i + 15, j + 4, k + 15, dungeonBricks);
        world.setBlock(i + 15, j + 5, k + 0, dungeonBricks);
        world.setBlock(i + 15, j + 5, k + 1, dungeonBricks);
        world.setBlock(i + 15, j + 5, k + 2, dungeonBricks);
        world.setBlock(i + 15, j + 5, k + 3, dungeonBricks);
        world.setBlock(i + 15, j + 5, k + 4, dungeonBricks);
        world.setBlock(i + 15, j + 5, k + 5, dungeonBricks);
        world.setBlock(i + 15, j + 5, k + 6, dungeonBricks);
        world.setBlock(i + 15, j + 5, k + 7, dungeonBricks);
        world.setBlock(i + 15, j + 5, k + 8, dungeonBricks);
        world.setBlock(i + 15, j + 5, k + 9, dungeonBricks);
        world.setBlock(i + 15, j + 5, k + 10, dungeonBricks);
        world.setBlock(i + 15, j + 5, k + 11, dungeonBricks);
        world.setBlock(i + 15, j + 5, k + 12, dungeonBricks);
        world.setBlock(i + 15, j + 5, k + 13, dungeonBricks);
        world.setBlock(i + 15, j + 5, k + 14, dungeonBricks);
        world.setBlock(i + 15, j + 5, k + 15, dungeonBricks);
        world.setBlock(i + 15, j + 6, k + 0, dungeonBricks);
        world.setBlock(i + 15, j + 6, k + 1, dungeonBricks);
        world.setBlock(i + 15, j + 6, k + 2, dungeonBricks);
        world.setBlock(i + 15, j + 6, k + 3, dungeonBricks);
        world.setBlock(i + 15, j + 6, k + 4, dungeonBricks);
        world.setBlock(i + 15, j + 6, k + 5, dungeonBricks);
        world.setBlock(i + 15, j + 6, k + 6, dungeonBricks);
        world.setBlock(i + 15, j + 6, k + 7, dungeonBricks);
        world.setBlock(i + 15, j + 6, k + 8, dungeonBricks);
        world.setBlock(i + 15, j + 6, k + 9, dungeonBricks);
        world.setBlock(i + 15, j + 6, k + 10, dungeonBricks);
        world.setBlock(i + 15, j + 6, k + 11, dungeonBricks);
        world.setBlock(i + 15, j + 6, k + 12, dungeonBricks);
        world.setBlock(i + 15, j + 6, k + 13, dungeonBricks);
        world.setBlock(i + 15, j + 6, k + 14, dungeonBricks);
        world.setBlock(i + 15, j + 6, k + 15, dungeonBricks);
        world.setBlock(i + 15, j + 7, k + 0, dungeonBricks);
        world.setBlock(i + 15, j + 7, k + 1, dungeonBricks);
        world.setBlock(i + 15, j + 7, k + 2, dungeonBricks);
        world.setBlock(i + 15, j + 7, k + 3, dungeonBricks);
        world.setBlock(i + 15, j + 7, k + 4, dungeonBricks);
        world.setBlock(i + 15, j + 7, k + 5, dungeonBricks);
        world.setBlock(i + 15, j + 7, k + 6, dungeonBricks);
        world.setBlock(i + 15, j + 7, k + 7, dungeonBricks);
        world.setBlock(i + 15, j + 7, k + 8, dungeonBricks);
        world.setBlock(i + 15, j + 7, k + 9, dungeonBricks);
        world.setBlock(i + 15, j + 7, k + 10, dungeonBricks);
        world.setBlock(i + 15, j + 7, k + 11, dungeonBricks);
        world.setBlock(i + 15, j + 7, k + 12, dungeonBricks);
        world.setBlock(i + 15, j + 7, k + 13, dungeonBricks);
        world.setBlock(i + 15, j + 7, k + 14, dungeonBricks);
        world.setBlock(i + 15, j + 7, k + 15, dungeonBricks);
        return true;
    }
}