/*
 *** MADE BY MITHION'S .SCHEMATIC TO JAVA CONVERTING TOOL v1.6 ***
 */

package net.divinerpg.dimensions.arcana.components;
import java.util.Random;

import net.divinerpg.dimensions.arcana.ArcanaChunk;
import net.divinerpg.utils.blocks.ArcanaBlocks;
import net.minecraft.block.Block;
import net.minecraft.init.Blocks;

public class DungeonComponent1 extends DungeonComponentBase {
	
    @Override
    public boolean generate(ArcanaChunk world, Random rand, int i, int j, int k) {

        Block dungeonBricks = ArcanaBlocks.degradedBrick;
        Block ancientbricks = ArcanaBlocks.ancientBrick;
        Block soulStone = ArcanaBlocks.soulStone;
        Block ancientstone = ArcanaBlocks.ancientStone;
        Block arcaniteTubes = ArcanaBlocks.arcanitetubes;

        world.setBlock(i + 0, j + 0, k + 0, ancientbricks);
        world.setBlock(i + 0, j + 0, k + 1, ancientbricks);
        world.setBlock(i + 0, j + 0, k + 2, ancientbricks);
        world.setBlock(i + 0, j + 0, k + 3, ancientbricks);
        world.setBlock(i + 0, j + 0, k + 4, ancientbricks);
        world.setBlock(i + 0, j + 0, k + 5, ancientbricks);
        world.setBlock(i + 0, j + 0, k + 6, ancientbricks);
        world.setBlock(i + 0, j + 0, k + 7, ancientbricks);
        world.setBlock(i + 0, j + 0, k + 8, ancientbricks);
        world.setBlock(i + 0, j + 0, k + 9, ancientbricks);
        world.setBlock(i + 0, j + 0, k + 10, ancientbricks);
        world.setBlock(i + 0, j + 0, k + 11, ancientbricks);
        world.setBlock(i + 0, j + 0, k + 12, ancientbricks);
        world.setBlock(i + 0, j + 0, k + 13, ancientbricks);
        world.setBlock(i + 0, j + 0, k + 14, ancientbricks);
        world.setBlock(i + 0, j + 0, k + 15, ancientbricks);
        world.setBlock(i + 0, j + 1, k + 0, ancientbricks);
        world.setBlock(i + 0, j + 1, k + 1, ancientbricks);
        world.setBlock(i + 0, j + 1, k + 2, ancientbricks);
        world.setBlock(i + 0, j + 1, k + 3, ancientbricks);
        world.setBlock(i + 0, j + 1, k + 4, ancientbricks);
        world.setBlock(i + 0, j + 1, k + 5, ancientbricks);
        world.setBlock(i + 0, j + 1, k + 6, ancientbricks);
        world.setBlock(i + 0, j + 1, k + 9, ancientbricks);
        world.setBlock(i + 0, j + 1, k + 10, ancientbricks);
        world.setBlock(i + 0, j + 1, k + 11, ancientbricks);
        world.setBlock(i + 0, j + 1, k + 12, ancientbricks);
        world.setBlock(i + 0, j + 1, k + 13, ancientbricks);
        world.setBlock(i + 0, j + 1, k + 14, ancientbricks);
        world.setBlock(i + 0, j + 1, k + 15, ancientbricks);
        world.setBlock(i + 0, j + 2, k + 0, ancientbricks);
        world.setBlock(i + 0, j + 2, k + 1, ancientbricks);
        world.setBlock(i + 0, j + 2, k + 2, ancientbricks);
        world.setBlock(i + 0, j + 2, k + 3, ancientbricks);
        world.setBlock(i + 0, j + 2, k + 4, ancientbricks);
        world.setBlock(i + 0, j + 2, k + 5, ancientbricks);
        world.setBlock(i + 0, j + 2, k + 6, ancientbricks);
        world.setBlock(i + 0, j + 2, k + 9, ancientbricks);
        world.setBlock(i + 0, j + 2, k + 10, ancientbricks);
        world.setBlock(i + 0, j + 2, k + 11, ancientbricks);
        world.setBlock(i + 0, j + 2, k + 12, ancientbricks);
        world.setBlock(i + 0, j + 2, k + 13, ancientbricks);
        world.setBlock(i + 0, j + 2, k + 14, ancientbricks);
        world.setBlock(i + 0, j + 2, k + 15, ancientbricks);
        world.setBlock(i + 0, j + 3, k + 0, ancientbricks);
        world.setBlock(i + 0, j + 3, k + 1, ancientbricks);
        world.setBlock(i + 0, j + 3, k + 2, ancientbricks);
        world.setBlock(i + 0, j + 3, k + 3, ancientbricks);
        world.setBlock(i + 0, j + 3, k + 4, ancientbricks);
        world.setBlock(i + 0, j + 3, k + 5, ancientbricks);
        world.setBlock(i + 0, j + 3, k + 6, ancientbricks);
        world.setBlock(i + 0, j + 3, k + 7, ancientbricks);
        world.setBlock(i + 0, j + 3, k + 8, ancientbricks);
        world.setBlock(i + 0, j + 3, k + 9, ancientbricks);
        world.setBlock(i + 0, j + 3, k + 10, ancientbricks);
        world.setBlock(i + 0, j + 3, k + 11, ancientbricks);
        world.setBlock(i + 0, j + 3, k + 12, ancientbricks);
        world.setBlock(i + 0, j + 3, k + 13, ancientbricks);
        world.setBlock(i + 0, j + 3, k + 14, ancientbricks);
        world.setBlock(i + 0, j + 3, k + 15, ancientbricks);
        world.setBlock(i + 0, j + 4, k + 0, ancientbricks);
        world.setBlock(i + 0, j + 4, k + 1, ancientbricks);
        world.setBlock(i + 0, j + 4, k + 2, ancientbricks);
        world.setBlock(i + 0, j + 4, k + 3, ancientbricks);
        world.setBlock(i + 0, j + 4, k + 4, ancientbricks);
        world.setBlock(i + 0, j + 4, k + 5, ancientbricks);
        world.setBlock(i + 0, j + 4, k + 6, ancientbricks);
        world.setBlock(i + 0, j + 4, k + 7, ancientbricks);
        world.setBlock(i + 0, j + 4, k + 8, ancientbricks);
        world.setBlock(i + 0, j + 4, k + 9, ancientbricks);
        world.setBlock(i + 0, j + 4, k + 10, ancientbricks);
        world.setBlock(i + 0, j + 4, k + 11, ancientbricks);
        world.setBlock(i + 0, j + 4, k + 12, ancientbricks);
        world.setBlock(i + 0, j + 4, k + 13, ancientbricks);
        world.setBlock(i + 0, j + 4, k + 14, ancientbricks);
        world.setBlock(i + 0, j + 4, k + 15, ancientbricks);
        world.setBlock(i + 0, j + 5, k + 0, soulStone);
        world.setBlock(i + 0, j + 5, k + 1, soulStone);
        world.setBlock(i + 0, j + 5, k + 2, soulStone);
        world.setBlock(i + 0, j + 5, k + 3, soulStone);
        world.setBlock(i + 0, j + 5, k + 4, soulStone);
        world.setBlock(i + 0, j + 5, k + 5, soulStone);
        world.setBlock(i + 0, j + 5, k + 6, soulStone);
        world.setBlock(i + 0, j + 5, k + 7, soulStone);
        world.setBlock(i + 0, j + 5, k + 8, soulStone);
        world.setBlock(i + 0, j + 5, k + 9, soulStone);
        world.setBlock(i + 0, j + 5, k + 10, soulStone);
        world.setBlock(i + 0, j + 5, k + 11, soulStone);
        world.setBlock(i + 0, j + 5, k + 12, soulStone);
        world.setBlock(i + 0, j + 5, k + 13, soulStone);
        world.setBlock(i + 0, j + 5, k + 14, soulStone);
        world.setBlock(i + 0, j + 5, k + 15, soulStone);
        world.setBlock(i + 0, j + 6, k + 0, ancientstone);
        world.setBlock(i + 0, j + 6, k + 1, ancientstone);
        world.setBlock(i + 0, j + 6, k + 2, ancientstone);
        world.setBlock(i + 0, j + 6, k + 3, ancientstone);
        world.setBlock(i + 0, j + 6, k + 4, ancientstone);
        world.setBlock(i + 0, j + 6, k + 5, ancientstone);
        world.setBlock(i + 0, j + 6, k + 6, ancientstone);
        world.setBlock(i + 0, j + 6, k + 7, ancientstone);
        world.setBlock(i + 0, j + 6, k + 8, ancientstone);
        world.setBlock(i + 0, j + 6, k + 9, ancientstone);
        world.setBlock(i + 0, j + 6, k + 10, ancientstone);
        world.setBlock(i + 0, j + 6, k + 11, ancientstone);
        world.setBlock(i + 0, j + 6, k + 12, ancientstone);
        world.setBlock(i + 0, j + 6, k + 13, ancientstone);
        world.setBlock(i + 0, j + 6, k + 14, ancientstone);
        world.setBlock(i + 0, j + 6, k + 15, ancientstone);
        world.setBlock(i + 0, j + 7, k + 0, dungeonBricks);
        world.setBlock(i + 0, j + 7, k + 1, dungeonBricks);
        world.setBlock(i + 0, j + 7, k + 2, dungeonBricks);
        world.setBlock(i + 0, j + 7, k + 3, dungeonBricks);
        world.setBlock(i + 0, j + 7, k + 4, dungeonBricks);
        world.setBlock(i + 0, j + 7, k + 5, dungeonBricks);
        world.setBlock(i + 0, j + 7, k + 6, dungeonBricks);
        world.setBlock(i + 0, j + 7, k + 7, dungeonBricks);
        world.setBlock(i + 0, j + 7, k + 8, dungeonBricks);
        world.setBlock(i + 0, j + 7, k + 9, dungeonBricks);
        world.setBlock(i + 0, j + 7, k + 10, dungeonBricks);
        world.setBlock(i + 0, j + 7, k + 11, dungeonBricks);
        world.setBlock(i + 0, j + 7, k + 12, dungeonBricks);
        world.setBlock(i + 0, j + 7, k + 13, dungeonBricks);
        world.setBlock(i + 0, j + 7, k + 14, dungeonBricks);
        world.setBlock(i + 0, j + 7, k + 15, dungeonBricks);
        world.setBlock(i + 1, j + 0, k + 0, dungeonBricks);
        world.setBlock(i + 1, j + 0, k + 1, dungeonBricks);
        world.setBlock(i + 1, j + 0, k + 2, dungeonBricks);
        world.setBlock(i + 1, j + 0, k + 3, Blocks.air);
        world.setBlock(i + 1, j + 0, k + 4, dungeonBricks);
        world.setBlock(i + 1, j + 0, k + 5, dungeonBricks);
        world.setBlock(i + 1, j + 0, k + 6, ArcanaBlocks.arcaniumMetal);
        world.setBlock(i + 1, j + 0, k + 7, ArcanaBlocks.arcaniumMetal);
        world.setBlock(i + 1, j + 0, k + 8, dungeonBricks);
        world.setBlock(i + 1, j + 0, k + 9, dungeonBricks);
        world.setBlock(i + 1, j + 0, k + 10, ArcanaBlocks.arcaniumPower);
        world.setBlock(i + 1, j + 0, k + 11, ArcanaBlocks.arcaniumMetal);
        world.setBlock(i + 1, j + 0, k + 12, ArcanaBlocks.arcaniumMetal);
        world.setBlock(i + 1, j + 0, k + 13, ArcanaBlocks.arcaniumMetal);
        world.setBlock(i + 1, j + 0, k + 14, ArcanaBlocks.arcaniumMetal);
        world.setBlock(i + 1, j + 0, k + 15, ancientbricks);
        world.setBlock(i + 1, j + 1, k + 0, soulStone);
        world.setBlock(i + 1, j + 1, k + 3, dungeonBricks);
        world.setBlock(i + 1, j + 1, k + 4, dungeonBricks);
        world.setBlock(i + 1, j + 1, k + 5, ancientbricks);
        world.setBlock(i + 1, j + 1, k + 8, ancientbricks);
        world.setBlock(i + 1, j + 1, k + 9, dungeonBricks);
        //world.setBlockAndMetadata(i + 1, j + 1, k + 14, arcaniteTubes, 1);
        world.setBlock(i + 1, j + 1, k + 15, ArcanaBlocks.arcaniumMetal);
        world.setBlock(i + 1, j + 2, k + 0, soulStone);
        world.setBlock(i + 1, j + 2, k + 4, ancientbricks);
        world.setBlock(i + 1, j + 2, k + 5, dungeonBricks);
        world.setBlock(i + 1, j + 2, k + 8, ancientbricks);
        //world.setBlockAndMetadata(i + 1, j + 2, k + 14, arcaniteTubes, 1);
        world.setBlock(i + 1, j + 2, k + 15, ArcanaBlocks.arcaniumMetal);
        world.setBlock(i + 1, j + 3, k + 0, soulStone);
        world.setBlock(i + 1, j + 3, k + 5, dungeonBricks);
        world.setBlock(i + 1, j + 3, k + 6, ancientbricks);
        world.setBlock(i + 1, j + 3, k + 7, dungeonBricks);
        world.setBlock(i + 1, j + 3, k + 14, ancientbricks);
        world.setBlock(i + 1, j + 3, k + 15, ancientbricks);
        world.setBlock(i + 1, j + 4, k + 0, ancientbricks);
        world.setBlock(i + 1, j + 4, k + 15, ancientbricks);
        world.setBlock(i + 1, j + 5, k + 0, soulStone);
        world.setBlock(i + 1, j + 5, k + 15, soulStone);
        world.setBlock(i + 1, j + 6, k + 0, ancientstone);
        world.setBlock(i + 1, j + 6, k + 15, ancientstone);
        world.setBlock(i + 1, j + 7, k + 0, dungeonBricks);
        world.setBlock(i + 1, j + 7, k + 15, dungeonBricks);
        world.setBlock(i + 2, j + 0, k + 0, dungeonBricks);
        world.setBlock(i + 2, j + 0, k + 1, ArcanaBlocks.dungenLamp);
        world.setBlock(i + 2, j + 0, k + 2, dungeonBricks);
        world.setBlock(i + 2, j + 0, k + 3, Blocks.air);
        world.setBlock(i + 2, j + 0, k + 4, dungeonBricks);
        world.setBlock(i + 2, j + 0, k + 5, dungeonBricks);
        world.setBlock(i + 2, j + 0, k + 6, ArcanaBlocks.arcaniumMetal);
        world.setBlock(i + 2, j + 0, k + 7, ArcanaBlocks.arcaniumMetal);
        world.setBlock(i + 2, j + 0, k + 8, dungeonBricks);
        world.setBlock(i + 2, j + 0, k + 9, dungeonBricks);
        world.setBlock(i + 2, j + 0, k + 10, dungeonBricks);
        world.setBlock(i + 2, j + 0, k + 11, dungeonBricks);
        world.setBlock(i + 2, j + 0, k + 12, dungeonBricks);
        world.setBlock(i + 2, j + 0, k + 13, dungeonBricks);
        world.setBlock(i + 2, j + 0, k + 14, dungeonBricks);
        world.setBlock(i + 2, j + 0, k + 15, ancientbricks);
        world.setBlock(i + 2, j + 1, k + 0, ancientstone);
        world.setBlock(i + 2, j + 1, k + 3, dungeonBricks);
        world.setBlock(i + 2, j + 1, k + 4, dungeonBricks);
        world.setBlock(i + 2, j + 1, k + 5, ancientbricks);
        world.setBlock(i + 2, j + 1, k + 8, ancientbricks);
        world.setBlock(i + 2, j + 1, k + 9, dungeonBricks);
        //world.setBlock(i + 2, j + 1, k + 14, arcaniteTubes);
        world.setBlock(i + 2, j + 1, k + 15, ArcanaBlocks.arcaniumMetal);
        world.setBlock(i + 2, j + 2, k + 0, ancientstone);
        world.setBlock(i + 2, j + 2, k + 4, ancientbricks);
        //world.setBlock(i + 2, j + 2, k + 5, arcaniteTubes);
        world.setBlock(i + 2, j + 2, k + 8, ancientbricks);
        //world.setBlock(i + 2, j + 2, k + 14, arcaniteTubes);
        world.setBlock(i + 2, j + 2, k + 15, ArcanaBlocks.arcaniumMetal);
        world.setBlock(i + 2, j + 3, k + 0, ancientstone);
        world.setBlock(i + 2, j + 3, k + 5, dungeonBricks);
        world.setBlock(i + 2, j + 3, k + 6, soulStone);
        world.setBlock(i + 2, j + 3, k + 7, dungeonBricks);
        world.setBlock(i + 2, j + 3, k + 14, ArcanaBlocks.dungenLamp);
        world.setBlock(i + 2, j + 3, k + 15, ancientbricks);
        world.setBlock(i + 2, j + 4, k + 0, ancientbricks);
        world.setBlock(i + 2, j + 4, k + 15, ancientbricks);
        world.setBlock(i + 2, j + 5, k + 0, soulStone);
        world.setBlock(i + 2, j + 5, k + 15, soulStone);
        world.setBlock(i + 2, j + 6, k + 0, ancientstone);
        world.setBlock(i + 2, j + 6, k + 15, ancientstone);
        world.setBlock(i + 2, j + 7, k + 0, dungeonBricks);
        world.setBlock(i + 2, j + 7, k + 15, dungeonBricks);
        world.setBlock(i + 3, j + 0, k + 0, dungeonBricks);
        world.setBlock(i + 3, j + 0, k + 1, dungeonBricks);
        world.setBlock(i + 3, j + 0, k + 2, dungeonBricks);
        world.setBlock(i + 3, j + 0, k + 3, dungeonBricks);
        world.setBlock(i + 3, j + 0, k + 4, dungeonBricks);
        world.setBlock(i + 3, j + 0, k + 5, dungeonBricks);
        world.setBlock(i + 3, j + 0, k + 6, ArcanaBlocks.arcaniumMetal);
        world.setBlock(i + 3, j + 0, k + 7, ArcanaBlocks.arcaniumMetal);
        world.setBlock(i + 3, j + 0, k + 8, dungeonBricks);
        world.setBlock(i + 3, j + 0, k + 9, dungeonBricks);
        world.setBlock(i + 3, j + 0, k + 10, ArcanaBlocks.arcaniumPower);
        world.setBlock(i + 3, j + 0, k + 11, ArcanaBlocks.arcaniumMetal);
        world.setBlock(i + 3, j + 0, k + 12, ArcanaBlocks.arcaniumMetal);
        world.setBlock(i + 3, j + 0, k + 13, ArcanaBlocks.arcaniumMetal);
        world.setBlock(i + 3, j + 0, k + 14, ArcanaBlocks.arcaniumMetal);
        world.setBlock(i + 3, j + 0, k + 15, ancientbricks);
        world.setBlock(i + 3, j + 1, k + 0, ancientbricks);
        world.setBlock(i + 3, j + 1, k + 3, dungeonBricks);
        world.setBlock(i + 3, j + 1, k + 4, dungeonBricks);
        world.setBlock(i + 3, j + 1, k + 5, ancientbricks);
        world.setBlock(i + 3, j + 1, k + 8, ancientbricks);
        world.setBlock(i + 3, j + 1, k + 9, dungeonBricks);
        //world.setBlock(i + 3, j + 1, k + 14, arcaniteTubes);
        world.setBlock(i + 3, j + 1, k + 15, ArcanaBlocks.arcaniumMetal);
        world.setBlock(i + 3, j + 2, k + 0, ancientbricks);
        world.setBlock(i + 3, j + 2, k + 4, ancientbricks);
        world.setBlock(i + 3, j + 2, k + 5, dungeonBricks);
        world.setBlock(i + 3, j + 2, k + 8, ancientbricks);
        //world.setBlock(i + 3, j + 2, k + 14, arcaniteTubes);
        world.setBlock(i + 3, j + 2, k + 15, ArcanaBlocks.arcaniumMetal);
        world.setBlock(i + 3, j + 3, k + 0, dungeonBricks);
        world.setBlock(i + 3, j + 3, k + 5, dungeonBricks);
        world.setBlock(i + 3, j + 3, k + 6, ancientbricks);
        world.setBlock(i + 3, j + 3, k + 7, dungeonBricks);
        world.setBlock(i + 3, j + 3, k + 14, ancientbricks);
        world.setBlock(i + 3, j + 3, k + 15, ancientbricks);
        world.setBlock(i + 3, j + 4, k + 0, ancientbricks);
        world.setBlock(i + 3, j + 4, k + 15, ancientbricks);
        world.setBlock(i + 3, j + 5, k + 0, soulStone);
        world.setBlock(i + 3, j + 5, k + 15, soulStone);
        world.setBlock(i + 3, j + 6, k + 0, ancientstone);
        world.setBlock(i + 3, j + 6, k + 15, ancientstone);
        world.setBlock(i + 3, j + 7, k + 0, dungeonBricks);
        world.setBlock(i + 3, j + 7, k + 15, dungeonBricks);
        world.setBlock(i + 4, j + 0, k + 0, dungeonBricks);
        world.setBlock(i + 4, j + 0, k + 1, ArcanaBlocks.dungenLamp);
        world.setBlock(i + 4, j + 0, k + 2, dungeonBricks);
        world.setBlock(i + 4, j + 0, k + 3, dungeonBricks);
        world.setBlock(i + 4, j + 0, k + 4, dungeonBricks);
        world.setBlock(i + 4, j + 0, k + 5, dungeonBricks);
        world.setBlock(i + 4, j + 0, k + 6, ArcanaBlocks.arcaniumMetal);
        world.setBlock(i + 4, j + 0, k + 7, ArcanaBlocks.arcaniumMetal);
        world.setBlock(i + 4, j + 0, k + 8, dungeonBricks);
        world.setBlock(i + 4, j + 0, k + 9, dungeonBricks);
        world.setBlock(i + 4, j + 0, k + 10, dungeonBricks);
        world.setBlock(i + 4, j + 0, k + 11, dungeonBricks);
        world.setBlock(i + 4, j + 0, k + 12, dungeonBricks);
        world.setBlock(i + 4, j + 0, k + 13, dungeonBricks);
        world.setBlock(i + 4, j + 0, k + 14, dungeonBricks);
        world.setBlock(i + 4, j + 0, k + 15, ancientbricks);
        world.setBlock(i + 4, j + 1, k + 0, dungeonBricks);
        world.setBlock(i + 4, j + 1, k + 3, dungeonBricks);
        world.setBlock(i + 4, j + 1, k + 4, dungeonBricks);
        world.setBlock(i + 4, j + 1, k + 5, ancientbricks);
        world.setBlock(i + 4, j + 1, k + 8, ancientbricks);
        world.setBlock(i + 4, j + 1, k + 9, dungeonBricks);
        world.setBlock(i + 4, j + 1, k + 15, ancientbricks);
        world.setBlock(i + 4, j + 2, k + 0, dungeonBricks);
        world.setBlock(i + 4, j + 2, k + 4, ancientbricks);
        //world.setBlock(i + 4, j + 2, k + 5, arcaniteTubes);
        world.setBlock(i + 4, j + 2, k + 8, ancientbricks);
        world.setBlock(i + 4, j + 2, k + 15, ancientbricks);
        world.setBlock(i + 4, j + 3, k + 0, dungeonBricks);
        world.setBlock(i + 4, j + 3, k + 5, dungeonBricks);
        world.setBlock(i + 4, j + 3, k + 6, soulStone);
        world.setBlock(i + 4, j + 3, k + 7, dungeonBricks);
        world.setBlock(i + 4, j + 3, k + 15, ancientbricks);
        world.setBlock(i + 4, j + 4, k + 0, ancientbricks);
        world.setBlock(i + 4, j + 4, k + 15, ancientbricks);
        world.setBlock(i + 4, j + 5, k + 0, soulStone);
        world.setBlock(i + 4, j + 5, k + 15, soulStone);
        world.setBlock(i + 4, j + 6, k + 0, ancientstone);
        world.setBlock(i + 4, j + 6, k + 15, ancientstone);
        world.setBlock(i + 4, j + 7, k + 0, dungeonBricks);
        world.setBlock(i + 4, j + 7, k + 15, dungeonBricks);
        world.setBlock(i + 5, j + 0, k + 0, dungeonBricks);
        world.setBlock(i + 5, j + 0, k + 1, dungeonBricks);
        world.setBlock(i + 5, j + 0, k + 2, dungeonBricks);
        world.setBlock(i + 5, j + 0, k + 3, dungeonBricks);
        world.setBlock(i + 5, j + 0, k + 4, dungeonBricks);
        world.setBlock(i + 5, j + 0, k + 5, dungeonBricks);
        world.setBlock(i + 5, j + 0, k + 6, ArcanaBlocks.arcaniumMetal);
        world.setBlock(i + 5, j + 0, k + 7, ArcanaBlocks.arcaniumMetal);
        world.setBlock(i + 5, j + 0, k + 8, dungeonBricks);
        world.setBlock(i + 5, j + 0, k + 9, dungeonBricks);
        world.setBlock(i + 5, j + 0, k + 10, ArcanaBlocks.arcaniumPower);
        world.setBlock(i + 5, j + 0, k + 11, ArcanaBlocks.arcaniumMetal);
        world.setBlock(i + 5, j + 0, k + 12, ArcanaBlocks.arcaniumMetal);
        world.setBlock(i + 5, j + 0, k + 13, ArcanaBlocks.arcaniumMetal);
        world.setBlock(i + 5, j + 0, k + 14, ArcanaBlocks.arcaniumMetal);
        world.setBlock(i + 5, j + 0, k + 15, ancientbricks);
        world.setBlock(i + 5, j + 1, k + 0, ancientbricks);
        world.setBlock(i + 5, j + 1, k + 3, dungeonBricks);
        world.setBlock(i + 5, j + 1, k + 4, dungeonBricks);
        world.setBlock(i + 5, j + 1, k + 5, ancientbricks);
        world.setBlock(i + 5, j + 1, k + 8, ancientbricks);
        world.setBlock(i + 5, j + 1, k + 9, dungeonBricks);
        world.setBlock(i + 5, j + 1, k + 15, ancientbricks);
        world.setBlock(i + 5, j + 2, k + 0, ancientbricks);
        world.setBlock(i + 5, j + 2, k + 4, ancientbricks);
        world.setBlock(i + 5, j + 2, k + 5, dungeonBricks);
        world.setBlock(i + 5, j + 2, k + 8, ancientbricks);
        world.setBlock(i + 5, j + 2, k + 15, ancientbricks);
        world.setBlock(i + 5, j + 3, k + 0, ancientbricks);
        world.setBlock(i + 5, j + 3, k + 5, dungeonBricks);
        world.setBlock(i + 5, j + 3, k + 6, ancientbricks);
        world.setBlock(i + 5, j + 3, k + 7, dungeonBricks);
        world.setBlock(i + 5, j + 3, k + 15, ancientbricks);
        world.setBlock(i + 5, j + 4, k + 0, ancientbricks);
        world.setBlock(i + 5, j + 4, k + 15, ancientbricks);
        world.setBlock(i + 5, j + 5, k + 0, soulStone);
        world.setBlock(i + 5, j + 5, k + 15, soulStone);
        world.setBlock(i + 5, j + 6, k + 0, ancientstone);
        world.setBlock(i + 5, j + 6, k + 15, ancientstone);
        world.setBlock(i + 5, j + 7, k + 0, dungeonBricks);
        world.setBlock(i + 5, j + 7, k + 15, dungeonBricks);
        world.setBlock(i + 6, j + 0, k + 0, dungeonBricks);
        world.setBlock(i + 6, j + 0, k + 1, ArcanaBlocks.dungenLamp);
        world.setBlock(i + 6, j + 0, k + 2, dungeonBricks);
        world.setBlock(i + 6, j + 0, k + 3, dungeonBricks);
        world.setBlock(i + 6, j + 0, k + 4, dungeonBricks);
        world.setBlock(i + 6, j + 0, k + 5, dungeonBricks);
        world.setBlock(i + 6, j + 0, k + 6, ArcanaBlocks.arcaniumMetal);
        world.setBlock(i + 6, j + 0, k + 7, ArcanaBlocks.arcaniumMetal);
        world.setBlock(i + 6, j + 0, k + 8, dungeonBricks);
        world.setBlock(i + 6, j + 0, k + 9, dungeonBricks);
        world.setBlock(i + 6, j + 0, k + 10, dungeonBricks);
        world.setBlock(i + 6, j + 0, k + 11, dungeonBricks);
        world.setBlock(i + 6, j + 0, k + 12, dungeonBricks);
        world.setBlock(i + 6, j + 0, k + 13, dungeonBricks);
        world.setBlock(i + 6, j + 0, k + 14, dungeonBricks);
        world.setBlock(i + 6, j + 0, k + 15, ancientbricks);
        world.setBlock(i + 6, j + 1, k + 0, ArcanaBlocks.arcaniumMetal);
        world.setBlock(i + 6, j + 1, k + 3, dungeonBricks);
        world.setBlock(i + 6, j + 1, k + 4, dungeonBricks);
        world.setBlock(i + 6, j + 1, k + 5, ancientbricks);
        world.setBlock(i + 6, j + 1, k + 8, ancientbricks);
        world.setBlock(i + 6, j + 1, k + 9, dungeonBricks);
        world.setBlock(i + 6, j + 1, k + 15, ArcanaBlocks.arcaniumMetal);
        world.setBlock(i + 6, j + 2, k + 0, ArcanaBlocks.arcaniumMetal);
        world.setBlock(i + 6, j + 2, k + 4, ancientbricks);
        //world.setBlock(i + 6, j + 2, k + 5, arcaniteTubes);
        world.setBlock(i + 6, j + 2, k + 8, ancientbricks);
        world.setBlock(i + 6, j + 2, k + 15, ArcanaBlocks.arcaniumMetal);
        world.setBlock(i + 6, j + 3, k + 0, ArcanaBlocks.arcaniumMetal);
        world.setBlock(i + 6, j + 3, k + 5, dungeonBricks);
        world.setBlock(i + 6, j + 3, k + 6, soulStone);
        world.setBlock(i + 6, j + 3, k + 7, dungeonBricks);
        world.setBlock(i + 6, j + 3, k + 15, ArcanaBlocks.arcaniumMetal);
        world.setBlock(i + 6, j + 4, k + 0, ancientbricks);
        world.setBlock(i + 6, j + 4, k + 15, ancientbricks);
        world.setBlock(i + 6, j + 5, k + 0, soulStone);
        world.setBlock(i + 6, j + 5, k + 15, soulStone);
        world.setBlock(i + 6, j + 6, k + 0, ancientstone);
        world.setBlock(i + 6, j + 6, k + 15, ancientstone);
        world.setBlock(i + 6, j + 7, k + 0, dungeonBricks);
        world.setBlock(i + 6, j + 7, k + 15, dungeonBricks);
        world.setBlock(i + 7, j + 0, k + 0, dungeonBricks);
        world.setBlock(i + 7, j + 0, k + 1, dungeonBricks);
        world.setBlock(i + 7, j + 0, k + 2, dungeonBricks);
        world.setBlock(i + 7, j + 0, k + 3, dungeonBricks);
        world.setBlock(i + 7, j + 0, k + 4, dungeonBricks);
        world.setBlock(i + 7, j + 0, k + 5, dungeonBricks);
        world.setBlock(i + 7, j + 0, k + 6, ArcanaBlocks.arcaniumMetal);
        world.setBlock(i + 7, j + 0, k + 7, ArcanaBlocks.arcaniumMetal);
        world.setBlock(i + 7, j + 0, k + 8, dungeonBricks);
        world.setBlock(i + 7, j + 0, k + 9, dungeonBricks);
        world.setBlock(i + 7, j + 0, k + 10, dungeonBricks);
        world.setBlock(i + 7, j + 0, k + 11, ancientbricks);
        world.setBlock(i + 7, j + 0, k + 12, dungeonBricks);
        world.setBlock(i + 7, j + 0, k + 13, ancientbricks);
        world.setBlock(i + 7, j + 0, k + 14, dungeonBricks);
        world.setBlock(i + 7, j + 0, k + 15, ancientbricks);
        world.setBlock(i + 7, j + 1, k + 3, dungeonBricks);
        world.setBlock(i + 7, j + 1, k + 4, dungeonBricks);
        world.setBlock(i + 7, j + 1, k + 5, ancientbricks);
        world.setBlock(i + 7, j + 1, k + 8, ancientbricks);
        world.setBlock(i + 7, j + 1, k + 9, dungeonBricks);
        world.setBlock(i + 7, j + 2, k + 4, ancientbricks);
        world.setBlock(i + 7, j + 2, k + 5, dungeonBricks);
        world.setBlock(i + 7, j + 2, k + 8, ancientbricks);
        world.setBlock(i + 7, j + 3, k + 0, ArcanaBlocks.arcaniumPower);
        world.setBlock(i + 7, j + 3, k + 5, dungeonBricks);
        world.setBlock(i + 7, j + 3, k + 6, ArcanaBlocks.dungenLamp);
        world.setBlock(i + 7, j + 3, k + 7, dungeonBricks);
        world.setBlock(i + 7, j + 3, k + 15, ArcanaBlocks.arcaniumPower);
        world.setBlock(i + 7, j + 4, k + 0, ancientbricks);
        world.setBlock(i + 7, j + 4, k + 15, ancientbricks);
        world.setBlock(i + 7, j + 5, k + 0, soulStone);
        world.setBlock(i + 7, j + 5, k + 15, soulStone);
        world.setBlock(i + 7, j + 6, k + 0, ancientstone);
        world.setBlock(i + 7, j + 6, k + 15, ancientstone);
        world.setBlock(i + 7, j + 7, k + 0, dungeonBricks);
        world.setBlock(i + 7, j + 7, k + 15, dungeonBricks);
        world.setBlock(i + 8, j + 0, k + 0, dungeonBricks);
        world.setBlock(i + 8, j + 0, k + 1, dungeonBricks);
        world.setBlock(i + 8, j + 0, k + 2, dungeonBricks);
        world.setBlock(i + 8, j + 0, k + 3, dungeonBricks);
        world.setBlock(i + 8, j + 0, k + 4, dungeonBricks);
        world.setBlock(i + 8, j + 0, k + 5, dungeonBricks);
        world.setBlock(i + 8, j + 0, k + 6, ArcanaBlocks.arcaniumMetal);
        world.setBlock(i + 8, j + 0, k + 7, ArcanaBlocks.arcaniumMetal);
        world.setBlock(i + 8, j + 0, k + 8, dungeonBricks);
        world.setBlock(i + 8, j + 0, k + 9, dungeonBricks);
        world.setBlock(i + 8, j + 0, k + 10, dungeonBricks);
        world.setBlock(i + 8, j + 0, k + 11, ancientbricks);
        world.setBlock(i + 8, j + 0, k + 12, dungeonBricks);
        world.setBlock(i + 8, j + 0, k + 13, ancientbricks);
        world.setBlock(i + 8, j + 0, k + 14, dungeonBricks);
        world.setBlock(i + 8, j + 0, k + 15, ancientbricks);
        world.setBlock(i + 8, j + 1, k + 3, dungeonBricks);
        world.setBlock(i + 8, j + 1, k + 4, dungeonBricks);
        world.setBlock(i + 8, j + 1, k + 5, ancientbricks);
        world.setBlock(i + 8, j + 1, k + 8, ancientbricks);
        world.setBlock(i + 8, j + 1, k + 9, dungeonBricks);
        world.setBlock(i + 8, j + 2, k + 4, ancientbricks);
        world.setBlock(i + 8, j + 2, k + 5, dungeonBricks);
        world.setBlock(i + 8, j + 2, k + 8, ancientbricks);
        world.setBlock(i + 8, j + 3, k + 0, ArcanaBlocks.arcaniumPower);
        world.setBlock(i + 8, j + 3, k + 5, dungeonBricks);
        world.setBlock(i + 8, j + 3, k + 6, ArcanaBlocks.dungenLamp);
        world.setBlock(i + 8, j + 3, k + 7, dungeonBricks);
        world.setBlock(i + 8, j + 3, k + 15, ArcanaBlocks.arcaniumPower);
        world.setBlock(i + 8, j + 4, k + 0, ancientbricks);
        world.setBlock(i + 8, j + 4, k + 15, ancientbricks);
        world.setBlock(i + 8, j + 5, k + 0, soulStone);
        world.setBlock(i + 8, j + 5, k + 15, soulStone);
        world.setBlock(i + 8, j + 6, k + 0, ancientstone);
        world.setBlock(i + 8, j + 6, k + 15, ancientstone);
        world.setBlock(i + 8, j + 7, k + 0, dungeonBricks);
        world.setBlock(i + 8, j + 7, k + 15, dungeonBricks);
        world.setBlock(i + 9, j + 0, k + 0, dungeonBricks);
        world.setBlock(i + 9, j + 0, k + 1, ArcanaBlocks.dungenLamp);
        world.setBlock(i + 9, j + 0, k + 2, dungeonBricks);
        world.setBlock(i + 9, j + 0, k + 3, dungeonBricks);
        world.setBlock(i + 9, j + 0, k + 4, dungeonBricks);
        world.setBlock(i + 9, j + 0, k + 5, dungeonBricks);
        world.setBlock(i + 9, j + 0, k + 6, ArcanaBlocks.arcaniumMetal);
        world.setBlock(i + 9, j + 0, k + 7, ArcanaBlocks.arcaniumMetal);
        world.setBlock(i + 9, j + 0, k + 8, dungeonBricks);
        world.setBlock(i + 9, j + 0, k + 9, dungeonBricks);
        world.setBlock(i + 9, j + 0, k + 10, dungeonBricks);
        world.setBlock(i + 9, j + 0, k + 11, dungeonBricks);
        world.setBlock(i + 9, j + 0, k + 12, dungeonBricks);
        world.setBlock(i + 9, j + 0, k + 13, dungeonBricks);
        world.setBlock(i + 9, j + 0, k + 14, dungeonBricks);
        world.setBlock(i + 9, j + 0, k + 15, ancientbricks);
        world.setBlock(i + 9, j + 1, k + 0, ArcanaBlocks.arcaniumMetal);
        world.setBlock(i + 9, j + 1, k + 3, dungeonBricks);
        world.setBlock(i + 9, j + 1, k + 4, dungeonBricks);
        world.setBlock(i + 9, j + 1, k + 5, ancientbricks);
        world.setBlock(i + 9, j + 1, k + 8, ancientbricks);
        world.setBlock(i + 9, j + 1, k + 9, dungeonBricks);
        world.setBlock(i + 9, j + 1, k + 15, ArcanaBlocks.arcaniumMetal);
        world.setBlock(i + 9, j + 2, k + 0, ArcanaBlocks.arcaniumMetal);
        world.setBlock(i + 9, j + 2, k + 4, ancientbricks);
        //world.setBlock(i + 9, j + 2, k + 5, arcaniteTubes);
        world.setBlock(i + 9, j + 2, k + 8, ancientbricks);
        world.setBlock(i + 9, j + 2, k + 15, ArcanaBlocks.arcaniumMetal);
        world.setBlock(i + 9, j + 3, k + 0, ArcanaBlocks.arcaniumMetal);
        world.setBlock(i + 9, j + 3, k + 5, dungeonBricks);
        world.setBlock(i + 9, j + 3, k + 6, soulStone);
        world.setBlock(i + 9, j + 3, k + 7, dungeonBricks);
        world.setBlock(i + 9, j + 3, k + 15, ArcanaBlocks.arcaniumMetal);
        world.setBlock(i + 9, j + 4, k + 0, ancientbricks);
        world.setBlock(i + 9, j + 4, k + 15, ancientbricks);
        world.setBlock(i + 9, j + 5, k + 0, soulStone);
        world.setBlock(i + 9, j + 5, k + 15, soulStone);
        world.setBlock(i + 9, j + 6, k + 0, ancientstone);
        world.setBlock(i + 9, j + 6, k + 15, ancientstone);
        world.setBlock(i + 9, j + 7, k + 0, dungeonBricks);
        world.setBlock(i + 9, j + 7, k + 15, dungeonBricks);
        world.setBlock(i + 10, j + 0, k + 0, dungeonBricks);
        world.setBlock(i + 10, j + 0, k + 1, dungeonBricks);
        world.setBlock(i + 10, j + 0, k + 2, dungeonBricks);
        world.setBlock(i + 10, j + 0, k + 3, dungeonBricks);
        world.setBlock(i + 10, j + 0, k + 4, dungeonBricks);
        world.setBlock(i + 10, j + 0, k + 5, dungeonBricks);
        world.setBlock(i + 10, j + 0, k + 6, ArcanaBlocks.arcaniumMetal);
        world.setBlock(i + 10, j + 0, k + 7, ArcanaBlocks.arcaniumMetal);
        world.setBlock(i + 10, j + 0, k + 8, dungeonBricks);
        world.setBlock(i + 10, j + 0, k + 9, dungeonBricks);
        world.setBlock(i + 10, j + 0, k + 10, ArcanaBlocks.arcaniumPower);
        world.setBlock(i + 10, j + 0, k + 11, ArcanaBlocks.arcaniumMetal);
        world.setBlock(i + 10, j + 0, k + 12, ArcanaBlocks.arcaniumMetal);
        world.setBlock(i + 10, j + 0, k + 13, ArcanaBlocks.arcaniumMetal);
        world.setBlock(i + 10, j + 0, k + 14, ArcanaBlocks.arcaniumMetal);
        world.setBlock(i + 10, j + 0, k + 15, ancientbricks);
        world.setBlock(i + 10, j + 1, k + 0, ancientbricks);
        world.setBlock(i + 10, j + 1, k + 3, dungeonBricks);
        world.setBlock(i + 10, j + 1, k + 4, dungeonBricks);
        world.setBlock(i + 10, j + 1, k + 5, ancientbricks);
        world.setBlock(i + 10, j + 1, k + 8, ancientbricks);
        world.setBlock(i + 10, j + 1, k + 9, dungeonBricks);
        world.setBlock(i + 10, j + 1, k + 15, ancientbricks);
        world.setBlock(i + 10, j + 2, k + 0, ancientbricks);
        world.setBlock(i + 10, j + 2, k + 4, ancientbricks);
        world.setBlock(i + 10, j + 2, k + 5, dungeonBricks);
        world.setBlock(i + 10, j + 2, k + 8, ancientbricks);
        world.setBlock(i + 10, j + 2, k + 15, ancientbricks);
        world.setBlock(i + 10, j + 3, k + 0, ancientbricks);
        world.setBlock(i + 10, j + 3, k + 5, dungeonBricks);
        world.setBlock(i + 10, j + 3, k + 6, ancientbricks);
        world.setBlock(i + 10, j + 3, k + 7, dungeonBricks);
        world.setBlock(i + 10, j + 3, k + 15, ancientbricks);
        world.setBlock(i + 10, j + 4, k + 0, ancientbricks);
        world.setBlock(i + 10, j + 4, k + 15, ancientbricks);
        world.setBlock(i + 10, j + 5, k + 0, soulStone);
        world.setBlock(i + 10, j + 5, k + 15, soulStone);
        world.setBlock(i + 10, j + 6, k + 0, ancientstone);
        world.setBlock(i + 10, j + 6, k + 15, ancientstone);
        world.setBlock(i + 10, j + 7, k + 0, dungeonBricks);
        world.setBlock(i + 10, j + 7, k + 15, dungeonBricks);
        world.setBlock(i + 11, j + 0, k + 0, dungeonBricks);
        world.setBlock(i + 11, j + 0, k + 1, ArcanaBlocks.dungenLamp);
        world.setBlock(i + 11, j + 0, k + 2, dungeonBricks);
        world.setBlock(i + 11, j + 0, k + 3, dungeonBricks);
        world.setBlock(i + 11, j + 0, k + 4, dungeonBricks);
        world.setBlock(i + 11, j + 0, k + 5, dungeonBricks);
        world.setBlock(i + 11, j + 0, k + 6, ArcanaBlocks.arcaniumMetal);
        world.setBlock(i + 11, j + 0, k + 7, ArcanaBlocks.arcaniumMetal);
        world.setBlock(i + 11, j + 0, k + 8, dungeonBricks);
        world.setBlock(i + 11, j + 0, k + 9, dungeonBricks);
        world.setBlock(i + 11, j + 0, k + 10, dungeonBricks);
        world.setBlock(i + 11, j + 0, k + 11, dungeonBricks);
        world.setBlock(i + 11, j + 0, k + 12, dungeonBricks);
        world.setBlock(i + 11, j + 0, k + 13, dungeonBricks);
        world.setBlock(i + 11, j + 0, k + 14, dungeonBricks);
        world.setBlock(i + 11, j + 0, k + 15, ancientbricks);
        world.setBlock(i + 11, j + 1, k + 0, dungeonBricks);
        world.setBlock(i + 11, j + 1, k + 3, dungeonBricks);
        world.setBlock(i + 11, j + 1, k + 4, dungeonBricks);
        world.setBlock(i + 11, j + 1, k + 5, ancientbricks);
        world.setBlock(i + 11, j + 1, k + 8, ancientbricks);
        world.setBlock(i + 11, j + 1, k + 9, dungeonBricks);
        world.setBlock(i + 11, j + 1, k + 15, ancientbricks);
        world.setBlock(i + 11, j + 2, k + 0, dungeonBricks);
        world.setBlock(i + 11, j + 2, k + 4, ancientbricks);
        //world.setBlock(i + 11, j + 2, k + 5, arcaniteTubes);
        world.setBlock(i + 11, j + 2, k + 8, ancientbricks);
        world.setBlock(i + 11, j + 2, k + 15, ancientbricks);
        world.setBlock(i + 11, j + 3, k + 0, dungeonBricks);
        world.setBlock(i + 11, j + 3, k + 5, dungeonBricks);
        world.setBlock(i + 11, j + 3, k + 6, soulStone);
        world.setBlock(i + 11, j + 3, k + 7, dungeonBricks);
        world.setBlock(i + 11, j + 3, k + 15, ancientbricks);
        world.setBlock(i + 11, j + 4, k + 0, ancientbricks);
        world.setBlock(i + 11, j + 4, k + 15, ancientbricks);
        world.setBlock(i + 11, j + 5, k + 0, soulStone);
        world.setBlock(i + 11, j + 5, k + 15, soulStone);
        world.setBlock(i + 11, j + 6, k + 0, ancientstone);
        world.setBlock(i + 11, j + 6, k + 15, ancientstone);
        world.setBlock(i + 11, j + 7, k + 0, dungeonBricks);
        world.setBlock(i + 11, j + 7, k + 15, dungeonBricks);
        world.setBlock(i + 12, j + 0, k + 0, dungeonBricks);
        world.setBlock(i + 12, j + 0, k + 1, dungeonBricks);
        world.setBlock(i + 12, j + 0, k + 2, dungeonBricks);
        world.setBlock(i + 12, j + 0, k + 3, dungeonBricks);
        world.setBlock(i + 12, j + 0, k + 4, dungeonBricks);
        world.setBlock(i + 12, j + 0, k + 5, dungeonBricks);
        world.setBlock(i + 12, j + 0, k + 6, ArcanaBlocks.arcaniumMetal);
        world.setBlock(i + 12, j + 0, k + 7, ArcanaBlocks.arcaniumMetal);
        world.setBlock(i + 12, j + 0, k + 8, dungeonBricks);
        world.setBlock(i + 12, j + 0, k + 9, dungeonBricks);
        world.setBlock(i + 12, j + 0, k + 10, ArcanaBlocks.arcaniumPower);
        world.setBlock(i + 12, j + 0, k + 11, ArcanaBlocks.arcaniumMetal);
        world.setBlock(i + 12, j + 0, k + 12, ArcanaBlocks.arcaniumMetal);
        world.setBlock(i + 12, j + 0, k + 13, ArcanaBlocks.arcaniumMetal);
        world.setBlock(i + 12, j + 0, k + 14, ArcanaBlocks.arcaniumMetal);
        world.setBlock(i + 12, j + 0, k + 15, ancientbricks);
        world.setBlock(i + 12, j + 1, k + 0, ancientbricks);
        world.setBlock(i + 12, j + 1, k + 3, dungeonBricks);
        world.setBlock(i + 12, j + 1, k + 4, dungeonBricks);
        world.setBlock(i + 12, j + 1, k + 5, ancientbricks);
        world.setBlock(i + 12, j + 1, k + 8, ancientbricks);
        world.setBlock(i + 12, j + 1, k + 9, dungeonBricks);
        //world.setBlock(i + 12, j + 1, k + 14, arcaniteTubes);
        world.setBlock(i + 12, j + 1, k + 15, ArcanaBlocks.arcaniumMetal);
        world.setBlock(i + 12, j + 2, k + 0, ancientbricks);
        world.setBlock(i + 12, j + 2, k + 4, ancientbricks);
        world.setBlock(i + 12, j + 2, k + 5, dungeonBricks);
        world.setBlock(i + 12, j + 2, k + 8, ancientbricks);
        //world.setBlock(i + 12, j + 2, k + 14, arcaniteTubes);
        world.setBlock(i + 12, j + 2, k + 15, ArcanaBlocks.arcaniumMetal);
        world.setBlock(i + 12, j + 3, k + 0, dungeonBricks);
        world.setBlock(i + 12, j + 3, k + 5, dungeonBricks);
        world.setBlock(i + 12, j + 3, k + 6, ancientbricks);
        world.setBlock(i + 12, j + 3, k + 7, dungeonBricks);
        world.setBlock(i + 12, j + 3, k + 14, ancientbricks);
        world.setBlock(i + 12, j + 3, k + 15, ancientbricks);
        world.setBlock(i + 12, j + 4, k + 0, ancientbricks);
        world.setBlock(i + 12, j + 4, k + 15, ancientbricks);
        world.setBlock(i + 12, j + 5, k + 0, soulStone);
        world.setBlock(i + 12, j + 5, k + 15, soulStone);
        world.setBlock(i + 12, j + 6, k + 0, ancientstone);
        world.setBlock(i + 12, j + 6, k + 15, ancientstone);
        world.setBlock(i + 12, j + 7, k + 0, dungeonBricks);
        world.setBlock(i + 12, j + 7, k + 15, dungeonBricks);
        world.setBlock(i + 13, j + 0, k + 0, dungeonBricks);
        world.setBlock(i + 13, j + 0, k + 1, ArcanaBlocks.dungenLamp);
        world.setBlock(i + 13, j + 0, k + 2, dungeonBricks);
        world.setBlock(i + 13, j + 0, k + 3, dungeonBricks);
        world.setBlock(i + 13, j + 0, k + 4, dungeonBricks);
        world.setBlock(i + 13, j + 0, k + 5, dungeonBricks);
        world.setBlock(i + 13, j + 0, k + 6, ArcanaBlocks.arcaniumMetal);
        world.setBlock(i + 13, j + 0, k + 7, ArcanaBlocks.arcaniumMetal);
        world.setBlock(i + 13, j + 0, k + 8, dungeonBricks);
        world.setBlock(i + 13, j + 0, k + 9, dungeonBricks);
        world.setBlock(i + 13, j + 0, k + 10, dungeonBricks);
        world.setBlock(i + 13, j + 0, k + 11, dungeonBricks);
        world.setBlock(i + 13, j + 0, k + 12, dungeonBricks);
        world.setBlock(i + 13, j + 0, k + 13, dungeonBricks);
        world.setBlock(i + 13, j + 0, k + 14, dungeonBricks);
        world.setBlock(i + 13, j + 0, k + 15, ancientbricks);
        world.setBlock(i + 13, j + 1, k + 0, ancientstone);
        world.setBlock(i + 13, j + 1, k + 3, dungeonBricks);
        world.setBlock(i + 13, j + 1, k + 4, dungeonBricks);
        world.setBlock(i + 13, j + 1, k + 5, ancientbricks);
        world.setBlock(i + 13, j + 1, k + 8, ancientbricks);
        world.setBlock(i + 13, j + 1, k + 9, dungeonBricks);
        //world.setBlock(i + 13, j + 1, k + 14, arcaniteTubes);
        world.setBlock(i + 13, j + 1, k + 15, ArcanaBlocks.arcaniumMetal);
        world.setBlock(i + 13, j + 2, k + 0, ancientstone);
        world.setBlock(i + 13, j + 2, k + 4, ancientbricks);
        //world.setBlock(i + 13, j + 2, k + 5, arcaniteTubes);
        world.setBlock(i + 13, j + 2, k + 8, ancientbricks);
        //world.setBlock(i + 13, j + 2, k + 14, arcaniteTubes);
        world.setBlock(i + 13, j + 2, k + 15, ArcanaBlocks.arcaniumMetal);
        world.setBlock(i + 13, j + 3, k + 0, ancientstone);
        world.setBlock(i + 13, j + 3, k + 5, dungeonBricks);
        world.setBlock(i + 13, j + 3, k + 6, soulStone);
        world.setBlock(i + 13, j + 3, k + 7, dungeonBricks);
        world.setBlock(i + 13, j + 3, k + 14, ArcanaBlocks.dungenLamp);
        world.setBlock(i + 13, j + 3, k + 15, ancientbricks);
        world.setBlock(i + 13, j + 4, k + 0, ancientbricks);
        world.setBlock(i + 13, j + 4, k + 15, ancientbricks);
        world.setBlock(i + 13, j + 5, k + 0, soulStone);
        world.setBlock(i + 13, j + 5, k + 15, soulStone);
        world.setBlock(i + 13, j + 6, k + 0, ancientstone);
        world.setBlock(i + 13, j + 6, k + 15, ancientstone);
        world.setBlock(i + 13, j + 7, k + 0, dungeonBricks);
        world.setBlock(i + 13, j + 7, k + 15, dungeonBricks);
        world.setBlock(i + 14, j + 0, k + 0, dungeonBricks);
        world.setBlock(i + 14, j + 0, k + 1, dungeonBricks);
        world.setBlock(i + 14, j + 0, k + 2, dungeonBricks);
        world.setBlock(i + 14, j + 0, k + 3, dungeonBricks);
        world.setBlock(i + 14, j + 0, k + 4, dungeonBricks);
        world.setBlock(i + 14, j + 0, k + 5, dungeonBricks);
        world.setBlock(i + 14, j + 0, k + 6, ArcanaBlocks.arcaniumMetal);
        world.setBlock(i + 14, j + 0, k + 7, ArcanaBlocks.arcaniumMetal);
        world.setBlock(i + 14, j + 0, k + 8, dungeonBricks);
        world.setBlock(i + 14, j + 0, k + 9, dungeonBricks);
        world.setBlock(i + 14, j + 0, k + 10, ArcanaBlocks.arcaniumPower);
        world.setBlock(i + 14, j + 0, k + 11, ArcanaBlocks.arcaniumMetal);
        world.setBlock(i + 14, j + 0, k + 12, ArcanaBlocks.arcaniumMetal);
        world.setBlock(i + 14, j + 0, k + 13, ArcanaBlocks.arcaniumMetal);
        world.setBlock(i + 14, j + 0, k + 14, ArcanaBlocks.arcaniumMetal);
        world.setBlock(i + 14, j + 0, k + 15, ancientbricks);
        world.setBlock(i + 14, j + 1, k + 0, soulStone);
        world.setBlock(i + 14, j + 1, k + 3, dungeonBricks);
        world.setBlock(i + 14, j + 1, k + 4, dungeonBricks);
        world.setBlock(i + 14, j + 1, k + 5, ancientbricks);
        world.setBlock(i + 14, j + 1, k + 8, ancientbricks);
        world.setBlock(i + 14, j + 1, k + 9, dungeonBricks);
        //world.setBlock(i + 14, j + 1, k + 14, arcaniteTubes);
        world.setBlock(i + 14, j + 1, k + 15, ArcanaBlocks.arcaniumMetal);
        world.setBlock(i + 14, j + 2, k + 0, soulStone);
        world.setBlock(i + 14, j + 2, k + 4, ancientbricks);
        world.setBlock(i + 14, j + 2, k + 5, dungeonBricks);
        world.setBlock(i + 14, j + 2, k + 8, ancientbricks);
        //world.setBlock(i + 14, j + 2, k + 14, arcaniteTubes);
        world.setBlock(i + 14, j + 2, k + 15, ArcanaBlocks.arcaniumMetal);
        world.setBlock(i + 14, j + 3, k + 0, soulStone);
        world.setBlock(i + 14, j + 3, k + 5, dungeonBricks);
        world.setBlock(i + 14, j + 3, k + 6, ancientbricks);
        world.setBlock(i + 14, j + 3, k + 7, dungeonBricks);
        world.setBlock(i + 14, j + 3, k + 14, ancientbricks);
        world.setBlock(i + 14, j + 3, k + 15, ancientbricks);
        world.setBlock(i + 14, j + 4, k + 0, ancientbricks);
        world.setBlock(i + 14, j + 4, k + 15, ancientbricks);
        world.setBlock(i + 14, j + 5, k + 0, soulStone);
        world.setBlock(i + 14, j + 5, k + 15, soulStone);
        world.setBlock(i + 14, j + 6, k + 0, ancientstone);
        world.setBlock(i + 14, j + 6, k + 15, ancientstone);
        world.setBlock(i + 14, j + 7, k + 0, dungeonBricks);
        world.setBlock(i + 14, j + 7, k + 15, dungeonBricks);
        world.setBlock(i + 15, j + 0, k + 0, ancientbricks);
        world.setBlock(i + 15, j + 0, k + 1, ancientbricks);
        world.setBlock(i + 15, j + 0, k + 2, ancientbricks);
        world.setBlock(i + 15, j + 0, k + 3, ancientbricks);
        world.setBlock(i + 15, j + 0, k + 4, ancientbricks);
        world.setBlock(i + 15, j + 0, k + 5, ancientbricks);
        world.setBlock(i + 15, j + 0, k + 6, ancientbricks);
        world.setBlock(i + 15, j + 0, k + 7, ancientbricks);
        world.setBlock(i + 15, j + 0, k + 8, ancientbricks);
        world.setBlock(i + 15, j + 0, k + 9, ancientbricks);
        world.setBlock(i + 15, j + 0, k + 10, ancientbricks);
        world.setBlock(i + 15, j + 0, k + 11, ancientbricks);
        world.setBlock(i + 15, j + 0, k + 12, ancientbricks);
        world.setBlock(i + 15, j + 0, k + 13, ancientbricks);
        world.setBlock(i + 15, j + 0, k + 14, ancientbricks);
        world.setBlock(i + 15, j + 0, k + 15, ancientbricks);
        world.setBlock(i + 15, j + 1, k + 0, ancientbricks);
        world.setBlock(i + 15, j + 1, k + 1, ancientbricks);
        world.setBlock(i + 15, j + 1, k + 2, ancientbricks);
        world.setBlock(i + 15, j + 1, k + 3, ancientbricks);
        world.setBlock(i + 15, j + 1, k + 4, ancientbricks);
        world.setBlock(i + 15, j + 1, k + 5, ancientbricks);
        world.setBlock(i + 15, j + 1, k + 6, ancientbricks);
        world.setBlock(i + 15, j + 1, k + 9, ancientbricks);
        world.setBlock(i + 15, j + 1, k + 10, ancientbricks);
        world.setBlock(i + 15, j + 1, k + 11, ancientbricks);
        world.setBlock(i + 15, j + 1, k + 12, ancientbricks);
        world.setBlock(i + 15, j + 1, k + 13, ancientbricks);
        world.setBlock(i + 15, j + 1, k + 14, ancientbricks);
        world.setBlock(i + 15, j + 1, k + 15, ancientbricks);
        world.setBlock(i + 15, j + 2, k + 0, ancientbricks);
        world.setBlock(i + 15, j + 2, k + 1, ancientbricks);
        world.setBlock(i + 15, j + 2, k + 2, ancientbricks);
        world.setBlock(i + 15, j + 2, k + 3, ancientbricks);
        world.setBlock(i + 15, j + 2, k + 4, ancientbricks);
        world.setBlock(i + 15, j + 2, k + 5, ancientbricks);
        world.setBlock(i + 15, j + 2, k + 6, ancientbricks);
        world.setBlock(i + 15, j + 2, k + 9, ancientbricks);
        world.setBlock(i + 15, j + 2, k + 10, ancientbricks);
        world.setBlock(i + 15, j + 2, k + 11, ancientbricks);
        world.setBlock(i + 15, j + 2, k + 12, ancientbricks);
        world.setBlock(i + 15, j + 2, k + 13, ancientbricks);
        world.setBlock(i + 15, j + 2, k + 14, ancientbricks);
        world.setBlock(i + 15, j + 2, k + 15, ancientbricks);
        world.setBlock(i + 15, j + 3, k + 0, ancientbricks);
        world.setBlock(i + 15, j + 3, k + 1, ancientbricks);
        world.setBlock(i + 15, j + 3, k + 2, ancientbricks);
        world.setBlock(i + 15, j + 3, k + 3, ancientbricks);
        world.setBlock(i + 15, j + 3, k + 4, ancientbricks);
        world.setBlock(i + 15, j + 3, k + 5, ancientbricks);
        world.setBlock(i + 15, j + 3, k + 6, ancientbricks);
        world.setBlock(i + 15, j + 3, k + 7, ancientbricks);
        world.setBlock(i + 15, j + 3, k + 8, ancientbricks);
        world.setBlock(i + 15, j + 3, k + 9, ancientbricks);
        world.setBlock(i + 15, j + 3, k + 10, ancientbricks);
        world.setBlock(i + 15, j + 3, k + 11, ancientbricks);
        world.setBlock(i + 15, j + 3, k + 12, ancientbricks);
        world.setBlock(i + 15, j + 3, k + 13, ancientbricks);
        world.setBlock(i + 15, j + 3, k + 14, ancientbricks);
        world.setBlock(i + 15, j + 3, k + 15, ancientbricks);
        world.setBlock(i + 15, j + 4, k + 0, ancientbricks);
        world.setBlock(i + 15, j + 4, k + 1, ancientbricks);
        world.setBlock(i + 15, j + 4, k + 2, ancientbricks);
        world.setBlock(i + 15, j + 4, k + 3, ancientbricks);
        world.setBlock(i + 15, j + 4, k + 4, ancientbricks);
        world.setBlock(i + 15, j + 4, k + 5, ancientbricks);
        world.setBlock(i + 15, j + 4, k + 6, ancientbricks);
        world.setBlock(i + 15, j + 4, k + 7, ancientbricks);
        world.setBlock(i + 15, j + 4, k + 8, ancientbricks);
        world.setBlock(i + 15, j + 4, k + 9, ancientbricks);
        world.setBlock(i + 15, j + 4, k + 10, ancientbricks);
        world.setBlock(i + 15, j + 4, k + 11, ancientbricks);
        world.setBlock(i + 15, j + 4, k + 12, ancientbricks);
        world.setBlock(i + 15, j + 4, k + 13, ancientbricks);
        world.setBlock(i + 15, j + 4, k + 14, ancientbricks);
        world.setBlock(i + 15, j + 4, k + 15, ancientbricks);
        world.setBlock(i + 15, j + 5, k + 0, soulStone);
        world.setBlock(i + 15, j + 5, k + 1, soulStone);
        world.setBlock(i + 15, j + 5, k + 2, soulStone);
        world.setBlock(i + 15, j + 5, k + 3, soulStone);
        world.setBlock(i + 15, j + 5, k + 4, soulStone);
        world.setBlock(i + 15, j + 5, k + 5, soulStone);
        world.setBlock(i + 15, j + 5, k + 6, soulStone);
        world.setBlock(i + 15, j + 5, k + 7, soulStone);
        world.setBlock(i + 15, j + 5, k + 8, soulStone);
        world.setBlock(i + 15, j + 5, k + 9, soulStone);
        world.setBlock(i + 15, j + 5, k + 10, soulStone);
        world.setBlock(i + 15, j + 5, k + 11, soulStone);
        world.setBlock(i + 15, j + 5, k + 12, soulStone);
        world.setBlock(i + 15, j + 5, k + 13, soulStone);
        world.setBlock(i + 15, j + 5, k + 14, soulStone);
        world.setBlock(i + 15, j + 5, k + 15, soulStone);
        world.setBlock(i + 15, j + 6, k + 0, ancientstone);
        world.setBlock(i + 15, j + 6, k + 1, ancientstone);
        world.setBlock(i + 15, j + 6, k + 2, ancientstone);
        world.setBlock(i + 15, j + 6, k + 3, ancientstone);
        world.setBlock(i + 15, j + 6, k + 4, ancientstone);
        world.setBlock(i + 15, j + 6, k + 5, ancientstone);
        world.setBlock(i + 15, j + 6, k + 6, ancientstone);
        world.setBlock(i + 15, j + 6, k + 7, ancientstone);
        world.setBlock(i + 15, j + 6, k + 8, ancientstone);
        world.setBlock(i + 15, j + 6, k + 9, ancientstone);
        world.setBlock(i + 15, j + 6, k + 10, ancientstone);
        world.setBlock(i + 15, j + 6, k + 11, ancientstone);
        world.setBlock(i + 15, j + 6, k + 12, ancientstone);
        world.setBlock(i + 15, j + 6, k + 13, ancientstone);
        world.setBlock(i + 15, j + 6, k + 14, ancientstone);
        world.setBlock(i + 15, j + 6, k + 15, ancientstone);
        world.setBlock(i + 15, j + 7, k + 0, dungeonBricks);
        world.setBlock(i + 15, j + 7, k + 1, dungeonBricks);
        world.setBlock(i + 15, j + 7, k + 2, dungeonBricks);
        world.setBlock(i + 15, j + 7, k + 3, dungeonBricks);
        world.setBlock(i + 15, j + 7, k + 4, dungeonBricks);
        world.setBlock(i + 15, j + 7, k + 5, dungeonBricks);
        world.setBlock(i + 15, j + 7, k + 6, dungeonBricks);
        world.setBlock(i + 15, j + 7, k + 7, dungeonBricks);
        world.setBlock(i + 15, j + 7, k + 8, dungeonBricks);
        world.setBlock(i + 15, j + 7, k + 9, dungeonBricks);
        world.setBlock(i + 15, j + 7, k + 10, dungeonBricks);
        world.setBlock(i + 15, j + 7, k + 11, dungeonBricks);
        world.setBlock(i + 15, j + 7, k + 12, dungeonBricks);
        world.setBlock(i + 15, j + 7, k + 13, dungeonBricks);
        world.setBlock(i + 15, j + 7, k + 14, dungeonBricks);
        world.setBlock(i + 15, j + 7, k + 15, dungeonBricks);
        world.setBlock(i + 13, j + 2, k + 5, arcaniteTubes);
        world.setBlock(i + 9, j + 2, k + 5, arcaniteTubes);
        world.setBlock(i + 6, j + 2, k + 5, arcaniteTubes);
        world.setBlock(i + 4, j + 2, k + 5, arcaniteTubes);
        world.setBlock(i + 2, j + 2, k + 5, arcaniteTubes);
        return true;
    }
}