package net.divinerpg.dimensions.arcana.components;
import java.util.Random;

import net.divinerpg.dimensions.arcana.ArcanaChunk;
import net.divinerpg.utils.blocks.ArcanaBlocks;
import net.minecraft.block.Block;

public class DungeonComponent extends DungeonComponentBase {

    @Override
    public boolean generate(ArcanaChunk arcanaChunk, Random rand, int x, int y, int z) {

        Block heatTraps = ArcanaBlocks.heatTrap;
        Block dungeonBricks = ArcanaBlocks.degradedBrick;
        Block ancientbricks = ArcanaBlocks.ancientBrick;
        Block soulStone = ArcanaBlocks.soulStone;
        Block ancientStone = ArcanaBlocks.ancientStone;

        arcanaChunk.setBlock(x + 0, y + 0, z + 0, heatTraps);
        arcanaChunk.setBlock(x + 0, y + 0, z + 1, heatTraps);
        arcanaChunk.setBlock(x + 0, y + 0, z + 2, dungeonBricks);
        arcanaChunk.setBlock(x + 0, y + 0, z + 3, dungeonBricks);
        arcanaChunk.setBlock(x + 0, y + 0, z + 4, ancientbricks);
        arcanaChunk.setBlock(x + 0, y + 0, z + 5, ancientbricks);
        arcanaChunk.setBlock(x + 0, y + 0, z + 6, ancientbricks);
        arcanaChunk.setBlock(x + 0, y + 0, z + 7, ancientbricks);
        arcanaChunk.setBlock(x + 0, y + 0, z + 8, ancientbricks);
        arcanaChunk.setBlock(x + 0, y + 0, z + 9, ancientbricks);
        arcanaChunk.setBlock(x + 0, y + 0, z + 10, ancientbricks);
        arcanaChunk.setBlock(x + 0, y + 0, z + 11, ancientbricks);
        arcanaChunk.setBlock(x + 0, y + 0, z + 12, dungeonBricks);
        arcanaChunk.setBlock(x + 0, y + 0, z + 13, dungeonBricks);
        arcanaChunk.setBlock(x + 0, y + 0, z + 14, heatTraps);
        arcanaChunk.setBlock(x + 0, y + 0, z + 15, heatTraps);
        arcanaChunk.setBlock(x + 0, y + 1, z + 0, heatTraps);
        arcanaChunk.setBlock(x + 0, y + 1, z + 1, heatTraps);
        arcanaChunk.setBlock(x + 0, y + 1, z + 2, soulStone);
        arcanaChunk.setBlock(x + 0, y + 1, z + 3, soulStone);
        arcanaChunk.setBlock(x + 0, y + 1, z + 4, soulStone);
        arcanaChunk.setBlock(x + 0, y + 1, z + 5, soulStone);
        arcanaChunk.setBlock(x + 0, y + 1, z + 6, ancientStone);
        arcanaChunk.setBlock(x + 0, y + 1, z + 9, ancientStone);
        arcanaChunk.setBlock(x + 0, y + 1, z + 10, soulStone);
        arcanaChunk.setBlock(x + 0, y + 1, z + 11, soulStone);
        arcanaChunk.setBlock(x + 0, y + 1, z + 12, soulStone);
        arcanaChunk.setBlock(x + 0, y + 1, z + 13, soulStone);
        arcanaChunk.setBlock(x + 0, y + 1, z + 14, heatTraps);
        arcanaChunk.setBlock(x + 0, y + 1, z + 15, heatTraps);
        arcanaChunk.setBlock(x + 0, y + 2, z + 0, heatTraps);
        arcanaChunk.setBlock(x + 0, y + 2, z + 1, heatTraps);
        arcanaChunk.setBlock(x + 0, y + 2, z + 2, soulStone);
        arcanaChunk.setBlock(x + 0, y + 2, z + 3, soulStone);
        arcanaChunk.setBlock(x + 0, y + 2, z + 4, soulStone);
        arcanaChunk.setBlock(x + 0, y + 2, z + 5, soulStone);
        arcanaChunk.setBlock(x + 0, y + 2, z + 6, ArcanaBlocks.dungenLamp);
        arcanaChunk.setBlock(x + 0, y + 2, z + 9, ArcanaBlocks.dungenLamp);
        arcanaChunk.setBlock(x + 0, y + 2, z + 10, soulStone);
        arcanaChunk.setBlock(x + 0, y + 2, z + 11, soulStone);
        arcanaChunk.setBlock(x + 0, y + 2, z + 12, soulStone);
        arcanaChunk.setBlock(x + 0, y + 2, z + 13, soulStone);
        arcanaChunk.setBlock(x + 0, y + 2, z + 14, heatTraps);
        arcanaChunk.setBlock(x + 0, y + 2, z + 15, heatTraps);
        arcanaChunk.setBlock(x + 0, y + 3, z + 0, heatTraps);
        arcanaChunk.setBlock(x + 0, y + 3, z + 1, heatTraps);
        arcanaChunk.setBlock(x + 0, y + 3, z + 2, soulStone);
        arcanaChunk.setBlock(x + 0, y + 3, z + 3, soulStone);
        arcanaChunk.setBlock(x + 0, y + 3, z + 4, soulStone);
        arcanaChunk.setBlock(x + 0, y + 3, z + 5, soulStone);
        arcanaChunk.setBlock(x + 0, y + 3, z + 6, ancientStone);
        arcanaChunk.setBlock(x + 0, y + 3, z + 7, ArcanaBlocks.arcaniumPower);
        arcanaChunk.setBlock(x + 0, y + 3, z + 8, ArcanaBlocks.arcaniumPower);
        arcanaChunk.setBlock(x + 0, y + 3, z + 9, ancientStone);
        arcanaChunk.setBlock(x + 0, y + 3, z + 10, soulStone);
        arcanaChunk.setBlock(x + 0, y + 3, z + 11, soulStone);
        arcanaChunk.setBlock(x + 0, y + 3, z + 12, soulStone);
        arcanaChunk.setBlock(x + 0, y + 3, z + 13, soulStone);
        arcanaChunk.setBlock(x + 0, y + 3, z + 14, heatTraps);
        arcanaChunk.setBlock(x + 0, y + 3, z + 15, heatTraps);
        arcanaChunk.setBlock(x + 0, y + 4, z + 0, heatTraps);
        arcanaChunk.setBlock(x + 0, y + 4, z + 1, heatTraps);
        arcanaChunk.setBlock(x + 0, y + 4, z + 2, soulStone);
        arcanaChunk.setBlock(x + 0, y + 4, z + 3, soulStone);
        arcanaChunk.setBlock(x + 0, y + 4, z + 4, soulStone);
        arcanaChunk.setBlock(x + 0, y + 4, z + 5, soulStone);
        arcanaChunk.setBlock(x + 0, y + 4, z + 6, soulStone);
        arcanaChunk.setBlock(x + 0, y + 4, z + 7, soulStone);
        arcanaChunk.setBlock(x + 0, y + 4, z + 8, soulStone);
        arcanaChunk.setBlock(x + 0, y + 4, z + 9, soulStone);
        arcanaChunk.setBlock(x + 0, y + 4, z + 10, soulStone);
        arcanaChunk.setBlock(x + 0, y + 4, z + 11, soulStone);
        arcanaChunk.setBlock(x + 0, y + 4, z + 12, soulStone);
        arcanaChunk.setBlock(x + 0, y + 4, z + 13, soulStone);
        arcanaChunk.setBlock(x + 0, y + 4, z + 14, heatTraps);
        arcanaChunk.setBlock(x + 0, y + 4, z + 15, heatTraps);
        arcanaChunk.setBlock(x + 0, y + 5, z + 0, heatTraps);
        arcanaChunk.setBlock(x + 0, y + 5, z + 1, heatTraps);
        arcanaChunk.setBlock(x + 0, y + 5, z + 2, soulStone);
        arcanaChunk.setBlock(x + 0, y + 5, z + 3, soulStone);
        arcanaChunk.setBlock(x + 0, y + 5, z + 4, soulStone);
        arcanaChunk.setBlock(x + 0, y + 5, z + 5, soulStone);
        arcanaChunk.setBlock(x + 0, y + 5, z + 6, soulStone);
        arcanaChunk.setBlock(x + 0, y + 5, z + 7, soulStone);
        arcanaChunk.setBlock(x + 0, y + 5, z + 8, soulStone);
        arcanaChunk.setBlock(x + 0, y + 5, z + 9, soulStone);
        arcanaChunk.setBlock(x + 0, y + 5, z + 10, soulStone);
        arcanaChunk.setBlock(x + 0, y + 5, z + 11, soulStone);
        arcanaChunk.setBlock(x + 0, y + 5, z + 12, soulStone);
        arcanaChunk.setBlock(x + 0, y + 5, z + 13, soulStone);
        arcanaChunk.setBlock(x + 0, y + 5, z + 14, heatTraps);
        arcanaChunk.setBlock(x + 0, y + 5, z + 15, heatTraps);
        arcanaChunk.setBlock(x + 0, y + 6, z + 0, heatTraps);
        arcanaChunk.setBlock(x + 0, y + 6, z + 1, heatTraps);
        arcanaChunk.setBlock(x + 0, y + 6, z + 2, ancientStone);
        arcanaChunk.setBlock(x + 0, y + 6, z + 3, ancientStone);
        arcanaChunk.setBlock(x + 0, y + 6, z + 4, ancientStone);
        arcanaChunk.setBlock(x + 0, y + 6, z + 5, ancientStone);
        arcanaChunk.setBlock(x + 0, y + 6, z + 6, ancientStone);
        arcanaChunk.setBlock(x + 0, y + 6, z + 7, ancientStone);
        arcanaChunk.setBlock(x + 0, y + 6, z + 8, ancientStone);
        arcanaChunk.setBlock(x + 0, y + 6, z + 9, ancientStone);
        arcanaChunk.setBlock(x + 0, y + 6, z + 10, ancientStone);
        arcanaChunk.setBlock(x + 0, y + 6, z + 11, ancientStone);
        arcanaChunk.setBlock(x + 0, y + 6, z + 12, ancientStone);
        arcanaChunk.setBlock(x + 0, y + 6, z + 13, ancientStone);
        arcanaChunk.setBlock(x + 0, y + 6, z + 14, heatTraps);
        arcanaChunk.setBlock(x + 0, y + 6, z + 15, heatTraps);
        arcanaChunk.setBlock(x + 0, y + 7, z + 0, heatTraps);
        arcanaChunk.setBlock(x + 0, y + 7, z + 1, heatTraps);
        arcanaChunk.setBlock(x + 0, y + 7, z + 2, ancientStone);
        arcanaChunk.setBlock(x + 0, y + 7, z + 3, ancientStone);
        arcanaChunk.setBlock(x + 0, y + 7, z + 4, ancientStone);
        arcanaChunk.setBlock(x + 0, y + 7, z + 5, ancientStone);
        arcanaChunk.setBlock(x + 0, y + 7, z + 6, ancientStone);
        arcanaChunk.setBlock(x + 0, y + 7, z + 7, ancientStone);
        arcanaChunk.setBlock(x + 0, y + 7, z + 8, ancientStone);
        arcanaChunk.setBlock(x + 0, y + 7, z + 9, ancientStone);
        arcanaChunk.setBlock(x + 0, y + 7, z + 10, ancientStone);
        arcanaChunk.setBlock(x + 0, y + 7, z + 11, ancientStone);
        arcanaChunk.setBlock(x + 0, y + 7, z + 12, ancientStone);
        arcanaChunk.setBlock(x + 0, y + 7, z + 13, ancientStone);
        arcanaChunk.setBlock(x + 0, y + 7, z + 14, heatTraps);
        arcanaChunk.setBlock(x + 0, y + 7, z + 15, heatTraps);
        arcanaChunk.setBlock(x + 1, y + 0, z + 0, heatTraps);
        arcanaChunk.setBlock(x + 1, y + 0, z + 1, heatTraps);
        arcanaChunk.setBlock(x + 1, y + 0, z + 2, heatTraps);
        arcanaChunk.setBlock(x + 1, y + 0, z + 3, dungeonBricks);
        arcanaChunk.setBlock(x + 1, y + 0, z + 4, dungeonBricks);
        arcanaChunk.setBlock(x + 1, y + 0, z + 5, ancientbricks);
        arcanaChunk.setBlock(x + 1, y + 0, z + 6, ancientbricks);
        arcanaChunk.setBlock(x + 1, y + 0, z + 7, ancientbricks);
        arcanaChunk.setBlock(x + 1, y + 0, z + 8, ancientbricks);
        arcanaChunk.setBlock(x + 1, y + 0, z + 9, ancientbricks);
        arcanaChunk.setBlock(x + 1, y + 0, z + 10, ancientbricks);
        arcanaChunk.setBlock(x + 1, y + 0, z + 11, dungeonBricks);
        arcanaChunk.setBlock(x + 1, y + 0, z + 12, dungeonBricks);
        arcanaChunk.setBlock(x + 1, y + 0, z + 13, heatTraps);
        arcanaChunk.setBlock(x + 1, y + 0, z + 14, heatTraps);
        arcanaChunk.setBlock(x + 1, y + 0, z + 15, heatTraps);
        arcanaChunk.setBlock(x + 1, y + 1, z + 0, heatTraps);
        arcanaChunk.setBlock(x + 1, y + 1, z + 1, heatTraps);
        arcanaChunk.setBlock(x + 1, y + 1, z + 14, heatTraps);
        arcanaChunk.setBlock(x + 1, y + 1, z + 15, heatTraps);
        arcanaChunk.setBlock(x + 1, y + 2, z + 0, heatTraps);
        arcanaChunk.setBlock(x + 1, y + 2, z + 1, heatTraps);
        arcanaChunk.setBlock(x + 1, y + 2, z + 14, heatTraps);
        arcanaChunk.setBlock(x + 1, y + 2, z + 15, heatTraps);
        arcanaChunk.setBlock(x + 1, y + 3, z + 0, heatTraps);
        arcanaChunk.setBlock(x + 1, y + 3, z + 1, heatTraps);
        arcanaChunk.setBlock(x + 1, y + 3, z + 14, heatTraps);
        arcanaChunk.setBlock(x + 1, y + 3, z + 15, heatTraps);
        arcanaChunk.setBlock(x + 1, y + 4, z + 0, heatTraps);
        arcanaChunk.setBlock(x + 1, y + 4, z + 1, heatTraps);
        arcanaChunk.setBlock(x + 1, y + 4, z + 14, heatTraps);
        arcanaChunk.setBlock(x + 1, y + 4, z + 15, heatTraps);
        arcanaChunk.setBlock(x + 1, y + 5, z + 0, heatTraps);
        arcanaChunk.setBlock(x + 1, y + 5, z + 1, heatTraps);
        arcanaChunk.setBlock(x + 1, y + 5, z + 14, heatTraps);
        arcanaChunk.setBlock(x + 1, y + 5, z + 15, heatTraps);
        arcanaChunk.setBlock(x + 1, y + 6, z + 0, heatTraps);
        arcanaChunk.setBlock(x + 1, y + 6, z + 1, heatTraps);
        arcanaChunk.setBlock(x + 1, y + 6, z + 14, heatTraps);
        arcanaChunk.setBlock(x + 1, y + 6, z + 15, heatTraps);
        arcanaChunk.setBlock(x + 1, y + 7, z + 0, heatTraps);
        arcanaChunk.setBlock(x + 1, y + 7, z + 1, heatTraps);
        arcanaChunk.setBlock(x + 1, y + 7, z + 2, heatTraps);
        arcanaChunk.setBlock(x + 1, y + 7, z + 13, heatTraps);
        arcanaChunk.setBlock(x + 1, y + 7, z + 14, heatTraps);
        arcanaChunk.setBlock(x + 1, y + 7, z + 15, heatTraps);
        arcanaChunk.setBlock(x + 2, y + 0, z + 0, dungeonBricks);
        arcanaChunk.setBlock(x + 2, y + 0, z + 1, heatTraps);
        arcanaChunk.setBlock(x + 2, y + 0, z + 2, heatTraps);
        arcanaChunk.setBlock(x + 2, y + 0, z + 3, heatTraps);
        arcanaChunk.setBlock(x + 2, y + 0, z + 4, dungeonBricks);
        arcanaChunk.setBlock(x + 2, y + 0, z + 5, dungeonBricks);
        arcanaChunk.setBlock(x + 2, y + 0, z + 6, ancientbricks);
        arcanaChunk.setBlock(x + 2, y + 0, z + 7, ancientbricks);
        arcanaChunk.setBlock(x + 2, y + 0, z + 8, ancientbricks);
        arcanaChunk.setBlock(x + 2, y + 0, z + 9, ancientbricks);
        arcanaChunk.setBlock(x + 2, y + 0, z + 10, dungeonBricks);
        arcanaChunk.setBlock(x + 2, y + 0, z + 11, dungeonBricks);
        arcanaChunk.setBlock(x + 2, y + 0, z + 12, heatTraps);
        arcanaChunk.setBlock(x + 2, y + 0, z + 13, heatTraps);
        arcanaChunk.setBlock(x + 2, y + 0, z + 14, heatTraps);
        arcanaChunk.setBlock(x + 2, y + 0, z + 15, dungeonBricks);
        arcanaChunk.setBlock(x + 2, y + 1, z + 0, soulStone);
        arcanaChunk.setBlock(x + 2, y + 1, z + 7, heatTraps);
        arcanaChunk.setBlock(x + 2, y + 1, z + 8, heatTraps);
        arcanaChunk.setBlock(x + 2, y + 1, z + 15, soulStone);
        arcanaChunk.setBlock(x + 2, y + 2, z + 0, soulStone);
        arcanaChunk.setBlock(x + 2, y + 2, z + 15, soulStone);
        arcanaChunk.setBlock(x + 2, y + 3, z + 0, soulStone);
        arcanaChunk.setBlock(x + 2, y + 3, z + 15, soulStone);
        arcanaChunk.setBlock(x + 2, y + 4, z + 0, soulStone);
        arcanaChunk.setBlock(x + 2, y + 4, z + 15, soulStone);
        arcanaChunk.setBlock(x + 2, y + 5, z + 0, soulStone);
        arcanaChunk.setBlock(x + 2, y + 5, z + 15, soulStone);
        arcanaChunk.setBlock(x + 2, y + 6, z + 0, ancientStone);
        arcanaChunk.setBlock(x + 2, y + 6, z + 15, ancientStone);
        arcanaChunk.setBlock(x + 2, y + 7, z + 0, ancientStone);
        arcanaChunk.setBlock(x + 2, y + 7, z + 1, heatTraps);
        arcanaChunk.setBlock(x + 2, y + 7, z + 2, heatTraps);
        arcanaChunk.setBlock(x + 2, y + 7, z + 3, heatTraps);
        arcanaChunk.setBlock(x + 2, y + 7, z + 12, heatTraps);
        arcanaChunk.setBlock(x + 2, y + 7, z + 13, heatTraps);
        arcanaChunk.setBlock(x + 2, y + 7, z + 14, heatTraps);
        arcanaChunk.setBlock(x + 2, y + 7, z + 15, ancientStone);
        arcanaChunk.setBlock(x + 3, y + 0, z + 0, dungeonBricks);
        arcanaChunk.setBlock(x + 3, y + 0, z + 1, dungeonBricks);
        arcanaChunk.setBlock(x + 3, y + 0, z + 2, heatTraps);
        arcanaChunk.setBlock(x + 3, y + 0, z + 3, heatTraps);
        arcanaChunk.setBlock(x + 3, y + 0, z + 4, heatTraps);
        arcanaChunk.setBlock(x + 3, y + 0, z + 5, dungeonBricks);
        arcanaChunk.setBlock(x + 3, y + 0, z + 6, dungeonBricks);
        arcanaChunk.setBlock(x + 3, y + 0, z + 7, ancientbricks);
        arcanaChunk.setBlock(x + 3, y + 0, z + 8, ancientbricks);
        arcanaChunk.setBlock(x + 3, y + 0, z + 9, dungeonBricks);
        arcanaChunk.setBlock(x + 3, y + 0, z + 10, dungeonBricks);
        arcanaChunk.setBlock(x + 3, y + 0, z + 11, heatTraps);
        arcanaChunk.setBlock(x + 3, y + 0, z + 12, heatTraps);
        arcanaChunk.setBlock(x + 3, y + 0, z + 13, heatTraps);
        arcanaChunk.setBlock(x + 3, y + 0, z + 14, dungeonBricks);
        arcanaChunk.setBlock(x + 3, y + 0, z + 15, dungeonBricks);
        arcanaChunk.setBlock(x + 3, y + 1, z + 0, soulStone);
        arcanaChunk.setBlock(x + 3, y + 1, z + 15, soulStone);
        arcanaChunk.setBlock(x + 3, y + 2, z + 0, soulStone);
        arcanaChunk.setBlock(x + 3, y + 2, z + 15, soulStone);
        arcanaChunk.setBlock(x + 3, y + 3, z + 0, soulStone);
        arcanaChunk.setBlock(x + 3, y + 3, z + 15, soulStone);
        arcanaChunk.setBlock(x + 3, y + 4, z + 0, soulStone);
        arcanaChunk.setBlock(x + 3, y + 4, z + 15, soulStone);
        arcanaChunk.setBlock(x + 3, y + 5, z + 0, soulStone);
        arcanaChunk.setBlock(x + 3, y + 5, z + 15, soulStone);
        arcanaChunk.setBlock(x + 3, y + 6, z + 0, ancientStone);
        arcanaChunk.setBlock(x + 3, y + 6, z + 15, ancientStone);
        arcanaChunk.setBlock(x + 3, y + 7, z + 0, ancientStone);
        arcanaChunk.setBlock(x + 3, y + 7, z + 2, heatTraps);
        arcanaChunk.setBlock(x + 3, y + 7, z + 3, heatTraps);
        arcanaChunk.setBlock(x + 3, y + 7, z + 4, heatTraps);
        arcanaChunk.setBlock(x + 3, y + 7, z + 11, heatTraps);
        arcanaChunk.setBlock(x + 3, y + 7, z + 12, heatTraps);
        arcanaChunk.setBlock(x + 3, y + 7, z + 13, heatTraps);
        arcanaChunk.setBlock(x + 3, y + 7, z + 15, ancientStone);
        arcanaChunk.setBlock(x + 4, y + 0, z + 0, ancientbricks);
        arcanaChunk.setBlock(x + 4, y + 0, z + 1, dungeonBricks);
        arcanaChunk.setBlock(x + 4, y + 0, z + 2, dungeonBricks);
        arcanaChunk.setBlock(x + 4, y + 0, z + 3, heatTraps);
        arcanaChunk.setBlock(x + 4, y + 0, z + 4, heatTraps);
        arcanaChunk.setBlock(x + 4, y + 0, z + 5, heatTraps);
        arcanaChunk.setBlock(x + 4, y + 0, z + 6, dungeonBricks);
        arcanaChunk.setBlock(x + 4, y + 0, z + 7, dungeonBricks);
        arcanaChunk.setBlock(x + 4, y + 0, z + 8, dungeonBricks);
        arcanaChunk.setBlock(x + 4, y + 0, z + 9, dungeonBricks);
        arcanaChunk.setBlock(x + 4, y + 0, z + 10, heatTraps);
        arcanaChunk.setBlock(x + 4, y + 0, z + 11, heatTraps);
        arcanaChunk.setBlock(x + 4, y + 0, z + 12, heatTraps);
        arcanaChunk.setBlock(x + 4, y + 0, z + 13, dungeonBricks);
        arcanaChunk.setBlock(x + 4, y + 0, z + 14, dungeonBricks);
        arcanaChunk.setBlock(x + 4, y + 0, z + 15, ancientbricks);
        arcanaChunk.setBlock(x + 4, y + 1, z + 0, soulStone);
        arcanaChunk.setBlock(x + 4, y + 1, z + 15, soulStone);
        arcanaChunk.setBlock(x + 4, y + 2, z + 0, soulStone);
        arcanaChunk.setBlock(x + 4, y + 2, z + 15, soulStone);
        arcanaChunk.setBlock(x + 4, y + 3, z + 0, soulStone);
        arcanaChunk.setBlock(x + 4, y + 3, z + 15, soulStone);
        arcanaChunk.setBlock(x + 4, y + 4, z + 0, soulStone);
        arcanaChunk.setBlock(x + 4, y + 4, z + 15, soulStone);
        arcanaChunk.setBlock(x + 4, y + 5, z + 0, soulStone);
        arcanaChunk.setBlock(x + 4, y + 5, z + 15, soulStone);
        arcanaChunk.setBlock(x + 4, y + 6, z + 0, ancientStone);
        arcanaChunk.setBlock(x + 4, y + 6, z + 15, ancientStone);
        arcanaChunk.setBlock(x + 4, y + 7, z + 0, ancientStone);
        arcanaChunk.setBlock(x + 4, y + 7, z + 3, heatTraps);
        arcanaChunk.setBlock(x + 4, y + 7, z + 4, heatTraps);
        arcanaChunk.setBlock(x + 4, y + 7, z + 5, heatTraps);
        arcanaChunk.setBlock(x + 4, y + 7, z + 10, heatTraps);
        arcanaChunk.setBlock(x + 4, y + 7, z + 11, heatTraps);
        arcanaChunk.setBlock(x + 4, y + 7, z + 12, heatTraps);
        arcanaChunk.setBlock(x + 4, y + 7, z + 15, ancientStone);
        arcanaChunk.setBlock(x + 5, y + 0, z + 0, ancientbricks);
        arcanaChunk.setBlock(x + 5, y + 0, z + 1, ancientbricks);
        arcanaChunk.setBlock(x + 5, y + 0, z + 2, dungeonBricks);
        arcanaChunk.setBlock(x + 5, y + 0, z + 3, dungeonBricks);
        arcanaChunk.setBlock(x + 5, y + 0, z + 4, heatTraps);
        arcanaChunk.setBlock(x + 5, y + 0, z + 5, heatTraps);
        arcanaChunk.setBlock(x + 5, y + 0, z + 6, heatTraps);
        arcanaChunk.setBlock(x + 5, y + 0, z + 7, dungeonBricks);
        arcanaChunk.setBlock(x + 5, y + 0, z + 8, dungeonBricks);
        arcanaChunk.setBlock(x + 5, y + 0, z + 9, heatTraps);
        arcanaChunk.setBlock(x + 5, y + 0, z + 10, heatTraps);
        arcanaChunk.setBlock(x + 5, y + 0, z + 11, heatTraps);
        arcanaChunk.setBlock(x + 5, y + 0, z + 12, dungeonBricks);
        arcanaChunk.setBlock(x + 5, y + 0, z + 13, dungeonBricks);
        arcanaChunk.setBlock(x + 5, y + 0, z + 14, ancientbricks);
        arcanaChunk.setBlock(x + 5, y + 0, z + 15, ancientbricks);
        arcanaChunk.setBlock(x + 5, y + 1, z + 0, soulStone);
        arcanaChunk.setBlock(x + 5, y + 1, z + 15, soulStone);
        arcanaChunk.setBlock(x + 5, y + 2, z + 0, soulStone);
        arcanaChunk.setBlock(x + 5, y + 2, z + 15, soulStone);
        arcanaChunk.setBlock(x + 5, y + 3, z + 0, soulStone);
        arcanaChunk.setBlock(x + 5, y + 3, z + 15, soulStone);
        arcanaChunk.setBlock(x + 5, y + 4, z + 0, soulStone);
        arcanaChunk.setBlock(x + 5, y + 4, z + 15, soulStone);
        arcanaChunk.setBlock(x + 5, y + 5, z + 0, soulStone);
        arcanaChunk.setBlock(x + 5, y + 5, z + 15, soulStone);
        arcanaChunk.setBlock(x + 5, y + 6, z + 0, ancientStone);
        arcanaChunk.setBlock(x + 5, y + 6, z + 15, ancientStone);
        arcanaChunk.setBlock(x + 5, y + 7, z + 0, ancientStone);
        arcanaChunk.setBlock(x + 5, y + 7, z + 4, heatTraps);
        arcanaChunk.setBlock(x + 5, y + 7, z + 5, heatTraps);
        arcanaChunk.setBlock(x + 5, y + 7, z + 6, heatTraps);
        arcanaChunk.setBlock(x + 5, y + 7, z + 9, heatTraps);
        arcanaChunk.setBlock(x + 5, y + 7, z + 10, heatTraps);
        arcanaChunk.setBlock(x + 5, y + 7, z + 11, heatTraps);
        arcanaChunk.setBlock(x + 5, y + 7, z + 15, ancientStone);
        arcanaChunk.setBlock(x + 6, y + 0, z + 0, ancientbricks);
        arcanaChunk.setBlock(x + 6, y + 0, z + 1, ancientbricks);
        arcanaChunk.setBlock(x + 6, y + 0, z + 2, ancientbricks);
        arcanaChunk.setBlock(x + 6, y + 0, z + 3, dungeonBricks);
        arcanaChunk.setBlock(x + 6, y + 0, z + 4, dungeonBricks);
        arcanaChunk.setBlock(x + 6, y + 0, z + 5, heatTraps);
        arcanaChunk.setBlock(x + 6, y + 0, z + 6, heatTraps);
        arcanaChunk.setBlock(x + 6, y + 0, z + 7, heatTraps);
        arcanaChunk.setBlock(x + 6, y + 0, z + 8, heatTraps);
        arcanaChunk.setBlock(x + 6, y + 0, z + 9, heatTraps);
        arcanaChunk.setBlock(x + 6, y + 0, z + 10, heatTraps);
        arcanaChunk.setBlock(x + 6, y + 0, z + 11, dungeonBricks);
        arcanaChunk.setBlock(x + 6, y + 0, z + 12, dungeonBricks);
        arcanaChunk.setBlock(x + 6, y + 0, z + 13, ancientbricks);
        arcanaChunk.setBlock(x + 6, y + 0, z + 14, ancientbricks);
        arcanaChunk.setBlock(x + 6, y + 0, z + 15, ancientbricks);
        arcanaChunk.setBlock(x + 6, y + 1, z + 0, ancientStone);
        arcanaChunk.setBlock(x + 6, y + 1, z + 7, heatTraps);
        arcanaChunk.setBlock(x + 6, y + 1, z + 8, heatTraps);
        arcanaChunk.setBlock(x + 6, y + 1, z + 15, ancientStone);
        arcanaChunk.setBlock(x + 6, y + 2, z + 0, ArcanaBlocks.dungenLamp);
        arcanaChunk.setBlock(x + 6, y + 2, z + 7, heatTraps);
        arcanaChunk.setBlock(x + 6, y + 2, z + 8, heatTraps);
        arcanaChunk.setBlock(x + 6, y + 2, z + 15, ArcanaBlocks.dungenLamp);
        arcanaChunk.setBlock(x + 6, y + 3, z + 0, ancientStone);
        arcanaChunk.setBlock(x + 6, y + 3, z + 7, heatTraps);
        arcanaChunk.setBlock(x + 6, y + 3, z + 8, heatTraps);
        arcanaChunk.setBlock(x + 6, y + 3, z + 15, ancientStone);
        arcanaChunk.setBlock(x + 6, y + 4, z + 0, soulStone);
        arcanaChunk.setBlock(x + 6, y + 4, z + 7, heatTraps);
        arcanaChunk.setBlock(x + 6, y + 4, z + 8, heatTraps);
        arcanaChunk.setBlock(x + 6, y + 4, z + 15, soulStone);
        arcanaChunk.setBlock(x + 6, y + 5, z + 0, soulStone);
        arcanaChunk.setBlock(x + 6, y + 5, z + 7, heatTraps);
        arcanaChunk.setBlock(x + 6, y + 5, z + 8, heatTraps);
        arcanaChunk.setBlock(x + 6, y + 5, z + 15, soulStone);
        arcanaChunk.setBlock(x + 6, y + 6, z + 0, ancientStone);
        arcanaChunk.setBlock(x + 6, y + 6, z + 7, heatTraps);
        arcanaChunk.setBlock(x + 6, y + 6, z + 8, heatTraps);
        arcanaChunk.setBlock(x + 6, y + 6, z + 15, ancientStone);
        arcanaChunk.setBlock(x + 6, y + 7, z + 0, ancientStone);
        arcanaChunk.setBlock(x + 6, y + 7, z + 5, heatTraps);
        arcanaChunk.setBlock(x + 6, y + 7, z + 6, heatTraps);
        arcanaChunk.setBlock(x + 6, y + 7, z + 7, heatTraps);
        arcanaChunk.setBlock(x + 6, y + 7, z + 8, heatTraps);
        arcanaChunk.setBlock(x + 6, y + 7, z + 9, heatTraps);
        arcanaChunk.setBlock(x + 6, y + 7, z + 10, heatTraps);
        arcanaChunk.setBlock(x + 6, y + 7, z + 15, ancientStone);
        arcanaChunk.setBlock(x + 7, y + 0, z + 0, ancientbricks);
        arcanaChunk.setBlock(x + 7, y + 0, z + 1, ancientbricks);
        arcanaChunk.setBlock(x + 7, y + 0, z + 2, ancientbricks);
        arcanaChunk.setBlock(x + 7, y + 0, z + 3, ancientbricks);
        arcanaChunk.setBlock(x + 7, y + 0, z + 4, dungeonBricks);
        arcanaChunk.setBlock(x + 7, y + 0, z + 5, dungeonBricks);
        arcanaChunk.setBlock(x + 7, y + 0, z + 6, heatTraps);
        arcanaChunk.setBlock(x + 7, y + 0, z + 7, ArcanaBlocks.arcanitetubes);
        arcanaChunk.setBlock(x + 7, y + 0, z + 8, ArcanaBlocks.arcanitetubes);
        arcanaChunk.setBlock(x + 7, y + 0, z + 9, heatTraps);
        arcanaChunk.setBlock(x + 7, y + 0, z + 10, dungeonBricks);
        arcanaChunk.setBlock(x + 7, y + 0, z + 11, dungeonBricks);
        arcanaChunk.setBlock(x + 7, y + 0, z + 12, ancientbricks);
        arcanaChunk.setBlock(x + 7, y + 0, z + 13, ancientbricks);
        arcanaChunk.setBlock(x + 7, y + 0, z + 14, ancientbricks);
        arcanaChunk.setBlock(x + 7, y + 0, z + 15, ancientbricks);
        arcanaChunk.setBlock(x + 7, y + 1, z + 2, heatTraps);
        arcanaChunk.setBlock(x + 7, y + 1, z + 6, heatTraps);
        arcanaChunk.setBlock(x + 7, y + 1, z + 7, heatTraps);
        arcanaChunk.setBlock(x + 7, y + 1, z + 8, heatTraps);
        arcanaChunk.setBlock(x + 7, y + 1, z + 9, heatTraps);
        arcanaChunk.setBlock(x + 7, y + 1, z + 13, heatTraps);
        arcanaChunk.setBlock(x + 7, y + 2, z + 6, heatTraps);
        arcanaChunk.setBlock(x + 7, y + 2, z + 7, heatTraps);
        arcanaChunk.setBlock(x + 7, y + 2, z + 8, heatTraps);
        arcanaChunk.setBlock(x + 7, y + 2, z + 9, heatTraps);
        arcanaChunk.setBlock(x + 7, y + 3, z + 0, ArcanaBlocks.arcaniumPower);
        arcanaChunk.setBlock(x + 7, y + 3, z + 6, heatTraps);
        arcanaChunk.setBlock(x + 7, y + 3, z + 7, heatTraps);
        arcanaChunk.setBlock(x + 7, y + 3, z + 8, heatTraps);
        arcanaChunk.setBlock(x + 7, y + 3, z + 9, heatTraps);
        arcanaChunk.setBlock(x + 7, y + 3, z + 15, ArcanaBlocks.arcaniumPower);
        arcanaChunk.setBlock(x + 7, y + 4, z + 0, soulStone);
        arcanaChunk.setBlock(x + 7, y + 4, z + 6, heatTraps);
        arcanaChunk.setBlock(x + 7, y + 4, z + 7, heatTraps);
        arcanaChunk.setBlock(x + 7, y + 4, z + 8, heatTraps);
        arcanaChunk.setBlock(x + 7, y + 4, z + 9, heatTraps);
        arcanaChunk.setBlock(x + 7, y + 4, z + 15, soulStone);
        arcanaChunk.setBlock(x + 7, y + 5, z + 0, soulStone);
        arcanaChunk.setBlock(x + 7, y + 5, z + 6, heatTraps);
        arcanaChunk.setBlock(x + 7, y + 5, z + 7, heatTraps);
        arcanaChunk.setBlock(x + 7, y + 5, z + 8, heatTraps);
        arcanaChunk.setBlock(x + 7, y + 5, z + 9, heatTraps);
        arcanaChunk.setBlock(x + 7, y + 5, z + 15, soulStone);
        arcanaChunk.setBlock(x + 7, y + 6, z + 0, ancientStone);
        arcanaChunk.setBlock(x + 7, y + 6, z + 6, heatTraps);
        arcanaChunk.setBlock(x + 7, y + 6, z + 7, heatTraps);
        arcanaChunk.setBlock(x + 7, y + 6, z + 8, heatTraps);
        arcanaChunk.setBlock(x + 7, y + 6, z + 9, heatTraps);
        arcanaChunk.setBlock(x + 7, y + 6, z + 15, ancientStone);
        arcanaChunk.setBlock(x + 7, y + 7, z + 0, ancientStone);
        arcanaChunk.setBlock(x + 7, y + 7, z + 6, heatTraps);
        arcanaChunk.setBlock(x + 7, y + 7, z + 7, heatTraps);
        arcanaChunk.setBlock(x + 7, y + 7, z + 8, heatTraps);
        arcanaChunk.setBlock(x + 7, y + 7, z + 9, heatTraps);
        arcanaChunk.setBlock(x + 7, y + 7, z + 15, ancientStone);
        arcanaChunk.setBlock(x + 8, y + 0, z + 0, ancientbricks);
        arcanaChunk.setBlock(x + 8, y + 0, z + 1, ancientbricks);
        arcanaChunk.setBlock(x + 8, y + 0, z + 2, ancientbricks);
        arcanaChunk.setBlock(x + 8, y + 0, z + 3, ancientbricks);
        arcanaChunk.setBlock(x + 8, y + 0, z + 4, dungeonBricks);
        arcanaChunk.setBlock(x + 8, y + 0, z + 5, dungeonBricks);
        arcanaChunk.setBlock(x + 8, y + 0, z + 6, heatTraps);
        arcanaChunk.setBlock(x + 8, y + 0, z + 7, ArcanaBlocks.arcanitetubes);
        arcanaChunk.setBlock(x + 8, y + 0, z + 8, ArcanaBlocks.arcanitetubes);
        arcanaChunk.setBlock(x + 8, y + 0, z + 9, heatTraps);
        arcanaChunk.setBlock(x + 8, y + 0, z + 10, dungeonBricks);
        arcanaChunk.setBlock(x + 8, y + 0, z + 11, dungeonBricks);
        arcanaChunk.setBlock(x + 8, y + 0, z + 12, ancientbricks);
        arcanaChunk.setBlock(x + 8, y + 0, z + 13, ancientbricks);
        arcanaChunk.setBlock(x + 8, y + 0, z + 14, ancientbricks);
        arcanaChunk.setBlock(x + 8, y + 0, z + 15, ancientbricks);
        arcanaChunk.setBlock(x + 8, y + 1, z + 2, heatTraps);
        arcanaChunk.setBlock(x + 8, y + 1, z + 6, heatTraps);
        arcanaChunk.setBlock(x + 8, y + 1, z + 7, heatTraps);
        arcanaChunk.setBlock(x + 8, y + 1, z + 8, heatTraps);
        arcanaChunk.setBlock(x + 8, y + 1, z + 9, heatTraps);
        arcanaChunk.setBlock(x + 8, y + 1, z + 13, heatTraps);
        arcanaChunk.setBlock(x + 8, y + 2, z + 6, heatTraps);
        arcanaChunk.setBlock(x + 8, y + 2, z + 7, heatTraps);
        arcanaChunk.setBlock(x + 8, y + 2, z + 8, heatTraps);
        arcanaChunk.setBlock(x + 8, y + 2, z + 9, heatTraps);
        arcanaChunk.setBlock(x + 8, y + 3, z + 0, ArcanaBlocks.arcaniumPower);
        arcanaChunk.setBlock(x + 8, y + 3, z + 6, heatTraps);
        arcanaChunk.setBlock(x + 8, y + 3, z + 7, heatTraps);
        arcanaChunk.setBlock(x + 8, y + 3, z + 8, heatTraps);
        arcanaChunk.setBlock(x + 8, y + 3, z + 9, heatTraps);
        arcanaChunk.setBlock(x + 8, y + 3, z + 15, ArcanaBlocks.arcaniumPower);
        arcanaChunk.setBlock(x + 8, y + 4, z + 0, soulStone);
        arcanaChunk.setBlock(x + 8, y + 4, z + 6, heatTraps);
        arcanaChunk.setBlock(x + 8, y + 4, z + 7, heatTraps);
        arcanaChunk.setBlock(x + 8, y + 4, z + 8, heatTraps);
        arcanaChunk.setBlock(x + 8, y + 4, z + 9, heatTraps);
        arcanaChunk.setBlock(x + 8, y + 4, z + 15, soulStone);
        arcanaChunk.setBlock(x + 8, y + 5, z + 0, soulStone);
        arcanaChunk.setBlock(x + 8, y + 5, z + 6, heatTraps);
        arcanaChunk.setBlock(x + 8, y + 5, z + 7, heatTraps);
        arcanaChunk.setBlock(x + 8, y + 5, z + 8, heatTraps);
        arcanaChunk.setBlock(x + 8, y + 5, z + 9, heatTraps);
        arcanaChunk.setBlock(x + 8, y + 5, z + 15, soulStone);
        arcanaChunk.setBlock(x + 8, y + 6, z + 0, ancientStone);
        arcanaChunk.setBlock(x + 8, y + 6, z + 6, heatTraps);
        arcanaChunk.setBlock(x + 8, y + 6, z + 7, heatTraps);
        arcanaChunk.setBlock(x + 8, y + 6, z + 8, heatTraps);
        arcanaChunk.setBlock(x + 8, y + 6, z + 9, heatTraps);
        arcanaChunk.setBlock(x + 8, y + 6, z + 15, ancientStone);
        arcanaChunk.setBlock(x + 8, y + 7, z + 0, ancientStone);
        arcanaChunk.setBlock(x + 8, y + 7, z + 6, heatTraps);
        arcanaChunk.setBlock(x + 8, y + 7, z + 7, heatTraps);
        arcanaChunk.setBlock(x + 8, y + 7, z + 8, heatTraps);
        arcanaChunk.setBlock(x + 8, y + 7, z + 9, heatTraps);
        arcanaChunk.setBlock(x + 8, y + 7, z + 15, ancientStone);
        arcanaChunk.setBlock(x + 9, y + 0, z + 0, ancientbricks);
        arcanaChunk.setBlock(x + 9, y + 0, z + 1, ancientbricks);
        arcanaChunk.setBlock(x + 9, y + 0, z + 2, ancientbricks);
        arcanaChunk.setBlock(x + 9, y + 0, z + 3, dungeonBricks);
        arcanaChunk.setBlock(x + 9, y + 0, z + 4, dungeonBricks);
        arcanaChunk.setBlock(x + 9, y + 0, z + 5, heatTraps);
        arcanaChunk.setBlock(x + 9, y + 0, z + 6, heatTraps);
        arcanaChunk.setBlock(x + 9, y + 0, z + 7, heatTraps);
        arcanaChunk.setBlock(x + 9, y + 0, z + 8, heatTraps);
        arcanaChunk.setBlock(x + 9, y + 0, z + 9, heatTraps);
        arcanaChunk.setBlock(x + 9, y + 0, z + 10, heatTraps);
        arcanaChunk.setBlock(x + 9, y + 0, z + 11, dungeonBricks);
        arcanaChunk.setBlock(x + 9, y + 0, z + 12, dungeonBricks);
        arcanaChunk.setBlock(x + 9, y + 0, z + 13, ancientbricks);
        arcanaChunk.setBlock(x + 9, y + 0, z + 14, ancientbricks);
        arcanaChunk.setBlock(x + 9, y + 0, z + 15, ancientbricks);
        arcanaChunk.setBlock(x + 9, y + 1, z + 0, ancientStone);
        arcanaChunk.setBlock(x + 9, y + 1, z + 7, ArcanaBlocks.dungenSpawnerPrisoner);
        arcanaChunk.setBlock(x + 9, y + 1, z + 8, heatTraps);
        arcanaChunk.setBlock(x + 9, y + 1, z + 15, ancientStone);
        arcanaChunk.setBlock(x + 9, y + 2, z + 0, ArcanaBlocks.dungenLamp);
        arcanaChunk.setBlock(x + 9, y + 2, z + 7, heatTraps);
        arcanaChunk.setBlock(x + 9, y + 2, z + 8, heatTraps);
        arcanaChunk.setBlock(x + 9, y + 2, z + 15, ArcanaBlocks.dungenLamp);
        arcanaChunk.setBlock(x + 9, y + 3, z + 0, ancientStone);
        arcanaChunk.setBlock(x + 9, y + 3, z + 7, heatTraps);
        arcanaChunk.setBlock(x + 9, y + 3, z + 8, heatTraps);
        arcanaChunk.setBlock(x + 9, y + 3, z + 15, ancientStone);
        arcanaChunk.setBlock(x + 9, y + 4, z + 0, soulStone);
        arcanaChunk.setBlock(x + 9, y + 4, z + 7, heatTraps);
        arcanaChunk.setBlock(x + 9, y + 4, z + 8, heatTraps);
        arcanaChunk.setBlock(x + 9, y + 4, z + 15, soulStone);
        arcanaChunk.setBlock(x + 9, y + 5, z + 0, soulStone);
        arcanaChunk.setBlock(x + 9, y + 5, z + 7, heatTraps);
        arcanaChunk.setBlock(x + 9, y + 5, z + 8, heatTraps);
        arcanaChunk.setBlock(x + 9, y + 5, z + 15, soulStone);
        arcanaChunk.setBlock(x + 9, y + 6, z + 0, ancientStone);
        arcanaChunk.setBlock(x + 9, y + 6, z + 7, heatTraps);
        arcanaChunk.setBlock(x + 9, y + 6, z + 8, heatTraps);
        arcanaChunk.setBlock(x + 9, y + 6, z + 15, ancientStone);
        arcanaChunk.setBlock(x + 9, y + 7, z + 0, ancientStone);
        arcanaChunk.setBlock(x + 9, y + 7, z + 5, heatTraps);
        arcanaChunk.setBlock(x + 9, y + 7, z + 6, heatTraps);
        arcanaChunk.setBlock(x + 9, y + 7, z + 7, heatTraps);
        arcanaChunk.setBlock(x + 9, y + 7, z + 8, heatTraps);
        arcanaChunk.setBlock(x + 9, y + 7, z + 9, heatTraps);
        arcanaChunk.setBlock(x + 9, y + 7, z + 10, heatTraps);
        arcanaChunk.setBlock(x + 9, y + 7, z + 15, ancientStone);
        arcanaChunk.setBlock(x + 10, y + 0, z + 0, ancientbricks);
        arcanaChunk.setBlock(x + 10, y + 0, z + 1, ancientbricks);
        arcanaChunk.setBlock(x + 10, y + 0, z + 2, dungeonBricks);
        arcanaChunk.setBlock(x + 10, y + 0, z + 3, dungeonBricks);
        arcanaChunk.setBlock(x + 10, y + 0, z + 4, heatTraps);
        arcanaChunk.setBlock(x + 10, y + 0, z + 5, heatTraps);
        arcanaChunk.setBlock(x + 10, y + 0, z + 6, heatTraps);
        arcanaChunk.setBlock(x + 10, y + 0, z + 7, dungeonBricks);
        arcanaChunk.setBlock(x + 10, y + 0, z + 8, dungeonBricks);
        arcanaChunk.setBlock(x + 10, y + 0, z + 9, heatTraps);
        arcanaChunk.setBlock(x + 10, y + 0, z + 10, heatTraps);
        arcanaChunk.setBlock(x + 10, y + 0, z + 11, heatTraps);
        arcanaChunk.setBlock(x + 10, y + 0, z + 12, dungeonBricks);
        arcanaChunk.setBlock(x + 10, y + 0, z + 13, dungeonBricks);
        arcanaChunk.setBlock(x + 10, y + 0, z + 14, ancientbricks);
        arcanaChunk.setBlock(x + 10, y + 0, z + 15, ancientbricks);
        arcanaChunk.setBlock(x + 10, y + 1, z + 0, soulStone);
        arcanaChunk.setBlock(x + 10, y + 1, z + 15, soulStone);
        arcanaChunk.setBlock(x + 10, y + 2, z + 0, soulStone);
        arcanaChunk.setBlock(x + 10, y + 2, z + 15, soulStone);
        arcanaChunk.setBlock(x + 10, y + 3, z + 0, soulStone);
        arcanaChunk.setBlock(x + 10, y + 3, z + 15, soulStone);
        arcanaChunk.setBlock(x + 10, y + 4, z + 0, soulStone);
        arcanaChunk.setBlock(x + 10, y + 4, z + 15, soulStone);
        arcanaChunk.setBlock(x + 10, y + 5, z + 0, soulStone);
        arcanaChunk.setBlock(x + 10, y + 5, z + 15, soulStone);
        arcanaChunk.setBlock(x + 10, y + 6, z + 0, ancientStone);
        arcanaChunk.setBlock(x + 10, y + 6, z + 15, ancientStone);
        arcanaChunk.setBlock(x + 10, y + 7, z + 0, ancientStone);
        arcanaChunk.setBlock(x + 10, y + 7, z + 4, heatTraps);
        arcanaChunk.setBlock(x + 10, y + 7, z + 5, heatTraps);
        arcanaChunk.setBlock(x + 10, y + 7, z + 6, heatTraps);
        arcanaChunk.setBlock(x + 10, y + 7, z + 9, heatTraps);
        arcanaChunk.setBlock(x + 10, y + 7, z + 10, heatTraps);
        arcanaChunk.setBlock(x + 10, y + 7, z + 11, heatTraps);
        arcanaChunk.setBlock(x + 10, y + 7, z + 15, ancientStone);
        arcanaChunk.setBlock(x + 11, y + 0, z + 0, ancientbricks);
        arcanaChunk.setBlock(x + 11, y + 0, z + 1, dungeonBricks);
        arcanaChunk.setBlock(x + 11, y + 0, z + 2, dungeonBricks);
        arcanaChunk.setBlock(x + 11, y + 0, z + 3, heatTraps);
        arcanaChunk.setBlock(x + 11, y + 0, z + 4, heatTraps);
        arcanaChunk.setBlock(x + 11, y + 0, z + 5, heatTraps);
        arcanaChunk.setBlock(x + 11, y + 0, z + 6, dungeonBricks);
        arcanaChunk.setBlock(x + 11, y + 0, z + 7, dungeonBricks);
        arcanaChunk.setBlock(x + 11, y + 0, z + 8, dungeonBricks);
        arcanaChunk.setBlock(x + 11, y + 0, z + 9, dungeonBricks);
        arcanaChunk.setBlock(x + 11, y + 0, z + 10, heatTraps);
        arcanaChunk.setBlock(x + 11, y + 0, z + 11, heatTraps);
        arcanaChunk.setBlock(x + 11, y + 0, z + 12, heatTraps);
        arcanaChunk.setBlock(x + 11, y + 0, z + 13, dungeonBricks);
        arcanaChunk.setBlock(x + 11, y + 0, z + 14, dungeonBricks);
        arcanaChunk.setBlock(x + 11, y + 0, z + 15, ancientbricks);
        arcanaChunk.setBlock(x + 11, y + 1, z + 0, soulStone);
        arcanaChunk.setBlock(x + 11, y + 1, z + 15, soulStone);
        arcanaChunk.setBlock(x + 11, y + 2, z + 0, soulStone);
        arcanaChunk.setBlock(x + 11, y + 2, z + 15, soulStone);
        arcanaChunk.setBlock(x + 11, y + 3, z + 0, soulStone);
        arcanaChunk.setBlock(x + 11, y + 3, z + 15, soulStone);
        arcanaChunk.setBlock(x + 11, y + 4, z + 0, soulStone);
        arcanaChunk.setBlock(x + 11, y + 4, z + 15, soulStone);
        arcanaChunk.setBlock(x + 11, y + 5, z + 0, soulStone);
        arcanaChunk.setBlock(x + 11, y + 5, z + 15, soulStone);
        arcanaChunk.setBlock(x + 11, y + 6, z + 0, ancientStone);
        arcanaChunk.setBlock(x + 11, y + 6, z + 15, ancientStone);
        arcanaChunk.setBlock(x + 11, y + 7, z + 0, ancientStone);
        arcanaChunk.setBlock(x + 11, y + 7, z + 3, heatTraps);
        arcanaChunk.setBlock(x + 11, y + 7, z + 4, heatTraps);
        arcanaChunk.setBlock(x + 11, y + 7, z + 5, heatTraps);
        arcanaChunk.setBlock(x + 11, y + 7, z + 10, heatTraps);
        arcanaChunk.setBlock(x + 11, y + 7, z + 11, heatTraps);
        arcanaChunk.setBlock(x + 11, y + 7, z + 12, heatTraps);
        arcanaChunk.setBlock(x + 11, y + 7, z + 15, ancientStone);
        arcanaChunk.setBlock(x + 12, y + 0, z + 0, dungeonBricks);
        arcanaChunk.setBlock(x + 12, y + 0, z + 1, dungeonBricks);
        arcanaChunk.setBlock(x + 12, y + 0, z + 2, heatTraps);
        arcanaChunk.setBlock(x + 12, y + 0, z + 3, heatTraps);
        arcanaChunk.setBlock(x + 12, y + 0, z + 4, heatTraps);
        arcanaChunk.setBlock(x + 12, y + 0, z + 5, dungeonBricks);
        arcanaChunk.setBlock(x + 12, y + 0, z + 6, dungeonBricks);
        arcanaChunk.setBlock(x + 12, y + 0, z + 7, ancientbricks);
        arcanaChunk.setBlock(x + 12, y + 0, z + 8, ancientbricks);
        arcanaChunk.setBlock(x + 12, y + 0, z + 9, dungeonBricks);
        arcanaChunk.setBlock(x + 12, y + 0, z + 10, dungeonBricks);
        arcanaChunk.setBlock(x + 12, y + 0, z + 11, heatTraps);
        arcanaChunk.setBlock(x + 12, y + 0, z + 12, heatTraps);
        arcanaChunk.setBlock(x + 12, y + 0, z + 13, heatTraps);
        arcanaChunk.setBlock(x + 12, y + 0, z + 14, dungeonBricks);
        arcanaChunk.setBlock(x + 12, y + 0, z + 15, dungeonBricks);
        arcanaChunk.setBlock(x + 12, y + 1, z + 0, soulStone);
        arcanaChunk.setBlock(x + 12, y + 1, z + 15, soulStone);
        arcanaChunk.setBlock(x + 12, y + 2, z + 0, soulStone);
        arcanaChunk.setBlock(x + 12, y + 2, z + 15, soulStone);
        arcanaChunk.setBlock(x + 12, y + 3, z + 0, soulStone);
        arcanaChunk.setBlock(x + 12, y + 3, z + 15, soulStone);
        arcanaChunk.setBlock(x + 12, y + 4, z + 0, soulStone);
        arcanaChunk.setBlock(x + 12, y + 4, z + 15, soulStone);
        arcanaChunk.setBlock(x + 12, y + 5, z + 0, soulStone);
        arcanaChunk.setBlock(x + 12, y + 5, z + 15, soulStone);
        arcanaChunk.setBlock(x + 12, y + 6, z + 0, ancientStone);
        arcanaChunk.setBlock(x + 12, y + 6, z + 15, ancientStone);
        arcanaChunk.setBlock(x + 12, y + 7, z + 0, ancientStone);
        arcanaChunk.setBlock(x + 12, y + 7, z + 2, heatTraps);
        arcanaChunk.setBlock(x + 12, y + 7, z + 3, heatTraps);
        arcanaChunk.setBlock(x + 12, y + 7, z + 4, heatTraps);
        arcanaChunk.setBlock(x + 12, y + 7, z + 11, heatTraps);
        arcanaChunk.setBlock(x + 12, y + 7, z + 12, heatTraps);
        arcanaChunk.setBlock(x + 12, y + 7, z + 13, heatTraps);
        arcanaChunk.setBlock(x + 12, y + 7, z + 15, ancientStone);
        arcanaChunk.setBlock(x + 13, y + 0, z + 0, dungeonBricks);
        arcanaChunk.setBlock(x + 13, y + 0, z + 1, heatTraps);
        arcanaChunk.setBlock(x + 13, y + 0, z + 2, heatTraps);
        arcanaChunk.setBlock(x + 13, y + 0, z + 3, heatTraps);
        arcanaChunk.setBlock(x + 13, y + 0, z + 4, dungeonBricks);
        arcanaChunk.setBlock(x + 13, y + 0, z + 5, dungeonBricks);
        arcanaChunk.setBlock(x + 13, y + 0, z + 6, ancientbricks);
        arcanaChunk.setBlock(x + 13, y + 0, z + 7, ancientbricks);
        arcanaChunk.setBlock(x + 13, y + 0, z + 8, ancientbricks);
        arcanaChunk.setBlock(x + 13, y + 0, z + 9, ancientbricks);
        arcanaChunk.setBlock(x + 13, y + 0, z + 10, dungeonBricks);
        arcanaChunk.setBlock(x + 13, y + 0, z + 11, dungeonBricks);
        arcanaChunk.setBlock(x + 13, y + 0, z + 12, heatTraps);
        arcanaChunk.setBlock(x + 13, y + 0, z + 13, heatTraps);
        arcanaChunk.setBlock(x + 13, y + 0, z + 14, heatTraps);
        arcanaChunk.setBlock(x + 13, y + 0, z + 15, dungeonBricks);
        arcanaChunk.setBlock(x + 13, y + 1, z + 0, soulStone);
        arcanaChunk.setBlock(x + 13, y + 1, z + 7, heatTraps);
        arcanaChunk.setBlock(x + 13, y + 1, z + 8, heatTraps);
        arcanaChunk.setBlock(x + 13, y + 1, z + 15, soulStone);
        arcanaChunk.setBlock(x + 13, y + 2, z + 0, soulStone);
        arcanaChunk.setBlock(x + 13, y + 2, z + 15, soulStone);
        arcanaChunk.setBlock(x + 13, y + 3, z + 0, soulStone);
        arcanaChunk.setBlock(x + 13, y + 3, z + 15, soulStone);
        arcanaChunk.setBlock(x + 13, y + 4, z + 0, soulStone);
        arcanaChunk.setBlock(x + 13, y + 4, z + 15, soulStone);
        arcanaChunk.setBlock(x + 13, y + 5, z + 0, soulStone);
        arcanaChunk.setBlock(x + 13, y + 5, z + 15, soulStone);
        arcanaChunk.setBlock(x + 13, y + 6, z + 0, ancientStone);
        arcanaChunk.setBlock(x + 13, y + 6, z + 15, ancientStone);
        arcanaChunk.setBlock(x + 13, y + 7, z + 0, ancientStone);
        arcanaChunk.setBlock(x + 13, y + 7, z + 1, heatTraps);
        arcanaChunk.setBlock(x + 13, y + 7, z + 2, heatTraps);
        arcanaChunk.setBlock(x + 13, y + 7, z + 3, heatTraps);
        arcanaChunk.setBlock(x + 13, y + 7, z + 12, heatTraps);
        arcanaChunk.setBlock(x + 13, y + 7, z + 13, heatTraps);
        arcanaChunk.setBlock(x + 13, y + 7, z + 14, heatTraps);
        arcanaChunk.setBlock(x + 13, y + 7, z + 15, ancientStone);
        arcanaChunk.setBlock(x + 14, y + 0, z + 0, heatTraps);
        arcanaChunk.setBlock(x + 14, y + 0, z + 1, heatTraps);
        arcanaChunk.setBlock(x + 14, y + 0, z + 2, heatTraps);
        arcanaChunk.setBlock(x + 14, y + 0, z + 3, dungeonBricks);
        arcanaChunk.setBlock(x + 14, y + 0, z + 4, dungeonBricks);
        arcanaChunk.setBlock(x + 14, y + 0, z + 5, ancientbricks);
        arcanaChunk.setBlock(x + 14, y + 0, z + 6, ancientbricks);
        arcanaChunk.setBlock(x + 14, y + 0, z + 7, ancientbricks);
        arcanaChunk.setBlock(x + 14, y + 0, z + 8, ancientbricks);
        arcanaChunk.setBlock(x + 14, y + 0, z + 9, ancientbricks);
        arcanaChunk.setBlock(x + 14, y + 0, z + 10, ancientbricks);
        arcanaChunk.setBlock(x + 14, y + 0, z + 11, dungeonBricks);
        arcanaChunk.setBlock(x + 14, y + 0, z + 12, dungeonBricks);
        arcanaChunk.setBlock(x + 14, y + 0, z + 13, heatTraps);
        arcanaChunk.setBlock(x + 14, y + 0, z + 14, heatTraps);
        arcanaChunk.setBlock(x + 14, y + 0, z + 15, heatTraps);
        arcanaChunk.setBlock(x + 14, y + 1, z + 0, heatTraps);
        arcanaChunk.setBlock(x + 14, y + 1, z + 1, heatTraps);
        arcanaChunk.setBlock(x + 14, y + 1, z + 14, heatTraps);
        arcanaChunk.setBlock(x + 14, y + 1, z + 15, heatTraps);
        arcanaChunk.setBlock(x + 14, y + 2, z + 0, heatTraps);
        arcanaChunk.setBlock(x + 14, y + 2, z + 1, heatTraps);
        arcanaChunk.setBlock(x + 14, y + 2, z + 14, heatTraps);
        arcanaChunk.setBlock(x + 14, y + 2, z + 15, heatTraps);
        arcanaChunk.setBlock(x + 14, y + 3, z + 0, heatTraps);
        arcanaChunk.setBlock(x + 14, y + 3, z + 1, heatTraps);
        arcanaChunk.setBlock(x + 14, y + 3, z + 14, heatTraps);
        arcanaChunk.setBlock(x + 14, y + 3, z + 15, heatTraps);
        arcanaChunk.setBlock(x + 14, y + 4, z + 0, heatTraps);
        arcanaChunk.setBlock(x + 14, y + 4, z + 1, heatTraps);
        arcanaChunk.setBlock(x + 14, y + 4, z + 14, heatTraps);
        arcanaChunk.setBlock(x + 14, y + 4, z + 15, heatTraps);
        arcanaChunk.setBlock(x + 14, y + 5, z + 0, heatTraps);
        arcanaChunk.setBlock(x + 14, y + 5, z + 1, heatTraps);
        arcanaChunk.setBlock(x + 14, y + 5, z + 14, heatTraps);
        arcanaChunk.setBlock(x + 14, y + 5, z + 15, heatTraps);
        arcanaChunk.setBlock(x + 14, y + 6, z + 0, heatTraps);
        arcanaChunk.setBlock(x + 14, y + 6, z + 1, heatTraps);
        arcanaChunk.setBlock(x + 14, y + 6, z + 14, heatTraps);
        arcanaChunk.setBlock(x + 14, y + 6, z + 15, heatTraps);
        arcanaChunk.setBlock(x + 14, y + 7, z + 0, heatTraps);
        arcanaChunk.setBlock(x + 14, y + 7, z + 1, heatTraps);
        arcanaChunk.setBlock(x + 14, y + 7, z + 2, heatTraps);
        arcanaChunk.setBlock(x + 14, y + 7, z + 13, heatTraps);
        arcanaChunk.setBlock(x + 14, y + 7, z + 14, heatTraps);
        arcanaChunk.setBlock(x + 14, y + 7, z + 15, heatTraps);
        arcanaChunk.setBlock(x + 15, y + 0, z + 0, heatTraps);
        arcanaChunk.setBlock(x + 15, y + 0, z + 1, heatTraps);
        arcanaChunk.setBlock(x + 15, y + 0, z + 2, dungeonBricks);
        arcanaChunk.setBlock(x + 15, y + 0, z + 3, dungeonBricks);
        arcanaChunk.setBlock(x + 15, y + 0, z + 4, ancientbricks);
        arcanaChunk.setBlock(x + 15, y + 0, z + 5, ancientbricks);
        arcanaChunk.setBlock(x + 15, y + 0, z + 6, ancientbricks);
        arcanaChunk.setBlock(x + 15, y + 0, z + 7, ancientbricks);
        arcanaChunk.setBlock(x + 15, y + 0, z + 8, ancientbricks);
        arcanaChunk.setBlock(x + 15, y + 0, z + 9, ancientbricks);
        arcanaChunk.setBlock(x + 15, y + 0, z + 10, ancientbricks);
        arcanaChunk.setBlock(x + 15, y + 0, z + 11, ancientbricks);
        arcanaChunk.setBlock(x + 15, y + 0, z + 12, dungeonBricks);
        arcanaChunk.setBlock(x + 15, y + 0, z + 13, dungeonBricks);
        arcanaChunk.setBlock(x + 15, y + 0, z + 14, heatTraps);
        arcanaChunk.setBlock(x + 15, y + 0, z + 15, heatTraps);
        arcanaChunk.setBlock(x + 15, y + 1, z + 0, heatTraps);
        arcanaChunk.setBlock(x + 15, y + 1, z + 1, heatTraps);
        arcanaChunk.setBlock(x + 15, y + 1, z + 2, soulStone);
        arcanaChunk.setBlock(x + 15, y + 1, z + 3, soulStone);
        arcanaChunk.setBlock(x + 15, y + 1, z + 4, soulStone);
        arcanaChunk.setBlock(x + 15, y + 1, z + 5, soulStone);
        arcanaChunk.setBlock(x + 15, y + 1, z + 6, ancientStone);
        arcanaChunk.setBlock(x + 15, y + 1, z + 9, ancientStone);
        arcanaChunk.setBlock(x + 15, y + 1, z + 10, soulStone);
        arcanaChunk.setBlock(x + 15, y + 1, z + 11, soulStone);
        arcanaChunk.setBlock(x + 15, y + 1, z + 12, soulStone);
        arcanaChunk.setBlock(x + 15, y + 1, z + 13, soulStone);
        arcanaChunk.setBlock(x + 15, y + 1, z + 14, heatTraps);
        arcanaChunk.setBlock(x + 15, y + 1, z + 15, heatTraps);
        arcanaChunk.setBlock(x + 15, y + 2, z + 0, heatTraps);
        arcanaChunk.setBlock(x + 15, y + 2, z + 1, heatTraps);
        arcanaChunk.setBlock(x + 15, y + 2, z + 2, soulStone);
        arcanaChunk.setBlock(x + 15, y + 2, z + 3, soulStone);
        arcanaChunk.setBlock(x + 15, y + 2, z + 4, soulStone);
        arcanaChunk.setBlock(x + 15, y + 2, z + 5, soulStone);
        arcanaChunk.setBlock(x + 15, y + 2, z + 6, ArcanaBlocks.dungenLamp);
        arcanaChunk.setBlock(x + 15, y + 2, z + 9, ArcanaBlocks.dungenLamp);
        arcanaChunk.setBlock(x + 15, y + 2, z + 10, soulStone);
        arcanaChunk.setBlock(x + 15, y + 2, z + 11, soulStone);
        arcanaChunk.setBlock(x + 15, y + 2, z + 12, soulStone);
        arcanaChunk.setBlock(x + 15, y + 2, z + 13, soulStone);
        arcanaChunk.setBlock(x + 15, y + 2, z + 14, heatTraps);
        arcanaChunk.setBlock(x + 15, y + 2, z + 15, heatTraps);
        arcanaChunk.setBlock(x + 15, y + 3, z + 0, heatTraps);
        arcanaChunk.setBlock(x + 15, y + 3, z + 1, heatTraps);
        arcanaChunk.setBlock(x + 15, y + 3, z + 2, soulStone);
        arcanaChunk.setBlock(x + 15, y + 3, z + 3, soulStone);
        arcanaChunk.setBlock(x + 15, y + 3, z + 4, soulStone);
        arcanaChunk.setBlock(x + 15, y + 3, z + 5, soulStone);
        arcanaChunk.setBlock(x + 15, y + 3, z + 6, ancientStone);
        arcanaChunk.setBlock(x + 15, y + 3, z + 7, ArcanaBlocks.arcaniumPower);
        arcanaChunk.setBlock(x + 15, y + 3, z + 8, ArcanaBlocks.arcaniumPower);
        arcanaChunk.setBlock(x + 15, y + 3, z + 9, ancientStone);
        arcanaChunk.setBlock(x + 15, y + 3, z + 10, soulStone);
        arcanaChunk.setBlock(x + 15, y + 3, z + 11, soulStone);
        arcanaChunk.setBlock(x + 15, y + 3, z + 12, soulStone);
        arcanaChunk.setBlock(x + 15, y + 3, z + 13, soulStone);
        arcanaChunk.setBlock(x + 15, y + 3, z + 14, heatTraps);
        arcanaChunk.setBlock(x + 15, y + 3, z + 15, heatTraps);
        arcanaChunk.setBlock(x + 15, y + 4, z + 0, heatTraps);
        arcanaChunk.setBlock(x + 15, y + 4, z + 1, heatTraps);
        arcanaChunk.setBlock(x + 15, y + 4, z + 2, soulStone);
        arcanaChunk.setBlock(x + 15, y + 4, z + 3, soulStone);
        arcanaChunk.setBlock(x + 15, y + 4, z + 4, soulStone);
        arcanaChunk.setBlock(x + 15, y + 4, z + 5, soulStone);
        arcanaChunk.setBlock(x + 15, y + 4, z + 6, soulStone);
        arcanaChunk.setBlock(x + 15, y + 4, z + 7, soulStone);
        arcanaChunk.setBlock(x + 15, y + 4, z + 8, soulStone);
        arcanaChunk.setBlock(x + 15, y + 4, z + 9, soulStone);
        arcanaChunk.setBlock(x + 15, y + 4, z + 10, soulStone);
        arcanaChunk.setBlock(x + 15, y + 4, z + 11, soulStone);
        arcanaChunk.setBlock(x + 15, y + 4, z + 12, soulStone);
        arcanaChunk.setBlock(x + 15, y + 4, z + 13, soulStone);
        arcanaChunk.setBlock(x + 15, y + 4, z + 14, heatTraps);
        arcanaChunk.setBlock(x + 15, y + 4, z + 15, heatTraps);
        arcanaChunk.setBlock(x + 15, y + 5, z + 0, heatTraps);
        arcanaChunk.setBlock(x + 15, y + 5, z + 1, heatTraps);
        arcanaChunk.setBlock(x + 15, y + 5, z + 2, soulStone);
        arcanaChunk.setBlock(x + 15, y + 5, z + 3, soulStone);
        arcanaChunk.setBlock(x + 15, y + 5, z + 4, soulStone);
        arcanaChunk.setBlock(x + 15, y + 5, z + 5, soulStone);
        arcanaChunk.setBlock(x + 15, y + 5, z + 6, soulStone);
        arcanaChunk.setBlock(x + 15, y + 5, z + 7, soulStone);
        arcanaChunk.setBlock(x + 15, y + 5, z + 8, soulStone);
        arcanaChunk.setBlock(x + 15, y + 5, z + 9, soulStone);
        arcanaChunk.setBlock(x + 15, y + 5, z + 10, soulStone);
        arcanaChunk.setBlock(x + 15, y + 5, z + 11, soulStone);
        arcanaChunk.setBlock(x + 15, y + 5, z + 12, soulStone);
        arcanaChunk.setBlock(x + 15, y + 5, z + 13, soulStone);
        arcanaChunk.setBlock(x + 15, y + 5, z + 14, heatTraps);
        arcanaChunk.setBlock(x + 15, y + 5, z + 15, heatTraps);
        arcanaChunk.setBlock(x + 15, y + 6, z + 0, heatTraps);
        arcanaChunk.setBlock(x + 15, y + 6, z + 1, heatTraps);
        arcanaChunk.setBlock(x + 15, y + 6, z + 2, ancientStone);
        arcanaChunk.setBlock(x + 15, y + 6, z + 3, ancientStone);
        arcanaChunk.setBlock(x + 15, y + 6, z + 4, ancientStone);
        arcanaChunk.setBlock(x + 15, y + 6, z + 5, ancientStone);
        arcanaChunk.setBlock(x + 15, y + 6, z + 6, ancientStone);
        arcanaChunk.setBlock(x + 15, y + 6, z + 7, ancientStone);
        arcanaChunk.setBlock(x + 15, y + 6, z + 8, ancientStone);
        arcanaChunk.setBlock(x + 15, y + 6, z + 9, ancientStone);
        arcanaChunk.setBlock(x + 15, y + 6, z + 10, ancientStone);
        arcanaChunk.setBlock(x + 15, y + 6, z + 11, ancientStone);
        arcanaChunk.setBlock(x + 15, y + 6, z + 12, ancientStone);
        arcanaChunk.setBlock(x + 15, y + 6, z + 13, ancientStone);
        arcanaChunk.setBlock(x + 15, y + 6, z + 14, heatTraps);
        arcanaChunk.setBlock(x + 15, y + 6, z + 15, heatTraps);
        arcanaChunk.setBlock(x + 15, y + 7, z + 0, heatTraps);
        arcanaChunk.setBlock(x + 15, y + 7, z + 1, heatTraps);
        arcanaChunk.setBlock(x + 15, y + 7, z + 2, ancientStone);
        arcanaChunk.setBlock(x + 15, y + 7, z + 3, ancientStone);
        arcanaChunk.setBlock(x + 15, y + 7, z + 4, ancientStone);
        arcanaChunk.setBlock(x + 15, y + 7, z + 5, ancientStone);
        arcanaChunk.setBlock(x + 15, y + 7, z + 6, ancientStone);
        arcanaChunk.setBlock(x + 15, y + 7, z + 7, ancientStone);
        arcanaChunk.setBlock(x + 15, y + 7, z + 8, ancientStone);
        arcanaChunk.setBlock(x + 15, y + 7, z + 9, ancientStone);
        arcanaChunk.setBlock(x + 15, y + 7, z + 10, ancientStone);
        arcanaChunk.setBlock(x + 15, y + 7, z + 11, ancientStone);
        arcanaChunk.setBlock(x + 15, y + 7, z + 12, ancientStone);
        arcanaChunk.setBlock(x + 15, y + 7, z + 13, ancientStone);
        arcanaChunk.setBlock(x + 15, y + 7, z + 14, heatTraps);
        arcanaChunk.setBlock(x + 15, y + 7, z + 15, heatTraps);
        return true;
    }
}