package net.divinerpg.dimensions.vethea.layer3;
import java.util.Random;

import net.divinerpg.utils.blocks.VetheaBlocks;
import net.minecraft.world.World;
import net.minecraft.world.gen.feature.WorldGenerator;

public class KarosMadhouse extends WorldGenerator
{
	protected int[] GetValidSpawnBlocks() {
		return new int[] {
		};
	}
	
	public KarosMadhouse() { }

	public boolean generate(World world, Random rand, int i, int j, int k) {

		world.setBlock(i + 0, j + 0, k + 2, VetheaBlocks.karosBricks2);
		world.setBlock(i + 0, j + 0, k + 3, VetheaBlocks.karosBricks2);
		world.setBlock(i + 0, j + 0, k + 4, VetheaBlocks.karosBricks2);
		world.setBlock(i + 0, j + 0, k + 5, VetheaBlocks.karosBricks2);
		world.setBlock(i + 0, j + 0, k + 6, VetheaBlocks.karosBricks2);
		world.setBlock(i + 0, j + 0, k + 7, VetheaBlocks.karosBricks2);
		world.setBlock(i + 0, j + 0, k + 8, VetheaBlocks.karosBricks2);
		world.setBlock(i + 0, j + 0, k + 9, VetheaBlocks.karosBricks2);
		world.setBlock(i + 0, j + 0, k + 10, VetheaBlocks.karosBricks2);
		world.setBlock(i + 0, j + 0, k + 11, VetheaBlocks.karosBricks2);
		world.setBlock(i + 0, j + 1, k + 3, VetheaBlocks.karosBricks2);
		world.setBlock(i + 0, j + 1, k + 4, VetheaBlocks.karosBricks2);
		world.setBlock(i + 0, j + 1, k + 5, VetheaBlocks.karosBricks2);
		world.setBlock(i + 0, j + 1, k + 6, VetheaBlocks.karosBricks2);
		world.setBlock(i + 0, j + 1, k + 7, VetheaBlocks.karosBricks2);
		world.setBlock(i + 0, j + 1, k + 8, VetheaBlocks.karosBricks2);
		world.setBlock(i + 0, j + 1, k + 9, VetheaBlocks.karosBricks2);
		world.setBlock(i + 0, j + 1, k + 10, VetheaBlocks.karosBricks2);
		world.setBlock(i + 0, j + 1, k + 11, VetheaBlocks.karosBricks2);
		world.setBlock(i + 0, j + 2, k + 4, VetheaBlocks.karosBricks2);
		world.setBlock(i + 0, j + 2, k + 5, VetheaBlocks.karosBricks);
		world.setBlock(i + 0, j + 2, k + 6, VetheaBlocks.karosBricks);
		world.setBlock(i + 0, j + 2, k + 7, VetheaBlocks.karosBricks);
		world.setBlock(i + 0, j + 2, k + 8, VetheaBlocks.karosBricks);
		world.setBlock(i + 0, j + 2, k + 9, VetheaBlocks.karosBricks);
		world.setBlock(i + 0, j + 2, k + 10, VetheaBlocks.karosBricks);
		world.setBlock(i + 0, j + 2, k + 11, VetheaBlocks.karosBricks);
		world.setBlock(i + 1, j + 0, k + 4, VetheaBlocks.karosBricks2);
		world.setBlock(i + 1, j + 0, k + 5, VetheaBlocks.karosHeatTileRed);
		world.setBlock(i + 1, j + 0, k + 6, VetheaBlocks.karosHeatTileGreen);
		world.setBlock(i + 1, j + 0, k + 7, VetheaBlocks.karosHeatTileRed);
		world.setBlock(i + 1, j + 0, k + 8, VetheaBlocks.karosHeatTileGreen);
		world.setBlock(i + 1, j + 0, k + 9, VetheaBlocks.karosHeatTileRed);
		world.setBlock(i + 1, j + 0, k + 10, VetheaBlocks.karosHeatTileGreen);
		world.setBlock(i + 1, j + 0, k + 11, VetheaBlocks.karosBricks2);
		world.setBlock(i + 1, j + 1, k + 11, VetheaBlocks.karosBricks2);
		world.setBlock(i + 1, j + 2, k + 11, VetheaBlocks.karosBricks);
		world.setBlock(i + 1, j + 3, k + 5, VetheaBlocks.karosBricks2);
		world.setBlock(i + 1, j + 3, k + 6, VetheaBlocks.karosBricks2);
		world.setBlock(i + 1, j + 3, k + 7, VetheaBlocks.karosBricks2);
		world.setBlock(i + 1, j + 3, k + 8, VetheaBlocks.karosBricks2);
		world.setBlock(i + 1, j + 3, k + 9, VetheaBlocks.karosBricks2);
		world.setBlock(i + 1, j + 3, k + 10, VetheaBlocks.karosBricks2);
		world.setBlock(i + 2, j + 0, k + 4, VetheaBlocks.karosBricks2);
		world.setBlock(i + 2, j + 0, k + 5, VetheaBlocks.karosHeatTileGreen);
		world.setBlock(i + 2, j + 0, k + 6, VetheaBlocks.karosHeatTileRed);
		world.setBlock(i + 2, j + 0, k + 7, VetheaBlocks.karosHeatTileGreen);
		world.setBlock(i + 2, j + 0, k + 8, VetheaBlocks.karosHeatTileRed);
		world.setBlock(i + 2, j + 0, k + 9, VetheaBlocks.karosHeatTileGreen);
		world.setBlock(i + 2, j + 0, k + 10, VetheaBlocks.karosHeatTileRed);
		world.setBlock(i + 2, j + 0, k + 11, VetheaBlocks.karosBricks2);
		world.setBlock(i + 2, j + 1, k + 11, VetheaBlocks.karosBricks2);
		world.setBlock(i + 2, j + 2, k + 11, VetheaBlocks.karosBricks);
		world.setBlock(i + 2, j + 3, k + 5, VetheaBlocks.karosBricks2);
		world.setBlock(i + 2, j + 3, k + 6, VetheaBlocks.karosBricks2);
		world.setBlock(i + 2, j + 3, k + 7, VetheaBlocks.karosBricks2);
		world.setBlock(i + 2, j + 3, k + 8, VetheaBlocks.karosBricks2);
		world.setBlock(i + 2, j + 3, k + 9, VetheaBlocks.karosBricks2);
		world.setBlock(i + 2, j + 3, k + 10, VetheaBlocks.karosBricks2);
		world.setBlock(i + 3, j + 0, k + 2, VetheaBlocks.karosBricks2);
		world.setBlock(i + 3, j + 0, k + 3, VetheaBlocks.karosBricks2);
		world.setBlock(i + 3, j + 0, k + 4, VetheaBlocks.karosBricks2);
		world.setBlock(i + 3, j + 0, k + 5, VetheaBlocks.karosBricks2);
		world.setBlock(i + 3, j + 0, k + 6, VetheaBlocks.karosBricks2);
		world.setBlock(i + 3, j + 0, k + 7, VetheaBlocks.karosBricks2);
		world.setBlock(i + 3, j + 0, k + 8, VetheaBlocks.karosBricks2);
		world.setBlock(i + 3, j + 0, k + 9, VetheaBlocks.karosHeatTileRed);
		world.setBlock(i + 3, j + 0, k + 10, VetheaBlocks.karosHeatTileGreen);
		world.setBlock(i + 3, j + 0, k + 11, VetheaBlocks.karosBricks2);
		world.setBlock(i + 3, j + 1, k + 3, VetheaBlocks.karosBricks2);
		world.setBlock(i + 3, j + 1, k + 4, VetheaBlocks.karosBricks2);
		world.setBlock(i + 3, j + 1, k + 5, VetheaBlocks.karosBricks2);
		world.setBlock(i + 3, j + 1, k + 6, VetheaBlocks.karosBricks2);
		world.setBlock(i + 3, j + 1, k + 7, VetheaBlocks.karosBricks2);
		world.setBlock(i + 3, j + 1, k + 8, VetheaBlocks.karosBricks2);
		world.setBlock(i + 3, j + 1, k + 11, VetheaBlocks.karosBricks2);
		world.setBlock(i + 3, j + 2, k + 4, VetheaBlocks.karosBricks2);
		world.setBlock(i + 3, j + 2, k + 5, VetheaBlocks.karosBricks);
		world.setBlock(i + 3, j + 2, k + 6, VetheaBlocks.karosBricks);
		world.setBlock(i + 3, j + 2, k + 7, VetheaBlocks.karosBricks);
		world.setBlock(i + 3, j + 2, k + 8, VetheaBlocks.karosBricks);
		world.setBlock(i + 3, j + 2, k + 11, VetheaBlocks.karosBricks);
		world.setBlock(i + 3, j + 3, k + 9, VetheaBlocks.karosBricks2);
		world.setBlock(i + 3, j + 3, k + 10, VetheaBlocks.karosBricks2);
		world.setBlock(i + 4, j + 0, k + 8, VetheaBlocks.karosBricks2);
		world.setBlock(i + 4, j + 0, k + 9, VetheaBlocks.karosHeatTileGreen);
		world.setBlock(i + 4, j + 0, k + 10, VetheaBlocks.karosHeatTileRed);
		world.setBlock(i + 4, j + 0, k + 11, VetheaBlocks.karosBricks2);
		world.setBlock(i + 4, j + 1, k + 8, VetheaBlocks.karosBricks2);
		world.setBlock(i + 4, j + 1, k + 11, VetheaBlocks.karosBricks2);
		world.setBlock(i + 4, j + 2, k + 8, VetheaBlocks.karosBricks);
		world.setBlock(i + 4, j + 2, k + 11, VetheaBlocks.karosBricks);
		world.setBlock(i + 4, j + 3, k + 9, VetheaBlocks.karosBricks2);
		world.setBlock(i + 4, j + 3, k + 10, VetheaBlocks.karosBricks2);
		world.setBlock(i + 5, j + 0, k + 8, VetheaBlocks.karosBricks2);
		world.setBlock(i + 5, j + 0, k + 9, VetheaBlocks.karosHeatTileRed);
		world.setBlock(i + 5, j + 0, k + 10, VetheaBlocks.karosHeatTileGreen);
		world.setBlock(i + 5, j + 0, k + 11, VetheaBlocks.karosBricks2);
		world.setBlock(i + 5, j + 1, k + 8, VetheaBlocks.karosBricks2);
		world.setBlock(i + 5, j + 1, k + 11, VetheaBlocks.karosBricks2);
		world.setBlock(i + 5, j + 2, k + 8, VetheaBlocks.karosBricks);
		world.setBlock(i + 5, j + 2, k + 11, VetheaBlocks.karosBricks);
		world.setBlock(i + 5, j + 3, k + 9, VetheaBlocks.karosBricks2);
		world.setBlock(i + 5, j + 3, k + 10, VetheaBlocks.karosBricks2);
		world.setBlock(i + 6, j + 0, k + 8, VetheaBlocks.karosBricks2);
		world.setBlock(i + 6, j + 0, k + 9, VetheaBlocks.karosHeatTileGreen);
		world.setBlock(i + 6, j + 0, k + 10, VetheaBlocks.karosHeatTileRed);
		world.setBlock(i + 6, j + 0, k + 11, VetheaBlocks.karosBricks2);
		world.setBlock(i + 6, j + 1, k + 8, VetheaBlocks.karosBricks2);
		world.setBlock(i + 6, j + 1, k + 11, VetheaBlocks.karosBricks2);
		world.setBlock(i + 6, j + 2, k + 8, VetheaBlocks.karosBricks);
		world.setBlock(i + 6, j + 2, k + 11, VetheaBlocks.karosBricks);
		world.setBlock(i + 6, j + 3, k + 9, VetheaBlocks.karosBricks2);
		world.setBlock(i + 6, j + 3, k + 10, VetheaBlocks.karosBricks2);
		world.setBlock(i + 7, j + 0, k + 8, VetheaBlocks.karosBricks2);
		world.setBlock(i + 7, j + 0, k + 9, VetheaBlocks.karosHeatTileRed);
		world.setBlock(i + 7, j + 0, k + 10, VetheaBlocks.karosHeatTileGreen);
		world.setBlock(i + 7, j + 0, k + 11, VetheaBlocks.karosBricks2);
		world.setBlock(i + 7, j + 1, k + 8, VetheaBlocks.karosBricks2);
		world.setBlock(i + 7, j + 1, k + 11, VetheaBlocks.karosBricks2);
		world.setBlock(i + 7, j + 2, k + 8, VetheaBlocks.karosBricks);
		world.setBlock(i + 7, j + 2, k + 11, VetheaBlocks.karosBricks);
		world.setBlock(i + 7, j + 3, k + 9, VetheaBlocks.karosBricks2);
		world.setBlock(i + 7, j + 3, k + 10, VetheaBlocks.karosBricks2);
		world.setBlock(i + 8, j + 0, k + 8, VetheaBlocks.karosBricks2);
		world.setBlock(i + 8, j + 0, k + 9, VetheaBlocks.karosHeatTileGreen);
		world.setBlock(i + 8, j + 0, k + 10, VetheaBlocks.karosHeatTileRed);
		world.setBlock(i + 8, j + 0, k + 11, VetheaBlocks.karosBricks2);
		world.setBlock(i + 8, j + 1, k + 8, VetheaBlocks.karosBricks2);
		world.setBlock(i + 8, j + 1, k + 11, VetheaBlocks.karosBricks2);
		world.setBlock(i + 8, j + 2, k + 8, VetheaBlocks.karosBricks);
		world.setBlock(i + 8, j + 2, k + 11, VetheaBlocks.karosBricks);
		world.setBlock(i + 8, j + 3, k + 8, VetheaBlocks.karosBricks);
		world.setBlock(i + 8, j + 3, k + 9, VetheaBlocks.karosBricks2);
		world.setBlock(i + 8, j + 3, k + 10, VetheaBlocks.karosBricks2);
		world.setBlock(i + 8, j + 3, k + 11, VetheaBlocks.karosBricks);
		world.setBlock(i + 8, j + 4, k + 8, VetheaBlocks.karosBricks);
		world.setBlock(i + 8, j + 4, k + 11, VetheaBlocks.karosBricks);
		world.setBlock(i + 9, j + 0, k + 3, VetheaBlocks.karosBricks2);
		world.setBlock(i + 9, j + 0, k + 5, VetheaBlocks.karosBricks2);
		world.setBlock(i + 9, j + 0, k + 7, VetheaBlocks.karosBricks2);
		world.setBlock(i + 9, j + 0, k + 8, VetheaBlocks.karosBricks2);
		world.setBlock(i + 9, j + 0, k + 9, VetheaBlocks.karosHeatTileRed);
		world.setBlock(i + 9, j + 0, k + 10, VetheaBlocks.karosHeatTileGreen);
		world.setBlock(i + 9, j + 0, k + 11, VetheaBlocks.karosBricks2);
		world.setBlock(i + 9, j + 0, k + 12, VetheaBlocks.karosBricks2);
		world.setBlock(i + 9, j + 0, k + 14, VetheaBlocks.karosBricks2);
		world.setBlock(i + 9, j + 0, k + 16, VetheaBlocks.karosBricks2);
		world.setBlock(i + 9, j + 1, k + 3, VetheaBlocks.karosBricks2);
		world.setBlock(i + 9, j + 1, k + 5, VetheaBlocks.karosBricks2);
		world.setBlock(i + 9, j + 1, k + 7, VetheaBlocks.karosBricks2);
		world.setBlock(i + 9, j + 1, k + 8, VetheaBlocks.karosBricks2);
		world.setBlock(i + 9, j + 1, k + 11, VetheaBlocks.karosBricks2);
		world.setBlock(i + 9, j + 1, k + 12, VetheaBlocks.karosBricks2);
		world.setBlock(i + 9, j + 1, k + 14, VetheaBlocks.karosBricks2);
		world.setBlock(i + 9, j + 1, k + 16, VetheaBlocks.karosBricks2);
		world.setBlock(i + 9, j + 2, k + 3, VetheaBlocks.karosBricks2);
		world.setBlock(i + 9, j + 2, k + 5, VetheaBlocks.karosBricks2);
		world.setBlock(i + 9, j + 2, k + 7, VetheaBlocks.karosBricks2);
		world.setBlock(i + 9, j + 2, k + 8, VetheaBlocks.karosBricks2);
		world.setBlock(i + 9, j + 2, k + 11, VetheaBlocks.karosBricks2);
		world.setBlock(i + 9, j + 2, k + 12, VetheaBlocks.karosBricks2);
		world.setBlock(i + 9, j + 2, k + 14, VetheaBlocks.karosBricks2);
		world.setBlock(i + 9, j + 2, k + 16, VetheaBlocks.karosBricks2);
		world.setBlock(i + 9, j + 3, k + 8, VetheaBlocks.karosBricks2);
		world.setBlock(i + 9, j + 3, k + 9, VetheaBlocks.karosBricks2);
		world.setBlock(i + 9, j + 3, k + 10, VetheaBlocks.karosBricks2);
		world.setBlock(i + 9, j + 3, k + 11, VetheaBlocks.karosBricks2);
		world.setBlock(i + 9, j + 4, k + 8, VetheaBlocks.karosBricks);
		world.setBlock(i + 9, j + 4, k + 11, VetheaBlocks.karosBricks);
		world.setBlock(i + 10, j + 0, k + 1, VetheaBlocks.karosBricks2);
		world.setBlock(i + 10, j + 0, k + 2, VetheaBlocks.karosBricks2);
		world.setBlock(i + 10, j + 0, k + 3, VetheaBlocks.karosBricks2);
		world.setBlock(i + 10, j + 0, k + 4, VetheaBlocks.karosBricks2);
		world.setBlock(i + 10, j + 0, k + 5, VetheaBlocks.karosBricks2);
		world.setBlock(i + 10, j + 0, k + 6, VetheaBlocks.karosBricks2);
		world.setBlock(i + 10, j + 0, k + 7, VetheaBlocks.karosBricks2);
		world.setBlock(i + 10, j + 0, k + 8, VetheaBlocks.karosBricks2);
		world.setBlock(i + 10, j + 0, k + 9, VetheaBlocks.karosHeatTileGreen);
		world.setBlock(i + 10, j + 0, k + 10, VetheaBlocks.karosHeatTileRed);
		world.setBlock(i + 10, j + 0, k + 11, VetheaBlocks.karosBricks2);
		world.setBlock(i + 10, j + 0, k + 12, VetheaBlocks.karosBricks2);
		world.setBlock(i + 10, j + 0, k + 13, VetheaBlocks.karosBricks2);
		world.setBlock(i + 10, j + 0, k + 14, VetheaBlocks.karosBricks2);
		world.setBlock(i + 10, j + 0, k + 15, VetheaBlocks.karosBricks2);
		world.setBlock(i + 10, j + 0, k + 16, VetheaBlocks.karosBricks2);
		world.setBlock(i + 10, j + 0, k + 17, VetheaBlocks.karosBricks2);
		world.setBlock(i + 10, j + 0, k + 18, VetheaBlocks.karosBricks2);
		world.setBlock(i + 10, j + 1, k + 1, VetheaBlocks.karosBricks2);
		world.setBlock(i + 10, j + 1, k + 2, VetheaBlocks.karosBricks2);
		world.setBlock(i + 10, j + 1, k + 3, VetheaBlocks.karosBricks2);
		world.setBlock(i + 10, j + 1, k + 4, VetheaBlocks.karosBricks2);
		world.setBlock(i + 10, j + 1, k + 5, VetheaBlocks.karosBricks2);
		world.setBlock(i + 10, j + 1, k + 6, VetheaBlocks.karosBricks2);
		world.setBlock(i + 10, j + 1, k + 7, VetheaBlocks.karosBricks2);
		world.setBlock(i + 10, j + 1, k + 8, VetheaBlocks.karosBricks2);
		world.setBlock(i + 10, j + 1, k + 11, VetheaBlocks.karosBricks2);
		world.setBlock(i + 10, j + 1, k + 12, VetheaBlocks.karosBricks2);
		world.setBlock(i + 10, j + 1, k + 13, VetheaBlocks.karosBricks2);
		world.setBlock(i + 10, j + 1, k + 14, VetheaBlocks.karosBricks2);
		world.setBlock(i + 10, j + 1, k + 15, VetheaBlocks.karosBricks2);
		world.setBlock(i + 10, j + 1, k + 16, VetheaBlocks.karosBricks2);
		world.setBlock(i + 10, j + 1, k + 17, VetheaBlocks.karosBricks2);
		world.setBlock(i + 10, j + 1, k + 18, VetheaBlocks.karosBricks2);
		world.setBlock(i + 10, j + 2, k + 1, VetheaBlocks.karosBricks);
		world.setBlock(i + 10, j + 2, k + 2, VetheaBlocks.karosBricks);
		world.setBlock(i + 10, j + 2, k + 3, VetheaBlocks.karosCannon);
		world.setBlock(i + 10, j + 2, k + 4, VetheaBlocks.karosBricks);
		world.setBlock(i + 10, j + 2, k + 5, VetheaBlocks.karosCannon);
		world.setBlock(i + 10, j + 2, k + 6, VetheaBlocks.karosBricks);
		world.setBlock(i + 10, j + 2, k + 7, VetheaBlocks.karosCannon);
		world.setBlock(i + 10, j + 2, k + 8, VetheaBlocks.karosBricks2);
		world.setBlock(i + 10, j + 2, k + 11, VetheaBlocks.karosBricks2);
		world.setBlock(i + 10, j + 2, k + 12, VetheaBlocks.karosCannon);
		world.setBlock(i + 10, j + 2, k + 13, VetheaBlocks.karosBricks);
		world.setBlock(i + 10, j + 2, k + 14, VetheaBlocks.karosCannon);
		world.setBlock(i + 10, j + 2, k + 15, VetheaBlocks.karosBricks);
		world.setBlock(i + 10, j + 2, k + 16, VetheaBlocks.karosCannon);
		world.setBlock(i + 10, j + 2, k + 17, VetheaBlocks.karosBricks);
		world.setBlock(i + 10, j + 2, k + 18, VetheaBlocks.karosBricks);
		world.setBlock(i + 10, j + 3, k + 1, VetheaBlocks.karosBricks);
		world.setBlock(i + 10, j + 3, k + 2, VetheaBlocks.karosBricks);
		world.setBlock(i + 10, j + 3, k + 3, VetheaBlocks.karosBricks);
		world.setBlock(i + 10, j + 3, k + 4, VetheaBlocks.karosBricks);
		world.setBlock(i + 10, j + 3, k + 5, VetheaBlocks.karosBricks);
		world.setBlock(i + 10, j + 3, k + 6, VetheaBlocks.karosBricks);
		world.setBlock(i + 10, j + 3, k + 7, VetheaBlocks.karosBricks);
		world.setBlock(i + 10, j + 3, k + 8, VetheaBlocks.karosBricks2);
		world.setBlock(i + 10, j + 3, k + 9, VetheaBlocks.karosBricks2);
		world.setBlock(i + 10, j + 3, k + 10, VetheaBlocks.karosBricks2);
		world.setBlock(i + 10, j + 3, k + 11, VetheaBlocks.karosBricks2);
		world.setBlock(i + 10, j + 3, k + 12, VetheaBlocks.karosBricks);
		world.setBlock(i + 10, j + 3, k + 13, VetheaBlocks.karosBricks);
		world.setBlock(i + 10, j + 3, k + 14, VetheaBlocks.karosBricks);
		world.setBlock(i + 10, j + 3, k + 15, VetheaBlocks.karosBricks);
		world.setBlock(i + 10, j + 3, k + 16, VetheaBlocks.karosBricks);
		world.setBlock(i + 10, j + 3, k + 17, VetheaBlocks.karosBricks);
		world.setBlock(i + 10, j + 3, k + 18, VetheaBlocks.karosBricks);
		world.setBlock(i + 10, j + 4, k + 8, VetheaBlocks.karosBricks);
		world.setBlock(i + 10, j + 4, k + 11, VetheaBlocks.karosBricks);
		world.setBlock(i + 11, j + 0, k + 1, VetheaBlocks.karosBricks2);
		world.setBlock(i + 11, j + 0, k + 2, VetheaBlocks.karosHeatTileGreen);
		world.setBlock(i + 11, j + 0, k + 3, VetheaBlocks.karosHeatTileGreen);
		world.setBlock(i + 11, j + 0, k + 4, VetheaBlocks.karosHeatTileRed);
		world.setBlock(i + 11, j + 0, k + 5, VetheaBlocks.karosHeatTileRed);
		world.setBlock(i + 11, j + 0, k + 6, VetheaBlocks.karosHeatTileGreen);
		world.setBlock(i + 11, j + 0, k + 7, VetheaBlocks.karosHeatTileGreen);
		world.setBlock(i + 11, j + 0, k + 8, VetheaBlocks.karosHeatTileRed);
		world.setBlock(i + 11, j + 0, k + 9, VetheaBlocks.karosHeatTileRed);
		world.setBlock(i + 11, j + 0, k + 10, VetheaBlocks.karosHeatTileGreen);
		world.setBlock(i + 11, j + 0, k + 11, VetheaBlocks.karosHeatTileGreen);
		world.setBlock(i + 11, j + 0, k + 12, VetheaBlocks.karosHeatTileRed);
		world.setBlock(i + 11, j + 0, k + 13, VetheaBlocks.karosHeatTileRed);
		world.setBlock(i + 11, j + 0, k + 14, VetheaBlocks.karosHeatTileGreen);
		world.setBlock(i + 11, j + 0, k + 15, VetheaBlocks.karosHeatTileGreen);
		world.setBlock(i + 11, j + 0, k + 16, VetheaBlocks.karosHeatTileRed);
		world.setBlock(i + 11, j + 0, k + 17, VetheaBlocks.karosHeatTileRed);
		world.setBlock(i + 11, j + 0, k + 18, VetheaBlocks.karosBricks2);
		world.setBlock(i + 11, j + 1, k + 1, VetheaBlocks.karosBricks2);
		world.setBlock(i + 11, j + 1, k + 18, VetheaBlocks.karosBricks2);
		world.setBlock(i + 11, j + 2, k + 1, VetheaBlocks.karosBricks);
		world.setBlock(i + 11, j + 2, k + 18, VetheaBlocks.karosBricks);
		world.setBlock(i + 11, j + 3, k + 1, VetheaBlocks.karosBricks);
		world.setBlock(i + 11, j + 3, k + 18, VetheaBlocks.karosBricks);
		world.setBlock(i + 11, j + 4, k + 2, VetheaBlocks.karosBricks);
		world.setBlock(i + 11, j + 4, k + 3, VetheaBlocks.karosBricks);
		world.setBlock(i + 11, j + 4, k + 4, VetheaBlocks.karosBricks);
		world.setBlock(i + 11, j + 4, k + 5, VetheaBlocks.karosBricks);
		world.setBlock(i + 11, j + 4, k + 6, VetheaBlocks.karosBricks);
		world.setBlock(i + 11, j + 4, k + 7, VetheaBlocks.karosBricks);
		world.setBlock(i + 11, j + 4, k + 8, VetheaBlocks.karosBricks);
		world.setBlock(i + 11, j + 4, k + 9, VetheaBlocks.karosBricks);
		world.setBlock(i + 11, j + 4, k + 10, VetheaBlocks.karosBricks);
		world.setBlock(i + 11, j + 4, k + 11, VetheaBlocks.karosBricks);
		world.setBlock(i + 11, j + 4, k + 12, VetheaBlocks.karosBricks);
		world.setBlock(i + 11, j + 4, k + 13, VetheaBlocks.karosBricks);
		world.setBlock(i + 11, j + 4, k + 14, VetheaBlocks.karosBricks);
		world.setBlock(i + 11, j + 4, k + 15, VetheaBlocks.karosBricks);
		world.setBlock(i + 11, j + 4, k + 16, VetheaBlocks.karosBricks);
		world.setBlock(i + 11, j + 4, k + 17, VetheaBlocks.karosBricks);
		world.setBlock(i + 12, j + 0, k + 0, VetheaBlocks.karosBricks2);
		world.setBlock(i + 12, j + 0, k + 1, VetheaBlocks.karosBricks2);
		world.setBlock(i + 12, j + 0, k + 2, VetheaBlocks.karosHeatTileGreen);
		world.setBlock(i + 12, j + 0, k + 3, VetheaBlocks.karosHeatTileGreen);
		world.setBlock(i + 12, j + 0, k + 4, VetheaBlocks.karosHeatTileRed);
		world.setBlock(i + 12, j + 0, k + 5, VetheaBlocks.karosHeatTileRed);
		world.setBlock(i + 12, j + 0, k + 6, VetheaBlocks.karosHeatTileGreen);
		world.setBlock(i + 12, j + 0, k + 7, VetheaBlocks.karosHeatTileGreen);
		world.setBlock(i + 12, j + 0, k + 8, VetheaBlocks.karosHeatTileRed);
		world.setBlock(i + 12, j + 0, k + 9, VetheaBlocks.karosHeatTileRed);
		world.setBlock(i + 12, j + 0, k + 10, VetheaBlocks.karosHeatTileGreen);
		world.setBlock(i + 12, j + 0, k + 11, VetheaBlocks.karosHeatTileGreen);
		world.setBlock(i + 12, j + 0, k + 12, VetheaBlocks.karosHeatTileRed);
		world.setBlock(i + 12, j + 0, k + 13, VetheaBlocks.karosHeatTileRed);
		world.setBlock(i + 12, j + 0, k + 14, VetheaBlocks.karosHeatTileGreen);
		world.setBlock(i + 12, j + 0, k + 15, VetheaBlocks.karosHeatTileGreen);
		world.setBlock(i + 12, j + 0, k + 16, VetheaBlocks.karosHeatTileRed);
		world.setBlock(i + 12, j + 0, k + 17, VetheaBlocks.karosHeatTileRed);
		world.setBlock(i + 12, j + 0, k + 18, VetheaBlocks.karosBricks2);
		world.setBlock(i + 12, j + 0, k + 19, VetheaBlocks.karosBricks2);
		world.setBlock(i + 12, j + 1, k + 0, VetheaBlocks.karosBricks2);
		world.setBlock(i + 12, j + 1, k + 1, VetheaBlocks.karosBricks2);
		world.setBlock(i + 12, j + 1, k + 18, VetheaBlocks.karosBricks2);
		world.setBlock(i + 12, j + 1, k + 19, VetheaBlocks.karosBricks2);
		world.setBlock(i + 12, j + 2, k + 0, VetheaBlocks.karosBricks2);
		world.setBlock(i + 12, j + 2, k + 1, VetheaBlocks.karosCannon);
		world.setBlock(i + 12, j + 2, k + 18, VetheaBlocks.karosCannon);
		world.setBlock(i + 12, j + 2, k + 19, VetheaBlocks.karosBricks2);
		world.setBlock(i + 12, j + 3, k + 1, VetheaBlocks.karosBricks);
		world.setBlock(i + 12, j + 3, k + 18, VetheaBlocks.karosBricks);
		world.setBlock(i + 12, j + 4, k + 2, VetheaBlocks.karosBricks);
		world.setBlock(i + 12, j + 4, k + 17, VetheaBlocks.karosBricks);
		world.setBlock(i + 12, j + 5, k + 3, VetheaBlocks.karosBricks);
		world.setBlock(i + 12, j + 5, k + 4, VetheaBlocks.karosBricks);
		world.setBlock(i + 12, j + 5, k + 5, VetheaBlocks.karosBricks);
		world.setBlock(i + 12, j + 5, k + 6, VetheaBlocks.karosBricks);
		world.setBlock(i + 12, j + 5, k + 7, VetheaBlocks.karosBricks);
		world.setBlock(i + 12, j + 5, k + 8, VetheaBlocks.karosBricks);
		world.setBlock(i + 12, j + 5, k + 9, VetheaBlocks.karosBricks);
		world.setBlock(i + 12, j + 5, k + 10, VetheaBlocks.karosBricks);
		world.setBlock(i + 12, j + 5, k + 11, VetheaBlocks.karosBricks);
		world.setBlock(i + 12, j + 5, k + 12, VetheaBlocks.karosBricks);
		world.setBlock(i + 12, j + 5, k + 13, VetheaBlocks.karosBricks);
		world.setBlock(i + 12, j + 5, k + 14, VetheaBlocks.karosBricks);
		world.setBlock(i + 12, j + 5, k + 15, VetheaBlocks.karosBricks);
		world.setBlock(i + 12, j + 5, k + 16, VetheaBlocks.karosBricks);
		world.setBlock(i + 13, j + 0, k + 1, VetheaBlocks.karosBricks2);
		world.setBlock(i + 13, j + 0, k + 2, VetheaBlocks.karosHeatTileRed);
		world.setBlock(i + 13, j + 0, k + 3, VetheaBlocks.karosHeatTileRed);
		world.setBlock(i + 13, j + 0, k + 4, VetheaBlocks.karosHeatTileGreen);
		world.setBlock(i + 13, j + 0, k + 5, VetheaBlocks.karosHeatTileGreen);
		world.setBlock(i + 13, j + 0, k + 6, VetheaBlocks.karosHeatTileRed);
		world.setBlock(i + 13, j + 0, k + 7, VetheaBlocks.karosHeatTileRed);
		world.setBlock(i + 13, j + 0, k + 8, VetheaBlocks.karosHeatTileGreen);
		world.setBlock(i + 13, j + 0, k + 9, VetheaBlocks.karosHeatTileGreen);
		world.setBlock(i + 13, j + 0, k + 10, VetheaBlocks.karosHeatTileRed);
		world.setBlock(i + 13, j + 0, k + 11, VetheaBlocks.karosHeatTileRed);
		world.setBlock(i + 13, j + 0, k + 12, VetheaBlocks.karosHeatTileGreen);
		world.setBlock(i + 13, j + 0, k + 13, VetheaBlocks.karosHeatTileGreen);
		world.setBlock(i + 13, j + 0, k + 14, VetheaBlocks.karosHeatTileRed);
		world.setBlock(i + 13, j + 0, k + 15, VetheaBlocks.karosHeatTileRed);
		world.setBlock(i + 13, j + 0, k + 16, VetheaBlocks.karosHeatTileGreen);
		world.setBlock(i + 13, j + 0, k + 17, VetheaBlocks.karosHeatTileGreen);
		world.setBlock(i + 13, j + 0, k + 18, VetheaBlocks.karosBricks2);
		world.setBlock(i + 13, j + 1, k + 1, VetheaBlocks.karosBricks2);
		world.setBlock(i + 13, j + 1, k + 18, VetheaBlocks.karosBricks2);
		world.setBlock(i + 13, j + 2, k + 1, VetheaBlocks.karosBricks);
		world.setBlock(i + 13, j + 2, k + 18, VetheaBlocks.karosBricks);
		world.setBlock(i + 13, j + 3, k + 1, VetheaBlocks.karosBricks);
		world.setBlock(i + 13, j + 3, k + 18, VetheaBlocks.karosBricks);
		world.setBlock(i + 13, j + 4, k + 2, VetheaBlocks.karosBricks);
		world.setBlock(i + 13, j + 4, k + 4, VetheaBlocks.helioticBeam);
		world.setBlock(i + 13, j + 4, k + 5, VetheaBlocks.helioticBeam);
		world.setBlock(i + 13, j + 4, k + 6, VetheaBlocks.helioticBeam);
		world.setBlock(i + 13, j + 4, k + 14, VetheaBlocks.helioticBeam);
		world.setBlock(i + 13, j + 4, k + 15, VetheaBlocks.helioticBeam);
		world.setBlock(i + 13, j + 4, k + 16, VetheaBlocks.helioticBeam);
		world.setBlock(i + 13, j + 4, k + 17, VetheaBlocks.karosBricks);
		world.setBlock(i + 13, j + 5, k + 3, VetheaBlocks.karosBricks);
		world.setBlock(i + 13, j + 5, k + 4, VetheaBlocks.karosBricks2);
		world.setBlock(i + 13, j + 5, k + 5, VetheaBlocks.karosBricks2);
		world.setBlock(i + 13, j + 5, k + 6, VetheaBlocks.karosBricks2);
		world.setBlock(i + 13, j + 5, k + 7, VetheaBlocks.karosBricks2);
		world.setBlock(i + 13, j + 5, k + 8, VetheaBlocks.karosBricks2);
		world.setBlock(i + 13, j + 5, k + 9, VetheaBlocks.karosBricks2);
		world.setBlock(i + 13, j + 5, k + 10, VetheaBlocks.karosBricks2);
		world.setBlock(i + 13, j + 5, k + 11, VetheaBlocks.karosBricks2);
		world.setBlock(i + 13, j + 5, k + 12, VetheaBlocks.karosBricks2);
		world.setBlock(i + 13, j + 5, k + 13, VetheaBlocks.karosBricks2);
		world.setBlock(i + 13, j + 5, k + 14, VetheaBlocks.karosBricks2);
		world.setBlock(i + 13, j + 5, k + 15, VetheaBlocks.karosBricks2);
		world.setBlock(i + 13, j + 5, k + 16, VetheaBlocks.karosBricks);
		world.setBlock(i + 14, j + 0, k + 0, VetheaBlocks.karosBricks2);
		world.setBlock(i + 14, j + 0, k + 1, VetheaBlocks.karosBricks2);
		world.setBlock(i + 14, j + 0, k + 2, VetheaBlocks.karosHeatTileRed);
		world.setBlock(i + 14, j + 0, k + 3, VetheaBlocks.karosHeatTileRed);
		world.setBlock(i + 14, j + 0, k + 4, VetheaBlocks.karosHeatTileGreen);
		world.setBlock(i + 14, j + 0, k + 5, VetheaBlocks.karosHeatTileGreen);
		world.setBlock(i + 14, j + 0, k + 6, VetheaBlocks.karosHeatTileRed);
		world.setBlock(i + 14, j + 0, k + 7, VetheaBlocks.karosHeatTileRed);
		world.setBlock(i + 14, j + 0, k + 8, VetheaBlocks.karosHeatTileGreen);
		world.setBlock(i + 14, j + 0, k + 9, VetheaBlocks.karosHeatTileGreen);
		world.setBlock(i + 14, j + 0, k + 10, VetheaBlocks.karosHeatTileRed);
		world.setBlock(i + 14, j + 0, k + 11, VetheaBlocks.karosHeatTileRed);
		world.setBlock(i + 14, j + 0, k + 12, VetheaBlocks.karosHeatTileGreen);
		world.setBlock(i + 14, j + 0, k + 13, VetheaBlocks.karosHeatTileGreen);
		world.setBlock(i + 14, j + 0, k + 14, VetheaBlocks.karosHeatTileRed);
		world.setBlock(i + 14, j + 0, k + 15, VetheaBlocks.karosHeatTileRed);
		world.setBlock(i + 14, j + 0, k + 16, VetheaBlocks.karosHeatTileGreen);
		world.setBlock(i + 14, j + 0, k + 17, VetheaBlocks.karosHeatTileGreen);
		world.setBlock(i + 14, j + 0, k + 18, VetheaBlocks.karosBricks2);
		world.setBlock(i + 14, j + 0, k + 19, VetheaBlocks.karosBricks2);
		world.setBlock(i + 14, j + 1, k + 0, VetheaBlocks.karosBricks2);
		world.setBlock(i + 14, j + 1, k + 1, VetheaBlocks.karosBricks2);
		world.setBlock(i + 14, j + 1, k + 18, VetheaBlocks.karosBricks2);
		world.setBlock(i + 14, j + 1, k + 19, VetheaBlocks.karosBricks2);
		world.setBlock(i + 14, j + 2, k + 0, VetheaBlocks.karosBricks2);
		world.setBlock(i + 14, j + 2, k + 1, VetheaBlocks.karosCannon);
		world.setBlock(i + 14, j + 2, k + 18, VetheaBlocks.karosCannon);
		world.setBlock(i + 14, j + 2, k + 19, VetheaBlocks.karosBricks2);
		world.setBlock(i + 14, j + 3, k + 1, VetheaBlocks.karosBricks);
		world.setBlock(i + 14, j + 3, k + 18, VetheaBlocks.karosBricks);
		world.setBlock(i + 14, j + 4, k + 2, VetheaBlocks.karosBricks);
		world.setBlock(i + 14, j + 4, k + 4, VetheaBlocks.helioticBeam);
		world.setBlock(i + 14, j + 4, k + 5, VetheaBlocks.helioticBeam);
		world.setBlock(i + 14, j + 4, k + 6, VetheaBlocks.helioticBeam);
		world.setBlock(i + 14, j + 4, k + 14, VetheaBlocks.helioticBeam);
		world.setBlock(i + 14, j + 4, k + 15, VetheaBlocks.helioticBeam);
		world.setBlock(i + 14, j + 4, k + 16, VetheaBlocks.helioticBeam);
		world.setBlock(i + 14, j + 4, k + 17, VetheaBlocks.karosBricks);
		world.setBlock(i + 14, j + 5, k + 3, VetheaBlocks.karosBricks);
		world.setBlock(i + 14, j + 5, k + 4, VetheaBlocks.karosBricks2);
		world.setBlock(i + 14, j + 5, k + 5, VetheaBlocks.karosBricks);
		world.setBlock(i + 14, j + 5, k + 6, VetheaBlocks.karosBricks);
		world.setBlock(i + 14, j + 5, k + 7, VetheaBlocks.karosBricks);
		world.setBlock(i + 14, j + 5, k + 8, VetheaBlocks.karosBricks);
		world.setBlock(i + 14, j + 5, k + 9, VetheaBlocks.karosBricks);
		world.setBlock(i + 14, j + 5, k + 10, VetheaBlocks.karosBricks);
		world.setBlock(i + 14, j + 5, k + 11, VetheaBlocks.karosBricks);
		world.setBlock(i + 14, j + 5, k + 12, VetheaBlocks.karosBricks);
		world.setBlock(i + 14, j + 5, k + 13, VetheaBlocks.karosBricks);
		world.setBlock(i + 14, j + 5, k + 14, VetheaBlocks.karosBricks);
		world.setBlock(i + 14, j + 5, k + 15, VetheaBlocks.karosBricks2);
		world.setBlock(i + 14, j + 5, k + 16, VetheaBlocks.karosBricks);
		world.setBlock(i + 15, j + 0, k + 1, VetheaBlocks.karosBricks2);
		world.setBlock(i + 15, j + 0, k + 2, VetheaBlocks.karosHeatTileGreen);
		world.setBlock(i + 15, j + 0, k + 3, VetheaBlocks.karosHeatTileGreen);
		world.setBlock(i + 15, j + 0, k + 4, VetheaBlocks.karosHeatTileRed);
		world.setBlock(i + 15, j + 0, k + 5, VetheaBlocks.karosHeatTileRed);
		world.setBlock(i + 15, j + 0, k + 6, VetheaBlocks.karosHeatTileGreen);
		world.setBlock(i + 15, j + 0, k + 7, VetheaBlocks.karosHeatTileGreen);
		world.setBlock(i + 15, j + 0, k + 8, VetheaBlocks.karosHeatTileRed);
		world.setBlock(i + 15, j + 0, k + 9, VetheaBlocks.karosHeatTileRed);
		world.setBlock(i + 15, j + 0, k + 10, VetheaBlocks.karosHeatTileGreen);
		world.setBlock(i + 15, j + 0, k + 11, VetheaBlocks.karosHeatTileGreen);
		world.setBlock(i + 15, j + 0, k + 12, VetheaBlocks.karosHeatTileRed);
		world.setBlock(i + 15, j + 0, k + 13, VetheaBlocks.karosHeatTileRed);
		world.setBlock(i + 15, j + 0, k + 14, VetheaBlocks.karosHeatTileGreen);
		world.setBlock(i + 15, j + 0, k + 15, VetheaBlocks.karosHeatTileGreen);
		world.setBlock(i + 15, j + 0, k + 16, VetheaBlocks.karosHeatTileRed);
		world.setBlock(i + 15, j + 0, k + 17, VetheaBlocks.karosHeatTileRed);
		world.setBlock(i + 15, j + 0, k + 18, VetheaBlocks.karosBricks2);
		world.setBlock(i + 15, j + 1, k + 1, VetheaBlocks.karosBricks2);
		world.setBlock(i + 15, j + 1, k + 18, VetheaBlocks.karosBricks2);
		world.setBlock(i + 15, j + 2, k + 1, VetheaBlocks.karosBricks);
		world.setBlock(i + 15, j + 2, k + 18, VetheaBlocks.karosBricks);
		world.setBlock(i + 15, j + 3, k + 1, VetheaBlocks.karosBricks);
		world.setBlock(i + 15, j + 3, k + 18, VetheaBlocks.karosBricks);
		world.setBlock(i + 15, j + 4, k + 2, VetheaBlocks.karosBricks);
		world.setBlock(i + 15, j + 4, k + 4, VetheaBlocks.helioticBeam);
		world.setBlock(i + 15, j + 4, k + 5, VetheaBlocks.helioticBeam);
		world.setBlock(i + 15, j + 4, k + 6, VetheaBlocks.helioticBeam);
		world.setBlock(i + 15, j + 4, k + 14, VetheaBlocks.helioticBeam);
		world.setBlock(i + 15, j + 4, k + 15, VetheaBlocks.helioticBeam);
		world.setBlock(i + 15, j + 4, k + 16, VetheaBlocks.helioticBeam);
		world.setBlock(i + 15, j + 4, k + 17, VetheaBlocks.karosBricks);
		world.setBlock(i + 15, j + 5, k + 3, VetheaBlocks.karosBricks);
		world.setBlock(i + 15, j + 5, k + 4, VetheaBlocks.karosBricks2);
		world.setBlock(i + 15, j + 5, k + 5, VetheaBlocks.karosBricks);
		world.setBlock(i + 15, j + 5, k + 6, VetheaBlocks.karosBricks2);
		world.setBlock(i + 15, j + 5, k + 7, VetheaBlocks.karosBricks2);
		world.setBlock(i + 15, j + 5, k + 8, VetheaBlocks.karosBricks2);
		world.setBlock(i + 15, j + 5, k + 9, VetheaBlocks.karosBricks2);
		world.setBlock(i + 15, j + 5, k + 10, VetheaBlocks.karosBricks2);
		world.setBlock(i + 15, j + 5, k + 11, VetheaBlocks.karosBricks2);
		world.setBlock(i + 15, j + 5, k + 12, VetheaBlocks.karosBricks2);
		world.setBlock(i + 15, j + 5, k + 13, VetheaBlocks.karosBricks2);
		world.setBlock(i + 15, j + 5, k + 14, VetheaBlocks.karosBricks);
		world.setBlock(i + 15, j + 5, k + 15, VetheaBlocks.karosBricks2);
		world.setBlock(i + 15, j + 5, k + 16, VetheaBlocks.karosBricks);
		world.setBlock(i + 16, j + 0, k + 0, VetheaBlocks.karosBricks2);
		world.setBlock(i + 16, j + 0, k + 1, VetheaBlocks.karosBricks2);
		world.setBlock(i + 16, j + 0, k + 2, VetheaBlocks.karosHeatTileGreen);
		world.setBlock(i + 16, j + 0, k + 3, VetheaBlocks.karosHeatTileGreen);
		world.setBlock(i + 16, j + 0, k + 4, VetheaBlocks.karosHeatTileRed);
		world.setBlock(i + 16, j + 0, k + 5, VetheaBlocks.karosHeatTileRed);
		world.setBlock(i + 16, j + 0, k + 6, VetheaBlocks.karosHeatTileGreen);
		world.setBlock(i + 16, j + 0, k + 7, VetheaBlocks.karosHeatTileGreen);
		world.setBlock(i + 16, j + 0, k + 8, VetheaBlocks.karosHeatTileRed);
		world.setBlock(i + 16, j + 0, k + 9, VetheaBlocks.karosHeatTileRed);
		world.setBlock(i + 16, j + 0, k + 10, VetheaBlocks.karosHeatTileGreen);
		world.setBlock(i + 16, j + 0, k + 11, VetheaBlocks.karosHeatTileGreen);
		world.setBlock(i + 16, j + 0, k + 12, VetheaBlocks.karosHeatTileRed);
		world.setBlock(i + 16, j + 0, k + 13, VetheaBlocks.karosHeatTileRed);
		world.setBlock(i + 16, j + 0, k + 14, VetheaBlocks.karosHeatTileGreen);
		world.setBlock(i + 16, j + 0, k + 15, VetheaBlocks.karosHeatTileGreen);
		world.setBlock(i + 16, j + 0, k + 16, VetheaBlocks.karosHeatTileRed);
		world.setBlock(i + 16, j + 0, k + 17, VetheaBlocks.karosHeatTileRed);
		world.setBlock(i + 16, j + 0, k + 18, VetheaBlocks.karosBricks2);
		world.setBlock(i + 16, j + 0, k + 19, VetheaBlocks.karosBricks2);
		world.setBlock(i + 16, j + 1, k + 0, VetheaBlocks.karosBricks2);
		world.setBlock(i + 16, j + 1, k + 1, VetheaBlocks.karosBricks2);
		world.setBlock(i + 16, j + 1, k + 18, VetheaBlocks.karosBricks2);
		world.setBlock(i + 16, j + 1, k + 19, VetheaBlocks.karosBricks2);
		world.setBlock(i + 16, j + 2, k + 0, VetheaBlocks.karosBricks2);
		world.setBlock(i + 16, j + 2, k + 1, VetheaBlocks.karosCannon);
		world.setBlock(i + 16, j + 2, k + 18, VetheaBlocks.karosCannon);
		world.setBlock(i + 16, j + 2, k + 19, VetheaBlocks.karosBricks2);
		world.setBlock(i + 16, j + 3, k + 1, VetheaBlocks.karosBricks);
		world.setBlock(i + 16, j + 3, k + 18, VetheaBlocks.karosBricks);
		world.setBlock(i + 16, j + 4, k + 2, VetheaBlocks.karosBricks);
		world.setBlock(i + 16, j + 4, k + 17, VetheaBlocks.karosBricks);
		world.setBlock(i + 16, j + 5, k + 3, VetheaBlocks.karosBricks);
		world.setBlock(i + 16, j + 5, k + 4, VetheaBlocks.karosBricks2);
		world.setBlock(i + 16, j + 5, k + 5, VetheaBlocks.karosBricks);
		world.setBlock(i + 16, j + 5, k + 6, VetheaBlocks.karosBricks2);
		world.setBlock(i + 16, j + 5, k + 7, VetheaBlocks.karosBricks);
		world.setBlock(i + 16, j + 5, k + 8, VetheaBlocks.karosBricks2);
		world.setBlock(i + 16, j + 5, k + 9, VetheaBlocks.karosBricks2);
		world.setBlock(i + 16, j + 5, k + 10, VetheaBlocks.karosBricks2);
		world.setBlock(i + 16, j + 5, k + 11, VetheaBlocks.karosBricks);
		world.setBlock(i + 16, j + 5, k + 12, VetheaBlocks.karosBricks2);
		world.setBlock(i + 16, j + 5, k + 13, VetheaBlocks.karosBricks2);
		world.setBlock(i + 16, j + 5, k + 14, VetheaBlocks.karosBricks);
		world.setBlock(i + 16, j + 5, k + 15, VetheaBlocks.karosBricks2);
		world.setBlock(i + 16, j + 5, k + 16, VetheaBlocks.karosBricks);
		world.setBlock(i + 17, j + 0, k + 1, VetheaBlocks.karosBricks2);
		world.setBlock(i + 17, j + 0, k + 2, VetheaBlocks.karosHeatTileRed);
		world.setBlock(i + 17, j + 0, k + 3, VetheaBlocks.karosHeatTileRed);
		world.setBlock(i + 17, j + 0, k + 4, VetheaBlocks.karosHeatTileGreen);
		world.setBlock(i + 17, j + 0, k + 5, VetheaBlocks.karosHeatTileGreen);
		world.setBlock(i + 17, j + 0, k + 6, VetheaBlocks.karosHeatTileRed);
		world.setBlock(i + 17, j + 0, k + 7, VetheaBlocks.karosHeatTileRed);
		world.setBlock(i + 17, j + 0, k + 8, VetheaBlocks.karosHeatTileGreen);
		world.setBlock(i + 17, j + 0, k + 9, VetheaBlocks.karosHeatTileGreen);
		world.setBlock(i + 17, j + 0, k + 10, VetheaBlocks.karosHeatTileRed);
		world.setBlock(i + 17, j + 0, k + 11, VetheaBlocks.karosHeatTileRed);
		world.setBlock(i + 17, j + 0, k + 12, VetheaBlocks.karosHeatTileGreen);
		world.setBlock(i + 17, j + 0, k + 13, VetheaBlocks.karosHeatTileGreen);
		world.setBlock(i + 17, j + 0, k + 14, VetheaBlocks.karosHeatTileRed);
		world.setBlock(i + 17, j + 0, k + 15, VetheaBlocks.karosHeatTileRed);
		world.setBlock(i + 17, j + 0, k + 16, VetheaBlocks.karosHeatTileGreen);
		world.setBlock(i + 17, j + 0, k + 17, VetheaBlocks.karosHeatTileGreen);
		world.setBlock(i + 17, j + 0, k + 18, VetheaBlocks.karosBricks2);
		world.setBlock(i + 17, j + 1, k + 1, VetheaBlocks.karosBricks2);
		world.setBlock(i + 17, j + 1, k + 18, VetheaBlocks.karosBricks2);
		world.setBlock(i + 17, j + 2, k + 1, VetheaBlocks.karosBricks);
		world.setBlock(i + 17, j + 2, k + 18, VetheaBlocks.karosBricks);
		world.setBlock(i + 17, j + 3, k + 1, VetheaBlocks.karosBricks);
		world.setBlock(i + 17, j + 3, k + 18, VetheaBlocks.karosBricks);
		world.setBlock(i + 17, j + 4, k + 2, VetheaBlocks.karosBricks);
		world.setBlock(i + 17, j + 4, k + 17, VetheaBlocks.karosBricks);
		world.setBlock(i + 17, j + 5, k + 3, VetheaBlocks.karosBricks);
		world.setBlock(i + 17, j + 5, k + 4, VetheaBlocks.karosBricks2);
		world.setBlock(i + 17, j + 5, k + 5, VetheaBlocks.karosBricks);
		world.setBlock(i + 17, j + 5, k + 6, VetheaBlocks.karosBricks2);
		world.setBlock(i + 17, j + 5, k + 7, VetheaBlocks.karosBricks);
		world.setBlock(i + 17, j + 5, k + 8, VetheaBlocks.karosBricks2);
		world.setBlock(i + 17, j + 5, k + 9, VetheaBlocks.karosBricks2);
		world.setBlock(i + 17, j + 5, k + 10, VetheaBlocks.karosBricks);
		world.setBlock(i + 17, j + 5, k + 11, VetheaBlocks.karosBricks2);
		world.setBlock(i + 17, j + 5, k + 12, VetheaBlocks.karosBricks2);
		world.setBlock(i + 17, j + 5, k + 13, VetheaBlocks.karosBricks2);
		world.setBlock(i + 17, j + 5, k + 14, VetheaBlocks.karosBricks);
		world.setBlock(i + 17, j + 5, k + 15, VetheaBlocks.karosBricks2);
		world.setBlock(i + 17, j + 5, k + 16, VetheaBlocks.karosBricks);
		world.setBlock(i + 18, j + 0, k + 0, VetheaBlocks.karosBricks2);
		world.setBlock(i + 18, j + 0, k + 1, VetheaBlocks.karosBricks2);
		world.setBlock(i + 18, j + 0, k + 2, VetheaBlocks.karosHeatTileRed);
		world.setBlock(i + 18, j + 0, k + 3, VetheaBlocks.karosHeatTileRed);
		world.setBlock(i + 18, j + 0, k + 4, VetheaBlocks.karosHeatTileGreen);
		world.setBlock(i + 18, j + 0, k + 5, VetheaBlocks.karosHeatTileGreen);
		world.setBlock(i + 18, j + 0, k + 6, VetheaBlocks.karosHeatTileRed);
		world.setBlock(i + 18, j + 0, k + 7, VetheaBlocks.karosHeatTileRed);
		world.setBlock(i + 18, j + 0, k + 8, VetheaBlocks.karosHeatTileGreen);
		world.setBlock(i + 18, j + 0, k + 9, VetheaBlocks.karosHeatTileGreen);
		world.setBlock(i + 18, j + 0, k + 10, VetheaBlocks.karosHeatTileRed);
		world.setBlock(i + 18, j + 0, k + 11, VetheaBlocks.karosHeatTileRed);
		world.setBlock(i + 18, j + 0, k + 12, VetheaBlocks.karosHeatTileGreen);
		world.setBlock(i + 18, j + 0, k + 13, VetheaBlocks.karosHeatTileGreen);
		world.setBlock(i + 18, j + 0, k + 14, VetheaBlocks.karosHeatTileRed);
		world.setBlock(i + 18, j + 0, k + 15, VetheaBlocks.karosHeatTileRed);
		world.setBlock(i + 18, j + 0, k + 16, VetheaBlocks.karosHeatTileGreen);
		world.setBlock(i + 18, j + 0, k + 17, VetheaBlocks.karosHeatTileGreen);
		world.setBlock(i + 18, j + 0, k + 18, VetheaBlocks.karosBricks2);
		world.setBlock(i + 18, j + 0, k + 19, VetheaBlocks.karosBricks2);
		world.setBlock(i + 18, j + 1, k + 0, VetheaBlocks.karosBricks2);
		world.setBlock(i + 18, j + 1, k + 1, VetheaBlocks.karosBricks2);
		world.setBlock(i + 18, j + 1, k + 18, VetheaBlocks.karosBricks2);
		world.setBlock(i + 18, j + 1, k + 19, VetheaBlocks.karosBricks2);
		world.setBlock(i + 18, j + 2, k + 0, VetheaBlocks.karosBricks2);
		world.setBlock(i + 18, j + 2, k + 1, VetheaBlocks.karosCannon);
		world.setBlock(i + 18, j + 2, k + 18, VetheaBlocks.karosCannon);
		world.setBlock(i + 18, j + 2, k + 19, VetheaBlocks.karosBricks2);
		world.setBlock(i + 18, j + 3, k + 1, VetheaBlocks.karosBricks);
		world.setBlock(i + 18, j + 3, k + 18, VetheaBlocks.karosBricks);
		world.setBlock(i + 18, j + 4, k + 2, VetheaBlocks.karosBricks);
		world.setBlock(i + 18, j + 4, k + 9, VetheaBlocks.helioticBeam);
		world.setBlock(i + 18, j + 4, k + 10, VetheaBlocks.helioticBeam);
		world.setBlock(i + 18, j + 4, k + 11, VetheaBlocks.helioticBeam);
		world.setBlock(i + 18, j + 4, k + 17, VetheaBlocks.karosBricks);
		world.setBlock(i + 18, j + 5, k + 3, VetheaBlocks.karosBricks);
		world.setBlock(i + 18, j + 5, k + 4, VetheaBlocks.karosBricks2);
		world.setBlock(i + 18, j + 5, k + 5, VetheaBlocks.karosBricks);
		world.setBlock(i + 18, j + 5, k + 6, VetheaBlocks.karosBricks2);
		world.setBlock(i + 18, j + 5, k + 7, VetheaBlocks.karosBricks);
		world.setBlock(i + 18, j + 5, k + 8, VetheaBlocks.karosBricks2);
		world.setBlock(i + 18, j + 5, k + 9, VetheaBlocks.karosBricks);
		world.setBlock(i + 18, j + 5, k + 10, VetheaBlocks.karosBricks2);
		world.setBlock(i + 18, j + 5, k + 11, VetheaBlocks.karosBricks2);
		world.setBlock(i + 18, j + 5, k + 12, VetheaBlocks.karosBricks2);
		world.setBlock(i + 18, j + 5, k + 13, VetheaBlocks.karosBricks2);
		world.setBlock(i + 18, j + 5, k + 14, VetheaBlocks.karosBricks);
		world.setBlock(i + 18, j + 5, k + 15, VetheaBlocks.karosBricks2);
		world.setBlock(i + 18, j + 5, k + 16, VetheaBlocks.karosBricks);
		world.setBlock(i + 19, j + 0, k + 1, VetheaBlocks.karosBricks2);
		world.setBlock(i + 19, j + 0, k + 2, VetheaBlocks.karosHeatTileGreen);
		world.setBlock(i + 19, j + 0, k + 3, VetheaBlocks.karosHeatTileGreen);
		world.setBlock(i + 19, j + 0, k + 4, VetheaBlocks.karosHeatTileRed);
		world.setBlock(i + 19, j + 0, k + 5, VetheaBlocks.karosHeatTileRed);
		world.setBlock(i + 19, j + 0, k + 6, VetheaBlocks.karosHeatTileGreen);
		world.setBlock(i + 19, j + 0, k + 7, VetheaBlocks.karosHeatTileGreen);
		world.setBlock(i + 19, j + 0, k + 8, VetheaBlocks.karosHeatTileRed);
		world.setBlock(i + 19, j + 0, k + 9, VetheaBlocks.karosHeatTileRed);
		world.setBlock(i + 19, j + 0, k + 10, VetheaBlocks.karosHeatTileGreen);
		world.setBlock(i + 19, j + 0, k + 11, VetheaBlocks.karosHeatTileGreen);
		world.setBlock(i + 19, j + 0, k + 12, VetheaBlocks.karosHeatTileRed);
		world.setBlock(i + 19, j + 0, k + 13, VetheaBlocks.karosHeatTileRed);
		world.setBlock(i + 19, j + 0, k + 14, VetheaBlocks.karosHeatTileGreen);
		world.setBlock(i + 19, j + 0, k + 15, VetheaBlocks.karosHeatTileGreen);
		world.setBlock(i + 19, j + 0, k + 16, VetheaBlocks.karosHeatTileRed);
		world.setBlock(i + 19, j + 0, k + 17, VetheaBlocks.karosHeatTileRed);
		world.setBlock(i + 19, j + 0, k + 18, VetheaBlocks.karosBricks2);
		world.setBlock(i + 19, j + 1, k + 1, VetheaBlocks.karosBricks2);
		world.setBlock(i + 19, j + 1, k + 18, VetheaBlocks.karosBricks2);
		world.setBlock(i + 19, j + 2, k + 1, VetheaBlocks.karosBricks);
		world.setBlock(i + 19, j + 2, k + 18, VetheaBlocks.karosBricks);
		world.setBlock(i + 19, j + 3, k + 1, VetheaBlocks.karosBricks);
		world.setBlock(i + 19, j + 3, k + 18, VetheaBlocks.karosBricks);
		world.setBlock(i + 19, j + 4, k + 2, VetheaBlocks.karosBricks);
		world.setBlock(i + 19, j + 4, k + 9, VetheaBlocks.helioticBeam);
		world.setBlock(i + 19, j + 4, k + 10, VetheaBlocks.helioticBeam);
		world.setBlock(i + 19, j + 4, k + 11, VetheaBlocks.helioticBeam);
		world.setBlock(i + 19, j + 4, k + 17, VetheaBlocks.karosBricks);
		world.setBlock(i + 19, j + 5, k + 3, VetheaBlocks.karosBricks);
		world.setBlock(i + 19, j + 5, k + 4, VetheaBlocks.karosBricks2);
		world.setBlock(i + 19, j + 5, k + 5, VetheaBlocks.karosBricks);
		world.setBlock(i + 19, j + 5, k + 6, VetheaBlocks.karosBricks2);
		world.setBlock(i + 19, j + 5, k + 7, VetheaBlocks.karosBricks);
		world.setBlock(i + 19, j + 5, k + 8, VetheaBlocks.karosBricks);
		world.setBlock(i + 19, j + 5, k + 9, VetheaBlocks.karosBricks2);
		world.setBlock(i + 19, j + 5, k + 10, VetheaBlocks.karosBricks2);
		world.setBlock(i + 19, j + 5, k + 11, VetheaBlocks.karosBricks2);
		world.setBlock(i + 19, j + 5, k + 12, VetheaBlocks.karosBricks2);
		world.setBlock(i + 19, j + 5, k + 13, VetheaBlocks.karosBricks2);
		world.setBlock(i + 19, j + 5, k + 14, VetheaBlocks.karosBricks);
		world.setBlock(i + 19, j + 5, k + 15, VetheaBlocks.karosBricks2);
		world.setBlock(i + 19, j + 5, k + 16, VetheaBlocks.karosBricks);
		world.setBlock(i + 20, j + 0, k + 0, VetheaBlocks.karosBricks2);
		world.setBlock(i + 20, j + 0, k + 1, VetheaBlocks.karosBricks2);
		world.setBlock(i + 20, j + 0, k + 2, VetheaBlocks.karosHeatTileGreen);
		world.setBlock(i + 20, j + 0, k + 3, VetheaBlocks.karosHeatTileGreen);
		world.setBlock(i + 20, j + 0, k + 4, VetheaBlocks.karosHeatTileRed);
		world.setBlock(i + 20, j + 0, k + 5, VetheaBlocks.karosHeatTileRed);
		world.setBlock(i + 20, j + 0, k + 6, VetheaBlocks.karosHeatTileGreen);
		world.setBlock(i + 20, j + 0, k + 7, VetheaBlocks.karosHeatTileGreen);
		world.setBlock(i + 20, j + 0, k + 8, VetheaBlocks.karosHeatTileRed);
		world.setBlock(i + 20, j + 0, k + 9, VetheaBlocks.karosHeatTileRed);
		world.setBlock(i + 20, j + 0, k + 10, VetheaBlocks.karosHeatTileGreen);
		world.setBlock(i + 20, j + 0, k + 11, VetheaBlocks.karosHeatTileGreen);
		world.setBlock(i + 20, j + 0, k + 12, VetheaBlocks.karosHeatTileRed);
		world.setBlock(i + 20, j + 0, k + 13, VetheaBlocks.karosHeatTileRed);
		world.setBlock(i + 20, j + 0, k + 14, VetheaBlocks.karosHeatTileGreen);
		world.setBlock(i + 20, j + 0, k + 15, VetheaBlocks.karosHeatTileGreen);
		world.setBlock(i + 20, j + 0, k + 16, VetheaBlocks.karosHeatTileRed);
		world.setBlock(i + 20, j + 0, k + 17, VetheaBlocks.karosHeatTileRed);
		world.setBlock(i + 20, j + 0, k + 18, VetheaBlocks.karosBricks2);
		world.setBlock(i + 20, j + 0, k + 19, VetheaBlocks.karosBricks2);
		world.setBlock(i + 20, j + 1, k + 0, VetheaBlocks.karosBricks2);
		world.setBlock(i + 20, j + 1, k + 1, VetheaBlocks.karosBricks2);
		world.setBlock(i + 20, j + 1, k + 18, VetheaBlocks.karosBricks2);
		world.setBlock(i + 20, j + 1, k + 19, VetheaBlocks.karosBricks2);
		world.setBlock(i + 20, j + 2, k + 0, VetheaBlocks.karosBricks2);
		world.setBlock(i + 20, j + 2, k + 1, VetheaBlocks.karosCannon);
		world.setBlock(i + 20, j + 2, k + 18, VetheaBlocks.karosCannon);
		world.setBlock(i + 20, j + 2, k + 19, VetheaBlocks.karosBricks2);
		world.setBlock(i + 20, j + 3, k + 1, VetheaBlocks.karosBricks);
		world.setBlock(i + 20, j + 3, k + 18, VetheaBlocks.karosBricks);
		world.setBlock(i + 20, j + 4, k + 2, VetheaBlocks.karosBricks);
		world.setBlock(i + 20, j + 4, k + 9, VetheaBlocks.helioticBeam);
		world.setBlock(i + 20, j + 4, k + 10, VetheaBlocks.helioticBeam);
		world.setBlock(i + 20, j + 4, k + 11, VetheaBlocks.helioticBeam);
		world.setBlock(i + 20, j + 4, k + 17, VetheaBlocks.karosBricks);
		world.setBlock(i + 20, j + 5, k + 3, VetheaBlocks.karosBricks);
		world.setBlock(i + 20, j + 5, k + 4, VetheaBlocks.karosBricks2);
		world.setBlock(i + 20, j + 5, k + 5, VetheaBlocks.karosBricks);
		world.setBlock(i + 20, j + 5, k + 6, VetheaBlocks.karosBricks2);
		world.setBlock(i + 20, j + 5, k + 7, VetheaBlocks.karosBricks);
		world.setBlock(i + 20, j + 5, k + 8, VetheaBlocks.karosBricks2);
		world.setBlock(i + 20, j + 5, k + 9, VetheaBlocks.karosBricks2);
		world.setBlock(i + 20, j + 5, k + 10, VetheaBlocks.karosBricks2);
		world.setBlock(i + 20, j + 5, k + 11, VetheaBlocks.karosBricks2);
		world.setBlock(i + 20, j + 5, k + 12, VetheaBlocks.karosBricks2);
		world.setBlock(i + 20, j + 5, k + 13, VetheaBlocks.karosBricks2);
		world.setBlock(i + 20, j + 5, k + 14, VetheaBlocks.karosBricks);
		world.setBlock(i + 20, j + 5, k + 15, VetheaBlocks.karosBricks2);
		world.setBlock(i + 20, j + 5, k + 16, VetheaBlocks.karosBricks);
		world.setBlock(i + 21, j + 0, k + 1, VetheaBlocks.karosBricks2);
		world.setBlock(i + 21, j + 0, k + 2, VetheaBlocks.karosHeatTileRed);
		world.setBlock(i + 21, j + 0, k + 3, VetheaBlocks.karosHeatTileRed);
		world.setBlock(i + 21, j + 0, k + 4, VetheaBlocks.karosHeatTileGreen);
		world.setBlock(i + 21, j + 0, k + 5, VetheaBlocks.karosHeatTileGreen);
		world.setBlock(i + 21, j + 0, k + 6, VetheaBlocks.karosHeatTileRed);
		world.setBlock(i + 21, j + 0, k + 7, VetheaBlocks.karosHeatTileRed);
		world.setBlock(i + 21, j + 0, k + 8, VetheaBlocks.karosHeatTileGreen);
		world.setBlock(i + 21, j + 0, k + 9, VetheaBlocks.karosHeatTileGreen);
		world.setBlock(i + 21, j + 0, k + 10, VetheaBlocks.karosHeatTileRed);
		world.setBlock(i + 21, j + 0, k + 11, VetheaBlocks.karosHeatTileRed);
		world.setBlock(i + 21, j + 0, k + 12, VetheaBlocks.karosHeatTileGreen);
		world.setBlock(i + 21, j + 0, k + 13, VetheaBlocks.karosHeatTileGreen);
		world.setBlock(i + 21, j + 0, k + 14, VetheaBlocks.karosHeatTileRed);
		world.setBlock(i + 21, j + 0, k + 15, VetheaBlocks.karosHeatTileRed);
		world.setBlock(i + 21, j + 0, k + 16, VetheaBlocks.karosHeatTileGreen);
		world.setBlock(i + 21, j + 0, k + 17, VetheaBlocks.karosHeatTileGreen);
		world.setBlock(i + 21, j + 0, k + 18, VetheaBlocks.karosBricks2);
		world.setBlock(i + 21, j + 1, k + 1, VetheaBlocks.karosBricks2);
		world.setBlock(i + 21, j + 1, k + 18, VetheaBlocks.karosBricks2);
		world.setBlock(i + 21, j + 2, k + 1, VetheaBlocks.karosBricks);
		world.setBlock(i + 21, j + 2, k + 18, VetheaBlocks.karosBricks);
		world.setBlock(i + 21, j + 3, k + 1, VetheaBlocks.karosBricks);
		world.setBlock(i + 21, j + 3, k + 18, VetheaBlocks.karosBricks);
		world.setBlock(i + 21, j + 4, k + 2, VetheaBlocks.karosBricks);
		world.setBlock(i + 21, j + 4, k + 17, VetheaBlocks.karosBricks);
		world.setBlock(i + 21, j + 5, k + 3, VetheaBlocks.karosBricks);
		world.setBlock(i + 21, j + 5, k + 4, VetheaBlocks.karosBricks2);
		world.setBlock(i + 21, j + 5, k + 5, VetheaBlocks.karosBricks);
		world.setBlock(i + 21, j + 5, k + 6, VetheaBlocks.karosBricks2);
		world.setBlock(i + 21, j + 5, k + 7, VetheaBlocks.karosBricks);
		world.setBlock(i + 21, j + 5, k + 8, VetheaBlocks.karosBricks);
		world.setBlock(i + 21, j + 5, k + 9, VetheaBlocks.karosBricks2);
		world.setBlock(i + 21, j + 5, k + 10, VetheaBlocks.karosBricks2);
		world.setBlock(i + 21, j + 5, k + 11, VetheaBlocks.karosBricks2);
		world.setBlock(i + 21, j + 5, k + 12, VetheaBlocks.karosBricks2);
		world.setBlock(i + 21, j + 5, k + 13, VetheaBlocks.karosBricks2);
		world.setBlock(i + 21, j + 5, k + 14, VetheaBlocks.karosBricks);
		world.setBlock(i + 21, j + 5, k + 15, VetheaBlocks.karosBricks2);
		world.setBlock(i + 21, j + 5, k + 16, VetheaBlocks.karosBricks);
		world.setBlock(i + 22, j + 0, k + 0, VetheaBlocks.karosBricks2);
		world.setBlock(i + 22, j + 0, k + 1, VetheaBlocks.karosBricks2);
		world.setBlock(i + 22, j + 0, k + 2, VetheaBlocks.karosHeatTileRed);
		world.setBlock(i + 22, j + 0, k + 3, VetheaBlocks.karosHeatTileRed);
		world.setBlock(i + 22, j + 0, k + 4, VetheaBlocks.karosHeatTileGreen);
		world.setBlock(i + 22, j + 0, k + 5, VetheaBlocks.karosHeatTileGreen);
		world.setBlock(i + 22, j + 0, k + 6, VetheaBlocks.karosHeatTileRed);
		world.setBlock(i + 22, j + 0, k + 7, VetheaBlocks.karosHeatTileRed);
		world.setBlock(i + 22, j + 0, k + 8, VetheaBlocks.karosHeatTileGreen);
		world.setBlock(i + 22, j + 0, k + 9, VetheaBlocks.karosHeatTileGreen);
		world.setBlock(i + 22, j + 0, k + 10, VetheaBlocks.karosHeatTileRed);
		world.setBlock(i + 22, j + 0, k + 11, VetheaBlocks.karosHeatTileRed);
		world.setBlock(i + 22, j + 0, k + 12, VetheaBlocks.karosHeatTileGreen);
		world.setBlock(i + 22, j + 0, k + 13, VetheaBlocks.karosHeatTileGreen);
		world.setBlock(i + 22, j + 0, k + 14, VetheaBlocks.karosHeatTileRed);
		world.setBlock(i + 22, j + 0, k + 15, VetheaBlocks.karosHeatTileRed);
		world.setBlock(i + 22, j + 0, k + 16, VetheaBlocks.karosHeatTileGreen);
		world.setBlock(i + 22, j + 0, k + 17, VetheaBlocks.karosHeatTileGreen);
		world.setBlock(i + 22, j + 0, k + 18, VetheaBlocks.karosBricks2);
		world.setBlock(i + 22, j + 0, k + 19, VetheaBlocks.karosBricks2);
		world.setBlock(i + 22, j + 1, k + 0, VetheaBlocks.karosBricks2);
		world.setBlock(i + 22, j + 1, k + 1, VetheaBlocks.karosBricks2);
		world.setBlock(i + 22, j + 1, k + 18, VetheaBlocks.karosBricks2);
		world.setBlock(i + 22, j + 1, k + 19, VetheaBlocks.karosBricks2);
		world.setBlock(i + 22, j + 2, k + 0, VetheaBlocks.karosBricks2);
		world.setBlock(i + 22, j + 2, k + 1, VetheaBlocks.karosCannon);
		world.setBlock(i + 22, j + 2, k + 18, VetheaBlocks.karosCannon);
		world.setBlock(i + 22, j + 2, k + 19, VetheaBlocks.karosBricks2);
		world.setBlock(i + 22, j + 3, k + 1, VetheaBlocks.karosBricks);
		world.setBlock(i + 22, j + 3, k + 18, VetheaBlocks.karosBricks);
		world.setBlock(i + 22, j + 4, k + 2, VetheaBlocks.karosBricks);
		world.setBlock(i + 22, j + 4, k + 12, VetheaBlocks.helioticBeam);
		world.setBlock(i + 22, j + 4, k + 13, VetheaBlocks.helioticBeam);
		world.setBlock(i + 22, j + 4, k + 14, VetheaBlocks.helioticBeam);
		world.setBlock(i + 22, j + 4, k + 17, VetheaBlocks.karosBricks);
		world.setBlock(i + 22, j + 5, k + 3, VetheaBlocks.karosBricks);
		world.setBlock(i + 22, j + 5, k + 4, VetheaBlocks.karosBricks2);
		world.setBlock(i + 22, j + 5, k + 5, VetheaBlocks.karosBricks);
		world.setBlock(i + 22, j + 5, k + 6, VetheaBlocks.karosBricks2);
		world.setBlock(i + 22, j + 5, k + 7, VetheaBlocks.karosBricks);
		world.setBlock(i + 22, j + 5, k + 8, VetheaBlocks.karosBricks2);
		world.setBlock(i + 22, j + 5, k + 9, VetheaBlocks.karosBricks);
		world.setBlock(i + 22, j + 5, k + 10, VetheaBlocks.karosBricks2);
		world.setBlock(i + 22, j + 5, k + 11, VetheaBlocks.karosBricks2);
		world.setBlock(i + 22, j + 5, k + 12, VetheaBlocks.karosBricks2);
		world.setBlock(i + 22, j + 5, k + 13, VetheaBlocks.karosBricks2);
		world.setBlock(i + 22, j + 5, k + 14, VetheaBlocks.karosBricks);
		world.setBlock(i + 22, j + 5, k + 15, VetheaBlocks.karosBricks2);
		world.setBlock(i + 22, j + 5, k + 16, VetheaBlocks.karosBricks);
		world.setBlock(i + 23, j + 0, k + 1, VetheaBlocks.karosBricks2);
		world.setBlock(i + 23, j + 0, k + 2, VetheaBlocks.karosHeatTileGreen);
		world.setBlock(i + 23, j + 0, k + 3, VetheaBlocks.karosHeatTileGreen);
		world.setBlock(i + 23, j + 0, k + 4, VetheaBlocks.karosHeatTileRed);
		world.setBlock(i + 23, j + 0, k + 5, VetheaBlocks.karosHeatTileRed);
		world.setBlock(i + 23, j + 0, k + 6, VetheaBlocks.karosHeatTileGreen);
		world.setBlock(i + 23, j + 0, k + 7, VetheaBlocks.karosHeatTileGreen);
		world.setBlock(i + 23, j + 0, k + 8, VetheaBlocks.karosHeatTileRed);
		world.setBlock(i + 23, j + 0, k + 9, VetheaBlocks.karosHeatTileRed);
		world.setBlock(i + 23, j + 0, k + 10, VetheaBlocks.karosHeatTileGreen);
		world.setBlock(i + 23, j + 0, k + 11, VetheaBlocks.karosHeatTileGreen);
		world.setBlock(i + 23, j + 0, k + 12, VetheaBlocks.karosHeatTileRed);
		world.setBlock(i + 23, j + 0, k + 13, VetheaBlocks.karosHeatTileRed);
		world.setBlock(i + 23, j + 0, k + 14, VetheaBlocks.karosHeatTileGreen);
		world.setBlock(i + 23, j + 0, k + 15, VetheaBlocks.karosHeatTileGreen);
		world.setBlock(i + 23, j + 0, k + 16, VetheaBlocks.karosHeatTileRed);
		world.setBlock(i + 23, j + 0, k + 17, VetheaBlocks.karosHeatTileRed);
		world.setBlock(i + 23, j + 0, k + 18, VetheaBlocks.karosBricks2);
		world.setBlock(i + 23, j + 1, k + 1, VetheaBlocks.karosBricks2);
		world.setBlock(i + 23, j + 1, k + 18, VetheaBlocks.karosBricks2);
		world.setBlock(i + 23, j + 2, k + 1, VetheaBlocks.karosBricks);
		world.setBlock(i + 23, j + 2, k + 18, VetheaBlocks.karosBricks);
		world.setBlock(i + 23, j + 3, k + 1, VetheaBlocks.karosBricks);
		world.setBlock(i + 23, j + 3, k + 18, VetheaBlocks.karosBricks);
		world.setBlock(i + 23, j + 4, k + 2, VetheaBlocks.karosBricks);
		world.setBlock(i + 23, j + 4, k + 4, VetheaBlocks.helioticBeam);
		world.setBlock(i + 23, j + 4, k + 5, VetheaBlocks.helioticBeam);
		world.setBlock(i + 23, j + 4, k + 6, VetheaBlocks.helioticBeam);
		world.setBlock(i + 23, j + 4, k + 12, VetheaBlocks.helioticBeam);
		world.setBlock(i + 23, j + 4, k + 13, VetheaBlocks.helioticBeam);
		world.setBlock(i + 23, j + 4, k + 14, VetheaBlocks.helioticBeam);
		world.setBlock(i + 23, j + 4, k + 17, VetheaBlocks.karosBricks);
		world.setBlock(i + 23, j + 5, k + 3, VetheaBlocks.karosBricks);
		world.setBlock(i + 23, j + 5, k + 4, VetheaBlocks.karosBricks2);
		world.setBlock(i + 23, j + 5, k + 5, VetheaBlocks.karosBricks);
		world.setBlock(i + 23, j + 5, k + 6, VetheaBlocks.karosBricks2);
		world.setBlock(i + 23, j + 5, k + 7, VetheaBlocks.karosBricks);
		world.setBlock(i + 23, j + 5, k + 8, VetheaBlocks.karosBricks2);
		world.setBlock(i + 23, j + 5, k + 9, VetheaBlocks.karosBricks2);
		world.setBlock(i + 23, j + 5, k + 10, VetheaBlocks.karosBricks);
		world.setBlock(i + 23, j + 5, k + 11, VetheaBlocks.karosBricks2);
		world.setBlock(i + 23, j + 5, k + 12, VetheaBlocks.karosBricks2);
		world.setBlock(i + 23, j + 5, k + 13, VetheaBlocks.karosBricks2);
		world.setBlock(i + 23, j + 5, k + 14, VetheaBlocks.karosBricks);
		world.setBlock(i + 23, j + 5, k + 15, VetheaBlocks.karosBricks2);
		world.setBlock(i + 23, j + 5, k + 16, VetheaBlocks.karosBricks);
		world.setBlock(i + 24, j + 0, k + 0, VetheaBlocks.karosBricks2);
		world.setBlock(i + 24, j + 0, k + 1, VetheaBlocks.karosBricks2);
		world.setBlock(i + 24, j + 0, k + 2, VetheaBlocks.karosHeatTileGreen);
		world.setBlock(i + 24, j + 0, k + 3, VetheaBlocks.karosHeatTileGreen);
		world.setBlock(i + 24, j + 0, k + 4, VetheaBlocks.karosHeatTileRed);
		world.setBlock(i + 24, j + 0, k + 5, VetheaBlocks.karosHeatTileRed);
		world.setBlock(i + 24, j + 0, k + 6, VetheaBlocks.karosHeatTileGreen);
		world.setBlock(i + 24, j + 0, k + 7, VetheaBlocks.karosHeatTileGreen);
		world.setBlock(i + 24, j + 0, k + 8, VetheaBlocks.karosHeatTileRed);
		world.setBlock(i + 24, j + 0, k + 9, VetheaBlocks.karosHeatTileRed);
		world.setBlock(i + 24, j + 0, k + 10, VetheaBlocks.karosHeatTileGreen);
		world.setBlock(i + 24, j + 0, k + 11, VetheaBlocks.karosHeatTileGreen);
		world.setBlock(i + 24, j + 0, k + 12, VetheaBlocks.karosHeatTileRed);
		world.setBlock(i + 24, j + 0, k + 13, VetheaBlocks.karosHeatTileRed);
		world.setBlock(i + 24, j + 0, k + 14, VetheaBlocks.karosHeatTileGreen);
		world.setBlock(i + 24, j + 0, k + 15, VetheaBlocks.karosHeatTileGreen);
		world.setBlock(i + 24, j + 0, k + 16, VetheaBlocks.karosHeatTileRed);
		world.setBlock(i + 24, j + 0, k + 17, VetheaBlocks.karosHeatTileRed);
		world.setBlock(i + 24, j + 0, k + 18, VetheaBlocks.karosBricks2);
		world.setBlock(i + 24, j + 0, k + 19, VetheaBlocks.karosBricks2);
		world.setBlock(i + 24, j + 1, k + 0, VetheaBlocks.karosBricks2);
		world.setBlock(i + 24, j + 1, k + 1, VetheaBlocks.karosBricks2);
		world.setBlock(i + 24, j + 1, k + 18, VetheaBlocks.karosBricks2);
		world.setBlock(i + 24, j + 1, k + 19, VetheaBlocks.karosBricks2);
		world.setBlock(i + 24, j + 2, k + 0, VetheaBlocks.karosBricks2);
		world.setBlock(i + 24, j + 2, k + 1, VetheaBlocks.karosCannon);
		world.setBlock(i + 24, j + 2, k + 18, VetheaBlocks.karosCannon);
		world.setBlock(i + 24, j + 2, k + 19, VetheaBlocks.karosBricks2);
		world.setBlock(i + 24, j + 3, k + 1, VetheaBlocks.karosBricks);
		world.setBlock(i + 24, j + 3, k + 18, VetheaBlocks.karosBricks);
		world.setBlock(i + 24, j + 4, k + 2, VetheaBlocks.karosBricks);
		world.setBlock(i + 24, j + 4, k + 4, VetheaBlocks.helioticBeam);
		world.setBlock(i + 24, j + 4, k + 5, VetheaBlocks.helioticBeam);
		world.setBlock(i + 24, j + 4, k + 6, VetheaBlocks.helioticBeam);
		world.setBlock(i + 24, j + 4, k + 12, VetheaBlocks.helioticBeam);
		world.setBlock(i + 24, j + 4, k + 13, VetheaBlocks.helioticBeam);
		world.setBlock(i + 24, j + 4, k + 14, VetheaBlocks.helioticBeam);
		world.setBlock(i + 24, j + 4, k + 17, VetheaBlocks.karosBricks);
		world.setBlock(i + 24, j + 5, k + 3, VetheaBlocks.karosBricks);
		world.setBlock(i + 24, j + 5, k + 4, VetheaBlocks.karosBricks2);
		world.setBlock(i + 24, j + 5, k + 5, VetheaBlocks.karosBricks);
		world.setBlock(i + 24, j + 5, k + 6, VetheaBlocks.karosBricks2);
		world.setBlock(i + 24, j + 5, k + 7, VetheaBlocks.karosBricks2);
		world.setBlock(i + 24, j + 5, k + 8, VetheaBlocks.karosBricks2);
		world.setBlock(i + 24, j + 5, k + 9, VetheaBlocks.karosBricks2);
		world.setBlock(i + 24, j + 5, k + 10, VetheaBlocks.karosBricks2);
		world.setBlock(i + 24, j + 5, k + 11, VetheaBlocks.karosBricks2);
		world.setBlock(i + 24, j + 5, k + 12, VetheaBlocks.karosBricks2);
		world.setBlock(i + 24, j + 5, k + 13, VetheaBlocks.karosBricks2);
		world.setBlock(i + 24, j + 5, k + 14, VetheaBlocks.karosBricks);
		world.setBlock(i + 24, j + 5, k + 15, VetheaBlocks.karosBricks2);
		world.setBlock(i + 24, j + 5, k + 16, VetheaBlocks.karosBricks);
		world.setBlock(i + 25, j + 0, k + 1, VetheaBlocks.karosBricks2);
		world.setBlock(i + 25, j + 0, k + 2, VetheaBlocks.karosHeatTileRed);
		world.setBlock(i + 25, j + 0, k + 3, VetheaBlocks.karosHeatTileRed);
		world.setBlock(i + 25, j + 0, k + 4, VetheaBlocks.karosHeatTileGreen);
		world.setBlock(i + 25, j + 0, k + 5, VetheaBlocks.karosHeatTileGreen);
		world.setBlock(i + 25, j + 0, k + 6, VetheaBlocks.karosHeatTileRed);
		world.setBlock(i + 25, j + 0, k + 7, VetheaBlocks.karosHeatTileRed);
		world.setBlock(i + 25, j + 0, k + 8, VetheaBlocks.karosHeatTileGreen);
		world.setBlock(i + 25, j + 0, k + 9, VetheaBlocks.karosHeatTileGreen);
		world.setBlock(i + 25, j + 0, k + 10, VetheaBlocks.karosHeatTileRed);
		world.setBlock(i + 25, j + 0, k + 11, VetheaBlocks.karosHeatTileRed);
		world.setBlock(i + 25, j + 0, k + 12, VetheaBlocks.karosHeatTileGreen);
		world.setBlock(i + 25, j + 0, k + 13, VetheaBlocks.karosHeatTileGreen);
		world.setBlock(i + 25, j + 0, k + 14, VetheaBlocks.karosHeatTileRed);
		world.setBlock(i + 25, j + 0, k + 15, VetheaBlocks.karosHeatTileRed);
		world.setBlock(i + 25, j + 0, k + 16, VetheaBlocks.karosHeatTileGreen);
		world.setBlock(i + 25, j + 0, k + 17, VetheaBlocks.karosHeatTileGreen);
		world.setBlock(i + 25, j + 0, k + 18, VetheaBlocks.karosBricks2);
		world.setBlock(i + 25, j + 1, k + 1, VetheaBlocks.karosBricks2);
		world.setBlock(i + 25, j + 1, k + 18, VetheaBlocks.karosBricks2);
		world.setBlock(i + 25, j + 2, k + 1, VetheaBlocks.karosBricks);
		world.setBlock(i + 25, j + 2, k + 18, VetheaBlocks.karosBricks);
		world.setBlock(i + 25, j + 3, k + 1, VetheaBlocks.karosBricks);
		world.setBlock(i + 25, j + 3, k + 18, VetheaBlocks.karosBricks);
		world.setBlock(i + 25, j + 4, k + 2, VetheaBlocks.karosBricks);
		world.setBlock(i + 25, j + 4, k + 4, VetheaBlocks.helioticBeam);
		world.setBlock(i + 25, j + 4, k + 5, VetheaBlocks.helioticBeam);
		world.setBlock(i + 25, j + 4, k + 6, VetheaBlocks.helioticBeam);
		world.setBlock(i + 25, j + 4, k + 17, VetheaBlocks.karosBricks);
		world.setBlock(i + 25, j + 5, k + 3, VetheaBlocks.karosBricks);
		world.setBlock(i + 25, j + 5, k + 4, VetheaBlocks.karosBricks2);
		world.setBlock(i + 25, j + 5, k + 5, VetheaBlocks.karosBricks);
		world.setBlock(i + 25, j + 5, k + 6, VetheaBlocks.karosBricks);
		world.setBlock(i + 25, j + 5, k + 7, VetheaBlocks.karosBricks);
		world.setBlock(i + 25, j + 5, k + 8, VetheaBlocks.karosBricks);
		world.setBlock(i + 25, j + 5, k + 9, VetheaBlocks.karosBricks);
		world.setBlock(i + 25, j + 5, k + 10, VetheaBlocks.karosBricks);
		world.setBlock(i + 25, j + 5, k + 11, VetheaBlocks.karosBricks);
		world.setBlock(i + 25, j + 5, k + 12, VetheaBlocks.karosBricks);
		world.setBlock(i + 25, j + 5, k + 13, VetheaBlocks.karosBricks);
		world.setBlock(i + 25, j + 5, k + 14, VetheaBlocks.karosBricks);
		world.setBlock(i + 25, j + 5, k + 15, VetheaBlocks.karosBricks2);
		world.setBlock(i + 25, j + 5, k + 16, VetheaBlocks.karosBricks);
		world.setBlock(i + 26, j + 0, k + 0, VetheaBlocks.karosBricks2);
		world.setBlock(i + 26, j + 0, k + 1, VetheaBlocks.karosBricks2);
		world.setBlock(i + 26, j + 0, k + 2, VetheaBlocks.karosHeatTileRed);
		world.setBlock(i + 26, j + 0, k + 3, VetheaBlocks.karosHeatTileRed);
		world.setBlock(i + 26, j + 0, k + 4, VetheaBlocks.karosHeatTileGreen);
		world.setBlock(i + 26, j + 0, k + 5, VetheaBlocks.karosHeatTileGreen);
		world.setBlock(i + 26, j + 0, k + 6, VetheaBlocks.karosHeatTileRed);
		world.setBlock(i + 26, j + 0, k + 7, VetheaBlocks.karosHeatTileRed);
		world.setBlock(i + 26, j + 0, k + 8, VetheaBlocks.karosHeatTileGreen);
		world.setBlock(i + 26, j + 0, k + 9, VetheaBlocks.karosHeatTileGreen);
		world.setBlock(i + 26, j + 0, k + 10, VetheaBlocks.karosHeatTileRed);
		world.setBlock(i + 26, j + 0, k + 11, VetheaBlocks.karosHeatTileRed);
		world.setBlock(i + 26, j + 0, k + 12, VetheaBlocks.karosHeatTileGreen);
		world.setBlock(i + 26, j + 0, k + 13, VetheaBlocks.karosHeatTileGreen);
		world.setBlock(i + 26, j + 0, k + 14, VetheaBlocks.karosHeatTileRed);
		world.setBlock(i + 26, j + 0, k + 15, VetheaBlocks.karosHeatTileRed);
		world.setBlock(i + 26, j + 0, k + 16, VetheaBlocks.karosHeatTileGreen);
		world.setBlock(i + 26, j + 0, k + 17, VetheaBlocks.karosHeatTileGreen);
		world.setBlock(i + 26, j + 0, k + 18, VetheaBlocks.karosBricks2);
		world.setBlock(i + 26, j + 0, k + 19, VetheaBlocks.karosBricks2);
		world.setBlock(i + 26, j + 1, k + 0, VetheaBlocks.karosBricks2);
		world.setBlock(i + 26, j + 1, k + 1, VetheaBlocks.karosBricks2);
		world.setBlock(i + 26, j + 1, k + 9, VetheaBlocks.villageLamp);
		world.setBlock(i + 26, j + 1, k + 10, VetheaBlocks.villageLamp);
		world.setBlock(i + 26, j + 1, k + 18, VetheaBlocks.karosBricks2);
		world.setBlock(i + 26, j + 1, k + 19, VetheaBlocks.karosBricks2);
		world.setBlock(i + 26, j + 2, k + 0, VetheaBlocks.karosBricks2);
		world.setBlock(i + 26, j + 2, k + 1, VetheaBlocks.karosCannon);
		world.setBlock(i + 26, j + 2, k + 18, VetheaBlocks.karosCannon);
		world.setBlock(i + 26, j + 2, k + 19, VetheaBlocks.karosBricks2);
		world.setBlock(i + 26, j + 3, k + 1, VetheaBlocks.karosBricks);
		world.setBlock(i + 26, j + 3, k + 18, VetheaBlocks.karosBricks);
		world.setBlock(i + 26, j + 4, k + 2, VetheaBlocks.karosBricks);
		world.setBlock(i + 26, j + 4, k + 17, VetheaBlocks.karosBricks);
		world.setBlock(i + 26, j + 5, k + 3, VetheaBlocks.karosBricks);
		world.setBlock(i + 26, j + 5, k + 4, VetheaBlocks.karosBricks2);
		world.setBlock(i + 26, j + 5, k + 5, VetheaBlocks.karosBricks2);
		world.setBlock(i + 26, j + 5, k + 6, VetheaBlocks.karosBricks2);
		world.setBlock(i + 26, j + 5, k + 7, VetheaBlocks.karosBricks2);
		world.setBlock(i + 26, j + 5, k + 8, VetheaBlocks.karosBricks2);
		world.setBlock(i + 26, j + 5, k + 9, VetheaBlocks.karosBricks2);
		world.setBlock(i + 26, j + 5, k + 10, VetheaBlocks.karosBricks2);
		world.setBlock(i + 26, j + 5, k + 11, VetheaBlocks.karosBricks2);
		world.setBlock(i + 26, j + 5, k + 12, VetheaBlocks.karosBricks2);
		world.setBlock(i + 26, j + 5, k + 13, VetheaBlocks.karosBricks2);
		world.setBlock(i + 26, j + 5, k + 14, VetheaBlocks.karosBricks2);
		world.setBlock(i + 26, j + 5, k + 15, VetheaBlocks.karosBricks2);
		world.setBlock(i + 26, j + 5, k + 16, VetheaBlocks.karosBricks);
		world.setBlock(i + 27, j + 0, k + 1, VetheaBlocks.karosBricks2);
		world.setBlock(i + 27, j + 0, k + 2, VetheaBlocks.karosHeatTileGreen);
		world.setBlock(i + 27, j + 0, k + 3, VetheaBlocks.karosHeatTileGreen);
		world.setBlock(i + 27, j + 0, k + 4, VetheaBlocks.karosHeatTileRed);
		world.setBlock(i + 27, j + 0, k + 5, VetheaBlocks.karosHeatTileRed);
		world.setBlock(i + 27, j + 0, k + 6, VetheaBlocks.karosHeatTileGreen);
		world.setBlock(i + 27, j + 0, k + 7, VetheaBlocks.karosHeatTileGreen);
		world.setBlock(i + 27, j + 0, k + 8, VetheaBlocks.karosHeatTileRed);
		world.setBlock(i + 27, j + 0, k + 9, VetheaBlocks.karosHeatTileRed);
		world.setBlock(i + 27, j + 0, k + 10, VetheaBlocks.karosHeatTileGreen);
		world.setBlock(i + 27, j + 0, k + 11, VetheaBlocks.karosHeatTileGreen);
		world.setBlock(i + 27, j + 0, k + 12, VetheaBlocks.karosHeatTileRed);
		world.setBlock(i + 27, j + 0, k + 13, VetheaBlocks.karosHeatTileRed);
		world.setBlock(i + 27, j + 0, k + 14, VetheaBlocks.karosHeatTileGreen);
		world.setBlock(i + 27, j + 0, k + 15, VetheaBlocks.karosHeatTileGreen);
		world.setBlock(i + 27, j + 0, k + 16, VetheaBlocks.karosHeatTileRed);
		world.setBlock(i + 27, j + 0, k + 17, VetheaBlocks.karosHeatTileRed);
		world.setBlock(i + 27, j + 0, k + 18, VetheaBlocks.karosBricks2);
		world.setBlock(i + 27, j + 1, k + 1, VetheaBlocks.karosBricks2);
		world.setBlock(i + 27, j + 1, k + 9, VetheaBlocks.villageLamp);
		world.setBlock(i + 27, j + 1, k + 10, VetheaBlocks.villageLamp);
		world.setBlock(i + 27, j + 1, k + 18, VetheaBlocks.karosBricks2);
		world.setBlock(i + 27, j + 2, k + 1, VetheaBlocks.karosBricks);
		world.setBlock(i + 27, j + 2, k + 9, VetheaBlocks.karosAltar);
		world.setBlock(i + 27, j + 2, k + 18, VetheaBlocks.karosBricks);
		world.setBlock(i + 27, j + 3, k + 1, VetheaBlocks.karosBricks);
		world.setBlock(i + 27, j + 3, k + 18, VetheaBlocks.karosBricks);
		world.setBlock(i + 27, j + 4, k + 2, VetheaBlocks.karosBricks);
		world.setBlock(i + 27, j + 4, k + 17, VetheaBlocks.karosBricks);
		world.setBlock(i + 27, j + 5, k + 3, VetheaBlocks.karosBricks);
		world.setBlock(i + 27, j + 5, k + 4, VetheaBlocks.karosBricks);
		world.setBlock(i + 27, j + 5, k + 5, VetheaBlocks.karosBricks);
		world.setBlock(i + 27, j + 5, k + 6, VetheaBlocks.karosBricks);
		world.setBlock(i + 27, j + 5, k + 7, VetheaBlocks.karosBricks);
		world.setBlock(i + 27, j + 5, k + 8, VetheaBlocks.karosBricks);
		world.setBlock(i + 27, j + 5, k + 9, VetheaBlocks.karosBricks);
		world.setBlock(i + 27, j + 5, k + 10, VetheaBlocks.karosBricks);
		world.setBlock(i + 27, j + 5, k + 11, VetheaBlocks.karosBricks);
		world.setBlock(i + 27, j + 5, k + 12, VetheaBlocks.karosBricks);
		world.setBlock(i + 27, j + 5, k + 13, VetheaBlocks.karosBricks);
		world.setBlock(i + 27, j + 5, k + 14, VetheaBlocks.karosBricks);
		world.setBlock(i + 27, j + 5, k + 15, VetheaBlocks.karosBricks);
		world.setBlock(i + 27, j + 5, k + 16, VetheaBlocks.karosBricks);
		world.setBlock(i + 28, j + 0, k + 0, VetheaBlocks.karosBricks2);
		world.setBlock(i + 28, j + 0, k + 1, VetheaBlocks.karosBricks2);
		world.setBlock(i + 28, j + 0, k + 2, VetheaBlocks.karosHeatTileGreen);
		world.setBlock(i + 28, j + 0, k + 3, VetheaBlocks.karosHeatTileGreen);
		world.setBlock(i + 28, j + 0, k + 4, VetheaBlocks.karosHeatTileRed);
		world.setBlock(i + 28, j + 0, k + 5, VetheaBlocks.karosHeatTileRed);
		world.setBlock(i + 28, j + 0, k + 6, VetheaBlocks.karosHeatTileGreen);
		world.setBlock(i + 28, j + 0, k + 7, VetheaBlocks.karosHeatTileGreen);
		world.setBlock(i + 28, j + 0, k + 8, VetheaBlocks.karosHeatTileRed);
		world.setBlock(i + 28, j + 0, k + 9, VetheaBlocks.karosHeatTileRed);
		world.setBlock(i + 28, j + 0, k + 10, VetheaBlocks.karosHeatTileGreen);
		world.setBlock(i + 28, j + 0, k + 11, VetheaBlocks.karosHeatTileGreen);
		world.setBlock(i + 28, j + 0, k + 12, VetheaBlocks.karosHeatTileRed);
		world.setBlock(i + 28, j + 0, k + 13, VetheaBlocks.karosHeatTileRed);
		world.setBlock(i + 28, j + 0, k + 14, VetheaBlocks.karosHeatTileGreen);
		world.setBlock(i + 28, j + 0, k + 15, VetheaBlocks.karosHeatTileGreen);
		world.setBlock(i + 28, j + 0, k + 16, VetheaBlocks.karosHeatTileRed);
		world.setBlock(i + 28, j + 0, k + 17, VetheaBlocks.karosHeatTileRed);
		world.setBlock(i + 28, j + 0, k + 18, VetheaBlocks.karosBricks2);
		world.setBlock(i + 28, j + 0, k + 19, VetheaBlocks.karosBricks2);
		world.setBlock(i + 28, j + 1, k + 0, VetheaBlocks.karosBricks2);
		world.setBlock(i + 28, j + 1, k + 1, VetheaBlocks.karosBricks2);
		world.setBlock(i + 28, j + 1, k + 9, VetheaBlocks.villageLamp);
		world.setBlock(i + 28, j + 1, k + 10, VetheaBlocks.villageLamp);
		world.setBlock(i + 28, j + 1, k + 18, VetheaBlocks.karosBricks2);
		world.setBlock(i + 28, j + 1, k + 19, VetheaBlocks.karosBricks2);
		world.setBlock(i + 28, j + 2, k + 0, VetheaBlocks.karosBricks2);
		world.setBlock(i + 28, j + 2, k + 1, VetheaBlocks.karosCannon);
		world.setBlock(i + 28, j + 2, k + 18, VetheaBlocks.karosCannon);
		world.setBlock(i + 28, j + 2, k + 19, VetheaBlocks.karosBricks2);
		world.setBlock(i + 28, j + 3, k + 1, VetheaBlocks.karosBricks);
		world.setBlock(i + 28, j + 3, k + 9, VetheaBlocks.karosCannon);
		world.setBlock(i + 28, j + 3, k + 10, VetheaBlocks.karosCannon);
		world.setBlock(i + 28, j + 3, k + 18, VetheaBlocks.karosBricks);
		world.setBlock(i + 28, j + 4, k + 2, VetheaBlocks.karosBricks);
		world.setBlock(i + 28, j + 4, k + 3, VetheaBlocks.karosBricks);
		world.setBlock(i + 28, j + 4, k + 4, VetheaBlocks.karosBricks);
		world.setBlock(i + 28, j + 4, k + 5, VetheaBlocks.karosBricks);
		world.setBlock(i + 28, j + 4, k + 6, VetheaBlocks.karosBricks);
		world.setBlock(i + 28, j + 4, k + 7, VetheaBlocks.karosBricks);
		world.setBlock(i + 28, j + 4, k + 8, VetheaBlocks.karosBricks);
		world.setBlock(i + 28, j + 4, k + 9, VetheaBlocks.karosBricks);
		world.setBlock(i + 28, j + 4, k + 10, VetheaBlocks.karosBricks);
		world.setBlock(i + 28, j + 4, k + 11, VetheaBlocks.karosBricks);
		world.setBlock(i + 28, j + 4, k + 12, VetheaBlocks.karosBricks);
		world.setBlock(i + 28, j + 4, k + 13, VetheaBlocks.karosBricks);
		world.setBlock(i + 28, j + 4, k + 14, VetheaBlocks.karosBricks);
		world.setBlock(i + 28, j + 4, k + 15, VetheaBlocks.karosBricks);
		world.setBlock(i + 28, j + 4, k + 16, VetheaBlocks.karosBricks);
		world.setBlock(i + 28, j + 4, k + 17, VetheaBlocks.karosBricks);
		world.setBlock(i + 29, j + 0, k + 1, VetheaBlocks.karosBricks2);
		world.setBlock(i + 29, j + 0, k + 2, VetheaBlocks.karosBricks2);
		world.setBlock(i + 29, j + 0, k + 3, VetheaBlocks.karosBricks2);
		world.setBlock(i + 29, j + 0, k + 4, VetheaBlocks.karosBricks2);
		world.setBlock(i + 29, j + 0, k + 5, VetheaBlocks.karosBricks2);
		world.setBlock(i + 29, j + 0, k + 6, VetheaBlocks.karosBricks2);
		world.setBlock(i + 29, j + 0, k + 7, VetheaBlocks.karosBricks2);
		world.setBlock(i + 29, j + 0, k + 8, VetheaBlocks.karosBricks2);
		world.setBlock(i + 29, j + 0, k + 9, VetheaBlocks.karosBricks2);
		world.setBlock(i + 29, j + 0, k + 10, VetheaBlocks.karosBricks2);
		world.setBlock(i + 29, j + 0, k + 11, VetheaBlocks.karosBricks2);
		world.setBlock(i + 29, j + 0, k + 12, VetheaBlocks.karosBricks2);
		world.setBlock(i + 29, j + 0, k + 13, VetheaBlocks.karosBricks2);
		world.setBlock(i + 29, j + 0, k + 14, VetheaBlocks.karosBricks2);
		world.setBlock(i + 29, j + 0, k + 15, VetheaBlocks.karosBricks2);
		world.setBlock(i + 29, j + 0, k + 16, VetheaBlocks.karosBricks2);
		world.setBlock(i + 29, j + 0, k + 17, VetheaBlocks.karosBricks2);
		world.setBlock(i + 29, j + 0, k + 18, VetheaBlocks.karosBricks2);
		world.setBlock(i + 29, j + 1, k + 1, VetheaBlocks.karosBricks2);
		world.setBlock(i + 29, j + 1, k + 2, VetheaBlocks.karosBricks2);
		world.setBlock(i + 29, j + 1, k + 3, VetheaBlocks.karosBricks2);
		world.setBlock(i + 29, j + 1, k + 4, VetheaBlocks.karosBricks2);
		world.setBlock(i + 29, j + 1, k + 5, VetheaBlocks.karosBricks2);
		world.setBlock(i + 29, j + 1, k + 6, VetheaBlocks.karosBricks2);
		world.setBlock(i + 29, j + 1, k + 7, VetheaBlocks.karosBricks2);
		world.setBlock(i + 29, j + 1, k + 8, VetheaBlocks.karosBricks2);
		world.setBlock(i + 29, j + 1, k + 9, VetheaBlocks.karosBricks2);
		world.setBlock(i + 29, j + 1, k + 10, VetheaBlocks.karosBricks2);
		world.setBlock(i + 29, j + 1, k + 11, VetheaBlocks.karosBricks2);
		world.setBlock(i + 29, j + 1, k + 12, VetheaBlocks.karosBricks2);
		world.setBlock(i + 29, j + 1, k + 13, VetheaBlocks.karosBricks2);
		world.setBlock(i + 29, j + 1, k + 14, VetheaBlocks.karosBricks2);
		world.setBlock(i + 29, j + 1, k + 15, VetheaBlocks.karosBricks2);
		world.setBlock(i + 29, j + 1, k + 16, VetheaBlocks.karosBricks2);
		world.setBlock(i + 29, j + 1, k + 17, VetheaBlocks.karosBricks2);
		world.setBlock(i + 29, j + 1, k + 18, VetheaBlocks.karosBricks2);
		world.setBlock(i + 29, j + 2, k + 1, VetheaBlocks.karosBricks);
		world.setBlock(i + 29, j + 2, k + 2, VetheaBlocks.karosCannon);
		world.setBlock(i + 29, j + 2, k + 3, VetheaBlocks.karosBricks);
		world.setBlock(i + 29, j + 2, k + 4, VetheaBlocks.karosCannon);
		world.setBlock(i + 29, j + 2, k + 5, VetheaBlocks.karosBricks);
		world.setBlock(i + 29, j + 2, k + 6, VetheaBlocks.karosCannon);
		world.setBlock(i + 29, j + 2, k + 7, VetheaBlocks.karosBricks);
		world.setBlock(i + 29, j + 2, k + 8, VetheaBlocks.karosCannon);
		world.setBlock(i + 29, j + 2, k + 9, VetheaBlocks.karosCannon);
		world.setBlock(i + 29, j + 2, k + 10, VetheaBlocks.karosCannon);
		world.setBlock(i + 29, j + 2, k + 11, VetheaBlocks.karosCannon);
		world.setBlock(i + 29, j + 2, k + 12, VetheaBlocks.karosBricks);
		world.setBlock(i + 29, j + 2, k + 13, VetheaBlocks.karosCannon);
		world.setBlock(i + 29, j + 2, k + 14, VetheaBlocks.karosBricks);
		world.setBlock(i + 29, j + 2, k + 15, VetheaBlocks.karosCannon);
		world.setBlock(i + 29, j + 2, k + 16, VetheaBlocks.karosBricks);
		world.setBlock(i + 29, j + 2, k + 17, VetheaBlocks.karosCannon);
		world.setBlock(i + 29, j + 2, k + 18, VetheaBlocks.karosBricks);
		world.setBlock(i + 29, j + 3, k + 1, VetheaBlocks.karosBricks);
		world.setBlock(i + 29, j + 3, k + 2, VetheaBlocks.karosBricks);
		world.setBlock(i + 29, j + 3, k + 3, VetheaBlocks.karosBricks);
		world.setBlock(i + 29, j + 3, k + 4, VetheaBlocks.karosBricks);
		world.setBlock(i + 29, j + 3, k + 5, VetheaBlocks.karosBricks);
		world.setBlock(i + 29, j + 3, k + 6, VetheaBlocks.karosBricks);
		world.setBlock(i + 29, j + 3, k + 7, VetheaBlocks.karosBricks);
		world.setBlock(i + 29, j + 3, k + 8, VetheaBlocks.karosBricks);
		world.setBlock(i + 29, j + 3, k + 9, VetheaBlocks.karosBricks);
		world.setBlock(i + 29, j + 3, k + 10, VetheaBlocks.karosBricks);
		world.setBlock(i + 29, j + 3, k + 11, VetheaBlocks.karosBricks);
		world.setBlock(i + 29, j + 3, k + 12, VetheaBlocks.karosBricks);
		world.setBlock(i + 29, j + 3, k + 13, VetheaBlocks.karosBricks);
		world.setBlock(i + 29, j + 3, k + 14, VetheaBlocks.karosBricks);
		world.setBlock(i + 29, j + 3, k + 15, VetheaBlocks.karosBricks);
		world.setBlock(i + 29, j + 3, k + 16, VetheaBlocks.karosBricks);
		world.setBlock(i + 29, j + 3, k + 17, VetheaBlocks.karosBricks);
		world.setBlock(i + 29, j + 3, k + 18, VetheaBlocks.karosBricks);
		world.setBlock(i + 30, j + 0, k + 2, VetheaBlocks.karosBricks2);
		world.setBlock(i + 30, j + 0, k + 4, VetheaBlocks.karosBricks2);
		world.setBlock(i + 30, j + 0, k + 6, VetheaBlocks.karosBricks2);
		world.setBlock(i + 30, j + 0, k + 8, VetheaBlocks.karosBricks2);
		world.setBlock(i + 30, j + 0, k + 11, VetheaBlocks.karosBricks2);
		world.setBlock(i + 30, j + 0, k + 13, VetheaBlocks.karosBricks2);
		world.setBlock(i + 30, j + 0, k + 15, VetheaBlocks.karosBricks2);
		world.setBlock(i + 30, j + 0, k + 17, VetheaBlocks.karosBricks2);
		world.setBlock(i + 30, j + 1, k + 2, VetheaBlocks.karosBricks2);
		world.setBlock(i + 30, j + 1, k + 4, VetheaBlocks.karosBricks2);
		world.setBlock(i + 30, j + 1, k + 6, VetheaBlocks.karosBricks2);
		world.setBlock(i + 30, j + 1, k + 8, VetheaBlocks.karosBricks2);
		world.setBlock(i + 30, j + 1, k + 11, VetheaBlocks.karosBricks2);
		world.setBlock(i + 30, j + 1, k + 13, VetheaBlocks.karosBricks2);
		world.setBlock(i + 30, j + 1, k + 15, VetheaBlocks.karosBricks2);
		world.setBlock(i + 30, j + 1, k + 17, VetheaBlocks.karosBricks2);
		world.setBlock(i + 30, j + 2, k + 2, VetheaBlocks.karosBricks2);
		world.setBlock(i + 30, j + 2, k + 4, VetheaBlocks.karosBricks2);
		world.setBlock(i + 30, j + 2, k + 6, VetheaBlocks.karosBricks2);
		world.setBlock(i + 30, j + 2, k + 8, VetheaBlocks.karosBricks2);
		world.setBlock(i + 30, j + 2, k + 9, VetheaBlocks.karosBricks2);
		world.setBlock(i + 30, j + 2, k + 10, VetheaBlocks.karosBricks2);
		world.setBlock(i + 30, j + 2, k + 11, VetheaBlocks.karosBricks2);
		world.setBlock(i + 30, j + 2, k + 13, VetheaBlocks.karosBricks2);
		world.setBlock(i + 30, j + 2, k + 15, VetheaBlocks.karosBricks2);
		world.setBlock(i + 30, j + 2, k + 17, VetheaBlocks.karosBricks2);

		return true;
	}
}