/*
*** MADE BY MITHION'S .SCHEMATIC TO JAVA CONVERTING TOOL v1.6 ***
*/

package net.divinerpg.dimensions.vethea.layer3;
import java.util.Random;

import net.divinerpg.utils.blocks.VetheaBlocks;
import net.minecraft.world.World;
import net.minecraft.world.gen.feature.WorldGenerator;

public class Tree8 extends WorldGenerator
{
	protected int[] GetValidSpawnBlocks() {
		return new int[] {
		};
	}

	public Tree8() { }

	public boolean generate(World world, Random rand, int i, int j, int k) {

		world.setBlock(i + 0, j + 14, k + 2, VetheaBlocks.mintwoodLeaves);
		world.setBlock(i + 0, j + 14, k + 3, VetheaBlocks.mintwoodLeaves);
		world.setBlock(i + 0, j + 14, k + 4, VetheaBlocks.mintwoodLeaves);
		world.setBlock(i + 0, j + 15, k + 2, VetheaBlocks.mintwoodLeaves);
		world.setBlock(i + 0, j + 15, k + 3, VetheaBlocks.mintwoodLeaves);
		world.setBlock(i + 0, j + 15, k + 4, VetheaBlocks.mintwoodLeaves);
		world.setBlock(i + 0, j + 16, k + 2, VetheaBlocks.mintwoodLeaves);
		world.setBlock(i + 0, j + 16, k + 3, VetheaBlocks.mintwoodLeaves);
		world.setBlock(i + 0, j + 16, k + 4, VetheaBlocks.mintwoodLeaves);
		world.setBlock(i + 1, j + 13, k + 2, VetheaBlocks.mintwoodLeaves);
		world.setBlock(i + 1, j + 13, k + 3, VetheaBlocks.mintwoodLeaves);
		world.setBlock(i + 1, j + 13, k + 4, VetheaBlocks.mintwoodLeaves);
		world.setBlock(i + 1, j + 13, k + 5, VetheaBlocks.mintwoodLeaves);
		world.setBlock(i + 1, j + 13, k + 6, VetheaBlocks.mintwoodLeaves);
		world.setBlock(i + 1, j + 13, k + 7, VetheaBlocks.mintwoodLeaves);
		world.setBlock(i + 1, j + 14, k + 1, VetheaBlocks.mintwoodLeaves);
		world.setBlock(i + 1, j + 14, k + 2, VetheaBlocks.mintwoodLeaves);
		world.setBlock(i + 1, j + 14, k + 3, VetheaBlocks.mintwoodLeaves);
		world.setBlock(i + 1, j + 14, k + 4, VetheaBlocks.mintwoodLeaves);
		world.setBlock(i + 1, j + 14, k + 5, VetheaBlocks.mintwoodLeaves);
		world.setBlock(i + 1, j + 14, k + 6, VetheaBlocks.mintwoodLeaves);
		world.setBlock(i + 1, j + 14, k + 7, VetheaBlocks.mintwoodLeaves);
		world.setBlock(i + 1, j + 14, k + 8, VetheaBlocks.mintwoodLeaves);
		world.setBlock(i + 1, j + 15, k + 1, VetheaBlocks.mintwoodLeaves);
		world.setBlock(i + 1, j + 15, k + 2, VetheaBlocks.mintwoodLeaves);
		world.setBlock(i + 1, j + 15, k + 3, VetheaBlocks.mintwoodLeaves);
		world.setBlock(i + 1, j + 15, k + 4, VetheaBlocks.mintwoodLeaves);
		world.setBlock(i + 1, j + 15, k + 5, VetheaBlocks.mintwoodLeaves);
		world.setBlock(i + 1, j + 15, k + 6, VetheaBlocks.mintwoodLeaves);
		world.setBlock(i + 1, j + 15, k + 7, VetheaBlocks.mintwoodLeaves);
		world.setBlock(i + 1, j + 15, k + 8, VetheaBlocks.mintwoodLeaves);
		world.setBlock(i + 1, j + 16, k + 1, VetheaBlocks.mintwoodLeaves);
		world.setBlock(i + 1, j + 16, k + 2, VetheaBlocks.mintwoodLeaves);
		world.setBlock(i + 1, j + 16, k + 3, VetheaBlocks.mintwoodLeaves);
		world.setBlock(i + 1, j + 16, k + 4, VetheaBlocks.mintwoodLeaves);
		world.setBlock(i + 1, j + 16, k + 5, VetheaBlocks.mintwoodLeaves);
		world.setBlock(i + 1, j + 16, k + 6, VetheaBlocks.mintwoodLeaves);
		world.setBlock(i + 1, j + 16, k + 7, VetheaBlocks.mintwoodLeaves);
		world.setBlock(i + 1, j + 16, k + 8, VetheaBlocks.mintwoodLeaves);
		world.setBlock(i + 1, j + 17, k + 2, VetheaBlocks.mintwoodLeaves);
		world.setBlock(i + 1, j + 17, k + 3, VetheaBlocks.mintwoodLeaves);
		world.setBlock(i + 1, j + 17, k + 4, VetheaBlocks.mintwoodLeaves);
		world.setBlock(i + 1, j + 17, k + 5, VetheaBlocks.mintwoodLeaves);
		world.setBlock(i + 1, j + 17, k + 6, VetheaBlocks.mintwoodLeaves);
		world.setBlock(i + 1, j + 17, k + 7, VetheaBlocks.mintwoodLeaves);
		world.setBlock(i + 2, j + 12, k + 4, VetheaBlocks.mintwoodLeaves);
		world.setBlock(i + 2, j + 12, k + 5, VetheaBlocks.mintwoodLeaves);
		world.setBlock(i + 2, j + 12, k + 6, VetheaBlocks.mintwoodLeaves);
		world.setBlock(i + 2, j + 12, k + 7, VetheaBlocks.mintwoodLeaves);
		world.setBlock(i + 2, j + 12, k + 8, VetheaBlocks.mintwoodLeaves);
		world.setBlock(i + 2, j + 13, k + 2, VetheaBlocks.mintwoodLeaves);
		world.setBlock(i + 2, j + 13, k + 3, VetheaBlocks.mintwoodLeaves);
		world.setBlock(i + 2, j + 13, k + 4, VetheaBlocks.mintwoodLeaves);
		world.setBlock(i + 2, j + 13, k + 5, VetheaBlocks.mintwoodLeaves);
		world.setBlock(i + 2, j + 13, k + 6, VetheaBlocks.mintwoodLeaves);
		world.setBlock(i + 2, j + 13, k + 7, VetheaBlocks.mintwoodLeaves);
		world.setBlock(i + 2, j + 13, k + 8, VetheaBlocks.mintwoodLeaves);
		world.setBlock(i + 2, j + 13, k + 9, VetheaBlocks.mintwoodLeaves);
		world.setBlock(i + 2, j + 14, k + 1, VetheaBlocks.mintwoodLeaves);
		world.setBlock(i + 2, j + 14, k + 2, VetheaBlocks.mintwoodLeaves);
		world.setBlock(i + 2, j + 14, k + 3, VetheaBlocks.mintwoodLeaves);
		world.setBlock(i + 2, j + 14, k + 4, VetheaBlocks.mintwoodLeaves);
		world.setBlock(i + 2, j + 14, k + 5, VetheaBlocks.mintwoodLeaves);
		world.setBlock(i + 2, j + 14, k + 6, VetheaBlocks.mintwoodLeaves);
		world.setBlock(i + 2, j + 14, k + 7, VetheaBlocks.mintwoodLeaves);
		world.setBlock(i + 2, j + 14, k + 8, VetheaBlocks.mintwoodLeaves);
		world.setBlock(i + 2, j + 14, k + 9, VetheaBlocks.mintwoodLeaves);
		world.setBlock(i + 2, j + 15, k + 1, VetheaBlocks.mintwoodLeaves);
		world.setBlock(i + 2, j + 15, k + 2, VetheaBlocks.mintwoodLeaves);
		world.setBlock(i + 2, j + 15, k + 3, VetheaBlocks.mintwoodLeaves);
		world.setBlock(i + 2, j + 15, k + 4, VetheaBlocks.mintwoodLeaves);
		world.setBlock(i + 2, j + 15, k + 5, VetheaBlocks.mintwoodLeaves);
		world.setBlock(i + 2, j + 15, k + 6, VetheaBlocks.mintwoodLeaves);
		world.setBlock(i + 2, j + 15, k + 7, VetheaBlocks.mintwoodLeaves);
		world.setBlock(i + 2, j + 15, k + 8, VetheaBlocks.mintwoodLeaves);
		world.setBlock(i + 2, j + 15, k + 9, VetheaBlocks.mintwoodLeaves);
		world.setBlock(i + 2, j + 16, k + 1, VetheaBlocks.mintwoodLeaves);
		world.setBlock(i + 2, j + 16, k + 2, VetheaBlocks.mintwoodLeaves);
		world.setBlock(i + 2, j + 16, k + 5, VetheaBlocks.mintwoodLeaves);
		world.setBlock(i + 2, j + 16, k + 6, VetheaBlocks.mintwoodLeaves);
		world.setBlock(i + 2, j + 16, k + 7, VetheaBlocks.mintwoodLeaves);
		world.setBlock(i + 2, j + 16, k + 8, VetheaBlocks.mintwoodLeaves);
		world.setBlock(i + 2, j + 16, k + 9, VetheaBlocks.mintwoodLeaves);
		world.setBlock(i + 2, j + 17, k + 2, VetheaBlocks.mintwoodLeaves);
		world.setBlock(i + 2, j + 17, k + 3, VetheaBlocks.mintwoodLeaves);
		world.setBlock(i + 2, j + 17, k + 4, VetheaBlocks.mintwoodLeaves);
		world.setBlock(i + 2, j + 17, k + 5, VetheaBlocks.mintwoodLeaves);
		world.setBlock(i + 2, j + 17, k + 6, VetheaBlocks.mintwoodLeaves);
		world.setBlock(i + 2, j + 17, k + 7, VetheaBlocks.mintwoodLeaves);
		world.setBlock(i + 2, j + 17, k + 8, VetheaBlocks.mintwoodLeaves);
		world.setBlock(i + 2, j + 17, k + 9, VetheaBlocks.mintwoodLeaves);
		world.setBlock(i + 2, j + 18, k + 4, VetheaBlocks.mintwoodLeaves);
		world.setBlock(i + 2, j + 18, k + 5, VetheaBlocks.mintwoodLeaves);
		world.setBlock(i + 2, j + 18, k + 6, VetheaBlocks.mintwoodLeaves);
		world.setBlock(i + 2, j + 18, k + 7, VetheaBlocks.mintwoodLeaves);
		world.setBlock(i + 2, j + 18, k + 8, VetheaBlocks.mintwoodLeaves);
		world.setBlock(i + 3, j + 11, k + 4, VetheaBlocks.mintwoodLeaves);
		world.setBlock(i + 3, j + 11, k + 5, VetheaBlocks.mintwoodLeaves);
		world.setBlock(i + 3, j + 11, k + 6, VetheaBlocks.mintwoodLeaves);
		world.setBlock(i + 3, j + 11, k + 7, VetheaBlocks.mintwoodLeaves);
		world.setBlock(i + 3, j + 11, k + 8, VetheaBlocks.mintwoodLeaves);
		world.setBlock(i + 3, j + 12, k + 3, VetheaBlocks.mintwoodLeaves);
		world.setBlock(i + 3, j + 12, k + 4, VetheaBlocks.mintwoodLeaves);
		world.setBlock(i + 3, j + 12, k + 5, VetheaBlocks.mintwoodLeaves);
		world.setBlock(i + 3, j + 12, k + 6, VetheaBlocks.mintwoodLeaves);
		world.setBlock(i + 3, j + 12, k + 7, VetheaBlocks.mintwoodLeaves);
		world.setBlock(i + 3, j + 12, k + 8, VetheaBlocks.mintwoodLeaves);
		world.setBlock(i + 3, j + 12, k + 9, VetheaBlocks.mintwoodLeaves);
		world.setBlock(i + 3, j + 13, k + 2, VetheaBlocks.mintwoodLeaves);
		world.setBlock(i + 3, j + 13, k + 3, VetheaBlocks.mintwoodLeaves);
		world.setBlock(i + 3, j + 13, k + 4, VetheaBlocks.mintwoodLeaves);
		world.setBlock(i + 3, j + 13, k + 5, VetheaBlocks.mintwoodLeaves);
		world.setBlock(i + 3, j + 13, k + 6, VetheaBlocks.mintwoodLeaves);
		world.setBlock(i + 3, j + 13, k + 7, VetheaBlocks.mintwoodLeaves);
		world.setBlock(i + 3, j + 13, k + 8, VetheaBlocks.mintwoodLeaves);
		world.setBlock(i + 3, j + 13, k + 9, VetheaBlocks.mintwoodLeaves);
		world.setBlock(i + 3, j + 13, k + 10, VetheaBlocks.mintwoodLeaves);
		world.setBlock(i + 3, j + 14, k + 1, VetheaBlocks.mintwoodLeaves);
		world.setBlock(i + 3, j + 14, k + 2, VetheaBlocks.mintwoodLeaves);
		world.setBlock(i + 3, j + 14, k + 3, VetheaBlocks.mintwoodLeaves);
		world.setBlock(i + 3, j + 14, k + 4, VetheaBlocks.mintwoodLeaves);
		world.setBlock(i + 3, j + 14, k + 5, VetheaBlocks.mintwoodLeaves);
		world.setBlock(i + 3, j + 14, k + 6, VetheaBlocks.mintwoodLeaves);
		world.setBlock(i + 3, j + 14, k + 7, VetheaBlocks.mintwoodLeaves);
		world.setBlock(i + 3, j + 14, k + 8, VetheaBlocks.mintwoodLeaves);
		world.setBlock(i + 3, j + 14, k + 9, VetheaBlocks.mintwoodLeaves);
		world.setBlock(i + 3, j + 14, k + 10, VetheaBlocks.mintwoodLeaves);
		world.setBlock(i + 3, j + 15, k + 1, VetheaBlocks.mintwoodLeaves);
		world.setBlock(i + 3, j + 15, k + 2, VetheaBlocks.mintwoodLeaves);
		world.setBlock(i + 3, j + 15, k + 4, VetheaBlocks.mintwoodLeaves);
		world.setBlock(i + 3, j + 15, k + 5, VetheaBlocks.mintwoodLeaves);
		world.setBlock(i + 3, j + 15, k + 6, VetheaBlocks.mintwoodLeaves);
		world.setBlock(i + 3, j + 15, k + 7, VetheaBlocks.mintwoodLeaves);
		world.setBlock(i + 3, j + 15, k + 8, VetheaBlocks.mintwoodLeaves);
		world.setBlock(i + 3, j + 15, k + 9, VetheaBlocks.mintwoodLeaves);
		world.setBlock(i + 3, j + 15, k + 10, VetheaBlocks.mintwoodLeaves);
		world.setBlock(i + 3, j + 16, k + 1, VetheaBlocks.mintwoodLeaves);
		world.setBlock(i + 3, j + 16, k + 2, VetheaBlocks.mintwoodLeaves);
		world.setBlock(i + 3, j + 16, k + 4, VetheaBlocks.mintwoodLeaves);
		world.setBlock(i + 3, j + 16, k + 5, VetheaBlocks.mintwoodLeaves);
		world.setBlock(i + 3, j + 16, k + 6, VetheaBlocks.mintwoodLeaves);
		world.setBlock(i + 3, j + 16, k + 7, VetheaBlocks.mintwoodLeaves);
		world.setBlock(i + 3, j + 16, k + 8, VetheaBlocks.mintwoodLeaves);
		world.setBlock(i + 3, j + 16, k + 9, VetheaBlocks.mintwoodLeaves);
		world.setBlock(i + 3, j + 16, k + 10, VetheaBlocks.mintwoodLeaves);
		world.setBlock(i + 3, j + 17, k + 2, VetheaBlocks.mintwoodLeaves);
		world.setBlock(i + 3, j + 17, k + 3, VetheaBlocks.mintwoodLeaves);
		world.setBlock(i + 3, j + 17, k + 4, VetheaBlocks.mintwoodLeaves);
		world.setBlock(i + 3, j + 17, k + 5, VetheaBlocks.mintwoodLeaves);
		world.setBlock(i + 3, j + 17, k + 6, VetheaBlocks.mintwoodLeaves);
		world.setBlock(i + 3, j + 17, k + 7, VetheaBlocks.mintwoodLeaves);
		world.setBlock(i + 3, j + 17, k + 8, VetheaBlocks.mintwoodLeaves);
		world.setBlock(i + 3, j + 17, k + 9, VetheaBlocks.mintwoodLeaves);
		world.setBlock(i + 3, j + 17, k + 10, VetheaBlocks.mintwoodLeaves);
		world.setBlock(i + 3, j + 18, k + 3, VetheaBlocks.mintwoodLeaves);
		world.setBlock(i + 3, j + 18, k + 4, VetheaBlocks.mintwoodLeaves);
		world.setBlock(i + 3, j + 18, k + 5, VetheaBlocks.mintwoodLeaves);
		world.setBlock(i + 3, j + 18, k + 6, VetheaBlocks.mintwoodLeaves);
		world.setBlock(i + 3, j + 18, k + 7, VetheaBlocks.mintwoodLeaves);
		world.setBlock(i + 3, j + 18, k + 8, VetheaBlocks.mintwoodLeaves);
		world.setBlock(i + 3, j + 18, k + 9, VetheaBlocks.mintwoodLeaves);
		world.setBlock(i + 3, j + 19, k + 4, VetheaBlocks.mintwoodLeaves);
		world.setBlock(i + 3, j + 19, k + 5, VetheaBlocks.mintwoodLeaves);
		world.setBlock(i + 3, j + 19, k + 6, VetheaBlocks.mintwoodLeaves);
		world.setBlock(i + 3, j + 19, k + 7, VetheaBlocks.mintwoodLeaves);
		world.setBlock(i + 3, j + 19, k + 8, VetheaBlocks.mintwoodLeaves);
		world.setBlock(i + 4, j + 0, k + 6, VetheaBlocks.mintwood);
		world.setBlock(i + 4, j + 0, k + 7, VetheaBlocks.mintwood);
		world.setBlock(i + 4, j + 1, k + 6, VetheaBlocks.mintwood);
		world.setBlock(i + 4, j + 1, k + 7, VetheaBlocks.mintwood);
		world.setBlock(i + 4, j + 2, k + 6, VetheaBlocks.mintwood);
		world.setBlock(i + 4, j + 2, k + 7, VetheaBlocks.mintwood);
		world.setBlock(i + 4, j + 3, k + 6, VetheaBlocks.mintwood);
		world.setBlock(i + 4, j + 3, k + 7, VetheaBlocks.mintwood);
		world.setBlock(i + 4, j + 4, k + 6, VetheaBlocks.mintwood);
		world.setBlock(i + 4, j + 4, k + 7, VetheaBlocks.mintwood);
		world.setBlock(i + 4, j + 5, k + 6, VetheaBlocks.mintwood);
		world.setBlock(i + 4, j + 5, k + 7, VetheaBlocks.mintwood);
		world.setBlock(i + 4, j + 6, k + 6, VetheaBlocks.mintwood);
		world.setBlock(i + 4, j + 6, k + 7, VetheaBlocks.mintwood);
		world.setBlock(i + 4, j + 7, k + 6, VetheaBlocks.mintwood);
		world.setBlock(i + 4, j + 7, k + 7, VetheaBlocks.mintwood);
		world.setBlock(i + 4, j + 8, k + 6, VetheaBlocks.mintwood);
		world.setBlock(i + 4, j + 8, k + 7, VetheaBlocks.mintwood);
		world.setBlock(i + 4, j + 9, k + 6, VetheaBlocks.mintwood);
		world.setBlock(i + 4, j + 9, k + 7, VetheaBlocks.mintwood);
		world.setBlock(i + 4, j + 10, k + 5, VetheaBlocks.mintwoodLeaves);
		world.setBlock(i + 4, j + 10, k + 6, VetheaBlocks.mintwoodLeaves);
		world.setBlock(i + 4, j + 10, k + 7, VetheaBlocks.mintwoodLeaves);
		world.setBlock(i + 4, j + 10, k + 8, VetheaBlocks.mintwoodLeaves);
		world.setBlock(i + 4, j + 11, k + 3, VetheaBlocks.mintwoodLeaves);
		world.setBlock(i + 4, j + 11, k + 4, VetheaBlocks.mintwoodLeaves);
		world.setBlock(i + 4, j + 11, k + 5, VetheaBlocks.mintwoodLeaves);
		world.setBlock(i + 4, j + 11, k + 6, VetheaBlocks.mintwoodLeaves);
		world.setBlock(i + 4, j + 11, k + 7, VetheaBlocks.mintwoodLeaves);
		world.setBlock(i + 4, j + 11, k + 8, VetheaBlocks.mintwoodLeaves);
		world.setBlock(i + 4, j + 11, k + 9, VetheaBlocks.mintwoodLeaves);
		world.setBlock(i + 4, j + 12, k + 2, VetheaBlocks.mintwoodLeaves);
		world.setBlock(i + 4, j + 12, k + 3, VetheaBlocks.mintwoodLeaves);
		world.setBlock(i + 4, j + 12, k + 4, VetheaBlocks.mintwoodLeaves);
		world.setBlock(i + 4, j + 12, k + 5, VetheaBlocks.mintwoodLeaves);
		world.setBlock(i + 4, j + 12, k + 6, VetheaBlocks.mintwoodLeaves);
		world.setBlock(i + 4, j + 12, k + 7, VetheaBlocks.mintwoodLeaves);
		world.setBlock(i + 4, j + 12, k + 8, VetheaBlocks.mintwoodLeaves);
		world.setBlock(i + 4, j + 12, k + 9, VetheaBlocks.mintwoodLeaves);
		world.setBlock(i + 4, j + 12, k + 10, VetheaBlocks.mintwoodLeaves);
		world.setBlock(i + 4, j + 13, k + 2, VetheaBlocks.mintwoodLeaves);
		world.setBlock(i + 4, j + 13, k + 3, VetheaBlocks.mintwoodLeaves);
		world.setBlock(i + 4, j + 13, k + 4, VetheaBlocks.mintwoodLeaves);
		world.setBlock(i + 4, j + 13, k + 5, VetheaBlocks.mintwoodLeaves);
		world.setBlock(i + 4, j + 13, k + 6, VetheaBlocks.mintwoodLeaves);
		world.setBlock(i + 4, j + 13, k + 7, VetheaBlocks.mintwoodLeaves);
		world.setBlock(i + 4, j + 13, k + 8, VetheaBlocks.mintwoodLeaves);
		world.setBlock(i + 4, j + 13, k + 9, VetheaBlocks.mintwoodLeaves);
		world.setBlock(i + 4, j + 13, k + 10, VetheaBlocks.mintwoodLeaves);
		world.setBlock(i + 4, j + 14, k + 1, VetheaBlocks.mintwoodLeaves);
		world.setBlock(i + 4, j + 14, k + 2, VetheaBlocks.mintwoodLeaves);
		world.setBlock(i + 4, j + 14, k + 3, VetheaBlocks.mintwoodLeaves);
		world.setBlock(i + 4, j + 14, k + 4, VetheaBlocks.mintwoodLeaves);
		world.setBlock(i + 4, j + 14, k + 5, VetheaBlocks.mintwoodLeaves);
		world.setBlock(i + 4, j + 14, k + 6, VetheaBlocks.mintwoodLeaves);
		world.setBlock(i + 4, j + 14, k + 7, VetheaBlocks.mintwoodLeaves);
		world.setBlock(i + 4, j + 14, k + 8, VetheaBlocks.mintwoodLeaves);
		world.setBlock(i + 4, j + 14, k + 9, VetheaBlocks.mintwoodLeaves);
		world.setBlock(i + 4, j + 14, k + 10, VetheaBlocks.mintwoodLeaves);
		world.setBlock(i + 4, j + 14, k + 11, VetheaBlocks.mintwoodLeaves);
		world.setBlock(i + 4, j + 15, k + 1, VetheaBlocks.mintwoodLeaves);
		world.setBlock(i + 4, j + 15, k + 2, VetheaBlocks.mintwoodLeaves);
		world.setBlock(i + 4, j + 15, k + 3, VetheaBlocks.mintwoodLeaves);
		world.setBlock(i + 4, j + 15, k + 4, VetheaBlocks.mintwoodLeaves);
		world.setBlock(i + 4, j + 15, k + 5, VetheaBlocks.mintwoodLeaves);
		world.setBlock(i + 4, j + 15, k + 6, VetheaBlocks.mintwoodLeaves);
		world.setBlock(i + 4, j + 15, k + 7, VetheaBlocks.mintwoodLeaves);
		world.setBlock(i + 4, j + 15, k + 8, VetheaBlocks.mintwoodLeaves);
		world.setBlock(i + 4, j + 15, k + 9, VetheaBlocks.mintwoodLeaves);
		world.setBlock(i + 4, j + 15, k + 10, VetheaBlocks.mintwoodLeaves);
		world.setBlock(i + 4, j + 15, k + 11, VetheaBlocks.mintwoodLeaves);
		world.setBlock(i + 4, j + 16, k + 1, VetheaBlocks.mintwoodLeaves);
		world.setBlock(i + 4, j + 16, k + 2, VetheaBlocks.mintwoodLeaves);
		world.setBlock(i + 4, j + 16, k + 3, VetheaBlocks.mintwoodLeaves);
		world.setBlock(i + 4, j + 16, k + 4, VetheaBlocks.mintwoodLeaves);
		world.setBlock(i + 4, j + 16, k + 5, VetheaBlocks.mintwoodLeaves);
		world.setBlock(i + 4, j + 16, k + 6, VetheaBlocks.mintwoodLeaves);
		world.setBlock(i + 4, j + 16, k + 7, VetheaBlocks.mintwoodLeaves);
		world.setBlock(i + 4, j + 16, k + 8, VetheaBlocks.mintwoodLeaves);
		world.setBlock(i + 4, j + 16, k + 9, VetheaBlocks.mintwoodLeaves);
		world.setBlock(i + 4, j + 16, k + 10, VetheaBlocks.mintwoodLeaves);
		world.setBlock(i + 4, j + 16, k + 11, VetheaBlocks.mintwoodLeaves);
		world.setBlock(i + 4, j + 17, k + 1, VetheaBlocks.mintwoodLeaves);
		world.setBlock(i + 4, j + 17, k + 2, VetheaBlocks.mintwoodLeaves);
		world.setBlock(i + 4, j + 17, k + 3, VetheaBlocks.mintwoodLeaves);
		world.setBlock(i + 4, j + 17, k + 4, VetheaBlocks.mintwoodLeaves);
		world.setBlock(i + 4, j + 17, k + 5, VetheaBlocks.mintwoodLeaves);
		world.setBlock(i + 4, j + 17, k + 6, VetheaBlocks.mintwoodLeaves);
		world.setBlock(i + 4, j + 17, k + 7, VetheaBlocks.mintwoodLeaves);
		world.setBlock(i + 4, j + 17, k + 8, VetheaBlocks.mintwoodLeaves);
		world.setBlock(i + 4, j + 17, k + 9, VetheaBlocks.mintwoodLeaves);
		world.setBlock(i + 4, j + 17, k + 10, VetheaBlocks.mintwoodLeaves);
		world.setBlock(i + 4, j + 18, k + 2, VetheaBlocks.mintwoodLeaves);
		world.setBlock(i + 4, j + 18, k + 3, VetheaBlocks.mintwoodLeaves);
		world.setBlock(i + 4, j + 18, k + 4, VetheaBlocks.mintwoodLeaves);
		world.setBlock(i + 4, j + 18, k + 5, VetheaBlocks.mintwoodLeaves);
		world.setBlock(i + 4, j + 18, k + 6, VetheaBlocks.mintwoodLeaves);
		world.setBlock(i + 4, j + 18, k + 7, VetheaBlocks.mintwoodLeaves);
		world.setBlock(i + 4, j + 18, k + 8, VetheaBlocks.mintwoodLeaves);
		world.setBlock(i + 4, j + 18, k + 9, VetheaBlocks.mintwoodLeaves);
		world.setBlock(i + 4, j + 18, k + 10, VetheaBlocks.mintwoodLeaves);
		world.setBlock(i + 4, j + 19, k + 3, VetheaBlocks.mintwoodLeaves);
		world.setBlock(i + 4, j + 19, k + 4, VetheaBlocks.mintwoodLeaves);
		world.setBlock(i + 4, j + 19, k + 5, VetheaBlocks.mintwoodLeaves);
		world.setBlock(i + 4, j + 19, k + 6, VetheaBlocks.mintwoodLeaves);
		world.setBlock(i + 4, j + 19, k + 7, VetheaBlocks.mintwoodLeaves);
		world.setBlock(i + 4, j + 19, k + 8, VetheaBlocks.mintwoodLeaves);
		world.setBlock(i + 4, j + 19, k + 9, VetheaBlocks.mintwoodLeaves);
		world.setBlock(i + 4, j + 20, k + 5, VetheaBlocks.mintwoodLeaves);
		world.setBlock(i + 4, j + 20, k + 6, VetheaBlocks.mintwoodLeaves);
		world.setBlock(i + 4, j + 20, k + 7, VetheaBlocks.mintwoodLeaves);
		world.setBlock(i + 5, j + 0, k + 6, VetheaBlocks.mintwood);
		world.setBlock(i + 5, j + 0, k + 7, VetheaBlocks.mintwood);
		world.setBlock(i + 5, j + 1, k + 6, VetheaBlocks.mintwood);
		world.setBlock(i + 5, j + 1, k + 7, VetheaBlocks.mintwood);
		world.setBlock(i + 5, j + 2, k + 6, VetheaBlocks.mintwood);
		world.setBlock(i + 5, j + 2, k + 7, VetheaBlocks.mintwood);
		world.setBlock(i + 5, j + 3, k + 6, VetheaBlocks.mintwood);
		world.setBlock(i + 5, j + 3, k + 7, VetheaBlocks.mintwood);
		world.setBlock(i + 5, j + 4, k + 6, VetheaBlocks.mintwood);
		world.setBlock(i + 5, j + 4, k + 7, VetheaBlocks.mintwood);
		world.setBlock(i + 5, j + 5, k + 6, VetheaBlocks.mintwood);
		world.setBlock(i + 5, j + 5, k + 7, VetheaBlocks.mintwood);
		world.setBlock(i + 5, j + 6, k + 6, VetheaBlocks.mintwood);
		world.setBlock(i + 5, j + 6, k + 7, VetheaBlocks.mintwood);
		world.setBlock(i + 5, j + 7, k + 6, VetheaBlocks.mintwood);
		world.setBlock(i + 5, j + 7, k + 7, VetheaBlocks.mintwood);
		world.setBlock(i + 5, j + 8, k + 6, VetheaBlocks.mintwood);
		world.setBlock(i + 5, j + 8, k + 7, VetheaBlocks.mintwood);
		world.setBlock(i + 5, j + 9, k + 5, VetheaBlocks.mintwoodLeaves);
		world.setBlock(i + 5, j + 9, k + 6, VetheaBlocks.mintwood);
		world.setBlock(i + 5, j + 9, k + 7, VetheaBlocks.mintwood);
		world.setBlock(i + 5, j + 9, k + 8, VetheaBlocks.mintwoodLeaves);
		world.setBlock(i + 5, j + 10, k + 4, VetheaBlocks.mintwoodLeaves);
		world.setBlock(i + 5, j + 10, k + 5, VetheaBlocks.mintwoodLeaves);
		world.setBlock(i + 5, j + 10, k + 6, VetheaBlocks.mintwoodLeaves);
		world.setBlock(i + 5, j + 10, k + 7, VetheaBlocks.mintwoodLeaves);
		world.setBlock(i + 5, j + 10, k + 8, VetheaBlocks.mintwoodLeaves);
		world.setBlock(i + 5, j + 11, k + 3, VetheaBlocks.mintwoodLeaves);
		world.setBlock(i + 5, j + 11, k + 4, VetheaBlocks.mintwoodLeaves);
		world.setBlock(i + 5, j + 11, k + 5, VetheaBlocks.mintwoodLeaves);
		world.setBlock(i + 5, j + 11, k + 6, VetheaBlocks.mintwoodLeaves);
		world.setBlock(i + 5, j + 11, k + 7, VetheaBlocks.mintwoodLeaves);
		world.setBlock(i + 5, j + 11, k + 8, VetheaBlocks.mintwoodLeaves);
		world.setBlock(i + 5, j + 11, k + 9, VetheaBlocks.mintwoodLeaves);
		world.setBlock(i + 5, j + 12, k + 2, VetheaBlocks.mintwoodLeaves);
		world.setBlock(i + 5, j + 12, k + 3, VetheaBlocks.mintwoodLeaves);
		world.setBlock(i + 5, j + 12, k + 4, VetheaBlocks.mintwoodLeaves);
		world.setBlock(i + 5, j + 12, k + 5, VetheaBlocks.mintwoodLeaves);
		world.setBlock(i + 5, j + 12, k + 6, VetheaBlocks.mintwoodLeaves);
		world.setBlock(i + 5, j + 12, k + 7, VetheaBlocks.mintwoodLeaves);
		world.setBlock(i + 5, j + 12, k + 8, VetheaBlocks.mintwoodLeaves);
		world.setBlock(i + 5, j + 12, k + 9, VetheaBlocks.mintwoodLeaves);
		world.setBlock(i + 5, j + 12, k + 10, VetheaBlocks.mintwoodLeaves);
		world.setBlock(i + 5, j + 12, k + 11, VetheaBlocks.mintwoodLeaves);
		world.setBlock(i + 5, j + 12, k + 12, VetheaBlocks.mintwoodLeaves);
		world.setBlock(i + 5, j + 13, k + 1, VetheaBlocks.mintwoodLeaves);
		world.setBlock(i + 5, j + 13, k + 2, VetheaBlocks.mintwoodLeaves);
		world.setBlock(i + 5, j + 13, k + 4, VetheaBlocks.mintwoodLeaves);
		world.setBlock(i + 5, j + 13, k + 5, VetheaBlocks.mintwoodLeaves);
		world.setBlock(i + 5, j + 13, k + 6, VetheaBlocks.mintwoodLeaves);
		world.setBlock(i + 5, j + 13, k + 7, VetheaBlocks.mintwoodLeaves);
		world.setBlock(i + 5, j + 13, k + 8, VetheaBlocks.mintwoodLeaves);
		world.setBlock(i + 5, j + 13, k + 9, VetheaBlocks.mintwoodLeaves);
		world.setBlock(i + 5, j + 13, k + 10, VetheaBlocks.mintwoodLeaves);
		world.setBlock(i + 5, j + 13, k + 11, VetheaBlocks.mintwoodLeaves);
		world.setBlock(i + 5, j + 13, k + 12, VetheaBlocks.mintwoodLeaves);
		world.setBlock(i + 5, j + 14, k + 1, VetheaBlocks.mintwoodLeaves);
		world.setBlock(i + 5, j + 14, k + 3, VetheaBlocks.mintwoodLeaves);
		world.setBlock(i + 5, j + 14, k + 5, VetheaBlocks.mintwoodLeaves);
		world.setBlock(i + 5, j + 14, k + 6, VetheaBlocks.mintwoodLeaves);
		world.setBlock(i + 5, j + 14, k + 7, VetheaBlocks.mintwoodLeaves);
		world.setBlock(i + 5, j + 14, k + 8, VetheaBlocks.mintwoodLeaves);
		world.setBlock(i + 5, j + 14, k + 9, VetheaBlocks.mintwoodLeaves);
		world.setBlock(i + 5, j + 14, k + 10, VetheaBlocks.mintwoodLeaves);
		world.setBlock(i + 5, j + 14, k + 11, VetheaBlocks.mintwoodLeaves);
		world.setBlock(i + 5, j + 14, k + 12, VetheaBlocks.mintwoodLeaves);
		world.setBlock(i + 5, j + 15, k + 1, VetheaBlocks.mintwoodLeaves);
		world.setBlock(i + 5, j + 15, k + 3, VetheaBlocks.mintwoodLeaves);
		world.setBlock(i + 5, j + 15, k + 5, VetheaBlocks.mintwoodLeaves);
		world.setBlock(i + 5, j + 15, k + 6, VetheaBlocks.mintwoodLeaves);
		world.setBlock(i + 5, j + 15, k + 7, VetheaBlocks.mintwoodLeaves);
		world.setBlock(i + 5, j + 15, k + 8, VetheaBlocks.mintwoodLeaves);
		world.setBlock(i + 5, j + 15, k + 9, VetheaBlocks.mintwoodLeaves);
		world.setBlock(i + 5, j + 15, k + 10, VetheaBlocks.mintwoodLeaves);
		world.setBlock(i + 5, j + 15, k + 11, VetheaBlocks.mintwoodLeaves);
		world.setBlock(i + 5, j + 16, k + 1, VetheaBlocks.mintwoodLeaves);
		world.setBlock(i + 5, j + 16, k + 2, VetheaBlocks.mintwoodLeaves);
		world.setBlock(i + 5, j + 16, k + 3, VetheaBlocks.mintwoodLeaves);
		world.setBlock(i + 5, j + 16, k + 4, VetheaBlocks.mintwoodLeaves);
		world.setBlock(i + 5, j + 16, k + 5, VetheaBlocks.mintwoodLeaves);
		world.setBlock(i + 5, j + 16, k + 6, VetheaBlocks.mintwoodLeaves);
		world.setBlock(i + 5, j + 16, k + 7, VetheaBlocks.mintwoodLeaves);
		world.setBlock(i + 5, j + 16, k + 8, VetheaBlocks.mintwoodLeaves);
		world.setBlock(i + 5, j + 16, k + 9, VetheaBlocks.mintwoodLeaves);
		world.setBlock(i + 5, j + 16, k + 10, VetheaBlocks.mintwoodLeaves);
		world.setBlock(i + 5, j + 16, k + 11, VetheaBlocks.mintwoodLeaves);
		world.setBlock(i + 5, j + 17, k + 1, VetheaBlocks.mintwoodLeaves);
		world.setBlock(i + 5, j + 17, k + 2, VetheaBlocks.mintwoodLeaves);
		world.setBlock(i + 5, j + 17, k + 3, VetheaBlocks.mintwoodLeaves);
		world.setBlock(i + 5, j + 17, k + 4, VetheaBlocks.mintwoodLeaves);
		world.setBlock(i + 5, j + 17, k + 5, VetheaBlocks.mintwoodLeaves);
		world.setBlock(i + 5, j + 17, k + 6, VetheaBlocks.mintwoodLeaves);
		world.setBlock(i + 5, j + 17, k + 7, VetheaBlocks.mintwoodLeaves);
		world.setBlock(i + 5, j + 17, k + 8, VetheaBlocks.mintwoodLeaves);
		world.setBlock(i + 5, j + 17, k + 9, VetheaBlocks.mintwoodLeaves);
		world.setBlock(i + 5, j + 17, k + 10, VetheaBlocks.mintwoodLeaves);
		world.setBlock(i + 5, j + 17, k + 11, VetheaBlocks.mintwoodLeaves);
		world.setBlock(i + 5, j + 18, k + 2, VetheaBlocks.mintwoodLeaves);
		world.setBlock(i + 5, j + 18, k + 3, VetheaBlocks.mintwoodLeaves);
		world.setBlock(i + 5, j + 18, k + 4, VetheaBlocks.mintwoodLeaves);
		world.setBlock(i + 5, j + 18, k + 5, VetheaBlocks.mintwoodLeaves);
		world.setBlock(i + 5, j + 18, k + 6, VetheaBlocks.mintwoodLeaves);
		world.setBlock(i + 5, j + 18, k + 7, VetheaBlocks.mintwoodLeaves);
		world.setBlock(i + 5, j + 18, k + 8, VetheaBlocks.mintwoodLeaves);
		world.setBlock(i + 5, j + 18, k + 9, VetheaBlocks.mintwoodLeaves);
		world.setBlock(i + 5, j + 18, k + 10, VetheaBlocks.mintwoodLeaves);
		world.setBlock(i + 5, j + 19, k + 3, VetheaBlocks.mintwoodLeaves);
		world.setBlock(i + 5, j + 19, k + 4, VetheaBlocks.mintwoodLeaves);
		world.setBlock(i + 5, j + 19, k + 5, VetheaBlocks.mintwoodLeaves);
		world.setBlock(i + 5, j + 19, k + 6, VetheaBlocks.mintwoodLeaves);
		world.setBlock(i + 5, j + 19, k + 7, VetheaBlocks.mintwoodLeaves);
		world.setBlock(i + 5, j + 19, k + 8, VetheaBlocks.mintwoodLeaves);
		world.setBlock(i + 5, j + 19, k + 9, VetheaBlocks.mintwoodLeaves);
		world.setBlock(i + 5, j + 20, k + 4, VetheaBlocks.mintwoodLeaves);
		world.setBlock(i + 5, j + 20, k + 5, VetheaBlocks.mintwoodLeaves);
		world.setBlock(i + 5, j + 20, k + 6, VetheaBlocks.mintwoodLeaves);
		world.setBlock(i + 5, j + 20, k + 7, VetheaBlocks.mintwoodLeaves);
		world.setBlock(i + 5, j + 20, k + 8, VetheaBlocks.mintwoodLeaves);
		world.setBlock(i + 6, j + 0, k + 4, VetheaBlocks.mintwood);
		world.setBlock(i + 6, j + 0, k + 5, VetheaBlocks.mintwood);
		world.setBlock(i + 6, j + 0, k + 6, VetheaBlocks.mintwood);
		world.setBlock(i + 6, j + 0, k + 7, VetheaBlocks.mintwood);
		world.setBlock(i + 6, j + 0, k + 8, VetheaBlocks.mintwood);
		world.setBlock(i + 6, j + 0, k + 9, VetheaBlocks.mintwood);
		world.setBlock(i + 6, j + 1, k + 4, VetheaBlocks.mintwood);
		world.setBlock(i + 6, j + 1, k + 5, VetheaBlocks.mintwood);
		world.setBlock(i + 6, j + 1, k + 6, VetheaBlocks.mintwood);
		world.setBlock(i + 6, j + 1, k + 7, VetheaBlocks.mintwood);
		world.setBlock(i + 6, j + 1, k + 8, VetheaBlocks.mintwood);
		world.setBlock(i + 6, j + 1, k + 9, VetheaBlocks.mintwood);
		world.setBlock(i + 6, j + 2, k + 4, VetheaBlocks.mintwood);
		world.setBlock(i + 6, j + 2, k + 5, VetheaBlocks.mintwood);
		world.setBlock(i + 6, j + 2, k + 6, VetheaBlocks.mintwood);
		world.setBlock(i + 6, j + 2, k + 7, VetheaBlocks.mintwood);
		world.setBlock(i + 6, j + 2, k + 8, VetheaBlocks.mintwood);
		world.setBlock(i + 6, j + 2, k + 9, VetheaBlocks.mintwood);
		world.setBlock(i + 6, j + 3, k + 4, VetheaBlocks.mintwood);
		world.setBlock(i + 6, j + 3, k + 5, VetheaBlocks.mintwood);
		world.setBlock(i + 6, j + 3, k + 6, VetheaBlocks.mintwood);
		world.setBlock(i + 6, j + 3, k + 7, VetheaBlocks.mintwood);
		world.setBlock(i + 6, j + 3, k + 8, VetheaBlocks.mintwood);
		world.setBlock(i + 6, j + 3, k + 9, VetheaBlocks.mintwood);
		world.setBlock(i + 6, j + 4, k + 4, VetheaBlocks.mintwood);
		world.setBlock(i + 6, j + 4, k + 5, VetheaBlocks.mintwood);
		world.setBlock(i + 6, j + 4, k + 6, VetheaBlocks.mintwood);
		world.setBlock(i + 6, j + 4, k + 7, VetheaBlocks.mintwood);
		world.setBlock(i + 6, j + 4, k + 8, VetheaBlocks.mintwood);
		world.setBlock(i + 6, j + 4, k + 9, VetheaBlocks.mintwood);
		world.setBlock(i + 6, j + 5, k + 4, VetheaBlocks.mintwood);
		world.setBlock(i + 6, j + 5, k + 5, VetheaBlocks.mintwood);
		world.setBlock(i + 6, j + 5, k + 6, VetheaBlocks.mintwood);
		world.setBlock(i + 6, j + 5, k + 7, VetheaBlocks.mintwood);
		world.setBlock(i + 6, j + 5, k + 8, VetheaBlocks.mintwood);
		world.setBlock(i + 6, j + 5, k + 9, VetheaBlocks.mintwood);
		world.setBlock(i + 6, j + 6, k + 4, VetheaBlocks.mintwood);
		world.setBlock(i + 6, j + 6, k + 5, VetheaBlocks.mintwood);
		world.setBlock(i + 6, j + 6, k + 6, VetheaBlocks.mintwood);
		world.setBlock(i + 6, j + 6, k + 7, VetheaBlocks.mintwood);
		world.setBlock(i + 6, j + 6, k + 8, VetheaBlocks.mintwood);
		world.setBlock(i + 6, j + 6, k + 9, VetheaBlocks.mintwood);
		world.setBlock(i + 6, j + 7, k + 4, VetheaBlocks.mintwood);
		world.setBlock(i + 6, j + 7, k + 5, VetheaBlocks.mintwood);
		world.setBlock(i + 6, j + 7, k + 6, VetheaBlocks.mintwood);
		world.setBlock(i + 6, j + 7, k + 7, VetheaBlocks.mintwood);
		world.setBlock(i + 6, j + 7, k + 8, VetheaBlocks.mintwood);
		world.setBlock(i + 6, j + 7, k + 9, VetheaBlocks.mintwood);
		world.setBlock(i + 6, j + 8, k + 4, VetheaBlocks.mintwood);
		world.setBlock(i + 6, j + 8, k + 5, VetheaBlocks.mintwood);
		world.setBlock(i + 6, j + 8, k + 6, VetheaBlocks.mintwood);
		world.setBlock(i + 6, j + 8, k + 7, VetheaBlocks.mintwood);
		world.setBlock(i + 6, j + 8, k + 8, VetheaBlocks.mintwood);
		world.setBlock(i + 6, j + 8, k + 9, VetheaBlocks.mintwood);
		world.setBlock(i + 6, j + 9, k + 4, VetheaBlocks.mintwood);
		world.setBlock(i + 6, j + 9, k + 5, VetheaBlocks.mintwood);
		world.setBlock(i + 6, j + 9, k + 6, VetheaBlocks.mintwood);
		world.setBlock(i + 6, j + 9, k + 7, VetheaBlocks.mintwood);
		world.setBlock(i + 6, j + 9, k + 8, VetheaBlocks.mintwood);
		world.setBlock(i + 6, j + 9, k + 9, VetheaBlocks.mintwood);
		world.setBlock(i + 6, j + 10, k + 4, VetheaBlocks.mintwoodLeaves);
		world.setBlock(i + 6, j + 10, k + 5, VetheaBlocks.mintwoodLeaves);
		world.setBlock(i + 6, j + 10, k + 6, VetheaBlocks.mintwoodLeaves);
		world.setBlock(i + 6, j + 10, k + 7, VetheaBlocks.mintwoodLeaves);
		world.setBlock(i + 6, j + 10, k + 8, VetheaBlocks.mintwoodLeaves);
		world.setBlock(i + 6, j + 10, k + 9, VetheaBlocks.mintwood);
		world.setBlock(i + 6, j + 11, k + 3, VetheaBlocks.mintwoodLeaves);
		world.setBlock(i + 6, j + 11, k + 4, VetheaBlocks.mintwoodLeaves);
		world.setBlock(i + 6, j + 11, k + 5, VetheaBlocks.mintwoodLeaves);
		world.setBlock(i + 6, j + 11, k + 6, VetheaBlocks.mintwoodLeaves);
		world.setBlock(i + 6, j + 11, k + 7, VetheaBlocks.mintwoodLeaves);
		world.setBlock(i + 6, j + 11, k + 8, VetheaBlocks.mintwoodLeaves);
		world.setBlock(i + 6, j + 11, k + 9, VetheaBlocks.mintwoodLeaves);
		world.setBlock(i + 6, j + 11, k + 10, VetheaBlocks.mintwoodLeaves);
		world.setBlock(i + 6, j + 11, k + 11, VetheaBlocks.mintwoodLeaves);
		world.setBlock(i + 6, j + 11, k + 12, VetheaBlocks.mintwoodLeaves);
		world.setBlock(i + 6, j + 12, k + 2, VetheaBlocks.mintwoodLeaves);
		world.setBlock(i + 6, j + 12, k + 3, VetheaBlocks.mintwoodLeaves);
		world.setBlock(i + 6, j + 12, k + 4, VetheaBlocks.mintwoodLeaves);
		world.setBlock(i + 6, j + 12, k + 5, VetheaBlocks.mintwoodLeaves);
		world.setBlock(i + 6, j + 12, k + 6, VetheaBlocks.mintwoodLeaves);
		world.setBlock(i + 6, j + 12, k + 7, VetheaBlocks.mintwoodLeaves);
		world.setBlock(i + 6, j + 12, k + 8, VetheaBlocks.mintwoodLeaves);
		world.setBlock(i + 6, j + 12, k + 9, VetheaBlocks.mintwoodLeaves);
		world.setBlock(i + 6, j + 12, k + 10, VetheaBlocks.mintwoodLeaves);
		world.setBlock(i + 6, j + 12, k + 11, VetheaBlocks.mintwoodLeaves);
		world.setBlock(i + 6, j + 12, k + 12, VetheaBlocks.mintwoodLeaves);
		world.setBlock(i + 6, j + 12, k + 13, VetheaBlocks.mintwoodLeaves);
		world.setBlock(i + 6, j + 13, k + 1, VetheaBlocks.mintwoodLeaves);
		world.setBlock(i + 6, j + 13, k + 2, VetheaBlocks.mintwoodLeaves);
		world.setBlock(i + 6, j + 13, k + 3, VetheaBlocks.mintwoodLeaves);
		world.setBlock(i + 6, j + 13, k + 4, VetheaBlocks.mintwoodLeaves);
		world.setBlock(i + 6, j + 13, k + 5, VetheaBlocks.mintwoodLeaves);
		world.setBlock(i + 6, j + 13, k + 6, VetheaBlocks.mintwoodLeaves);
		world.setBlock(i + 6, j + 13, k + 7, VetheaBlocks.mintwoodLeaves);
		world.setBlock(i + 6, j + 13, k + 8, VetheaBlocks.mintwoodLeaves);
		world.setBlock(i + 6, j + 13, k + 9, VetheaBlocks.mintwoodLeaves);
		world.setBlock(i + 6, j + 13, k + 10, VetheaBlocks.mintwoodLeaves);
		world.setBlock(i + 6, j + 13, k + 11, VetheaBlocks.mintwoodLeaves);
		world.setBlock(i + 6, j + 13, k + 12, VetheaBlocks.mintwoodLeaves);
		world.setBlock(i + 6, j + 13, k + 13, VetheaBlocks.mintwoodLeaves);
		world.setBlock(i + 6, j + 14, k + 1, VetheaBlocks.mintwoodLeaves);
		world.setBlock(i + 6, j + 14, k + 2, VetheaBlocks.mintwoodLeaves);
		world.setBlock(i + 6, j + 14, k + 3, VetheaBlocks.mintwoodLeaves);
		world.setBlock(i + 6, j + 14, k + 5, VetheaBlocks.mintwoodLeaves);
		world.setBlock(i + 6, j + 14, k + 6, VetheaBlocks.mintwoodLeaves);
		world.setBlock(i + 6, j + 14, k + 7, VetheaBlocks.mintwoodLeaves);
		world.setBlock(i + 6, j + 14, k + 8, VetheaBlocks.mintwoodLeaves);
		world.setBlock(i + 6, j + 14, k + 9, VetheaBlocks.mintwoodLeaves);
		world.setBlock(i + 6, j + 14, k + 10, VetheaBlocks.mintwoodLeaves);
		world.setBlock(i + 6, j + 14, k + 11, VetheaBlocks.mintwoodLeaves);
		world.setBlock(i + 6, j + 14, k + 12, VetheaBlocks.mintwoodLeaves);
		world.setBlock(i + 6, j + 14, k + 13, VetheaBlocks.mintwoodLeaves);
		world.setBlock(i + 6, j + 15, k + 1, VetheaBlocks.mintwoodLeaves);
		world.setBlock(i + 6, j + 15, k + 2, VetheaBlocks.mintwoodLeaves);
		world.setBlock(i + 6, j + 15, k + 3, VetheaBlocks.mintwoodLeaves);
		world.setBlock(i + 6, j + 15, k + 7, VetheaBlocks.mintwoodLeaves);
		world.setBlock(i + 6, j + 15, k + 8, VetheaBlocks.mintwoodLeaves);
		world.setBlock(i + 6, j + 15, k + 9, VetheaBlocks.mintwoodLeaves);
		world.setBlock(i + 6, j + 15, k + 10, VetheaBlocks.mintwoodLeaves);
		world.setBlock(i + 6, j + 15, k + 11, VetheaBlocks.mintwoodLeaves);
		world.setBlock(i + 6, j + 15, k + 12, VetheaBlocks.mintwoodLeaves);
		world.setBlock(i + 6, j + 16, k + 1, VetheaBlocks.mintwoodLeaves);
		world.setBlock(i + 6, j + 16, k + 2, VetheaBlocks.mintwoodLeaves);
		world.setBlock(i + 6, j + 16, k + 3, VetheaBlocks.mintwoodLeaves);
		world.setBlock(i + 6, j + 16, k + 4, VetheaBlocks.mintwoodLeaves);
		world.setBlock(i + 6, j + 16, k + 8, VetheaBlocks.mintwoodLeaves);
		world.setBlock(i + 6, j + 16, k + 9, VetheaBlocks.mintwoodLeaves);
		world.setBlock(i + 6, j + 16, k + 10, VetheaBlocks.mintwoodLeaves);
		world.setBlock(i + 6, j + 16, k + 11, VetheaBlocks.mintwoodLeaves);
		world.setBlock(i + 6, j + 17, k + 1, VetheaBlocks.mintwoodLeaves);
		world.setBlock(i + 6, j + 17, k + 2, VetheaBlocks.mintwoodLeaves);
		world.setBlock(i + 6, j + 17, k + 3, VetheaBlocks.mintwoodLeaves);
		world.setBlock(i + 6, j + 17, k + 4, VetheaBlocks.mintwoodLeaves);
		world.setBlock(i + 6, j + 17, k + 5, VetheaBlocks.mintwoodLeaves);
		world.setBlock(i + 6, j + 17, k + 8, VetheaBlocks.mintwoodLeaves);
		world.setBlock(i + 6, j + 17, k + 9, VetheaBlocks.mintwoodLeaves);
		world.setBlock(i + 6, j + 17, k + 10, VetheaBlocks.mintwoodLeaves);
		world.setBlock(i + 6, j + 17, k + 11, VetheaBlocks.mintwoodLeaves);
		world.setBlock(i + 6, j + 18, k + 2, VetheaBlocks.mintwoodLeaves);
		world.setBlock(i + 6, j + 18, k + 3, VetheaBlocks.mintwoodLeaves);
		world.setBlock(i + 6, j + 18, k + 4, VetheaBlocks.mintwoodLeaves);
		world.setBlock(i + 6, j + 18, k + 5, VetheaBlocks.mintwoodLeaves);
		world.setBlock(i + 6, j + 18, k + 6, VetheaBlocks.mintwoodLeaves);
		world.setBlock(i + 6, j + 18, k + 7, VetheaBlocks.mintwoodLeaves);
		world.setBlock(i + 6, j + 18, k + 8, VetheaBlocks.mintwoodLeaves);
		world.setBlock(i + 6, j + 18, k + 9, VetheaBlocks.mintwoodLeaves);
		world.setBlock(i + 6, j + 18, k + 10, VetheaBlocks.mintwoodLeaves);
		world.setBlock(i + 6, j + 19, k + 3, VetheaBlocks.mintwoodLeaves);
		world.setBlock(i + 6, j + 19, k + 4, VetheaBlocks.mintwoodLeaves);
		world.setBlock(i + 6, j + 19, k + 5, VetheaBlocks.mintwoodLeaves);
		world.setBlock(i + 6, j + 19, k + 6, VetheaBlocks.mintwoodLeaves);
		world.setBlock(i + 6, j + 19, k + 7, VetheaBlocks.mintwoodLeaves);
		world.setBlock(i + 6, j + 19, k + 8, VetheaBlocks.mintwoodLeaves);
		world.setBlock(i + 6, j + 19, k + 9, VetheaBlocks.mintwoodLeaves);
		world.setBlock(i + 6, j + 20, k + 4, VetheaBlocks.mintwoodLeaves);
		world.setBlock(i + 6, j + 20, k + 5, VetheaBlocks.mintwoodLeaves);
		world.setBlock(i + 6, j + 20, k + 6, VetheaBlocks.mintwoodLeaves);
		world.setBlock(i + 6, j + 20, k + 7, VetheaBlocks.mintwoodLeaves);
		world.setBlock(i + 6, j + 20, k + 8, VetheaBlocks.mintwoodLeaves);
		world.setBlock(i + 7, j + 0, k + 4, VetheaBlocks.mintwood);
		world.setBlock(i + 7, j + 0, k + 5, VetheaBlocks.mintwood);
		world.setBlock(i + 7, j + 0, k + 6, VetheaBlocks.mintwood);
		world.setBlock(i + 7, j + 0, k + 7, VetheaBlocks.mintwood);
		world.setBlock(i + 7, j + 0, k + 8, VetheaBlocks.mintwood);
		world.setBlock(i + 7, j + 0, k + 9, VetheaBlocks.mintwood);
		world.setBlock(i + 7, j + 1, k + 4, VetheaBlocks.mintwood);
		world.setBlock(i + 7, j + 1, k + 5, VetheaBlocks.mintwood);
		world.setBlock(i + 7, j + 1, k + 6, VetheaBlocks.mintwood);
		world.setBlock(i + 7, j + 1, k + 7, VetheaBlocks.mintwood);
		world.setBlock(i + 7, j + 1, k + 8, VetheaBlocks.mintwood);
		world.setBlock(i + 7, j + 1, k + 9, VetheaBlocks.mintwood);
		world.setBlock(i + 7, j + 2, k + 4, VetheaBlocks.mintwood);
		world.setBlock(i + 7, j + 2, k + 5, VetheaBlocks.mintwood);
		world.setBlock(i + 7, j + 2, k + 6, VetheaBlocks.mintwood);
		world.setBlock(i + 7, j + 2, k + 7, VetheaBlocks.mintwood);
		world.setBlock(i + 7, j + 2, k + 8, VetheaBlocks.mintwood);
		world.setBlock(i + 7, j + 2, k + 9, VetheaBlocks.mintwood);
		world.setBlock(i + 7, j + 3, k + 4, VetheaBlocks.mintwood);
		world.setBlock(i + 7, j + 3, k + 5, VetheaBlocks.mintwood);
		world.setBlock(i + 7, j + 3, k + 6, VetheaBlocks.mintwood);
		world.setBlock(i + 7, j + 3, k + 7, VetheaBlocks.mintwood);
		world.setBlock(i + 7, j + 3, k + 8, VetheaBlocks.mintwood);
		world.setBlock(i + 7, j + 3, k + 9, VetheaBlocks.mintwood);
		world.setBlock(i + 7, j + 4, k + 4, VetheaBlocks.mintwood);
		world.setBlock(i + 7, j + 4, k + 5, VetheaBlocks.mintwood);
		world.setBlock(i + 7, j + 4, k + 6, VetheaBlocks.mintwood);
		world.setBlock(i + 7, j + 4, k + 7, VetheaBlocks.mintwood);
		world.setBlock(i + 7, j + 4, k + 8, VetheaBlocks.mintwood);
		world.setBlock(i + 7, j + 4, k + 9, VetheaBlocks.mintwood);
		world.setBlock(i + 7, j + 5, k + 4, VetheaBlocks.mintwood);
		world.setBlock(i + 7, j + 5, k + 5, VetheaBlocks.mintwood);
		world.setBlock(i + 7, j + 5, k + 6, VetheaBlocks.mintwood);
		world.setBlock(i + 7, j + 5, k + 7, VetheaBlocks.mintwood);
		world.setBlock(i + 7, j + 5, k + 8, VetheaBlocks.mintwood);
		world.setBlock(i + 7, j + 5, k + 9, VetheaBlocks.mintwood);
		world.setBlock(i + 7, j + 6, k + 4, VetheaBlocks.mintwood);
		world.setBlock(i + 7, j + 6, k + 5, VetheaBlocks.mintwood);
		world.setBlock(i + 7, j + 6, k + 6, VetheaBlocks.mintwood);
		world.setBlock(i + 7, j + 6, k + 7, VetheaBlocks.mintwood);
		world.setBlock(i + 7, j + 6, k + 8, VetheaBlocks.mintwood);
		world.setBlock(i + 7, j + 6, k + 9, VetheaBlocks.mintwood);
		world.setBlock(i + 7, j + 7, k + 4, VetheaBlocks.mintwood);
		world.setBlock(i + 7, j + 7, k + 5, VetheaBlocks.mintwood);
		world.setBlock(i + 7, j + 7, k + 6, VetheaBlocks.mintwood);
		world.setBlock(i + 7, j + 7, k + 7, VetheaBlocks.mintwood);
		world.setBlock(i + 7, j + 7, k + 8, VetheaBlocks.mintwood);
		world.setBlock(i + 7, j + 7, k + 9, VetheaBlocks.mintwood);
		world.setBlock(i + 7, j + 8, k + 4, VetheaBlocks.mintwood);
		world.setBlock(i + 7, j + 8, k + 5, VetheaBlocks.mintwood);
		world.setBlock(i + 7, j + 8, k + 6, VetheaBlocks.mintwood);
		world.setBlock(i + 7, j + 8, k + 7, VetheaBlocks.mintwood);
		world.setBlock(i + 7, j + 8, k + 8, VetheaBlocks.mintwood);
		world.setBlock(i + 7, j + 8, k + 9, VetheaBlocks.mintwood);
		world.setBlock(i + 7, j + 9, k + 4, VetheaBlocks.mintwood);
		world.setBlock(i + 7, j + 9, k + 5, VetheaBlocks.mintwood);
		world.setBlock(i + 7, j + 9, k + 6, VetheaBlocks.mintwood);
		world.setBlock(i + 7, j + 9, k + 7, VetheaBlocks.mintwood);
		world.setBlock(i + 7, j + 9, k + 8, VetheaBlocks.mintwood);
		world.setBlock(i + 7, j + 9, k + 9, VetheaBlocks.mintwood);
		world.setBlock(i + 7, j + 10, k + 4, VetheaBlocks.mintwoodLeaves);
		world.setBlock(i + 7, j + 10, k + 5, VetheaBlocks.mintwoodLeaves);
		world.setBlock(i + 7, j + 10, k + 6, VetheaBlocks.mintwoodLeaves);
		world.setBlock(i + 7, j + 10, k + 7, VetheaBlocks.mintwoodLeaves);
		world.setBlock(i + 7, j + 10, k + 8, VetheaBlocks.mintwoodLeaves);
		world.setBlock(i + 7, j + 10, k + 9, VetheaBlocks.mintwood);
		world.setBlock(i + 7, j + 11, k + 3, VetheaBlocks.mintwoodLeaves);
		world.setBlock(i + 7, j + 11, k + 4, VetheaBlocks.mintwoodLeaves);
		world.setBlock(i + 7, j + 11, k + 5, VetheaBlocks.mintwoodLeaves);
		world.setBlock(i + 7, j + 11, k + 6, VetheaBlocks.mintwoodLeaves);
		world.setBlock(i + 7, j + 11, k + 7, VetheaBlocks.mintwoodLeaves);
		world.setBlock(i + 7, j + 11, k + 8, VetheaBlocks.mintwoodLeaves);
		world.setBlock(i + 7, j + 11, k + 9, VetheaBlocks.mintwoodLeaves);
		world.setBlock(i + 7, j + 11, k + 10, VetheaBlocks.mintwoodLeaves);
		world.setBlock(i + 7, j + 11, k + 11, VetheaBlocks.mintwoodLeaves);
		world.setBlock(i + 7, j + 11, k + 12, VetheaBlocks.mintwoodLeaves);
		world.setBlock(i + 7, j + 12, k + 2, VetheaBlocks.mintwoodLeaves);
		world.setBlock(i + 7, j + 12, k + 3, VetheaBlocks.mintwoodLeaves);
		world.setBlock(i + 7, j + 12, k + 4, VetheaBlocks.mintwoodLeaves);
		world.setBlock(i + 7, j + 12, k + 5, VetheaBlocks.mintwoodLeaves);
		world.setBlock(i + 7, j + 12, k + 6, VetheaBlocks.mintwoodLeaves);
		world.setBlock(i + 7, j + 12, k + 7, VetheaBlocks.mintwoodLeaves);
		world.setBlock(i + 7, j + 12, k + 8, VetheaBlocks.mintwoodLeaves);
		world.setBlock(i + 7, j + 12, k + 9, VetheaBlocks.mintwoodLeaves);
		world.setBlock(i + 7, j + 12, k + 10, VetheaBlocks.mintwoodLeaves);
		world.setBlock(i + 7, j + 12, k + 11, VetheaBlocks.mintwoodLeaves);
		world.setBlock(i + 7, j + 12, k + 12, VetheaBlocks.mintwoodLeaves);
		world.setBlock(i + 7, j + 12, k + 13, VetheaBlocks.mintwoodLeaves);
		world.setBlock(i + 7, j + 13, k + 1, VetheaBlocks.mintwoodLeaves);
		world.setBlock(i + 7, j + 13, k + 2, VetheaBlocks.mintwoodLeaves);
		world.setBlock(i + 7, j + 13, k + 3, VetheaBlocks.mintwoodLeaves);
		world.setBlock(i + 7, j + 13, k + 4, VetheaBlocks.mintwoodLeaves);
		world.setBlock(i + 7, j + 13, k + 5, VetheaBlocks.mintwoodLeaves);
		world.setBlock(i + 7, j + 13, k + 6, VetheaBlocks.mintwoodLeaves);
		world.setBlock(i + 7, j + 13, k + 7, VetheaBlocks.mintwoodLeaves);
		world.setBlock(i + 7, j + 13, k + 8, VetheaBlocks.mintwoodLeaves);
		world.setBlock(i + 7, j + 13, k + 9, VetheaBlocks.mintwoodLeaves);
		world.setBlock(i + 7, j + 13, k + 10, VetheaBlocks.mintwoodLeaves);
		world.setBlock(i + 7, j + 13, k + 11, VetheaBlocks.mintwoodLeaves);
		world.setBlock(i + 7, j + 13, k + 12, VetheaBlocks.mintwoodLeaves);
		world.setBlock(i + 7, j + 13, k + 13, VetheaBlocks.mintwoodLeaves);
		world.setBlock(i + 7, j + 14, k + 1, VetheaBlocks.mintwoodLeaves);
		world.setBlock(i + 7, j + 14, k + 2, VetheaBlocks.mintwoodLeaves);
		world.setBlock(i + 7, j + 14, k + 3, VetheaBlocks.mintwoodLeaves);
		world.setBlock(i + 7, j + 14, k + 4, VetheaBlocks.mintwoodLeaves);
		world.setBlock(i + 7, j + 14, k + 5, VetheaBlocks.mintwoodLeaves);
		world.setBlock(i + 7, j + 14, k + 6, VetheaBlocks.mintwoodLeaves);
		world.setBlock(i + 7, j + 14, k + 7, VetheaBlocks.mintwoodLeaves);
		world.setBlock(i + 7, j + 14, k + 8, VetheaBlocks.mintwoodLeaves);
		world.setBlock(i + 7, j + 14, k + 9, VetheaBlocks.mintwoodLeaves);
		world.setBlock(i + 7, j + 14, k + 10, VetheaBlocks.mintwoodLeaves);
		world.setBlock(i + 7, j + 14, k + 11, VetheaBlocks.mintwoodLeaves);
		world.setBlock(i + 7, j + 14, k + 12, VetheaBlocks.mintwoodLeaves);
		world.setBlock(i + 7, j + 14, k + 13, VetheaBlocks.mintwoodLeaves);
		world.setBlock(i + 7, j + 15, k + 1, VetheaBlocks.mintwoodLeaves);
		world.setBlock(i + 7, j + 15, k + 2, VetheaBlocks.mintwoodLeaves);
		world.setBlock(i + 7, j + 15, k + 3, VetheaBlocks.mintwoodLeaves);
		world.setBlock(i + 7, j + 15, k + 4, VetheaBlocks.mintwoodLeaves);
		world.setBlock(i + 7, j + 15, k + 5, VetheaBlocks.mintwoodLeaves);
		world.setBlock(i + 7, j + 15, k + 6, VetheaBlocks.mintwoodLeaves);
		world.setBlock(i + 7, j + 15, k + 7, VetheaBlocks.mintwoodLeaves);
		world.setBlock(i + 7, j + 15, k + 8, VetheaBlocks.mintwoodLeaves);
		world.setBlock(i + 7, j + 15, k + 9, VetheaBlocks.mintwoodLeaves);
		world.setBlock(i + 7, j + 15, k + 10, VetheaBlocks.mintwoodLeaves);
		world.setBlock(i + 7, j + 15, k + 11, VetheaBlocks.mintwoodLeaves);
		world.setBlock(i + 7, j + 15, k + 12, VetheaBlocks.mintwoodLeaves);
		world.setBlock(i + 7, j + 16, k + 1, VetheaBlocks.mintwoodLeaves);
		world.setBlock(i + 7, j + 16, k + 2, VetheaBlocks.mintwoodLeaves);
		world.setBlock(i + 7, j + 16, k + 3, VetheaBlocks.mintwoodLeaves);
		world.setBlock(i + 7, j + 16, k + 4, VetheaBlocks.mintwoodLeaves);
		world.setBlock(i + 7, j + 16, k + 5, VetheaBlocks.mintwoodLeaves);
		world.setBlock(i + 7, j + 16, k + 6, VetheaBlocks.mintwoodLeaves);
		world.setBlock(i + 7, j + 16, k + 8, VetheaBlocks.mintwoodLeaves);
		world.setBlock(i + 7, j + 16, k + 9, VetheaBlocks.mintwoodLeaves);
		world.setBlock(i + 7, j + 16, k + 10, VetheaBlocks.mintwoodLeaves);
		world.setBlock(i + 7, j + 16, k + 11, VetheaBlocks.mintwoodLeaves);
		world.setBlock(i + 7, j + 17, k + 1, VetheaBlocks.mintwoodLeaves);
		world.setBlock(i + 7, j + 17, k + 2, VetheaBlocks.mintwoodLeaves);
		world.setBlock(i + 7, j + 17, k + 3, VetheaBlocks.mintwoodLeaves);
		world.setBlock(i + 7, j + 17, k + 4, VetheaBlocks.mintwoodLeaves);
		world.setBlock(i + 7, j + 17, k + 5, VetheaBlocks.mintwoodLeaves);
		world.setBlock(i + 7, j + 17, k + 6, VetheaBlocks.mintwoodLeaves);
		world.setBlock(i + 7, j + 17, k + 8, VetheaBlocks.mintwoodLeaves);
		world.setBlock(i + 7, j + 17, k + 9, VetheaBlocks.mintwoodLeaves);
		world.setBlock(i + 7, j + 17, k + 10, VetheaBlocks.mintwoodLeaves);
		world.setBlock(i + 7, j + 17, k + 11, VetheaBlocks.mintwoodLeaves);
		world.setBlock(i + 7, j + 18, k + 2, VetheaBlocks.mintwoodLeaves);
		world.setBlock(i + 7, j + 18, k + 3, VetheaBlocks.mintwoodLeaves);
		world.setBlock(i + 7, j + 18, k + 4, VetheaBlocks.mintwoodLeaves);
		world.setBlock(i + 7, j + 18, k + 5, VetheaBlocks.mintwoodLeaves);
		world.setBlock(i + 7, j + 18, k + 6, VetheaBlocks.mintwoodLeaves);
		world.setBlock(i + 7, j + 18, k + 8, VetheaBlocks.mintwoodLeaves);
		world.setBlock(i + 7, j + 18, k + 9, VetheaBlocks.mintwoodLeaves);
		world.setBlock(i + 7, j + 18, k + 10, VetheaBlocks.mintwoodLeaves);
		world.setBlock(i + 7, j + 19, k + 3, VetheaBlocks.mintwoodLeaves);
		world.setBlock(i + 7, j + 19, k + 4, VetheaBlocks.mintwoodLeaves);
		world.setBlock(i + 7, j + 19, k + 5, VetheaBlocks.mintwoodLeaves);
		world.setBlock(i + 7, j + 19, k + 6, VetheaBlocks.mintwoodLeaves);
		world.setBlock(i + 7, j + 19, k + 7, VetheaBlocks.mintwoodLeaves);
		world.setBlock(i + 7, j + 19, k + 8, VetheaBlocks.mintwoodLeaves);
		world.setBlock(i + 7, j + 19, k + 9, VetheaBlocks.mintwoodLeaves);
		world.setBlock(i + 7, j + 20, k + 4, VetheaBlocks.mintwoodLeaves);
		world.setBlock(i + 7, j + 20, k + 5, VetheaBlocks.mintwoodLeaves);
		world.setBlock(i + 7, j + 20, k + 6, VetheaBlocks.mintwoodLeaves);
		world.setBlock(i + 7, j + 20, k + 7, VetheaBlocks.mintwoodLeaves);
		world.setBlock(i + 7, j + 20, k + 8, VetheaBlocks.mintwoodLeaves);
		world.setBlock(i + 8, j + 0, k + 6, VetheaBlocks.mintwood);
		world.setBlock(i + 8, j + 0, k + 7, VetheaBlocks.mintwood);
		world.setBlock(i + 8, j + 1, k + 6, VetheaBlocks.mintwood);
		world.setBlock(i + 8, j + 1, k + 7, VetheaBlocks.mintwood);
		world.setBlock(i + 8, j + 2, k + 6, VetheaBlocks.mintwood);
		world.setBlock(i + 8, j + 2, k + 7, VetheaBlocks.mintwood);
		world.setBlock(i + 8, j + 3, k + 6, VetheaBlocks.mintwood);
		world.setBlock(i + 8, j + 3, k + 7, VetheaBlocks.mintwood);
		world.setBlock(i + 8, j + 4, k + 6, VetheaBlocks.mintwood);
		world.setBlock(i + 8, j + 4, k + 7, VetheaBlocks.mintwood);
		world.setBlock(i + 8, j + 5, k + 6, VetheaBlocks.mintwood);
		world.setBlock(i + 8, j + 5, k + 7, VetheaBlocks.mintwood);
		world.setBlock(i + 8, j + 6, k + 6, VetheaBlocks.mintwood);
		world.setBlock(i + 8, j + 6, k + 7, VetheaBlocks.mintwood);
		world.setBlock(i + 8, j + 7, k + 6, VetheaBlocks.mintwood);
		world.setBlock(i + 8, j + 7, k + 7, VetheaBlocks.mintwood);
		world.setBlock(i + 8, j + 8, k + 6, VetheaBlocks.mintwood);
		world.setBlock(i + 8, j + 8, k + 7, VetheaBlocks.mintwood);
		world.setBlock(i + 8, j + 9, k + 6, VetheaBlocks.mintwood);
		world.setBlock(i + 8, j + 9, k + 7, VetheaBlocks.mintwood);
		world.setBlock(i + 8, j + 10, k + 5, VetheaBlocks.mintwoodLeaves);
		world.setBlock(i + 8, j + 10, k + 6, VetheaBlocks.mintwoodLeaves);
		world.setBlock(i + 8, j + 10, k + 7, VetheaBlocks.mintwoodLeaves);
		world.setBlock(i + 8, j + 11, k + 3, VetheaBlocks.mintwoodLeaves);
		world.setBlock(i + 8, j + 11, k + 4, VetheaBlocks.mintwoodLeaves);
		world.setBlock(i + 8, j + 11, k + 5, VetheaBlocks.mintwoodLeaves);
		world.setBlock(i + 8, j + 11, k + 6, VetheaBlocks.mintwoodLeaves);
		world.setBlock(i + 8, j + 11, k + 7, VetheaBlocks.mintwoodLeaves);
		world.setBlock(i + 8, j + 11, k + 8, VetheaBlocks.mintwoodLeaves);
		world.setBlock(i + 8, j + 11, k + 9, VetheaBlocks.mintwoodLeaves);
		world.setBlock(i + 8, j + 11, k + 10, VetheaBlocks.mintwoodLeaves);
		world.setBlock(i + 8, j + 11, k + 11, VetheaBlocks.mintwoodLeaves);
		world.setBlock(i + 8, j + 11, k + 12, VetheaBlocks.mintwoodLeaves);
		world.setBlock(i + 8, j + 12, k + 2, VetheaBlocks.mintwoodLeaves);
		world.setBlock(i + 8, j + 12, k + 3, VetheaBlocks.mintwoodLeaves);
		world.setBlock(i + 8, j + 12, k + 4, VetheaBlocks.mintwoodLeaves);
		world.setBlock(i + 8, j + 12, k + 5, VetheaBlocks.mintwoodLeaves);
		world.setBlock(i + 8, j + 12, k + 6, VetheaBlocks.mintwoodLeaves);
		world.setBlock(i + 8, j + 12, k + 7, VetheaBlocks.mintwoodLeaves);
		world.setBlock(i + 8, j + 12, k + 8, VetheaBlocks.mintwoodLeaves);
		world.setBlock(i + 8, j + 12, k + 9, VetheaBlocks.mintwoodLeaves);
		world.setBlock(i + 8, j + 12, k + 10, VetheaBlocks.mintwoodLeaves);
		world.setBlock(i + 8, j + 12, k + 11, VetheaBlocks.mintwoodLeaves);
		world.setBlock(i + 8, j + 12, k + 12, VetheaBlocks.mintwoodLeaves);
		world.setBlock(i + 8, j + 12, k + 13, VetheaBlocks.mintwoodLeaves);
		world.setBlock(i + 8, j + 13, k + 2, VetheaBlocks.mintwoodLeaves);
		world.setBlock(i + 8, j + 13, k + 3, VetheaBlocks.mintwoodLeaves);
		world.setBlock(i + 8, j + 13, k + 4, VetheaBlocks.mintwoodLeaves);
		world.setBlock(i + 8, j + 13, k + 5, VetheaBlocks.mintwoodLeaves);
		world.setBlock(i + 8, j + 13, k + 6, VetheaBlocks.mintwoodLeaves);
		world.setBlock(i + 8, j + 13, k + 7, VetheaBlocks.mintwoodLeaves);
		world.setBlock(i + 8, j + 13, k + 8, VetheaBlocks.mintwoodLeaves);
		world.setBlock(i + 8, j + 13, k + 9, VetheaBlocks.mintwoodLeaves);
		world.setBlock(i + 8, j + 13, k + 10, VetheaBlocks.mintwoodLeaves);
		world.setBlock(i + 8, j + 13, k + 11, VetheaBlocks.mintwoodLeaves);
		world.setBlock(i + 8, j + 13, k + 12, VetheaBlocks.mintwoodLeaves);
		world.setBlock(i + 8, j + 13, k + 13, VetheaBlocks.mintwoodLeaves);
		world.setBlock(i + 8, j + 14, k + 1, VetheaBlocks.mintwoodLeaves);
		world.setBlock(i + 8, j + 14, k + 2, VetheaBlocks.mintwoodLeaves);
		world.setBlock(i + 8, j + 14, k + 3, VetheaBlocks.mintwoodLeaves);
		world.setBlock(i + 8, j + 14, k + 4, VetheaBlocks.mintwoodLeaves);
		world.setBlock(i + 8, j + 14, k + 5, VetheaBlocks.mintwoodLeaves);
		world.setBlock(i + 8, j + 14, k + 6, VetheaBlocks.mintwoodLeaves);
		world.setBlock(i + 8, j + 14, k + 7, VetheaBlocks.mintwoodLeaves);
		world.setBlock(i + 8, j + 14, k + 8, VetheaBlocks.mintwoodLeaves);
		world.setBlock(i + 8, j + 14, k + 9, VetheaBlocks.mintwoodLeaves);
		world.setBlock(i + 8, j + 14, k + 10, VetheaBlocks.mintwoodLeaves);
		world.setBlock(i + 8, j + 14, k + 11, VetheaBlocks.mintwoodLeaves);
		world.setBlock(i + 8, j + 14, k + 12, VetheaBlocks.mintwoodLeaves);
		world.setBlock(i + 8, j + 14, k + 13, VetheaBlocks.mintwoodLeaves);
		world.setBlock(i + 8, j + 15, k + 1, VetheaBlocks.mintwoodLeaves);
		world.setBlock(i + 8, j + 15, k + 2, VetheaBlocks.mintwoodLeaves);
		world.setBlock(i + 8, j + 15, k + 3, VetheaBlocks.mintwoodLeaves);
		world.setBlock(i + 8, j + 15, k + 4, VetheaBlocks.mintwoodLeaves);
		world.setBlock(i + 8, j + 15, k + 5, VetheaBlocks.mintwoodLeaves);
		world.setBlock(i + 8, j + 15, k + 6, VetheaBlocks.mintwoodLeaves);
		world.setBlock(i + 8, j + 15, k + 7, VetheaBlocks.mintwoodLeaves);
		world.setBlock(i + 8, j + 15, k + 8, VetheaBlocks.mintwoodLeaves);
		world.setBlock(i + 8, j + 15, k + 9, VetheaBlocks.mintwoodLeaves);
		world.setBlock(i + 8, j + 15, k + 10, VetheaBlocks.mintwoodLeaves);
		world.setBlock(i + 8, j + 15, k + 11, VetheaBlocks.mintwoodLeaves);
		world.setBlock(i + 8, j + 15, k + 12, VetheaBlocks.mintwoodLeaves);
		world.setBlock(i + 8, j + 16, k + 1, VetheaBlocks.mintwoodLeaves);
		world.setBlock(i + 8, j + 16, k + 2, VetheaBlocks.mintwoodLeaves);
		world.setBlock(i + 8, j + 16, k + 3, VetheaBlocks.mintwoodLeaves);
		world.setBlock(i + 8, j + 16, k + 4, VetheaBlocks.mintwoodLeaves);
		world.setBlock(i + 8, j + 16, k + 5, VetheaBlocks.mintwoodLeaves);
		world.setBlock(i + 8, j + 16, k + 6, VetheaBlocks.mintwoodLeaves);
		world.setBlock(i + 8, j + 16, k + 7, VetheaBlocks.mintwoodLeaves);
		world.setBlock(i + 8, j + 16, k + 8, VetheaBlocks.mintwoodLeaves);
		world.setBlock(i + 8, j + 16, k + 9, VetheaBlocks.mintwoodLeaves);
		world.setBlock(i + 8, j + 16, k + 10, VetheaBlocks.mintwoodLeaves);
		world.setBlock(i + 8, j + 16, k + 11, VetheaBlocks.mintwoodLeaves);
		world.setBlock(i + 8, j + 17, k + 2, VetheaBlocks.mintwoodLeaves);
		world.setBlock(i + 8, j + 17, k + 3, VetheaBlocks.mintwoodLeaves);
		world.setBlock(i + 8, j + 17, k + 4, VetheaBlocks.mintwoodLeaves);
		world.setBlock(i + 8, j + 17, k + 5, VetheaBlocks.mintwoodLeaves);
		world.setBlock(i + 8, j + 17, k + 6, VetheaBlocks.mintwoodLeaves);
		world.setBlock(i + 8, j + 17, k + 7, VetheaBlocks.mintwoodLeaves);
		world.setBlock(i + 8, j + 17, k + 8, VetheaBlocks.mintwoodLeaves);
		world.setBlock(i + 8, j + 17, k + 9, VetheaBlocks.mintwoodLeaves);
		world.setBlock(i + 8, j + 17, k + 10, VetheaBlocks.mintwoodLeaves);
		world.setBlock(i + 8, j + 18, k + 2, VetheaBlocks.mintwoodLeaves);
		world.setBlock(i + 8, j + 18, k + 3, VetheaBlocks.mintwoodLeaves);
		world.setBlock(i + 8, j + 18, k + 4, VetheaBlocks.mintwoodLeaves);
		world.setBlock(i + 8, j + 18, k + 5, VetheaBlocks.mintwoodLeaves);
		world.setBlock(i + 8, j + 18, k + 6, VetheaBlocks.mintwoodLeaves);
		world.setBlock(i + 8, j + 18, k + 7, VetheaBlocks.mintwoodLeaves);
		world.setBlock(i + 8, j + 18, k + 8, VetheaBlocks.mintwoodLeaves);
		world.setBlock(i + 8, j + 18, k + 9, VetheaBlocks.mintwoodLeaves);
		world.setBlock(i + 8, j + 18, k + 10, VetheaBlocks.mintwoodLeaves);
		world.setBlock(i + 8, j + 19, k + 2, VetheaBlocks.mintwoodLeaves);
		world.setBlock(i + 8, j + 19, k + 3, VetheaBlocks.mintwoodLeaves);
		world.setBlock(i + 8, j + 19, k + 4, VetheaBlocks.mintwoodLeaves);
		world.setBlock(i + 8, j + 19, k + 5, VetheaBlocks.mintwoodLeaves);
		world.setBlock(i + 8, j + 19, k + 6, VetheaBlocks.mintwoodLeaves);
		world.setBlock(i + 8, j + 19, k + 7, VetheaBlocks.mintwoodLeaves);
		world.setBlock(i + 8, j + 19, k + 8, VetheaBlocks.mintwoodLeaves);
		world.setBlock(i + 8, j + 19, k + 9, VetheaBlocks.mintwoodLeaves);
		world.setBlock(i + 8, j + 20, k + 3, VetheaBlocks.mintwoodLeaves);
		world.setBlock(i + 8, j + 20, k + 4, VetheaBlocks.mintwoodLeaves);
		world.setBlock(i + 8, j + 20, k + 5, VetheaBlocks.mintwoodLeaves);
		world.setBlock(i + 8, j + 20, k + 6, VetheaBlocks.mintwoodLeaves);
		world.setBlock(i + 8, j + 20, k + 7, VetheaBlocks.mintwoodLeaves);
		world.setBlock(i + 9, j + 0, k + 6, VetheaBlocks.mintwood);
		world.setBlock(i + 9, j + 0, k + 7, VetheaBlocks.mintwood);
		world.setBlock(i + 9, j + 1, k + 6, VetheaBlocks.mintwood);
		world.setBlock(i + 9, j + 1, k + 7, VetheaBlocks.mintwood);
		world.setBlock(i + 9, j + 2, k + 6, VetheaBlocks.mintwood);
		world.setBlock(i + 9, j + 2, k + 7, VetheaBlocks.mintwood);
		world.setBlock(i + 9, j + 3, k + 6, VetheaBlocks.mintwood);
		world.setBlock(i + 9, j + 3, k + 7, VetheaBlocks.mintwood);
		world.setBlock(i + 9, j + 4, k + 6, VetheaBlocks.mintwood);
		world.setBlock(i + 9, j + 4, k + 7, VetheaBlocks.mintwood);
		world.setBlock(i + 9, j + 5, k + 6, VetheaBlocks.mintwood);
		world.setBlock(i + 9, j + 5, k + 7, VetheaBlocks.mintwood);
		world.setBlock(i + 9, j + 6, k + 6, VetheaBlocks.mintwood);
		world.setBlock(i + 9, j + 6, k + 7, VetheaBlocks.mintwood);
		world.setBlock(i + 9, j + 7, k + 6, VetheaBlocks.mintwood);
		world.setBlock(i + 9, j + 7, k + 7, VetheaBlocks.mintwood);
		world.setBlock(i + 9, j + 8, k + 6, VetheaBlocks.mintwood);
		world.setBlock(i + 9, j + 8, k + 7, VetheaBlocks.mintwood);
		world.setBlock(i + 9, j + 9, k + 6, VetheaBlocks.mintwood);
		world.setBlock(i + 9, j + 9, k + 7, VetheaBlocks.mintwood);
		world.setBlock(i + 9, j + 10, k + 6, VetheaBlocks.mintwood);
		world.setBlock(i + 9, j + 10, k + 7, VetheaBlocks.mintwood);
		world.setBlock(i + 9, j + 11, k + 4, VetheaBlocks.mintwoodLeaves);
		world.setBlock(i + 9, j + 11, k + 5, VetheaBlocks.mintwoodLeaves);
		world.setBlock(i + 9, j + 11, k + 6, VetheaBlocks.mintwoodLeaves);
		world.setBlock(i + 9, j + 11, k + 7, VetheaBlocks.mintwoodLeaves);
		world.setBlock(i + 9, j + 11, k + 8, VetheaBlocks.mintwoodLeaves);
		world.setBlock(i + 9, j + 12, k + 3, VetheaBlocks.mintwoodLeaves);
		world.setBlock(i + 9, j + 12, k + 4, VetheaBlocks.mintwoodLeaves);
		world.setBlock(i + 9, j + 12, k + 5, VetheaBlocks.mintwoodLeaves);
		world.setBlock(i + 9, j + 12, k + 6, VetheaBlocks.mintwoodLeaves);
		world.setBlock(i + 9, j + 12, k + 7, VetheaBlocks.mintwoodLeaves);
		world.setBlock(i + 9, j + 12, k + 8, VetheaBlocks.mintwoodLeaves);
		world.setBlock(i + 9, j + 12, k + 9, VetheaBlocks.mintwoodLeaves);
		world.setBlock(i + 9, j + 12, k + 10, VetheaBlocks.mintwoodLeaves);
		world.setBlock(i + 9, j + 12, k + 11, VetheaBlocks.mintwoodLeaves);
		world.setBlock(i + 9, j + 12, k + 12, VetheaBlocks.mintwoodLeaves);
		world.setBlock(i + 9, j + 13, k + 2, VetheaBlocks.mintwoodLeaves);
		world.setBlock(i + 9, j + 13, k + 3, VetheaBlocks.mintwoodLeaves);
		world.setBlock(i + 9, j + 13, k + 4, VetheaBlocks.mintwoodLeaves);
		world.setBlock(i + 9, j + 13, k + 5, VetheaBlocks.mintwoodLeaves);
		world.setBlock(i + 9, j + 13, k + 6, VetheaBlocks.mintwoodLeaves);
		world.setBlock(i + 9, j + 13, k + 7, VetheaBlocks.mintwoodLeaves);
		world.setBlock(i + 9, j + 13, k + 8, VetheaBlocks.mintwoodLeaves);
		world.setBlock(i + 9, j + 13, k + 9, VetheaBlocks.mintwoodLeaves);
		world.setBlock(i + 9, j + 13, k + 10, VetheaBlocks.mintwoodLeaves);
		world.setBlock(i + 9, j + 13, k + 11, VetheaBlocks.mintwoodLeaves);
		world.setBlock(i + 9, j + 13, k + 12, VetheaBlocks.mintwoodLeaves);
		world.setBlock(i + 9, j + 14, k + 2, VetheaBlocks.mintwoodLeaves);
		world.setBlock(i + 9, j + 14, k + 3, VetheaBlocks.mintwoodLeaves);
		world.setBlock(i + 9, j + 14, k + 4, VetheaBlocks.mintwoodLeaves);
		world.setBlock(i + 9, j + 14, k + 5, VetheaBlocks.mintwoodLeaves);
		world.setBlock(i + 9, j + 14, k + 6, VetheaBlocks.mintwoodLeaves);
		world.setBlock(i + 9, j + 14, k + 7, VetheaBlocks.mintwoodLeaves);
		world.setBlock(i + 9, j + 14, k + 8, VetheaBlocks.mintwoodLeaves);
		world.setBlock(i + 9, j + 14, k + 9, VetheaBlocks.mintwoodLeaves);
		world.setBlock(i + 9, j + 14, k + 10, VetheaBlocks.mintwoodLeaves);
		world.setBlock(i + 9, j + 14, k + 11, VetheaBlocks.mintwoodLeaves);
		world.setBlock(i + 9, j + 14, k + 12, VetheaBlocks.mintwoodLeaves);
		world.setBlock(i + 9, j + 15, k + 2, VetheaBlocks.mintwoodLeaves);
		world.setBlock(i + 9, j + 15, k + 3, VetheaBlocks.mintwoodLeaves);
		world.setBlock(i + 9, j + 15, k + 4, VetheaBlocks.mintwoodLeaves);
		world.setBlock(i + 9, j + 15, k + 5, VetheaBlocks.mintwoodLeaves);
		world.setBlock(i + 9, j + 15, k + 6, VetheaBlocks.mintwoodLeaves);
		world.setBlock(i + 9, j + 15, k + 7, VetheaBlocks.mintwoodLeaves);
		world.setBlock(i + 9, j + 15, k + 8, VetheaBlocks.mintwoodLeaves);
		world.setBlock(i + 9, j + 15, k + 9, VetheaBlocks.mintwoodLeaves);
		world.setBlock(i + 9, j + 15, k + 11, VetheaBlocks.mintwoodLeaves);
		world.setBlock(i + 9, j + 15, k + 12, VetheaBlocks.mintwoodLeaves);
		world.setBlock(i + 9, j + 16, k + 2, VetheaBlocks.mintwoodLeaves);
		world.setBlock(i + 9, j + 16, k + 3, VetheaBlocks.mintwoodLeaves);
		world.setBlock(i + 9, j + 16, k + 4, VetheaBlocks.mintwoodLeaves);
		world.setBlock(i + 9, j + 16, k + 5, VetheaBlocks.mintwoodLeaves);
		world.setBlock(i + 9, j + 16, k + 6, VetheaBlocks.mintwoodLeaves);
		world.setBlock(i + 9, j + 16, k + 7, VetheaBlocks.mintwoodLeaves);
		world.setBlock(i + 9, j + 16, k + 8, VetheaBlocks.mintwoodLeaves);
		world.setBlock(i + 9, j + 16, k + 9, VetheaBlocks.mintwoodLeaves);
		world.setBlock(i + 9, j + 16, k + 10, VetheaBlocks.mintwoodLeaves);
		world.setBlock(i + 9, j + 16, k + 11, VetheaBlocks.mintwoodLeaves);
		world.setBlock(i + 9, j + 17, k + 2, VetheaBlocks.mintwoodLeaves);
		world.setBlock(i + 9, j + 17, k + 3, VetheaBlocks.mintwoodLeaves);
		world.setBlock(i + 9, j + 17, k + 4, VetheaBlocks.mintwoodLeaves);
		world.setBlock(i + 9, j + 17, k + 5, VetheaBlocks.mintwoodLeaves);
		world.setBlock(i + 9, j + 17, k + 6, VetheaBlocks.mintwoodLeaves);
		world.setBlock(i + 9, j + 17, k + 7, VetheaBlocks.mintwoodLeaves);
		world.setBlock(i + 9, j + 17, k + 8, VetheaBlocks.mintwoodLeaves);
		world.setBlock(i + 9, j + 17, k + 9, VetheaBlocks.mintwoodLeaves);
		world.setBlock(i + 9, j + 17, k + 10, VetheaBlocks.mintwoodLeaves);
		world.setBlock(i + 9, j + 18, k + 2, VetheaBlocks.mintwoodLeaves);
		world.setBlock(i + 9, j + 18, k + 3, VetheaBlocks.mintwoodLeaves);
		world.setBlock(i + 9, j + 18, k + 4, VetheaBlocks.mintwoodLeaves);
		world.setBlock(i + 9, j + 18, k + 5, VetheaBlocks.mintwoodLeaves);
		world.setBlock(i + 9, j + 18, k + 6, VetheaBlocks.mintwoodLeaves);
		world.setBlock(i + 9, j + 18, k + 7, VetheaBlocks.mintwoodLeaves);
		world.setBlock(i + 9, j + 18, k + 8, VetheaBlocks.mintwoodLeaves);
		world.setBlock(i + 9, j + 18, k + 9, VetheaBlocks.mintwoodLeaves);
		world.setBlock(i + 9, j + 19, k + 2, VetheaBlocks.mintwoodLeaves);
		world.setBlock(i + 9, j + 19, k + 3, VetheaBlocks.mintwoodLeaves);
		world.setBlock(i + 9, j + 19, k + 5, VetheaBlocks.mintwoodLeaves);
		world.setBlock(i + 9, j + 19, k + 6, VetheaBlocks.mintwoodLeaves);
		world.setBlock(i + 9, j + 19, k + 7, VetheaBlocks.mintwoodLeaves);
		world.setBlock(i + 9, j + 19, k + 8, VetheaBlocks.mintwoodLeaves);
		world.setBlock(i + 9, j + 20, k + 3, VetheaBlocks.mintwoodLeaves);
		world.setBlock(i + 9, j + 20, k + 4, VetheaBlocks.mintwoodLeaves);
		world.setBlock(i + 9, j + 20, k + 5, VetheaBlocks.mintwoodLeaves);
		world.setBlock(i + 10, j + 12, k + 4, VetheaBlocks.mintwoodLeaves);
		world.setBlock(i + 10, j + 12, k + 5, VetheaBlocks.mintwoodLeaves);
		world.setBlock(i + 10, j + 12, k + 6, VetheaBlocks.mintwoodLeaves);
		world.setBlock(i + 10, j + 12, k + 7, VetheaBlocks.mintwoodLeaves);
		world.setBlock(i + 10, j + 12, k + 8, VetheaBlocks.mintwoodLeaves);
		world.setBlock(i + 10, j + 12, k + 9, VetheaBlocks.mintwoodLeaves);
		world.setBlock(i + 10, j + 12, k + 10, VetheaBlocks.mintwoodLeaves);
		world.setBlock(i + 10, j + 12, k + 11, VetheaBlocks.mintwoodLeaves);
		world.setBlock(i + 10, j + 13, k + 2, VetheaBlocks.mintwoodLeaves);
		world.setBlock(i + 10, j + 13, k + 3, VetheaBlocks.mintwoodLeaves);
		world.setBlock(i + 10, j + 13, k + 4, VetheaBlocks.mintwoodLeaves);
		world.setBlock(i + 10, j + 13, k + 5, VetheaBlocks.mintwoodLeaves);
		world.setBlock(i + 10, j + 13, k + 6, VetheaBlocks.mintwoodLeaves);
		world.setBlock(i + 10, j + 13, k + 7, VetheaBlocks.mintwoodLeaves);
		world.setBlock(i + 10, j + 13, k + 8, VetheaBlocks.mintwoodLeaves);
		world.setBlock(i + 10, j + 13, k + 9, VetheaBlocks.mintwoodLeaves);
		world.setBlock(i + 10, j + 13, k + 10, VetheaBlocks.mintwoodLeaves);
		world.setBlock(i + 10, j + 13, k + 11, VetheaBlocks.mintwoodLeaves);
		world.setBlock(i + 10, j + 13, k + 12, VetheaBlocks.mintwoodLeaves);
		world.setBlock(i + 10, j + 14, k + 1, VetheaBlocks.mintwoodLeaves);
		world.setBlock(i + 10, j + 14, k + 2, VetheaBlocks.mintwoodLeaves);
		world.setBlock(i + 10, j + 14, k + 3, VetheaBlocks.mintwoodLeaves);
		world.setBlock(i + 10, j + 14, k + 4, VetheaBlocks.mintwoodLeaves);
		world.setBlock(i + 10, j + 14, k + 5, VetheaBlocks.mintwoodLeaves);
		world.setBlock(i + 10, j + 14, k + 6, VetheaBlocks.mintwoodLeaves);
		world.setBlock(i + 10, j + 14, k + 7, VetheaBlocks.mintwoodLeaves);
		world.setBlock(i + 10, j + 14, k + 8, VetheaBlocks.mintwoodLeaves);
		world.setBlock(i + 10, j + 14, k + 9, VetheaBlocks.mintwoodLeaves);
		world.setBlock(i + 10, j + 14, k + 10, VetheaBlocks.mintwoodLeaves);
		world.setBlock(i + 10, j + 14, k + 11, VetheaBlocks.mintwoodLeaves);
		world.setBlock(i + 10, j + 14, k + 12, VetheaBlocks.mintwoodLeaves);
		world.setBlock(i + 10, j + 15, k + 1, VetheaBlocks.mintwoodLeaves);
		world.setBlock(i + 10, j + 15, k + 2, VetheaBlocks.mintwoodLeaves);
		world.setBlock(i + 10, j + 15, k + 3, VetheaBlocks.mintwoodLeaves);
		world.setBlock(i + 10, j + 15, k + 4, VetheaBlocks.mintwoodLeaves);
		world.setBlock(i + 10, j + 15, k + 5, VetheaBlocks.mintwoodLeaves);
		world.setBlock(i + 10, j + 15, k + 6, VetheaBlocks.mintwoodLeaves);
		world.setBlock(i + 10, j + 15, k + 7, VetheaBlocks.mintwoodLeaves);
		world.setBlock(i + 10, j + 15, k + 8, VetheaBlocks.mintwoodLeaves);
		world.setBlock(i + 10, j + 15, k + 9, VetheaBlocks.mintwoodLeaves);
		world.setBlock(i + 10, j + 15, k + 10, VetheaBlocks.mintwoodLeaves);
		world.setBlock(i + 10, j + 15, k + 12, VetheaBlocks.mintwoodLeaves);
		world.setBlock(i + 10, j + 16, k + 1, VetheaBlocks.mintwoodLeaves);
		world.setBlock(i + 10, j + 16, k + 2, VetheaBlocks.mintwoodLeaves);
		world.setBlock(i + 10, j + 16, k + 3, VetheaBlocks.mintwoodLeaves);
		world.setBlock(i + 10, j + 16, k + 4, VetheaBlocks.mintwoodLeaves);
		world.setBlock(i + 10, j + 16, k + 5, VetheaBlocks.mintwoodLeaves);
		world.setBlock(i + 10, j + 16, k + 6, VetheaBlocks.mintwoodLeaves);
		world.setBlock(i + 10, j + 16, k + 7, VetheaBlocks.mintwoodLeaves);
		world.setBlock(i + 10, j + 16, k + 8, VetheaBlocks.mintwoodLeaves);
		world.setBlock(i + 10, j + 16, k + 9, VetheaBlocks.mintwoodLeaves);
		world.setBlock(i + 10, j + 16, k + 10, VetheaBlocks.mintwoodLeaves);
		world.setBlock(i + 10, j + 16, k + 11, VetheaBlocks.mintwoodLeaves);
		world.setBlock(i + 10, j + 17, k + 2, VetheaBlocks.mintwoodLeaves);
		world.setBlock(i + 10, j + 17, k + 3, VetheaBlocks.mintwoodLeaves);
		world.setBlock(i + 10, j + 17, k + 4, VetheaBlocks.mintwoodLeaves);
		world.setBlock(i + 10, j + 17, k + 5, VetheaBlocks.mintwoodLeaves);
		world.setBlock(i + 10, j + 17, k + 6, VetheaBlocks.mintwoodLeaves);
		world.setBlock(i + 10, j + 17, k + 7, VetheaBlocks.mintwoodLeaves);
		world.setBlock(i + 10, j + 17, k + 8, VetheaBlocks.mintwoodLeaves);
		world.setBlock(i + 10, j + 17, k + 9, VetheaBlocks.mintwoodLeaves);
		world.setBlock(i + 10, j + 18, k + 2, VetheaBlocks.mintwoodLeaves);
		world.setBlock(i + 10, j + 18, k + 3, VetheaBlocks.mintwoodLeaves);
		world.setBlock(i + 10, j + 18, k + 4, VetheaBlocks.mintwoodLeaves);
		world.setBlock(i + 10, j + 18, k + 5, VetheaBlocks.mintwoodLeaves);
		world.setBlock(i + 10, j + 18, k + 6, VetheaBlocks.mintwoodLeaves);
		world.setBlock(i + 10, j + 18, k + 7, VetheaBlocks.mintwoodLeaves);
		world.setBlock(i + 10, j + 18, k + 8, VetheaBlocks.mintwoodLeaves);
		world.setBlock(i + 10, j + 19, k + 2, VetheaBlocks.mintwoodLeaves);
		world.setBlock(i + 10, j + 19, k + 3, VetheaBlocks.mintwoodLeaves);
		world.setBlock(i + 10, j + 19, k + 4, VetheaBlocks.mintwoodLeaves);
		world.setBlock(i + 10, j + 19, k + 5, VetheaBlocks.mintwoodLeaves);
		world.setBlock(i + 10, j + 19, k + 6, VetheaBlocks.mintwoodLeaves);
		world.setBlock(i + 10, j + 20, k + 3, VetheaBlocks.mintwoodLeaves);
		world.setBlock(i + 10, j + 20, k + 4, VetheaBlocks.mintwoodLeaves);
		world.setBlock(i + 10, j + 20, k + 5, VetheaBlocks.mintwoodLeaves);
		world.setBlock(i + 11, j + 12, k + 9, VetheaBlocks.mintwoodLeaves);
		world.setBlock(i + 11, j + 12, k + 10, VetheaBlocks.mintwoodLeaves);
		world.setBlock(i + 11, j + 12, k + 11, VetheaBlocks.mintwoodLeaves);
		world.setBlock(i + 11, j + 13, k + 2, VetheaBlocks.mintwoodLeaves);
		world.setBlock(i + 11, j + 13, k + 3, VetheaBlocks.mintwoodLeaves);
		world.setBlock(i + 11, j + 13, k + 4, VetheaBlocks.mintwoodLeaves);
		world.setBlock(i + 11, j + 13, k + 5, VetheaBlocks.mintwoodLeaves);
		world.setBlock(i + 11, j + 13, k + 6, VetheaBlocks.mintwoodLeaves);
		world.setBlock(i + 11, j + 13, k + 7, VetheaBlocks.mintwoodLeaves);
		world.setBlock(i + 11, j + 13, k + 8, VetheaBlocks.mintwoodLeaves);
		world.setBlock(i + 11, j + 13, k + 9, VetheaBlocks.mintwoodLeaves);
		world.setBlock(i + 11, j + 13, k + 10, VetheaBlocks.mintwoodLeaves);
		world.setBlock(i + 11, j + 13, k + 11, VetheaBlocks.mintwoodLeaves);
		world.setBlock(i + 11, j + 13, k + 12, VetheaBlocks.mintwoodLeaves);
		world.setBlock(i + 11, j + 14, k + 1, VetheaBlocks.mintwoodLeaves);
		world.setBlock(i + 11, j + 14, k + 2, VetheaBlocks.mintwoodLeaves);
		world.setBlock(i + 11, j + 14, k + 3, VetheaBlocks.mintwoodLeaves);
		world.setBlock(i + 11, j + 14, k + 4, VetheaBlocks.mintwoodLeaves);
		world.setBlock(i + 11, j + 14, k + 5, VetheaBlocks.mintwoodLeaves);
		world.setBlock(i + 11, j + 14, k + 6, VetheaBlocks.mintwoodLeaves);
		world.setBlock(i + 11, j + 14, k + 7, VetheaBlocks.mintwoodLeaves);
		world.setBlock(i + 11, j + 14, k + 8, VetheaBlocks.mintwoodLeaves);
		world.setBlock(i + 11, j + 14, k + 9, VetheaBlocks.mintwoodLeaves);
		world.setBlock(i + 11, j + 14, k + 10, VetheaBlocks.mintwoodLeaves);
		world.setBlock(i + 11, j + 14, k + 11, VetheaBlocks.mintwoodLeaves);
		world.setBlock(i + 11, j + 14, k + 12, VetheaBlocks.mintwoodLeaves);
		world.setBlock(i + 11, j + 15, k + 1, VetheaBlocks.mintwoodLeaves);
		world.setBlock(i + 11, j + 15, k + 2, VetheaBlocks.mintwoodLeaves);
		world.setBlock(i + 11, j + 15, k + 3, VetheaBlocks.mintwoodLeaves);
		world.setBlock(i + 11, j + 15, k + 4, VetheaBlocks.mintwoodLeaves);
		world.setBlock(i + 11, j + 15, k + 5, VetheaBlocks.mintwoodLeaves);
		world.setBlock(i + 11, j + 15, k + 6, VetheaBlocks.mintwoodLeaves);
		world.setBlock(i + 11, j + 15, k + 7, VetheaBlocks.mintwoodLeaves);
		world.setBlock(i + 11, j + 15, k + 8, VetheaBlocks.mintwoodLeaves);
		world.setBlock(i + 11, j + 15, k + 9, VetheaBlocks.mintwoodLeaves);
		world.setBlock(i + 11, j + 15, k + 10, VetheaBlocks.mintwoodLeaves);
		world.setBlock(i + 11, j + 15, k + 11, VetheaBlocks.mintwoodLeaves);
		world.setBlock(i + 11, j + 15, k + 12, VetheaBlocks.mintwoodLeaves);
		world.setBlock(i + 11, j + 16, k + 1, VetheaBlocks.mintwoodLeaves);
		world.setBlock(i + 11, j + 16, k + 2, VetheaBlocks.mintwoodLeaves);
		world.setBlock(i + 11, j + 16, k + 3, VetheaBlocks.mintwoodLeaves);
		world.setBlock(i + 11, j + 16, k + 4, VetheaBlocks.mintwoodLeaves);
		world.setBlock(i + 11, j + 16, k + 5, VetheaBlocks.mintwoodLeaves);
		world.setBlock(i + 11, j + 16, k + 6, VetheaBlocks.mintwoodLeaves);
		world.setBlock(i + 11, j + 16, k + 7, VetheaBlocks.mintwoodLeaves);
		world.setBlock(i + 11, j + 16, k + 8, VetheaBlocks.mintwoodLeaves);
		world.setBlock(i + 11, j + 16, k + 9, VetheaBlocks.mintwoodLeaves);
		world.setBlock(i + 11, j + 16, k + 10, VetheaBlocks.mintwoodLeaves);
		world.setBlock(i + 11, j + 16, k + 11, VetheaBlocks.mintwoodLeaves);
		world.setBlock(i + 11, j + 17, k + 2, VetheaBlocks.mintwoodLeaves);
		world.setBlock(i + 11, j + 17, k + 3, VetheaBlocks.mintwoodLeaves);
		world.setBlock(i + 11, j + 17, k + 4, VetheaBlocks.mintwoodLeaves);
		world.setBlock(i + 11, j + 17, k + 5, VetheaBlocks.mintwoodLeaves);
		world.setBlock(i + 11, j + 17, k + 6, VetheaBlocks.mintwoodLeaves);
		world.setBlock(i + 11, j + 17, k + 7, VetheaBlocks.mintwoodLeaves);
		world.setBlock(i + 11, j + 18, k + 3, VetheaBlocks.mintwoodLeaves);
		world.setBlock(i + 11, j + 18, k + 4, VetheaBlocks.mintwoodLeaves);
		world.setBlock(i + 11, j + 18, k + 5, VetheaBlocks.mintwoodLeaves);
		world.setBlock(i + 11, j + 19, k + 3, VetheaBlocks.mintwoodLeaves);
		world.setBlock(i + 11, j + 19, k + 4, VetheaBlocks.mintwoodLeaves);
		world.setBlock(i + 11, j + 19, k + 5, VetheaBlocks.mintwoodLeaves);
		world.setBlock(i + 12, j + 13, k + 2, VetheaBlocks.mintwoodLeaves);
		world.setBlock(i + 12, j + 13, k + 3, VetheaBlocks.mintwoodLeaves);
		world.setBlock(i + 12, j + 13, k + 4, VetheaBlocks.mintwoodLeaves);
		world.setBlock(i + 12, j + 13, k + 9, VetheaBlocks.mintwoodLeaves);
		world.setBlock(i + 12, j + 13, k + 10, VetheaBlocks.mintwoodLeaves);
		world.setBlock(i + 12, j + 13, k + 11, VetheaBlocks.mintwoodLeaves);
		world.setBlock(i + 12, j + 14, k + 1, VetheaBlocks.mintwoodLeaves);
		world.setBlock(i + 12, j + 14, k + 2, VetheaBlocks.mintwoodLeaves);
		world.setBlock(i + 12, j + 14, k + 3, VetheaBlocks.mintwoodLeaves);
		world.setBlock(i + 12, j + 14, k + 4, VetheaBlocks.mintwoodLeaves);
		world.setBlock(i + 12, j + 14, k + 5, VetheaBlocks.mintwoodLeaves);
		world.setBlock(i + 12, j + 14, k + 9, VetheaBlocks.mintwoodLeaves);
		world.setBlock(i + 12, j + 14, k + 10, VetheaBlocks.mintwoodLeaves);
		world.setBlock(i + 12, j + 14, k + 11, VetheaBlocks.mintwoodLeaves);
		world.setBlock(i + 12, j + 15, k + 1, VetheaBlocks.mintwoodLeaves);
		world.setBlock(i + 12, j + 15, k + 2, VetheaBlocks.mintwoodLeaves);
		world.setBlock(i + 12, j + 15, k + 3, VetheaBlocks.mintwoodLeaves);
		world.setBlock(i + 12, j + 15, k + 4, VetheaBlocks.mintwoodLeaves);
		world.setBlock(i + 12, j + 15, k + 5, VetheaBlocks.mintwoodLeaves);
		world.setBlock(i + 12, j + 15, k + 9, VetheaBlocks.mintwoodLeaves);
		world.setBlock(i + 12, j + 15, k + 10, VetheaBlocks.mintwoodLeaves);
		world.setBlock(i + 12, j + 15, k + 11, VetheaBlocks.mintwoodLeaves);
		world.setBlock(i + 12, j + 16, k + 1, VetheaBlocks.mintwoodLeaves);
		world.setBlock(i + 12, j + 16, k + 2, VetheaBlocks.mintwoodLeaves);
		world.setBlock(i + 12, j + 16, k + 3, VetheaBlocks.mintwoodLeaves);
		world.setBlock(i + 12, j + 16, k + 4, VetheaBlocks.mintwoodLeaves);
		world.setBlock(i + 12, j + 16, k + 5, VetheaBlocks.mintwoodLeaves);
		world.setBlock(i + 12, j + 16, k + 10, VetheaBlocks.mintwoodLeaves);
		world.setBlock(i + 12, j + 17, k + 2, VetheaBlocks.mintwoodLeaves);
		world.setBlock(i + 12, j + 17, k + 3, VetheaBlocks.mintwoodLeaves);
		world.setBlock(i + 12, j + 17, k + 4, VetheaBlocks.mintwoodLeaves);
		world.setBlock(i + 13, j + 14, k + 2, VetheaBlocks.mintwoodLeaves);
		world.setBlock(i + 13, j + 14, k + 3, VetheaBlocks.mintwoodLeaves);
		world.setBlock(i + 13, j + 14, k + 4, VetheaBlocks.mintwoodLeaves);
		world.setBlock(i + 13, j + 15, k + 2, VetheaBlocks.mintwoodLeaves);
		world.setBlock(i + 13, j + 15, k + 3, VetheaBlocks.mintwoodLeaves);
		world.setBlock(i + 13, j + 15, k + 4, VetheaBlocks.mintwoodLeaves);
		world.setBlock(i + 13, j + 16, k + 2, VetheaBlocks.mintwoodLeaves);
		world.setBlock(i + 13, j + 16, k + 4, VetheaBlocks.mintwoodLeaves);

		return true;
	}
}