/*
*** MADE BY MITHION'S .SCHEMATIC TO JAVA CONVERTING TOOL v1.6 ***
*/

package net.divinerpg.dimensions.vethea.village;
import java.util.Random;

import net.divinerpg.utils.blocks.VetheaBlocks;
import net.minecraft.world.World;
import net.minecraft.world.gen.feature.WorldGenerator;

public class HouseDown2 extends WorldGenerator
{
	protected int[] GetValidSpawnBlocks() {
		return new int[] {
		};
	}

	public HouseDown2() { }

	public boolean generate(World world, Random rand, int i, int j, int k) {

		world.setBlock(i + 0, j + 0, k + 0, VetheaBlocks.darkDreamBricks);
		world.setBlock(i + 0, j + 0, k + 1, VetheaBlocks.darkDreamBricks);
		world.setBlock(i + 0, j + 0, k + 2, VetheaBlocks.darkDreamBricks);
		world.setBlock(i + 0, j + 0, k + 3, VetheaBlocks.darkDreamBricks);
		world.setBlock(i + 0, j + 0, k + 4, VetheaBlocks.darkDreamBricks);
		world.setBlock(i + 0, j + 0, k + 5, VetheaBlocks.darkDreamBricks);
		world.setBlock(i + 0, j + 0, k + 6, VetheaBlocks.darkDreamBricks);
		world.setBlock(i + 0, j + 0, k + 7, VetheaBlocks.darkDreamBricks);
		world.setBlock(i + 0, j + 0, k + 8, VetheaBlocks.darkDreamBricks);
		world.setBlock(i + 0, j + 0, k + 9, VetheaBlocks.darkDreamBricks);
		world.setBlock(i + 0, j + 0, k + 10, VetheaBlocks.darkDreamBricks);
		world.setBlock(i + 0, j + 1, k + 0, VetheaBlocks.darkDreamBricks);
		world.setBlock(i + 0, j + 1, k + 1, VetheaBlocks.lightDreamBricks);
		world.setBlock(i + 0, j + 1, k + 2, VetheaBlocks.lightDreamBricks);
		world.setBlock(i + 0, j + 1, k + 3, VetheaBlocks.lightDreamBricks);
		world.setBlock(i + 0, j + 1, k + 4, VetheaBlocks.lightDreamBricks);
		world.setBlock(i + 0, j + 1, k + 5, VetheaBlocks.lightDreamBricks);
		world.setBlock(i + 0, j + 1, k + 6, VetheaBlocks.lightDreamBricks);
		world.setBlock(i + 0, j + 1, k + 7, VetheaBlocks.lightDreamBricks);
		world.setBlock(i + 0, j + 1, k + 8, VetheaBlocks.lightDreamBricks);
		world.setBlock(i + 0, j + 1, k + 9, VetheaBlocks.lightDreamBricks);
		world.setBlock(i + 0, j + 1, k + 10, VetheaBlocks.darkDreamBricks);
		world.setBlock(i + 0, j + 2, k + 0, VetheaBlocks.darkDreamBricks);
		world.setBlock(i + 0, j + 2, k + 1, VetheaBlocks.darkDreamBricks);
		world.setBlock(i + 0, j + 2, k + 2, VetheaBlocks.darkDreamBricks);
		world.setBlock(i + 0, j + 2, k + 3, VetheaBlocks.darkDreamBricks);
		world.setBlock(i + 0, j + 2, k + 4, VetheaBlocks.darkDreamBricks);
		world.setBlock(i + 0, j + 2, k + 5, VetheaBlocks.darkDreamBricks);
		world.setBlock(i + 0, j + 2, k + 6, VetheaBlocks.darkDreamBricks);
		world.setBlock(i + 0, j + 2, k + 7, VetheaBlocks.darkDreamBricks);
		world.setBlock(i + 0, j + 2, k + 8, VetheaBlocks.darkDreamBricks);
		world.setBlock(i + 0, j + 2, k + 9, VetheaBlocks.darkDreamBricks);
		world.setBlock(i + 0, j + 2, k + 10, VetheaBlocks.darkDreamBricks);
		world.setBlock(i + 1, j + 0, k + 0, VetheaBlocks.darkDreamBricks);
		world.setBlock(i + 1, j + 0, k + 1, VetheaBlocks.smoothGlass);
		world.setBlock(i + 1, j + 0, k + 2, VetheaBlocks.smoothGlass);
		world.setBlock(i + 1, j + 0, k + 3, VetheaBlocks.smoothGlass);
		world.setBlock(i + 1, j + 0, k + 4, VetheaBlocks.smoothGlass);
		world.setBlock(i + 1, j + 0, k + 5, VetheaBlocks.smoothGlass);
		world.setBlock(i + 1, j + 0, k + 6, VetheaBlocks.smoothGlass);
		world.setBlock(i + 1, j + 0, k + 7, VetheaBlocks.smoothGlass);
		world.setBlock(i + 1, j + 0, k + 8, VetheaBlocks.smoothGlass);
		world.setBlock(i + 1, j + 0, k + 9, VetheaBlocks.smoothGlass);
		world.setBlock(i + 1, j + 0, k + 10, VetheaBlocks.darkDreamBricks);
		world.setBlock(i + 1, j + 1, k + 0, VetheaBlocks.lightDreamBricks);
		world.setBlock(i + 1, j + 1, k + 1, VetheaBlocks.firelight);
		world.setBlock(i + 1, j + 1, k + 9, VetheaBlocks.firelight);
		world.setBlock(i + 1, j + 1, k + 10, VetheaBlocks.lightDreamBricks);
		world.setBlock(i + 1, j + 2, k + 0, VetheaBlocks.darkDreamBricks);
		world.setBlock(i + 1, j + 2, k + 10, VetheaBlocks.darkDreamBricks);
		world.setBlock(i + 1, j + 3, k + 1, VetheaBlocks.darkDreamBricks);
		world.setBlock(i + 1, j + 3, k + 2, VetheaBlocks.darkDreamBricks);
		world.setBlock(i + 1, j + 3, k + 3, VetheaBlocks.darkDreamBricks);
		world.setBlock(i + 1, j + 3, k + 4, VetheaBlocks.darkDreamBricks);
		world.setBlock(i + 1, j + 3, k + 5, VetheaBlocks.darkDreamBricks);
		world.setBlock(i + 1, j + 3, k + 6, VetheaBlocks.darkDreamBricks);
		world.setBlock(i + 1, j + 3, k + 7, VetheaBlocks.darkDreamBricks);
		world.setBlock(i + 1, j + 3, k + 8, VetheaBlocks.darkDreamBricks);
		world.setBlock(i + 1, j + 3, k + 9, VetheaBlocks.darkDreamBricks);
		world.setBlock(i + 1, j + 4, k + 1, VetheaBlocks.darkDreamBricks);
		world.setBlock(i + 1, j + 4, k + 2, VetheaBlocks.lightDreamBricks);
		world.setBlock(i + 1, j + 4, k + 3, VetheaBlocks.lightDreamBricks);
		world.setBlock(i + 1, j + 4, k + 4, VetheaBlocks.lightDreamBricks);
		world.setBlock(i + 1, j + 4, k + 5, VetheaBlocks.lightDreamBricks);
		world.setBlock(i + 1, j + 4, k + 6, VetheaBlocks.lightDreamBricks);
		world.setBlock(i + 1, j + 4, k + 7, VetheaBlocks.lightDreamBricks);
		world.setBlock(i + 1, j + 4, k + 8, VetheaBlocks.lightDreamBricks);
		world.setBlock(i + 1, j + 4, k + 9, VetheaBlocks.darkDreamBricks);
		world.setBlock(i + 1, j + 5, k + 1, VetheaBlocks.darkDreamBricks);
		world.setBlock(i + 1, j + 5, k + 2, VetheaBlocks.darkDreamBricks);
		world.setBlock(i + 1, j + 5, k + 3, VetheaBlocks.darkDreamBricks);
		world.setBlock(i + 1, j + 5, k + 4, VetheaBlocks.darkDreamBricks);
		world.setBlock(i + 1, j + 5, k + 5, VetheaBlocks.darkDreamBricks);
		world.setBlock(i + 1, j + 5, k + 6, VetheaBlocks.darkDreamBricks);
		world.setBlock(i + 1, j + 5, k + 7, VetheaBlocks.darkDreamBricks);
		world.setBlock(i + 1, j + 5, k + 8, VetheaBlocks.darkDreamBricks);
		world.setBlock(i + 1, j + 5, k + 9, VetheaBlocks.darkDreamBricks);
		world.setBlock(i + 1, j + 12, k + 3, VetheaBlocks.darkDreamBricks);
		world.setBlock(i + 1, j + 12, k + 7, VetheaBlocks.darkDreamBricks);
		world.setBlock(i + 1, j + 13, k + 4, VetheaBlocks.darkDreamBricks);
		world.setBlock(i + 1, j + 13, k + 5, VetheaBlocks.darkDreamBricks);
		world.setBlock(i + 1, j + 13, k + 6, VetheaBlocks.darkDreamBricks);
		world.setBlock(i + 2, j + 0, k + 0, VetheaBlocks.darkDreamBricks);
		world.setBlock(i + 2, j + 0, k + 1, VetheaBlocks.smoothGlass);
		world.setBlock(i + 2, j + 0, k + 2, VetheaBlocks.smoothGlass);
		world.setBlock(i + 2, j + 0, k + 3, VetheaBlocks.smoothGlass);
		world.setBlock(i + 2, j + 0, k + 4, VetheaBlocks.smoothGlass);
		world.setBlock(i + 2, j + 0, k + 5, VetheaBlocks.smoothGlass);
		world.setBlock(i + 2, j + 0, k + 6, VetheaBlocks.smoothGlass);
		world.setBlock(i + 2, j + 0, k + 7, VetheaBlocks.smoothGlass);
		world.setBlock(i + 2, j + 0, k + 8, VetheaBlocks.smoothGlass);
		world.setBlock(i + 2, j + 0, k + 9, VetheaBlocks.smoothGlass);
		world.setBlock(i + 2, j + 0, k + 10, VetheaBlocks.darkDreamBricks);
		world.setBlock(i + 2, j + 1, k + 0, VetheaBlocks.lightDreamBricks);
		world.setBlock(i + 2, j + 1, k + 10, VetheaBlocks.lightDreamBricks);
		world.setBlock(i + 2, j + 2, k + 0, VetheaBlocks.darkDreamBricks);
		world.setBlock(i + 2, j + 2, k + 10, VetheaBlocks.darkDreamBricks);
		world.setBlock(i + 2, j + 3, k + 1, VetheaBlocks.darkDreamBricks);
		world.setBlock(i + 2, j + 3, k + 9, VetheaBlocks.darkDreamBricks);
		world.setBlock(i + 2, j + 4, k + 1, VetheaBlocks.lightDreamBricks);
		world.setBlock(i + 2, j + 4, k + 9, VetheaBlocks.lightDreamBricks);
		world.setBlock(i + 2, j + 5, k + 1, VetheaBlocks.darkDreamBricks);
		world.setBlock(i + 2, j + 5, k + 9, VetheaBlocks.darkDreamBricks);
		world.setBlock(i + 2, j + 6, k + 2, VetheaBlocks.darkDreamBricks);
		world.setBlock(i + 2, j + 6, k + 3, VetheaBlocks.darkDreamBricks);
		world.setBlock(i + 2, j + 6, k + 4, VetheaBlocks.darkDreamBricks);
		world.setBlock(i + 2, j + 6, k + 5, VetheaBlocks.darkDreamBricks);
		world.setBlock(i + 2, j + 6, k + 6, VetheaBlocks.darkDreamBricks);
		world.setBlock(i + 2, j + 6, k + 7, VetheaBlocks.darkDreamBricks);
		world.setBlock(i + 2, j + 6, k + 8, VetheaBlocks.darkDreamBricks);
		world.setBlock(i + 2, j + 12, k + 3, VetheaBlocks.darkDreamBricks);
		world.setBlock(i + 2, j + 12, k + 7, VetheaBlocks.darkDreamBricks);
		world.setBlock(i + 2, j + 13, k + 4, VetheaBlocks.darkDreamBricks);
		world.setBlock(i + 2, j + 13, k + 5, VetheaBlocks.darkDreamBricks);
		world.setBlock(i + 2, j + 13, k + 6, VetheaBlocks.darkDreamBricks);
		world.setBlock(i + 3, j + 0, k + 0, VetheaBlocks.darkDreamBricks);
		world.setBlock(i + 3, j + 0, k + 1, VetheaBlocks.smoothGlass);
		world.setBlock(i + 3, j + 0, k + 2, VetheaBlocks.smoothGlass);
		world.setBlock(i + 3, j + 0, k + 3, VetheaBlocks.smoothGlass);
		world.setBlock(i + 3, j + 0, k + 4, VetheaBlocks.smoothGlass);
		world.setBlock(i + 3, j + 0, k + 5, VetheaBlocks.smoothGlass);
		world.setBlock(i + 3, j + 0, k + 6, VetheaBlocks.smoothGlass);
		world.setBlock(i + 3, j + 0, k + 7, VetheaBlocks.smoothGlass);
		world.setBlock(i + 3, j + 0, k + 8, VetheaBlocks.smoothGlass);
		world.setBlock(i + 3, j + 0, k + 9, VetheaBlocks.smoothGlass);
		world.setBlock(i + 3, j + 0, k + 10, VetheaBlocks.darkDreamBricks);
		world.setBlock(i + 3, j + 1, k + 0, VetheaBlocks.lightDreamBricks);
		world.setBlock(i + 3, j + 1, k + 10, VetheaBlocks.lightDreamBricks);
		world.setBlock(i + 3, j + 2, k + 0, VetheaBlocks.darkDreamBricks);
		world.setBlock(i + 3, j + 2, k + 10, VetheaBlocks.darkDreamBricks);
		world.setBlock(i + 3, j + 3, k + 1, VetheaBlocks.darkDreamBricks);
		world.setBlock(i + 3, j + 3, k + 9, VetheaBlocks.darkDreamBricks);
		world.setBlock(i + 3, j + 4, k + 1, VetheaBlocks.lightDreamBricks);
		world.setBlock(i + 3, j + 4, k + 9, VetheaBlocks.lightDreamBricks);
		world.setBlock(i + 3, j + 5, k + 1, VetheaBlocks.darkDreamBricks);
		world.setBlock(i + 3, j + 5, k + 9, VetheaBlocks.darkDreamBricks);
		world.setBlock(i + 3, j + 6, k + 2, VetheaBlocks.darkDreamBricks);
		world.setBlock(i + 3, j + 6, k + 8, VetheaBlocks.darkDreamBricks);
		world.setBlock(i + 3, j + 7, k + 3, VetheaBlocks.darkDreamBricks);
		world.setBlock(i + 3, j + 7, k + 4, VetheaBlocks.darkDreamBricks);
		world.setBlock(i + 3, j + 7, k + 5, VetheaBlocks.darkDreamBricks);
		world.setBlock(i + 3, j + 7, k + 6, VetheaBlocks.darkDreamBricks);
		world.setBlock(i + 3, j + 7, k + 7, VetheaBlocks.darkDreamBricks);
		world.setBlock(i + 3, j + 12, k + 3, VetheaBlocks.darkDreamBricks);
		world.setBlock(i + 3, j + 12, k + 7, VetheaBlocks.darkDreamBricks);
		world.setBlock(i + 3, j + 13, k + 4, VetheaBlocks.darkDreamBricks);
		world.setBlock(i + 3, j + 13, k + 5, VetheaBlocks.darkDreamBricks);
		world.setBlock(i + 3, j + 13, k + 6, VetheaBlocks.darkDreamBricks);
		world.setBlock(i + 4, j + 0, k + 0, VetheaBlocks.darkDreamBricks);
		world.setBlock(i + 4, j + 0, k + 1, VetheaBlocks.smoothGlass);
		world.setBlock(i + 4, j + 0, k + 2, VetheaBlocks.smoothGlass);
		world.setBlock(i + 4, j + 0, k + 3, VetheaBlocks.smoothGlass);
		world.setBlock(i + 4, j + 0, k + 4, VetheaBlocks.smoothGlass);
		world.setBlock(i + 4, j + 0, k + 5, VetheaBlocks.smoothGlass);
		world.setBlock(i + 4, j + 0, k + 6, VetheaBlocks.smoothGlass);
		world.setBlock(i + 4, j + 0, k + 7, VetheaBlocks.smoothGlass);
		world.setBlock(i + 4, j + 0, k + 8, VetheaBlocks.smoothGlass);
		world.setBlock(i + 4, j + 0, k + 9, VetheaBlocks.smoothGlass);
		world.setBlock(i + 4, j + 0, k + 10, VetheaBlocks.darkDreamBricks);
		world.setBlock(i + 4, j + 1, k + 0, VetheaBlocks.lightDreamBricks);
		world.setBlock(i + 4, j + 1, k + 10, VetheaBlocks.lightDreamBricks);
		world.setBlock(i + 4, j + 2, k + 0, VetheaBlocks.darkDreamBricks);
		world.setBlock(i + 4, j + 2, k + 10, VetheaBlocks.darkDreamBricks);
		world.setBlock(i + 4, j + 3, k + 1, VetheaBlocks.darkDreamBricks);
		world.setBlock(i + 4, j + 3, k + 9, VetheaBlocks.darkDreamBricks);
		world.setBlock(i + 4, j + 4, k + 1, VetheaBlocks.lightDreamBricks);
		world.setBlock(i + 4, j + 4, k + 9, VetheaBlocks.lightDreamBricks);
		world.setBlock(i + 4, j + 5, k + 1, VetheaBlocks.darkDreamBricks);
		world.setBlock(i + 4, j + 5, k + 9, VetheaBlocks.darkDreamBricks);
		world.setBlock(i + 4, j + 6, k + 2, VetheaBlocks.darkDreamBricks);
		world.setBlock(i + 4, j + 6, k + 8, VetheaBlocks.darkDreamBricks);
		world.setBlock(i + 4, j + 7, k + 3, VetheaBlocks.darkDreamBricks);
		world.setBlock(i + 4, j + 7, k + 4, VetheaBlocks.lunaStone);
		world.setBlock(i + 4, j + 7, k + 5, VetheaBlocks.lunaStone);
		world.setBlock(i + 4, j + 7, k + 6, VetheaBlocks.lunaStone);
		world.setBlock(i + 4, j + 7, k + 7, VetheaBlocks.darkDreamBricks);
		world.setBlock(i + 4, j + 8, k + 4, VetheaBlocks.darkDreamBricks);
		world.setBlock(i + 4, j + 8, k + 5, VetheaBlocks.darkDreamBricks);
		world.setBlock(i + 4, j + 8, k + 6, VetheaBlocks.darkDreamBricks);
		world.setBlock(i + 4, j + 9, k + 4, VetheaBlocks.darkDreamBricks);
		world.setBlock(i + 4, j + 9, k + 5, VetheaBlocks.lightDreamBricks);
		world.setBlock(i + 4, j + 9, k + 6, VetheaBlocks.darkDreamBricks);
		world.setBlock(i + 4, j + 10, k + 4, VetheaBlocks.darkDreamBricks);
		world.setBlock(i + 4, j + 10, k + 5, VetheaBlocks.darkDreamBricks);
		world.setBlock(i + 4, j + 10, k + 6, VetheaBlocks.darkDreamBricks);
		world.setBlock(i + 4, j + 11, k + 4, VetheaBlocks.darkDreamBricks);
		world.setBlock(i + 4, j + 11, k + 6, VetheaBlocks.darkDreamBricks);
		world.setBlock(i + 4, j + 12, k + 4, VetheaBlocks.darkDreamBricks);
		world.setBlock(i + 4, j + 12, k + 6, VetheaBlocks.darkDreamBricks);
		world.setBlock(i + 4, j + 13, k + 4, VetheaBlocks.darkDreamBricks);
		world.setBlock(i + 4, j + 13, k + 5, VetheaBlocks.darkDreamBricks);
		world.setBlock(i + 4, j + 13, k + 6, VetheaBlocks.darkDreamBricks);
		world.setBlock(i + 5, j + 0, k + 0, VetheaBlocks.darkDreamBricks);
		world.setBlock(i + 5, j + 0, k + 1, VetheaBlocks.smoothGlass);
		world.setBlock(i + 5, j + 0, k + 2, VetheaBlocks.smoothGlass);
		world.setBlock(i + 5, j + 0, k + 3, VetheaBlocks.smoothGlass);
		world.setBlock(i + 5, j + 0, k + 4, VetheaBlocks.smoothGlass);
		world.setBlock(i + 5, j + 0, k + 5, VetheaBlocks.smoothGlass);
		world.setBlock(i + 5, j + 0, k + 6, VetheaBlocks.smoothGlass);
		world.setBlock(i + 5, j + 0, k + 7, VetheaBlocks.smoothGlass);
		world.setBlock(i + 5, j + 0, k + 8, VetheaBlocks.smoothGlass);
		world.setBlock(i + 5, j + 0, k + 9, VetheaBlocks.smoothGlass);
		world.setBlock(i + 5, j + 0, k + 10, VetheaBlocks.darkDreamBricks);
		world.setBlock(i + 5, j + 1, k + 0, VetheaBlocks.lightDreamBricks);
		world.setBlock(i + 5, j + 1, k + 10, VetheaBlocks.lightDreamBricks);
		world.setBlock(i + 5, j + 2, k + 0, VetheaBlocks.darkDreamBricks);
		world.setBlock(i + 5, j + 2, k + 10, VetheaBlocks.darkDreamBricks);
		world.setBlock(i + 5, j + 3, k + 1, VetheaBlocks.darkDreamBricks);
		world.setBlock(i + 5, j + 3, k + 9, VetheaBlocks.darkDreamBricks);
		world.setBlock(i + 5, j + 4, k + 1, VetheaBlocks.lightDreamBricks);
		world.setBlock(i + 5, j + 4, k + 9, VetheaBlocks.lightDreamBricks);
		world.setBlock(i + 5, j + 5, k + 1, VetheaBlocks.darkDreamBricks);
		world.setBlock(i + 5, j + 5, k + 9, VetheaBlocks.darkDreamBricks);
		world.setBlock(i + 5, j + 6, k + 2, VetheaBlocks.darkDreamBricks);
		world.setBlock(i + 5, j + 6, k + 8, VetheaBlocks.darkDreamBricks);
		world.setBlock(i + 5, j + 7, k + 3, VetheaBlocks.darkDreamBricks);
		world.setBlock(i + 5, j + 7, k + 7, VetheaBlocks.darkDreamBricks);
		world.setBlock(i + 5, j + 8, k + 4, VetheaBlocks.darkDreamBricks);
		world.setBlock(i + 5, j + 8, k + 6, VetheaBlocks.darkDreamBricks);
		world.setBlock(i + 5, j + 9, k + 4, VetheaBlocks.lightDreamBricks);
		world.setBlock(i + 5, j + 9, k + 6, VetheaBlocks.lightDreamBricks);
		world.setBlock(i + 5, j + 10, k + 4, VetheaBlocks.lightDreamBricks);
		world.setBlock(i + 5, j + 10, k + 6, VetheaBlocks.lightDreamBricks);
		world.setBlock(i + 5, j + 11, k + 4, VetheaBlocks.smoothGlass);
		world.setBlock(i + 5, j + 11, k + 6, VetheaBlocks.smoothGlass);
		world.setBlock(i + 5, j + 12, k + 4, VetheaBlocks.lightDreamBricks);
		world.setBlock(i + 5, j + 12, k + 6, VetheaBlocks.lightDreamBricks);
		world.setBlock(i + 5, j + 13, k + 4, VetheaBlocks.darkDreamBricks);
		world.setBlock(i + 5, j + 13, k + 5, VetheaBlocks.lunaStone);
		world.setBlock(i + 5, j + 13, k + 6, VetheaBlocks.darkDreamBricks);
		world.setBlock(i + 6, j + 0, k + 0, VetheaBlocks.darkDreamBricks);
		world.setBlock(i + 6, j + 0, k + 1, VetheaBlocks.smoothGlass);
		world.setBlock(i + 6, j + 0, k + 2, VetheaBlocks.smoothGlass);
		world.setBlock(i + 6, j + 0, k + 3, VetheaBlocks.smoothGlass);
		world.setBlock(i + 6, j + 0, k + 4, VetheaBlocks.smoothGlass);
		world.setBlock(i + 6, j + 0, k + 5, VetheaBlocks.smoothGlass);
		world.setBlock(i + 6, j + 0, k + 6, VetheaBlocks.smoothGlass);
		world.setBlock(i + 6, j + 0, k + 7, VetheaBlocks.smoothGlass);
		world.setBlock(i + 6, j + 0, k + 8, VetheaBlocks.smoothGlass);
		world.setBlock(i + 6, j + 0, k + 9, VetheaBlocks.smoothGlass);
		world.setBlock(i + 6, j + 0, k + 10, VetheaBlocks.darkDreamBricks);
		world.setBlock(i + 6, j + 1, k + 0, VetheaBlocks.lightDreamBricks);
		world.setBlock(i + 6, j + 1, k + 10, VetheaBlocks.lightDreamBricks);
		world.setBlock(i + 6, j + 2, k + 0, VetheaBlocks.darkDreamBricks);
		world.setBlock(i + 6, j + 2, k + 10, VetheaBlocks.darkDreamBricks);
		world.setBlock(i + 6, j + 3, k + 1, VetheaBlocks.darkDreamBricks);
		world.setBlock(i + 6, j + 3, k + 9, VetheaBlocks.darkDreamBricks);
		world.setBlock(i + 6, j + 4, k + 1, VetheaBlocks.lightDreamBricks);
		world.setBlock(i + 6, j + 4, k + 9, VetheaBlocks.lightDreamBricks);
		world.setBlock(i + 6, j + 5, k + 1, VetheaBlocks.darkDreamBricks);
		world.setBlock(i + 6, j + 5, k + 9, VetheaBlocks.darkDreamBricks);
		world.setBlock(i + 6, j + 6, k + 2, VetheaBlocks.darkDreamBricks);
		world.setBlock(i + 6, j + 6, k + 8, VetheaBlocks.darkDreamBricks);
		world.setBlock(i + 6, j + 7, k + 3, VetheaBlocks.darkDreamBricks);
		world.setBlock(i + 6, j + 7, k + 7, VetheaBlocks.darkDreamBricks);
		world.setBlock(i + 6, j + 8, k + 4, VetheaBlocks.darkDreamBricks);
		world.setBlock(i + 6, j + 8, k + 6, VetheaBlocks.darkDreamBricks);
		world.setBlock(i + 6, j + 9, k + 4, VetheaBlocks.lightDreamBricks);
		world.setBlock(i + 6, j + 9, k + 6, VetheaBlocks.lightDreamBricks);
		world.setBlock(i + 6, j + 10, k + 4, VetheaBlocks.lightDreamBricks);
		world.setBlock(i + 6, j + 10, k + 6, VetheaBlocks.lightDreamBricks);
		world.setBlock(i + 6, j + 11, k + 4, VetheaBlocks.smoothGlass);
		world.setBlock(i + 6, j + 11, k + 6, VetheaBlocks.smoothGlass);
		world.setBlock(i + 6, j + 12, k + 4, VetheaBlocks.lightDreamBricks);
		world.setBlock(i + 6, j + 12, k + 6, VetheaBlocks.lightDreamBricks);
		world.setBlock(i + 6, j + 13, k + 4, VetheaBlocks.darkDreamBricks);
		world.setBlock(i + 6, j + 13, k + 5, VetheaBlocks.lunaStone);
		world.setBlock(i + 6, j + 13, k + 6, VetheaBlocks.darkDreamBricks);
		world.setBlock(i + 7, j + 0, k + 0, VetheaBlocks.darkDreamBricks);
		world.setBlock(i + 7, j + 0, k + 1, VetheaBlocks.smoothGlass);
		world.setBlock(i + 7, j + 0, k + 2, VetheaBlocks.smoothGlass);
		world.setBlock(i + 7, j + 0, k + 3, VetheaBlocks.smoothGlass);
		world.setBlock(i + 7, j + 0, k + 4, VetheaBlocks.smoothGlass);
		world.setBlock(i + 7, j + 0, k + 5, VetheaBlocks.smoothGlass);
		world.setBlock(i + 7, j + 0, k + 6, VetheaBlocks.smoothGlass);
		world.setBlock(i + 7, j + 0, k + 7, VetheaBlocks.smoothGlass);
		world.setBlock(i + 7, j + 0, k + 8, VetheaBlocks.smoothGlass);
		world.setBlock(i + 7, j + 0, k + 9, VetheaBlocks.smoothGlass);
		world.setBlock(i + 7, j + 0, k + 10, VetheaBlocks.darkDreamBricks);
		world.setBlock(i + 7, j + 1, k + 0, VetheaBlocks.lightDreamBricks);
		world.setBlock(i + 7, j + 1, k + 10, VetheaBlocks.lightDreamBricks);
		world.setBlock(i + 7, j + 2, k + 0, VetheaBlocks.darkDreamBricks);
		world.setBlock(i + 7, j + 2, k + 10, VetheaBlocks.darkDreamBricks);
		world.setBlock(i + 7, j + 3, k + 1, VetheaBlocks.darkDreamBricks);
		world.setBlock(i + 7, j + 3, k + 9, VetheaBlocks.darkDreamBricks);
		world.setBlock(i + 7, j + 4, k + 1, VetheaBlocks.lightDreamBricks);
		world.setBlock(i + 7, j + 4, k + 9, VetheaBlocks.lightDreamBricks);
		world.setBlock(i + 7, j + 5, k + 1, VetheaBlocks.darkDreamBricks);
		world.setBlock(i + 7, j + 5, k + 9, VetheaBlocks.darkDreamBricks);
		world.setBlock(i + 7, j + 6, k + 2, VetheaBlocks.darkDreamBricks);
		world.setBlock(i + 7, j + 6, k + 8, VetheaBlocks.darkDreamBricks);
		world.setBlock(i + 7, j + 7, k + 3, VetheaBlocks.darkDreamBricks);
		world.setBlock(i + 7, j + 7, k + 7, VetheaBlocks.darkDreamBricks);
		world.setBlock(i + 7, j + 8, k + 4, VetheaBlocks.darkDreamBricks);
		world.setBlock(i + 7, j + 8, k + 6, VetheaBlocks.darkDreamBricks);
		world.setBlock(i + 7, j + 9, k + 4, VetheaBlocks.lightDreamBricks);
		world.setBlock(i + 7, j + 9, k + 6, VetheaBlocks.lightDreamBricks);
		world.setBlock(i + 7, j + 10, k + 4, VetheaBlocks.lightDreamBricks);
		world.setBlock(i + 7, j + 10, k + 6, VetheaBlocks.lightDreamBricks);
		world.setBlock(i + 7, j + 11, k + 4, VetheaBlocks.smoothGlass);
		world.setBlock(i + 7, j + 11, k + 6, VetheaBlocks.smoothGlass);
		world.setBlock(i + 7, j + 12, k + 4, VetheaBlocks.lightDreamBricks);
		world.setBlock(i + 7, j + 12, k + 6, VetheaBlocks.lightDreamBricks);
		world.setBlock(i + 7, j + 13, k + 4, VetheaBlocks.darkDreamBricks);
		world.setBlock(i + 7, j + 13, k + 5, VetheaBlocks.lunaStone);
		world.setBlock(i + 7, j + 13, k + 6, VetheaBlocks.darkDreamBricks);
		world.setBlock(i + 8, j + 0, k + 0, VetheaBlocks.darkDreamBricks);
		world.setBlock(i + 8, j + 0, k + 1, VetheaBlocks.smoothGlass);
		world.setBlock(i + 8, j + 0, k + 2, VetheaBlocks.smoothGlass);
		world.setBlock(i + 8, j + 0, k + 3, VetheaBlocks.smoothGlass);
		world.setBlock(i + 8, j + 0, k + 4, VetheaBlocks.smoothGlass);
		world.setBlock(i + 8, j + 0, k + 5, VetheaBlocks.smoothGlass);
		world.setBlock(i + 8, j + 0, k + 6, VetheaBlocks.smoothGlass);
		world.setBlock(i + 8, j + 0, k + 7, VetheaBlocks.smoothGlass);
		world.setBlock(i + 8, j + 0, k + 8, VetheaBlocks.smoothGlass);
		world.setBlock(i + 8, j + 0, k + 9, VetheaBlocks.smoothGlass);
		world.setBlock(i + 8, j + 0, k + 10, VetheaBlocks.darkDreamBricks);
		world.setBlock(i + 8, j + 1, k + 0, VetheaBlocks.lightDreamBricks);
		world.setBlock(i + 8, j + 1, k + 10, VetheaBlocks.lightDreamBricks);
		world.setBlock(i + 8, j + 2, k + 0, VetheaBlocks.darkDreamBricks);
		world.setBlock(i + 8, j + 2, k + 10, VetheaBlocks.darkDreamBricks);
		world.setBlock(i + 8, j + 3, k + 1, VetheaBlocks.darkDreamBricks);
		world.setBlock(i + 8, j + 3, k + 9, VetheaBlocks.darkDreamBricks);
		world.setBlock(i + 8, j + 4, k + 1, VetheaBlocks.lightDreamBricks);
		world.setBlock(i + 8, j + 4, k + 9, VetheaBlocks.lightDreamBricks);
		world.setBlock(i + 8, j + 5, k + 1, VetheaBlocks.darkDreamBricks);
		world.setBlock(i + 8, j + 5, k + 9, VetheaBlocks.darkDreamBricks);
		world.setBlock(i + 8, j + 6, k + 2, VetheaBlocks.darkDreamBricks);
		world.setBlock(i + 8, j + 6, k + 8, VetheaBlocks.darkDreamBricks);
		world.setBlock(i + 8, j + 7, k + 3, VetheaBlocks.darkDreamBricks);
		world.setBlock(i + 8, j + 7, k + 7, VetheaBlocks.darkDreamBricks);
		world.setBlock(i + 8, j + 8, k + 4, VetheaBlocks.darkDreamBricks);
		world.setBlock(i + 8, j + 8, k + 6, VetheaBlocks.darkDreamBricks);
		world.setBlock(i + 8, j + 9, k + 4, VetheaBlocks.lightDreamBricks);
		world.setBlock(i + 8, j + 9, k + 6, VetheaBlocks.lightDreamBricks);
		world.setBlock(i + 8, j + 10, k + 4, VetheaBlocks.lightDreamBricks);
		world.setBlock(i + 8, j + 10, k + 6, VetheaBlocks.lightDreamBricks);
		world.setBlock(i + 8, j + 11, k + 4, VetheaBlocks.smoothGlass);
		world.setBlock(i + 8, j + 11, k + 6, VetheaBlocks.smoothGlass);
		world.setBlock(i + 8, j + 12, k + 4, VetheaBlocks.lightDreamBricks);
		world.setBlock(i + 8, j + 12, k + 6, VetheaBlocks.lightDreamBricks);
		world.setBlock(i + 8, j + 13, k + 4, VetheaBlocks.darkDreamBricks);
		world.setBlock(i + 8, j + 13, k + 5, VetheaBlocks.lunaStone);
		world.setBlock(i + 8, j + 13, k + 6, VetheaBlocks.darkDreamBricks);
		world.setBlock(i + 9, j + 0, k + 0, VetheaBlocks.darkDreamBricks);
		world.setBlock(i + 9, j + 0, k + 1, VetheaBlocks.smoothGlass);
		world.setBlock(i + 9, j + 0, k + 2, VetheaBlocks.smoothGlass);
		world.setBlock(i + 9, j + 0, k + 3, VetheaBlocks.smoothGlass);
		world.setBlock(i + 9, j + 0, k + 4, VetheaBlocks.smoothGlass);
		world.setBlock(i + 9, j + 0, k + 5, VetheaBlocks.smoothGlass);
		world.setBlock(i + 9, j + 0, k + 6, VetheaBlocks.smoothGlass);
		world.setBlock(i + 9, j + 0, k + 7, VetheaBlocks.smoothGlass);
		world.setBlock(i + 9, j + 0, k + 8, VetheaBlocks.smoothGlass);
		world.setBlock(i + 9, j + 0, k + 9, VetheaBlocks.smoothGlass);
		world.setBlock(i + 9, j + 0, k + 10, VetheaBlocks.darkDreamBricks);
		world.setBlock(i + 9, j + 1, k + 0, VetheaBlocks.lightDreamBricks);
		world.setBlock(i + 9, j + 1, k + 10, VetheaBlocks.lightDreamBricks);
		world.setBlock(i + 9, j + 2, k + 0, VetheaBlocks.darkDreamBricks);
		world.setBlock(i + 9, j + 2, k + 10, VetheaBlocks.darkDreamBricks);
		world.setBlock(i + 9, j + 3, k + 1, VetheaBlocks.darkDreamBricks);
		world.setBlock(i + 9, j + 3, k + 9, VetheaBlocks.darkDreamBricks);
		world.setBlock(i + 9, j + 4, k + 1, VetheaBlocks.lightDreamBricks);
		world.setBlock(i + 9, j + 4, k + 9, VetheaBlocks.lightDreamBricks);
		world.setBlock(i + 9, j + 5, k + 1, VetheaBlocks.darkDreamBricks);
		world.setBlock(i + 9, j + 5, k + 9, VetheaBlocks.darkDreamBricks);
		world.setBlock(i + 9, j + 6, k + 2, VetheaBlocks.darkDreamBricks);
		world.setBlock(i + 9, j + 6, k + 8, VetheaBlocks.darkDreamBricks);
		world.setBlock(i + 9, j + 7, k + 3, VetheaBlocks.darkDreamBricks);
		world.setBlock(i + 9, j + 7, k + 4, VetheaBlocks.lunaStone);
		world.setBlock(i + 9, j + 7, k + 5, VetheaBlocks.lunaStone);
		world.setBlock(i + 9, j + 7, k + 6, VetheaBlocks.lunaStone);
		world.setBlock(i + 9, j + 7, k + 7, VetheaBlocks.darkDreamBricks);
		world.setBlock(i + 9, j + 8, k + 4, VetheaBlocks.darkDreamBricks);
		world.setBlock(i + 9, j + 8, k + 5, VetheaBlocks.darkDreamBricks);
		world.setBlock(i + 9, j + 8, k + 6, VetheaBlocks.darkDreamBricks);
		world.setBlock(i + 9, j + 9, k + 4, VetheaBlocks.darkDreamBricks);
		world.setBlock(i + 9, j + 9, k + 5, VetheaBlocks.lightDreamBricks);
		world.setBlock(i + 9, j + 9, k + 6, VetheaBlocks.darkDreamBricks);
		world.setBlock(i + 9, j + 10, k + 4, VetheaBlocks.darkDreamBricks);
		world.setBlock(i + 9, j + 10, k + 5, VetheaBlocks.lightDreamBricks);
		world.setBlock(i + 9, j + 10, k + 6, VetheaBlocks.darkDreamBricks);
		world.setBlock(i + 9, j + 11, k + 4, VetheaBlocks.darkDreamBricks);
		world.setBlock(i + 9, j + 11, k + 5, VetheaBlocks.smoothGlass);
		world.setBlock(i + 9, j + 11, k + 6, VetheaBlocks.darkDreamBricks);
		world.setBlock(i + 9, j + 12, k + 4, VetheaBlocks.darkDreamBricks);
		world.setBlock(i + 9, j + 12, k + 5, VetheaBlocks.lightDreamBricks);
		world.setBlock(i + 9, j + 12, k + 6, VetheaBlocks.darkDreamBricks);
		world.setBlock(i + 9, j + 13, k + 4, VetheaBlocks.darkDreamBricks);
		world.setBlock(i + 9, j + 13, k + 5, VetheaBlocks.darkDreamBricks);
		world.setBlock(i + 9, j + 13, k + 6, VetheaBlocks.darkDreamBricks);
		world.setBlock(i + 10, j + 0, k + 0, VetheaBlocks.darkDreamBricks);
		world.setBlock(i + 10, j + 0, k + 1, VetheaBlocks.smoothGlass);
		world.setBlock(i + 10, j + 0, k + 2, VetheaBlocks.smoothGlass);
		world.setBlock(i + 10, j + 0, k + 3, VetheaBlocks.smoothGlass);
		world.setBlock(i + 10, j + 0, k + 4, VetheaBlocks.smoothGlass);
		world.setBlock(i + 10, j + 0, k + 5, VetheaBlocks.smoothGlass);
		world.setBlock(i + 10, j + 0, k + 6, VetheaBlocks.smoothGlass);
		world.setBlock(i + 10, j + 0, k + 7, VetheaBlocks.smoothGlass);
		world.setBlock(i + 10, j + 0, k + 8, VetheaBlocks.smoothGlass);
		world.setBlock(i + 10, j + 0, k + 9, VetheaBlocks.smoothGlass);
		world.setBlock(i + 10, j + 0, k + 10, VetheaBlocks.darkDreamBricks);
		world.setBlock(i + 10, j + 1, k + 0, VetheaBlocks.lightDreamBricks);
		world.setBlock(i + 10, j + 1, k + 10, VetheaBlocks.lightDreamBricks);
		world.setBlock(i + 10, j + 2, k + 0, VetheaBlocks.darkDreamBricks);
		world.setBlock(i + 10, j + 2, k + 10, VetheaBlocks.darkDreamBricks);
		world.setBlock(i + 10, j + 3, k + 1, VetheaBlocks.darkDreamBricks);
		world.setBlock(i + 10, j + 3, k + 9, VetheaBlocks.darkDreamBricks);
		world.setBlock(i + 10, j + 4, k + 1, VetheaBlocks.lightDreamBricks);
		world.setBlock(i + 10, j + 4, k + 9, VetheaBlocks.lightDreamBricks);
		world.setBlock(i + 10, j + 5, k + 1, VetheaBlocks.darkDreamBricks);
		world.setBlock(i + 10, j + 5, k + 9, VetheaBlocks.darkDreamBricks);
		world.setBlock(i + 10, j + 6, k + 2, VetheaBlocks.darkDreamBricks);
		world.setBlock(i + 10, j + 6, k + 8, VetheaBlocks.darkDreamBricks);
		world.setBlock(i + 10, j + 7, k + 3, VetheaBlocks.darkDreamBricks);
		world.setBlock(i + 10, j + 7, k + 4, VetheaBlocks.darkDreamBricks);
		world.setBlock(i + 10, j + 7, k + 5, VetheaBlocks.darkDreamBricks);
		world.setBlock(i + 10, j + 7, k + 6, VetheaBlocks.darkDreamBricks);
		world.setBlock(i + 10, j + 7, k + 7, VetheaBlocks.darkDreamBricks);
		world.setBlock(i + 11, j + 0, k + 0, VetheaBlocks.darkDreamBricks);
		world.setBlock(i + 11, j + 0, k + 1, VetheaBlocks.smoothGlass);
		world.setBlock(i + 11, j + 0, k + 2, VetheaBlocks.smoothGlass);
		world.setBlock(i + 11, j + 0, k + 3, VetheaBlocks.smoothGlass);
		world.setBlock(i + 11, j + 0, k + 4, VetheaBlocks.smoothGlass);
		world.setBlock(i + 11, j + 0, k + 5, VetheaBlocks.smoothGlass);
		world.setBlock(i + 11, j + 0, k + 6, VetheaBlocks.smoothGlass);
		world.setBlock(i + 11, j + 0, k + 7, VetheaBlocks.smoothGlass);
		world.setBlock(i + 11, j + 0, k + 8, VetheaBlocks.smoothGlass);
		world.setBlock(i + 11, j + 0, k + 9, VetheaBlocks.smoothGlass);
		world.setBlock(i + 11, j + 0, k + 10, VetheaBlocks.darkDreamBricks);
		world.setBlock(i + 11, j + 1, k + 0, VetheaBlocks.lightDreamBricks);
		world.setBlock(i + 11, j + 1, k + 10, VetheaBlocks.lightDreamBricks);
		world.setBlock(i + 11, j + 2, k + 0, VetheaBlocks.darkDreamBricks);
		world.setBlock(i + 11, j + 2, k + 10, VetheaBlocks.darkDreamBricks);
		world.setBlock(i + 11, j + 3, k + 1, VetheaBlocks.darkDreamBricks);
		world.setBlock(i + 11, j + 3, k + 9, VetheaBlocks.darkDreamBricks);
		world.setBlock(i + 11, j + 4, k + 1, VetheaBlocks.lightDreamBricks);
		world.setBlock(i + 11, j + 4, k + 9, VetheaBlocks.lightDreamBricks);
		world.setBlock(i + 11, j + 5, k + 1, VetheaBlocks.darkDreamBricks);
		world.setBlock(i + 11, j + 5, k + 9, VetheaBlocks.darkDreamBricks);
		world.setBlock(i + 11, j + 6, k + 2, VetheaBlocks.darkDreamBricks);
		world.setBlock(i + 11, j + 6, k + 3, VetheaBlocks.darkDreamBricks);
		world.setBlock(i + 11, j + 6, k + 4, VetheaBlocks.darkDreamBricks);
		world.setBlock(i + 11, j + 6, k + 5, VetheaBlocks.darkDreamBricks);
		world.setBlock(i + 11, j + 6, k + 6, VetheaBlocks.darkDreamBricks);
		world.setBlock(i + 11, j + 6, k + 7, VetheaBlocks.darkDreamBricks);
		world.setBlock(i + 11, j + 6, k + 8, VetheaBlocks.darkDreamBricks);
		world.setBlock(i + 12, j + 0, k + 0, VetheaBlocks.darkDreamBricks);
		world.setBlock(i + 12, j + 0, k + 1, VetheaBlocks.smoothGlass);
		world.setBlock(i + 12, j + 0, k + 2, VetheaBlocks.smoothGlass);
		world.setBlock(i + 12, j + 0, k + 3, VetheaBlocks.smoothGlass);
		world.setBlock(i + 12, j + 0, k + 4, VetheaBlocks.smoothGlass);
		world.setBlock(i + 12, j + 0, k + 5, VetheaBlocks.smoothGlass);
		world.setBlock(i + 12, j + 0, k + 6, VetheaBlocks.smoothGlass);
		world.setBlock(i + 12, j + 0, k + 7, VetheaBlocks.smoothGlass);
		world.setBlock(i + 12, j + 0, k + 8, VetheaBlocks.smoothGlass);
		world.setBlock(i + 12, j + 0, k + 9, VetheaBlocks.smoothGlass);
		world.setBlock(i + 12, j + 0, k + 10, VetheaBlocks.darkDreamBricks);
		world.setBlock(i + 12, j + 1, k + 0, VetheaBlocks.lightDreamBricks);
		world.setBlock(i + 12, j + 1, k + 1, VetheaBlocks.firelight);
		world.setBlock(i + 12, j + 1, k + 9, VetheaBlocks.firelight);
		world.setBlock(i + 12, j + 1, k + 10, VetheaBlocks.lightDreamBricks);
		world.setBlock(i + 12, j + 2, k + 0, VetheaBlocks.darkDreamBricks);
		world.setBlock(i + 12, j + 2, k + 10, VetheaBlocks.darkDreamBricks);
		world.setBlock(i + 12, j + 3, k + 1, VetheaBlocks.darkDreamBricks);
		world.setBlock(i + 12, j + 3, k + 2, VetheaBlocks.darkDreamBricks);
		world.setBlock(i + 12, j + 3, k + 3, VetheaBlocks.darkDreamBricks);
		world.setBlock(i + 12, j + 3, k + 4, VetheaBlocks.darkDreamBricks);
		world.setBlock(i + 12, j + 3, k + 5, VetheaBlocks.darkDreamBricks);
		world.setBlock(i + 12, j + 3, k + 6, VetheaBlocks.darkDreamBricks);
		world.setBlock(i + 12, j + 3, k + 7, VetheaBlocks.darkDreamBricks);
		world.setBlock(i + 12, j + 3, k + 8, VetheaBlocks.darkDreamBricks);
		world.setBlock(i + 12, j + 3, k + 9, VetheaBlocks.darkDreamBricks);
		world.setBlock(i + 12, j + 4, k + 1, VetheaBlocks.darkDreamBricks);
		world.setBlock(i + 12, j + 4, k + 2, VetheaBlocks.lightDreamBricks);
		world.setBlock(i + 12, j + 4, k + 3, VetheaBlocks.lightDreamBricks);
		world.setBlock(i + 12, j + 4, k + 4, VetheaBlocks.lightDreamBricks);
		world.setBlock(i + 12, j + 4, k + 5, VetheaBlocks.lightDreamBricks);
		world.setBlock(i + 12, j + 4, k + 6, VetheaBlocks.lightDreamBricks);
		world.setBlock(i + 12, j + 4, k + 7, VetheaBlocks.lightDreamBricks);
		world.setBlock(i + 12, j + 4, k + 8, VetheaBlocks.lightDreamBricks);
		world.setBlock(i + 12, j + 4, k + 9, VetheaBlocks.darkDreamBricks);
		world.setBlock(i + 12, j + 5, k + 1, VetheaBlocks.darkDreamBricks);
		world.setBlock(i + 12, j + 5, k + 2, VetheaBlocks.darkDreamBricks);
		world.setBlock(i + 12, j + 5, k + 3, VetheaBlocks.darkDreamBricks);
		world.setBlock(i + 12, j + 5, k + 4, VetheaBlocks.darkDreamBricks);
		world.setBlock(i + 12, j + 5, k + 5, VetheaBlocks.darkDreamBricks);
		world.setBlock(i + 12, j + 5, k + 6, VetheaBlocks.darkDreamBricks);
		world.setBlock(i + 12, j + 5, k + 7, VetheaBlocks.darkDreamBricks);
		world.setBlock(i + 12, j + 5, k + 8, VetheaBlocks.darkDreamBricks);
		world.setBlock(i + 12, j + 5, k + 9, VetheaBlocks.darkDreamBricks);
		world.setBlock(i + 13, j + 0, k + 0, VetheaBlocks.darkDreamBricks);
		world.setBlock(i + 13, j + 0, k + 1, VetheaBlocks.darkDreamBricks);
		world.setBlock(i + 13, j + 0, k + 2, VetheaBlocks.darkDreamBricks);
		world.setBlock(i + 13, j + 0, k + 3, VetheaBlocks.darkDreamBricks);
		world.setBlock(i + 13, j + 0, k + 4, VetheaBlocks.darkDreamBricks);
		world.setBlock(i + 13, j + 0, k + 5, VetheaBlocks.darkDreamBricks);
		world.setBlock(i + 13, j + 0, k + 6, VetheaBlocks.darkDreamBricks);
		world.setBlock(i + 13, j + 0, k + 7, VetheaBlocks.darkDreamBricks);
		world.setBlock(i + 13, j + 0, k + 8, VetheaBlocks.darkDreamBricks);
		world.setBlock(i + 13, j + 0, k + 9, VetheaBlocks.darkDreamBricks);
		world.setBlock(i + 13, j + 0, k + 10, VetheaBlocks.darkDreamBricks);
		world.setBlock(i + 13, j + 1, k + 0, VetheaBlocks.darkDreamBricks);
		world.setBlock(i + 13, j + 1, k + 1, VetheaBlocks.lightDreamBricks);
		world.setBlock(i + 13, j + 1, k + 2, VetheaBlocks.lightDreamBricks);
		world.setBlock(i + 13, j + 1, k + 3, VetheaBlocks.lightDreamBricks);
		world.setBlock(i + 13, j + 1, k + 4, VetheaBlocks.lightDreamBricks);
		world.setBlock(i + 13, j + 1, k + 5, VetheaBlocks.lightDreamBricks);
		world.setBlock(i + 13, j + 1, k + 6, VetheaBlocks.lightDreamBricks);
		world.setBlock(i + 13, j + 1, k + 7, VetheaBlocks.lightDreamBricks);
		world.setBlock(i + 13, j + 1, k + 8, VetheaBlocks.lightDreamBricks);
		world.setBlock(i + 13, j + 1, k + 9, VetheaBlocks.lightDreamBricks);
		world.setBlock(i + 13, j + 1, k + 10, VetheaBlocks.darkDreamBricks);
		world.setBlock(i + 13, j + 2, k + 0, VetheaBlocks.darkDreamBricks);
		world.setBlock(i + 13, j + 2, k + 1, VetheaBlocks.darkDreamBricks);
		world.setBlock(i + 13, j + 2, k + 2, VetheaBlocks.darkDreamBricks);
		world.setBlock(i + 13, j + 2, k + 3, VetheaBlocks.darkDreamBricks);
		world.setBlock(i + 13, j + 2, k + 4, VetheaBlocks.darkDreamBricks);
		world.setBlock(i + 13, j + 2, k + 5, VetheaBlocks.darkDreamBricks);
		world.setBlock(i + 13, j + 2, k + 6, VetheaBlocks.darkDreamBricks);
		world.setBlock(i + 13, j + 2, k + 7, VetheaBlocks.darkDreamBricks);
		world.setBlock(i + 13, j + 2, k + 8, VetheaBlocks.darkDreamBricks);
		world.setBlock(i + 13, j + 2, k + 9, VetheaBlocks.darkDreamBricks);
		world.setBlock(i + 13, j + 2, k + 10, VetheaBlocks.darkDreamBricks);

		return true;
	}
}