/*
*** MADE BY MITHION'S .SCHEMATIC TO JAVA CONVERTING TOOL v1.6 ***
*/

package net.divinerpg.dimensions.vethea.village;
import java.util.Random;

import net.divinerpg.utils.blocks.VetheaBlocks;
import net.minecraft.world.World;
import net.minecraft.world.gen.feature.WorldGenerator;

public class HouseUp5 extends WorldGenerator
{
	protected int[] GetValidSpawnBlocks() {
		return new int[] {
		};
	}

	public HouseUp5() { }

	public boolean generate(World world, Random rand, int i, int j, int k) {

		world.setBlock(i + 0, j + 0, k + 0, VetheaBlocks.darkDreamBricks);
		world.setBlock(i + 0, j + 0, k + 1, VetheaBlocks.darkDreamBricks);
		world.setBlock(i + 0, j + 0, k + 5, VetheaBlocks.darkDreamBricks);
		world.setBlock(i + 0, j + 0, k + 15, VetheaBlocks.darkDreamBricks);
		world.setBlock(i + 0, j + 1, k + 1, VetheaBlocks.darkDreamBricks);
		world.setBlock(i + 0, j + 1, k + 2, VetheaBlocks.darkDreamBricks);
		world.setBlock(i + 0, j + 2, k + 1, VetheaBlocks.darkDreamBricks);
		world.setBlock(i + 0, j + 2, k + 2, VetheaBlocks.darkDreamBricks);
		world.setBlock(i + 0, j + 3, k + 0, VetheaBlocks.darkDreamBricks);
		world.setBlock(i + 0, j + 3, k + 5, VetheaBlocks.darkDreamBricks);
		world.setBlock(i + 0, j + 3, k + 15, VetheaBlocks.darkDreamBricks);
		world.setBlock(i + 1, j + 0, k + 1, VetheaBlocks.darkDreamBricks);
		world.setBlock(i + 1, j + 0, k + 2, VetheaBlocks.darkDreamBricks);
		world.setBlock(i + 1, j + 0, k + 5, VetheaBlocks.darkDreamBricks);
		world.setBlock(i + 1, j + 0, k + 15, VetheaBlocks.darkDreamBricks);
		world.setBlock(i + 1, j + 1, k + 2, VetheaBlocks.darkDreamBricks);
		world.setBlock(i + 1, j + 1, k + 3, VetheaBlocks.darkDreamBricks);
		world.setBlock(i + 1, j + 1, k + 6, VetheaBlocks.darkDreamBricks);
		world.setBlock(i + 1, j + 1, k + 7, VetheaBlocks.darkDreamBricks);
		world.setBlock(i + 1, j + 1, k + 8, VetheaBlocks.darkDreamBricks);
		world.setBlock(i + 1, j + 1, k + 9, VetheaBlocks.darkDreamBricks);
		world.setBlock(i + 1, j + 1, k + 10, VetheaBlocks.darkDreamBricks);
		world.setBlock(i + 1, j + 1, k + 11, VetheaBlocks.darkDreamBricks);
		world.setBlock(i + 1, j + 1, k + 12, VetheaBlocks.darkDreamBricks);
		world.setBlock(i + 1, j + 1, k + 13, VetheaBlocks.darkDreamBricks);
		world.setBlock(i + 1, j + 1, k + 14, VetheaBlocks.darkDreamBricks);
		world.setBlock(i + 1, j + 2, k + 2, VetheaBlocks.darkDreamBricks);
		world.setBlock(i + 1, j + 2, k + 3, VetheaBlocks.darkDreamBricks);
		world.setBlock(i + 1, j + 2, k + 6, VetheaBlocks.darkDreamBricks);
		world.setBlock(i + 1, j + 2, k + 7, VetheaBlocks.darkDreamBricks);
		world.setBlock(i + 1, j + 2, k + 8, VetheaBlocks.darkDreamBricks);
		world.setBlock(i + 1, j + 2, k + 9, VetheaBlocks.darkDreamBricks);
		world.setBlock(i + 1, j + 2, k + 10, VetheaBlocks.darkDreamBricks);
		world.setBlock(i + 1, j + 2, k + 11, VetheaBlocks.darkDreamBricks);
		world.setBlock(i + 1, j + 2, k + 12, VetheaBlocks.darkDreamBricks);
		world.setBlock(i + 1, j + 2, k + 13, VetheaBlocks.darkDreamBricks);
		world.setBlock(i + 1, j + 2, k + 14, VetheaBlocks.darkDreamBricks);
		world.setBlock(i + 1, j + 3, k + 0, VetheaBlocks.darkDreamBricks);
		world.setBlock(i + 1, j + 3, k + 1, VetheaBlocks.darkDreamBricks);
		world.setBlock(i + 1, j + 3, k + 5, VetheaBlocks.darkDreamBricks);
		world.setBlock(i + 1, j + 3, k + 15, VetheaBlocks.darkDreamBricks);
		world.setBlock(i + 2, j + 0, k + 2, VetheaBlocks.darkDreamBricks);
		world.setBlock(i + 2, j + 0, k + 3, VetheaBlocks.darkDreamBricks);
		world.setBlock(i + 2, j + 0, k + 5, VetheaBlocks.darkDreamBricks);
		world.setBlock(i + 2, j + 0, k + 6, VetheaBlocks.darkDreamBricks);
		world.setBlock(i + 2, j + 0, k + 7, VetheaBlocks.darkDreamBricks);
		world.setBlock(i + 2, j + 0, k + 8, VetheaBlocks.darkDreamBricks);
		world.setBlock(i + 2, j + 0, k + 9, VetheaBlocks.darkDreamBricks);
		world.setBlock(i + 2, j + 0, k + 10, VetheaBlocks.darkDreamBricks);
		world.setBlock(i + 2, j + 0, k + 11, VetheaBlocks.darkDreamBricks);
		world.setBlock(i + 2, j + 0, k + 12, VetheaBlocks.darkDreamBricks);
		world.setBlock(i + 2, j + 0, k + 13, VetheaBlocks.darkDreamBricks);
		world.setBlock(i + 2, j + 0, k + 14, VetheaBlocks.darkDreamBricks);
		world.setBlock(i + 2, j + 0, k + 15, VetheaBlocks.darkDreamBricks);
		world.setBlock(i + 2, j + 1, k + 3, VetheaBlocks.darkDreamBricks);
		world.setBlock(i + 2, j + 1, k + 4, VetheaBlocks.darkDreamBricks);
		world.setBlock(i + 2, j + 1, k + 5, VetheaBlocks.darkDreamBricks);
		world.setBlock(i + 2, j + 1, k + 6, VetheaBlocks.lunaStone);
		world.setBlock(i + 2, j + 1, k + 7, VetheaBlocks.lunaStone);
		world.setBlock(i + 2, j + 1, k + 8, VetheaBlocks.lunaStone);
		world.setBlock(i + 2, j + 1, k + 9, VetheaBlocks.lunaStone);
		world.setBlock(i + 2, j + 1, k + 10, VetheaBlocks.lunaStone);
		world.setBlock(i + 2, j + 1, k + 11, VetheaBlocks.lunaStone);
		world.setBlock(i + 2, j + 1, k + 12, VetheaBlocks.lunaStone);
		world.setBlock(i + 2, j + 1, k + 13, VetheaBlocks.lunaStone);
		world.setBlock(i + 2, j + 1, k + 14, VetheaBlocks.lunaStone);
		world.setBlock(i + 2, j + 1, k + 15, VetheaBlocks.darkDreamBricks);
		world.setBlock(i + 2, j + 2, k + 3, VetheaBlocks.darkDreamBricks);
		world.setBlock(i + 2, j + 2, k + 4, VetheaBlocks.darkDreamBricks);
		world.setBlock(i + 2, j + 2, k + 5, VetheaBlocks.darkDreamBricks);
		world.setBlock(i + 2, j + 2, k + 6, VetheaBlocks.lunaStone);
		world.setBlock(i + 2, j + 2, k + 7, VetheaBlocks.lunaStone);
		world.setBlock(i + 2, j + 2, k + 8, VetheaBlocks.lunaStone);
		world.setBlock(i + 2, j + 2, k + 9, VetheaBlocks.lunaStone);
		world.setBlock(i + 2, j + 2, k + 10, VetheaBlocks.lunaStone);
		world.setBlock(i + 2, j + 2, k + 11, VetheaBlocks.lunaStone);
		world.setBlock(i + 2, j + 2, k + 12, VetheaBlocks.lunaStone);
		world.setBlock(i + 2, j + 2, k + 13, VetheaBlocks.lunaStone);
		world.setBlock(i + 2, j + 2, k + 14, VetheaBlocks.lunaStone);
		world.setBlock(i + 2, j + 2, k + 15, VetheaBlocks.darkDreamBricks);
		world.setBlock(i + 2, j + 3, k + 1, VetheaBlocks.darkDreamBricks);
		world.setBlock(i + 2, j + 3, k + 2, VetheaBlocks.darkDreamBricks);
		world.setBlock(i + 2, j + 3, k + 5, VetheaBlocks.darkDreamBricks);
		world.setBlock(i + 2, j + 3, k + 6, VetheaBlocks.darkDreamBricks);
		world.setBlock(i + 2, j + 3, k + 7, VetheaBlocks.darkDreamBricks);
		world.setBlock(i + 2, j + 3, k + 8, VetheaBlocks.darkDreamBricks);
		world.setBlock(i + 2, j + 3, k + 9, VetheaBlocks.darkDreamBricks);
		world.setBlock(i + 2, j + 3, k + 10, VetheaBlocks.darkDreamBricks);
		world.setBlock(i + 2, j + 3, k + 11, VetheaBlocks.darkDreamBricks);
		world.setBlock(i + 2, j + 3, k + 12, VetheaBlocks.darkDreamBricks);
		world.setBlock(i + 2, j + 3, k + 13, VetheaBlocks.darkDreamBricks);
		world.setBlock(i + 2, j + 3, k + 14, VetheaBlocks.darkDreamBricks);
		world.setBlock(i + 2, j + 3, k + 15, VetheaBlocks.darkDreamBricks);
		world.setBlock(i + 3, j + 0, k + 3, VetheaBlocks.darkDreamBricks);
		world.setBlock(i + 3, j + 0, k + 4, VetheaBlocks.darkDreamBricks);
		world.setBlock(i + 3, j + 0, k + 5, VetheaBlocks.darkDreamBricks);
		world.setBlock(i + 3, j + 0, k + 6,  VetheaBlocks.smoothGlass);
		world.setBlock(i + 3, j + 0, k + 7,  VetheaBlocks.smoothGlass);
		world.setBlock(i + 3, j + 0, k + 8,  VetheaBlocks.smoothGlass);
		world.setBlock(i + 3, j + 0, k + 9,  VetheaBlocks.smoothGlass);
		world.setBlock(i + 3, j + 0, k + 10,  VetheaBlocks.smoothGlass);
		world.setBlock(i + 3, j + 0, k + 11,  VetheaBlocks.smoothGlass);
		world.setBlock(i + 3, j + 0, k + 12,  VetheaBlocks.smoothGlass);
		world.setBlock(i + 3, j + 0, k + 13,  VetheaBlocks.smoothGlass);
		world.setBlock(i + 3, j + 0, k + 14,  VetheaBlocks.smoothGlass);
		world.setBlock(i + 3, j + 0, k + 15, VetheaBlocks.darkDreamBricks);
		world.setBlock(i + 3, j + 1, k + 15, VetheaBlocks.darkDreamBricks);
		world.setBlock(i + 3, j + 2, k + 15, VetheaBlocks.darkDreamBricks);
		world.setBlock(i + 3, j + 3, k + 2, VetheaBlocks.darkDreamBricks);
		world.setBlock(i + 3, j + 3, k + 3, VetheaBlocks.darkDreamBricks);
		world.setBlock(i + 3, j + 3, k + 4, VetheaBlocks.darkDreamBricks);
		world.setBlock(i + 3, j + 3, k + 5, VetheaBlocks.darkDreamBricks);
		world.setBlock(i + 3, j + 3, k + 6,  VetheaBlocks.smoothGlass);
		world.setBlock(i + 3, j + 3, k + 7,  VetheaBlocks.smoothGlass);
		world.setBlock(i + 3, j + 3, k + 8,  VetheaBlocks.smoothGlass);
		world.setBlock(i + 3, j + 3, k + 9,  VetheaBlocks.smoothGlass);
		world.setBlock(i + 3, j + 3, k + 10,  VetheaBlocks.smoothGlass);
		world.setBlock(i + 3, j + 3, k + 11,  VetheaBlocks.smoothGlass);
		world.setBlock(i + 3, j + 3, k + 12,  VetheaBlocks.smoothGlass);
		world.setBlock(i + 3, j + 3, k + 13,  VetheaBlocks.smoothGlass);
		world.setBlock(i + 3, j + 3, k + 14,  VetheaBlocks.smoothGlass);
		world.setBlock(i + 3, j + 3, k + 15, VetheaBlocks.darkDreamBricks);
		world.setBlock(i + 4, j + 0, k + 5, VetheaBlocks.darkDreamBricks);
		world.setBlock(i + 4, j + 0, k + 6,  VetheaBlocks.smoothGlass);
		world.setBlock(i + 4, j + 0, k + 7,  VetheaBlocks.smoothGlass);
		world.setBlock(i + 4, j + 0, k + 8,  VetheaBlocks.smoothGlass);
		world.setBlock(i + 4, j + 0, k + 9,  VetheaBlocks.smoothGlass);
		world.setBlock(i + 4, j + 0, k + 10,  VetheaBlocks.smoothGlass);
		world.setBlock(i + 4, j + 0, k + 11,  VetheaBlocks.smoothGlass);
		world.setBlock(i + 4, j + 0, k + 12,  VetheaBlocks.smoothGlass);
		world.setBlock(i + 4, j + 0, k + 13,  VetheaBlocks.smoothGlass);
		world.setBlock(i + 4, j + 0, k + 14,  VetheaBlocks.smoothGlass);
		world.setBlock(i + 4, j + 0, k + 15, VetheaBlocks.darkDreamBricks);
		world.setBlock(i + 4, j + 1, k + 15,  VetheaBlocks.smoothGlass);
		world.setBlock(i + 4, j + 2, k + 15,  VetheaBlocks.smoothGlass);
		world.setBlock(i + 4, j + 3, k + 5, VetheaBlocks.darkDreamBricks);
		world.setBlock(i + 4, j + 3, k + 6,  VetheaBlocks.smoothGlass);
		world.setBlock(i + 4, j + 3, k + 7,  VetheaBlocks.smoothGlass);
		world.setBlock(i + 4, j + 3, k + 8,  VetheaBlocks.smoothGlass);
		world.setBlock(i + 4, j + 3, k + 9,  VetheaBlocks.smoothGlass);
		world.setBlock(i + 4, j + 3, k + 10,  VetheaBlocks.smoothGlass);
		world.setBlock(i + 4, j + 3, k + 11,  VetheaBlocks.smoothGlass);
		world.setBlock(i + 4, j + 3, k + 12,  VetheaBlocks.smoothGlass);
		world.setBlock(i + 4, j + 3, k + 13,  VetheaBlocks.smoothGlass);
		world.setBlock(i + 4, j + 3, k + 14,  VetheaBlocks.smoothGlass);
		world.setBlock(i + 4, j + 3, k + 15, VetheaBlocks.darkDreamBricks);
		world.setBlock(i + 5, j + 0, k + 5, VetheaBlocks.darkDreamBricks);
		world.setBlock(i + 5, j + 0, k + 6, VetheaBlocks.darkDreamBricks);
		world.setBlock(i + 5, j + 0, k + 7, VetheaBlocks.darkDreamBricks);
		world.setBlock(i + 5, j + 0, k + 8, VetheaBlocks.darkDreamBricks);
		world.setBlock(i + 5, j + 0, k + 9, VetheaBlocks.darkDreamBricks);
		world.setBlock(i + 5, j + 0, k + 10, VetheaBlocks.darkDreamBricks);
		world.setBlock(i + 5, j + 0, k + 11, VetheaBlocks.darkDreamBricks);
		world.setBlock(i + 5, j + 0, k + 12, VetheaBlocks.darkDreamBricks);
		world.setBlock(i + 5, j + 0, k + 13, VetheaBlocks.darkDreamBricks);
		world.setBlock(i + 5, j + 0, k + 14, VetheaBlocks.darkDreamBricks);
		world.setBlock(i + 5, j + 0, k + 15, VetheaBlocks.darkDreamBricks);
		world.setBlock(i + 5, j + 1, k + 5, VetheaBlocks.darkDreamBricks);
		world.setBlock(i + 5, j + 1, k + 15, VetheaBlocks.darkDreamBricks);
		world.setBlock(i + 5, j + 2, k + 5, VetheaBlocks.darkDreamBricks);
		world.setBlock(i + 5, j + 2, k + 6, VetheaBlocks.firelight);
		world.setBlock(i + 5, j + 2, k + 14, VetheaBlocks.firelight);
		world.setBlock(i + 5, j + 2, k + 15, VetheaBlocks.darkDreamBricks);
		world.setBlock(i + 5, j + 3, k + 5, VetheaBlocks.darkDreamBricks);
		world.setBlock(i + 5, j + 3, k + 6, VetheaBlocks.darkDreamBricks);
		world.setBlock(i + 5, j + 3, k + 7, VetheaBlocks.darkDreamBricks);
		world.setBlock(i + 5, j + 3, k + 8, VetheaBlocks.darkDreamBricks);
		world.setBlock(i + 5, j + 3, k + 9, VetheaBlocks.darkDreamBricks);
		world.setBlock(i + 5, j + 3, k + 10, VetheaBlocks.darkDreamBricks);
		world.setBlock(i + 5, j + 3, k + 11, VetheaBlocks.darkDreamBricks);
		world.setBlock(i + 5, j + 3, k + 12, VetheaBlocks.darkDreamBricks);
		world.setBlock(i + 5, j + 3, k + 13, VetheaBlocks.darkDreamBricks);
		world.setBlock(i + 5, j + 3, k + 14, VetheaBlocks.darkDreamBricks);
		world.setBlock(i + 5, j + 3, k + 15, VetheaBlocks.darkDreamBricks);
		world.setBlock(i + 6, j + 1, k + 5, VetheaBlocks.darkDreamBricks);
		world.setBlock(i + 6, j + 1, k + 6, VetheaBlocks.darkDreamBricks);
		world.setBlock(i + 6, j + 1, k + 7, VetheaBlocks.darkDreamBricks);
		world.setBlock(i + 6, j + 1, k + 8, VetheaBlocks.darkDreamBricks);
		world.setBlock(i + 6, j + 1, k + 9, VetheaBlocks.darkDreamBricks);
		world.setBlock(i + 6, j + 1, k + 10, VetheaBlocks.darkDreamBricks);
		world.setBlock(i + 6, j + 1, k + 11, VetheaBlocks.darkDreamBricks);
		world.setBlock(i + 6, j + 1, k + 12, VetheaBlocks.darkDreamBricks);
		world.setBlock(i + 6, j + 1, k + 13, VetheaBlocks.darkDreamBricks);
		world.setBlock(i + 6, j + 1, k + 14, VetheaBlocks.darkDreamBricks);
		world.setBlock(i + 6, j + 1, k + 15, VetheaBlocks.darkDreamBricks);
		world.setBlock(i + 6, j + 2, k + 5, VetheaBlocks.darkDreamBricks);
		world.setBlock(i + 6, j + 2, k + 6, VetheaBlocks.darkDreamBricks);
		world.setBlock(i + 6, j + 2, k + 7, VetheaBlocks.darkDreamBricks);
		world.setBlock(i + 6, j + 2, k + 8, VetheaBlocks.darkDreamBricks);
		world.setBlock(i + 6, j + 2, k + 9, VetheaBlocks.darkDreamBricks);
		world.setBlock(i + 6, j + 2, k + 10, VetheaBlocks.darkDreamBricks);
		world.setBlock(i + 6, j + 2, k + 11, VetheaBlocks.darkDreamBricks);
		world.setBlock(i + 6, j + 2, k + 12, VetheaBlocks.darkDreamBricks);
		world.setBlock(i + 6, j + 2, k + 13, VetheaBlocks.darkDreamBricks);
		world.setBlock(i + 6, j + 2, k + 14, VetheaBlocks.darkDreamBricks);
		world.setBlock(i + 6, j + 2, k + 15, VetheaBlocks.darkDreamBricks);

		return true;
	}
}