/*
*** MADE BY MITHION'S .SCHEMATIC TO JAVA CONVERTING TOOL v1.6 ***
*/

package net.divinerpg.dimensions.vethea.village;
import java.util.Random;

import net.divinerpg.utils.blocks.VetheaBlocks;
import net.minecraft.world.World;
import net.minecraft.world.gen.feature.WorldGenerator;

public class HouseDown3 extends WorldGenerator
{
	protected int[] GetValidSpawnBlocks() {
		return new int[] {
		};
	}

	public HouseDown3() { }

	public boolean generate(World world, Random rand, int i, int j, int k) {

		world.setBlock(i + 0, j + 4, k + 1, VetheaBlocks.darkDreamBricks);
		world.setBlock(i + 0, j + 4, k + 6, VetheaBlocks.darkDreamBricks);
		world.setBlock(i + 0, j + 5, k + 1, VetheaBlocks.darkDreamBricks);
		world.setBlock(i + 0, j + 5, k + 2, VetheaBlocks.darkDreamBricks);
		world.setBlock(i + 0, j + 5, k + 3, VetheaBlocks.darkDreamBricks);
		world.setBlock(i + 0, j + 5, k + 4, VetheaBlocks.darkDreamBricks);
		world.setBlock(i + 0, j + 5, k + 5, VetheaBlocks.darkDreamBricks);
		world.setBlock(i + 0, j + 5, k + 6, VetheaBlocks.darkDreamBricks);
		world.setBlock(i + 1, j + 4, k + 1, VetheaBlocks.smoothGlass);
		world.setBlock(i + 1, j + 4, k + 6, VetheaBlocks.smoothGlass);
		world.setBlock(i + 1, j + 5, k + 1, VetheaBlocks.darkDreamBricks);
		world.setBlock(i + 1, j + 5, k + 2, VetheaBlocks.darkDreamBricks);
		world.setBlock(i + 1, j + 5, k + 3, VetheaBlocks.darkDreamBricks);
		world.setBlock(i + 1, j + 5, k + 4, VetheaBlocks.darkDreamBricks);
		world.setBlock(i + 1, j + 5, k + 5, VetheaBlocks.darkDreamBricks);
		world.setBlock(i + 1, j + 5, k + 6, VetheaBlocks.darkDreamBricks);
		world.setBlock(i + 2, j + 4, k + 1, VetheaBlocks.darkDreamBricks);
		world.setBlock(i + 2, j + 4, k + 6, VetheaBlocks.darkDreamBricks);
		world.setBlock(i + 2, j + 5, k + 1, VetheaBlocks.darkDreamBricks);
		world.setBlock(i + 2, j + 5, k + 2, VetheaBlocks.darkDreamBricks);
		world.setBlock(i + 2, j + 5, k + 3, VetheaBlocks.darkDreamBricks);
		world.setBlock(i + 2, j + 5, k + 4, VetheaBlocks.darkDreamBricks);
		world.setBlock(i + 2, j + 5, k + 5, VetheaBlocks.darkDreamBricks);
		world.setBlock(i + 2, j + 5, k + 6, VetheaBlocks.darkDreamBricks);
		world.setBlock(i + 3, j + 0, k + 2, VetheaBlocks.darkDreamBricks);
		world.setBlock(i + 3, j + 0, k + 3, VetheaBlocks.darkDreamBricks);
		world.setBlock(i + 3, j + 0, k + 4, VetheaBlocks.darkDreamBricks);
		world.setBlock(i + 3, j + 0, k + 5, VetheaBlocks.darkDreamBricks);
		world.setBlock(i + 3, j + 1, k + 2, VetheaBlocks.darkDreamBricks);
		world.setBlock(i + 3, j + 1, k + 3, VetheaBlocks.lightDreamBricks);
		world.setBlock(i + 3, j + 1, k + 4, VetheaBlocks.lightDreamBricks);
		world.setBlock(i + 3, j + 1, k + 5, VetheaBlocks.darkDreamBricks);
		world.setBlock(i + 3, j + 2, k + 1, VetheaBlocks.darkDreamBricks);
		world.setBlock(i + 3, j + 2, k + 2, VetheaBlocks.darkDreamBricks);
		world.setBlock(i + 3, j + 2, k + 3, VetheaBlocks.smoothGlass);
		world.setBlock(i + 3, j + 2, k + 4, VetheaBlocks.smoothGlass);
		world.setBlock(i + 3, j + 2, k + 5, VetheaBlocks.darkDreamBricks);
		world.setBlock(i + 3, j + 2, k + 6, VetheaBlocks.darkDreamBricks);
		world.setBlock(i + 3, j + 3, k + 0, VetheaBlocks.darkDreamBricks);
		world.setBlock(i + 3, j + 3, k + 1, VetheaBlocks.darkDreamBricks);
		world.setBlock(i + 3, j + 3, k + 3, VetheaBlocks.lightDreamBricks);
		world.setBlock(i + 3, j + 3, k + 4, VetheaBlocks.lightDreamBricks);
		world.setBlock(i + 3, j + 3, k + 6, VetheaBlocks.darkDreamBricks);
		world.setBlock(i + 3, j + 3, k + 7, VetheaBlocks.darkDreamBricks);
		world.setBlock(i + 3, j + 4, k + 0, VetheaBlocks.darkDreamBricks);
		world.setBlock(i + 3, j + 4, k + 1, VetheaBlocks.darkDreamBricks);
		world.setBlock(i + 3, j + 4, k + 3, VetheaBlocks.darkDreamBricks);
		world.setBlock(i + 3, j + 4, k + 4, VetheaBlocks.darkDreamBricks);
		world.setBlock(i + 3, j + 4, k + 6, VetheaBlocks.darkDreamBricks);
		world.setBlock(i + 3, j + 4, k + 7, VetheaBlocks.darkDreamBricks);
		world.setBlock(i + 3, j + 5, k + 0, VetheaBlocks.darkDreamBricks);
		world.setBlock(i + 3, j + 5, k + 1, VetheaBlocks.darkDreamBricks);
		world.setBlock(i + 3, j + 5, k + 2, VetheaBlocks.darkDreamBricks);
		world.setBlock(i + 3, j + 5, k + 3, VetheaBlocks.darkDreamBricks);
		world.setBlock(i + 3, j + 5, k + 4, VetheaBlocks.darkDreamBricks);
		world.setBlock(i + 3, j + 5, k + 5, VetheaBlocks.darkDreamBricks);
		world.setBlock(i + 3, j + 5, k + 6, VetheaBlocks.darkDreamBricks);
		world.setBlock(i + 3, j + 5, k + 7, VetheaBlocks.darkDreamBricks);
		world.setBlock(i + 4, j + 0, k + 2, VetheaBlocks.darkDreamBricks);
		world.setBlock(i + 4, j + 0, k + 3, VetheaBlocks.smoothGlass);
		world.setBlock(i + 4, j + 0, k + 4, VetheaBlocks.smoothGlass);
		world.setBlock(i + 4, j + 0, k + 5, VetheaBlocks.darkDreamBricks);
		world.setBlock(i + 4, j + 1, k + 1, VetheaBlocks.darkDreamBricks);
		world.setBlock(i + 4, j + 1, k + 6, VetheaBlocks.darkDreamBricks);
		world.setBlock(i + 4, j + 2, k + 0, VetheaBlocks.darkDreamBricks);
		world.setBlock(i + 4, j + 2, k + 7, VetheaBlocks.darkDreamBricks);
		world.setBlock(i + 4, j + 3, k + 0, VetheaBlocks.darkDreamBricks);
		world.setBlock(i + 4, j + 3, k + 7, VetheaBlocks.darkDreamBricks);
		world.setBlock(i + 4, j + 4, k + 0, VetheaBlocks.darkDreamBricks);
		world.setBlock(i + 4, j + 4, k + 7, VetheaBlocks.darkDreamBricks);
		world.setBlock(i + 4, j + 5, k + 0, VetheaBlocks.darkDreamBricks);
		world.setBlock(i + 4, j + 5, k + 1, VetheaBlocks.lunaStone);
		world.setBlock(i + 4, j + 5, k + 2, VetheaBlocks.lunaStone);
		world.setBlock(i + 4, j + 5, k + 3, VetheaBlocks.lunaStone);
		world.setBlock(i + 4, j + 5, k + 4, VetheaBlocks.lunaStone);
		world.setBlock(i + 4, j + 5, k + 5, VetheaBlocks.lunaStone);
		world.setBlock(i + 4, j + 5, k + 6, VetheaBlocks.lunaStone);
		world.setBlock(i + 4, j + 5, k + 7, VetheaBlocks.darkDreamBricks);
		world.setBlock(i + 5, j + 0, k + 2, VetheaBlocks.darkDreamBricks);
		world.setBlock(i + 5, j + 0, k + 3, VetheaBlocks.smoothGlass);
		world.setBlock(i + 5, j + 0, k + 4, VetheaBlocks.smoothGlass);
		world.setBlock(i + 5, j + 0, k + 5, VetheaBlocks.darkDreamBricks);
		world.setBlock(i + 5, j + 1, k + 1, VetheaBlocks.darkDreamBricks);
		world.setBlock(i + 5, j + 1, k + 6, VetheaBlocks.darkDreamBricks);
		world.setBlock(i + 5, j + 2, k + 0, VetheaBlocks.darkDreamBricks);
		world.setBlock(i + 5, j + 2, k + 7, VetheaBlocks.darkDreamBricks);
		world.setBlock(i + 5, j + 3, k + 0, VetheaBlocks.smoothGlass);
		world.setBlock(i + 5, j + 3, k + 7, VetheaBlocks.smoothGlass);
		world.setBlock(i + 5, j + 4, k + 0, VetheaBlocks.lightDreamBricks);
		world.setBlock(i + 5, j + 4, k + 7, VetheaBlocks.lightDreamBricks);
		world.setBlock(i + 5, j + 5, k + 0, VetheaBlocks.darkDreamBricks);
		world.setBlock(i + 5, j + 5, k + 1, VetheaBlocks.lunaStone);
		world.setBlock(i + 5, j + 5, k + 2, VetheaBlocks.lunaStone);
		world.setBlock(i + 5, j + 5, k + 3, VetheaBlocks.lunaStone);
		world.setBlock(i + 5, j + 5, k + 4, VetheaBlocks.lunaStone);
		world.setBlock(i + 5, j + 5, k + 5, VetheaBlocks.lunaStone);
		world.setBlock(i + 5, j + 5, k + 6, VetheaBlocks.lunaStone);
		world.setBlock(i + 5, j + 5, k + 7, VetheaBlocks.darkDreamBricks);
		world.setBlock(i + 6, j + 0, k + 2, VetheaBlocks.darkDreamBricks);
		world.setBlock(i + 6, j + 0, k + 3, VetheaBlocks.smoothGlass);
		world.setBlock(i + 6, j + 0, k + 4, VetheaBlocks.smoothGlass);
		world.setBlock(i + 6, j + 0, k + 5, VetheaBlocks.darkDreamBricks);
		world.setBlock(i + 6, j + 1, k + 1, VetheaBlocks.darkDreamBricks);
		world.setBlock(i + 6, j + 1, k + 6, VetheaBlocks.darkDreamBricks);
		world.setBlock(i + 6, j + 2, k + 0, VetheaBlocks.darkDreamBricks);
		world.setBlock(i + 6, j + 2, k + 7, VetheaBlocks.darkDreamBricks);
		world.setBlock(i + 6, j + 3, k + 0, VetheaBlocks.smoothGlass);
		world.setBlock(i + 6, j + 3, k + 7, VetheaBlocks.smoothGlass);
		world.setBlock(i + 6, j + 4, k + 0, VetheaBlocks.lightDreamBricks);
		world.setBlock(i + 6, j + 4, k + 7, VetheaBlocks.lightDreamBricks);
		world.setBlock(i + 6, j + 5, k + 0, VetheaBlocks.darkDreamBricks);
		world.setBlock(i + 6, j + 5, k + 1, VetheaBlocks.lunaStone);
		world.setBlock(i + 6, j + 5, k + 2, VetheaBlocks.lunaStone);
		world.setBlock(i + 6, j + 5, k + 3, VetheaBlocks.lunaStone);
		world.setBlock(i + 6, j + 5, k + 4, VetheaBlocks.lunaStone);
		world.setBlock(i + 6, j + 5, k + 5, VetheaBlocks.lunaStone);
		world.setBlock(i + 6, j + 5, k + 6, VetheaBlocks.lunaStone);
		world.setBlock(i + 6, j + 5, k + 7, VetheaBlocks.darkDreamBricks);
		world.setBlock(i + 7, j + 0, k + 2, VetheaBlocks.darkDreamBricks);
		world.setBlock(i + 7, j + 0, k + 3, VetheaBlocks.smoothGlass);
		world.setBlock(i + 7, j + 0, k + 4, VetheaBlocks.smoothGlass);
		world.setBlock(i + 7, j + 0, k + 5, VetheaBlocks.darkDreamBricks);
		world.setBlock(i + 7, j + 1, k + 1, VetheaBlocks.darkDreamBricks);
		world.setBlock(i + 7, j + 1, k + 6, VetheaBlocks.darkDreamBricks);
		world.setBlock(i + 7, j + 2, k + 0, VetheaBlocks.darkDreamBricks);
		world.setBlock(i + 7, j + 2, k + 7, VetheaBlocks.darkDreamBricks);
		world.setBlock(i + 7, j + 3, k + 0, VetheaBlocks.smoothGlass);
		world.setBlock(i + 7, j + 3, k + 7, VetheaBlocks.smoothGlass);
		world.setBlock(i + 7, j + 4, k + 0, VetheaBlocks.lightDreamBricks);
		world.setBlock(i + 7, j + 4, k + 7, VetheaBlocks.lightDreamBricks);
		world.setBlock(i + 7, j + 5, k + 0, VetheaBlocks.darkDreamBricks);
		world.setBlock(i + 7, j + 5, k + 1, VetheaBlocks.lunaStone);
		world.setBlock(i + 7, j + 5, k + 2, VetheaBlocks.lunaStone);
		world.setBlock(i + 7, j + 5, k + 3, VetheaBlocks.lunaStone);
		world.setBlock(i + 7, j + 5, k + 4, VetheaBlocks.lunaStone);
		world.setBlock(i + 7, j + 5, k + 5, VetheaBlocks.lunaStone);
		world.setBlock(i + 7, j + 5, k + 6, VetheaBlocks.lunaStone);
		world.setBlock(i + 7, j + 5, k + 7, VetheaBlocks.darkDreamBricks);
		world.setBlock(i + 8, j + 0, k + 2, VetheaBlocks.darkDreamBricks);
		world.setBlock(i + 8, j + 0, k + 3, VetheaBlocks.smoothGlass);
		world.setBlock(i + 8, j + 0, k + 4, VetheaBlocks.smoothGlass);
		world.setBlock(i + 8, j + 0, k + 5, VetheaBlocks.darkDreamBricks);
		world.setBlock(i + 8, j + 1, k + 1, VetheaBlocks.darkDreamBricks);
		world.setBlock(i + 8, j + 1, k + 6, VetheaBlocks.darkDreamBricks);
		world.setBlock(i + 8, j + 2, k + 0, VetheaBlocks.darkDreamBricks);
		world.setBlock(i + 8, j + 2, k + 7, VetheaBlocks.darkDreamBricks);
		world.setBlock(i + 8, j + 3, k + 0, VetheaBlocks.smoothGlass);
		world.setBlock(i + 8, j + 3, k + 7, VetheaBlocks.smoothGlass);
		world.setBlock(i + 8, j + 4, k + 0, VetheaBlocks.lightDreamBricks);
		world.setBlock(i + 8, j + 4, k + 7, VetheaBlocks.lightDreamBricks);
		world.setBlock(i + 8, j + 5, k + 0, VetheaBlocks.darkDreamBricks);
		world.setBlock(i + 8, j + 5, k + 1, VetheaBlocks.lunaStone);
		world.setBlock(i + 8, j + 5, k + 2, VetheaBlocks.lunaStone);
		world.setBlock(i + 8, j + 5, k + 3, VetheaBlocks.lunaStone);
		world.setBlock(i + 8, j + 5, k + 4, VetheaBlocks.lunaStone);
		world.setBlock(i + 8, j + 5, k + 5, VetheaBlocks.lunaStone);
		world.setBlock(i + 8, j + 5, k + 6, VetheaBlocks.lunaStone);
		world.setBlock(i + 8, j + 5, k + 7, VetheaBlocks.darkDreamBricks);
		world.setBlock(i + 9, j + 0, k + 2, VetheaBlocks.darkDreamBricks);
		world.setBlock(i + 9, j + 0, k + 3, VetheaBlocks.darkDreamBricks);
		world.setBlock(i + 9, j + 0, k + 4, VetheaBlocks.darkDreamBricks);
		world.setBlock(i + 9, j + 0, k + 5, VetheaBlocks.darkDreamBricks);
		world.setBlock(i + 9, j + 1, k + 1, VetheaBlocks.darkDreamBricks);
		world.setBlock(i + 9, j + 1, k + 2, VetheaBlocks.firelight);
		world.setBlock(i + 9, j + 1, k + 5, VetheaBlocks.firelight);
		world.setBlock(i + 9, j + 1, k + 6, VetheaBlocks.darkDreamBricks);
		world.setBlock(i + 9, j + 2, k + 0, VetheaBlocks.darkDreamBricks);
		world.setBlock(i + 9, j + 2, k + 7, VetheaBlocks.darkDreamBricks);
		world.setBlock(i + 9, j + 3, k + 0, VetheaBlocks.smoothGlass);
		world.setBlock(i + 9, j + 3, k + 7, VetheaBlocks.smoothGlass);
		world.setBlock(i + 9, j + 4, k + 0, VetheaBlocks.lightDreamBricks);
		world.setBlock(i + 9, j + 4, k + 7, VetheaBlocks.lightDreamBricks);
		world.setBlock(i + 9, j + 5, k + 0, VetheaBlocks.darkDreamBricks);
		world.setBlock(i + 9, j + 5, k + 1, VetheaBlocks.lunaStone);
		world.setBlock(i + 9, j + 5, k + 2, VetheaBlocks.lunaStone);
		world.setBlock(i + 9, j + 5, k + 3, VetheaBlocks.lunaStone);
		world.setBlock(i + 9, j + 5, k + 4, VetheaBlocks.lunaStone);
		world.setBlock(i + 9, j + 5, k + 5, VetheaBlocks.lunaStone);
		world.setBlock(i + 9, j + 5, k + 6, VetheaBlocks.lunaStone);
		world.setBlock(i + 9, j + 5, k + 7, VetheaBlocks.darkDreamBricks);
		world.setBlock(i + 10, j + 1, k + 1, VetheaBlocks.darkDreamBricks);
		world.setBlock(i + 10, j + 1, k + 2, VetheaBlocks.darkDreamBricks);
		world.setBlock(i + 10, j + 1, k + 3, VetheaBlocks.darkDreamBricks);
		world.setBlock(i + 10, j + 1, k + 4, VetheaBlocks.darkDreamBricks);
		world.setBlock(i + 10, j + 1, k + 5, VetheaBlocks.darkDreamBricks);
		world.setBlock(i + 10, j + 1, k + 6, VetheaBlocks.darkDreamBricks);
		world.setBlock(i + 10, j + 2, k + 0, VetheaBlocks.darkDreamBricks);
		world.setBlock(i + 10, j + 2, k + 1, VetheaBlocks.darkDreamBricks);
		world.setBlock(i + 10, j + 2, k + 2, VetheaBlocks.darkDreamBricks);
		world.setBlock(i + 10, j + 2, k + 3, VetheaBlocks.darkDreamBricks);
		world.setBlock(i + 10, j + 2, k + 4, VetheaBlocks.darkDreamBricks);
		world.setBlock(i + 10, j + 2, k + 5, VetheaBlocks.darkDreamBricks);
		world.setBlock(i + 10, j + 2, k + 6, VetheaBlocks.darkDreamBricks);
		world.setBlock(i + 10, j + 2, k + 7, VetheaBlocks.darkDreamBricks);
		world.setBlock(i + 10, j + 3, k + 0, VetheaBlocks.darkDreamBricks);
		world.setBlock(i + 10, j + 3, k + 1, VetheaBlocks.smoothGlass);
		world.setBlock(i + 10, j + 3, k + 2, VetheaBlocks.smoothGlass);
		world.setBlock(i + 10, j + 3, k + 3, VetheaBlocks.smoothGlass);
		world.setBlock(i + 10, j + 3, k + 4, VetheaBlocks.smoothGlass);
		world.setBlock(i + 10, j + 3, k + 5, VetheaBlocks.smoothGlass);
		world.setBlock(i + 10, j + 3, k + 6, VetheaBlocks.smoothGlass);
		world.setBlock(i + 10, j + 3, k + 7, VetheaBlocks.darkDreamBricks);
		world.setBlock(i + 10, j + 4, k + 0, VetheaBlocks.darkDreamBricks);
		world.setBlock(i + 10, j + 4, k + 1, VetheaBlocks.lightDreamBricks);
		world.setBlock(i + 10, j + 4, k + 2, VetheaBlocks.lightDreamBricks);
		world.setBlock(i + 10, j + 4, k + 3, VetheaBlocks.lightDreamBricks);
		world.setBlock(i + 10, j + 4, k + 4, VetheaBlocks.lightDreamBricks);
		world.setBlock(i + 10, j + 4, k + 5, VetheaBlocks.lightDreamBricks);
		world.setBlock(i + 10, j + 4, k + 6, VetheaBlocks.lightDreamBricks);
		world.setBlock(i + 10, j + 4, k + 7, VetheaBlocks.darkDreamBricks);
		world.setBlock(i + 10, j + 5, k + 0, VetheaBlocks.darkDreamBricks);
		world.setBlock(i + 10, j + 5, k + 1, VetheaBlocks.darkDreamBricks);
		world.setBlock(i + 10, j + 5, k + 2, VetheaBlocks.darkDreamBricks);
		world.setBlock(i + 10, j + 5, k + 3, VetheaBlocks.darkDreamBricks);
		world.setBlock(i + 10, j + 5, k + 4, VetheaBlocks.darkDreamBricks);
		world.setBlock(i + 10, j + 5, k + 5, VetheaBlocks.darkDreamBricks);
		world.setBlock(i + 10, j + 5, k + 6, VetheaBlocks.darkDreamBricks);
		world.setBlock(i + 10, j + 5, k + 7, VetheaBlocks.darkDreamBricks);

		return true;
	}
}