package divinerpg.dimensions.vethea.all;

import divinerpg.dimensions.vethea.IVetheanStructure;
import divinerpg.dimensions.vethea.VetheaChunk;
import divinerpg.registry.ModBlocks;

public class FloatingTree2 implements IVetheanStructure {

	@Override
	public void generate(VetheaChunk chunk, int i, int j, int k) {
		chunk.setBlock(i + 0, j + 1, k + 1, ModBlocks.mintwoodLeaves);
		chunk.setBlock(i + 0, j + 1, k + 2, ModBlocks.mintwoodLeaves);
		chunk.setBlock(i + 0, j + 1, k + 8, ModBlocks.dreamStone);
		chunk.setBlock(i + 0, j + 2, k + 2, ModBlocks.mintwoodLeaves);
		chunk.setBlock(i + 0, j + 2, k + 3, ModBlocks.mintwoodLeaves);
		chunk.setBlock(i + 0, j + 2, k + 8, ModBlocks.dreamStone);
		chunk.setBlock(i + 1, j + 0, k + 2, ModBlocks.mintwoodLeaves);
		chunk.setBlock(i + 1, j + 0, k + 8, ModBlocks.dreamStone);
		chunk.setBlock(i + 1, j + 1, k + 0, ModBlocks.mintwoodLeaves);
		chunk.setBlock(i + 1, j + 1, k + 1, ModBlocks.mintwoodLeaves);
		chunk.setBlock(i + 1, j + 1, k + 2, ModBlocks.mintwood);
		chunk.setBlock(i + 1, j + 1, k + 3, ModBlocks.mintwood);
		chunk.setBlock(i + 1, j + 1, k + 4, ModBlocks.mintwood);
		chunk.setBlock(i + 1, j + 1, k + 5, ModBlocks.mintwood);
		chunk.setBlock(i + 1, j + 1, k + 6, ModBlocks.mintwood);
		chunk.setBlock(i + 1, j + 1, k + 7, ModBlocks.dreamStone);
		chunk.setBlock(i + 1, j + 1, k + 8, ModBlocks.dreamStone);
		chunk.setBlock(i + 1, j + 2, k + 1, ModBlocks.mintwoodLeaves);
		chunk.setBlock(i + 1, j + 2, k + 2, ModBlocks.mintwood);
		chunk.setBlock(i + 1, j + 2, k + 3, ModBlocks.mintwood);
		chunk.setBlock(i + 1, j + 2, k + 4, ModBlocks.mintwood);
		chunk.setBlock(i + 1, j + 2, k + 5, ModBlocks.mintwood);
		chunk.setBlock(i + 1, j + 2, k + 6, ModBlocks.mintwood);
		chunk.setBlock(i + 1, j + 2, k + 7, ModBlocks.dreamStone);
		chunk.setBlock(i + 1, j + 2, k + 8, ModBlocks.dreamStone);
		chunk.setBlock(i + 1, j + 3, k + 2, ModBlocks.mintwoodLeaves);
		chunk.setBlock(i + 1, j + 3, k + 3, ModBlocks.mintwoodLeaves);
		chunk.setBlock(i + 1, j + 3, k + 8, ModBlocks.dreamStone);
		chunk.setBlock(i + 2, j + 0, k + 2, ModBlocks.mintwoodLeaves);
		chunk.setBlock(i + 2, j + 0, k + 8, ModBlocks.dreamStone);
		chunk.setBlock(i + 2, j + 1, k + 1, ModBlocks.mintwoodLeaves);
		chunk.setBlock(i + 2, j + 1, k + 2, ModBlocks.mintwood);
		chunk.setBlock(i + 2, j + 1, k + 3, ModBlocks.mintwood);
		chunk.setBlock(i + 2, j + 1, k + 4, ModBlocks.mintwood);
		chunk.setBlock(i + 2, j + 1, k + 5, ModBlocks.mintwood);
		chunk.setBlock(i + 2, j + 1, k + 6, ModBlocks.mintwood);
		chunk.setBlock(i + 2, j + 1, k + 7, ModBlocks.dreamStone);
		chunk.setBlock(i + 2, j + 1, k + 8, ModBlocks.dreamStone);
		chunk.setBlock(i + 2, j + 2, k + 1, ModBlocks.mintwoodLeaves);
		chunk.setBlock(i + 2, j + 2, k + 2, ModBlocks.mintwood);
		chunk.setBlock(i + 2, j + 2, k + 3, ModBlocks.mintwood);
		chunk.setBlock(i + 2, j + 2, k + 4, ModBlocks.mintwood);
		chunk.setBlock(i + 2, j + 2, k + 5, ModBlocks.mintwood);
		chunk.setBlock(i + 2, j + 2, k + 6, ModBlocks.mintwood);
		chunk.setBlock(i + 2, j + 2, k + 7, ModBlocks.dreamStone);
		chunk.setBlock(i + 2, j + 2, k + 8, ModBlocks.dreamStone);
		chunk.setBlock(i + 2, j + 3, k + 2, ModBlocks.mintwoodLeaves);
		chunk.setBlock(i + 2, j + 3, k + 8, ModBlocks.dreamStone);
		chunk.setBlock(i + 3, j + 0, k + 2, ModBlocks.mintwoodLeaves);
		chunk.setBlock(i + 3, j + 1, k + 2, ModBlocks.mintwoodLeaves);
		chunk.setBlock(i + 3, j + 1, k + 8, ModBlocks.dreamStone);
		chunk.setBlock(i + 3, j + 2, k + 2, ModBlocks.mintwoodLeaves);
		chunk.setBlock(i + 3, j + 2, k + 3, ModBlocks.mintwoodLeaves);
		chunk.setBlock(i + 3, j + 2, k + 8, ModBlocks.dreamStone);
		}
}
