package divinerpg.dimensions.vethea.all;
import divinerpg.dimensions.vethea.IVetheanStructure;
import divinerpg.dimensions.vethea.VetheaChunk;
import divinerpg.registry.ModBlocks;

public class FloatingTree5 implements IVetheanStructure
{

	public void generate(VetheaChunk chunk, int i, int j, int k) {

		chunk.setBlock(i + 0, j + 1, k + 8, ModBlocks.hyrewoodLeaves);
		chunk.setBlock(i + 1, j + 0, k + 8, ModBlocks.hyrewoodLeaves);
		chunk.setBlock(i + 1, j + 1, k + 5, ModBlocks.dreamStone);
		chunk.setBlock(i + 1, j + 1, k + 6, ModBlocks.hyrewoodLog);
		chunk.setBlock(i + 1, j + 1, k + 7, ModBlocks.hyrewoodLog);
		chunk.setBlock(i + 1, j + 1, k + 8, ModBlocks.hyrewoodLog);
		chunk.setBlock(i + 1, j + 1, k + 9, ModBlocks.hyrewoodLeaves);
		chunk.setBlock(i + 1, j + 2, k + 1, ModBlocks.hyrewoodLeaves);
		chunk.setBlock(i + 1, j + 2, k + 5, ModBlocks.dreamStone);
		chunk.setBlock(i + 1, j + 2, k + 8, ModBlocks.hyrewoodLeaves);
		chunk.setBlock(i + 2, j + 0, k + 5, ModBlocks.dreamStone);
		chunk.setBlock(i + 2, j + 1, k + 1, ModBlocks.hyrewoodLeaves);
		chunk.setBlock(i + 2, j + 1, k + 4, ModBlocks.dreamStone);
		chunk.setBlock(i + 2, j + 1, k + 5, ModBlocks.dreamStone);
		chunk.setBlock(i + 2, j + 1, k + 6, ModBlocks.dreamStone);
		chunk.setBlock(i + 2, j + 1, k + 8, ModBlocks.hyrewoodLeaves);
		chunk.setBlock(i + 2, j + 2, k + 0, ModBlocks.hyrewoodLeaves);
		chunk.setBlock(i + 2, j + 2, k + 1, ModBlocks.hyrewoodLeaves);
		chunk.setBlock(i + 2, j + 2, k + 2, ModBlocks.hyrewoodLog);
		chunk.setBlock(i + 2, j + 2, k + 3, ModBlocks.hyrewoodLog);
		chunk.setBlock(i + 2, j + 2, k + 4, ModBlocks.dreamStone);
		chunk.setBlock(i + 2, j + 2, k + 5, ModBlocks.dreamStone);
		chunk.setBlock(i + 2, j + 2, k + 6, ModBlocks.dreamStone);
		chunk.setBlock(i + 2, j + 3, k + 1, ModBlocks.hyrewoodLeaves);
		chunk.setBlock(i + 2, j + 3, k + 5, ModBlocks.dreamStone);
		chunk.setBlock(i + 2, j + 5, k + 6, ModBlocks.hyrewoodLeaves);
		chunk.setBlock(i + 3, j + 0, k + 5, ModBlocks.dreamStone);
		chunk.setBlock(i + 3, j + 1, k + 4, ModBlocks.dreamStone);
		chunk.setBlock(i + 3, j + 1, k + 5, ModBlocks.dreamStone);
		chunk.setBlock(i + 3, j + 1, k + 6, ModBlocks.dreamStone);
		chunk.setBlock(i + 3, j + 2, k + 1, ModBlocks.hyrewoodLeaves);
		chunk.setBlock(i + 3, j + 2, k + 4, ModBlocks.dreamStone);
		chunk.setBlock(i + 3, j + 2, k + 5, ModBlocks.dreamStone);
		chunk.setBlock(i + 3, j + 2, k + 6, ModBlocks.dreamStone);
		chunk.setBlock(i + 3, j + 3, k + 5, ModBlocks.dreamStone);
		chunk.setBlock(i + 3, j + 3, k + 6, ModBlocks.hyrewoodLog);
		chunk.setBlock(i + 3, j + 4, k + 6, ModBlocks.hyrewoodLog);
		chunk.setBlock(i + 3, j + 5, k + 5, ModBlocks.hyrewoodLeaves);
		chunk.setBlock(i + 3, j + 5, k + 6, ModBlocks.dreamDirt);
		chunk.setBlock(i + 3, j + 5, k + 7, ModBlocks.hyrewoodLeaves);
		chunk.setBlock(i + 3, j + 6, k + 6, ModBlocks.hyrewoodLeaves);
		chunk.setBlock(i + 4, j + 1, k + 5, ModBlocks.dreamStone);
		chunk.setBlock(i + 4, j + 2, k + 5, ModBlocks.dreamStone);
		chunk.setBlock(i + 4, j + 5, k + 6, ModBlocks.hyrewoodLeaves);
	}
}