package divinerpg.dimensions.vethea.layer2;
import divinerpg.dimensions.vethea.IVetheanStructure;
import divinerpg.dimensions.vethea.VetheaChunk;
import divinerpg.registry.ModBlocks;

public class Tree3 implements IVetheanStructure {

	public void generate(VetheaChunk chunk, int i, int j, int k) {
		chunk.setBlock(i + 0, j + 17, k + 8, ModBlocks.dreamwoodLeaves);
		chunk.setBlock(i + 0, j + 18, k + 7, ModBlocks.dreamwoodLeaves);
		chunk.setBlock(i + 0, j + 18, k + 8, ModBlocks.dreamwoodLeaves);
		chunk.setBlock(i + 0, j + 18, k + 9, ModBlocks.dreamwoodLeaves);
		chunk.setBlock(i + 0, j + 19, k + 6, ModBlocks.dreamwoodLeaves);
		chunk.setBlock(i + 0, j + 19, k + 7, ModBlocks.dreamwoodLeaves);
		chunk.setBlock(i + 0, j + 19, k + 8, ModBlocks.dreamwoodLeaves);
		chunk.setBlock(i + 0, j + 19, k + 9, ModBlocks.dreamwoodLeaves);
		chunk.setBlock(i + 0, j + 19, k + 10, ModBlocks.dreamwoodLeaves);
		chunk.setBlock(i + 0, j + 20, k + 7, ModBlocks.dreamwoodLeaves);
		chunk.setBlock(i + 0, j + 20, k + 8, ModBlocks.dreamwoodLeaves);
		chunk.setBlock(i + 0, j + 20, k + 9, ModBlocks.dreamwoodLeaves);
		chunk.setBlock(i + 0, j + 21, k + 8, ModBlocks.dreamwoodLeaves);
		chunk.setBlock(i + 1, j + 16, k + 7, ModBlocks.dreamwoodLeaves);
		chunk.setBlock(i + 1, j + 16, k + 8, ModBlocks.dreamwoodLeaves);
		chunk.setBlock(i + 1, j + 16, k + 9, ModBlocks.dreamwoodLeaves);
		chunk.setBlock(i + 1, j + 17, k + 6, ModBlocks.dreamwoodLeaves);
		chunk.setBlock(i + 1, j + 17, k + 7, ModBlocks.dreamwoodLeaves);
		chunk.setBlock(i + 1, j + 17, k + 8, ModBlocks.dreamwoodLeaves);
		chunk.setBlock(i + 1, j + 17, k + 9, ModBlocks.dreamwoodLeaves);
		chunk.setBlock(i + 1, j + 17, k + 10, ModBlocks.dreamwoodLeaves);
		chunk.setBlock(i + 1, j + 18, k + 5, ModBlocks.dreamwoodLeaves);
		chunk.setBlock(i + 1, j + 18, k + 6, ModBlocks.dreamwoodLeaves);
		chunk.setBlock(i + 1, j + 18, k + 7, ModBlocks.dreamwoodLeaves);
		chunk.setBlock(i + 1, j + 18, k + 8, ModBlocks.dreamwoodLeaves);
		chunk.setBlock(i + 1, j + 18, k + 9, ModBlocks.dreamwoodLeaves);
		chunk.setBlock(i + 1, j + 18, k + 10, ModBlocks.dreamwoodLeaves);
		chunk.setBlock(i + 1, j + 18, k + 11, ModBlocks.dreamwoodLeaves);
		chunk.setBlock(i + 1, j + 19, k + 5, ModBlocks.dreamwoodLeaves);
		chunk.setBlock(i + 1, j + 19, k + 6, ModBlocks.dreamwoodLeaves);
		chunk.setBlock(i + 1, j + 19, k + 7, ModBlocks.dreamwoodLeaves);
		chunk.setBlock(i + 1, j + 19, k + 8, ModBlocks.dreamwoodLeaves);
		chunk.setBlock(i + 1, j + 19, k + 9, ModBlocks.dreamwoodLeaves);
		chunk.setBlock(i + 1, j + 19, k + 10, ModBlocks.dreamwoodLeaves);
		chunk.setBlock(i + 1, j + 19, k + 11, ModBlocks.dreamwoodLeaves);
		chunk.setBlock(i + 1, j + 20, k + 5, ModBlocks.dreamwoodLeaves);
		chunk.setBlock(i + 1, j + 20, k + 6, ModBlocks.dreamwoodLeaves);
		chunk.setBlock(i + 1, j + 20, k + 7, ModBlocks.dreamwoodLeaves);
		chunk.setBlock(i + 1, j + 20, k + 8, ModBlocks.dreamwoodLeaves);
		chunk.setBlock(i + 1, j + 20, k + 9, ModBlocks.dreamwoodLeaves);
		chunk.setBlock(i + 1, j + 20, k + 10, ModBlocks.dreamwoodLeaves);
		chunk.setBlock(i + 1, j + 20, k + 11, ModBlocks.dreamwoodLeaves);
		chunk.setBlock(i + 1, j + 21, k + 6, ModBlocks.dreamwoodLeaves);
		chunk.setBlock(i + 1, j + 21, k + 7, ModBlocks.dreamwoodLeaves);
		chunk.setBlock(i + 1, j + 21, k + 8, ModBlocks.dreamwoodLeaves);
		chunk.setBlock(i + 1, j + 21, k + 9, ModBlocks.dreamwoodLeaves);
		chunk.setBlock(i + 1, j + 21, k + 10, ModBlocks.dreamwoodLeaves);
		chunk.setBlock(i + 1, j + 22, k + 7, ModBlocks.dreamwoodLeaves);
		chunk.setBlock(i + 1, j + 22, k + 8, ModBlocks.dreamwoodLeaves);
		chunk.setBlock(i + 1, j + 22, k + 9, ModBlocks.dreamwoodLeaves);
		chunk.setBlock(i + 2, j + 15, k + 8, ModBlocks.dreamwoodLeaves);
		chunk.setBlock(i + 2, j + 16, k + 6, ModBlocks.dreamwoodLeaves);
		chunk.setBlock(i + 2, j + 16, k + 7, ModBlocks.dreamwoodLeaves);
		chunk.setBlock(i + 2, j + 16, k + 8, ModBlocks.dreamwoodLeaves);
		chunk.setBlock(i + 2, j + 16, k + 9, ModBlocks.dreamwoodLeaves);
		chunk.setBlock(i + 2, j + 16, k + 10, ModBlocks.dreamwoodLeaves);
		chunk.setBlock(i + 2, j + 17, k + 5, ModBlocks.dreamwoodLeaves);
		chunk.setBlock(i + 2, j + 17, k + 6, ModBlocks.dreamwoodLeaves);
		chunk.setBlock(i + 2, j + 17, k + 7, ModBlocks.dreamwoodLeaves);
		chunk.setBlock(i + 2, j + 17, k + 8, ModBlocks.dreamwoodLeaves);
		chunk.setBlock(i + 2, j + 17, k + 9, ModBlocks.dreamwoodLeaves);
		chunk.setBlock(i + 2, j + 17, k + 10, ModBlocks.dreamwoodLeaves);
		chunk.setBlock(i + 2, j + 17, k + 11, ModBlocks.dreamwoodLeaves);
		chunk.setBlock(i + 2, j + 18, k + 5, ModBlocks.dreamwoodLeaves);
		chunk.setBlock(i + 2, j + 18, k + 6, ModBlocks.dreamwoodLeaves);
		chunk.setBlock(i + 2, j + 18, k + 7, ModBlocks.dreamwoodLeaves);
		chunk.setBlock(i + 2, j + 18, k + 8, ModBlocks.dreamwoodLeaves);
		chunk.setBlock(i + 2, j + 18, k + 9, ModBlocks.dreamwoodLeaves);
		chunk.setBlock(i + 2, j + 18, k + 10, ModBlocks.dreamwoodLeaves);
		chunk.setBlock(i + 2, j + 18, k + 11, ModBlocks.dreamwoodLeaves);
		chunk.setBlock(i + 2, j + 19, k + 4, ModBlocks.dreamwoodLeaves);
		chunk.setBlock(i + 2, j + 19, k + 5, ModBlocks.dreamwoodLeaves);
		chunk.setBlock(i + 2, j + 19, k + 6, ModBlocks.dreamwoodLeaves);
		chunk.setBlock(i + 2, j + 19, k + 7, ModBlocks.dreamwoodLeaves);
		chunk.setBlock(i + 2, j + 19, k + 8, ModBlocks.dreamwoodLeaves);
		chunk.setBlock(i + 2, j + 19, k + 9, ModBlocks.dreamwoodLeaves);
		chunk.setBlock(i + 2, j + 19, k + 10, ModBlocks.dreamwoodLeaves);
		chunk.setBlock(i + 2, j + 19, k + 11, ModBlocks.dreamwoodLeaves);
		chunk.setBlock(i + 2, j + 19, k + 12, ModBlocks.dreamwoodLeaves);
		chunk.setBlock(i + 2, j + 20, k + 5, ModBlocks.dreamwoodLeaves);
		chunk.setBlock(i + 2, j + 20, k + 6, ModBlocks.dreamwoodLeaves);
		chunk.setBlock(i + 2, j + 20, k + 7, ModBlocks.dreamwoodLeaves);
		chunk.setBlock(i + 2, j + 20, k + 8, ModBlocks.dreamwoodLeaves);
		chunk.setBlock(i + 2, j + 20, k + 9, ModBlocks.dreamwoodLeaves);
		chunk.setBlock(i + 2, j + 20, k + 10, ModBlocks.dreamwoodLeaves);
		chunk.setBlock(i + 2, j + 20, k + 11, ModBlocks.dreamwoodLeaves);
		chunk.setBlock(i + 2, j + 21, k + 5, ModBlocks.dreamwoodLeaves);
		chunk.setBlock(i + 2, j + 21, k + 6, ModBlocks.dreamwoodLeaves);
		chunk.setBlock(i + 2, j + 21, k + 7, ModBlocks.dreamwoodLeaves);
		chunk.setBlock(i + 2, j + 21, k + 8, ModBlocks.dreamwoodLeaves);
		chunk.setBlock(i + 2, j + 21, k + 9, ModBlocks.dreamwoodLeaves);
		chunk.setBlock(i + 2, j + 21, k + 10, ModBlocks.dreamwoodLeaves);
		chunk.setBlock(i + 2, j + 21, k + 11, ModBlocks.dreamwoodLeaves);
		chunk.setBlock(i + 2, j + 22, k + 6, ModBlocks.dreamwoodLeaves);
		chunk.setBlock(i + 2, j + 22, k + 7, ModBlocks.dreamwoodLeaves);
		chunk.setBlock(i + 2, j + 22, k + 8, ModBlocks.dreamwoodLeaves);
		chunk.setBlock(i + 2, j + 22, k + 9, ModBlocks.dreamwoodLeaves);
		chunk.setBlock(i + 2, j + 22, k + 10, ModBlocks.dreamwoodLeaves);
		chunk.setBlock(i + 2, j + 23, k + 8, ModBlocks.dreamwoodLeaves);
		chunk.setBlock(i + 3, j + 10, k + 7, ModBlocks.dreamwoodLog);
		chunk.setBlock(i + 3, j + 10, k + 8, ModBlocks.dreamwoodLog);
		chunk.setBlock(i + 3, j + 11, k + 7, ModBlocks.dreamwoodLog);
		chunk.setBlock(i + 3, j + 11, k + 8, ModBlocks.dreamwoodLog);
		chunk.setBlock(i + 3, j + 12, k + 7, ModBlocks.dreamwoodLog);
		chunk.setBlock(i + 3, j + 12, k + 8, ModBlocks.dreamwoodLog);
		chunk.setBlock(i + 3, j + 13, k + 7, ModBlocks.dreamwoodLog);
		chunk.setBlock(i + 3, j + 13, k + 8, ModBlocks.dreamwoodLog);
		chunk.setBlock(i + 3, j + 14, k + 7, ModBlocks.dreamwoodLog);
		chunk.setBlock(i + 3, j + 14, k + 8, ModBlocks.dreamwoodLog);
		chunk.setBlock(i + 3, j + 15, k + 7, ModBlocks.dreamwoodLeaves);
		chunk.setBlock(i + 3, j + 15, k + 8, ModBlocks.dreamwoodLeaves);
		chunk.setBlock(i + 3, j + 15, k + 9, ModBlocks.dreamwoodLeaves);
		chunk.setBlock(i + 3, j + 16, k + 5, ModBlocks.dreamwoodLeaves);
		chunk.setBlock(i + 3, j + 16, k + 6, ModBlocks.dreamwoodLeaves);
		chunk.setBlock(i + 3, j + 16, k + 7, ModBlocks.dreamwoodLeaves);
		chunk.setBlock(i + 3, j + 16, k + 8, ModBlocks.dreamwoodLeaves);
		chunk.setBlock(i + 3, j + 16, k + 9, ModBlocks.dreamwoodLeaves);
		chunk.setBlock(i + 3, j + 16, k + 10, ModBlocks.dreamwoodLeaves);
		chunk.setBlock(i + 3, j + 16, k + 11, ModBlocks.dreamwoodLeaves);
		chunk.setBlock(i + 3, j + 17, k + 4, ModBlocks.dreamwoodLeaves);
		chunk.setBlock(i + 3, j + 17, k + 5, ModBlocks.dreamwoodLeaves);
		chunk.setBlock(i + 3, j + 17, k + 6, ModBlocks.dreamwoodLeaves);
		chunk.setBlock(i + 3, j + 17, k + 7, ModBlocks.dreamwoodLeaves);
		chunk.setBlock(i + 3, j + 17, k + 8, ModBlocks.dreamwoodLeaves);
		chunk.setBlock(i + 3, j + 17, k + 9, ModBlocks.dreamwoodLeaves);
		chunk.setBlock(i + 3, j + 17, k + 10, ModBlocks.dreamwoodLeaves);
		chunk.setBlock(i + 3, j + 17, k + 11, ModBlocks.dreamwoodLeaves);
		chunk.setBlock(i + 3, j + 18, k + 3, ModBlocks.dreamwoodLeaves);
		chunk.setBlock(i + 3, j + 18, k + 4, ModBlocks.dreamwoodLeaves);
		chunk.setBlock(i + 3, j + 18, k + 5, ModBlocks.dreamwoodLeaves);
		chunk.setBlock(i + 3, j + 18, k + 6, ModBlocks.dreamwoodLeaves);
		chunk.setBlock(i + 3, j + 18, k + 7, ModBlocks.dreamwoodLeaves);
		chunk.setBlock(i + 3, j + 18, k + 8, ModBlocks.dreamwoodLeaves);
		chunk.setBlock(i + 3, j + 18, k + 9, ModBlocks.dreamwoodLeaves);
		chunk.setBlock(i + 3, j + 18, k + 10, ModBlocks.dreamwoodLeaves);
		chunk.setBlock(i + 3, j + 18, k + 11, ModBlocks.dreamwoodLeaves);
		chunk.setBlock(i + 3, j + 18, k + 12, ModBlocks.dreamwoodLeaves);
		chunk.setBlock(i + 3, j + 19, k + 2, ModBlocks.dreamwoodLeaves);
		chunk.setBlock(i + 3, j + 19, k + 3, ModBlocks.dreamwoodLeaves);
		chunk.setBlock(i + 3, j + 19, k + 4, ModBlocks.dreamwoodLeaves);
		chunk.setBlock(i + 3, j + 19, k + 5, ModBlocks.dreamwoodLeaves);
		chunk.setBlock(i + 3, j + 19, k + 6, ModBlocks.dreamwoodLeaves);
		chunk.setBlock(i + 3, j + 19, k + 7, ModBlocks.dreamwoodLeaves);
		chunk.setBlock(i + 3, j + 19, k + 8, ModBlocks.dreamwoodLeaves);
		chunk.setBlock(i + 3, j + 19, k + 9, ModBlocks.dreamwoodLeaves);
		chunk.setBlock(i + 3, j + 19, k + 10, ModBlocks.dreamwoodLeaves);
		chunk.setBlock(i + 3, j + 19, k + 11, ModBlocks.dreamwoodLeaves);
		chunk.setBlock(i + 3, j + 19, k + 12, ModBlocks.dreamwoodLeaves);
		chunk.setBlock(i + 3, j + 20, k + 3, ModBlocks.dreamwoodLeaves);
		chunk.setBlock(i + 3, j + 20, k + 4, ModBlocks.dreamwoodLeaves);
		chunk.setBlock(i + 3, j + 20, k + 5, ModBlocks.dreamwoodLeaves);
		chunk.setBlock(i + 3, j + 20, k + 6, ModBlocks.dreamwoodLeaves);
		chunk.setBlock(i + 3, j + 20, k + 7, ModBlocks.dreamwoodLeaves);
		chunk.setBlock(i + 3, j + 20, k + 8, ModBlocks.dreamwoodLeaves);
		chunk.setBlock(i + 3, j + 20, k + 9, ModBlocks.dreamwoodLeaves);
		chunk.setBlock(i + 3, j + 20, k + 10, ModBlocks.dreamwoodLeaves);
		chunk.setBlock(i + 3, j + 20, k + 11, ModBlocks.dreamwoodLeaves);
		chunk.setBlock(i + 3, j + 20, k + 12, ModBlocks.dreamwoodLeaves);
		chunk.setBlock(i + 3, j + 20, k + 13, ModBlocks.dreamwoodLeaves);
		chunk.setBlock(i + 3, j + 21, k + 4, ModBlocks.dreamwoodLeaves);
		chunk.setBlock(i + 3, j + 21, k + 5, ModBlocks.dreamwoodLeaves);
		chunk.setBlock(i + 3, j + 21, k + 6, ModBlocks.dreamwoodLeaves);
		chunk.setBlock(i + 3, j + 21, k + 7, ModBlocks.dreamwoodLeaves);
		chunk.setBlock(i + 3, j + 21, k + 8, ModBlocks.dreamwoodLeaves);
		chunk.setBlock(i + 3, j + 21, k + 9, ModBlocks.dreamwoodLeaves);
		chunk.setBlock(i + 3, j + 21, k + 10, ModBlocks.dreamwoodLeaves);
		chunk.setBlock(i + 3, j + 21, k + 11, ModBlocks.dreamwoodLeaves);
		chunk.setBlock(i + 3, j + 21, k + 12, ModBlocks.dreamwoodLeaves);
		chunk.setBlock(i + 3, j + 22, k + 5, ModBlocks.dreamwoodLeaves);
		chunk.setBlock(i + 3, j + 22, k + 6, ModBlocks.dreamwoodLeaves);
		chunk.setBlock(i + 3, j + 22, k + 7, ModBlocks.dreamwoodLeaves);
		chunk.setBlock(i + 3, j + 22, k + 8, ModBlocks.dreamwoodLeaves);
		chunk.setBlock(i + 3, j + 22, k + 9, ModBlocks.dreamwoodLeaves);
		chunk.setBlock(i + 3, j + 22, k + 10, ModBlocks.dreamwoodLeaves);
		chunk.setBlock(i + 3, j + 22, k + 11, ModBlocks.dreamwoodLeaves);
		chunk.setBlock(i + 3, j + 23, k + 7, ModBlocks.dreamwoodLeaves);
		chunk.setBlock(i + 3, j + 23, k + 8, ModBlocks.dreamwoodLeaves);
		chunk.setBlock(i + 3, j + 23, k + 9, ModBlocks.dreamwoodLeaves);
		chunk.setBlock(i + 4, j + 10, k + 7, ModBlocks.dreamwoodLog);
		chunk.setBlock(i + 4, j + 10, k + 8, ModBlocks.dreamwoodLog);
		chunk.setBlock(i + 4, j + 11, k + 7, ModBlocks.dreamwoodLog);
		chunk.setBlock(i + 4, j + 11, k + 8, ModBlocks.dreamwoodLog);
		chunk.setBlock(i + 4, j + 12, k + 7, ModBlocks.dreamwoodLog);
		chunk.setBlock(i + 4, j + 12, k + 8, ModBlocks.dreamwoodLog);
		chunk.setBlock(i + 4, j + 13, k + 7, ModBlocks.dreamwoodLog);
		chunk.setBlock(i + 4, j + 13, k + 8, ModBlocks.dreamwoodLog);
		chunk.setBlock(i + 4, j + 14, k + 7, ModBlocks.dreamwoodLog);
		chunk.setBlock(i + 4, j + 14, k + 8, ModBlocks.dreamwoodLog);
		chunk.setBlock(i + 4, j + 15, k + 6, ModBlocks.dreamwoodLeaves);
		chunk.setBlock(i + 4, j + 15, k + 7, ModBlocks.dreamwoodLeaves);
		chunk.setBlock(i + 4, j + 15, k + 8, ModBlocks.dreamwoodLeaves);
		chunk.setBlock(i + 4, j + 15, k + 9, ModBlocks.dreamwoodLeaves);
		chunk.setBlock(i + 4, j + 15, k + 10, ModBlocks.dreamwoodLeaves);
		chunk.setBlock(i + 4, j + 16, k + 3, ModBlocks.dreamwoodLeaves);
		chunk.setBlock(i + 4, j + 16, k + 4, ModBlocks.dreamwoodLeaves);
		chunk.setBlock(i + 4, j + 16, k + 5, ModBlocks.dreamwoodLeaves);
		chunk.setBlock(i + 4, j + 16, k + 6, ModBlocks.dreamwoodLeaves);
		chunk.setBlock(i + 4, j + 16, k + 7, ModBlocks.dreamwoodLeaves);
		chunk.setBlock(i + 4, j + 16, k + 8, ModBlocks.dreamwoodLeaves);
		chunk.setBlock(i + 4, j + 16, k + 9, ModBlocks.dreamwoodLeaves);
		chunk.setBlock(i + 4, j + 16, k + 10, ModBlocks.dreamwoodLeaves);
		chunk.setBlock(i + 4, j + 16, k + 11, ModBlocks.dreamwoodLeaves);
		chunk.setBlock(i + 4, j + 17, k + 2, ModBlocks.dreamwoodLeaves);
		chunk.setBlock(i + 4, j + 17, k + 3, ModBlocks.dreamwoodLeaves);
		chunk.setBlock(i + 4, j + 17, k + 4, ModBlocks.dreamwoodLeaves);
		chunk.setBlock(i + 4, j + 17, k + 5, ModBlocks.dreamwoodLeaves);
		chunk.setBlock(i + 4, j + 17, k + 6, ModBlocks.dreamwoodLeaves);
		chunk.setBlock(i + 4, j + 17, k + 7, ModBlocks.dreamwoodLeaves);
		chunk.setBlock(i + 4, j + 17, k + 8, ModBlocks.dreamwoodLeaves);
		chunk.setBlock(i + 4, j + 17, k + 9, ModBlocks.dreamwoodLeaves);
		chunk.setBlock(i + 4, j + 17, k + 10, ModBlocks.dreamwoodLeaves);
		chunk.setBlock(i + 4, j + 17, k + 11, ModBlocks.dreamwoodLeaves);
		chunk.setBlock(i + 4, j + 17, k + 12, ModBlocks.dreamwoodLeaves);
		chunk.setBlock(i + 4, j + 18, k + 1, ModBlocks.dreamwoodLeaves);
		chunk.setBlock(i + 4, j + 18, k + 2, ModBlocks.dreamwoodLeaves);
		chunk.setBlock(i + 4, j + 18, k + 3, ModBlocks.dreamwoodLeaves);
		chunk.setBlock(i + 4, j + 18, k + 4, ModBlocks.dreamwoodLeaves);
		chunk.setBlock(i + 4, j + 18, k + 5, ModBlocks.dreamwoodLeaves);
		chunk.setBlock(i + 4, j + 18, k + 6, ModBlocks.dreamwoodLeaves);
		chunk.setBlock(i + 4, j + 18, k + 7, ModBlocks.dreamwoodLeaves);
		chunk.setBlock(i + 4, j + 18, k + 8, ModBlocks.dreamwoodLeaves);
		chunk.setBlock(i + 4, j + 18, k + 9, ModBlocks.dreamwoodLeaves);
		chunk.setBlock(i + 4, j + 18, k + 10, ModBlocks.dreamwoodLeaves);
		chunk.setBlock(i + 4, j + 18, k + 11, ModBlocks.dreamwoodLeaves);
		chunk.setBlock(i + 4, j + 18, k + 12, ModBlocks.dreamwoodLeaves);
		chunk.setBlock(i + 4, j + 18, k + 13, ModBlocks.dreamwoodLeaves);
		chunk.setBlock(i + 4, j + 19, k + 1, ModBlocks.dreamwoodLeaves);
		chunk.setBlock(i + 4, j + 19, k + 2, ModBlocks.dreamwoodLeaves);
		chunk.setBlock(i + 4, j + 19, k + 3, ModBlocks.dreamwoodLeaves);
		chunk.setBlock(i + 4, j + 19, k + 4, ModBlocks.dreamwoodLeaves);
		chunk.setBlock(i + 4, j + 19, k + 5, ModBlocks.dreamwoodLeaves);
		chunk.setBlock(i + 4, j + 19, k + 6, ModBlocks.dreamwoodLeaves);
		chunk.setBlock(i + 4, j + 19, k + 7, ModBlocks.dreamwoodLeaves);
		chunk.setBlock(i + 4, j + 19, k + 8, ModBlocks.dreamwoodLeaves);
		chunk.setBlock(i + 4, j + 19, k + 9, ModBlocks.dreamwoodLeaves);
		chunk.setBlock(i + 4, j + 19, k + 10, ModBlocks.dreamwoodLeaves);
		chunk.setBlock(i + 4, j + 19, k + 11, ModBlocks.dreamwoodLeaves);
		chunk.setBlock(i + 4, j + 19, k + 12, ModBlocks.dreamwoodLeaves);
		chunk.setBlock(i + 4, j + 19, k + 13, ModBlocks.dreamwoodLeaves);
		chunk.setBlock(i + 4, j + 19, k + 14, ModBlocks.dreamwoodLeaves);
		chunk.setBlock(i + 4, j + 20, k + 1, ModBlocks.dreamwoodLeaves);
		chunk.setBlock(i + 4, j + 20, k + 2, ModBlocks.dreamwoodLeaves);
		chunk.setBlock(i + 4, j + 20, k + 3, ModBlocks.dreamwoodLeaves);
		chunk.setBlock(i + 4, j + 20, k + 4, ModBlocks.dreamwoodLeaves);
		chunk.setBlock(i + 4, j + 20, k + 5, ModBlocks.dreamwoodLeaves);
		chunk.setBlock(i + 4, j + 20, k + 6, ModBlocks.dreamwoodLeaves);
		chunk.setBlock(i + 4, j + 20, k + 7, ModBlocks.dreamwoodLeaves);
		chunk.setBlock(i + 4, j + 20, k + 8, ModBlocks.dreamwoodLeaves);
		chunk.setBlock(i + 4, j + 20, k + 9, ModBlocks.dreamwoodLeaves);
		chunk.setBlock(i + 4, j + 20, k + 10, ModBlocks.dreamwoodLeaves);
		chunk.setBlock(i + 4, j + 20, k + 11, ModBlocks.dreamwoodLeaves);
		chunk.setBlock(i + 4, j + 20, k + 12, ModBlocks.dreamwoodLeaves);
		chunk.setBlock(i + 4, j + 20, k + 13, ModBlocks.dreamwoodLeaves);
		chunk.setBlock(i + 4, j + 20, k + 14, ModBlocks.dreamwoodLeaves);
		chunk.setBlock(i + 4, j + 21, k + 2, ModBlocks.dreamwoodLeaves);
		chunk.setBlock(i + 4, j + 21, k + 3, ModBlocks.dreamwoodLeaves);
		chunk.setBlock(i + 4, j + 21, k + 4, ModBlocks.dreamwoodLeaves);
		chunk.setBlock(i + 4, j + 21, k + 5, ModBlocks.dreamwoodLeaves);
		chunk.setBlock(i + 4, j + 21, k + 6, ModBlocks.dreamwoodLeaves);
		chunk.setBlock(i + 4, j + 21, k + 7, ModBlocks.dreamwoodLeaves);
		chunk.setBlock(i + 4, j + 21, k + 8, ModBlocks.dreamwoodLeaves);
		chunk.setBlock(i + 4, j + 21, k + 9, ModBlocks.dreamwoodLeaves);
		chunk.setBlock(i + 4, j + 21, k + 10, ModBlocks.dreamwoodLeaves);
		chunk.setBlock(i + 4, j + 21, k + 11, ModBlocks.dreamwoodLeaves);
		chunk.setBlock(i + 4, j + 21, k + 12, ModBlocks.dreamwoodLeaves);
		chunk.setBlock(i + 4, j + 21, k + 13, ModBlocks.dreamwoodLeaves);
		chunk.setBlock(i + 4, j + 21, k + 14, ModBlocks.dreamwoodLeaves);
		chunk.setBlock(i + 4, j + 22, k + 3, ModBlocks.dreamwoodLeaves);
		chunk.setBlock(i + 4, j + 22, k + 4, ModBlocks.dreamwoodLeaves);
		chunk.setBlock(i + 4, j + 22, k + 5, ModBlocks.dreamwoodLeaves);
		chunk.setBlock(i + 4, j + 22, k + 6, ModBlocks.dreamwoodLeaves);
		chunk.setBlock(i + 4, j + 22, k + 7, ModBlocks.dreamwoodLeaves);
		chunk.setBlock(i + 4, j + 22, k + 8, ModBlocks.dreamwoodLeaves);
		chunk.setBlock(i + 4, j + 22, k + 9, ModBlocks.dreamwoodLeaves);
		chunk.setBlock(i + 4, j + 22, k + 10, ModBlocks.dreamwoodLeaves);
		chunk.setBlock(i + 4, j + 22, k + 11, ModBlocks.dreamwoodLeaves);
		chunk.setBlock(i + 4, j + 22, k + 12, ModBlocks.dreamwoodLeaves);
		chunk.setBlock(i + 4, j + 22, k + 13, ModBlocks.dreamwoodLeaves);
		chunk.setBlock(i + 4, j + 23, k + 6, ModBlocks.dreamwoodLeaves);
		chunk.setBlock(i + 4, j + 23, k + 7, ModBlocks.dreamwoodLeaves);
		chunk.setBlock(i + 4, j + 23, k + 8, ModBlocks.dreamwoodLeaves);
		chunk.setBlock(i + 4, j + 23, k + 9, ModBlocks.dreamwoodLeaves);
		chunk.setBlock(i + 4, j + 23, k + 10, ModBlocks.dreamwoodLeaves);
		chunk.setBlock(i + 4, j + 23, k + 11, ModBlocks.dreamwoodLeaves);
		chunk.setBlock(i + 4, j + 23, k + 12, ModBlocks.dreamwoodLeaves);
		chunk.setBlock(i + 5, j + 0, k + 7, ModBlocks.dreamwoodLog);
		chunk.setBlock(i + 5, j + 0, k + 8, ModBlocks.dreamwoodLog);
		chunk.setBlock(i + 5, j + 10, k + 7, ModBlocks.dreamwoodLog);
		chunk.setBlock(i + 5, j + 10, k + 8, ModBlocks.dreamwoodLog);
		chunk.setBlock(i + 5, j + 15, k + 4, ModBlocks.dreamwoodLeaves);
		chunk.setBlock(i + 5, j + 15, k + 7, ModBlocks.dreamwoodLeaves);
		chunk.setBlock(i + 5, j + 15, k + 8, ModBlocks.dreamwoodLeaves);
		chunk.setBlock(i + 5, j + 15, k + 9, ModBlocks.dreamwoodLeaves);
		chunk.setBlock(i + 5, j + 16, k + 2, ModBlocks.dreamwoodLeaves);
		chunk.setBlock(i + 5, j + 16, k + 3, ModBlocks.dreamwoodLeaves);
		chunk.setBlock(i + 5, j + 16, k + 4, ModBlocks.dreamwoodLeaves);
		chunk.setBlock(i + 5, j + 16, k + 5, ModBlocks.dreamwoodLeaves);
		chunk.setBlock(i + 5, j + 16, k + 6, ModBlocks.dreamwoodLeaves);
		chunk.setBlock(i + 5, j + 16, k + 7, ModBlocks.dreamwoodLeaves);
		chunk.setBlock(i + 5, j + 16, k + 8, ModBlocks.dreamwoodLeaves);
		chunk.setBlock(i + 5, j + 16, k + 9, ModBlocks.dreamwoodLeaves);
		chunk.setBlock(i + 5, j + 16, k + 10, ModBlocks.dreamwoodLeaves);
		chunk.setBlock(i + 5, j + 16, k + 11, ModBlocks.dreamwoodLeaves);
		chunk.setBlock(i + 5, j + 17, k + 1, ModBlocks.dreamwoodLeaves);
		chunk.setBlock(i + 5, j + 17, k + 2, ModBlocks.dreamwoodLeaves);
		chunk.setBlock(i + 5, j + 17, k + 3, ModBlocks.dreamwoodLeaves);
		chunk.setBlock(i + 5, j + 17, k + 4, ModBlocks.dreamwoodLeaves);
		chunk.setBlock(i + 5, j + 17, k + 5, ModBlocks.dreamwoodLeaves);
		chunk.setBlock(i + 5, j + 17, k + 6, ModBlocks.dreamwoodLeaves);
		chunk.setBlock(i + 5, j + 17, k + 7, ModBlocks.dreamwoodLeaves);
		chunk.setBlock(i + 5, j + 17, k + 8, ModBlocks.dreamwoodLeaves);
		chunk.setBlock(i + 5, j + 17, k + 9, ModBlocks.dreamwoodLeaves);
		chunk.setBlock(i + 5, j + 17, k + 10, ModBlocks.dreamwoodLeaves);
		chunk.setBlock(i + 5, j + 17, k + 11, ModBlocks.dreamwoodLeaves);
		chunk.setBlock(i + 5, j + 17, k + 12, ModBlocks.dreamwoodLeaves);
		chunk.setBlock(i + 5, j + 17, k + 13, ModBlocks.dreamwoodLeaves);
		chunk.setBlock(i + 5, j + 18, k + 1, ModBlocks.dreamwoodLeaves);
		chunk.setBlock(i + 5, j + 18, k + 2, ModBlocks.dreamwoodLeaves);
		chunk.setBlock(i + 5, j + 18, k + 3, ModBlocks.dreamwoodLeaves);
		chunk.setBlock(i + 5, j + 18, k + 4, ModBlocks.dreamwoodLeaves);
		chunk.setBlock(i + 5, j + 18, k + 5, ModBlocks.dreamwoodLeaves);
		chunk.setBlock(i + 5, j + 18, k + 6, ModBlocks.dreamwoodLeaves);
		chunk.setBlock(i + 5, j + 18, k + 7, ModBlocks.dreamwoodLeaves);
		chunk.setBlock(i + 5, j + 18, k + 8, ModBlocks.dreamwoodLeaves);
		chunk.setBlock(i + 5, j + 18, k + 9, ModBlocks.dreamwoodLeaves);
		chunk.setBlock(i + 5, j + 18, k + 10, ModBlocks.dreamwoodLeaves);
		chunk.setBlock(i + 5, j + 18, k + 11, ModBlocks.dreamwoodLeaves);
		chunk.setBlock(i + 5, j + 18, k + 12, ModBlocks.dreamwoodLeaves);
		chunk.setBlock(i + 5, j + 18, k + 13, ModBlocks.dreamwoodLeaves);
		chunk.setBlock(i + 5, j + 18, k + 14, ModBlocks.dreamwoodLeaves);
		chunk.setBlock(i + 5, j + 19, k + 0, ModBlocks.dreamwoodLeaves);
		chunk.setBlock(i + 5, j + 19, k + 1, ModBlocks.dreamwoodLeaves);
		chunk.setBlock(i + 5, j + 19, k + 2, ModBlocks.dreamwoodLeaves);
		chunk.setBlock(i + 5, j + 19, k + 3, ModBlocks.dreamwoodLeaves);
		chunk.setBlock(i + 5, j + 19, k + 4, ModBlocks.dreamwoodLeaves);
		chunk.setBlock(i + 5, j + 19, k + 5, ModBlocks.dreamwoodLeaves);
		chunk.setBlock(i + 5, j + 19, k + 6, ModBlocks.dreamwoodLeaves);
		chunk.setBlock(i + 5, j + 19, k + 7, ModBlocks.dreamwoodLeaves);
		chunk.setBlock(i + 5, j + 19, k + 8, ModBlocks.dreamwoodLeaves);
		chunk.setBlock(i + 5, j + 19, k + 9, ModBlocks.dreamwoodLeaves);
		chunk.setBlock(i + 5, j + 19, k + 10, ModBlocks.dreamwoodLeaves);
		chunk.setBlock(i + 5, j + 19, k + 11, ModBlocks.dreamwoodLeaves);
		chunk.setBlock(i + 5, j + 19, k + 12, ModBlocks.dreamwoodLeaves);
		chunk.setBlock(i + 5, j + 19, k + 13, ModBlocks.dreamwoodLeaves);
		chunk.setBlock(i + 5, j + 19, k + 14, ModBlocks.dreamwoodLeaves);
		chunk.setBlock(i + 5, j + 20, k + 1, ModBlocks.dreamwoodLeaves);
		chunk.setBlock(i + 5, j + 20, k + 2, ModBlocks.dreamwoodLeaves);
		chunk.setBlock(i + 5, j + 20, k + 3, ModBlocks.dreamwoodLeaves);
		chunk.setBlock(i + 5, j + 20, k + 4, ModBlocks.dreamwoodLeaves);
		chunk.setBlock(i + 5, j + 20, k + 5, ModBlocks.dreamwoodLeaves);
		chunk.setBlock(i + 5, j + 20, k + 6, ModBlocks.dreamwoodLeaves);
		chunk.setBlock(i + 5, j + 20, k + 7, ModBlocks.dreamwoodLeaves);
		chunk.setBlock(i + 5, j + 20, k + 8, ModBlocks.dreamwoodLeaves);
		chunk.setBlock(i + 5, j + 20, k + 9, ModBlocks.dreamwoodLeaves);
		chunk.setBlock(i + 5, j + 20, k + 10, ModBlocks.dreamwoodLeaves);
		chunk.setBlock(i + 5, j + 20, k + 11, ModBlocks.dreamwoodLeaves);
		chunk.setBlock(i + 5, j + 20, k + 12, ModBlocks.dreamwoodLeaves);
		chunk.setBlock(i + 5, j + 20, k + 13, ModBlocks.dreamwoodLeaves);
		chunk.setBlock(i + 5, j + 20, k + 14, ModBlocks.dreamwoodLeaves);
		chunk.setBlock(i + 5, j + 20, k + 15, ModBlocks.dreamwoodLeaves);
		chunk.setBlock(i + 5, j + 21, k + 1, ModBlocks.dreamwoodLeaves);
		chunk.setBlock(i + 5, j + 21, k + 2, ModBlocks.dreamwoodLeaves);
		chunk.setBlock(i + 5, j + 21, k + 3, ModBlocks.dreamwoodLeaves);
		chunk.setBlock(i + 5, j + 21, k + 4, ModBlocks.dreamwoodLeaves);
		chunk.setBlock(i + 5, j + 21, k + 5, ModBlocks.dreamwoodLeaves);
		chunk.setBlock(i + 5, j + 21, k + 6, ModBlocks.dreamwoodLeaves);
		chunk.setBlock(i + 5, j + 21, k + 7, ModBlocks.dreamwoodLeaves);
		chunk.setBlock(i + 5, j + 21, k + 8, ModBlocks.dreamwoodLeaves);
		chunk.setBlock(i + 5, j + 21, k + 9, ModBlocks.dreamwoodLeaves);
		chunk.setBlock(i + 5, j + 21, k + 10, ModBlocks.dreamwoodLeaves);
		chunk.setBlock(i + 5, j + 21, k + 11, ModBlocks.dreamwoodLeaves);
		chunk.setBlock(i + 5, j + 21, k + 12, ModBlocks.dreamwoodLeaves);
		chunk.setBlock(i + 5, j + 21, k + 13, ModBlocks.dreamwoodLeaves);
		chunk.setBlock(i + 5, j + 21, k + 14, ModBlocks.dreamwoodLeaves);
		chunk.setBlock(i + 5, j + 22, k + 2, ModBlocks.dreamwoodLeaves);
		chunk.setBlock(i + 5, j + 22, k + 3, ModBlocks.dreamwoodLeaves);
		chunk.setBlock(i + 5, j + 22, k + 4, ModBlocks.dreamwoodLeaves);
		chunk.setBlock(i + 5, j + 22, k + 5, ModBlocks.dreamwoodLeaves);
		chunk.setBlock(i + 5, j + 22, k + 6, ModBlocks.dreamwoodLeaves);
		chunk.setBlock(i + 5, j + 22, k + 7, ModBlocks.dreamwoodLeaves);
		chunk.setBlock(i + 5, j + 22, k + 8, ModBlocks.dreamwoodLeaves);
		chunk.setBlock(i + 5, j + 22, k + 9, ModBlocks.dreamwoodLeaves);
		chunk.setBlock(i + 5, j + 22, k + 10, ModBlocks.dreamwoodLeaves);
		chunk.setBlock(i + 5, j + 22, k + 11, ModBlocks.dreamwoodLeaves);
		chunk.setBlock(i + 5, j + 22, k + 12, ModBlocks.dreamwoodLeaves);
		chunk.setBlock(i + 5, j + 22, k + 13, ModBlocks.dreamwoodLeaves);
		chunk.setBlock(i + 5, j + 22, k + 14, ModBlocks.dreamwoodLeaves);
		chunk.setBlock(i + 5, j + 23, k + 4, ModBlocks.dreamwoodLeaves);
		chunk.setBlock(i + 5, j + 23, k + 7, ModBlocks.dreamwoodLeaves);
		chunk.setBlock(i + 5, j + 23, k + 8, ModBlocks.dreamwoodLeaves);
		chunk.setBlock(i + 5, j + 23, k + 9, ModBlocks.dreamwoodLeaves);
		chunk.setBlock(i + 5, j + 23, k + 10, ModBlocks.dreamwoodLeaves);
		chunk.setBlock(i + 5, j + 23, k + 11, ModBlocks.dreamwoodLeaves);
		chunk.setBlock(i + 5, j + 23, k + 12, ModBlocks.dreamwoodLeaves);
		chunk.setBlock(i + 5, j + 23, k + 13, ModBlocks.dreamwoodLeaves);
		chunk.setBlock(i + 5, j + 24, k + 11, ModBlocks.dreamwoodLeaves);
		chunk.setBlock(i + 6, j + 0, k + 6, ModBlocks.dreamwoodLog);
		chunk.setBlock(i + 6, j + 0, k + 7, ModBlocks.dreamwoodLog);
		chunk.setBlock(i + 6, j + 0, k + 8, ModBlocks.dreamwoodLog);
		chunk.setBlock(i + 6, j + 0, k + 9, ModBlocks.dreamwoodLog);
		chunk.setBlock(i + 6, j + 1, k + 7, ModBlocks.dreamwoodLog);
		chunk.setBlock(i + 6, j + 1, k + 8, ModBlocks.dreamwoodLog);
		chunk.setBlock(i + 6, j + 9, k + 7, ModBlocks.dreamwoodLog);
		chunk.setBlock(i + 6, j + 9, k + 8, ModBlocks.dreamwoodLog);
		chunk.setBlock(i + 6, j + 10, k + 7, ModBlocks.dreamwoodLog);
		chunk.setBlock(i + 6, j + 10, k + 8, ModBlocks.dreamwoodLog);
		chunk.setBlock(i + 6, j + 15, k + 3, ModBlocks.dreamwoodLeaves);
		chunk.setBlock(i + 6, j + 15, k + 4, ModBlocks.dreamwoodLeaves);
		chunk.setBlock(i + 6, j + 15, k + 5, ModBlocks.dreamwoodLeaves);
		chunk.setBlock(i + 6, j + 15, k + 8, ModBlocks.dreamwoodLeaves);
		chunk.setBlock(i + 6, j + 16, k + 1, ModBlocks.dreamwoodLeaves);
		chunk.setBlock(i + 6, j + 16, k + 2, ModBlocks.dreamwoodLeaves);
		chunk.setBlock(i + 6, j + 16, k + 3, ModBlocks.dreamwoodLeaves);
		chunk.setBlock(i + 6, j + 16, k + 4, ModBlocks.dreamwoodLeaves);
		chunk.setBlock(i + 6, j + 16, k + 5, ModBlocks.dreamwoodLeaves);
		chunk.setBlock(i + 6, j + 16, k + 6, ModBlocks.dreamwoodLeaves);
		chunk.setBlock(i + 6, j + 16, k + 7, ModBlocks.dreamwoodLeaves);
		chunk.setBlock(i + 6, j + 16, k + 8, ModBlocks.dreamwoodLeaves);
		chunk.setBlock(i + 6, j + 16, k + 9, ModBlocks.dreamwoodLeaves);
		chunk.setBlock(i + 6, j + 16, k + 10, ModBlocks.dreamwoodLeaves);
		chunk.setBlock(i + 6, j + 16, k + 11, ModBlocks.dreamwoodLeaves);
		chunk.setBlock(i + 6, j + 16, k + 12, ModBlocks.dreamwoodLeaves);
		chunk.setBlock(i + 6, j + 17, k + 1, ModBlocks.dreamwoodLeaves);
		chunk.setBlock(i + 6, j + 17, k + 2, ModBlocks.dreamwoodLeaves);
		chunk.setBlock(i + 6, j + 17, k + 3, ModBlocks.dreamwoodLeaves);
		chunk.setBlock(i + 6, j + 17, k + 4, ModBlocks.dreamwoodLeaves);
		chunk.setBlock(i + 6, j + 17, k + 5, ModBlocks.dreamwoodLeaves);
		chunk.setBlock(i + 6, j + 17, k + 6, ModBlocks.dreamwoodLeaves);
		chunk.setBlock(i + 6, j + 17, k + 7, ModBlocks.dreamwoodLeaves);
		chunk.setBlock(i + 6, j + 17, k + 8, ModBlocks.dreamwoodLeaves);
		chunk.setBlock(i + 6, j + 17, k + 9, ModBlocks.dreamwoodLeaves);
		chunk.setBlock(i + 6, j + 17, k + 10, ModBlocks.dreamwoodLeaves);
		chunk.setBlock(i + 6, j + 17, k + 11, ModBlocks.dreamwoodLeaves);
		chunk.setBlock(i + 6, j + 17, k + 12, ModBlocks.dreamwoodLeaves);
		chunk.setBlock(i + 6, j + 17, k + 13, ModBlocks.dreamwoodLeaves);
		chunk.setBlock(i + 6, j + 17, k + 14, ModBlocks.dreamwoodLeaves);
		chunk.setBlock(i + 6, j + 18, k + 0, ModBlocks.dreamwoodLeaves);
		chunk.setBlock(i + 6, j + 18, k + 1, ModBlocks.dreamwoodLeaves);
		chunk.setBlock(i + 6, j + 18, k + 2, ModBlocks.dreamwoodLeaves);
		chunk.setBlock(i + 6, j + 18, k + 3, ModBlocks.dreamwoodLeaves);
		chunk.setBlock(i + 6, j + 18, k + 4, ModBlocks.dreamwoodLeaves);
		chunk.setBlock(i + 6, j + 18, k + 5, ModBlocks.dreamwoodLeaves);
		chunk.setBlock(i + 6, j + 18, k + 6, ModBlocks.dreamwoodLeaves);
		chunk.setBlock(i + 6, j + 18, k + 7, ModBlocks.dreamwoodLeaves);
		chunk.setBlock(i + 6, j + 18, k + 8, ModBlocks.dreamwoodLeaves);
		chunk.setBlock(i + 6, j + 18, k + 9, ModBlocks.dreamwoodLeaves);
		chunk.setBlock(i + 6, j + 18, k + 10, ModBlocks.dreamwoodLeaves);
		chunk.setBlock(i + 6, j + 18, k + 11, ModBlocks.dreamwoodLeaves);
		chunk.setBlock(i + 6, j + 18, k + 12, ModBlocks.dreamwoodLeaves);
		chunk.setBlock(i + 6, j + 18, k + 13, ModBlocks.dreamwoodLeaves);
		chunk.setBlock(i + 6, j + 18, k + 14, ModBlocks.dreamwoodLeaves);
		chunk.setBlock(i + 6, j + 19, k + 0, ModBlocks.dreamwoodLeaves);
		chunk.setBlock(i + 6, j + 19, k + 1, ModBlocks.dreamwoodLeaves);
		chunk.setBlock(i + 6, j + 19, k + 2, ModBlocks.dreamwoodLeaves);
		chunk.setBlock(i + 6, j + 19, k + 3, ModBlocks.dreamwoodLeaves);
		chunk.setBlock(i + 6, j + 19, k + 4, ModBlocks.dreamwoodLeaves);
		chunk.setBlock(i + 6, j + 19, k + 5, ModBlocks.dreamwoodLeaves);
		chunk.setBlock(i + 6, j + 19, k + 6, ModBlocks.dreamwoodLeaves);
		chunk.setBlock(i + 6, j + 19, k + 7, ModBlocks.dreamwoodLeaves);
		chunk.setBlock(i + 6, j + 19, k + 8, ModBlocks.dreamwoodLeaves);
		chunk.setBlock(i + 6, j + 19, k + 9, ModBlocks.dreamwoodLeaves);
		chunk.setBlock(i + 6, j + 19, k + 10, ModBlocks.dreamwoodLeaves);
		chunk.setBlock(i + 6, j + 19, k + 11, ModBlocks.dreamwoodLeaves);
		chunk.setBlock(i + 6, j + 19, k + 12, ModBlocks.dreamwoodLeaves);
		chunk.setBlock(i + 6, j + 19, k + 13, ModBlocks.dreamwoodLeaves);
		chunk.setBlock(i + 6, j + 19, k + 14, ModBlocks.dreamwoodLeaves);
		chunk.setBlock(i + 6, j + 19, k + 15, ModBlocks.dreamwoodLeaves);
		chunk.setBlock(i + 6, j + 20, k + 0, ModBlocks.dreamwoodLeaves);
		chunk.setBlock(i + 6, j + 20, k + 1, ModBlocks.dreamwoodLeaves);
		chunk.setBlock(i + 6, j + 20, k + 2, ModBlocks.dreamwoodLeaves);
		chunk.setBlock(i + 6, j + 20, k + 3, ModBlocks.dreamwoodLeaves);
		chunk.setBlock(i + 6, j + 20, k + 4, ModBlocks.dreamwoodLeaves);
		chunk.setBlock(i + 6, j + 20, k + 5, ModBlocks.dreamwoodLeaves);
		chunk.setBlock(i + 6, j + 20, k + 6, ModBlocks.dreamwoodLeaves);
		chunk.setBlock(i + 6, j + 20, k + 7, ModBlocks.dreamwoodLeaves);
		chunk.setBlock(i + 6, j + 20, k + 8, ModBlocks.dreamwoodLeaves);
		chunk.setBlock(i + 6, j + 20, k + 9, ModBlocks.dreamwoodLeaves);
		chunk.setBlock(i + 6, j + 20, k + 10, ModBlocks.dreamwoodLeaves);
		chunk.setBlock(i + 6, j + 20, k + 11, ModBlocks.dreamwoodLeaves);
		chunk.setBlock(i + 6, j + 20, k + 12, ModBlocks.dreamwoodLeaves);
		chunk.setBlock(i + 6, j + 20, k + 13, ModBlocks.dreamwoodLeaves);
		chunk.setBlock(i + 6, j + 20, k + 14, ModBlocks.dreamwoodLeaves);
		chunk.setBlock(i + 6, j + 20, k + 15, ModBlocks.dreamwoodLeaves);
		chunk.setBlock(i + 6, j + 21, k + 1, ModBlocks.dreamwoodLeaves);
		chunk.setBlock(i + 6, j + 21, k + 2, ModBlocks.dreamwoodLeaves);
		chunk.setBlock(i + 6, j + 21, k + 3, ModBlocks.dreamwoodLeaves);
		chunk.setBlock(i + 6, j + 21, k + 4, ModBlocks.dreamwoodLeaves);
		chunk.setBlock(i + 6, j + 21, k + 5, ModBlocks.dreamwoodLeaves);
		chunk.setBlock(i + 6, j + 21, k + 6, ModBlocks.dreamwoodLeaves);
		chunk.setBlock(i + 6, j + 21, k + 7, ModBlocks.dreamwoodLeaves);
		chunk.setBlock(i + 6, j + 21, k + 8, ModBlocks.dreamwoodLeaves);
		chunk.setBlock(i + 6, j + 21, k + 9, ModBlocks.dreamwoodLeaves);
		chunk.setBlock(i + 6, j + 21, k + 10, ModBlocks.dreamwoodLeaves);
		chunk.setBlock(i + 6, j + 21, k + 11, ModBlocks.dreamwoodLeaves);
		chunk.setBlock(i + 6, j + 21, k + 12, ModBlocks.dreamwoodLeaves);
		chunk.setBlock(i + 6, j + 21, k + 13, ModBlocks.dreamwoodLeaves);
		chunk.setBlock(i + 6, j + 21, k + 14, ModBlocks.dreamwoodLeaves);
		chunk.setBlock(i + 6, j + 21, k + 15, ModBlocks.dreamwoodLeaves);
		chunk.setBlock(i + 6, j + 22, k + 1, ModBlocks.dreamwoodLeaves);
		chunk.setBlock(i + 6, j + 22, k + 2, ModBlocks.dreamwoodLeaves);
		chunk.setBlock(i + 6, j + 22, k + 3, ModBlocks.dreamwoodLeaves);
		chunk.setBlock(i + 6, j + 22, k + 4, ModBlocks.dreamwoodLeaves);
		chunk.setBlock(i + 6, j + 22, k + 5, ModBlocks.dreamwoodLeaves);
		chunk.setBlock(i + 6, j + 22, k + 6, ModBlocks.dreamwoodLeaves);
		chunk.setBlock(i + 6, j + 22, k + 7, ModBlocks.dreamwoodLeaves);
		chunk.setBlock(i + 6, j + 22, k + 8, ModBlocks.dreamwoodLeaves);
		chunk.setBlock(i + 6, j + 22, k + 9, ModBlocks.dreamwoodLeaves);
		chunk.setBlock(i + 6, j + 22, k + 10, ModBlocks.dreamwoodLeaves);
		chunk.setBlock(i + 6, j + 22, k + 11, ModBlocks.dreamwoodLeaves);
		chunk.setBlock(i + 6, j + 22, k + 12, ModBlocks.dreamwoodLeaves);
		chunk.setBlock(i + 6, j + 22, k + 13, ModBlocks.dreamwoodLeaves);
		chunk.setBlock(i + 6, j + 22, k + 14, ModBlocks.dreamwoodLeaves);
		chunk.setBlock(i + 6, j + 23, k + 3, ModBlocks.dreamwoodLeaves);
		chunk.setBlock(i + 6, j + 23, k + 4, ModBlocks.dreamwoodLeaves);
		chunk.setBlock(i + 6, j + 23, k + 5, ModBlocks.dreamwoodLeaves);
		chunk.setBlock(i + 6, j + 23, k + 8, ModBlocks.dreamwoodLeaves);
		chunk.setBlock(i + 6, j + 23, k + 9, ModBlocks.dreamwoodLeaves);
		chunk.setBlock(i + 6, j + 23, k + 10, ModBlocks.dreamwoodLeaves);
		chunk.setBlock(i + 6, j + 23, k + 11, ModBlocks.dreamwoodLeaves);
		chunk.setBlock(i + 6, j + 23, k + 12, ModBlocks.dreamwoodLeaves);
		chunk.setBlock(i + 6, j + 23, k + 13, ModBlocks.dreamwoodLeaves);
		chunk.setBlock(i + 6, j + 23, k + 14, ModBlocks.dreamwoodLeaves);
		chunk.setBlock(i + 6, j + 24, k + 10, ModBlocks.dreamwoodLeaves);
		chunk.setBlock(i + 6, j + 24, k + 11, ModBlocks.dreamwoodLeaves);
		chunk.setBlock(i + 6, j + 24, k + 12, ModBlocks.dreamwoodLeaves);
		chunk.setBlock(i + 7, j + 0, k + 5, ModBlocks.dreamwoodLog);
		chunk.setBlock(i + 7, j + 0, k + 6, ModBlocks.dreamwoodLog);
		chunk.setBlock(i + 7, j + 0, k + 7, ModBlocks.dreamwoodLog);
		chunk.setBlock(i + 7, j + 0, k + 8, ModBlocks.dreamwoodLog);
		chunk.setBlock(i + 7, j + 0, k + 9, ModBlocks.dreamwoodLog);
		chunk.setBlock(i + 7, j + 0, k + 10, ModBlocks.dreamwoodLog);
		chunk.setBlock(i + 7, j + 1, k + 6, ModBlocks.dreamwoodLog);
		chunk.setBlock(i + 7, j + 1, k + 7, ModBlocks.dreamwoodLog);
		chunk.setBlock(i + 7, j + 1, k + 8, ModBlocks.dreamwoodLog);
		chunk.setBlock(i + 7, j + 1, k + 9, ModBlocks.dreamwoodLog);
		chunk.setBlock(i + 7, j + 2, k + 7, ModBlocks.dreamwoodLog);
		chunk.setBlock(i + 7, j + 2, k + 8, ModBlocks.dreamwoodLog);
		chunk.setBlock(i + 7, j + 3, k + 7, ModBlocks.dreamwoodLog);
		chunk.setBlock(i + 7, j + 3, k + 8, ModBlocks.dreamwoodLog);
		chunk.setBlock(i + 7, j + 4, k + 7, ModBlocks.dreamwoodLog);
		chunk.setBlock(i + 7, j + 4, k + 8, ModBlocks.dreamwoodLog);
		chunk.setBlock(i + 7, j + 5, k + 7, ModBlocks.dreamwoodLog);
		chunk.setBlock(i + 7, j + 5, k + 8, ModBlocks.dreamwoodLog);
		chunk.setBlock(i + 7, j + 6, k + 7, ModBlocks.dreamwoodLog);
		chunk.setBlock(i + 7, j + 6, k + 8, ModBlocks.dreamwoodLog);
		chunk.setBlock(i + 7, j + 7, k + 7, ModBlocks.dreamwoodLog);
		chunk.setBlock(i + 7, j + 7, k + 8, ModBlocks.dreamwoodLog);
		chunk.setBlock(i + 7, j + 8, k + 7, ModBlocks.dreamwoodLog);
		chunk.setBlock(i + 7, j + 8, k + 8, ModBlocks.dreamwoodLog);
		chunk.setBlock(i + 7, j + 9, k + 6, ModBlocks.dreamwoodLog);
		chunk.setBlock(i + 7, j + 9, k + 7, ModBlocks.dreamwoodLog);
		chunk.setBlock(i + 7, j + 9, k + 8, ModBlocks.dreamwoodLog);
		chunk.setBlock(i + 7, j + 9, k + 9, ModBlocks.dreamwoodLog);
		chunk.setBlock(i + 7, j + 10, k + 3, ModBlocks.dreamwoodLog);
		chunk.setBlock(i + 7, j + 10, k + 4, ModBlocks.dreamwoodLog);
		chunk.setBlock(i + 7, j + 10, k + 5, ModBlocks.dreamwoodLog);
		chunk.setBlock(i + 7, j + 10, k + 6, ModBlocks.dreamwoodLog);
		chunk.setBlock(i + 7, j + 10, k + 7, ModBlocks.dreamwoodLog);
		chunk.setBlock(i + 7, j + 10, k + 8, ModBlocks.dreamwoodLog);
		chunk.setBlock(i + 7, j + 10, k + 9, ModBlocks.dreamwoodLog);
		chunk.setBlock(i + 7, j + 10, k + 10, ModBlocks.dreamwoodLog);
		chunk.setBlock(i + 7, j + 10, k + 11, ModBlocks.dreamwoodLog);
		chunk.setBlock(i + 7, j + 10, k + 12, ModBlocks.dreamwoodLog);
		chunk.setBlock(i + 7, j + 11, k + 3, ModBlocks.dreamwoodLog);
		chunk.setBlock(i + 7, j + 11, k + 4, ModBlocks.dreamwoodLog);
		chunk.setBlock(i + 7, j + 11, k + 11, ModBlocks.dreamwoodLog);
		chunk.setBlock(i + 7, j + 11, k + 12, ModBlocks.dreamwoodLog);
		chunk.setBlock(i + 7, j + 12, k + 3, ModBlocks.dreamwoodLog);
		chunk.setBlock(i + 7, j + 12, k + 4, ModBlocks.dreamwoodLog);
		chunk.setBlock(i + 7, j + 12, k + 11, ModBlocks.dreamwoodLog);
		chunk.setBlock(i + 7, j + 12, k + 12, ModBlocks.dreamwoodLog);
		chunk.setBlock(i + 7, j + 13, k + 3, ModBlocks.dreamwoodLog);
		chunk.setBlock(i + 7, j + 13, k + 4, ModBlocks.dreamwoodLog);
		chunk.setBlock(i + 7, j + 13, k + 11, ModBlocks.dreamwoodLog);
		chunk.setBlock(i + 7, j + 13, k + 12, ModBlocks.dreamwoodLog);
		chunk.setBlock(i + 7, j + 14, k + 3, ModBlocks.dreamwoodLog);
		chunk.setBlock(i + 7, j + 14, k + 4, ModBlocks.dreamwoodLog);
		chunk.setBlock(i + 7, j + 14, k + 11, ModBlocks.dreamwoodLog);
		chunk.setBlock(i + 7, j + 14, k + 12, ModBlocks.dreamwoodLog);
		chunk.setBlock(i + 7, j + 15, k + 2, ModBlocks.dreamwoodLeaves);
		chunk.setBlock(i + 7, j + 15, k + 3, ModBlocks.dreamwoodLeaves);
		chunk.setBlock(i + 7, j + 15, k + 4, ModBlocks.dreamwoodLeaves);
		chunk.setBlock(i + 7, j + 15, k + 5, ModBlocks.dreamwoodLeaves);
		chunk.setBlock(i + 7, j + 15, k + 6, ModBlocks.dreamwoodLeaves);
		chunk.setBlock(i + 7, j + 15, k + 11, ModBlocks.dreamwoodLog);
		chunk.setBlock(i + 7, j + 15, k + 12, ModBlocks.dreamwoodLog);
		chunk.setBlock(i + 7, j + 16, k + 1, ModBlocks.dreamwoodLeaves);
		chunk.setBlock(i + 7, j + 16, k + 2, ModBlocks.dreamwoodLeaves);
		chunk.setBlock(i + 7, j + 16, k + 3, ModBlocks.dreamwoodLeaves);
		chunk.setBlock(i + 7, j + 16, k + 4, ModBlocks.dreamwoodLeaves);
		chunk.setBlock(i + 7, j + 16, k + 5, ModBlocks.dreamwoodLeaves);
		chunk.setBlock(i + 7, j + 16, k + 6, ModBlocks.dreamwoodLeaves);
		chunk.setBlock(i + 7, j + 16, k + 7, ModBlocks.dreamwoodLeaves);
		chunk.setBlock(i + 7, j + 16, k + 8, ModBlocks.dreamwoodLeaves);
		chunk.setBlock(i + 7, j + 16, k + 9, ModBlocks.dreamwoodLeaves);
		chunk.setBlock(i + 7, j + 16, k + 10, ModBlocks.dreamwoodLeaves);
		chunk.setBlock(i + 7, j + 16, k + 11, ModBlocks.dreamwoodLeaves);
		chunk.setBlock(i + 7, j + 16, k + 12, ModBlocks.dreamwoodLeaves);
		chunk.setBlock(i + 7, j + 16, k + 13, ModBlocks.dreamwoodLeaves);
		chunk.setBlock(i + 7, j + 17, k + 0, ModBlocks.dreamwoodLeaves);
		chunk.setBlock(i + 7, j + 17, k + 1, ModBlocks.dreamwoodLeaves);
		chunk.setBlock(i + 7, j + 17, k + 2, ModBlocks.dreamwoodLeaves);
		chunk.setBlock(i + 7, j + 17, k + 3, ModBlocks.dreamwoodLeaves);
		chunk.setBlock(i + 7, j + 17, k + 4, ModBlocks.dreamwoodLeaves);
		chunk.setBlock(i + 7, j + 17, k + 5, ModBlocks.dreamwoodLeaves);
		chunk.setBlock(i + 7, j + 17, k + 6, ModBlocks.dreamwoodLeaves);
		chunk.setBlock(i + 7, j + 17, k + 7, ModBlocks.dreamwoodLeaves);
		chunk.setBlock(i + 7, j + 17, k + 8, ModBlocks.dreamwoodLeaves);
		chunk.setBlock(i + 7, j + 17, k + 9, ModBlocks.dreamwoodLeaves);
		chunk.setBlock(i + 7, j + 17, k + 10, ModBlocks.dreamwoodLeaves);
		chunk.setBlock(i + 7, j + 17, k + 11, ModBlocks.dreamwoodLeaves);
		chunk.setBlock(i + 7, j + 17, k + 12, ModBlocks.dreamwoodLeaves);
		chunk.setBlock(i + 7, j + 17, k + 13, ModBlocks.dreamwoodLeaves);
		chunk.setBlock(i + 7, j + 17, k + 14, ModBlocks.dreamwoodLeaves);
		chunk.setBlock(i + 7, j + 18, k + 0, ModBlocks.dreamwoodLeaves);
		chunk.setBlock(i + 7, j + 18, k + 1, ModBlocks.dreamwoodLeaves);
		chunk.setBlock(i + 7, j + 18, k + 2, ModBlocks.dreamwoodLeaves);
		chunk.setBlock(i + 7, j + 18, k + 3, ModBlocks.dreamwoodLeaves);
		chunk.setBlock(i + 7, j + 18, k + 4, ModBlocks.dreamwoodLeaves);
		chunk.setBlock(i + 7, j + 18, k + 5, ModBlocks.dreamwoodLeaves);
		chunk.setBlock(i + 7, j + 18, k + 6, ModBlocks.dreamwoodLeaves);
		chunk.setBlock(i + 7, j + 18, k + 7, ModBlocks.dreamwoodLeaves);
		chunk.setBlock(i + 7, j + 18, k + 8, ModBlocks.dreamwoodLeaves);
		chunk.setBlock(i + 7, j + 18, k + 9, ModBlocks.dreamwoodLeaves);
		chunk.setBlock(i + 7, j + 18, k + 10, ModBlocks.dreamwoodLeaves);
		chunk.setBlock(i + 7, j + 18, k + 11, ModBlocks.dreamwoodLeaves);
		chunk.setBlock(i + 7, j + 18, k + 12, ModBlocks.dreamwoodLeaves);
		chunk.setBlock(i + 7, j + 18, k + 13, ModBlocks.dreamwoodLeaves);
		chunk.setBlock(i + 7, j + 18, k + 14, ModBlocks.dreamwoodLeaves);
		chunk.setBlock(i + 7, j + 18, k + 15, ModBlocks.dreamwoodLeaves);
		chunk.setBlock(i + 7, j + 19, k + 0, ModBlocks.dreamwoodLeaves);
		chunk.setBlock(i + 7, j + 19, k + 1, ModBlocks.dreamwoodLeaves);
		chunk.setBlock(i + 7, j + 19, k + 2, ModBlocks.dreamwoodLeaves);
		chunk.setBlock(i + 7, j + 19, k + 3, ModBlocks.dreamwoodLeaves);
		chunk.setBlock(i + 7, j + 19, k + 4, ModBlocks.dreamwoodLeaves);
		chunk.setBlock(i + 7, j + 19, k + 5, ModBlocks.dreamwoodLeaves);
		chunk.setBlock(i + 7, j + 19, k + 6, ModBlocks.dreamwoodLeaves);
		chunk.setBlock(i + 7, j + 19, k + 7, ModBlocks.dreamwoodLeaves);
		chunk.setBlock(i + 7, j + 19, k + 8, ModBlocks.dreamwoodLeaves);
		chunk.setBlock(i + 7, j + 19, k + 9, ModBlocks.dreamwoodLeaves);
		chunk.setBlock(i + 7, j + 19, k + 10, ModBlocks.dreamwoodLeaves);
		chunk.setBlock(i + 7, j + 19, k + 11, ModBlocks.dreamwoodLeaves);
		chunk.setBlock(i + 7, j + 19, k + 12, ModBlocks.dreamwoodLeaves);
		chunk.setBlock(i + 7, j + 19, k + 13, ModBlocks.dreamwoodLeaves);
		chunk.setBlock(i + 7, j + 19, k + 14, ModBlocks.dreamwoodLeaves);
		chunk.setBlock(i + 7, j + 19, k + 15, ModBlocks.dreamwoodLeaves);
		chunk.setBlock(i + 7, j + 20, k + 0, ModBlocks.dreamwoodLeaves);
		chunk.setBlock(i + 7, j + 20, k + 1, ModBlocks.dreamwoodLeaves);
		chunk.setBlock(i + 7, j + 20, k + 2, ModBlocks.dreamwoodLeaves);
		chunk.setBlock(i + 7, j + 20, k + 3, ModBlocks.dreamwoodLeaves);
		chunk.setBlock(i + 7, j + 20, k + 5, ModBlocks.dreamwoodLeaves);
		chunk.setBlock(i + 7, j + 20, k + 6, ModBlocks.dreamwoodLeaves);
		chunk.setBlock(i + 7, j + 20, k + 7, ModBlocks.dreamwoodLeaves);
		chunk.setBlock(i + 7, j + 20, k + 8, ModBlocks.dreamwoodLeaves);
		chunk.setBlock(i + 7, j + 20, k + 9, ModBlocks.dreamwoodLeaves);
		chunk.setBlock(i + 7, j + 20, k + 10, ModBlocks.dreamwoodLeaves);
		chunk.setBlock(i + 7, j + 20, k + 11, ModBlocks.dreamwoodLeaves);
		chunk.setBlock(i + 7, j + 20, k + 12, ModBlocks.dreamwoodLeaves);
		chunk.setBlock(i + 7, j + 20, k + 13, ModBlocks.dreamwoodLeaves);
		chunk.setBlock(i + 7, j + 20, k + 14, ModBlocks.dreamwoodLeaves);
		chunk.setBlock(i + 7, j + 20, k + 15, ModBlocks.dreamwoodLeaves);
		chunk.setBlock(i + 7, j + 21, k + 0, ModBlocks.dreamwoodLeaves);
		chunk.setBlock(i + 7, j + 21, k + 1, ModBlocks.dreamwoodLeaves);
		chunk.setBlock(i + 7, j + 21, k + 2, ModBlocks.dreamwoodLeaves);
		chunk.setBlock(i + 7, j + 21, k + 3, ModBlocks.dreamwoodLeaves);
		chunk.setBlock(i + 7, j + 21, k + 4, ModBlocks.dreamwoodLeaves);
		chunk.setBlock(i + 7, j + 21, k + 5, ModBlocks.dreamwoodLeaves);
		chunk.setBlock(i + 7, j + 21, k + 6, ModBlocks.dreamwoodLeaves);
		chunk.setBlock(i + 7, j + 21, k + 7, ModBlocks.dreamwoodLeaves);
		chunk.setBlock(i + 7, j + 21, k + 8, ModBlocks.dreamwoodLeaves);
		chunk.setBlock(i + 7, j + 21, k + 9, ModBlocks.dreamwoodLeaves);
		chunk.setBlock(i + 7, j + 21, k + 10, ModBlocks.dreamwoodLeaves);
		chunk.setBlock(i + 7, j + 21, k + 11, ModBlocks.dreamwoodLeaves);
		chunk.setBlock(i + 7, j + 21, k + 12, ModBlocks.dreamwoodLeaves);
		chunk.setBlock(i + 7, j + 21, k + 13, ModBlocks.dreamwoodLeaves);
		chunk.setBlock(i + 7, j + 21, k + 14, ModBlocks.dreamwoodLeaves);
		chunk.setBlock(i + 7, j + 21, k + 15, ModBlocks.dreamwoodLeaves);
		chunk.setBlock(i + 7, j + 22, k + 1, ModBlocks.dreamwoodLeaves);
		chunk.setBlock(i + 7, j + 22, k + 2, ModBlocks.dreamwoodLeaves);
		chunk.setBlock(i + 7, j + 22, k + 3, ModBlocks.dreamwoodLeaves);
		chunk.setBlock(i + 7, j + 22, k + 4, ModBlocks.dreamwoodLeaves);
		chunk.setBlock(i + 7, j + 22, k + 5, ModBlocks.dreamwoodLeaves);
		chunk.setBlock(i + 7, j + 22, k + 6, ModBlocks.dreamwoodLeaves);
		chunk.setBlock(i + 7, j + 22, k + 7, ModBlocks.dreamwoodLeaves);
		chunk.setBlock(i + 7, j + 22, k + 8, ModBlocks.dreamwoodLeaves);
		chunk.setBlock(i + 7, j + 22, k + 9, ModBlocks.dreamwoodLeaves);
		chunk.setBlock(i + 7, j + 22, k + 10, ModBlocks.dreamwoodLeaves);
		chunk.setBlock(i + 7, j + 22, k + 12, ModBlocks.dreamwoodLeaves);
		chunk.setBlock(i + 7, j + 22, k + 13, ModBlocks.dreamwoodLeaves);
		chunk.setBlock(i + 7, j + 22, k + 14, ModBlocks.dreamwoodLeaves);
		chunk.setBlock(i + 7, j + 22, k + 15, ModBlocks.dreamwoodLeaves);
		chunk.setBlock(i + 7, j + 23, k + 2, ModBlocks.dreamwoodLeaves);
		chunk.setBlock(i + 7, j + 23, k + 3, ModBlocks.dreamwoodLeaves);
		chunk.setBlock(i + 7, j + 23, k + 4, ModBlocks.dreamwoodLeaves);
		chunk.setBlock(i + 7, j + 23, k + 5, ModBlocks.dreamwoodLeaves);
		chunk.setBlock(i + 7, j + 23, k + 6, ModBlocks.dreamwoodLeaves);
		chunk.setBlock(i + 7, j + 23, k + 8, ModBlocks.dreamwoodLeaves);
		chunk.setBlock(i + 7, j + 23, k + 9, ModBlocks.dreamwoodLeaves);
		chunk.setBlock(i + 7, j + 23, k + 10, ModBlocks.dreamwoodLeaves);
		chunk.setBlock(i + 7, j + 23, k + 11, ModBlocks.dreamwoodLeaves);
		chunk.setBlock(i + 7, j + 23, k + 12, ModBlocks.dreamwoodLeaves);
		chunk.setBlock(i + 7, j + 23, k + 13, ModBlocks.dreamwoodLeaves);
		chunk.setBlock(i + 7, j + 23, k + 14, ModBlocks.dreamwoodLeaves);
		chunk.setBlock(i + 7, j + 24, k + 9, ModBlocks.dreamwoodLeaves);
		chunk.setBlock(i + 7, j + 24, k + 10, ModBlocks.dreamwoodLeaves);
		chunk.setBlock(i + 7, j + 24, k + 11, ModBlocks.dreamwoodLeaves);
		chunk.setBlock(i + 7, j + 24, k + 12, ModBlocks.dreamwoodLeaves);
		chunk.setBlock(i + 7, j + 24, k + 13, ModBlocks.dreamwoodLeaves);
		chunk.setBlock(i + 8, j + 0, k + 5, ModBlocks.dreamwoodLog);
		chunk.setBlock(i + 8, j + 0, k + 6, ModBlocks.dreamwoodLog);
		chunk.setBlock(i + 8, j + 0, k + 7, ModBlocks.dreamwoodLog);
		chunk.setBlock(i + 8, j + 0, k + 8, ModBlocks.dreamwoodLog);
		chunk.setBlock(i + 8, j + 0, k + 9, ModBlocks.dreamwoodLog);
		chunk.setBlock(i + 8, j + 0, k + 10, ModBlocks.dreamwoodLog);
		chunk.setBlock(i + 8, j + 1, k + 6, ModBlocks.dreamwoodLog);
		chunk.setBlock(i + 8, j + 1, k + 7, ModBlocks.dreamwoodLog);
		chunk.setBlock(i + 8, j + 1, k + 8, ModBlocks.dreamwoodLog);
		chunk.setBlock(i + 8, j + 1, k + 9, ModBlocks.dreamwoodLog);
		chunk.setBlock(i + 8, j + 2, k + 7, ModBlocks.dreamwoodLog);
		chunk.setBlock(i + 8, j + 2, k + 8, ModBlocks.dreamwoodLog);
		chunk.setBlock(i + 8, j + 3, k + 7, ModBlocks.dreamwoodLog);
		chunk.setBlock(i + 8, j + 3, k + 8, ModBlocks.dreamwoodLog);
		chunk.setBlock(i + 8, j + 4, k + 7, ModBlocks.dreamwoodLog);
		chunk.setBlock(i + 8, j + 4, k + 8, ModBlocks.dreamwoodLog);
		chunk.setBlock(i + 8, j + 5, k + 7, ModBlocks.dreamwoodLog);
		chunk.setBlock(i + 8, j + 5, k + 8, ModBlocks.dreamwoodLog);
		chunk.setBlock(i + 8, j + 6, k + 7, ModBlocks.dreamwoodLog);
		chunk.setBlock(i + 8, j + 6, k + 8, ModBlocks.dreamwoodLog);
		chunk.setBlock(i + 8, j + 7, k + 7, ModBlocks.dreamwoodLog);
		chunk.setBlock(i + 8, j + 7, k + 8, ModBlocks.dreamwoodLog);
		chunk.setBlock(i + 8, j + 8, k + 7, ModBlocks.dreamwoodLog);
		chunk.setBlock(i + 8, j + 8, k + 8, ModBlocks.dreamwoodLog);
		chunk.setBlock(i + 8, j + 9, k + 6, ModBlocks.dreamwoodLog);
		chunk.setBlock(i + 8, j + 9, k + 7, ModBlocks.dreamwoodLog);
		chunk.setBlock(i + 8, j + 9, k + 8, ModBlocks.dreamwoodLog);
		chunk.setBlock(i + 8, j + 9, k + 9, ModBlocks.dreamwoodLog);
		chunk.setBlock(i + 8, j + 10, k + 3, ModBlocks.dreamwoodLog);
		chunk.setBlock(i + 8, j + 10, k + 4, ModBlocks.dreamwoodLog);
		chunk.setBlock(i + 8, j + 10, k + 5, ModBlocks.dreamwoodLog);
		chunk.setBlock(i + 8, j + 10, k + 6, ModBlocks.dreamwoodLog);
		chunk.setBlock(i + 8, j + 10, k + 7, ModBlocks.dreamwoodLog);
		chunk.setBlock(i + 8, j + 10, k + 8, ModBlocks.dreamwoodLog);
		chunk.setBlock(i + 8, j + 10, k + 9, ModBlocks.dreamwoodLog);
		chunk.setBlock(i + 8, j + 10, k + 10, ModBlocks.dreamwoodLog);
		chunk.setBlock(i + 8, j + 10, k + 11, ModBlocks.dreamwoodLog);
		chunk.setBlock(i + 8, j + 10, k + 12, ModBlocks.dreamwoodLog);
		chunk.setBlock(i + 8, j + 11, k + 3, ModBlocks.dreamwoodLog);
		chunk.setBlock(i + 8, j + 11, k + 4, ModBlocks.dreamwoodLog);
		chunk.setBlock(i + 8, j + 11, k + 11, ModBlocks.dreamwoodLog);
		chunk.setBlock(i + 8, j + 11, k + 12, ModBlocks.dreamwoodLog);
		chunk.setBlock(i + 8, j + 12, k + 3, ModBlocks.dreamwoodLog);
		chunk.setBlock(i + 8, j + 12, k + 4, ModBlocks.dreamwoodLog);
		chunk.setBlock(i + 8, j + 12, k + 11, ModBlocks.dreamwoodLog);
		chunk.setBlock(i + 8, j + 12, k + 12, ModBlocks.dreamwoodLog);
		chunk.setBlock(i + 8, j + 13, k + 3, ModBlocks.dreamwoodLog);
		chunk.setBlock(i + 8, j + 13, k + 4, ModBlocks.dreamwoodLog);
		chunk.setBlock(i + 8, j + 13, k + 11, ModBlocks.dreamwoodLog);
		chunk.setBlock(i + 8, j + 13, k + 12, ModBlocks.dreamwoodLog);
		chunk.setBlock(i + 8, j + 14, k + 3, ModBlocks.dreamwoodLog);
		chunk.setBlock(i + 8, j + 14, k + 4, ModBlocks.dreamwoodLog);
		chunk.setBlock(i + 8, j + 14, k + 11, ModBlocks.dreamwoodLog);
		chunk.setBlock(i + 8, j + 14, k + 12, ModBlocks.dreamwoodLog);
		chunk.setBlock(i + 8, j + 15, k + 3, ModBlocks.dreamwoodLeaves);
		chunk.setBlock(i + 8, j + 15, k + 4, ModBlocks.dreamwoodLeaves);
		chunk.setBlock(i + 8, j + 15, k + 5, ModBlocks.dreamwoodLeaves);
		chunk.setBlock(i + 8, j + 15, k + 11, ModBlocks.dreamwoodLog);
		chunk.setBlock(i + 8, j + 15, k + 12, ModBlocks.dreamwoodLog);
		chunk.setBlock(i + 8, j + 16, k + 1, ModBlocks.dreamwoodLeaves);
		chunk.setBlock(i + 8, j + 16, k + 2, ModBlocks.dreamwoodLeaves);
		chunk.setBlock(i + 8, j + 16, k + 3, ModBlocks.dreamwoodLeaves);
		chunk.setBlock(i + 8, j + 16, k + 4, ModBlocks.dreamwoodLeaves);
		chunk.setBlock(i + 8, j + 16, k + 5, ModBlocks.dreamwoodLeaves);
		chunk.setBlock(i + 8, j + 16, k + 6, ModBlocks.dreamwoodLeaves);
		chunk.setBlock(i + 8, j + 16, k + 7, ModBlocks.dreamwoodLeaves);
		chunk.setBlock(i + 8, j + 16, k + 8, ModBlocks.dreamwoodLeaves);
		chunk.setBlock(i + 8, j + 16, k + 9, ModBlocks.dreamwoodLeaves);
		chunk.setBlock(i + 8, j + 16, k + 10, ModBlocks.dreamwoodLeaves);
		chunk.setBlock(i + 8, j + 16, k + 11, ModBlocks.dreamwoodLeaves);
		chunk.setBlock(i + 8, j + 16, k + 12, ModBlocks.dreamwoodLeaves);
		chunk.setBlock(i + 8, j + 17, k + 1, ModBlocks.dreamwoodLeaves);
		chunk.setBlock(i + 8, j + 17, k + 2, ModBlocks.dreamwoodLeaves);
		chunk.setBlock(i + 8, j + 17, k + 3, ModBlocks.dreamwoodLeaves);
		chunk.setBlock(i + 8, j + 17, k + 4, ModBlocks.dreamwoodLeaves);
		chunk.setBlock(i + 8, j + 17, k + 5, ModBlocks.dreamwoodLeaves);
		chunk.setBlock(i + 8, j + 17, k + 6, ModBlocks.dreamwoodLeaves);
		chunk.setBlock(i + 8, j + 17, k + 7, ModBlocks.dreamwoodLeaves);
		chunk.setBlock(i + 8, j + 17, k + 8, ModBlocks.dreamwoodLeaves);
		chunk.setBlock(i + 8, j + 17, k + 9, ModBlocks.dreamwoodLeaves);
		chunk.setBlock(i + 8, j + 17, k + 10, ModBlocks.dreamwoodLeaves);
		chunk.setBlock(i + 8, j + 17, k + 11, ModBlocks.dreamwoodLeaves);
		chunk.setBlock(i + 8, j + 17, k + 12, ModBlocks.dreamwoodLeaves);
		chunk.setBlock(i + 8, j + 17, k + 13, ModBlocks.dreamwoodLeaves);
		chunk.setBlock(i + 8, j + 17, k + 14, ModBlocks.dreamwoodLeaves);
		chunk.setBlock(i + 8, j + 18, k + 0, ModBlocks.dreamwoodLeaves);
		chunk.setBlock(i + 8, j + 18, k + 1, ModBlocks.dreamwoodLeaves);
		chunk.setBlock(i + 8, j + 18, k + 2, ModBlocks.dreamwoodLeaves);
		chunk.setBlock(i + 8, j + 18, k + 3, ModBlocks.dreamwoodLeaves);
		chunk.setBlock(i + 8, j + 18, k + 4, ModBlocks.dreamwoodLeaves);
		chunk.setBlock(i + 8, j + 18, k + 5, ModBlocks.dreamwoodLeaves);
		chunk.setBlock(i + 8, j + 18, k + 6, ModBlocks.dreamwoodLeaves);
		chunk.setBlock(i + 8, j + 18, k + 7, ModBlocks.dreamwoodLeaves);
		chunk.setBlock(i + 8, j + 18, k + 8, ModBlocks.dreamwoodLeaves);
		chunk.setBlock(i + 8, j + 18, k + 9, ModBlocks.dreamwoodLeaves);
		chunk.setBlock(i + 8, j + 18, k + 10, ModBlocks.dreamwoodLeaves);
		chunk.setBlock(i + 8, j + 18, k + 11, ModBlocks.dreamwoodLeaves);
		chunk.setBlock(i + 8, j + 18, k + 12, ModBlocks.dreamwoodLeaves);
		chunk.setBlock(i + 8, j + 18, k + 13, ModBlocks.dreamwoodLeaves);
		chunk.setBlock(i + 8, j + 18, k + 14, ModBlocks.dreamwoodLeaves);
		chunk.setBlock(i + 8, j + 19, k + 0, ModBlocks.dreamwoodLeaves);
		chunk.setBlock(i + 8, j + 19, k + 1, ModBlocks.dreamwoodLeaves);
		chunk.setBlock(i + 8, j + 19, k + 2, ModBlocks.dreamwoodLeaves);
		chunk.setBlock(i + 8, j + 19, k + 3, ModBlocks.dreamwoodLeaves);
		chunk.setBlock(i + 8, j + 19, k + 4, ModBlocks.dreamwoodLeaves);
		chunk.setBlock(i + 8, j + 19, k + 5, ModBlocks.dreamwoodLeaves);
		chunk.setBlock(i + 8, j + 19, k + 6, ModBlocks.dreamwoodLeaves);
		chunk.setBlock(i + 8, j + 19, k + 7, ModBlocks.dreamwoodLeaves);
		chunk.setBlock(i + 8, j + 19, k + 8, ModBlocks.dreamwoodLeaves);
		chunk.setBlock(i + 8, j + 19, k + 9, ModBlocks.dreamwoodLeaves);
		chunk.setBlock(i + 8, j + 19, k + 10, ModBlocks.dreamwoodLeaves);
		chunk.setBlock(i + 8, j + 19, k + 11, ModBlocks.dreamwoodLeaves);
		chunk.setBlock(i + 8, j + 19, k + 12, ModBlocks.dreamwoodLeaves);
		chunk.setBlock(i + 8, j + 19, k + 13, ModBlocks.dreamwoodLeaves);
		chunk.setBlock(i + 8, j + 19, k + 14, ModBlocks.dreamwoodLeaves);
		chunk.setBlock(i + 8, j + 19, k + 15, ModBlocks.dreamwoodLeaves);
		chunk.setBlock(i + 8, j + 20, k + 0, ModBlocks.dreamwoodLeaves);
		chunk.setBlock(i + 8, j + 20, k + 1, ModBlocks.dreamwoodLeaves);
		chunk.setBlock(i + 8, j + 20, k + 2, ModBlocks.dreamwoodLeaves);
		chunk.setBlock(i + 8, j + 20, k + 3, ModBlocks.dreamwoodLeaves);
		chunk.setBlock(i + 8, j + 20, k + 4, ModBlocks.dreamwoodLeaves);
		chunk.setBlock(i + 8, j + 20, k + 5, ModBlocks.dreamwoodLeaves);
		chunk.setBlock(i + 8, j + 20, k + 6, ModBlocks.dreamwoodLeaves);
		chunk.setBlock(i + 8, j + 20, k + 7, ModBlocks.dreamwoodLeaves);
		chunk.setBlock(i + 8, j + 20, k + 8, ModBlocks.dreamwoodLeaves);
		chunk.setBlock(i + 8, j + 20, k + 9, ModBlocks.dreamwoodLeaves);
		chunk.setBlock(i + 8, j + 20, k + 10, ModBlocks.dreamwoodLeaves);
		chunk.setBlock(i + 8, j + 20, k + 11, ModBlocks.dreamwoodLeaves);
		chunk.setBlock(i + 8, j + 20, k + 12, ModBlocks.dreamwoodLeaves);
		chunk.setBlock(i + 8, j + 20, k + 13, ModBlocks.dreamwoodLeaves);
		chunk.setBlock(i + 8, j + 20, k + 14, ModBlocks.dreamwoodLeaves);
		chunk.setBlock(i + 8, j + 20, k + 15, ModBlocks.dreamwoodLeaves);
		chunk.setBlock(i + 8, j + 21, k + 1, ModBlocks.dreamwoodLeaves);
		chunk.setBlock(i + 8, j + 21, k + 2, ModBlocks.dreamwoodLeaves);
		chunk.setBlock(i + 8, j + 21, k + 3, ModBlocks.dreamwoodLeaves);
		chunk.setBlock(i + 8, j + 21, k + 4, ModBlocks.dreamwoodLeaves);
		chunk.setBlock(i + 8, j + 21, k + 5, ModBlocks.dreamwoodLeaves);
		chunk.setBlock(i + 8, j + 21, k + 6, ModBlocks.dreamwoodLeaves);
		chunk.setBlock(i + 8, j + 21, k + 7, ModBlocks.dreamwoodLeaves);
		chunk.setBlock(i + 8, j + 21, k + 8, ModBlocks.dreamwoodLeaves);
		chunk.setBlock(i + 8, j + 21, k + 9, ModBlocks.dreamwoodLeaves);
		chunk.setBlock(i + 8, j + 21, k + 11, ModBlocks.dreamwoodLeaves);
		chunk.setBlock(i + 8, j + 21, k + 12, ModBlocks.dreamwoodLeaves);
		chunk.setBlock(i + 8, j + 21, k + 13, ModBlocks.dreamwoodLeaves);
		chunk.setBlock(i + 8, j + 21, k + 14, ModBlocks.dreamwoodLeaves);
		chunk.setBlock(i + 8, j + 21, k + 15, ModBlocks.dreamwoodLeaves);
		chunk.setBlock(i + 8, j + 22, k + 1, ModBlocks.dreamwoodLeaves);
		chunk.setBlock(i + 8, j + 22, k + 2, ModBlocks.dreamwoodLeaves);
		chunk.setBlock(i + 8, j + 22, k + 3, ModBlocks.dreamwoodLeaves);
		chunk.setBlock(i + 8, j + 22, k + 4, ModBlocks.dreamwoodLeaves);
		chunk.setBlock(i + 8, j + 22, k + 5, ModBlocks.dreamwoodLeaves);
		chunk.setBlock(i + 8, j + 22, k + 6, ModBlocks.dreamwoodLeaves);
		chunk.setBlock(i + 8, j + 22, k + 7, ModBlocks.dreamwoodLeaves);
		chunk.setBlock(i + 8, j + 22, k + 8, ModBlocks.dreamwoodLeaves);
		chunk.setBlock(i + 8, j + 22, k + 9, ModBlocks.dreamwoodLeaves);
		chunk.setBlock(i + 8, j + 22, k + 10, ModBlocks.dreamwoodLeaves);
		chunk.setBlock(i + 8, j + 22, k + 11, ModBlocks.dreamwoodLeaves);
		chunk.setBlock(i + 8, j + 22, k + 12, ModBlocks.dreamwoodLeaves);
		chunk.setBlock(i + 8, j + 22, k + 13, ModBlocks.dreamwoodLeaves);
		chunk.setBlock(i + 8, j + 22, k + 14, ModBlocks.dreamwoodLeaves);
		chunk.setBlock(i + 8, j + 23, k + 3, ModBlocks.dreamwoodLeaves);
		chunk.setBlock(i + 8, j + 23, k + 4, ModBlocks.dreamwoodLeaves);
		chunk.setBlock(i + 8, j + 23, k + 5, ModBlocks.dreamwoodLeaves);
		chunk.setBlock(i + 8, j + 23, k + 8, ModBlocks.dreamwoodLeaves);
		chunk.setBlock(i + 8, j + 23, k + 9, ModBlocks.dreamwoodLeaves);
		chunk.setBlock(i + 8, j + 23, k + 10, ModBlocks.dreamwoodLeaves);
		chunk.setBlock(i + 8, j + 23, k + 11, ModBlocks.dreamwoodLeaves);
		chunk.setBlock(i + 8, j + 23, k + 12, ModBlocks.dreamwoodLeaves);
		chunk.setBlock(i + 8, j + 23, k + 13, ModBlocks.dreamwoodLeaves);
		chunk.setBlock(i + 8, j + 23, k + 14, ModBlocks.dreamwoodLeaves);
		chunk.setBlock(i + 8, j + 24, k + 10, ModBlocks.dreamwoodLeaves);
		chunk.setBlock(i + 8, j + 24, k + 11, ModBlocks.dreamwoodLeaves);
		chunk.setBlock(i + 8, j + 24, k + 12, ModBlocks.dreamwoodLeaves);
		chunk.setBlock(i + 9, j + 0, k + 6, ModBlocks.dreamwoodLog);
		chunk.setBlock(i + 9, j + 0, k + 7, ModBlocks.dreamwoodLog);
		chunk.setBlock(i + 9, j + 0, k + 8, ModBlocks.dreamwoodLog);
		chunk.setBlock(i + 9, j + 0, k + 9, ModBlocks.dreamwoodLog);
		chunk.setBlock(i + 9, j + 1, k + 7, ModBlocks.dreamwoodLog);
		chunk.setBlock(i + 9, j + 1, k + 8, ModBlocks.dreamwoodLog);
		chunk.setBlock(i + 9, j + 9, k + 7, ModBlocks.dreamwoodLog);
		chunk.setBlock(i + 9, j + 9, k + 8, ModBlocks.dreamwoodLog);
		chunk.setBlock(i + 9, j + 10, k + 7, ModBlocks.dreamwoodLog);
		chunk.setBlock(i + 9, j + 10, k + 8, ModBlocks.dreamwoodLog);
		chunk.setBlock(i + 9, j + 15, k + 4, ModBlocks.dreamwoodLeaves);
		chunk.setBlock(i + 9, j + 15, k + 8, ModBlocks.dreamwoodLeaves);
		chunk.setBlock(i + 9, j + 16, k + 2, ModBlocks.dreamwoodLeaves);
		chunk.setBlock(i + 9, j + 16, k + 3, ModBlocks.dreamwoodLeaves);
		chunk.setBlock(i + 9, j + 16, k + 4, ModBlocks.dreamwoodLeaves);
		chunk.setBlock(i + 9, j + 16, k + 5, ModBlocks.dreamwoodLeaves);
		chunk.setBlock(i + 9, j + 16, k + 6, ModBlocks.dreamwoodLeaves);
		chunk.setBlock(i + 9, j + 16, k + 7, ModBlocks.dreamwoodLeaves);
		chunk.setBlock(i + 9, j + 16, k + 8, ModBlocks.dreamwoodLeaves);
		chunk.setBlock(i + 9, j + 16, k + 9, ModBlocks.dreamwoodLeaves);
		chunk.setBlock(i + 9, j + 16, k + 10, ModBlocks.dreamwoodLeaves);
		chunk.setBlock(i + 9, j + 16, k + 11, ModBlocks.dreamwoodLeaves);
		chunk.setBlock(i + 9, j + 17, k + 1, ModBlocks.dreamwoodLeaves);
		chunk.setBlock(i + 9, j + 17, k + 2, ModBlocks.dreamwoodLeaves);
		chunk.setBlock(i + 9, j + 17, k + 3, ModBlocks.dreamwoodLeaves);
		chunk.setBlock(i + 9, j + 17, k + 4, ModBlocks.dreamwoodLeaves);
		chunk.setBlock(i + 9, j + 17, k + 5, ModBlocks.dreamwoodLeaves);
		chunk.setBlock(i + 9, j + 17, k + 6, ModBlocks.dreamwoodLeaves);
		chunk.setBlock(i + 9, j + 17, k + 7, ModBlocks.dreamwoodLeaves);
		chunk.setBlock(i + 9, j + 17, k + 8, ModBlocks.dreamwoodLeaves);
		chunk.setBlock(i + 9, j + 17, k + 9, ModBlocks.dreamwoodLeaves);
		chunk.setBlock(i + 9, j + 17, k + 10, ModBlocks.dreamwoodLeaves);
		chunk.setBlock(i + 9, j + 17, k + 11, ModBlocks.dreamwoodLeaves);
		chunk.setBlock(i + 9, j + 17, k + 12, ModBlocks.dreamwoodLeaves);
		chunk.setBlock(i + 9, j + 17, k + 13, ModBlocks.dreamwoodLeaves);
		chunk.setBlock(i + 9, j + 18, k + 1, ModBlocks.dreamwoodLeaves);
		chunk.setBlock(i + 9, j + 18, k + 2, ModBlocks.dreamwoodLeaves);
		chunk.setBlock(i + 9, j + 18, k + 3, ModBlocks.dreamwoodLeaves);
		chunk.setBlock(i + 9, j + 18, k + 4, ModBlocks.dreamwoodLeaves);
		chunk.setBlock(i + 9, j + 18, k + 5, ModBlocks.dreamwoodLeaves);
		chunk.setBlock(i + 9, j + 18, k + 6, ModBlocks.dreamwoodLeaves);
		chunk.setBlock(i + 9, j + 18, k + 7, ModBlocks.dreamwoodLeaves);
		chunk.setBlock(i + 9, j + 18, k + 8, ModBlocks.dreamwoodLeaves);
		chunk.setBlock(i + 9, j + 18, k + 9, ModBlocks.dreamwoodLeaves);
		chunk.setBlock(i + 9, j + 18, k + 10, ModBlocks.dreamwoodLeaves);
		chunk.setBlock(i + 9, j + 18, k + 11, ModBlocks.dreamwoodLeaves);
		chunk.setBlock(i + 9, j + 18, k + 12, ModBlocks.dreamwoodLeaves);
		chunk.setBlock(i + 9, j + 18, k + 13, ModBlocks.dreamwoodLeaves);
		chunk.setBlock(i + 9, j + 18, k + 14, ModBlocks.dreamwoodLeaves);
		chunk.setBlock(i + 9, j + 19, k + 0, ModBlocks.dreamwoodLeaves);
		chunk.setBlock(i + 9, j + 19, k + 1, ModBlocks.dreamwoodLeaves);
		chunk.setBlock(i + 9, j + 19, k + 2, ModBlocks.dreamwoodLeaves);
		chunk.setBlock(i + 9, j + 19, k + 3, ModBlocks.dreamwoodLeaves);
		chunk.setBlock(i + 9, j + 19, k + 4, ModBlocks.dreamwoodLeaves);
		chunk.setBlock(i + 9, j + 19, k + 5, ModBlocks.dreamwoodLeaves);
		chunk.setBlock(i + 9, j + 19, k + 6, ModBlocks.dreamwoodLeaves);
		chunk.setBlock(i + 9, j + 19, k + 7, ModBlocks.dreamwoodLeaves);
		chunk.setBlock(i + 9, j + 19, k + 8, ModBlocks.dreamwoodLeaves);
		chunk.setBlock(i + 9, j + 19, k + 9, ModBlocks.dreamwoodLeaves);
		chunk.setBlock(i + 9, j + 19, k + 10, ModBlocks.dreamwoodLeaves);
		chunk.setBlock(i + 9, j + 19, k + 11, ModBlocks.dreamwoodLeaves);
		chunk.setBlock(i + 9, j + 19, k + 12, ModBlocks.dreamwoodLeaves);
		chunk.setBlock(i + 9, j + 19, k + 13, ModBlocks.dreamwoodLeaves);
		chunk.setBlock(i + 9, j + 19, k + 14, ModBlocks.dreamwoodLeaves);
		chunk.setBlock(i + 9, j + 20, k + 1, ModBlocks.dreamwoodLeaves);
		chunk.setBlock(i + 9, j + 20, k + 2, ModBlocks.dreamwoodLeaves);
		chunk.setBlock(i + 9, j + 20, k + 3, ModBlocks.dreamwoodLeaves);
		chunk.setBlock(i + 9, j + 20, k + 4, ModBlocks.dreamwoodLeaves);
		chunk.setBlock(i + 9, j + 20, k + 5, ModBlocks.dreamwoodLeaves);
		chunk.setBlock(i + 9, j + 20, k + 6, ModBlocks.dreamwoodLeaves);
		chunk.setBlock(i + 9, j + 20, k + 7, ModBlocks.dreamwoodLeaves);
		chunk.setBlock(i + 9, j + 20, k + 8, ModBlocks.dreamwoodLeaves);
		chunk.setBlock(i + 9, j + 20, k + 9, ModBlocks.dreamwoodLeaves);
		chunk.setBlock(i + 9, j + 20, k + 10, ModBlocks.dreamwoodLeaves);
		chunk.setBlock(i + 9, j + 20, k + 11, ModBlocks.dreamwoodLeaves);
		chunk.setBlock(i + 9, j + 20, k + 12, ModBlocks.dreamwoodLeaves);
		chunk.setBlock(i + 9, j + 20, k + 13, ModBlocks.dreamwoodLeaves);
		chunk.setBlock(i + 9, j + 20, k + 14, ModBlocks.dreamwoodLeaves);
		chunk.setBlock(i + 9, j + 20, k + 15, ModBlocks.dreamwoodLeaves);
		chunk.setBlock(i + 9, j + 21, k + 1, ModBlocks.dreamwoodLeaves);
		chunk.setBlock(i + 9, j + 21, k + 2, ModBlocks.dreamwoodLeaves);
		chunk.setBlock(i + 9, j + 21, k + 3, ModBlocks.dreamwoodLeaves);
		chunk.setBlock(i + 9, j + 21, k + 4, ModBlocks.dreamwoodLeaves);
		chunk.setBlock(i + 9, j + 21, k + 5, ModBlocks.dreamwoodLeaves);
		chunk.setBlock(i + 9, j + 21, k + 6, ModBlocks.dreamwoodLeaves);
		chunk.setBlock(i + 9, j + 21, k + 7, ModBlocks.dreamwoodLeaves);
		chunk.setBlock(i + 9, j + 21, k + 8, ModBlocks.dreamwoodLeaves);
		chunk.setBlock(i + 9, j + 21, k + 9, ModBlocks.dreamwoodLeaves);
		chunk.setBlock(i + 9, j + 21, k + 10, ModBlocks.dreamwoodLeaves);
		chunk.setBlock(i + 9, j + 21, k + 11, ModBlocks.dreamwoodLeaves);
		chunk.setBlock(i + 9, j + 21, k + 12, ModBlocks.dreamwoodLeaves);
		chunk.setBlock(i + 9, j + 21, k + 13, ModBlocks.dreamwoodLeaves);
		chunk.setBlock(i + 9, j + 21, k + 14, ModBlocks.dreamwoodLeaves);
		chunk.setBlock(i + 9, j + 22, k + 2, ModBlocks.dreamwoodLeaves);
		chunk.setBlock(i + 9, j + 22, k + 3, ModBlocks.dreamwoodLeaves);
		chunk.setBlock(i + 9, j + 22, k + 4, ModBlocks.dreamwoodLeaves);
		chunk.setBlock(i + 9, j + 22, k + 5, ModBlocks.dreamwoodLeaves);
		chunk.setBlock(i + 9, j + 22, k + 6, ModBlocks.dreamwoodLeaves);
		chunk.setBlock(i + 9, j + 22, k + 7, ModBlocks.dreamwoodLeaves);
		chunk.setBlock(i + 9, j + 22, k + 8, ModBlocks.dreamwoodLeaves);
		chunk.setBlock(i + 9, j + 22, k + 9, ModBlocks.dreamwoodLeaves);
		chunk.setBlock(i + 9, j + 22, k + 10, ModBlocks.dreamwoodLeaves);
		chunk.setBlock(i + 9, j + 22, k + 11, ModBlocks.dreamwoodLeaves);
		chunk.setBlock(i + 9, j + 22, k + 12, ModBlocks.dreamwoodLeaves);
		chunk.setBlock(i + 9, j + 22, k + 13, ModBlocks.dreamwoodLeaves);
		chunk.setBlock(i + 9, j + 22, k + 14, ModBlocks.dreamwoodLeaves);
		chunk.setBlock(i + 9, j + 23, k + 4, ModBlocks.dreamwoodLeaves);
		chunk.setBlock(i + 9, j + 23, k + 8, ModBlocks.dreamwoodLeaves);
		chunk.setBlock(i + 9, j + 23, k + 9, ModBlocks.dreamwoodLeaves);
		chunk.setBlock(i + 9, j + 23, k + 10, ModBlocks.dreamwoodLeaves);
		chunk.setBlock(i + 9, j + 23, k + 11, ModBlocks.dreamwoodLeaves);
		chunk.setBlock(i + 9, j + 23, k + 12, ModBlocks.dreamwoodLeaves);
		chunk.setBlock(i + 9, j + 23, k + 13, ModBlocks.dreamwoodLeaves);
		chunk.setBlock(i + 9, j + 24, k + 11, ModBlocks.dreamwoodLeaves);
		chunk.setBlock(i + 10, j + 0, k + 7, ModBlocks.dreamwoodLog);
		chunk.setBlock(i + 10, j + 0, k + 8, ModBlocks.dreamwoodLog);
		chunk.setBlock(i + 10, j + 10, k + 7, ModBlocks.dreamwoodLog);
		chunk.setBlock(i + 10, j + 10, k + 8, ModBlocks.dreamwoodLog);
		chunk.setBlock(i + 10, j + 15, k + 7, ModBlocks.dreamwoodLeaves);
		chunk.setBlock(i + 10, j + 15, k + 8, ModBlocks.dreamwoodLeaves);
		chunk.setBlock(i + 10, j + 15, k + 9, ModBlocks.dreamwoodLeaves);
		chunk.setBlock(i + 10, j + 16, k + 3, ModBlocks.dreamwoodLeaves);
		chunk.setBlock(i + 10, j + 16, k + 4, ModBlocks.dreamwoodLeaves);
		chunk.setBlock(i + 10, j + 16, k + 5, ModBlocks.dreamwoodLeaves);
		chunk.setBlock(i + 10, j + 16, k + 6, ModBlocks.dreamwoodLeaves);
		chunk.setBlock(i + 10, j + 16, k + 7, ModBlocks.dreamwoodLeaves);
		chunk.setBlock(i + 10, j + 16, k + 8, ModBlocks.dreamwoodLeaves);
		chunk.setBlock(i + 10, j + 16, k + 9, ModBlocks.dreamwoodLeaves);
		chunk.setBlock(i + 10, j + 16, k + 10, ModBlocks.dreamwoodLeaves);
		chunk.setBlock(i + 10, j + 16, k + 11, ModBlocks.dreamwoodLeaves);
		chunk.setBlock(i + 10, j + 17, k + 2, ModBlocks.dreamwoodLeaves);
		chunk.setBlock(i + 10, j + 17, k + 3, ModBlocks.dreamwoodLeaves);
		chunk.setBlock(i + 10, j + 17, k + 4, ModBlocks.dreamwoodLeaves);
		chunk.setBlock(i + 10, j + 17, k + 5, ModBlocks.dreamwoodLeaves);
		chunk.setBlock(i + 10, j + 17, k + 6, ModBlocks.dreamwoodLeaves);
		chunk.setBlock(i + 10, j + 17, k + 7, ModBlocks.dreamwoodLeaves);
		chunk.setBlock(i + 10, j + 17, k + 8, ModBlocks.dreamwoodLeaves);
		chunk.setBlock(i + 10, j + 17, k + 9, ModBlocks.dreamwoodLeaves);
		chunk.setBlock(i + 10, j + 17, k + 10, ModBlocks.dreamwoodLeaves);
		chunk.setBlock(i + 10, j + 17, k + 11, ModBlocks.dreamwoodLeaves);
		chunk.setBlock(i + 10, j + 17, k + 12, ModBlocks.dreamwoodLeaves);
		chunk.setBlock(i + 10, j + 18, k + 1, ModBlocks.dreamwoodLeaves);
		chunk.setBlock(i + 10, j + 18, k + 2, ModBlocks.dreamwoodLeaves);
		chunk.setBlock(i + 10, j + 18, k + 3, ModBlocks.dreamwoodLeaves);
		chunk.setBlock(i + 10, j + 18, k + 4, ModBlocks.dreamwoodLeaves);
		chunk.setBlock(i + 10, j + 18, k + 5, ModBlocks.dreamwoodLeaves);
		chunk.setBlock(i + 10, j + 18, k + 6, ModBlocks.dreamwoodLeaves);
		chunk.setBlock(i + 10, j + 18, k + 7, ModBlocks.dreamwoodLeaves);
		chunk.setBlock(i + 10, j + 18, k + 8, ModBlocks.dreamwoodLeaves);
		chunk.setBlock(i + 10, j + 18, k + 9, ModBlocks.dreamwoodLeaves);
		chunk.setBlock(i + 10, j + 18, k + 10, ModBlocks.dreamwoodLeaves);
		chunk.setBlock(i + 10, j + 18, k + 11, ModBlocks.dreamwoodLeaves);
		chunk.setBlock(i + 10, j + 18, k + 12, ModBlocks.dreamwoodLeaves);
		chunk.setBlock(i + 10, j + 18, k + 13, ModBlocks.dreamwoodLeaves);
		chunk.setBlock(i + 10, j + 19, k + 1, ModBlocks.dreamwoodLeaves);
		chunk.setBlock(i + 10, j + 19, k + 2, ModBlocks.dreamwoodLeaves);
		chunk.setBlock(i + 10, j + 19, k + 3, ModBlocks.dreamwoodLeaves);
		chunk.setBlock(i + 10, j + 19, k + 4, ModBlocks.dreamwoodLeaves);
		chunk.setBlock(i + 10, j + 19, k + 5, ModBlocks.dreamwoodLeaves);
		chunk.setBlock(i + 10, j + 19, k + 6, ModBlocks.dreamwoodLeaves);
		chunk.setBlock(i + 10, j + 19, k + 7, ModBlocks.dreamwoodLeaves);
		chunk.setBlock(i + 10, j + 19, k + 8, ModBlocks.dreamwoodLeaves);
		chunk.setBlock(i + 10, j + 19, k + 9, ModBlocks.dreamwoodLeaves);
		chunk.setBlock(i + 10, j + 19, k + 10, ModBlocks.dreamwoodLeaves);
		chunk.setBlock(i + 10, j + 19, k + 11, ModBlocks.dreamwoodLeaves);
		chunk.setBlock(i + 10, j + 19, k + 12, ModBlocks.dreamwoodLeaves);
		chunk.setBlock(i + 10, j + 19, k + 13, ModBlocks.dreamwoodLeaves);
		chunk.setBlock(i + 10, j + 19, k + 14, ModBlocks.dreamwoodLeaves);
		chunk.setBlock(i + 10, j + 20, k + 1, ModBlocks.dreamwoodLeaves);
		chunk.setBlock(i + 10, j + 20, k + 2, ModBlocks.dreamwoodLeaves);
		chunk.setBlock(i + 10, j + 20, k + 3, ModBlocks.dreamwoodLeaves);
		chunk.setBlock(i + 10, j + 20, k + 4, ModBlocks.dreamwoodLeaves);
		chunk.setBlock(i + 10, j + 20, k + 5, ModBlocks.dreamwoodLeaves);
		chunk.setBlock(i + 10, j + 20, k + 6, ModBlocks.dreamwoodLeaves);
		chunk.setBlock(i + 10, j + 20, k + 7, ModBlocks.dreamwoodLeaves);
		chunk.setBlock(i + 10, j + 20, k + 8, ModBlocks.dreamwoodLeaves);
		chunk.setBlock(i + 10, j + 20, k + 9, ModBlocks.dreamwoodLeaves);
		chunk.setBlock(i + 10, j + 20, k + 10, ModBlocks.dreamwoodLeaves);
		chunk.setBlock(i + 10, j + 20, k + 11, ModBlocks.dreamwoodLeaves);
		chunk.setBlock(i + 10, j + 20, k + 12, ModBlocks.dreamwoodLeaves);
		chunk.setBlock(i + 10, j + 20, k + 13, ModBlocks.dreamwoodLeaves);
		chunk.setBlock(i + 10, j + 20, k + 14, ModBlocks.dreamwoodLeaves);
		chunk.setBlock(i + 10, j + 21, k + 2, ModBlocks.dreamwoodLeaves);
		chunk.setBlock(i + 10, j + 21, k + 3, ModBlocks.dreamwoodLeaves);
		chunk.setBlock(i + 10, j + 21, k + 4, ModBlocks.dreamwoodLeaves);
		chunk.setBlock(i + 10, j + 21, k + 5, ModBlocks.dreamwoodLeaves);
		chunk.setBlock(i + 10, j + 21, k + 6, ModBlocks.dreamwoodLeaves);
		chunk.setBlock(i + 10, j + 21, k + 7, ModBlocks.dreamwoodLeaves);
		chunk.setBlock(i + 10, j + 21, k + 8, ModBlocks.dreamwoodLeaves);
		chunk.setBlock(i + 10, j + 21, k + 9, ModBlocks.dreamwoodLeaves);
		chunk.setBlock(i + 10, j + 21, k + 10, ModBlocks.dreamwoodLeaves);
		chunk.setBlock(i + 10, j + 21, k + 11, ModBlocks.dreamwoodLeaves);
		chunk.setBlock(i + 10, j + 21, k + 12, ModBlocks.dreamwoodLeaves);
		chunk.setBlock(i + 10, j + 21, k + 13, ModBlocks.dreamwoodLeaves);
		chunk.setBlock(i + 10, j + 21, k + 14, ModBlocks.dreamwoodLeaves);
		chunk.setBlock(i + 10, j + 22, k + 3, ModBlocks.dreamwoodLeaves);
		chunk.setBlock(i + 10, j + 22, k + 4, ModBlocks.dreamwoodLeaves);
		chunk.setBlock(i + 10, j + 22, k + 5, ModBlocks.dreamwoodLeaves);
		chunk.setBlock(i + 10, j + 22, k + 6, ModBlocks.dreamwoodLeaves);
		chunk.setBlock(i + 10, j + 22, k + 7, ModBlocks.dreamwoodLeaves);
		chunk.setBlock(i + 10, j + 22, k + 8, ModBlocks.dreamwoodLeaves);
		chunk.setBlock(i + 10, j + 22, k + 9, ModBlocks.dreamwoodLeaves);
		chunk.setBlock(i + 10, j + 22, k + 10, ModBlocks.dreamwoodLeaves);
		chunk.setBlock(i + 10, j + 22, k + 11, ModBlocks.dreamwoodLeaves);
		chunk.setBlock(i + 10, j + 22, k + 12, ModBlocks.dreamwoodLeaves);
		chunk.setBlock(i + 10, j + 22, k + 13, ModBlocks.dreamwoodLeaves);
		chunk.setBlock(i + 10, j + 23, k + 7, ModBlocks.dreamwoodLeaves);
		chunk.setBlock(i + 10, j + 23, k + 8, ModBlocks.dreamwoodLeaves);
		chunk.setBlock(i + 10, j + 23, k + 9, ModBlocks.dreamwoodLeaves);
		chunk.setBlock(i + 10, j + 23, k + 10, ModBlocks.dreamwoodLeaves);
		chunk.setBlock(i + 10, j + 23, k + 11, ModBlocks.dreamwoodLeaves);
		chunk.setBlock(i + 10, j + 23, k + 12, ModBlocks.dreamwoodLeaves);
		chunk.setBlock(i + 11, j + 10, k + 7, ModBlocks.dreamwoodLog);
		chunk.setBlock(i + 11, j + 10, k + 8, ModBlocks.dreamwoodLog);
		chunk.setBlock(i + 11, j + 11, k + 7, ModBlocks.dreamwoodLog);
		chunk.setBlock(i + 11, j + 11, k + 8, ModBlocks.dreamwoodLog);
		chunk.setBlock(i + 11, j + 12, k + 7, ModBlocks.dreamwoodLog);
		chunk.setBlock(i + 11, j + 12, k + 8, ModBlocks.dreamwoodLog);
		chunk.setBlock(i + 11, j + 13, k + 7, ModBlocks.dreamwoodLog);
		chunk.setBlock(i + 11, j + 13, k + 8, ModBlocks.dreamwoodLog);
		chunk.setBlock(i + 11, j + 14, k + 7, ModBlocks.dreamwoodLog);
		chunk.setBlock(i + 11, j + 14, k + 8, ModBlocks.dreamwoodLog);
		chunk.setBlock(i + 11, j + 15, k + 6, ModBlocks.dreamwoodLeaves);
		chunk.setBlock(i + 11, j + 15, k + 7, ModBlocks.dreamwoodLeaves);
		chunk.setBlock(i + 11, j + 15, k + 8, ModBlocks.dreamwoodLeaves);
		chunk.setBlock(i + 11, j + 15, k + 9, ModBlocks.dreamwoodLeaves);
		chunk.setBlock(i + 11, j + 15, k + 10, ModBlocks.dreamwoodLeaves);
		chunk.setBlock(i + 11, j + 16, k + 5, ModBlocks.dreamwoodLeaves);
		chunk.setBlock(i + 11, j + 16, k + 6, ModBlocks.dreamwoodLeaves);
		chunk.setBlock(i + 11, j + 16, k + 7, ModBlocks.dreamwoodLeaves);
		chunk.setBlock(i + 11, j + 16, k + 8, ModBlocks.dreamwoodLeaves);
		chunk.setBlock(i + 11, j + 16, k + 9, ModBlocks.dreamwoodLeaves);
		chunk.setBlock(i + 11, j + 16, k + 10, ModBlocks.dreamwoodLeaves);
		chunk.setBlock(i + 11, j + 16, k + 11, ModBlocks.dreamwoodLeaves);
		chunk.setBlock(i + 11, j + 17, k + 4, ModBlocks.dreamwoodLeaves);
		chunk.setBlock(i + 11, j + 17, k + 5, ModBlocks.dreamwoodLeaves);
		chunk.setBlock(i + 11, j + 17, k + 6, ModBlocks.dreamwoodLeaves);
		chunk.setBlock(i + 11, j + 17, k + 7, ModBlocks.dreamwoodLeaves);
		chunk.setBlock(i + 11, j + 17, k + 8, ModBlocks.dreamwoodLeaves);
		chunk.setBlock(i + 11, j + 17, k + 9, ModBlocks.dreamwoodLeaves);
		chunk.setBlock(i + 11, j + 17, k + 10, ModBlocks.dreamwoodLeaves);
		chunk.setBlock(i + 11, j + 17, k + 11, ModBlocks.dreamwoodLeaves);
		chunk.setBlock(i + 11, j + 17, k + 12, ModBlocks.dreamwoodLeaves);
		chunk.setBlock(i + 11, j + 18, k + 3, ModBlocks.dreamwoodLeaves);
		chunk.setBlock(i + 11, j + 18, k + 4, ModBlocks.dreamwoodLeaves);
		chunk.setBlock(i + 11, j + 18, k + 5, ModBlocks.dreamwoodLeaves);
		chunk.setBlock(i + 11, j + 18, k + 6, ModBlocks.dreamwoodLeaves);
		chunk.setBlock(i + 11, j + 18, k + 7, ModBlocks.dreamwoodLeaves);
		chunk.setBlock(i + 11, j + 18, k + 8, ModBlocks.dreamwoodLeaves);
		chunk.setBlock(i + 11, j + 18, k + 9, ModBlocks.dreamwoodLeaves);
		chunk.setBlock(i + 11, j + 18, k + 10, ModBlocks.dreamwoodLeaves);
		chunk.setBlock(i + 11, j + 18, k + 11, ModBlocks.dreamwoodLeaves);
		chunk.setBlock(i + 11, j + 18, k + 12, ModBlocks.dreamwoodLeaves);
		chunk.setBlock(i + 11, j + 19, k + 2, ModBlocks.dreamwoodLeaves);
		chunk.setBlock(i + 11, j + 19, k + 3, ModBlocks.dreamwoodLeaves);
		chunk.setBlock(i + 11, j + 19, k + 4, ModBlocks.dreamwoodLeaves);
		chunk.setBlock(i + 11, j + 19, k + 5, ModBlocks.dreamwoodLeaves);
		chunk.setBlock(i + 11, j + 19, k + 6, ModBlocks.dreamwoodLeaves);
		chunk.setBlock(i + 11, j + 19, k + 7, ModBlocks.dreamwoodLeaves);
		chunk.setBlock(i + 11, j + 19, k + 8, ModBlocks.dreamwoodLeaves);
		chunk.setBlock(i + 11, j + 19, k + 9, ModBlocks.dreamwoodLeaves);
		chunk.setBlock(i + 11, j + 19, k + 10, ModBlocks.dreamwoodLeaves);
		chunk.setBlock(i + 11, j + 19, k + 11, ModBlocks.dreamwoodLeaves);
		chunk.setBlock(i + 11, j + 19, k + 12, ModBlocks.dreamwoodLeaves);
		chunk.setBlock(i + 11, j + 20, k + 3, ModBlocks.dreamwoodLeaves);
		chunk.setBlock(i + 11, j + 20, k + 4, ModBlocks.dreamwoodLeaves);
		chunk.setBlock(i + 11, j + 20, k + 5, ModBlocks.dreamwoodLeaves);
		chunk.setBlock(i + 11, j + 20, k + 6, ModBlocks.dreamwoodLeaves);
		chunk.setBlock(i + 11, j + 20, k + 7, ModBlocks.dreamwoodLeaves);
		chunk.setBlock(i + 11, j + 20, k + 8, ModBlocks.dreamwoodLeaves);
		chunk.setBlock(i + 11, j + 20, k + 9, ModBlocks.dreamwoodLeaves);
		chunk.setBlock(i + 11, j + 20, k + 10, ModBlocks.dreamwoodLeaves);
		chunk.setBlock(i + 11, j + 20, k + 11, ModBlocks.dreamwoodLeaves);
		chunk.setBlock(i + 11, j + 20, k + 12, ModBlocks.dreamwoodLeaves);
		chunk.setBlock(i + 11, j + 20, k + 13, ModBlocks.dreamwoodLeaves);
		chunk.setBlock(i + 11, j + 21, k + 4, ModBlocks.dreamwoodLeaves);
		chunk.setBlock(i + 11, j + 21, k + 5, ModBlocks.dreamwoodLeaves);
		chunk.setBlock(i + 11, j + 21, k + 6, ModBlocks.dreamwoodLeaves);
		chunk.setBlock(i + 11, j + 21, k + 7, ModBlocks.dreamwoodLeaves);
		chunk.setBlock(i + 11, j + 21, k + 8, ModBlocks.dreamwoodLeaves);
		chunk.setBlock(i + 11, j + 21, k + 9, ModBlocks.dreamwoodLeaves);
		chunk.setBlock(i + 11, j + 21, k + 10, ModBlocks.dreamwoodLeaves);
		chunk.setBlock(i + 11, j + 21, k + 11, ModBlocks.dreamwoodLeaves);
		chunk.setBlock(i + 11, j + 21, k + 12, ModBlocks.dreamwoodLeaves);
		chunk.setBlock(i + 11, j + 22, k + 5, ModBlocks.dreamwoodLeaves);
		chunk.setBlock(i + 11, j + 22, k + 6, ModBlocks.dreamwoodLeaves);
		chunk.setBlock(i + 11, j + 22, k + 7, ModBlocks.dreamwoodLeaves);
		chunk.setBlock(i + 11, j + 22, k + 8, ModBlocks.dreamwoodLeaves);
		chunk.setBlock(i + 11, j + 22, k + 9, ModBlocks.dreamwoodLeaves);
		chunk.setBlock(i + 11, j + 22, k + 10, ModBlocks.dreamwoodLeaves);
		chunk.setBlock(i + 11, j + 22, k + 11, ModBlocks.dreamwoodLeaves);
		chunk.setBlock(i + 11, j + 23, k + 6, ModBlocks.dreamwoodLeaves);
		chunk.setBlock(i + 11, j + 23, k + 7, ModBlocks.dreamwoodLeaves);
		chunk.setBlock(i + 11, j + 23, k + 8, ModBlocks.dreamwoodLeaves);
		chunk.setBlock(i + 11, j + 23, k + 9, ModBlocks.dreamwoodLeaves);
		chunk.setBlock(i + 11, j + 23, k + 10, ModBlocks.dreamwoodLeaves);
		chunk.setBlock(i + 12, j + 10, k + 7, ModBlocks.dreamwoodLog);
		chunk.setBlock(i + 12, j + 10, k + 8, ModBlocks.dreamwoodLog);
		chunk.setBlock(i + 12, j + 11, k + 7, ModBlocks.dreamwoodLog);
		chunk.setBlock(i + 12, j + 11, k + 8, ModBlocks.dreamwoodLog);
		chunk.setBlock(i + 12, j + 12, k + 7, ModBlocks.dreamwoodLog);
		chunk.setBlock(i + 12, j + 12, k + 8, ModBlocks.dreamwoodLog);
		chunk.setBlock(i + 12, j + 13, k + 7, ModBlocks.dreamwoodLog);
		chunk.setBlock(i + 12, j + 13, k + 8, ModBlocks.dreamwoodLog);
		chunk.setBlock(i + 12, j + 14, k + 7, ModBlocks.dreamwoodLog);
		chunk.setBlock(i + 12, j + 14, k + 8, ModBlocks.dreamwoodLog);
		chunk.setBlock(i + 12, j + 15, k + 7, ModBlocks.dreamwoodLeaves);
		chunk.setBlock(i + 12, j + 15, k + 8, ModBlocks.dreamwoodLeaves);
		chunk.setBlock(i + 12, j + 15, k + 9, ModBlocks.dreamwoodLeaves);
		chunk.setBlock(i + 12, j + 16, k + 5, ModBlocks.dreamwoodLeaves);
		chunk.setBlock(i + 12, j + 16, k + 6, ModBlocks.dreamwoodLeaves);
		chunk.setBlock(i + 12, j + 16, k + 7, ModBlocks.dreamwoodLeaves);
		chunk.setBlock(i + 12, j + 16, k + 8, ModBlocks.dreamwoodLeaves);
		chunk.setBlock(i + 12, j + 16, k + 9, ModBlocks.dreamwoodLeaves);
		chunk.setBlock(i + 12, j + 16, k + 10, ModBlocks.dreamwoodLeaves);
		chunk.setBlock(i + 12, j + 16, k + 11, ModBlocks.dreamwoodLeaves);
		chunk.setBlock(i + 12, j + 17, k + 5, ModBlocks.dreamwoodLeaves);
		chunk.setBlock(i + 12, j + 17, k + 6, ModBlocks.dreamwoodLeaves);
		chunk.setBlock(i + 12, j + 17, k + 7, ModBlocks.dreamwoodLeaves);
		chunk.setBlock(i + 12, j + 17, k + 8, ModBlocks.dreamwoodLeaves);
		chunk.setBlock(i + 12, j + 17, k + 9, ModBlocks.dreamwoodLeaves);
		chunk.setBlock(i + 12, j + 17, k + 10, ModBlocks.dreamwoodLeaves);
		chunk.setBlock(i + 12, j + 17, k + 11, ModBlocks.dreamwoodLeaves);
		chunk.setBlock(i + 12, j + 18, k + 4, ModBlocks.dreamwoodLeaves);
		chunk.setBlock(i + 12, j + 18, k + 5, ModBlocks.dreamwoodLeaves);
		chunk.setBlock(i + 12, j + 18, k + 6, ModBlocks.dreamwoodLeaves);
		chunk.setBlock(i + 12, j + 18, k + 7, ModBlocks.dreamwoodLeaves);
		chunk.setBlock(i + 12, j + 18, k + 8, ModBlocks.dreamwoodLeaves);
		chunk.setBlock(i + 12, j + 18, k + 9, ModBlocks.dreamwoodLeaves);
		chunk.setBlock(i + 12, j + 18, k + 10, ModBlocks.dreamwoodLeaves);
		chunk.setBlock(i + 12, j + 18, k + 11, ModBlocks.dreamwoodLeaves);
		chunk.setBlock(i + 12, j + 18, k + 12, ModBlocks.dreamwoodLeaves);
		chunk.setBlock(i + 12, j + 19, k + 4, ModBlocks.dreamwoodLeaves);
		chunk.setBlock(i + 12, j + 19, k + 5, ModBlocks.dreamwoodLeaves);
		chunk.setBlock(i + 12, j + 19, k + 6, ModBlocks.dreamwoodLeaves);
		chunk.setBlock(i + 12, j + 19, k + 7, ModBlocks.dreamwoodLeaves);
		chunk.setBlock(i + 12, j + 19, k + 8, ModBlocks.dreamwoodLeaves);
		chunk.setBlock(i + 12, j + 19, k + 9, ModBlocks.dreamwoodLeaves);
		chunk.setBlock(i + 12, j + 19, k + 10, ModBlocks.dreamwoodLeaves);
		chunk.setBlock(i + 12, j + 19, k + 11, ModBlocks.dreamwoodLeaves);
		chunk.setBlock(i + 12, j + 19, k + 12, ModBlocks.dreamwoodLeaves);
		chunk.setBlock(i + 12, j + 20, k + 4, ModBlocks.dreamwoodLeaves);
		chunk.setBlock(i + 12, j + 20, k + 5, ModBlocks.dreamwoodLeaves);
		chunk.setBlock(i + 12, j + 20, k + 6, ModBlocks.dreamwoodLeaves);
		chunk.setBlock(i + 12, j + 20, k + 7, ModBlocks.dreamwoodLeaves);
		chunk.setBlock(i + 12, j + 20, k + 8, ModBlocks.dreamwoodLeaves);
		chunk.setBlock(i + 12, j + 20, k + 9, ModBlocks.dreamwoodLeaves);
		chunk.setBlock(i + 12, j + 20, k + 10, ModBlocks.dreamwoodLeaves);
		chunk.setBlock(i + 12, j + 20, k + 11, ModBlocks.dreamwoodLeaves);
		chunk.setBlock(i + 12, j + 20, k + 12, ModBlocks.dreamwoodLeaves);
		chunk.setBlock(i + 12, j + 21, k + 5, ModBlocks.dreamwoodLeaves);
		chunk.setBlock(i + 12, j + 21, k + 6, ModBlocks.dreamwoodLeaves);
		chunk.setBlock(i + 12, j + 21, k + 7, ModBlocks.dreamwoodLeaves);
		chunk.setBlock(i + 12, j + 21, k + 8, ModBlocks.dreamwoodLeaves);
		chunk.setBlock(i + 12, j + 21, k + 9, ModBlocks.dreamwoodLeaves);
		chunk.setBlock(i + 12, j + 21, k + 10, ModBlocks.dreamwoodLeaves);
		chunk.setBlock(i + 12, j + 21, k + 11, ModBlocks.dreamwoodLeaves);
		chunk.setBlock(i + 12, j + 22, k + 5, ModBlocks.dreamwoodLeaves);
		chunk.setBlock(i + 12, j + 22, k + 6, ModBlocks.dreamwoodLeaves);
		chunk.setBlock(i + 12, j + 22, k + 7, ModBlocks.dreamwoodLeaves);
		chunk.setBlock(i + 12, j + 22, k + 8, ModBlocks.dreamwoodLeaves);
		chunk.setBlock(i + 12, j + 22, k + 9, ModBlocks.dreamwoodLeaves);
		chunk.setBlock(i + 12, j + 22, k + 10, ModBlocks.dreamwoodLeaves);
		chunk.setBlock(i + 12, j + 22, k + 11, ModBlocks.dreamwoodLeaves);
		chunk.setBlock(i + 12, j + 23, k + 7, ModBlocks.dreamwoodLeaves);
		chunk.setBlock(i + 12, j + 23, k + 8, ModBlocks.dreamwoodLeaves);
		chunk.setBlock(i + 12, j + 23, k + 9, ModBlocks.dreamwoodLeaves);
		chunk.setBlock(i + 13, j + 15, k + 8, ModBlocks.dreamwoodLeaves);
		chunk.setBlock(i + 13, j + 16, k + 6, ModBlocks.dreamwoodLeaves);
		chunk.setBlock(i + 13, j + 16, k + 7, ModBlocks.dreamwoodLeaves);
		chunk.setBlock(i + 13, j + 16, k + 8, ModBlocks.dreamwoodLeaves);
		chunk.setBlock(i + 13, j + 16, k + 9, ModBlocks.dreamwoodLeaves);
		chunk.setBlock(i + 13, j + 16, k + 10, ModBlocks.dreamwoodLeaves);
		chunk.setBlock(i + 13, j + 17, k + 5, ModBlocks.dreamwoodLeaves);
		chunk.setBlock(i + 13, j + 17, k + 6, ModBlocks.dreamwoodLeaves);
		chunk.setBlock(i + 13, j + 17, k + 7, ModBlocks.dreamwoodLeaves);
		chunk.setBlock(i + 13, j + 17, k + 8, ModBlocks.dreamwoodLeaves);
		chunk.setBlock(i + 13, j + 17, k + 9, ModBlocks.dreamwoodLeaves);
		chunk.setBlock(i + 13, j + 17, k + 10, ModBlocks.dreamwoodLeaves);
		chunk.setBlock(i + 13, j + 17, k + 11, ModBlocks.dreamwoodLeaves);
		chunk.setBlock(i + 13, j + 18, k + 5, ModBlocks.dreamwoodLeaves);
		chunk.setBlock(i + 13, j + 18, k + 6, ModBlocks.dreamwoodLeaves);
		chunk.setBlock(i + 13, j + 18, k + 7, ModBlocks.dreamwoodLeaves);
		chunk.setBlock(i + 13, j + 18, k + 8, ModBlocks.dreamwoodLeaves);
		chunk.setBlock(i + 13, j + 18, k + 9, ModBlocks.dreamwoodLeaves);
		chunk.setBlock(i + 13, j + 18, k + 10, ModBlocks.dreamwoodLeaves);
		chunk.setBlock(i + 13, j + 18, k + 11, ModBlocks.dreamwoodLeaves);
		chunk.setBlock(i + 13, j + 19, k + 4, ModBlocks.dreamwoodLeaves);
		chunk.setBlock(i + 13, j + 19, k + 5, ModBlocks.dreamwoodLeaves);
		chunk.setBlock(i + 13, j + 19, k + 6, ModBlocks.dreamwoodLeaves);
		chunk.setBlock(i + 13, j + 19, k + 7, ModBlocks.dreamwoodLeaves);
		chunk.setBlock(i + 13, j + 19, k + 8, ModBlocks.dreamwoodLeaves);
		chunk.setBlock(i + 13, j + 19, k + 9, ModBlocks.dreamwoodLeaves);
		chunk.setBlock(i + 13, j + 19, k + 10, ModBlocks.dreamwoodLeaves);
		chunk.setBlock(i + 13, j + 19, k + 11, ModBlocks.dreamwoodLeaves);
		chunk.setBlock(i + 13, j + 19, k + 12, ModBlocks.dreamwoodLeaves);
		chunk.setBlock(i + 13, j + 20, k + 5, ModBlocks.dreamwoodLeaves);
		chunk.setBlock(i + 13, j + 20, k + 6, ModBlocks.dreamwoodLeaves);
		chunk.setBlock(i + 13, j + 20, k + 7, ModBlocks.dreamwoodLeaves);
		chunk.setBlock(i + 13, j + 20, k + 8, ModBlocks.dreamwoodLeaves);
		chunk.setBlock(i + 13, j + 20, k + 9, ModBlocks.dreamwoodLeaves);
		chunk.setBlock(i + 13, j + 20, k + 10, ModBlocks.dreamwoodLeaves);
		chunk.setBlock(i + 13, j + 20, k + 11, ModBlocks.dreamwoodLeaves);
		chunk.setBlock(i + 13, j + 21, k + 5, ModBlocks.dreamwoodLeaves);
		chunk.setBlock(i + 13, j + 21, k + 6, ModBlocks.dreamwoodLeaves);
		chunk.setBlock(i + 13, j + 21, k + 7, ModBlocks.dreamwoodLeaves);
		chunk.setBlock(i + 13, j + 21, k + 8, ModBlocks.dreamwoodLeaves);
		chunk.setBlock(i + 13, j + 21, k + 9, ModBlocks.dreamwoodLeaves);
		chunk.setBlock(i + 13, j + 21, k + 10, ModBlocks.dreamwoodLeaves);
		chunk.setBlock(i + 13, j + 21, k + 11, ModBlocks.dreamwoodLeaves);
		chunk.setBlock(i + 13, j + 22, k + 6, ModBlocks.dreamwoodLeaves);
		chunk.setBlock(i + 13, j + 22, k + 7, ModBlocks.dreamwoodLeaves);
		chunk.setBlock(i + 13, j + 22, k + 8, ModBlocks.dreamwoodLeaves);
		chunk.setBlock(i + 13, j + 22, k + 9, ModBlocks.dreamwoodLeaves);
		chunk.setBlock(i + 13, j + 22, k + 10, ModBlocks.dreamwoodLeaves);
		chunk.setBlock(i + 13, j + 23, k + 8, ModBlocks.dreamwoodLeaves);
		chunk.setBlock(i + 14, j + 16, k + 7, ModBlocks.dreamwoodLeaves);
		chunk.setBlock(i + 14, j + 16, k + 8, ModBlocks.dreamwoodLeaves);
		chunk.setBlock(i + 14, j + 16, k + 9, ModBlocks.dreamwoodLeaves);
		chunk.setBlock(i + 14, j + 17, k + 6, ModBlocks.dreamwoodLeaves);
		chunk.setBlock(i + 14, j + 17, k + 7, ModBlocks.dreamwoodLeaves);
		chunk.setBlock(i + 14, j + 17, k + 8, ModBlocks.dreamwoodLeaves);
		chunk.setBlock(i + 14, j + 17, k + 9, ModBlocks.dreamwoodLeaves);
		chunk.setBlock(i + 14, j + 17, k + 10, ModBlocks.dreamwoodLeaves);
		chunk.setBlock(i + 14, j + 18, k + 5, ModBlocks.dreamwoodLeaves);
		chunk.setBlock(i + 14, j + 18, k + 6, ModBlocks.dreamwoodLeaves);
		chunk.setBlock(i + 14, j + 18, k + 7, ModBlocks.dreamwoodLeaves);
		chunk.setBlock(i + 14, j + 18, k + 8, ModBlocks.dreamwoodLeaves);
		chunk.setBlock(i + 14, j + 18, k + 9, ModBlocks.dreamwoodLeaves);
		chunk.setBlock(i + 14, j + 18, k + 10, ModBlocks.dreamwoodLeaves);
		chunk.setBlock(i + 14, j + 18, k + 11, ModBlocks.dreamwoodLeaves);
		chunk.setBlock(i + 14, j + 19, k + 5, ModBlocks.dreamwoodLeaves);
		chunk.setBlock(i + 14, j + 19, k + 6, ModBlocks.dreamwoodLeaves);
		chunk.setBlock(i + 14, j + 19, k + 7, ModBlocks.dreamwoodLeaves);
		chunk.setBlock(i + 14, j + 19, k + 8, ModBlocks.dreamwoodLeaves);
		chunk.setBlock(i + 14, j + 19, k + 9, ModBlocks.dreamwoodLeaves);
		chunk.setBlock(i + 14, j + 19, k + 10, ModBlocks.dreamwoodLeaves);
		chunk.setBlock(i + 14, j + 19, k + 11, ModBlocks.dreamwoodLeaves);
		chunk.setBlock(i + 14, j + 20, k + 5, ModBlocks.dreamwoodLeaves);
		chunk.setBlock(i + 14, j + 20, k + 6, ModBlocks.dreamwoodLeaves);
		chunk.setBlock(i + 14, j + 20, k + 7, ModBlocks.dreamwoodLeaves);
		chunk.setBlock(i + 14, j + 20, k + 8, ModBlocks.dreamwoodLeaves);
		chunk.setBlock(i + 14, j + 20, k + 9, ModBlocks.dreamwoodLeaves);
		chunk.setBlock(i + 14, j + 20, k + 10, ModBlocks.dreamwoodLeaves);
		chunk.setBlock(i + 14, j + 20, k + 11, ModBlocks.dreamwoodLeaves);
		chunk.setBlock(i + 14, j + 21, k + 6, ModBlocks.dreamwoodLeaves);
		chunk.setBlock(i + 14, j + 21, k + 7, ModBlocks.dreamwoodLeaves);
		chunk.setBlock(i + 14, j + 21, k + 8, ModBlocks.dreamwoodLeaves);
		chunk.setBlock(i + 14, j + 21, k + 9, ModBlocks.dreamwoodLeaves);
		chunk.setBlock(i + 14, j + 21, k + 10, ModBlocks.dreamwoodLeaves);
		chunk.setBlock(i + 14, j + 22, k + 7, ModBlocks.dreamwoodLeaves);
		chunk.setBlock(i + 14, j + 22, k + 8, ModBlocks.dreamwoodLeaves);
		chunk.setBlock(i + 14, j + 22, k + 9, ModBlocks.dreamwoodLeaves);
		chunk.setBlock(i + 15, j + 17, k + 8, ModBlocks.dreamwoodLeaves);
		chunk.setBlock(i + 15, j + 18, k + 7, ModBlocks.dreamwoodLeaves);
		chunk.setBlock(i + 15, j + 18, k + 8, ModBlocks.dreamwoodLeaves);
		chunk.setBlock(i + 15, j + 18, k + 9, ModBlocks.dreamwoodLeaves);
		chunk.setBlock(i + 15, j + 19, k + 6, ModBlocks.dreamwoodLeaves);
		chunk.setBlock(i + 15, j + 19, k + 7, ModBlocks.dreamwoodLeaves);
		chunk.setBlock(i + 15, j + 19, k + 8, ModBlocks.dreamwoodLeaves);
		chunk.setBlock(i + 15, j + 19, k + 9, ModBlocks.dreamwoodLeaves);
		chunk.setBlock(i + 15, j + 19, k + 10, ModBlocks.dreamwoodLeaves);
		chunk.setBlock(i + 15, j + 20, k + 7, ModBlocks.dreamwoodLeaves);
		chunk.setBlock(i + 15, j + 20, k + 8, ModBlocks.dreamwoodLeaves);
		chunk.setBlock(i + 15, j + 20, k + 9, ModBlocks.dreamwoodLeaves);
		chunk.setBlock(i + 15, j + 21, k + 8, ModBlocks.dreamwoodLeaves);
	}
}