package divinerpg.dimensions.vethea.layer1;
import divinerpg.dimensions.vethea.IVetheanStructure;
import divinerpg.dimensions.vethea.VetheaChunk;
import divinerpg.registry.ModBlocks;

public class Tree4 implements IVetheanStructure {

public void generate(VetheaChunk chunk, int i, int j, int k) {

		chunk.setBlock(i + 0, j + 6, k + 3, ModBlocks.firewoodLeaves);
		chunk.setBlock(i + 0, j + 7, k + 0, ModBlocks.firewoodLeaves);
		chunk.setBlock(i + 0, j + 7, k + 3, ModBlocks.firewoodLeaves);
		chunk.setBlock(i + 0, j + 8, k + 0, ModBlocks.firewoodLeaves);
		chunk.setBlock(i + 0, j + 8, k + 2, ModBlocks.firewoodLeaves);
		chunk.setBlock(i + 0, j + 8, k + 3, ModBlocks.firewoodLeaves);
		chunk.setBlock(i + 0, j + 9, k + 0, ModBlocks.firewoodLeaves);
		chunk.setBlock(i + 0, j + 9, k + 1, ModBlocks.firewoodLeaves);
		chunk.setBlock(i + 0, j + 9, k + 2, ModBlocks.firewoodLeaves);
		chunk.setBlock(i + 0, j + 10, k + 0, ModBlocks.firewoodLeaves);
		chunk.setBlock(i + 0, j + 10, k + 1, ModBlocks.firewoodLeaves);
		chunk.setBlock(i + 0, j + 10, k + 2, ModBlocks.firewoodLeaves);
		chunk.setBlock(i + 0, j + 10, k + 3, ModBlocks.firewoodLeaves);
		chunk.setBlock(i + 0, j + 11, k + 0, ModBlocks.firewoodLeaves);
		chunk.setBlock(i + 0, j + 11, k + 3, ModBlocks.firewoodLeaves);
		chunk.setBlock(i + 0, j + 12, k + 0, ModBlocks.firewoodLeaves);
		chunk.setBlock(i + 0, j + 12, k + 3, ModBlocks.firewoodLeaves);
		chunk.setBlock(i + 0, j + 13, k + 0, ModBlocks.firewoodLeaves);
		chunk.setBlock(i + 0, j + 13, k + 1, ModBlocks.firewoodLeaves);
		chunk.setBlock(i + 0, j + 13, k + 2, ModBlocks.firewoodLeaves);
		chunk.setBlock(i + 0, j + 13, k + 3, ModBlocks.firewoodLeaves);
		chunk.setBlock(i + 0, j + 13, k + 4, ModBlocks.firewoodLeaves);
		chunk.setBlock(i + 0, j + 13, k + 5, ModBlocks.firewoodLeaves);
		chunk.setBlock(i + 1, j + 13, k + 0, ModBlocks.firewoodLeaves);
		chunk.setBlock(i + 1, j + 13, k + 5, ModBlocks.firewoodLeaves);
		chunk.setBlock(i + 1, j + 14, k + 1, ModBlocks.firewoodLeaves);
		chunk.setBlock(i + 1, j + 14, k + 2, ModBlocks.firewoodLeaves);
		chunk.setBlock(i + 1, j + 14, k + 3, ModBlocks.firewoodLeaves);
		chunk.setBlock(i + 1, j + 14, k + 4, ModBlocks.firewoodLeaves);
		chunk.setBlock(i + 2, j + 0, k + 2, ModBlocks.firewoodLog);
		chunk.setBlock(i + 2, j + 0, k + 3, ModBlocks.firewoodLog);
		chunk.setBlock(i + 2, j + 1, k + 2, ModBlocks.firewoodLog);
		chunk.setBlock(i + 2, j + 1, k + 3, ModBlocks.firewoodLog);
		chunk.setBlock(i + 2, j + 2, k + 2, ModBlocks.firewoodLog);
		chunk.setBlock(i + 2, j + 2, k + 3, ModBlocks.firewoodLog);
		chunk.setBlock(i + 2, j + 3, k + 2, ModBlocks.firewoodLog);
		chunk.setBlock(i + 2, j + 3, k + 3, ModBlocks.firewoodLog);
		chunk.setBlock(i + 2, j + 4, k + 2, ModBlocks.firewoodLog);
		chunk.setBlock(i + 2, j + 4, k + 3, ModBlocks.firewoodLog);
		chunk.setBlock(i + 2, j + 5, k + 2, ModBlocks.firewoodLog);
		chunk.setBlock(i + 2, j + 5, k + 3, ModBlocks.firewoodLog);
		chunk.setBlock(i + 2, j + 6, k + 2, ModBlocks.firewoodLog);
		chunk.setBlock(i + 2, j + 6, k + 3, ModBlocks.firewoodLog);
		chunk.setBlock(i + 2, j + 7, k + 2, ModBlocks.firewoodLog);
		chunk.setBlock(i + 2, j + 7, k + 3, ModBlocks.firewoodLog);
		chunk.setBlock(i + 2, j + 7, k + 5, ModBlocks.firewoodLeaves);
		chunk.setBlock(i + 2, j + 8, k + 2, ModBlocks.firewoodLog);
		chunk.setBlock(i + 2, j + 8, k + 3, ModBlocks.firewoodLog);
		chunk.setBlock(i + 2, j + 8, k + 5, ModBlocks.firewoodLeaves);
		chunk.setBlock(i + 2, j + 9, k + 2, ModBlocks.firewoodLog);
		chunk.setBlock(i + 2, j + 9, k + 3, ModBlocks.firewoodLog);
		chunk.setBlock(i + 2, j + 10, k + 0, ModBlocks.firewoodLeaves);
		chunk.setBlock(i + 2, j + 10, k + 2, ModBlocks.firewoodLog);
		chunk.setBlock(i + 2, j + 10, k + 3, ModBlocks.firewoodLog);
		chunk.setBlock(i + 2, j + 11, k + 0, ModBlocks.firewoodLeaves);
		chunk.setBlock(i + 2, j + 11, k + 2, ModBlocks.firewoodLog);
		chunk.setBlock(i + 2, j + 11, k + 3, ModBlocks.firewoodLog);
		chunk.setBlock(i + 2, j + 11, k + 5, ModBlocks.firewoodLeaves);
		chunk.setBlock(i + 2, j + 12, k + 2, ModBlocks.firewoodLog);
		chunk.setBlock(i + 2, j + 12, k + 3, ModBlocks.firewoodLog);
		chunk.setBlock(i + 2, j + 12, k + 5, ModBlocks.firewoodLeaves);
		chunk.setBlock(i + 2, j + 13, k + 0, ModBlocks.firewoodLeaves);
		chunk.setBlock(i + 2, j + 13, k + 2, ModBlocks.firewoodLog);
		chunk.setBlock(i + 2, j + 13, k + 3, ModBlocks.firewoodLog);
		chunk.setBlock(i + 2, j + 13, k + 5, ModBlocks.firewoodLeaves);
		chunk.setBlock(i + 2, j + 14, k + 1, ModBlocks.firewoodLeaves);
		chunk.setBlock(i + 2, j + 14, k + 2, ModBlocks.firewoodLeaves);
		chunk.setBlock(i + 2, j + 14, k + 3, ModBlocks.firewoodLeaves);
		chunk.setBlock(i + 2, j + 14, k + 4, ModBlocks.firewoodLeaves);
		chunk.setBlock(i + 2, j + 15, k + 2, ModBlocks.firewoodLeaves);
		chunk.setBlock(i + 2, j + 15, k + 3, ModBlocks.firewoodLeaves);
		chunk.setBlock(i + 3, j + 0, k + 2, ModBlocks.firewoodLog);
		chunk.setBlock(i + 3, j + 0, k + 3, ModBlocks.firewoodLog);
		chunk.setBlock(i + 3, j + 1, k + 2, ModBlocks.firewoodLog);
		chunk.setBlock(i + 3, j + 1, k + 3, ModBlocks.firewoodLog);
		chunk.setBlock(i + 3, j + 2, k + 2, ModBlocks.firewoodLog);
		chunk.setBlock(i + 3, j + 2, k + 3, ModBlocks.firewoodLog);
		chunk.setBlock(i + 3, j + 3, k + 2, ModBlocks.firewoodLog);
		chunk.setBlock(i + 3, j + 3, k + 3, ModBlocks.firewoodLog);
		chunk.setBlock(i + 3, j + 4, k + 2, ModBlocks.firewoodLog);
		chunk.setBlock(i + 3, j + 4, k + 3, ModBlocks.firewoodLog);
		chunk.setBlock(i + 3, j + 5, k + 2, ModBlocks.firewoodLog);
		chunk.setBlock(i + 3, j + 5, k + 3, ModBlocks.firewoodLog);
		chunk.setBlock(i + 3, j + 6, k + 0, ModBlocks.firewoodLeaves);
		chunk.setBlock(i + 3, j + 6, k + 2, ModBlocks.firewoodLog);
		chunk.setBlock(i + 3, j + 6, k + 3, ModBlocks.firewoodLog);
		chunk.setBlock(i + 3, j + 7, k + 2, ModBlocks.firewoodLog);
		chunk.setBlock(i + 3, j + 7, k + 3, ModBlocks.firewoodLog);
		chunk.setBlock(i + 3, j + 8, k + 2, ModBlocks.firewoodLog);
		chunk.setBlock(i + 3, j + 8, k + 3, ModBlocks.firewoodLog);
		chunk.setBlock(i + 3, j + 8, k + 5, ModBlocks.firewoodLeaves);
		chunk.setBlock(i + 3, j + 9, k + 2, ModBlocks.firewoodLog);
		chunk.setBlock(i + 3, j + 9, k + 3, ModBlocks.firewoodLog);
		chunk.setBlock(i + 3, j + 9, k + 5, ModBlocks.firewoodLeaves);
		chunk.setBlock(i + 3, j + 10, k + 2, ModBlocks.firewoodLog);
		chunk.setBlock(i + 3, j + 10, k + 3, ModBlocks.firewoodLog);
		chunk.setBlock(i + 3, j + 10, k + 5, ModBlocks.firewoodLeaves);
		chunk.setBlock(i + 3, j + 11, k + 0, ModBlocks.firewoodLeaves);
		chunk.setBlock(i + 3, j + 11, k + 2, ModBlocks.firewoodLog);
		chunk.setBlock(i + 3, j + 11, k + 3, ModBlocks.firewoodLog);
		chunk.setBlock(i + 3, j + 11, k + 5, ModBlocks.firewoodLeaves);
		chunk.setBlock(i + 3, j + 12, k + 2, ModBlocks.firewoodLog);
		chunk.setBlock(i + 3, j + 12, k + 3, ModBlocks.firewoodLog);
		chunk.setBlock(i + 3, j + 13, k + 0, ModBlocks.firewoodLeaves);
		chunk.setBlock(i + 3, j + 13, k + 2, ModBlocks.firewoodLog);
		chunk.setBlock(i + 3, j + 13, k + 3, ModBlocks.firewoodLog);
		chunk.setBlock(i + 3, j + 13, k + 5, ModBlocks.firewoodLeaves);
		chunk.setBlock(i + 3, j + 14, k + 1, ModBlocks.firewoodLeaves);
		chunk.setBlock(i + 3, j + 14, k + 2, ModBlocks.firewoodLeaves);
		chunk.setBlock(i + 3, j + 14, k + 3, ModBlocks.firewoodLeaves);
		chunk.setBlock(i + 3, j + 14, k + 4, ModBlocks.firewoodLeaves);
		chunk.setBlock(i + 3, j + 15, k + 2, ModBlocks.firewoodLeaves);
		chunk.setBlock(i + 3, j + 15, k + 3, ModBlocks.firewoodLeaves);
		chunk.setBlock(i + 4, j + 6, k + 0, ModBlocks.firewoodLeaves);
		chunk.setBlock(i + 4, j + 7, k + 0, ModBlocks.firewoodLeaves);
		chunk.setBlock(i + 4, j + 8, k + 0, ModBlocks.firewoodLeaves);
		chunk.setBlock(i + 4, j + 10, k + 0, ModBlocks.firewoodLeaves);
		chunk.setBlock(i + 4, j + 11, k + 0, ModBlocks.firewoodLeaves);
		chunk.setBlock(i + 4, j + 12, k + 0, ModBlocks.firewoodLeaves);
		chunk.setBlock(i + 4, j + 13, k + 0, ModBlocks.firewoodLeaves);
		chunk.setBlock(i + 4, j + 13, k + 5, ModBlocks.firewoodLeaves);
		chunk.setBlock(i + 4, j + 14, k + 1, ModBlocks.firewoodLeaves);
		chunk.setBlock(i + 4, j + 14, k + 2, ModBlocks.firewoodLeaves);
		chunk.setBlock(i + 4, j + 14, k + 3, ModBlocks.firewoodLeaves);
		chunk.setBlock(i + 4, j + 14, k + 4, ModBlocks.firewoodLeaves);
		chunk.setBlock(i + 5, j + 7, k + 4, ModBlocks.firewoodLeaves);
		chunk.setBlock(i + 5, j + 7, k + 5, ModBlocks.firewoodLeaves);
		chunk.setBlock(i + 5, j + 8, k + 0, ModBlocks.firewoodLeaves);
		chunk.setBlock(i + 5, j + 8, k + 4, ModBlocks.firewoodLeaves);
		chunk.setBlock(i + 5, j + 9, k + 0, ModBlocks.firewoodLeaves);
		chunk.setBlock(i + 5, j + 9, k + 4, ModBlocks.firewoodLeaves);
		chunk.setBlock(i + 5, j + 9, k + 5, ModBlocks.firewoodLeaves);
		chunk.setBlock(i + 5, j + 10, k + 0, ModBlocks.firewoodLeaves);
		chunk.setBlock(i + 5, j + 10, k + 5, ModBlocks.firewoodLeaves);
		chunk.setBlock(i + 5, j + 11, k + 4, ModBlocks.firewoodLeaves);
		chunk.setBlock(i + 5, j + 11, k + 5, ModBlocks.firewoodLeaves);
		chunk.setBlock(i + 5, j + 12, k + 4, ModBlocks.firewoodLeaves);
		chunk.setBlock(i + 5, j + 13, k + 0, ModBlocks.firewoodLeaves);
		chunk.setBlock(i + 5, j + 13, k + 1, ModBlocks.firewoodLeaves);
		chunk.setBlock(i + 5, j + 13, k + 2, ModBlocks.firewoodLeaves);
		chunk.setBlock(i + 5, j + 13, k + 3, ModBlocks.firewoodLeaves);
		chunk.setBlock(i + 5, j + 13, k + 4, ModBlocks.firewoodLeaves);
		chunk.setBlock(i + 5, j + 13, k + 5, ModBlocks.firewoodLeaves);
		chunk.setBlock(i + 6, j + 7, k + 2, ModBlocks.firewoodLeaves);
		chunk.setBlock(i + 6, j + 8, k + 1, ModBlocks.firewoodLeaves);
		chunk.setBlock(i + 6, j + 8, k + 2, ModBlocks.firewoodLeaves);
		chunk.setBlock(i + 6, j + 9, k + 1, ModBlocks.firewoodLeaves);
		chunk.setBlock(i + 6, j + 10, k + 1, ModBlocks.firewoodLeaves);
		chunk.setBlock(i + 6, j + 10, k + 2, ModBlocks.firewoodLeaves);
		chunk.setBlock(i + 6, j + 11, k + 2, ModBlocks.firewoodLeaves);
		chunk.setBlock(i + 6, j + 12, k + 2, ModBlocks.firewoodLeaves);
		chunk.setBlock(i + 6, j + 13, k + 2, ModBlocks.firewoodLeaves);
	}
}