/*
*** MADE BY MITHION'S .SCHEMATIC TO JAVA CONVERTING TOOL v1.6 ***
*/

package divinerpg.dimensions.vethea.layer4;
import java.util.Random;

import divinerpg.dimensions.vethea.VetheaWorldGenerator;
import divinerpg.registry.ModBlocks;
import net.minecraft.block.Block;
import net.minecraft.util.math.BlockPos;
import net.minecraft.world.World;
import net.minecraft.world.gen.feature.WorldGenerator;

public class Layer4Tree1 extends VetheaWorldGenerator
{

	public boolean generate(World world, Random rand, int i, int j, int k) {

		setBlock(world, i + 0, j + 3, k + 8, ModBlocks.firewoodLeaves);
		setBlock(world, i + 0, j + 3, k + 9, ModBlocks.firewoodLeaves);
		setBlock(world, i + 0, j + 3, k + 10, ModBlocks.firewoodLeaves);
		setBlock(world, i + 0, j + 4, k + 8, ModBlocks.firewoodLeaves);
		setBlock(world, i + 0, j + 4, k + 9, ModBlocks.firewoodLeaves);
		setBlock(world, i + 0, j + 4, k + 10, ModBlocks.firewoodLeaves);
		setBlock(world, i + 0, j + 5, k + 8, ModBlocks.firewoodLeaves);
		setBlock(world, i + 0, j + 5, k + 9, ModBlocks.firewoodLeaves);
		setBlock(world, i + 0, j + 5, k + 10, ModBlocks.firewoodLeaves);
		setBlock(world, i + 1, j + 2, k + 7, ModBlocks.firewoodLeaves);
		setBlock(world, i + 1, j + 2, k + 8, ModBlocks.firewoodLeaves);
		setBlock(world, i + 1, j + 2, k + 9, ModBlocks.firewoodLeaves);
		setBlock(world, i + 1, j + 2, k + 10, ModBlocks.firewoodLeaves);
		setBlock(world, i + 1, j + 2, k + 11, ModBlocks.firewoodLeaves);
		setBlock(world, i + 1, j + 3, k + 7, ModBlocks.firewoodLeaves);
		setBlock(world, i + 1, j + 3, k + 8, ModBlocks.firewoodLeaves);
		setBlock(world, i + 1, j + 3, k + 9, ModBlocks.firewoodLeaves);
		setBlock(world, i + 1, j + 3, k + 10, ModBlocks.firewoodLeaves);
		setBlock(world, i + 1, j + 3, k + 11, ModBlocks.firewoodLeaves);
		setBlock(world, i + 1, j + 4, k + 7, ModBlocks.firewoodLeaves);
		setBlock(world, i + 1, j + 4, k + 8, ModBlocks.firewoodLeaves);
		setBlock(world, i + 1, j + 4, k + 9, ModBlocks.firewoodLeaves);
		setBlock(world, i + 1, j + 4, k + 10, ModBlocks.firewoodLeaves);
		setBlock(world, i + 1, j + 4, k + 11, ModBlocks.firewoodLeaves);
		setBlock(world, i + 1, j + 5, k + 7, ModBlocks.firewoodLeaves);
		setBlock(world, i + 1, j + 5, k + 8, ModBlocks.firewoodLeaves);
		setBlock(world, i + 1, j + 5, k + 9, ModBlocks.firewoodLeaves);
		setBlock(world, i + 1, j + 5, k + 10, ModBlocks.firewoodLeaves);
		setBlock(world, i + 1, j + 5, k + 11, ModBlocks.firewoodLeaves);
		setBlock(world, i + 1, j + 6, k + 7, ModBlocks.firewoodLeaves);
		setBlock(world, i + 1, j + 6, k + 8, ModBlocks.firewoodLeaves);
		setBlock(world, i + 1, j + 6, k + 9, ModBlocks.firewoodLeaves);
		setBlock(world, i + 1, j + 6, k + 10, ModBlocks.firewoodLeaves);
		setBlock(world, i + 1, j + 6, k + 11, ModBlocks.firewoodLeaves);
		setBlock(world, i + 2, j + 1, k + 8, ModBlocks.firewoodLeaves);
		setBlock(world, i + 2, j + 1, k + 9, ModBlocks.firewoodLeaves);
		setBlock(world, i + 2, j + 1, k + 10, ModBlocks.firewoodLeaves);
		setBlock(world, i + 2, j + 2, k + 7, ModBlocks.firewoodLeaves);
		setBlock(world, i + 2, j + 2, k + 8, ModBlocks.firewoodLeaves);
		setBlock(world, i + 2, j + 2, k + 9, ModBlocks.firewoodLeaves);
		setBlock(world, i + 2, j + 2, k + 10, ModBlocks.firewoodLeaves);
		setBlock(world, i + 2, j + 2, k + 11, ModBlocks.firewoodLeaves);
		setBlock(world, i + 2, j + 3, k + 6, ModBlocks.firewoodLeaves);
		setBlock(world, i + 2, j + 3, k + 7, ModBlocks.firewoodLeaves);
		setBlock(world, i + 2, j + 3, k + 8, ModBlocks.firewoodLeaves);
		setBlock(world, i + 2, j + 3, k + 9, ModBlocks.firewoodLeaves);
		setBlock(world, i + 2, j + 3, k + 10, ModBlocks.firewoodLeaves);
		setBlock(world, i + 2, j + 3, k + 11, ModBlocks.firewoodLeaves);
		setBlock(world, i + 2, j + 3, k + 12, ModBlocks.firewoodLeaves);
		setBlock(world, i + 2, j + 4, k + 6, ModBlocks.firewoodLeaves);
		setBlock(world, i + 2, j + 4, k + 7, ModBlocks.firewoodLeaves);
		setBlock(world, i + 2, j + 4, k + 8, ModBlocks.firewoodLeaves);
		setBlock(world, i + 2, j + 4, k + 9, ModBlocks.firewoodLeaves);
		setBlock(world, i + 2, j + 4, k + 10, ModBlocks.firewoodLeaves);
		setBlock(world, i + 2, j + 4, k + 11, ModBlocks.firewoodLeaves);
		setBlock(world, i + 2, j + 4, k + 12, ModBlocks.firewoodLeaves);
		setBlock(world, i + 2, j + 5, k + 6, ModBlocks.firewoodLeaves);
		setBlock(world, i + 2, j + 5, k + 7, ModBlocks.firewoodLeaves);
		setBlock(world, i + 2, j + 5, k + 8, ModBlocks.firewoodLeaves);
		setBlock(world, i + 2, j + 5, k + 9, ModBlocks.firewoodLeaves);
		setBlock(world, i + 2, j + 5, k + 10, ModBlocks.firewoodLeaves);
		setBlock(world, i + 2, j + 5, k + 11, ModBlocks.firewoodLeaves);
		setBlock(world, i + 2, j + 5, k + 12, ModBlocks.firewoodLeaves);
		setBlock(world, i + 2, j + 6, k + 7, ModBlocks.firewoodLeaves);
		setBlock(world, i + 2, j + 6, k + 8, ModBlocks.firewoodLeaves);
		setBlock(world, i + 2, j + 6, k + 9, ModBlocks.firewoodLeaves);
		setBlock(world, i + 2, j + 6, k + 10, ModBlocks.firewoodLeaves);
		setBlock(world, i + 2, j + 6, k + 11, ModBlocks.firewoodLeaves);
		setBlock(world, i + 2, j + 7, k + 8, ModBlocks.firewoodLeaves);
		setBlock(world, i + 2, j + 7, k + 9, ModBlocks.firewoodLeaves);
		setBlock(world, i + 2, j + 7, k + 10, ModBlocks.firewoodLeaves);
		setBlock(world, i + 3, j + 1, k + 8, ModBlocks.firewoodLeaves);
		setBlock(world, i + 3, j + 1, k + 9, ModBlocks.firewoodLeaves);
		setBlock(world, i + 3, j + 1, k + 10, ModBlocks.firewoodLeaves);
		setBlock(world, i + 3, j + 2, k + 7, ModBlocks.firewoodLeaves);
		setBlock(world, i + 3, j + 2, k + 8, ModBlocks.firewoodLeaves);
		setBlock(world, i + 3, j + 2, k + 9, ModBlocks.firewoodLeaves);
		setBlock(world, i + 3, j + 2, k + 10, ModBlocks.firewoodLeaves);
		setBlock(world, i + 3, j + 2, k + 11, ModBlocks.firewoodLeaves);
		setBlock(world, i + 3, j + 3, k + 6, ModBlocks.firewoodLeaves);
		setBlock(world, i + 3, j + 3, k + 7, ModBlocks.firewoodLeaves);
		setBlock(world, i + 3, j + 3, k + 8, ModBlocks.firewoodLeaves);
		setBlock(world, i + 3, j + 3, k + 9, ModBlocks.firewoodLeaves);
		setBlock(world, i + 3, j + 3, k + 10, ModBlocks.firewoodLeaves);
		setBlock(world, i + 3, j + 3, k + 11, ModBlocks.firewoodLeaves);
		setBlock(world, i + 3, j + 3, k + 12, ModBlocks.firewoodLeaves);
		setBlock(world, i + 3, j + 4, k + 6, ModBlocks.firewoodLeaves);
		setBlock(world, i + 3, j + 4, k + 7, ModBlocks.firewoodLeaves);
		setBlock(world, i + 3, j + 4, k + 8, ModBlocks.firewoodLeaves);
		setBlock(world, i + 3, j + 4, k + 10, ModBlocks.firewoodLeaves);
		setBlock(world, i + 3, j + 4, k + 11, ModBlocks.firewoodLeaves);
		setBlock(world, i + 3, j + 4, k + 12, ModBlocks.firewoodLeaves);
		setBlock(world, i + 3, j + 5, k + 6, ModBlocks.firewoodLeaves);
		setBlock(world, i + 3, j + 5, k + 7, ModBlocks.firewoodLeaves);
		setBlock(world, i + 3, j + 5, k + 8, ModBlocks.firewoodLeaves);
		setBlock(world, i + 3, j + 5, k + 10, ModBlocks.firewoodLeaves);
		setBlock(world, i + 3, j + 5, k + 11, ModBlocks.firewoodLeaves);
		setBlock(world, i + 3, j + 5, k + 12, ModBlocks.firewoodLeaves);
		setBlock(world, i + 3, j + 6, k + 7, ModBlocks.firewoodLeaves);
		setBlock(world, i + 3, j + 6, k + 8, ModBlocks.firewoodLeaves);
		setBlock(world, i + 3, j + 6, k + 10, ModBlocks.firewoodLeaves);
		setBlock(world, i + 3, j + 6, k + 11, ModBlocks.firewoodLeaves);
		setBlock(world, i + 3, j + 7, k + 8, ModBlocks.firewoodLeaves);
		setBlock(world, i + 3, j + 7, k + 9, ModBlocks.firewoodLeaves);
		setBlock(world, i + 3, j + 7, k + 10, ModBlocks.firewoodLeaves);
		setBlock(world, i + 3, j + 8, k + 8, ModBlocks.firewood);
		setBlock(world, i + 3, j + 8, k + 9, ModBlocks.firewood);
		setBlock(world, i + 3, j + 9, k + 8, ModBlocks.firewood);
		setBlock(world, i + 3, j + 9, k + 9, ModBlocks.firewood);
		setBlock(world, i + 3, j + 10, k + 8, ModBlocks.firewood);
		setBlock(world, i + 3, j + 10, k + 9, ModBlocks.firewood);
		setBlock(world, i + 3, j + 11, k + 8, ModBlocks.firewood);
		setBlock(world, i + 3, j + 11, k + 9, ModBlocks.firewood);
		setBlock(world, i + 3, j + 12, k + 8, ModBlocks.firewood);
		setBlock(world, i + 3, j + 12, k + 9, ModBlocks.firewood);
		setBlock(world, i + 4, j + 1, k + 8, ModBlocks.firewoodLeaves);
		setBlock(world, i + 4, j + 1, k + 9, ModBlocks.firewoodLeaves);
		setBlock(world, i + 4, j + 1, k + 10, ModBlocks.firewoodLeaves);
		setBlock(world, i + 4, j + 2, k + 7, ModBlocks.firewoodLeaves);
		setBlock(world, i + 4, j + 2, k + 8, ModBlocks.firewoodLeaves);
		setBlock(world, i + 4, j + 2, k + 10, ModBlocks.firewoodLeaves);
		setBlock(world, i + 4, j + 2, k + 11, ModBlocks.firewoodLeaves);
		setBlock(world, i + 4, j + 3, k + 6, ModBlocks.firewoodLeaves);
		setBlock(world, i + 4, j + 3, k + 7, ModBlocks.firewoodLeaves);
		setBlock(world, i + 4, j + 3, k + 8, ModBlocks.firewoodLeaves);
		setBlock(world, i + 4, j + 3, k + 9, ModBlocks.firewoodLeaves);
		setBlock(world, i + 4, j + 3, k + 10, ModBlocks.firewoodLeaves);
		setBlock(world, i + 4, j + 3, k + 11, ModBlocks.firewoodLeaves);
		setBlock(world, i + 4, j + 3, k + 12, ModBlocks.firewoodLeaves);
		setBlock(world, i + 4, j + 4, k + 6, ModBlocks.firewoodLeaves);
		setBlock(world, i + 4, j + 4, k + 7, ModBlocks.firewoodLeaves);
		setBlock(world, i + 4, j + 4, k + 8, ModBlocks.firewoodLeaves);
		setBlock(world, i + 4, j + 4, k + 9, ModBlocks.firewoodLeaves);
		setBlock(world, i + 4, j + 4, k + 10, ModBlocks.firewoodLeaves);
		setBlock(world, i + 4, j + 4, k + 11, ModBlocks.firewoodLeaves);
		setBlock(world, i + 4, j + 4, k + 12, ModBlocks.firewoodLeaves);
		setBlock(world, i + 4, j + 5, k + 6, ModBlocks.firewoodLeaves);
		setBlock(world, i + 4, j + 5, k + 7, ModBlocks.firewoodLeaves);
		setBlock(world, i + 4, j + 5, k + 8, ModBlocks.firewoodLeaves);
		setBlock(world, i + 4, j + 5, k + 10, ModBlocks.firewoodLeaves);
		setBlock(world, i + 4, j + 5, k + 11, ModBlocks.firewoodLeaves);
		setBlock(world, i + 4, j + 5, k + 12, ModBlocks.firewoodLeaves);
		setBlock(world, i + 4, j + 6, k + 7, ModBlocks.firewoodLeaves);
		setBlock(world, i + 4, j + 6, k + 8, ModBlocks.firewoodLeaves);
		setBlock(world, i + 4, j + 6, k + 9, ModBlocks.firewoodLeaves);
		setBlock(world, i + 4, j + 6, k + 10, ModBlocks.firewoodLeaves);
		setBlock(world, i + 4, j + 6, k + 11, ModBlocks.firewoodLeaves);
		setBlock(world, i + 4, j + 7, k + 8, ModBlocks.firewoodLeaves);
		setBlock(world, i + 4, j + 7, k + 9, ModBlocks.firewoodLeaves);
		setBlock(world, i + 4, j + 7, k + 10, ModBlocks.firewoodLeaves);
		setBlock(world, i + 4, j + 8, k + 8, ModBlocks.firewood);
		setBlock(world, i + 4, j + 8, k + 9, ModBlocks.firewood);
		setBlock(world, i + 4, j + 9, k + 8, ModBlocks.firewood);
		setBlock(world, i + 4, j + 9, k + 9, ModBlocks.firewood);
		setBlock(world, i + 4, j + 10, k + 8, ModBlocks.firewood);
		setBlock(world, i + 4, j + 10, k + 9, ModBlocks.firewood);
		setBlock(world, i + 4, j + 11, k + 8, ModBlocks.firewood);
		setBlock(world, i + 4, j + 11, k + 9, ModBlocks.firewood);
		setBlock(world, i + 4, j + 12, k + 8, ModBlocks.firewood);
		setBlock(world, i + 4, j + 12, k + 9, ModBlocks.firewood);
		setBlock(world, i + 5, j + 2, k + 7, ModBlocks.firewoodLeaves);
		setBlock(world, i + 5, j + 2, k + 8, ModBlocks.firewoodLeaves);
		setBlock(world, i + 5, j + 2, k + 9, ModBlocks.firewoodLeaves);
		setBlock(world, i + 5, j + 2, k + 10, ModBlocks.firewoodLeaves);
		setBlock(world, i + 5, j + 2, k + 11, ModBlocks.firewoodLeaves);
		setBlock(world, i + 5, j + 3, k + 7, ModBlocks.firewoodLeaves);
		setBlock(world, i + 5, j + 3, k + 8, ModBlocks.firewoodLeaves);
		setBlock(world, i + 5, j + 3, k + 9, ModBlocks.firewoodLeaves);
		setBlock(world, i + 5, j + 3, k + 10, ModBlocks.firewoodLeaves);
		setBlock(world, i + 5, j + 3, k + 11, ModBlocks.firewoodLeaves);
		setBlock(world, i + 5, j + 4, k + 7, ModBlocks.firewoodLeaves);
		setBlock(world, i + 5, j + 4, k + 8, ModBlocks.firewoodLeaves);
		setBlock(world, i + 5, j + 4, k + 9, ModBlocks.firewoodLeaves);
		setBlock(world, i + 5, j + 4, k + 10, ModBlocks.firewoodLeaves);
		setBlock(world, i + 5, j + 4, k + 11, ModBlocks.firewoodLeaves);
		setBlock(world, i + 5, j + 5, k + 7, ModBlocks.firewoodLeaves);
		setBlock(world, i + 5, j + 5, k + 8, ModBlocks.firewoodLeaves);
		setBlock(world, i + 5, j + 5, k + 9, ModBlocks.firewoodLeaves);
		setBlock(world, i + 5, j + 5, k + 10, ModBlocks.firewoodLeaves);
		setBlock(world, i + 5, j + 5, k + 11, ModBlocks.firewoodLeaves);
		setBlock(world, i + 5, j + 6, k + 7, ModBlocks.firewoodLeaves);
		setBlock(world, i + 5, j + 6, k + 8, ModBlocks.firewoodLeaves);
		setBlock(world, i + 5, j + 6, k + 9, ModBlocks.firewoodLeaves);
		setBlock(world, i + 5, j + 6, k + 10, ModBlocks.firewoodLeaves);
		setBlock(world, i + 5, j + 6, k + 11, ModBlocks.firewoodLeaves);
		setBlock(world, i + 5, j + 11, k + 8, ModBlocks.firewood);
		setBlock(world, i + 5, j + 11, k + 9, ModBlocks.firewood);
		setBlock(world, i + 5, j + 12, k + 8, ModBlocks.firewood);
		setBlock(world, i + 5, j + 12, k + 9, ModBlocks.firewood);
		setBlock(world, i + 6, j + 0, k + 8, ModBlocks.firewood);
		setBlock(world, i + 6, j + 0, k + 9, ModBlocks.firewood);
		setBlock(world, i + 6, j + 3, k + 8, ModBlocks.firewoodLeaves);
		setBlock(world, i + 6, j + 3, k + 9, ModBlocks.firewoodLeaves);
		setBlock(world, i + 6, j + 3, k + 10, ModBlocks.firewoodLeaves);
		setBlock(world, i + 6, j + 4, k + 2, ModBlocks.firewoodLeaves);
		setBlock(world, i + 6, j + 4, k + 3, ModBlocks.firewoodLeaves);
		setBlock(world, i + 6, j + 4, k + 4, ModBlocks.firewoodLeaves);
		setBlock(world, i + 6, j + 4, k + 8, ModBlocks.firewoodLeaves);
		setBlock(world, i + 6, j + 4, k + 9, ModBlocks.firewoodLeaves);
		setBlock(world, i + 6, j + 4, k + 10, ModBlocks.firewoodLeaves);
		setBlock(world, i + 6, j + 4, k + 13, ModBlocks.firewoodLeaves);
		setBlock(world, i + 6, j + 4, k + 14, ModBlocks.firewoodLeaves);
		setBlock(world, i + 6, j + 4, k + 15, ModBlocks.firewoodLeaves);
		setBlock(world, i + 6, j + 5, k + 2, ModBlocks.firewoodLeaves);
		setBlock(world, i + 6, j + 5, k + 3, ModBlocks.firewoodLeaves);
		setBlock(world, i + 6, j + 5, k + 4, ModBlocks.firewoodLeaves);
		setBlock(world, i + 6, j + 5, k + 8, ModBlocks.firewoodLeaves);
		setBlock(world, i + 6, j + 5, k + 9, ModBlocks.firewoodLeaves);
		setBlock(world, i + 6, j + 5, k + 10, ModBlocks.firewoodLeaves);
		setBlock(world, i + 6, j + 5, k + 13, ModBlocks.firewoodLeaves);
		setBlock(world, i + 6, j + 5, k + 14, ModBlocks.firewoodLeaves);
		setBlock(world, i + 6, j + 5, k + 15, ModBlocks.firewoodLeaves);
		setBlock(world, i + 6, j + 6, k + 2, ModBlocks.firewoodLeaves);
		setBlock(world, i + 6, j + 6, k + 3, ModBlocks.firewoodLeaves);
		setBlock(world, i + 6, j + 6, k + 4, ModBlocks.firewoodLeaves);
		setBlock(world, i + 6, j + 6, k + 13, ModBlocks.firewoodLeaves);
		setBlock(world, i + 6, j + 6, k + 14, ModBlocks.firewoodLeaves);
		setBlock(world, i + 6, j + 6, k + 15, ModBlocks.firewoodLeaves);
		setBlock(world, i + 6, j + 11, k + 8, ModBlocks.firewood);
		setBlock(world, i + 6, j + 11, k + 9, ModBlocks.firewood);
		setBlock(world, i + 6, j + 12, k + 8, ModBlocks.firewood);
		setBlock(world, i + 6, j + 12, k + 9, ModBlocks.firewood);
		setBlock(world, i + 6, j + 13, k + 8, ModBlocks.firewood);
		setBlock(world, i + 6, j + 13, k + 9, ModBlocks.firewood);
		setBlock(world, i + 7, j + 0, k + 7, ModBlocks.firewood);
		setBlock(world, i + 7, j + 0, k + 8, ModBlocks.firewood);
		setBlock(world, i + 7, j + 0, k + 9, ModBlocks.firewood);
		setBlock(world, i + 7, j + 0, k + 10, ModBlocks.firewood);
		setBlock(world, i + 7, j + 1, k + 8, ModBlocks.firewood);
		setBlock(world, i + 7, j + 1, k + 9, ModBlocks.firewood);
		setBlock(world, i + 7, j + 3, k + 1, ModBlocks.firewoodLeaves);
		setBlock(world, i + 7, j + 3, k + 2, ModBlocks.firewoodLeaves);
		setBlock(world, i + 7, j + 3, k + 3, ModBlocks.firewoodLeaves);
		setBlock(world, i + 7, j + 3, k + 4, ModBlocks.firewoodLeaves);
		setBlock(world, i + 7, j + 3, k + 5, ModBlocks.firewoodLeaves);
		setBlock(world, i + 7, j + 3, k + 12, ModBlocks.firewoodLeaves);
		setBlock(world, i + 7, j + 3, k + 13, ModBlocks.firewoodLeaves);
		setBlock(world, i + 7, j + 3, k + 14, ModBlocks.firewoodLeaves);
		setBlock(world, i + 7, j + 3, k + 15, ModBlocks.firewoodLeaves);
		setBlock(world, i + 7, j + 3, k + 16, ModBlocks.firewoodLeaves);
		setBlock(world, i + 7, j + 4, k + 1, ModBlocks.firewoodLeaves);
		setBlock(world, i + 7, j + 4, k + 2, ModBlocks.firewoodLeaves);
		setBlock(world, i + 7, j + 4, k + 3, ModBlocks.firewoodLeaves);
		setBlock(world, i + 7, j + 4, k + 4, ModBlocks.firewoodLeaves);
		setBlock(world, i + 7, j + 4, k + 5, ModBlocks.firewoodLeaves);
		setBlock(world, i + 7, j + 4, k + 12, ModBlocks.firewoodLeaves);
		setBlock(world, i + 7, j + 4, k + 13, ModBlocks.firewoodLeaves);
		setBlock(world, i + 7, j + 4, k + 14, ModBlocks.firewoodLeaves);
		setBlock(world, i + 7, j + 4, k + 15, ModBlocks.firewoodLeaves);
		setBlock(world, i + 7, j + 4, k + 16, ModBlocks.firewoodLeaves);
		setBlock(world, i + 7, j + 5, k + 1, ModBlocks.firewoodLeaves);
		setBlock(world, i + 7, j + 5, k + 2, ModBlocks.firewoodLeaves);
		setBlock(world, i + 7, j + 5, k + 3, ModBlocks.firewoodLeaves);
		setBlock(world, i + 7, j + 5, k + 4, ModBlocks.firewoodLeaves);
		setBlock(world, i + 7, j + 5, k + 5, ModBlocks.firewoodLeaves);
		setBlock(world, i + 7, j + 5, k + 12, ModBlocks.firewoodLeaves);
		setBlock(world, i + 7, j + 5, k + 13, ModBlocks.firewoodLeaves);
		setBlock(world, i + 7, j + 5, k + 14, ModBlocks.firewoodLeaves);
		setBlock(world, i + 7, j + 5, k + 15, ModBlocks.firewoodLeaves);
		setBlock(world, i + 7, j + 5, k + 16, ModBlocks.firewoodLeaves);
		setBlock(world, i + 7, j + 6, k + 1, ModBlocks.firewoodLeaves);
		setBlock(world, i + 7, j + 6, k + 2, ModBlocks.firewoodLeaves);
		setBlock(world, i + 7, j + 6, k + 3, ModBlocks.firewoodLeaves);
		setBlock(world, i + 7, j + 6, k + 4, ModBlocks.firewoodLeaves);
		setBlock(world, i + 7, j + 6, k + 5, ModBlocks.firewoodLeaves);
		setBlock(world, i + 7, j + 6, k + 12, ModBlocks.firewoodLeaves);
		setBlock(world, i + 7, j + 6, k + 13, ModBlocks.firewoodLeaves);
		setBlock(world, i + 7, j + 6, k + 14, ModBlocks.firewoodLeaves);
		setBlock(world, i + 7, j + 6, k + 15, ModBlocks.firewoodLeaves);
		setBlock(world, i + 7, j + 6, k + 16, ModBlocks.firewoodLeaves);
		setBlock(world, i + 7, j + 7, k + 1, ModBlocks.firewoodLeaves);
		setBlock(world, i + 7, j + 7, k + 2, ModBlocks.firewoodLeaves);
		setBlock(world, i + 7, j + 7, k + 3, ModBlocks.firewoodLeaves);
		setBlock(world, i + 7, j + 7, k + 4, ModBlocks.firewoodLeaves);
		setBlock(world, i + 7, j + 7, k + 5, ModBlocks.firewoodLeaves);
		setBlock(world, i + 7, j + 7, k + 12, ModBlocks.firewoodLeaves);
		setBlock(world, i + 7, j + 7, k + 13, ModBlocks.firewoodLeaves);
		setBlock(world, i + 7, j + 7, k + 14, ModBlocks.firewoodLeaves);
		setBlock(world, i + 7, j + 7, k + 15, ModBlocks.firewoodLeaves);
		setBlock(world, i + 7, j + 7, k + 16, ModBlocks.firewoodLeaves);
		setBlock(world, i + 7, j + 11, k + 8, ModBlocks.firewood);
		setBlock(world, i + 7, j + 11, k + 9, ModBlocks.firewood);
		setBlock(world, i + 7, j + 12, k + 8, ModBlocks.firewood);
		setBlock(world, i + 7, j + 12, k + 9, ModBlocks.firewood);
		setBlock(world, i + 7, j + 13, k + 8, ModBlocks.firewood);
		setBlock(world, i + 7, j + 13, k + 9, ModBlocks.firewood);
		setBlock(world, i + 7, j + 14, k + 8, ModBlocks.firewood);
		setBlock(world, i + 7, j + 14, k + 9, ModBlocks.firewood);
		setBlock(world, i + 8, j + 0, k + 6, ModBlocks.firewood);
		setBlock(world, i + 8, j + 0, k + 7, ModBlocks.firewood);
		setBlock(world, i + 8, j + 0, k + 8, ModBlocks.firewood);
		setBlock(world, i + 8, j + 0, k + 9, ModBlocks.firewood);
		setBlock(world, i + 8, j + 0, k + 10, ModBlocks.firewood);
		setBlock(world, i + 8, j + 0, k + 11, ModBlocks.firewood);
		setBlock(world, i + 8, j + 1, k + 7, ModBlocks.firewood);
		setBlock(world, i + 8, j + 1, k + 8, ModBlocks.firewood);
		setBlock(world, i + 8, j + 1, k + 9, ModBlocks.firewood);
		setBlock(world, i + 8, j + 1, k + 10, ModBlocks.firewood);
		setBlock(world, i + 8, j + 2, k + 2, ModBlocks.firewoodLeaves);
		setBlock(world, i + 8, j + 2, k + 3, ModBlocks.firewoodLeaves);
		setBlock(world, i + 8, j + 2, k + 4, ModBlocks.firewoodLeaves);
		setBlock(world, i + 8, j + 2, k + 8, ModBlocks.firewood);
		setBlock(world, i + 8, j + 2, k + 9, ModBlocks.firewood);
		setBlock(world, i + 8, j + 2, k + 13, ModBlocks.firewoodLeaves);
		setBlock(world, i + 8, j + 2, k + 14, ModBlocks.firewoodLeaves);
		setBlock(world, i + 8, j + 2, k + 15, ModBlocks.firewoodLeaves);
		setBlock(world, i + 8, j + 3, k + 1, ModBlocks.firewoodLeaves);
		setBlock(world, i + 8, j + 3, k + 2, ModBlocks.firewoodLeaves);
		setBlock(world, i + 8, j + 3, k + 3, ModBlocks.firewoodLeaves);
		setBlock(world, i + 8, j + 3, k + 4, ModBlocks.firewoodLeaves);
		setBlock(world, i + 8, j + 3, k + 5, ModBlocks.firewoodLeaves);
		setBlock(world, i + 8, j + 3, k + 8, ModBlocks.firewood);
		setBlock(world, i + 8, j + 3, k + 9, ModBlocks.firewood);
		setBlock(world, i + 8, j + 3, k + 12, ModBlocks.firewoodLeaves);
		setBlock(world, i + 8, j + 3, k + 13, ModBlocks.firewoodLeaves);
		setBlock(world, i + 8, j + 3, k + 14, ModBlocks.firewoodLeaves);
		setBlock(world, i + 8, j + 3, k + 15, ModBlocks.firewoodLeaves);
		setBlock(world, i + 8, j + 3, k + 16, ModBlocks.firewoodLeaves);
		setBlock(world, i + 8, j + 4, k + 0, ModBlocks.firewoodLeaves);
		setBlock(world, i + 8, j + 4, k + 1, ModBlocks.firewoodLeaves);
		setBlock(world, i + 8, j + 4, k + 2, ModBlocks.firewoodLeaves);
		setBlock(world, i + 8, j + 4, k + 3, ModBlocks.firewoodLeaves);
		setBlock(world, i + 8, j + 4, k + 4, ModBlocks.firewoodLeaves);
		setBlock(world, i + 8, j + 4, k + 5, ModBlocks.firewoodLeaves);
		setBlock(world, i + 8, j + 4, k + 6, ModBlocks.firewoodLeaves);
		setBlock(world, i + 8, j + 4, k + 8, ModBlocks.firewood);
		setBlock(world, i + 8, j + 4, k + 9, ModBlocks.firewood);
		setBlock(world, i + 8, j + 4, k + 11, ModBlocks.firewoodLeaves);
		setBlock(world, i + 8, j + 4, k + 12, ModBlocks.firewoodLeaves);
		setBlock(world, i + 8, j + 4, k + 13, ModBlocks.firewoodLeaves);
		setBlock(world, i + 8, j + 4, k + 14, ModBlocks.firewoodLeaves);
		setBlock(world, i + 8, j + 4, k + 15, ModBlocks.firewoodLeaves);
		setBlock(world, i + 8, j + 4, k + 16, ModBlocks.firewoodLeaves);
		setBlock(world, i + 8, j + 4, k + 17, ModBlocks.firewoodLeaves);
		setBlock(world, i + 8, j + 5, k + 0, ModBlocks.firewoodLeaves);
		setBlock(world, i + 8, j + 5, k + 1, ModBlocks.firewoodLeaves);
		setBlock(world, i + 8, j + 5, k + 2, ModBlocks.firewoodLeaves);
		setBlock(world, i + 8, j + 5, k + 3, ModBlocks.firewoodLeaves);
		setBlock(world, i + 8, j + 5, k + 4, ModBlocks.firewoodLeaves);
		setBlock(world, i + 8, j + 5, k + 5, ModBlocks.firewoodLeaves);
		setBlock(world, i + 8, j + 5, k + 6, ModBlocks.firewoodLeaves);
		setBlock(world, i + 8, j + 5, k + 8, ModBlocks.firewood);
		setBlock(world, i + 8, j + 5, k + 9, ModBlocks.firewood);
		setBlock(world, i + 8, j + 5, k + 11, ModBlocks.firewoodLeaves);
		setBlock(world, i + 8, j + 5, k + 12, ModBlocks.firewoodLeaves);
		setBlock(world, i + 8, j + 5, k + 13, ModBlocks.firewoodLeaves);
		setBlock(world, i + 8, j + 5, k + 14, ModBlocks.firewoodLeaves);
		setBlock(world, i + 8, j + 5, k + 15, ModBlocks.firewoodLeaves);
		setBlock(world, i + 8, j + 5, k + 16, ModBlocks.firewoodLeaves);
		setBlock(world, i + 8, j + 5, k + 17, ModBlocks.firewoodLeaves);
		setBlock(world, i + 8, j + 6, k + 0, ModBlocks.firewoodLeaves);
		setBlock(world, i + 8, j + 6, k + 1, ModBlocks.firewoodLeaves);
		setBlock(world, i + 8, j + 6, k + 2, ModBlocks.firewoodLeaves);
		setBlock(world, i + 8, j + 6, k + 3, ModBlocks.firewoodLeaves);
		setBlock(world, i + 8, j + 6, k + 4, ModBlocks.firewoodLeaves);
		setBlock(world, i + 8, j + 6, k + 5, ModBlocks.firewoodLeaves);
		setBlock(world, i + 8, j + 6, k + 6, ModBlocks.firewoodLeaves);
		setBlock(world, i + 8, j + 6, k + 8, ModBlocks.firewood);
		setBlock(world, i + 8, j + 6, k + 9, ModBlocks.firewood);
		setBlock(world, i + 8, j + 6, k + 11, ModBlocks.firewoodLeaves);
		setBlock(world, i + 8, j + 6, k + 12, ModBlocks.firewoodLeaves);
		setBlock(world, i + 8, j + 6, k + 13, ModBlocks.firewoodLeaves);
		setBlock(world, i + 8, j + 6, k + 14, ModBlocks.firewoodLeaves);
		setBlock(world, i + 8, j + 6, k + 15, ModBlocks.firewoodLeaves);
		setBlock(world, i + 8, j + 6, k + 16, ModBlocks.firewoodLeaves);
		setBlock(world, i + 8, j + 6, k + 17, ModBlocks.firewoodLeaves);
		setBlock(world, i + 8, j + 7, k + 1, ModBlocks.firewoodLeaves);
		setBlock(world, i + 8, j + 7, k + 2, ModBlocks.firewoodLeaves);
		setBlock(world, i + 8, j + 7, k + 3, ModBlocks.firewoodLeaves);
		setBlock(world, i + 8, j + 7, k + 4, ModBlocks.firewoodLeaves);
		setBlock(world, i + 8, j + 7, k + 5, ModBlocks.firewoodLeaves);
		setBlock(world, i + 8, j + 7, k + 8, ModBlocks.firewood);
		setBlock(world, i + 8, j + 7, k + 9, ModBlocks.firewood);
		setBlock(world, i + 8, j + 7, k + 12, ModBlocks.firewoodLeaves);
		setBlock(world, i + 8, j + 7, k + 13, ModBlocks.firewoodLeaves);
		setBlock(world, i + 8, j + 7, k + 14, ModBlocks.firewoodLeaves);
		setBlock(world, i + 8, j + 7, k + 15, ModBlocks.firewoodLeaves);
		setBlock(world, i + 8, j + 7, k + 16, ModBlocks.firewoodLeaves);
		setBlock(world, i + 8, j + 8, k + 2, ModBlocks.firewoodLeaves);
		setBlock(world, i + 8, j + 8, k + 3, ModBlocks.firewoodLeaves);
		setBlock(world, i + 8, j + 8, k + 4, ModBlocks.firewoodLeaves);
		setBlock(world, i + 8, j + 8, k + 8, ModBlocks.firewood);
		setBlock(world, i + 8, j + 8, k + 9, ModBlocks.firewood);
		setBlock(world, i + 8, j + 8, k + 13, ModBlocks.firewoodLeaves);
		setBlock(world, i + 8, j + 8, k + 14, ModBlocks.firewoodLeaves);
		setBlock(world, i + 8, j + 8, k + 15, ModBlocks.firewoodLeaves);
		setBlock(world, i + 8, j + 9, k + 3, ModBlocks.firewood);
		setBlock(world, i + 8, j + 9, k + 4, ModBlocks.firewood);
		setBlock(world, i + 8, j + 9, k + 8, ModBlocks.firewood);
		setBlock(world, i + 8, j + 9, k + 9, ModBlocks.firewood);
		setBlock(world, i + 8, j + 9, k + 13, ModBlocks.firewood);
		setBlock(world, i + 8, j + 9, k + 14, ModBlocks.firewood);
		setBlock(world, i + 8, j + 10, k + 3, ModBlocks.firewood);
		setBlock(world, i + 8, j + 10, k + 4, ModBlocks.firewood);
		setBlock(world, i + 8, j + 10, k + 8, ModBlocks.firewood);
		setBlock(world, i + 8, j + 10, k + 9, ModBlocks.firewood);
		setBlock(world, i + 8, j + 10, k + 13, ModBlocks.firewood);
		setBlock(world, i + 8, j + 10, k + 14, ModBlocks.firewood);
		setBlock(world, i + 8, j + 11, k + 3, ModBlocks.firewood);
		setBlock(world, i + 8, j + 11, k + 4, ModBlocks.firewood);
		setBlock(world, i + 8, j + 11, k + 5, ModBlocks.firewood);
		setBlock(world, i + 8, j + 11, k + 6, ModBlocks.firewood);
		setBlock(world, i + 8, j + 11, k + 7, ModBlocks.firewood);
		setBlock(world, i + 8, j + 11, k + 8, ModBlocks.firewood);
		setBlock(world, i + 8, j + 11, k + 9, ModBlocks.firewood);
		setBlock(world, i + 8, j + 11, k + 10, ModBlocks.firewood);
		setBlock(world, i + 8, j + 11, k + 11, ModBlocks.firewood);
		setBlock(world, i + 8, j + 11, k + 12, ModBlocks.firewood);
		setBlock(world, i + 8, j + 11, k + 13, ModBlocks.firewood);
		setBlock(world, i + 8, j + 11, k + 14, ModBlocks.firewood);
		setBlock(world, i + 8, j + 12, k + 3, ModBlocks.firewood);
		setBlock(world, i + 8, j + 12, k + 4, ModBlocks.firewood);
		setBlock(world, i + 8, j + 12, k + 5, ModBlocks.firewood);
		setBlock(world, i + 8, j + 12, k + 6, ModBlocks.firewood);
		setBlock(world, i + 8, j + 12, k + 7, ModBlocks.firewood);
		setBlock(world, i + 8, j + 12, k + 8, ModBlocks.firewood);
		setBlock(world, i + 8, j + 12, k + 9, ModBlocks.firewood);
		setBlock(world, i + 8, j + 12, k + 10, ModBlocks.firewood);
		setBlock(world, i + 8, j + 12, k + 11, ModBlocks.firewood);
		setBlock(world, i + 8, j + 12, k + 12, ModBlocks.firewood);
		setBlock(world, i + 8, j + 12, k + 13, ModBlocks.firewood);
		setBlock(world, i + 8, j + 12, k + 14, ModBlocks.firewood);
		setBlock(world, i + 8, j + 13, k + 6, ModBlocks.firewood);
		setBlock(world, i + 8, j + 13, k + 7, ModBlocks.firewood);
		setBlock(world, i + 8, j + 13, k + 8, ModBlocks.firewood);
		setBlock(world, i + 8, j + 13, k + 9, ModBlocks.firewood);
		setBlock(world, i + 8, j + 13, k + 10, ModBlocks.firewood);
		setBlock(world, i + 8, j + 13, k + 11, ModBlocks.firewood);
		setBlock(world, i + 8, j + 14, k + 7, ModBlocks.firewood);
		setBlock(world, i + 8, j + 14, k + 8, ModBlocks.firewood);
		setBlock(world, i + 8, j + 14, k + 9, ModBlocks.firewood);
		setBlock(world, i + 8, j + 14, k + 10, ModBlocks.firewood);
		setBlock(world, i + 9, j + 0, k + 6, ModBlocks.firewood);
		setBlock(world, i + 9, j + 0, k + 7, ModBlocks.firewood);
		setBlock(world, i + 9, j + 0, k + 8, ModBlocks.firewood);
		setBlock(world, i + 9, j + 0, k + 9, ModBlocks.firewood);
		setBlock(world, i + 9, j + 0, k + 10, ModBlocks.firewood);
		setBlock(world, i + 9, j + 0, k + 11, ModBlocks.firewood);
		setBlock(world, i + 9, j + 1, k + 7, ModBlocks.firewood);
		setBlock(world, i + 9, j + 1, k + 8, ModBlocks.firewood);
		setBlock(world, i + 9, j + 1, k + 9, ModBlocks.firewood);
		setBlock(world, i + 9, j + 1, k + 10, ModBlocks.firewood);
		setBlock(world, i + 9, j + 2, k + 2, ModBlocks.firewoodLeaves);
		setBlock(world, i + 9, j + 2, k + 3, ModBlocks.firewoodLeaves);
		setBlock(world, i + 9, j + 2, k + 4, ModBlocks.firewoodLeaves);
		setBlock(world, i + 9, j + 2, k + 8, ModBlocks.firewood);
		setBlock(world, i + 9, j + 2, k + 9, ModBlocks.firewood);
		setBlock(world, i + 9, j + 2, k + 13, ModBlocks.firewoodLeaves);
		setBlock(world, i + 9, j + 2, k + 14, ModBlocks.firewoodLeaves);
		setBlock(world, i + 9, j + 2, k + 15, ModBlocks.firewoodLeaves);
		setBlock(world, i + 9, j + 3, k + 1, ModBlocks.firewoodLeaves);
		setBlock(world, i + 9, j + 3, k + 2, ModBlocks.firewoodLeaves);
		setBlock(world, i + 9, j + 3, k + 3, ModBlocks.firewoodLeaves);
		setBlock(world, i + 9, j + 3, k + 4, ModBlocks.firewoodLeaves);
		setBlock(world, i + 9, j + 3, k + 5, ModBlocks.firewoodLeaves);
		setBlock(world, i + 9, j + 3, k + 8, ModBlocks.firewood);
		setBlock(world, i + 9, j + 3, k + 9, ModBlocks.firewood);
		setBlock(world, i + 9, j + 3, k + 12, ModBlocks.firewoodLeaves);
		setBlock(world, i + 9, j + 3, k + 13, ModBlocks.firewoodLeaves);
		setBlock(world, i + 9, j + 3, k + 14, ModBlocks.firewoodLeaves);
		setBlock(world, i + 9, j + 3, k + 15, ModBlocks.firewoodLeaves);
		setBlock(world, i + 9, j + 3, k + 16, ModBlocks.firewoodLeaves);
		setBlock(world, i + 9, j + 4, k + 0, ModBlocks.firewoodLeaves);
		setBlock(world, i + 9, j + 4, k + 1, ModBlocks.firewoodLeaves);
		setBlock(world, i + 9, j + 4, k + 2, ModBlocks.firewoodLeaves);
		setBlock(world, i + 9, j + 4, k + 3, ModBlocks.firewoodLeaves);
		setBlock(world, i + 9, j + 4, k + 4, ModBlocks.firewoodLeaves);
		setBlock(world, i + 9, j + 4, k + 5, ModBlocks.firewoodLeaves);
		setBlock(world, i + 9, j + 4, k + 6, ModBlocks.firewoodLeaves);
		setBlock(world, i + 9, j + 4, k + 8, ModBlocks.firewood);
		setBlock(world, i + 9, j + 4, k + 9, ModBlocks.firewood);
		setBlock(world, i + 9, j + 4, k + 11, ModBlocks.firewoodLeaves);
		setBlock(world, i + 9, j + 4, k + 12, ModBlocks.firewoodLeaves);
		setBlock(world, i + 9, j + 4, k + 13, ModBlocks.firewoodLeaves);
		setBlock(world, i + 9, j + 4, k + 14, ModBlocks.firewoodLeaves);
		setBlock(world, i + 9, j + 4, k + 15, ModBlocks.firewoodLeaves);
		setBlock(world, i + 9, j + 4, k + 16, ModBlocks.firewoodLeaves);
		setBlock(world, i + 9, j + 4, k + 17, ModBlocks.firewoodLeaves);
		setBlock(world, i + 9, j + 5, k + 0, ModBlocks.firewoodLeaves);
		setBlock(world, i + 9, j + 5, k + 1, ModBlocks.firewoodLeaves);
		setBlock(world, i + 9, j + 5, k + 2, ModBlocks.firewoodLeaves);
		setBlock(world, i + 9, j + 5, k + 3, ModBlocks.firewoodLeaves);
		setBlock(world, i + 9, j + 5, k + 4, ModBlocks.firewoodLeaves);
		setBlock(world, i + 9, j + 5, k + 5, ModBlocks.firewoodLeaves);
		setBlock(world, i + 9, j + 5, k + 6, ModBlocks.firewoodLeaves);
		setBlock(world, i + 9, j + 5, k + 8, ModBlocks.firewood);
		setBlock(world, i + 9, j + 5, k + 9, ModBlocks.firewood);
		setBlock(world, i + 9, j + 5, k + 11, ModBlocks.firewoodLeaves);
		setBlock(world, i + 9, j + 5, k + 12, ModBlocks.firewoodLeaves);
		setBlock(world, i + 9, j + 5, k + 13, ModBlocks.firewoodLeaves);
		setBlock(world, i + 9, j + 5, k + 14, ModBlocks.firewoodLeaves);
		setBlock(world, i + 9, j + 5, k + 15, ModBlocks.firewoodLeaves);
		setBlock(world, i + 9, j + 5, k + 16, ModBlocks.firewoodLeaves);
		setBlock(world, i + 9, j + 5, k + 17, ModBlocks.firewoodLeaves);
		setBlock(world, i + 9, j + 6, k + 0, ModBlocks.firewoodLeaves);
		setBlock(world, i + 9, j + 6, k + 1, ModBlocks.firewoodLeaves);
		setBlock(world, i + 9, j + 6, k + 2, ModBlocks.firewoodLeaves);
		setBlock(world, i + 9, j + 6, k + 3, ModBlocks.firewoodLeaves);
		setBlock(world, i + 9, j + 6, k + 4, ModBlocks.firewoodLeaves);
		setBlock(world, i + 9, j + 6, k + 5, ModBlocks.firewoodLeaves);
		setBlock(world, i + 9, j + 6, k + 6, ModBlocks.firewoodLeaves);
		setBlock(world, i + 9, j + 6, k + 8, ModBlocks.firewood);
		setBlock(world, i + 9, j + 6, k + 9, ModBlocks.firewood);
		setBlock(world, i + 9, j + 6, k + 11, ModBlocks.firewoodLeaves);
		setBlock(world, i + 9, j + 6, k + 12, ModBlocks.firewoodLeaves);
		setBlock(world, i + 9, j + 6, k + 13, ModBlocks.firewoodLeaves);
		setBlock(world, i + 9, j + 6, k + 14, ModBlocks.firewoodLeaves);
		setBlock(world, i + 9, j + 6, k + 15, ModBlocks.firewoodLeaves);
		setBlock(world, i + 9, j + 6, k + 16, ModBlocks.firewoodLeaves);
		setBlock(world, i + 9, j + 6, k + 17, ModBlocks.firewoodLeaves);
		setBlock(world, i + 9, j + 7, k + 1, ModBlocks.firewoodLeaves);
		setBlock(world, i + 9, j + 7, k + 2, ModBlocks.firewoodLeaves);
		setBlock(world, i + 9, j + 7, k + 3, ModBlocks.firewoodLeaves);
		setBlock(world, i + 9, j + 7, k + 4, ModBlocks.firewoodLeaves);
		setBlock(world, i + 9, j + 7, k + 5, ModBlocks.firewoodLeaves);
		setBlock(world, i + 9, j + 7, k + 8, ModBlocks.firewood);
		setBlock(world, i + 9, j + 7, k + 9, ModBlocks.firewood);
		setBlock(world, i + 9, j + 7, k + 12, ModBlocks.firewoodLeaves);
		setBlock(world, i + 9, j + 7, k + 13, ModBlocks.firewoodLeaves);
		setBlock(world, i + 9, j + 7, k + 14, ModBlocks.firewoodLeaves);
		setBlock(world, i + 9, j + 7, k + 15, ModBlocks.firewoodLeaves);
		setBlock(world, i + 9, j + 7, k + 16, ModBlocks.firewoodLeaves);
		setBlock(world, i + 9, j + 8, k + 2, ModBlocks.firewoodLeaves);
		setBlock(world, i + 9, j + 8, k + 3, ModBlocks.firewoodLeaves);
		setBlock(world, i + 9, j + 8, k + 4, ModBlocks.firewoodLeaves);
		setBlock(world, i + 9, j + 8, k + 8, ModBlocks.firewood);
		setBlock(world, i + 9, j + 8, k + 9, ModBlocks.firewood);
		setBlock(world, i + 9, j + 8, k + 13, ModBlocks.firewoodLeaves);
		setBlock(world, i + 9, j + 8, k + 14, ModBlocks.firewoodLeaves);
		setBlock(world, i + 9, j + 8, k + 15, ModBlocks.firewoodLeaves);
		setBlock(world, i + 9, j + 9, k + 3, ModBlocks.firewood);
		setBlock(world, i + 9, j + 9, k + 4, ModBlocks.firewood);
		setBlock(world, i + 9, j + 9, k + 8, ModBlocks.firewood);
		setBlock(world, i + 9, j + 9, k + 9, ModBlocks.firewood);
		setBlock(world, i + 9, j + 9, k + 13, ModBlocks.firewood);
		setBlock(world, i + 9, j + 9, k + 14, ModBlocks.firewood);
		setBlock(world, i + 9, j + 10, k + 3, ModBlocks.firewood);
		setBlock(world, i + 9, j + 10, k + 4, ModBlocks.firewood);
		setBlock(world, i + 9, j + 10, k + 8, ModBlocks.firewood);
		setBlock(world, i + 9, j + 10, k + 9, ModBlocks.firewood);
		setBlock(world, i + 9, j + 10, k + 13, ModBlocks.firewood);
		setBlock(world, i + 9, j + 10, k + 14, ModBlocks.firewood);
		setBlock(world, i + 9, j + 11, k + 3, ModBlocks.firewood);
		setBlock(world, i + 9, j + 11, k + 4, ModBlocks.firewood);
		setBlock(world, i + 9, j + 11, k + 5, ModBlocks.firewood);
		setBlock(world, i + 9, j + 11, k + 6, ModBlocks.firewood);
		setBlock(world, i + 9, j + 11, k + 7, ModBlocks.firewood);
		setBlock(world, i + 9, j + 11, k + 8, ModBlocks.firewood);
		setBlock(world, i + 9, j + 11, k + 9, ModBlocks.firewood);
		setBlock(world, i + 9, j + 11, k + 10, ModBlocks.firewood);
		setBlock(world, i + 9, j + 11, k + 11, ModBlocks.firewood);
		setBlock(world, i + 9, j + 11, k + 12, ModBlocks.firewood);
		setBlock(world, i + 9, j + 11, k + 13, ModBlocks.firewood);
		setBlock(world, i + 9, j + 11, k + 14, ModBlocks.firewood);
		setBlock(world, i + 9, j + 12, k + 3, ModBlocks.firewood);
		setBlock(world, i + 9, j + 12, k + 4, ModBlocks.firewood);
		setBlock(world, i + 9, j + 12, k + 5, ModBlocks.firewood);
		setBlock(world, i + 9, j + 12, k + 6, ModBlocks.firewood);
		setBlock(world, i + 9, j + 12, k + 7, ModBlocks.firewood);
		setBlock(world, i + 9, j + 12, k + 8, ModBlocks.firewood);
		setBlock(world, i + 9, j + 12, k + 9, ModBlocks.firewood);
		setBlock(world, i + 9, j + 12, k + 10, ModBlocks.firewood);
		setBlock(world, i + 9, j + 12, k + 11, ModBlocks.firewood);
		setBlock(world, i + 9, j + 12, k + 12, ModBlocks.firewood);
		setBlock(world, i + 9, j + 12, k + 13, ModBlocks.firewood);
		setBlock(world, i + 9, j + 12, k + 14, ModBlocks.firewood);
		setBlock(world, i + 9, j + 13, k + 6, ModBlocks.firewood);
		setBlock(world, i + 9, j + 13, k + 7, ModBlocks.firewood);
		setBlock(world, i + 9, j + 13, k + 8, ModBlocks.firewood);
		setBlock(world, i + 9, j + 13, k + 9, ModBlocks.firewood);
		setBlock(world, i + 9, j + 13, k + 10, ModBlocks.firewood);
		setBlock(world, i + 9, j + 13, k + 11, ModBlocks.firewood);
		setBlock(world, i + 9, j + 14, k + 7, ModBlocks.firewood);
		setBlock(world, i + 9, j + 14, k + 8, ModBlocks.firewood);
		setBlock(world, i + 9, j + 14, k + 9, ModBlocks.firewood);
		setBlock(world, i + 9, j + 14, k + 10, ModBlocks.firewood);
		setBlock(world, i + 10, j + 0, k + 7, ModBlocks.firewood);
		setBlock(world, i + 10, j + 0, k + 8, ModBlocks.firewood);
		setBlock(world, i + 10, j + 0, k + 9, ModBlocks.firewood);
		setBlock(world, i + 10, j + 0, k + 10, ModBlocks.firewood);
		setBlock(world, i + 10, j + 1, k + 8, ModBlocks.firewood);
		setBlock(world, i + 10, j + 1, k + 9, ModBlocks.firewood);
		setBlock(world, i + 10, j + 2, k + 2, ModBlocks.firewoodLeaves);
		setBlock(world, i + 10, j + 2, k + 3, ModBlocks.firewoodLeaves);
		setBlock(world, i + 10, j + 2, k + 4, ModBlocks.firewoodLeaves);
		setBlock(world, i + 10, j + 2, k + 13, ModBlocks.firewoodLeaves);
		setBlock(world, i + 10, j + 2, k + 14, ModBlocks.firewoodLeaves);
		setBlock(world, i + 10, j + 2, k + 15, ModBlocks.firewoodLeaves);
		setBlock(world, i + 10, j + 3, k + 1, ModBlocks.firewoodLeaves);
		setBlock(world, i + 10, j + 3, k + 2, ModBlocks.firewoodLeaves);
		setBlock(world, i + 10, j + 3, k + 3, ModBlocks.firewoodLeaves);
		setBlock(world, i + 10, j + 3, k + 4, ModBlocks.firewoodLeaves);
		setBlock(world, i + 10, j + 3, k + 5, ModBlocks.firewoodLeaves);
		setBlock(world, i + 10, j + 3, k + 12, ModBlocks.firewoodLeaves);
		setBlock(world, i + 10, j + 3, k + 13, ModBlocks.firewoodLeaves);
		setBlock(world, i + 10, j + 3, k + 14, ModBlocks.firewoodLeaves);
		setBlock(world, i + 10, j + 3, k + 15, ModBlocks.firewoodLeaves);
		setBlock(world, i + 10, j + 3, k + 16, ModBlocks.firewoodLeaves);
		setBlock(world, i + 10, j + 4, k + 0, ModBlocks.firewoodLeaves);
		setBlock(world, i + 10, j + 4, k + 1, ModBlocks.firewoodLeaves);
		setBlock(world, i + 10, j + 4, k + 2, ModBlocks.firewoodLeaves);
		setBlock(world, i + 10, j + 4, k + 3, ModBlocks.firewoodLeaves);
		setBlock(world, i + 10, j + 4, k + 4, ModBlocks.firewoodLeaves);
		setBlock(world, i + 10, j + 4, k + 5, ModBlocks.firewoodLeaves);
		setBlock(world, i + 10, j + 4, k + 6, ModBlocks.firewoodLeaves);
		setBlock(world, i + 10, j + 4, k + 11, ModBlocks.firewoodLeaves);
		setBlock(world, i + 10, j + 4, k + 12, ModBlocks.firewoodLeaves);
		setBlock(world, i + 10, j + 4, k + 13, ModBlocks.firewoodLeaves);
		setBlock(world, i + 10, j + 4, k + 14, ModBlocks.firewoodLeaves);
		setBlock(world, i + 10, j + 4, k + 15, ModBlocks.firewoodLeaves);
		setBlock(world, i + 10, j + 4, k + 16, ModBlocks.firewoodLeaves);
		setBlock(world, i + 10, j + 4, k + 17, ModBlocks.firewoodLeaves);
		setBlock(world, i + 10, j + 5, k + 0, ModBlocks.firewoodLeaves);
		setBlock(world, i + 10, j + 5, k + 1, ModBlocks.firewoodLeaves);
		setBlock(world, i + 10, j + 5, k + 2, ModBlocks.firewoodLeaves);
		setBlock(world, i + 10, j + 5, k + 3, ModBlocks.firewoodLeaves);
		setBlock(world, i + 10, j + 5, k + 4, ModBlocks.firewoodLeaves);
		setBlock(world, i + 10, j + 5, k + 5, ModBlocks.firewoodLeaves);
		setBlock(world, i + 10, j + 5, k + 6, ModBlocks.firewoodLeaves);
		setBlock(world, i + 10, j + 5, k + 11, ModBlocks.firewoodLeaves);
		setBlock(world, i + 10, j + 5, k + 12, ModBlocks.firewoodLeaves);
		setBlock(world, i + 10, j + 5, k + 13, ModBlocks.firewoodLeaves);
		setBlock(world, i + 10, j + 5, k + 14, ModBlocks.firewoodLeaves);
		setBlock(world, i + 10, j + 5, k + 15, ModBlocks.firewoodLeaves);
		setBlock(world, i + 10, j + 5, k + 16, ModBlocks.firewoodLeaves);
		setBlock(world, i + 10, j + 5, k + 17, ModBlocks.firewoodLeaves);
		setBlock(world, i + 10, j + 6, k + 0, ModBlocks.firewoodLeaves);
		setBlock(world, i + 10, j + 6, k + 1, ModBlocks.firewoodLeaves);
		setBlock(world, i + 10, j + 6, k + 2, ModBlocks.firewoodLeaves);
		setBlock(world, i + 10, j + 6, k + 3, ModBlocks.firewoodLeaves);
		setBlock(world, i + 10, j + 6, k + 4, ModBlocks.firewoodLeaves);
		setBlock(world, i + 10, j + 6, k + 5, ModBlocks.firewoodLeaves);
		setBlock(world, i + 10, j + 6, k + 6, ModBlocks.firewoodLeaves);
		setBlock(world, i + 10, j + 6, k + 11, ModBlocks.firewoodLeaves);
		setBlock(world, i + 10, j + 6, k + 12, ModBlocks.firewoodLeaves);
		setBlock(world, i + 10, j + 6, k + 13, ModBlocks.firewoodLeaves);
		setBlock(world, i + 10, j + 6, k + 14, ModBlocks.firewoodLeaves);
		setBlock(world, i + 10, j + 6, k + 15, ModBlocks.firewoodLeaves);
		setBlock(world, i + 10, j + 6, k + 16, ModBlocks.firewoodLeaves);
		setBlock(world, i + 10, j + 6, k + 17, ModBlocks.firewoodLeaves);
		setBlock(world, i + 10, j + 7, k + 1, ModBlocks.firewoodLeaves);
		setBlock(world, i + 10, j + 7, k + 2, ModBlocks.firewoodLeaves);
		setBlock(world, i + 10, j + 7, k + 3, ModBlocks.firewoodLeaves);
		setBlock(world, i + 10, j + 7, k + 4, ModBlocks.firewoodLeaves);
		setBlock(world, i + 10, j + 7, k + 5, ModBlocks.firewoodLeaves);
		setBlock(world, i + 10, j + 7, k + 12, ModBlocks.firewoodLeaves);
		setBlock(world, i + 10, j + 7, k + 13, ModBlocks.firewoodLeaves);
		setBlock(world, i + 10, j + 7, k + 14, ModBlocks.firewoodLeaves);
		setBlock(world, i + 10, j + 7, k + 15, ModBlocks.firewoodLeaves);
		setBlock(world, i + 10, j + 7, k + 16, ModBlocks.firewoodLeaves);
		setBlock(world, i + 10, j + 8, k + 2, ModBlocks.firewoodLeaves);
		setBlock(world, i + 10, j + 8, k + 3, ModBlocks.firewoodLeaves);
		setBlock(world, i + 10, j + 8, k + 4, ModBlocks.firewoodLeaves);
		setBlock(world, i + 10, j + 8, k + 13, ModBlocks.firewoodLeaves);
		setBlock(world, i + 10, j + 8, k + 14, ModBlocks.firewoodLeaves);
		setBlock(world, i + 10, j + 8, k + 15, ModBlocks.firewoodLeaves);
		setBlock(world, i + 10, j + 11, k + 8, ModBlocks.firewood);
		setBlock(world, i + 10, j + 11, k + 9, ModBlocks.firewood);
		setBlock(world, i + 10, j + 12, k + 8, ModBlocks.firewood);
		setBlock(world, i + 10, j + 12, k + 9, ModBlocks.firewood);
		setBlock(world, i + 10, j + 13, k + 8, ModBlocks.firewood);
		setBlock(world, i + 10, j + 13, k + 9, ModBlocks.firewood);
		setBlock(world, i + 10, j + 14, k + 8, ModBlocks.firewood);
		setBlock(world, i + 10, j + 14, k + 9, ModBlocks.firewood);
		setBlock(world, i + 11, j + 0, k + 8, ModBlocks.firewood);
		setBlock(world, i + 11, j + 0, k + 9, ModBlocks.firewood);
		setBlock(world, i + 11, j + 3, k + 1, ModBlocks.firewoodLeaves);
		setBlock(world, i + 11, j + 3, k + 2, ModBlocks.firewoodLeaves);
		setBlock(world, i + 11, j + 3, k + 3, ModBlocks.firewoodLeaves);
		setBlock(world, i + 11, j + 3, k + 4, ModBlocks.firewoodLeaves);
		setBlock(world, i + 11, j + 3, k + 5, ModBlocks.firewoodLeaves);
		setBlock(world, i + 11, j + 3, k + 12, ModBlocks.firewoodLeaves);
		setBlock(world, i + 11, j + 3, k + 13, ModBlocks.firewoodLeaves);
		setBlock(world, i + 11, j + 3, k + 14, ModBlocks.firewoodLeaves);
		setBlock(world, i + 11, j + 3, k + 15, ModBlocks.firewoodLeaves);
		setBlock(world, i + 11, j + 3, k + 16, ModBlocks.firewoodLeaves);
		setBlock(world, i + 11, j + 4, k + 1, ModBlocks.firewoodLeaves);
		setBlock(world, i + 11, j + 4, k + 2, ModBlocks.firewoodLeaves);
		setBlock(world, i + 11, j + 4, k + 3, ModBlocks.firewoodLeaves);
		setBlock(world, i + 11, j + 4, k + 4, ModBlocks.firewoodLeaves);
		setBlock(world, i + 11, j + 4, k + 5, ModBlocks.firewoodLeaves);
		setBlock(world, i + 11, j + 4, k + 12, ModBlocks.firewoodLeaves);
		setBlock(world, i + 11, j + 4, k + 13, ModBlocks.firewoodLeaves);
		setBlock(world, i + 11, j + 4, k + 14, ModBlocks.firewoodLeaves);
		setBlock(world, i + 11, j + 4, k + 15, ModBlocks.firewoodLeaves);
		setBlock(world, i + 11, j + 4, k + 16, ModBlocks.firewoodLeaves);
		setBlock(world, i + 11, j + 5, k + 1, ModBlocks.firewoodLeaves);
		setBlock(world, i + 11, j + 5, k + 2, ModBlocks.firewoodLeaves);
		setBlock(world, i + 11, j + 5, k + 3, ModBlocks.firewoodLeaves);
		setBlock(world, i + 11, j + 5, k + 4, ModBlocks.firewoodLeaves);
		setBlock(world, i + 11, j + 5, k + 5, ModBlocks.firewoodLeaves);
		setBlock(world, i + 11, j + 5, k + 12, ModBlocks.firewoodLeaves);
		setBlock(world, i + 11, j + 5, k + 13, ModBlocks.firewoodLeaves);
		setBlock(world, i + 11, j + 5, k + 14, ModBlocks.firewoodLeaves);
		setBlock(world, i + 11, j + 5, k + 15, ModBlocks.firewoodLeaves);
		setBlock(world, i + 11, j + 5, k + 16, ModBlocks.firewoodLeaves);
		setBlock(world, i + 11, j + 6, k + 1, ModBlocks.firewoodLeaves);
		setBlock(world, i + 11, j + 6, k + 2, ModBlocks.firewoodLeaves);
		setBlock(world, i + 11, j + 6, k + 3, ModBlocks.firewoodLeaves);
		setBlock(world, i + 11, j + 6, k + 4, ModBlocks.firewoodLeaves);
		setBlock(world, i + 11, j + 6, k + 5, ModBlocks.firewoodLeaves);
		setBlock(world, i + 11, j + 6, k + 12, ModBlocks.firewoodLeaves);
		setBlock(world, i + 11, j + 6, k + 13, ModBlocks.firewoodLeaves);
		setBlock(world, i + 11, j + 6, k + 14, ModBlocks.firewoodLeaves);
		setBlock(world, i + 11, j + 6, k + 15, ModBlocks.firewoodLeaves);
		setBlock(world, i + 11, j + 6, k + 16, ModBlocks.firewoodLeaves);
		setBlock(world, i + 11, j + 7, k + 1, ModBlocks.firewoodLeaves);
		setBlock(world, i + 11, j + 7, k + 2, ModBlocks.firewoodLeaves);
		setBlock(world, i + 11, j + 7, k + 3, ModBlocks.firewoodLeaves);
		setBlock(world, i + 11, j + 7, k + 4, ModBlocks.firewoodLeaves);
		setBlock(world, i + 11, j + 7, k + 5, ModBlocks.firewoodLeaves);
		setBlock(world, i + 11, j + 7, k + 12, ModBlocks.firewoodLeaves);
		setBlock(world, i + 11, j + 7, k + 13, ModBlocks.firewoodLeaves);
		setBlock(world, i + 11, j + 7, k + 14, ModBlocks.firewoodLeaves);
		setBlock(world, i + 11, j + 7, k + 15, ModBlocks.firewoodLeaves);
		setBlock(world, i + 11, j + 7, k + 16, ModBlocks.firewoodLeaves);
		setBlock(world, i + 11, j + 11, k + 8, ModBlocks.firewood);
		setBlock(world, i + 11, j + 11, k + 9, ModBlocks.firewood);
		setBlock(world, i + 11, j + 12, k + 8, ModBlocks.firewood);
		setBlock(world, i + 11, j + 12, k + 9, ModBlocks.firewood);
		setBlock(world, i + 11, j + 13, k + 8, ModBlocks.firewood);
		setBlock(world, i + 11, j + 13, k + 9, ModBlocks.firewood);
		setBlock(world, i + 12, j + 3, k + 8, ModBlocks.firewoodLeaves);
		setBlock(world, i + 12, j + 3, k + 9, ModBlocks.firewoodLeaves);
		setBlock(world, i + 12, j + 3, k + 10, ModBlocks.firewoodLeaves);
		setBlock(world, i + 12, j + 4, k + 2, ModBlocks.firewoodLeaves);
		setBlock(world, i + 12, j + 4, k + 3, ModBlocks.firewoodLeaves);
		setBlock(world, i + 12, j + 4, k + 4, ModBlocks.firewoodLeaves);
		setBlock(world, i + 12, j + 4, k + 8, ModBlocks.firewoodLeaves);
		setBlock(world, i + 12, j + 4, k + 9, ModBlocks.firewoodLeaves);
		setBlock(world, i + 12, j + 4, k + 10, ModBlocks.firewoodLeaves);
		setBlock(world, i + 12, j + 4, k + 13, ModBlocks.firewoodLeaves);
		setBlock(world, i + 12, j + 4, k + 14, ModBlocks.firewoodLeaves);
		setBlock(world, i + 12, j + 4, k + 15, ModBlocks.firewoodLeaves);
		setBlock(world, i + 12, j + 5, k + 2, ModBlocks.firewoodLeaves);
		setBlock(world, i + 12, j + 5, k + 3, ModBlocks.firewoodLeaves);
		setBlock(world, i + 12, j + 5, k + 4, ModBlocks.firewoodLeaves);
		setBlock(world, i + 12, j + 5, k + 8, ModBlocks.firewoodLeaves);
		setBlock(world, i + 12, j + 5, k + 9, ModBlocks.firewoodLeaves);
		setBlock(world, i + 12, j + 5, k + 10, ModBlocks.firewoodLeaves);
		setBlock(world, i + 12, j + 5, k + 13, ModBlocks.firewoodLeaves);
		setBlock(world, i + 12, j + 5, k + 14, ModBlocks.firewoodLeaves);
		setBlock(world, i + 12, j + 5, k + 15, ModBlocks.firewoodLeaves);
		setBlock(world, i + 12, j + 6, k + 2, ModBlocks.firewoodLeaves);
		setBlock(world, i + 12, j + 6, k + 3, ModBlocks.firewoodLeaves);
		setBlock(world, i + 12, j + 6, k + 4, ModBlocks.firewoodLeaves);
		setBlock(world, i + 12, j + 6, k + 13, ModBlocks.firewoodLeaves);
		setBlock(world, i + 12, j + 6, k + 14, ModBlocks.firewoodLeaves);
		setBlock(world, i + 12, j + 6, k + 15, ModBlocks.firewoodLeaves);
		setBlock(world, i + 12, j + 11, k + 8, ModBlocks.firewood);
		setBlock(world, i + 12, j + 11, k + 9, ModBlocks.firewood);
		setBlock(world, i + 12, j + 12, k + 8, ModBlocks.firewood);
		setBlock(world, i + 12, j + 12, k + 9, ModBlocks.firewood);
		setBlock(world, i + 13, j + 2, k + 7, ModBlocks.firewoodLeaves);
		setBlock(world, i + 13, j + 2, k + 8, ModBlocks.firewoodLeaves);
		setBlock(world, i + 13, j + 2, k + 9, ModBlocks.firewoodLeaves);
		setBlock(world, i + 13, j + 2, k + 10, ModBlocks.firewoodLeaves);
		setBlock(world, i + 13, j + 2, k + 11, ModBlocks.firewoodLeaves);
		setBlock(world, i + 13, j + 3, k + 7, ModBlocks.firewoodLeaves);
		setBlock(world, i + 13, j + 3, k + 8, ModBlocks.firewoodLeaves);
		setBlock(world, i + 13, j + 3, k + 9, ModBlocks.firewoodLeaves);
		setBlock(world, i + 13, j + 3, k + 10, ModBlocks.firewoodLeaves);
		setBlock(world, i + 13, j + 3, k + 11, ModBlocks.firewoodLeaves);
		setBlock(world, i + 13, j + 4, k + 7, ModBlocks.firewoodLeaves);
		setBlock(world, i + 13, j + 4, k + 8, ModBlocks.firewoodLeaves);
		setBlock(world, i + 13, j + 4, k + 9, ModBlocks.firewoodLeaves);
		setBlock(world, i + 13, j + 4, k + 10, ModBlocks.firewoodLeaves);
		setBlock(world, i + 13, j + 4, k + 11, ModBlocks.firewoodLeaves);
		setBlock(world, i + 13, j + 5, k + 7, ModBlocks.firewoodLeaves);
		setBlock(world, i + 13, j + 5, k + 8, ModBlocks.firewoodLeaves);
		setBlock(world, i + 13, j + 5, k + 9, ModBlocks.firewoodLeaves);
		setBlock(world, i + 13, j + 5, k + 10, ModBlocks.firewoodLeaves);
		setBlock(world, i + 13, j + 5, k + 11, ModBlocks.firewoodLeaves);
		setBlock(world, i + 13, j + 6, k + 7, ModBlocks.firewoodLeaves);
		setBlock(world, i + 13, j + 6, k + 8, ModBlocks.firewoodLeaves);
		setBlock(world, i + 13, j + 6, k + 9, ModBlocks.firewoodLeaves);
		setBlock(world, i + 13, j + 6, k + 10, ModBlocks.firewoodLeaves);
		setBlock(world, i + 13, j + 6, k + 11, ModBlocks.firewoodLeaves);
		setBlock(world, i + 13, j + 7, k + 8, ModBlocks.firewood);
		setBlock(world, i + 13, j + 7, k + 9, ModBlocks.firewood);
		setBlock(world, i + 13, j + 8, k + 8, ModBlocks.firewood);
		setBlock(world, i + 13, j + 8, k + 9, ModBlocks.firewood);
		setBlock(world, i + 13, j + 9, k + 8, ModBlocks.firewood);
		setBlock(world, i + 13, j + 9, k + 9, ModBlocks.firewood);
		setBlock(world, i + 13, j + 10, k + 8, ModBlocks.firewood);
		setBlock(world, i + 13, j + 10, k + 9, ModBlocks.firewood);
		setBlock(world, i + 13, j + 11, k + 8, ModBlocks.firewood);
		setBlock(world, i + 13, j + 11, k + 9, ModBlocks.firewood);
		setBlock(world, i + 13, j + 12, k + 8, ModBlocks.firewood);
		setBlock(world, i + 13, j + 12, k + 9, ModBlocks.firewood);
		setBlock(world, i + 14, j + 1, k + 8, ModBlocks.firewoodLeaves);
		setBlock(world, i + 14, j + 1, k + 9, ModBlocks.firewoodLeaves);
		setBlock(world, i + 14, j + 1, k + 10, ModBlocks.firewoodLeaves);
		setBlock(world, i + 14, j + 2, k + 7, ModBlocks.firewoodLeaves);
		setBlock(world, i + 14, j + 2, k + 8, ModBlocks.firewoodLeaves);
		setBlock(world, i + 14, j + 2, k + 9, ModBlocks.firewoodLeaves);
		setBlock(world, i + 14, j + 2, k + 10, ModBlocks.firewoodLeaves);
		setBlock(world, i + 14, j + 2, k + 11, ModBlocks.firewoodLeaves);
		setBlock(world, i + 14, j + 3, k + 6, ModBlocks.firewoodLeaves);
		setBlock(world, i + 14, j + 3, k + 7, ModBlocks.firewoodLeaves);
		setBlock(world, i + 14, j + 3, k + 8, ModBlocks.firewoodLeaves);
		setBlock(world, i + 14, j + 3, k + 9, ModBlocks.firewoodLeaves);
		setBlock(world, i + 14, j + 3, k + 10, ModBlocks.firewoodLeaves);
		setBlock(world, i + 14, j + 3, k + 11, ModBlocks.firewoodLeaves);
		setBlock(world, i + 14, j + 3, k + 12, ModBlocks.firewoodLeaves);
		setBlock(world, i + 14, j + 4, k + 6, ModBlocks.firewoodLeaves);
		setBlock(world, i + 14, j + 4, k + 7, ModBlocks.firewoodLeaves);
		setBlock(world, i + 14, j + 4, k + 8, ModBlocks.firewoodLeaves);
		setBlock(world, i + 14, j + 4, k + 9, ModBlocks.firewoodLeaves);
		setBlock(world, i + 14, j + 4, k + 10, ModBlocks.firewoodLeaves);
		setBlock(world, i + 14, j + 4, k + 11, ModBlocks.firewoodLeaves);
		setBlock(world, i + 14, j + 4, k + 12, ModBlocks.firewoodLeaves);
		setBlock(world, i + 14, j + 5, k + 6, ModBlocks.firewoodLeaves);
		setBlock(world, i + 14, j + 5, k + 7, ModBlocks.firewoodLeaves);
		setBlock(world, i + 14, j + 5, k + 8, ModBlocks.firewoodLeaves);
		setBlock(world, i + 14, j + 5, k + 9, ModBlocks.firewoodLeaves);
		setBlock(world, i + 14, j + 5, k + 10, ModBlocks.firewoodLeaves);
		setBlock(world, i + 14, j + 5, k + 11, ModBlocks.firewoodLeaves);
		setBlock(world, i + 14, j + 5, k + 12, ModBlocks.firewoodLeaves);
		setBlock(world, i + 14, j + 6, k + 7, ModBlocks.firewoodLeaves);
		setBlock(world, i + 14, j + 6, k + 8, ModBlocks.firewoodLeaves);
		setBlock(world, i + 14, j + 6, k + 9, ModBlocks.firewoodLeaves);
		setBlock(world, i + 14, j + 6, k + 10, ModBlocks.firewoodLeaves);
		setBlock(world, i + 14, j + 6, k + 11, ModBlocks.firewoodLeaves);
		setBlock(world, i + 14, j + 7, k + 8, ModBlocks.firewoodLeaves);
		setBlock(world, i + 14, j + 7, k + 9, ModBlocks.firewoodLeaves);
		setBlock(world, i + 14, j + 7, k + 10, ModBlocks.firewoodLeaves);
		setBlock(world, i + 14, j + 8, k + 8, ModBlocks.firewood);
		setBlock(world, i + 14, j + 8, k + 9, ModBlocks.firewood);
		setBlock(world, i + 14, j + 9, k + 8, ModBlocks.firewood);
		setBlock(world, i + 14, j + 9, k + 9, ModBlocks.firewood);
		setBlock(world, i + 14, j + 10, k + 8, ModBlocks.firewood);
		setBlock(world, i + 14, j + 10, k + 9, ModBlocks.firewood);
		setBlock(world, i + 14, j + 11, k + 8, ModBlocks.firewood);
		setBlock(world, i + 14, j + 11, k + 9, ModBlocks.firewood);
		setBlock(world, i + 14, j + 12, k + 8, ModBlocks.firewood);
		setBlock(world, i + 14, j + 12, k + 9, ModBlocks.firewood);
		setBlock(world, i + 15, j + 1, k + 8, ModBlocks.firewoodLeaves);
		setBlock(world, i + 15, j + 1, k + 9, ModBlocks.firewoodLeaves);
		setBlock(world, i + 15, j + 1, k + 10, ModBlocks.firewoodLeaves);
		setBlock(world, i + 15, j + 2, k + 7, ModBlocks.firewoodLeaves);
		setBlock(world, i + 15, j + 2, k + 8, ModBlocks.firewoodLeaves);
		setBlock(world, i + 15, j + 2, k + 9, ModBlocks.firewoodLeaves);
		setBlock(world, i + 15, j + 2, k + 10, ModBlocks.firewoodLeaves);
		setBlock(world, i + 15, j + 2, k + 11, ModBlocks.firewoodLeaves);
		setBlock(world, i + 15, j + 3, k + 6, ModBlocks.firewoodLeaves);
		setBlock(world, i + 15, j + 3, k + 7, ModBlocks.firewoodLeaves);
		setBlock(world, i + 15, j + 3, k + 8, ModBlocks.firewoodLeaves);
		setBlock(world, i + 15, j + 3, k + 9, ModBlocks.firewoodLeaves);
		setBlock(world, i + 15, j + 3, k + 10, ModBlocks.firewoodLeaves);
		setBlock(world, i + 15, j + 3, k + 11, ModBlocks.firewoodLeaves);
		setBlock(world, i + 15, j + 3, k + 12, ModBlocks.firewoodLeaves);
		setBlock(world, i + 15, j + 4, k + 6, ModBlocks.firewoodLeaves);
		setBlock(world, i + 15, j + 4, k + 7, ModBlocks.firewoodLeaves);
		setBlock(world, i + 15, j + 4, k + 8, ModBlocks.firewoodLeaves);
		setBlock(world, i + 15, j + 4, k + 9, ModBlocks.firewoodLeaves);
		setBlock(world, i + 15, j + 4, k + 10, ModBlocks.firewoodLeaves);
		setBlock(world, i + 15, j + 4, k + 11, ModBlocks.firewoodLeaves);
		setBlock(world, i + 15, j + 4, k + 12, ModBlocks.firewoodLeaves);
		setBlock(world, i + 15, j + 5, k + 6, ModBlocks.firewoodLeaves);
		setBlock(world, i + 15, j + 5, k + 7, ModBlocks.firewoodLeaves);
		setBlock(world, i + 15, j + 5, k + 8, ModBlocks.firewoodLeaves);
		setBlock(world, i + 15, j + 5, k + 9, ModBlocks.firewoodLeaves);
		setBlock(world, i + 15, j + 5, k + 10, ModBlocks.firewoodLeaves);
		setBlock(world, i + 15, j + 5, k + 11, ModBlocks.firewoodLeaves);
		setBlock(world, i + 15, j + 5, k + 12, ModBlocks.firewoodLeaves);
		setBlock(world, i + 15, j + 6, k + 7, ModBlocks.firewoodLeaves);
		setBlock(world, i + 15, j + 6, k + 8, ModBlocks.firewoodLeaves);
		setBlock(world, i + 15, j + 6, k + 9, ModBlocks.firewoodLeaves);
		setBlock(world, i + 15, j + 6, k + 10, ModBlocks.firewoodLeaves);
		setBlock(world, i + 15, j + 6, k + 11, ModBlocks.firewoodLeaves);
		setBlock(world, i + 15, j + 7, k + 8, ModBlocks.firewoodLeaves);
		setBlock(world, i + 15, j + 7, k + 9, ModBlocks.firewoodLeaves);
		setBlock(world, i + 15, j + 7, k + 10, ModBlocks.firewoodLeaves);
		setBlock(world, i + 16, j + 1, k + 8, ModBlocks.firewoodLeaves);
		setBlock(world, i + 16, j + 1, k + 9, ModBlocks.firewoodLeaves);
		setBlock(world, i + 16, j + 1, k + 10, ModBlocks.firewoodLeaves);
		setBlock(world, i + 16, j + 2, k + 7, ModBlocks.firewoodLeaves);
		setBlock(world, i + 16, j + 2, k + 8, ModBlocks.firewoodLeaves);
		setBlock(world, i + 16, j + 2, k + 9, ModBlocks.firewoodLeaves);
		setBlock(world, i + 16, j + 2, k + 10, ModBlocks.firewoodLeaves);
		setBlock(world, i + 16, j + 2, k + 11, ModBlocks.firewoodLeaves);
		setBlock(world, i + 16, j + 3, k + 6, ModBlocks.firewoodLeaves);
		setBlock(world, i + 16, j + 3, k + 7, ModBlocks.firewoodLeaves);
		setBlock(world, i + 16, j + 3, k + 8, ModBlocks.firewoodLeaves);
		setBlock(world, i + 16, j + 3, k + 9, ModBlocks.firewoodLeaves);
		setBlock(world, i + 16, j + 3, k + 10, ModBlocks.firewoodLeaves);
		setBlock(world, i + 16, j + 3, k + 11, ModBlocks.firewoodLeaves);
		setBlock(world, i + 16, j + 3, k + 12, ModBlocks.firewoodLeaves);
		setBlock(world, i + 16, j + 4, k + 6, ModBlocks.firewoodLeaves);
		setBlock(world, i + 16, j + 4, k + 7, ModBlocks.firewoodLeaves);
		setBlock(world, i + 16, j + 4, k + 8, ModBlocks.firewoodLeaves);
		setBlock(world, i + 16, j + 4, k + 9, ModBlocks.firewoodLeaves);
		setBlock(world, i + 16, j + 4, k + 10, ModBlocks.firewoodLeaves);
		setBlock(world, i + 16, j + 4, k + 11, ModBlocks.firewoodLeaves);
		setBlock(world, i + 16, j + 4, k + 12, ModBlocks.firewoodLeaves);
		setBlock(world, i + 16, j + 5, k + 6, ModBlocks.firewoodLeaves);
		setBlock(world, i + 16, j + 5, k + 7, ModBlocks.firewoodLeaves);
		setBlock(world, i + 16, j + 5, k + 8, ModBlocks.firewoodLeaves);
		setBlock(world, i + 16, j + 5, k + 9, ModBlocks.firewoodLeaves);
		setBlock(world, i + 16, j + 5, k + 10, ModBlocks.firewoodLeaves);
		setBlock(world, i + 16, j + 5, k + 11, ModBlocks.firewoodLeaves);
		setBlock(world, i + 16, j + 5, k + 12, ModBlocks.firewoodLeaves);
		setBlock(world, i + 16, j + 6, k + 7, ModBlocks.firewoodLeaves);
		setBlock(world, i + 16, j + 6, k + 8, ModBlocks.firewoodLeaves);
		setBlock(world, i + 16, j + 6, k + 9, ModBlocks.firewoodLeaves);
		setBlock(world, i + 16, j + 6, k + 10, ModBlocks.firewoodLeaves);
		setBlock(world, i + 16, j + 6, k + 11, ModBlocks.firewoodLeaves);
		setBlock(world, i + 16, j + 7, k + 8, ModBlocks.firewoodLeaves);
		setBlock(world, i + 16, j + 7, k + 9, ModBlocks.firewoodLeaves);
		setBlock(world, i + 16, j + 7, k + 10, ModBlocks.firewoodLeaves);
		setBlock(world, i + 17, j + 2, k + 7, ModBlocks.firewoodLeaves);
		setBlock(world, i + 17, j + 2, k + 8, ModBlocks.firewoodLeaves);
		setBlock(world, i + 17, j + 2, k + 9, ModBlocks.firewoodLeaves);
		setBlock(world, i + 17, j + 2, k + 10, ModBlocks.firewoodLeaves);
		setBlock(world, i + 17, j + 2, k + 11, ModBlocks.firewoodLeaves);
		setBlock(world, i + 17, j + 3, k + 7, ModBlocks.firewoodLeaves);
		setBlock(world, i + 17, j + 3, k + 8, ModBlocks.firewoodLeaves);
		setBlock(world, i + 17, j + 3, k + 9, ModBlocks.firewoodLeaves);
		setBlock(world, i + 17, j + 3, k + 10, ModBlocks.firewoodLeaves);
		setBlock(world, i + 17, j + 3, k + 11, ModBlocks.firewoodLeaves);
		setBlock(world, i + 17, j + 4, k + 7, ModBlocks.firewoodLeaves);
		setBlock(world, i + 17, j + 4, k + 8, ModBlocks.firewoodLeaves);
		setBlock(world, i + 17, j + 4, k + 9, ModBlocks.firewoodLeaves);
		setBlock(world, i + 17, j + 4, k + 10, ModBlocks.firewoodLeaves);
		setBlock(world, i + 17, j + 4, k + 11, ModBlocks.firewoodLeaves);
		setBlock(world, i + 17, j + 5, k + 7, ModBlocks.firewoodLeaves);
		setBlock(world, i + 17, j + 5, k + 8, ModBlocks.firewoodLeaves);
		setBlock(world, i + 17, j + 5, k + 9, ModBlocks.firewoodLeaves);
		setBlock(world, i + 17, j + 5, k + 10, ModBlocks.firewoodLeaves);
		setBlock(world, i + 17, j + 5, k + 11, ModBlocks.firewoodLeaves);
		setBlock(world, i + 17, j + 6, k + 7, ModBlocks.firewoodLeaves);
		setBlock(world, i + 17, j + 6, k + 8, ModBlocks.firewoodLeaves);
		setBlock(world, i + 17, j + 6, k + 9, ModBlocks.firewoodLeaves);
		setBlock(world, i + 17, j + 6, k + 10, ModBlocks.firewoodLeaves);
		setBlock(world, i + 17, j + 6, k + 11, ModBlocks.firewoodLeaves);
		setBlock(world, i + 18, j + 3, k + 8, ModBlocks.firewoodLeaves);
		setBlock(world, i + 18, j + 3, k + 9, ModBlocks.firewoodLeaves);
		setBlock(world, i + 18, j + 3, k + 10, ModBlocks.firewoodLeaves);
		setBlock(world, i + 18, j + 4, k + 8, ModBlocks.firewoodLeaves);
		setBlock(world, i + 18, j + 4, k + 9, ModBlocks.firewoodLeaves);
		setBlock(world, i + 18, j + 4, k + 10, ModBlocks.firewoodLeaves);
		setBlock(world, i + 18, j + 5, k + 8, ModBlocks.firewoodLeaves);
		setBlock(world, i + 18, j + 5, k + 9, ModBlocks.firewoodLeaves);
		setBlock(world, i + 18, j + 5, k + 10, ModBlocks.firewoodLeaves);

		return true;
	}
}