package net.divinerpg.dimensions.vethea.all;

import net.divinerpg.dimensions.vethea.IVetheanStructure;
import net.divinerpg.dimensions.vethea.VetheaChunk;
import net.divinerpg.utils.blocks.VetheaBlocks;

public class FloatingTree2 implements IVetheanStructure {

	@Override
	public void generate(VetheaChunk chunk, int i, int j, int k) {
		chunk.setBlock(i + 0, j + 1, k + 1, VetheaBlocks.mintwoodLeaves);
		chunk.setBlock(i + 0, j + 1, k + 2, VetheaBlocks.mintwoodLeaves);
		chunk.setBlock(i + 0, j + 1, k + 8, VetheaBlocks.dreamStone);
		chunk.setBlock(i + 0, j + 2, k + 2, VetheaBlocks.mintwoodLeaves);
		chunk.setBlock(i + 0, j + 2, k + 3, VetheaBlocks.mintwoodLeaves);
		chunk.setBlock(i + 0, j + 2, k + 8, VetheaBlocks.dreamStone);
		chunk.setBlock(i + 1, j + 0, k + 2, VetheaBlocks.mintwoodLeaves);
		chunk.setBlock(i + 1, j + 0, k + 8, VetheaBlocks.dreamStone);
		chunk.setBlock(i + 1, j + 1, k + 0, VetheaBlocks.mintwoodLeaves);
		chunk.setBlock(i + 1, j + 1, k + 1, VetheaBlocks.mintwoodLeaves);
		chunk.setBlock(i + 1, j + 1, k + 2, VetheaBlocks.mintwood);
		chunk.setBlock(i + 1, j + 1, k + 3, VetheaBlocks.mintwood);
		chunk.setBlock(i + 1, j + 1, k + 4, VetheaBlocks.mintwood);
		chunk.setBlock(i + 1, j + 1, k + 5, VetheaBlocks.mintwood);
		chunk.setBlock(i + 1, j + 1, k + 6, VetheaBlocks.mintwood);
		chunk.setBlock(i + 1, j + 1, k + 7, VetheaBlocks.dreamStone);
		chunk.setBlock(i + 1, j + 1, k + 8, VetheaBlocks.dreamStone);
		chunk.setBlock(i + 1, j + 2, k + 1, VetheaBlocks.mintwoodLeaves);
		chunk.setBlock(i + 1, j + 2, k + 2, VetheaBlocks.mintwood);
		chunk.setBlock(i + 1, j + 2, k + 3, VetheaBlocks.mintwood);
		chunk.setBlock(i + 1, j + 2, k + 4, VetheaBlocks.mintwood);
		chunk.setBlock(i + 1, j + 2, k + 5, VetheaBlocks.mintwood);
		chunk.setBlock(i + 1, j + 2, k + 6, VetheaBlocks.mintwood);
		chunk.setBlock(i + 1, j + 2, k + 7, VetheaBlocks.dreamStone);
		chunk.setBlock(i + 1, j + 2, k + 8, VetheaBlocks.dreamStone);
		chunk.setBlock(i + 1, j + 3, k + 2, VetheaBlocks.mintwoodLeaves);
		chunk.setBlock(i + 1, j + 3, k + 3, VetheaBlocks.mintwoodLeaves);
		chunk.setBlock(i + 1, j + 3, k + 8, VetheaBlocks.dreamStone);
		chunk.setBlock(i + 2, j + 0, k + 2, VetheaBlocks.mintwoodLeaves);
		chunk.setBlock(i + 2, j + 0, k + 8, VetheaBlocks.dreamStone);
		chunk.setBlock(i + 2, j + 1, k + 1, VetheaBlocks.mintwoodLeaves);
		chunk.setBlock(i + 2, j + 1, k + 2, VetheaBlocks.mintwood);
		chunk.setBlock(i + 2, j + 1, k + 3, VetheaBlocks.mintwood);
		chunk.setBlock(i + 2, j + 1, k + 4, VetheaBlocks.mintwood);
		chunk.setBlock(i + 2, j + 1, k + 5, VetheaBlocks.mintwood);
		chunk.setBlock(i + 2, j + 1, k + 6, VetheaBlocks.mintwood);
		chunk.setBlock(i + 2, j + 1, k + 7, VetheaBlocks.dreamStone);
		chunk.setBlock(i + 2, j + 1, k + 8, VetheaBlocks.dreamStone);
		chunk.setBlock(i + 2, j + 2, k + 1, VetheaBlocks.mintwoodLeaves);
		chunk.setBlock(i + 2, j + 2, k + 2, VetheaBlocks.mintwood);
		chunk.setBlock(i + 2, j + 2, k + 3, VetheaBlocks.mintwood);
		chunk.setBlock(i + 2, j + 2, k + 4, VetheaBlocks.mintwood);
		chunk.setBlock(i + 2, j + 2, k + 5, VetheaBlocks.mintwood);
		chunk.setBlock(i + 2, j + 2, k + 6, VetheaBlocks.mintwood);
		chunk.setBlock(i + 2, j + 2, k + 7, VetheaBlocks.dreamStone);
		chunk.setBlock(i + 2, j + 2, k + 8, VetheaBlocks.dreamStone);
		chunk.setBlock(i + 2, j + 3, k + 2, VetheaBlocks.mintwoodLeaves);
		chunk.setBlock(i + 2, j + 3, k + 8, VetheaBlocks.dreamStone);
		chunk.setBlock(i + 3, j + 0, k + 2, VetheaBlocks.mintwoodLeaves);
		chunk.setBlock(i + 3, j + 1, k + 2, VetheaBlocks.mintwoodLeaves);
		chunk.setBlock(i + 3, j + 1, k + 8, VetheaBlocks.dreamStone);
		chunk.setBlock(i + 3, j + 2, k + 2, VetheaBlocks.mintwoodLeaves);
		chunk.setBlock(i + 3, j + 2, k + 3, VetheaBlocks.mintwoodLeaves);
		chunk.setBlock(i + 3, j + 2, k + 8, VetheaBlocks.dreamStone);
		}
}
