/*
*** MADE BY MITHION'S .SCHEMATIC TO JAVA CONVERTING TOOL v1.6 ***
*/

package net.divinerpg.dimensions.vethea.all;
import java.util.Random;

import net.divinerpg.utils.blocks.VetheaBlocks;
import net.minecraft.world.World;
import net.minecraft.world.gen.feature.WorldGenerator;

public class TreeFloating3 extends WorldGenerator
{
	protected int[] GetValidSpawnBlocks() {
		return new int[] {
		};
	}
	
	public TreeFloating3() { }

	public boolean generate(World world, Random rand, int i, int j, int k) {

		world.setBlock(i + 0, j + 2, k + 1, VetheaBlocks.firewoodLeaves);
		world.setBlock(i + 0, j + 2, k + 2, VetheaBlocks.firewoodLeaves);
		world.setBlock(i + 0, j + 2, k + 3, VetheaBlocks.firewoodLeaves);
		world.setBlock(i + 0, j + 5, k + 1, VetheaBlocks.dreamStone);
		world.setBlock(i + 0, j + 5, k + 2, VetheaBlocks.dreamStone);
		world.setBlock(i + 1, j + 0, k + 2, VetheaBlocks.firewoodLeaves);
		world.setBlock(i + 1, j + 1, k + 0, VetheaBlocks.firewoodLeaves);
		world.setBlock(i + 1, j + 1, k + 1, VetheaBlocks.firewoodLeaves);
		world.setBlock(i + 1, j + 1, k + 2, VetheaBlocks.firewoodLeaves);
		world.setBlock(i + 1, j + 2, k + 0, VetheaBlocks.firewoodLeaves);
		world.setBlock(i + 1, j + 2, k + 1, VetheaBlocks.firewood);
		world.setBlock(i + 1, j + 2, k + 2, VetheaBlocks.firewood);
		world.setBlock(i + 1, j + 2, k + 3, VetheaBlocks.firewoodLeaves);
		world.setBlock(i + 1, j + 3, k + 1, VetheaBlocks.firewood);
		world.setBlock(i + 1, j + 3, k + 2, VetheaBlocks.firewood);
		world.setBlock(i + 1, j + 3, k + 3, VetheaBlocks.firewoodLeaves);
		world.setBlock(i + 1, j + 4, k + 1, VetheaBlocks.firewood);
		world.setBlock(i + 1, j + 4, k + 2, VetheaBlocks.firewood);
		world.setBlock(i + 1, j + 5, k + 0, VetheaBlocks.dreamStone);
		world.setBlock(i + 1, j + 5, k + 1, VetheaBlocks.dreamStone);
		world.setBlock(i + 1, j + 5, k + 2, VetheaBlocks.dreamStone);
		world.setBlock(i + 1, j + 5, k + 3, VetheaBlocks.dreamStone);
		world.setBlock(i + 2, j + 1, k + 1, VetheaBlocks.firewoodLeaves);
		world.setBlock(i + 2, j + 1, k + 2, VetheaBlocks.firewoodLeaves);
		world.setBlock(i + 2, j + 2, k + 0, VetheaBlocks.firewoodLeaves);
		world.setBlock(i + 2, j + 2, k + 1, VetheaBlocks.firewood);
		world.setBlock(i + 2, j + 2, k + 2, VetheaBlocks.firewood);
		world.setBlock(i + 2, j + 2, k + 3, VetheaBlocks.firewoodLeaves);
		world.setBlock(i + 2, j + 3, k + 1, VetheaBlocks.firewood);
		world.setBlock(i + 2, j + 3, k + 2, VetheaBlocks.firewood);
		world.setBlock(i + 2, j + 4, k + 1, VetheaBlocks.firewood);
		world.setBlock(i + 2, j + 4, k + 2, VetheaBlocks.firewood);
		world.setBlock(i + 2, j + 5, k + 0, VetheaBlocks.dreamStone);
		world.setBlock(i + 2, j + 5, k + 1, VetheaBlocks.dreamStone);
		world.setBlock(i + 2, j + 5, k + 2, VetheaBlocks.dreamStone);
		world.setBlock(i + 2, j + 5, k + 3, VetheaBlocks.dreamStone);
		world.setBlock(i + 3, j + 2, k + 1, VetheaBlocks.firewoodLeaves);
		world.setBlock(i + 3, j + 2, k + 2, VetheaBlocks.firewoodLeaves);
		world.setBlock(i + 3, j + 5, k + 1, VetheaBlocks.dreamStone);
		world.setBlock(i + 3, j + 5, k + 2, VetheaBlocks.dreamStone);

		return true;
	}
}