package net.divinerpg.dimensions.vethea.all;
import net.divinerpg.dimensions.vethea.IVetheanStructure;
import net.divinerpg.dimensions.vethea.VetheaChunk;
import net.divinerpg.utils.blocks.VetheaBlocks;

public class FloatingTree5 implements IVetheanStructure
{

	public void generate(VetheaChunk chunk, int i, int j, int k) {

		chunk.setBlock(i + 0, j + 1, k + 8, VetheaBlocks.hyrewoodLeaves);
		chunk.setBlock(i + 1, j + 0, k + 8, VetheaBlocks.hyrewoodLeaves);
		chunk.setBlock(i + 1, j + 1, k + 5, VetheaBlocks.dreamStone);
		chunk.setBlock(i + 1, j + 1, k + 6, VetheaBlocks.hyrewood);
		chunk.setBlock(i + 1, j + 1, k + 7, VetheaBlocks.hyrewood);
		chunk.setBlock(i + 1, j + 1, k + 8, VetheaBlocks.hyrewood);
		chunk.setBlock(i + 1, j + 1, k + 9, VetheaBlocks.hyrewoodLeaves);
		chunk.setBlock(i + 1, j + 2, k + 1, VetheaBlocks.hyrewoodLeaves);
		chunk.setBlock(i + 1, j + 2, k + 5, VetheaBlocks.dreamStone);
		chunk.setBlock(i + 1, j + 2, k + 8, VetheaBlocks.hyrewoodLeaves);
		chunk.setBlock(i + 2, j + 0, k + 5, VetheaBlocks.dreamStone);
		chunk.setBlock(i + 2, j + 1, k + 1, VetheaBlocks.hyrewoodLeaves);
		chunk.setBlock(i + 2, j + 1, k + 4, VetheaBlocks.dreamStone);
		chunk.setBlock(i + 2, j + 1, k + 5, VetheaBlocks.dreamStone);
		chunk.setBlock(i + 2, j + 1, k + 6, VetheaBlocks.dreamStone);
		chunk.setBlock(i + 2, j + 1, k + 8, VetheaBlocks.hyrewoodLeaves);
		chunk.setBlock(i + 2, j + 2, k + 0, VetheaBlocks.hyrewoodLeaves);
		chunk.setBlock(i + 2, j + 2, k + 1, VetheaBlocks.hyrewoodLeaves);
		chunk.setBlock(i + 2, j + 2, k + 2, VetheaBlocks.hyrewood);
		chunk.setBlock(i + 2, j + 2, k + 3, VetheaBlocks.hyrewood);
		chunk.setBlock(i + 2, j + 2, k + 4, VetheaBlocks.dreamStone);
		chunk.setBlock(i + 2, j + 2, k + 5, VetheaBlocks.dreamStone);
		chunk.setBlock(i + 2, j + 2, k + 6, VetheaBlocks.dreamStone);
		chunk.setBlock(i + 2, j + 3, k + 1, VetheaBlocks.hyrewoodLeaves);
		chunk.setBlock(i + 2, j + 3, k + 5, VetheaBlocks.dreamStone);
		chunk.setBlock(i + 2, j + 5, k + 6, VetheaBlocks.hyrewoodLeaves);
		chunk.setBlock(i + 3, j + 0, k + 5, VetheaBlocks.dreamStone);
		chunk.setBlock(i + 3, j + 1, k + 4, VetheaBlocks.dreamStone);
		chunk.setBlock(i + 3, j + 1, k + 5, VetheaBlocks.dreamStone);
		chunk.setBlock(i + 3, j + 1, k + 6, VetheaBlocks.dreamStone);
		chunk.setBlock(i + 3, j + 2, k + 1, VetheaBlocks.hyrewoodLeaves);
		chunk.setBlock(i + 3, j + 2, k + 4, VetheaBlocks.dreamStone);
		chunk.setBlock(i + 3, j + 2, k + 5, VetheaBlocks.dreamStone);
		chunk.setBlock(i + 3, j + 2, k + 6, VetheaBlocks.dreamStone);
		chunk.setBlock(i + 3, j + 3, k + 5, VetheaBlocks.dreamStone);
		chunk.setBlock(i + 3, j + 3, k + 6, VetheaBlocks.hyrewood);
		chunk.setBlock(i + 3, j + 4, k + 6, VetheaBlocks.hyrewood);
		chunk.setBlock(i + 3, j + 5, k + 5, VetheaBlocks.hyrewoodLeaves);
		chunk.setBlock(i + 3, j + 5, k + 6, VetheaBlocks.dreamDirt);
		chunk.setBlock(i + 3, j + 5, k + 7, VetheaBlocks.hyrewoodLeaves);
		chunk.setBlock(i + 3, j + 6, k + 6, VetheaBlocks.hyrewoodLeaves);
		chunk.setBlock(i + 4, j + 1, k + 5, VetheaBlocks.dreamStone);
		chunk.setBlock(i + 4, j + 2, k + 5, VetheaBlocks.dreamStone);
		chunk.setBlock(i + 4, j + 5, k + 6, VetheaBlocks.hyrewoodLeaves);
	}
}